Workbook

Sheet Income statement
B1: Income Statement — Monthly 2027–2030 (€)
C2: 46388 | D2: 46419 | E2: 46447 | F2: 46478 | G2: 46508 | H2: 46539 | I2: 46569 | J2: 46600 | K2: 46631 | L2: 46661 | M2: 46692 | N2: 46722 | O2: 46753 | P2: 46784 | Q2: 46813 | R2: 46844 | S2: 46874 | T2: 46905 | U2: 46935 | V2: 46966 | W2: 46997 | X2: 47027 | Y2: 47058 | Z2: 47088 | AA2: 47119 | AB2: 47150 | AC2: 47178 | AD2: 47209 | AE2: 47239 | AF2: 47270 | AG2: 47300 | AH2: 47331 | AI2: 47362 | AJ2: 47392 | AK2: 47423 | AL2: 47453 | AM2: 47484 | AN2: 47515 | AO2: 47543 | AP2: 47574 | AQ2: 47604 | AR2: 47635 | AS2: 47665 | AT2: 47696 | AU2: 47727 | AV2: 47757 | AW2: 47788 | AX2: 47818 | AZ2: 2027 | BA2: 2028 | BB2: 2029 | BC2: 2030
B4: Revenues
B5: Retainer | C5: ='Commercials Forecast'!F23 -> 11833.333 | D5: ='Commercials Forecast'!G23 -> 23666.667 | E5: ='Commercials Forecast'!H23 -> 35500 | F5: ='Commercials Forecast'!I23 -> 47333.333 | G5: ='Commercials Forecast'!J23 -> 59166.667 | H5: ='Commercials Forecast'!K23 -> 60500 | I5: ='Commercials Forecast'!L23 -> 61833.333 | J5: ='Commercials Forecast'!M23 -> 61833.333 | ... AX5: ='Commercials Forecast'!BA23 -> 280583.33 | AZ5: =SUMPRODUCT((YEAR($C$2:$AX$2)=AZ$2)*$C5:$AX5) -> 609000 | BA5: =SUMPRODUCT((YEAR($C$2:$AX$2)=BA$2)*$C5:$AX5) -> 1417733.3 | BB5: =SUMPRODUCT((YEAR($C$2:$AX$2)=BB$2)*$C5:$AX5) -> 2275536.7 | BC5: =SUMPRODUCT((YEAR($C$2:$AX$2)=BC$2)*$C5:$AX5) -> 3146756.7
B6: Closing fees | C6: ='Commercials Forecast'!F24 -> 0 | D6: ='Commercials Forecast'!G24 -> 0 | E6: ='Commercials Forecast'!H24 -> 0 | F6: ='Commercials Forecast'!I24 -> 0 | G6: ='Commercials Forecast'!J24 -> 0 | H6: ='Commercials Forecast'!K24 -> 6750 | I6: ='Commercials Forecast'!L24 -> 6750 | J6: ='Commercials Forecast'!M24 -> 16750 | ... AX6: ='Commercials Forecast'!BA24 -> 1318125 | AZ6: =SUMPRODUCT((YEAR($C$2:$AX$2)=AZ$2)*$C6:$AX6) -> 97250 | BA6: =SUMPRODUCT((YEAR($C$2:$AX$2)=BA$2)*$C6:$AX6) -> 837520 | BB6: =SUMPRODUCT((YEAR($C$2:$AX$2)=BB$2)*$C6:$AX6) -> 4011364 | BC6: =SUMPRODUCT((YEAR($C$2:$AX$2)=BC$2)*$C6:$AX6) -> 12008762
B7: Less: industry-partner share | C7: ='Commercials Forecast'!F26 -> -739.58333 | D7: ='Commercials Forecast'!G26 -> -1479.1667 | E7: ='Commercials Forecast'!H26 -> -2218.75 | F7: ='Commercials Forecast'!I26 -> -2958.3333 | G7: ='Commercials Forecast'!J26 -> -3697.9167 | H7: ='Commercials Forecast'!K26 -> -4203.125 | I7: ='Commercials Forecast'!L26 -> -4286.4583 | J7: ='Commercials Forecast'!M26 -> -4911.4583 | ... AX7: ='Commercials Forecast'!BA26 -> -99919.271 | AZ7: =SUMPRODUCT((YEAR($C$2:$AX$2)=AZ$2)*$C7:$AX7) -> -44140.625 | BA7: =SUMPRODUCT((YEAR($C$2:$AX$2)=BA$2)*$C7:$AX7) -> -140953.33 | BB7: =SUMPRODUCT((YEAR($C$2:$AX$2)=BB$2)*$C7:$AX7) -> -392931.29 | BC7: =SUMPRODUCT((YEAR($C$2:$AX$2)=BC$2)*$C7:$AX7) -> -947219.95
B8: Total revenues | C8: =C5+C6+C7 -> 11093.75 | D8: =D5+D6+D7 -> 22187.5 | E8: =E5+E6+E7 -> 33281.25 | F8: =F5+F6+F7 -> 44375 | G8: =G5+G6+G7 -> 55468.75 | H8: =H5+H6+H7 -> 63046.875 | I8: =I5+I6+I7 -> 64296.875 | J8: =J5+J6+J7 -> 73671.875 | ... AX8: =AX5+AX6+AX7 -> 1498789.1 | AZ8: =SUMPRODUCT((YEAR($C$2:$AX$2)=AZ$2)*$C8:$AX8) -> 662109.38 | BA8: =SUMPRODUCT((YEAR($C$2:$AX$2)=BA$2)*$C8:$AX8) -> 2114300 | BB8: =SUMPRODUCT((YEAR($C$2:$AX$2)=BB$2)*$C8:$AX8) -> 5893969.4 | BC8: =SUMPRODUCT((YEAR($C$2:$AX$2)=BC$2)*$C8:$AX8) -> 14208299
B10: Personnel
B11: Gross salary | C11: =Personnel!F17+Personnel!F20 -> 32000 | D11: =Personnel!G17+Personnel!G20 -> 35000 | E11: =Personnel!H17+Personnel!H20 -> 35000 | F11: =Personnel!I17+Personnel!I20 -> 38000 | G11: =Personnel!J17+Personnel!J20 -> 38000 | H11: =Personnel!K17+Personnel!K20 -> 38000 | I11: =Personnel!L17+Personnel!L20 -> 38000 | J11: =Personnel!M17+Personnel!M20 -> 38000 | ... AX11: =Personnel!BA17+Personnel!BA20 -> 89000 | AZ11: =SUMPRODUCT((YEAR($C$2:$AX$2)=AZ$2)*$C11:$AX11) -> 444000 | BA11: =SUMPRODUCT((YEAR($C$2:$AX$2)=BA$2)*$C11:$AX11) -> 709500 | BB11: =SUMPRODUCT((YEAR($C$2:$AX$2)=BB$2)*$C11:$AX11) -> 882000 | BC11: =SUMPRODUCT((YEAR($C$2:$AX$2)=BC$2)*$C11:$AX11) -> 1038000
B12: Bonus | C12: =Personnel!F21 -> 0 | D12: =Personnel!G21 -> 0 | E12: =Personnel!H21 -> 0 | F12: =Personnel!I21 -> 0 | G12: =Personnel!J21 -> 0 | H12: =Personnel!K21 -> 2598.75 | I12: =Personnel!L21 -> 2598.75 | J12: =Personnel!M21 -> 6448.75 | ... AX12: =Personnel!BA21 -> 507478.12 | AZ12: =SUMPRODUCT((YEAR($C$2:$AX$2)=AZ$2)*$C12:$AX12) -> 37441.25 | BA12: =SUMPRODUCT((YEAR($C$2:$AX$2)=BA$2)*$C12:$AX12) -> 322445.2 | BB12: =SUMPRODUCT((YEAR($C$2:$AX$2)=BB$2)*$C12:$AX12) -> 1544375.1 | BC12: =SUMPRODUCT((YEAR($C$2:$AX$2)=BC$2)*$C12:$AX12) -> 4623373.6
B13: Employer taxes | C13: =Personnel!F18+Personnel!F19 -> 6987.4 | D13: =Personnel!G18+Personnel!G19 -> 7843 | E13: =Personnel!H18+Personnel!H19 -> 7843 | F13: =Personnel!I18+Personnel!I19 -> 8698.6 | G13: =Personnel!J18+Personnel!J19 -> 8698.6 | H13: =Personnel!K18+Personnel!K19 -> 8698.6 | I13: =Personnel!L18+Personnel!L19 -> 8698.6 | J13: =Personnel!M18+Personnel!M19 -> 8698.6 | ... AX13: =Personnel!BA18+Personnel!BA19 -> 23243.8 | AZ13: =SUMPRODUCT((YEAR($C$2:$AX$2)=AZ$2)*$C13:$AX13) -> 100960.8 | BA13: =SUMPRODUCT((YEAR($C$2:$AX$2)=BA$2)*$C13:$AX13) -> 176681.4 | BB13: =SUMPRODUCT((YEAR($C$2:$AX$2)=BB$2)*$C13:$AX13) -> 225878.4 | BC13: =SUMPRODUCT((YEAR($C$2:$AX$2)=BC$2)*$C13:$AX13) -> 270369.6
B14: Contractors | C14: =Personnel!F22 -> 450 | D14: =Personnel!G22 -> 450 | E14: =Personnel!H22 -> 450 | F14: =Personnel!I22 -> 450 | G14: =Personnel!J22 -> 450 | H14: =Personnel!K22 -> 450 | I14: =Personnel!L22 -> 450 | J14: =Personnel!M22 -> 450 | ... AX14: =Personnel!BA22 -> 450 | AZ14: =SUMPRODUCT((YEAR($C$2:$AX$2)=AZ$2)*$C14:$AX14) -> 5400 | BA14: =SUMPRODUCT((YEAR($C$2:$AX$2)=BA$2)*$C14:$AX14) -> 5400 | BB14: =SUMPRODUCT((YEAR($C$2:$AX$2)=BB$2)*$C14:$AX14) -> 5400 | BC14: =SUMPRODUCT((YEAR($C$2:$AX$2)=BC$2)*$C14:$AX14) -> 5400
B15: Strategic Advisory costs | C15: 0 | D15: 0 | E15: 0 | F15: 0 | G15: 0 | H15: 0 | I15: 0 | J15: 0 | K15: 0 | L15: 0 | M15: 0 | N15: 0 | O15: 0 | P15: 0 | Q15: 0 | R15: 0 | S15: 0 | T15: 0 | U15: 0 | V15: 0 | W15: 0 | X15: 0 | Y15: 0 | Z15: 0 | AA15: 0 | AB15: 0 | AC15: 0 | AD15: 0 | AE15: 0 | AF15: 0 | AG15: 0 | AH15: 0 | AI15: 0 | AJ15: 0 | AK15: 0 | AL15: 0 | AM15: 0 | AN15: 0 | AO15: 0 | AP15: 0 | AQ15: 0 | AR15: 0 | AS15: 0 | AT15: 0 | AU15: 0 | AV15: 0 | AW15: 0 | AX15: 0 | AZ15: =SUMPRODUCT((YEAR($C$2:$AX$2)=AZ$2)*$C15:$AX15) -> 0 | BA15: =SUMPRODUCT((YEAR($C$2:$AX$2)=BA$2)*$C15:$AX15) -> 0 | BB15: =SUMPRODUCT((YEAR($C$2:$AX$2)=BB$2)*$C15:$AX15) -> 0 | BC15: =SUMPRODUCT((YEAR($C$2:$AX$2)=BC$2)*$C15:$AX15) -> 0
B16: Other people costs | C16: =Personnel!F23 -> 267 | D16: =Personnel!G23 -> 267 | E16: =Personnel!H23 -> 267 | F16: =Personnel!I23 -> 267 | G16: =Personnel!J23 -> 267 | H16: =Personnel!K23 -> 267 | I16: =Personnel!L23 -> 267 | J16: =Personnel!M23 -> 267 | ... AX16: =Personnel!BA23 -> 267 | AZ16: =SUMPRODUCT((YEAR($C$2:$AX$2)=AZ$2)*$C16:$AX16) -> 3204 | BA16: =SUMPRODUCT((YEAR($C$2:$AX$2)=BA$2)*$C16:$AX16) -> 3204 | BB16: =SUMPRODUCT((YEAR($C$2:$AX$2)=BB$2)*$C16:$AX16) -> 3204 | BC16: =SUMPRODUCT((YEAR($C$2:$AX$2)=BC$2)*$C16:$AX16) -> 3204
B17: Total personnel | C17: =SUM(C11:C16) -> 39704.4 | D17: =SUM(D11:D16) -> 43560 | E17: =SUM(E11:E16) -> 43560 | F17: =SUM(F11:F16) -> 47415.6 | G17: =SUM(G11:G16) -> 47415.6 | H17: =SUM(H11:H16) -> 50014.35 | I17: =SUM(I11:I16) -> 50014.35 | J17: =SUM(J11:J16) -> 53864.35 | ... AX17: =SUM(AX11:AX16) -> 620438.93 | AZ17: =SUMPRODUCT((YEAR($C$2:$AX$2)=AZ$2)*$C17:$AX17) -> 591006.05 | BA17: =SUMPRODUCT((YEAR($C$2:$AX$2)=BA$2)*$C17:$AX17) -> 1217230.6 | BB17: =SUMPRODUCT((YEAR($C$2:$AX$2)=BB$2)*$C17:$AX17) -> 2660857.5 | BC17: =SUMPRODUCT((YEAR($C$2:$AX$2)=BC$2)*$C17:$AX17) -> 5940347.2
B19: Gross profit | C19: =C8-C17 -> -28610.65 | D19: =D8-D17 -> -21372.5 | E19: =E8-E17 -> -10278.75 | F19: =F8-F17 -> -3040.6 | G19: =G8-G17 -> 8053.15 | H19: =H8-H17 -> 13032.525 | I19: =I8-I17 -> 14282.525 | J19: =J8-J17 -> 19807.525 | ... AX19: =AX8-AX17 -> 878350.14 | AZ19: =SUMPRODUCT((YEAR($C$2:$AX$2)=AZ$2)*$C19:$AX19) -> 71103.325 | BA19: =SUMPRODUCT((YEAR($C$2:$AX$2)=BA$2)*$C19:$AX19) -> 897069.4 | BB19: =SUMPRODUCT((YEAR($C$2:$AX$2)=BB$2)*$C19:$AX19) -> 3233111.8 | BC19: =SUMPRODUCT((YEAR($C$2:$AX$2)=BC$2)*$C19:$AX19) -> 8267952.1
B21: Other OPEX
B22: Rent | C22: =OPEX!F7 -> 3600 | D22: =OPEX!G7 -> 4200 | E22: =OPEX!H7 -> 4200 | F22: =OPEX!I7 -> 4800 | G22: =OPEX!J7 -> 4800 | H22: =OPEX!K7 -> 4800 | I22: =OPEX!L7 -> 4800 | J22: =OPEX!M7 -> 4800 | ... AX22: =OPEX!BA7 -> 12000 | AZ22: =SUMPRODUCT((YEAR($C$2:$AX$2)=AZ$2)*$C22:$AX22) -> 55200 | BA22: =SUMPRODUCT((YEAR($C$2:$AX$2)=BA$2)*$C22:$AX22) -> 92400 | BB22: =SUMPRODUCT((YEAR($C$2:$AX$2)=BB$2)*$C22:$AX22) -> 116400 | BC22: =SUMPRODUCT((YEAR($C$2:$AX$2)=BC$2)*$C22:$AX22) -> 138000
B23: Software | C23: =OPEX!F8 -> 2303.3333 | D23: =OPEX!G8 -> 2423.3333 | E23: =OPEX!H8 -> 2423.3333 | F23: =OPEX!I8 -> 2543.3333 | G23: =OPEX!J8 -> 2543.3333 | H23: =OPEX!K8 -> 2543.3333 | I23: =OPEX!L8 -> 2543.3333 | J23: =OPEX!M8 -> 2543.3333 | ... AX23: =OPEX!BA8 -> 3983.3333 | AZ23: =SUMPRODUCT((YEAR($C$2:$AX$2)=AZ$2)*$C23:$AX23) -> 30040 | BA23: =SUMPRODUCT((YEAR($C$2:$AX$2)=BA$2)*$C23:$AX23) -> 37480 | BB23: =SUMPRODUCT((YEAR($C$2:$AX$2)=BB$2)*$C23:$AX23) -> 42280 | BC23: =SUMPRODUCT((YEAR($C$2:$AX$2)=BC$2)*$C23:$AX23) -> 46600
B24: Office | C24: =OPEX!F9 -> 240 | D24: =OPEX!G9 -> 280 | E24: =OPEX!H9 -> 280 | F24: =OPEX!I9 -> 320 | G24: =OPEX!J9 -> 320 | H24: =OPEX!K9 -> 320 | I24: =OPEX!L9 -> 320 | J24: =OPEX!M9 -> 320 | ... AX24: =OPEX!BA9 -> 800 | AZ24: =SUMPRODUCT((YEAR($C$2:$AX$2)=AZ$2)*$C24:$AX24) -> 3680 | BA24: =SUMPRODUCT((YEAR($C$2:$AX$2)=BA$2)*$C24:$AX24) -> 6160 | BB24: =SUMPRODUCT((YEAR($C$2:$AX$2)=BB$2)*$C24:$AX24) -> 7760 | BC24: =SUMPRODUCT((YEAR($C$2:$AX$2)=BC$2)*$C24:$AX24) -> 9200
B25: Marketing & Sales | C25: =OPEX!F10 -> 2000 | D25: =OPEX!G10 -> 2000 | E25: =OPEX!H10 -> 2000 | F25: =OPEX!I10 -> 2000 | G25: =OPEX!J10 -> 2000 | H25: =OPEX!K10 -> 2000 | I25: =OPEX!L10 -> 2000 | J25: =OPEX!M10 -> 2000 | ... AX25: =OPEX!BA10 -> 2000 | AZ25: =SUMPRODUCT((YEAR($C$2:$AX$2)=AZ$2)*$C25:$AX25) -> 24000 | BA25: =SUMPRODUCT((YEAR($C$2:$AX$2)=BA$2)*$C25:$AX25) -> 24000 | BB25: =SUMPRODUCT((YEAR($C$2:$AX$2)=BB$2)*$C25:$AX25) -> 24000 | BC25: =SUMPRODUCT((YEAR($C$2:$AX$2)=BC$2)*$C25:$AX25) -> 24000
B26: Travel | C26: =OPEX!F11 -> 500 | D26: =OPEX!G11 -> 500 | E26: =OPEX!H11 -> 500 | F26: =OPEX!I11 -> 500 | G26: =OPEX!J11 -> 500 | H26: =OPEX!K11 -> 500 | I26: =OPEX!L11 -> 500 | J26: =OPEX!M11 -> 500 | ... AX26: =OPEX!BA11 -> 500 | AZ26: =SUMPRODUCT((YEAR($C$2:$AX$2)=AZ$2)*$C26:$AX26) -> 6000 | BA26: =SUMPRODUCT((YEAR($C$2:$AX$2)=BA$2)*$C26:$AX26) -> 6000 | BB26: =SUMPRODUCT((YEAR($C$2:$AX$2)=BB$2)*$C26:$AX26) -> 6000 | BC26: =SUMPRODUCT((YEAR($C$2:$AX$2)=BC$2)*$C26:$AX26) -> 6000
B27: SG&A | C27: =OPEX!F12 -> 600 | D27: =OPEX!G12 -> 700 | E27: =OPEX!H12 -> 700 | F27: =OPEX!I12 -> 800 | G27: =OPEX!J12 -> 800 | H27: =OPEX!K12 -> 800 | I27: =OPEX!L12 -> 800 | J27: =OPEX!M12 -> 800 | ... AX27: =OPEX!BA12 -> 2000 | AZ27: =SUMPRODUCT((YEAR($C$2:$AX$2)=AZ$2)*$C27:$AX27) -> 9200 | BA27: =SUMPRODUCT((YEAR($C$2:$AX$2)=BA$2)*$C27:$AX27) -> 15400 | BB27: =SUMPRODUCT((YEAR($C$2:$AX$2)=BB$2)*$C27:$AX27) -> 19400 | BC27: =SUMPRODUCT((YEAR($C$2:$AX$2)=BC$2)*$C27:$AX27) -> 23000
B28: Other | C28: =OPEX!F13 -> 140 | D28: =OPEX!G13 -> 140 | E28: =OPEX!H13 -> 140 | F28: =OPEX!I13 -> 140 | G28: =OPEX!J13 -> 140 | H28: =OPEX!K13 -> 140 | I28: =OPEX!L13 -> 140 | J28: =OPEX!M13 -> 140 | ... AX28: =OPEX!BA13 -> 140 | AZ28: =SUMPRODUCT((YEAR($C$2:$AX$2)=AZ$2)*$C28:$AX28) -> 1680 | BA28: =SUMPRODUCT((YEAR($C$2:$AX$2)=BA$2)*$C28:$AX28) -> 1680 | BB28: =SUMPRODUCT((YEAR($C$2:$AX$2)=BB$2)*$C28:$AX28) -> 1680 | BC28: =SUMPRODUCT((YEAR($C$2:$AX$2)=BC$2)*$C28:$AX28) -> 1680
B29: Total other OPEX | C29: =SUM(C22:C28) -> 9383.3333 | D29: =SUM(D22:D28) -> 10243.333 | E29: =SUM(E22:E28) -> 10243.333 | F29: =SUM(F22:F28) -> 11103.333 | G29: =SUM(G22:G28) -> 11103.333 | H29: =SUM(H22:H28) -> 11103.333 | I29: =SUM(I22:I28) -> 11103.333 | J29: =SUM(J22:J28) -> 11103.333 | ... AX29: =SUM(AX22:AX28) -> 21423.333 | AZ29: =SUMPRODUCT((YEAR($C$2:$AX$2)=AZ$2)*$C29:$AX29) -> 129800 | BA29: =SUMPRODUCT((YEAR($C$2:$AX$2)=BA$2)*$C29:$AX29) -> 183120 | BB29: =SUMPRODUCT((YEAR($C$2:$AX$2)=BB$2)*$C29:$AX29) -> 217520 | BC29: =SUMPRODUCT((YEAR($C$2:$AX$2)=BC$2)*$C29:$AX29) -> 248480
B31: RX allocation | C31: =OPEX!F14 -> 1307 | D31: =OPEX!G14 -> 1307 | E31: =OPEX!H14 -> 1307 | F31: =OPEX!I14 -> 1307 | G31: =OPEX!J14 -> 1307 | H31: =OPEX!K14 -> 1307 | I31: =OPEX!L14 -> 1307 | J31: =OPEX!M14 -> 1307 | ... AX31: =OPEX!BA14 -> 1307 | AZ31: =SUMPRODUCT((YEAR($C$2:$AX$2)=AZ$2)*$C31:$AX31) -> 15684 | BA31: =SUMPRODUCT((YEAR($C$2:$AX$2)=BA$2)*$C31:$AX31) -> 15684 | BB31: =SUMPRODUCT((YEAR($C$2:$AX$2)=BB$2)*$C31:$AX31) -> 15684 | BC31: =SUMPRODUCT((YEAR($C$2:$AX$2)=BC$2)*$C31:$AX31) -> 15684
B33: Total costs | C33: =C17+C29+C31 -> 50394.733 | D33: =D17+D29+D31 -> 55110.333 | E33: =E17+E29+E31 -> 55110.333 | F33: =F17+F29+F31 -> 59825.933 | G33: =G17+G29+G31 -> 59825.933 | H33: =H17+H29+H31 -> 62424.683 | I33: =I17+I29+I31 -> 62424.683 | J33: =J17+J29+J31 -> 66274.683 | ... AX33: =AX17+AX29+AX31 -> 643169.26 | AZ33: =SUMPRODUCT((YEAR($C$2:$AX$2)=AZ$2)*$C33:$AX33) -> 736490.05 | BA33: =SUMPRODUCT((YEAR($C$2:$AX$2)=BA$2)*$C33:$AX33) -> 1416034.6 | BB33: =SUMPRODUCT((YEAR($C$2:$AX$2)=BB$2)*$C33:$AX33) -> 2894061.5 | BC33: =SUMPRODUCT((YEAR($C$2:$AX$2)=BC$2)*$C33:$AX33) -> 6204511.2
B35: EBITDA (total) | C35: =C8-C33 -> -39300.983 | D35: =D8-D33 -> -32922.833 | E35: =E8-E33 -> -21829.083 | F35: =F8-F33 -> -15450.933 | G35: =G8-G33 -> -4357.1833 | H35: =H8-H33 -> 622.19167 | I35: =I8-I33 -> 1872.1917 | J35: =J8-J33 -> 7397.1917 | ... AX35: =AX8-AX33 -> 855619.8 | AZ35: =SUMPRODUCT((YEAR($C$2:$AX$2)=AZ$2)*$C35:$AX35) -> -74380.675 | BA35: =SUMPRODUCT((YEAR($C$2:$AX$2)=BA$2)*$C35:$AX35) -> 698265.4 | BB35: =SUMPRODUCT((YEAR($C$2:$AX$2)=BB$2)*$C35:$AX35) -> 2999907.8 | BC35: =SUMPRODUCT((YEAR($C$2:$AX$2)=BC$2)*$C35:$AX35) -> 8003788.1
B36: EBITDA margin (total) | C36: =IF(C8=0,0,C35/C8) -> -3.5426239 | D36: =IF(D8=0,0,D35/D8) -> -1.483846 | E36: =IF(E8=0,0,E35/E8) -> -0.65589734 | F36: =IF(F8=0,0,F35/F8) -> -0.34819005 | G36: =IF(G8=0,0,G35/G8) -> -0.078552038 | H36: =IF(H8=0,0,H35/H8) -> 0.0098687154 | I36: =IF(I8=0,0,I35/I8) -> 0.029117926 | J36: =IF(J8=0,0,J35/J8) -> 0.10040727 | ... AX36: =IF(AX8=0,0,AX35/AX8) -> 0.57087406 | AZ36: =IF(AZ8=0,0,AZ35/AZ8) -> -0.11233895 | BA36: =IF(BA8=0,0,BA35/BA8) -> 0.33025843 | BB36: =IF(BB8=0,0,BB35/BB8) -> 0.5089792 | BC36: =IF(BC8=0,0,BC35/BC8) -> 0.56331781
B38: EBITDA (without success fee) | C38: =C5-C33+C12 -> -38561.4 | D38: =D5-D33+D12 -> -31443.667 | E38: =E5-E33+E12 -> -19610.333 | F38: =F5-F33+F12 -> -12492.6 | G38: =G5-G33+G12 -> -659.26667 | H38: =H5-H33+H12 -> 674.06667 | I38: =I5-I33+I12 -> 2007.4 | J38: =J5-J33+J12 -> 2007.4 | ... AX38: =AX5-AX33+AX12 -> 144892.2 | AZ38: =SUMPRODUCT((YEAR($C$2:$AX$2)=AZ$2)*$C38:$AX38) -> -90048.8 | BA38: =SUMPRODUCT((YEAR($C$2:$AX$2)=BA$2)*$C38:$AX38) -> 324143.93 | BB38: =SUMPRODUCT((YEAR($C$2:$AX$2)=BB$2)*$C38:$AX38) -> 925850.27 | BC38: =SUMPRODUCT((YEAR($C$2:$AX$2)=BC$2)*$C38:$AX38) -> 1565619.1
B39: EBITDA margin (without success fee) | C39: =IF(C5=0,0,C38/C5) -> -3.2587099 | D39: =IF(D5=0,0,D38/D5) -> -1.3286056 | E39: =IF(E5=0,0,E38/E5) -> -0.55240376 | F39: =IF(F5=0,0,F38/F5) -> -0.26392817 | G39: =IF(G5=0,0,G38/G5) -> -0.011142535 | H39: =IF(H5=0,0,H38/H5) -> 0.011141598 | I39: =IF(I5=0,0,I38/I5) -> 0.03246469 | J39: =IF(J5=0,0,J38/J5) -> 0.03246469 | ... AX39: =IF(AX5=0,0,AX38/AX5) -> 0.51639632 | AZ39: =IF(AZ5=0,0,AZ38/AZ5) -> -0.14786338 | BA39: =IF(BA5=0,0,BA38/BA5) -> 0.22863533 | BB39: =IF(BB5=0,0,BB38/BB5) -> 0.40687117 | BC39: =IF(BC5=0,0,BC38/BC5) -> 0.4975342

Sheet Parameters
A1: Revenues
A2: Retainer
A3: Growth | B3: 7000
A4: Avg contract length (months) | B4: 5 | E4: =((2*12)+(3*5))/5 -> 7.8
A6: M&A | B6: 8000
A7: Avg contract length (months) | B7: 7
A9: Success fee (avg;%) | B9: % | C9: Ticket/EV
A10: Growth | B10: 0.01
A11: Growth | C11: 3000000
A12: M&A | B12: 0.01
A13: M&A | C13: 10000000
A15: Labour Costs | B15: Total | C15: Base | D15: Annual gross + holiday | E15: Holiday pay | F15: Ermpolyer tax rate
A16: Rob | C16: 10000 | D16: =(C16*12)+E16 -> 129600 | E16: =8%*(C16*12) -> 9600 | F16: 0.19
A17: Simon | B17: =D17*(1+F17)/12 -> 8353.8 | C17: 6500 | D17: =(C17*12)+E17 -> 84240 | E17: =8%*(C17*12) -> 6240 | F17: 0.19
A18: FTE Associate | B18: =D18*(1+F18)/12 -> 5783.4 | C18: 4500 | D18: =(C18*12)+E18 -> 58320 | E18: =8%*(C18*12) -> 4320 | F18: 0.19
A19: FTE Analyst | B19: =D19*(1+F19)/12 -> 3855.6 | C19: 3000 | D19: =C19*12*(1.08) -> 38880 | E19: =8%*(C19*12) -> 2880 | F19: 0.19
A20: Intern | B20: 500
A23: All other OPEX | B23: Total | C23: Price | D23: Quantity
A24: Software
A25: Database (total, not by FTE) | B25: =PRODUCT(C25:D25) -> 1583.3333 | C25: =19000/12 -> 1583.3333 | D25: 1
A26: Hubspot: Sales (total, not by FTE) | B26: =PRODUCT(C26:D26) -> 180 | C26: 90 | D26: 2
A27: Hubspot: Basic (total, not by FTE) | B27: =PRODUCT(C27:D27) -> 220 | C27: 44 | D27: 5
A28: Lemlist: Multi channel | B28: =PRODUCT(C28:D28) -> 495 | C28: 99 | D28: 5
A29: OpenAI (chatGPT) | B29: =PRODUCT(C29:D29) -> 105 | C29: 21 | D29: 5
A30: Claude | B30: =PRODUCT(C30:D30) -> 105 | C30: 21 | D30: 5
A31: Framer | B31: =PRODUCT(C31:D31) -> 30 | C31: 30 | D31: 1
A32: Google suite; Biz Standard (Everyone; Evolute) | B32: =PRODUCT(C32:D32) -> 102 | C32: 17 | D32: 6
A33: Google business starter (Evolute 2) | B33: =PRODUCT(C33:D33) -> 18 | C33: 9 | D33: 2
D34: 1
D35: 1
A36: TOTAL | B36: =sum(B25:B35) -> 2838.3333
A38: Office
A39: Rent | B39: 3762 | D39: 1
A40: Food | B40: =PRODUCT(C40:D40) -> 600 | C40: =5*20 -> 100 | D40: 6
A41: Desks
A42: Chair
A43: Computers | B43: =PRODUCT(C43:D43) -> 240 | C43: 40 | D43: 6
A44: Parking | B44: 450 | D44: 1
A47: FORECAST DRIVERS (2027–2030)
C48: 2027 | D48: 2028 | E48: 2029 | F48: 2030
...

Sheet Commercials Forecast
B2: Commercials Forecast — Monthly 2027–2030 (€, revenue only)
E3: Unit | F3: 46388 | G3: 46419 | H3: 46447 | I3: 46478 | J3: 46508 | K3: 46539 | L3: 46569 | M3: 46600 | N3: 46631 | O3: 46661 | P3: 46692 | Q3: 46722 | R3: 46753 | S3: 46784 | T3: 46813 | U3: 46844 | V3: 46874 | W3: 46905 | X3: 46935 | Y3: 46966 | Z3: 46997 | AA3: 47027 | AB3: 47058 | AC3: 47088 | AD3: 47119 | AE3: 47150 | AF3: 47178 | AG3: 47209 | AH3: 47239 | AI3: 47270 | AJ3: 47300 | AK3: 47331 | AL3: 47362 | AM3: 47392 | AN3: 47423 | AO3: 47453 | AP3: 47484 | AQ3: 47515 | AR3: 47543 | AS3: 47574 | AT3: 47604 | AU3: 47635 | AV3: 47665 | AW3: 47696 | AX3: 47727 | AY3: 47757 | AZ3: 47788 | BA3: 47818 | BC3: 2027 | BD3: 2028 | BE3: 2029 | BF3: 2030
B6: GROWTH CAPITAL
B7: New deals started | E7: # | F7: {=INDEX(Parameters!$C$49:$F$49,MATCH(YEAR(F$3),Parameters!$C$48:$F$48,0))*INDEX(Parameters!$C$50:$F$50,MATCH(YEAR(F$3),Parameters!$C$48:$F$48,0))/12} -> 1.5 | G7: {=INDEX(Parameters!$C$49:$F$49,MATCH(YEAR(G$3),Parameters!$C$48:$F$48,0))*INDEX(Parameters!$C$50:$F$50,MATCH(YEAR(G$3),Parameters!$C$48:$F$48,0))/12} -> 1.5 | H7: {=INDEX(Parameters!$C$49:$F$49,MATCH(YEAR(H$3),Parameters!$C$48:$F$48,0))*INDEX(Parameters!$C$50:$F$50,MATCH(YEAR(H$3),Parameters!$C$48:$F$48,0))/12} -> 1.5 | I7: {=INDEX(Parameters!$C$49:$F$49,MATCH(YEAR(I$3),Parameters!$C$48:$F$48,0))*INDEX(Parameters!$C$50:$F$50,MATCH(YEAR(I$3),Parameters!$C$48:$F$48,0))/12} -> 1.5 | J7: {=INDEX(Parameters!$C$49:$F$49,MATCH(YEAR(J$3),Parameters!$C$48:$F$48,0))*INDEX(Parameters!$C$50:$F$50,MATCH(YEAR(J$3),Parameters!$C$48:$F$48,0))/12} -> 1.5 | K7: {=INDEX(Parameters!$C$49:$F$49,MATCH(YEAR(K$3),Parameters!$C$48:$F$48,0))*INDEX(Parameters!$C$50:$F$50,MATCH(YEAR(K$3),Parameters!$C$48:$F$48,0))/12} -> 1.5 | L7: {=INDEX(Parameters!$C$49:$F$49,MATCH(YEAR(L$3),Parameters!$C$48:$F$48,0))*INDEX(Parameters!$C$50:$F$50,MATCH(YEAR(L$3),Parameters!$C$48:$F$48,0))/12} -> 1.5 | M7: {=INDEX(Parameters!$C$49:$F$49,MATCH(YEAR(M$3),Parameters!$C$48:$F$48,0))*INDEX(Parameters!$C$50:$F$50,MATCH(YEAR(M$3),Parameters!$C$48:$F$48,0))/12} -> 1.5 | ... BA7: {=INDEX(Parameters!$C$49:$F$49,MATCH(YEAR(BA$3),Parameters!$C$48:$F$48,0))*INDEX(Parameters!$C$50:$F$50,MATCH(YEAR(BA$3),Parameters!$C$48:$F$48,0))/12} -> 3.0833333 | BC7: =SUMPRODUCT((YEAR($F$3:$BA$3)=BC$3)*$F7:$BA7) -> 18 | BD7: =SUMPRODUCT((YEAR($F$3:$BA$3)=BD$3)*$F7:$BA7) -> 30.8 | BE7: =SUMPRODUCT((YEAR($F$3:$BA$3)=BE$3)*$F7:$BA7) -> 36.54 | BF7: =SUMPRODUCT((YEAR($F$3:$BA$3)=BF$3)*$F7:$BA7) -> 37
B8: Live projects | E8: # | F8: =SUM(F7) -> 1.5 | G8: =SUM(F7:G7) -> 3 | H8: =SUM(F7:H7) -> 4.5 | I8: =SUM(F7:I7) -> 6 | J8: =SUM(F7:J7) -> 7.5 | K8: =SUM(G7:K7) -> 7.5 | L8: =SUM(H7:L7) -> 7.5 | M8: =SUM(I7:M7) -> 7.5 | N8: =SUM(J7:N7) -> 7.5 | O8: =SUM(K7:O7) -> 7.5 | P8: =SUM(L7:P7) -> 7.5 | Q8: =SUM(M7:Q7) -> 7.5 | ... BA8: =SUM(AW7:BA7) -> 15.416667 | BC8: =SUMPRODUCT((YEAR($F$3:$BA$3)=BC$3)*$F8:$BA8)/12 -> 6.25 | BD8: =SUMPRODUCT((YEAR($F$3:$BA$3)=BD$3)*$F8:$BA8)/12 -> 11.944444 | BE8: =SUMPRODUCT((YEAR($F$3:$BA$3)=BE$3)*$F8:$BA8)/12 -> 14.826389 | BF8: =SUMPRODUCT((YEAR($F$3:$BA$3)=BF$3)*$F8:$BA8)/12 -> 15.384722
B9: Retainer revenue | E9: € | F9: =F8*Parameters!$B$3 -> 10500 | G9: =G8*Parameters!$B$3 -> 21000 | H9: =H8*Parameters!$B$3 -> 31500 | I9: =I8*Parameters!$B$3 -> 42000 | J9: =J8*Parameters!$B$3 -> 52500 | K9: =K8*Parameters!$B$3 -> 52500 | L9: =L8*Parameters!$B$3 -> 52500 | M9: =M8*Parameters!$B$3 -> 52500 | ... BA9: =BA8*Parameters!$B$3 -> 107916.67 | BC9: =SUMPRODUCT((YEAR($F$3:$BA$3)=BC$3)*$F9:$BA9) -> 525000 | BD9: =SUMPRODUCT((YEAR($F$3:$BA$3)=BD$3)*$F9:$BA9) -> 1003333.3 | BE9: =SUMPRODUCT((YEAR($F$3:$BA$3)=BE$3)*$F9:$BA9) -> 1245416.7 | BF9: =SUMPRODUCT((YEAR($F$3:$BA$3)=BF$3)*$F9:$BA9) -> 1292316.7
B10: Deals closed | E10: # | F10: 0 | G10: 0 | H10: 0 | I10: 0 | J10: 0 | K10: {=F7*INDEX(Parameters!$C$52:$F$52,MATCH(YEAR(K$3),Parameters!$C$48:$F$48,0))} -> 0.225 | L10: {=G7*INDEX(Parameters!$C$52:$F$52,MATCH(YEAR(L$3),Parameters!$C$48:$F$48,0))} -> 0.225 | M10: {=H7*INDEX(Parameters!$C$52:$F$52,MATCH(YEAR(M$3),Parameters!$C$48:$F$48,0))} -> 0.225 | N10: {=I7*INDEX(Parameters!$C$52:$F$52,MATCH(YEAR(N$3),Parameters!$C$48:$F$48,0))} -> 0.225 | O10: {=J7*INDEX(Parameters!$C$52:$F$52,MATCH(YEAR(O$3),Parameters!$C$48:$F$48,0))} -> 0.225 | P10: {=K7*INDEX(Parameters!$C$52:$F$52,MATCH(YEAR(P$3),Parameters!$C$48:$F$48,0))} -> 0.225 | Q10: {=L7*INDEX(Parameters!$C$52:$F$52,MATCH(YEAR(Q$3),Parameters!$C$48:$F$48,0))} -> 0.225 | R10: {=M7*INDEX(Parameters!$C$52:$F$52,MATCH(YEAR(R$3),Parameters!$C$48:$F$48,0))} -> 0.27 | ... BA10: {=AV7*INDEX(Parameters!$C$52:$F$52,MATCH(YEAR(BA$3),Parameters!$C$48:$F$48,0))} -> 0.77083333 | BC10: =SUMPRODUCT((YEAR($F$3:$BA$3)=BC$3)*$F10:$BA10) -> 1.575 | BD10: =SUMPRODUCT((YEAR($F$3:$BA$3)=BD$3)*$F10:$BA10) -> 4.584 | BE10: =SUMPRODUCT((YEAR($F$3:$BA$3)=BE$3)*$F10:$BA10) -> 7.5126333 | BF10: =SUMPRODUCT((YEAR($F$3:$BA$3)=BF$3)*$F10:$BA10) -> 9.2020833
B11: Success fees | E11: € | F11: =F10*(Parameters!$C$11*Parameters!$B$10) -> 0 | G11: =G10*(Parameters!$C$11*Parameters!$B$10) -> 0 | H11: =H10*(Parameters!$C$11*Parameters!$B$10) -> 0 | I11: =I10*(Parameters!$C$11*Parameters!$B$10) -> 0 | J11: =J10*(Parameters!$C$11*Parameters!$B$10) -> 0 | K11: =K10*(Parameters!$C$11*Parameters!$B$10) -> 6750 | L11: =L10*(Parameters!$C$11*Parameters!$B$10) -> 6750 | M11: =M10*(Parameters!$C$11*Parameters!$B$10) -> 6750 | ... BA11: =BA10*(Parameters!$C$11*Parameters!$B$10) -> 23125 | BC11: =SUMPRODUCT((YEAR($F$3:$BA$3)=BC$3)*$F11:$BA11) -> 47250 | BD11: =SUMPRODUCT((YEAR($F$3:$BA$3)=BD$3)*$F11:$BA11) -> 137520 | BE11: =SUMPRODUCT((YEAR($F$3:$BA$3)=BE$3)*$F11:$BA11) -> 225379 | BF11: =SUMPRODUCT((YEAR($F$3:$BA$3)=BF$3)*$F11:$BA11) -> 276062.5
B12: Total Growth revenue | E12: € | F12: =F9+F11 -> 10500 | G12: =G9+G11 -> 21000 | H12: =H9+H11 -> 31500 | I12: =I9+I11 -> 42000 | J12: =J9+J11 -> 52500 | K12: =K9+K11 -> 59250 | L12: =L9+L11 -> 59250 | M12: =M9+M11 -> 59250 | ... BA12: =BA9+BA11 -> 131041.67 | BC12: =SUMPRODUCT((YEAR($F$3:$BA$3)=BC$3)*$F12:$BA12) -> 572250 | BD12: =SUMPRODUCT((YEAR($F$3:$BA$3)=BD$3)*$F12:$BA12) -> 1140853.3 | BE12: =SUMPRODUCT((YEAR($F$3:$BA$3)=BE$3)*$F12:$BA12) -> 1470795.7 | BF12: =SUMPRODUCT((YEAR($F$3:$BA$3)=BF$3)*$F12:$BA12) -> 1568379.2
B14: M&A
B15: New deals started | E15: # | F15: {=INDEX(Parameters!$C$49:$F$49,MATCH(YEAR(F$3),Parameters!$C$48:$F$48,0))*(1-INDEX(Parameters!$C$50:$F$50,MATCH(YEAR(F$3),Parameters!$C$48:$F$48,0)))/12} -> 0.16666667 | G15: {=INDEX(Parameters!$C$49:$F$49,MATCH(YEAR(G$3),Parameters!$C$48:$F$48,0))*(1-INDEX(Parameters!$C$50:$F$50,MATCH(YEAR(G$3),Parameters!$C$48:$F$48,0)))/12} -> 0.16666667 | H15: {=INDEX(Parameters!$C$49:$F$49,MATCH(YEAR(H$3),Parameters!$C$48:$F$48,0))*(1-INDEX(Parameters!$C$50:$F$50,MATCH(YEAR(H$3),Parameters!$C$48:$F$48,0)))/12} -> 0.16666667 | I15: {=INDEX(Parameters!$C$49:$F$49,MATCH(YEAR(I$3),Parameters!$C$48:$F$48,0))*(1-INDEX(Parameters!$C$50:$F$50,MATCH(YEAR(I$3),Parameters!$C$48:$F$48,0)))/12} -> 0.16666667 | J15: {=INDEX(Parameters!$C$49:$F$49,MATCH(YEAR(J$3),Parameters!$C$48:$F$48,0))*(1-INDEX(Parameters!$C$50:$F$50,MATCH(YEAR(J$3),Parameters!$C$48:$F$48,0)))/12} -> 0.16666667 | K15: {=INDEX(Parameters!$C$49:$F$49,MATCH(YEAR(K$3),Parameters!$C$48:$F$48,0))*(1-INDEX(Parameters!$C$50:$F$50,MATCH(YEAR(K$3),Parameters!$C$48:$F$48,0)))/12} -> 0.16666667 | L15: {=INDEX(Parameters!$C$49:$F$49,MATCH(YEAR(L$3),Parameters!$C$48:$F$48,0))*(1-INDEX(Parameters!$C$50:$F$50,MATCH(YEAR(L$3),Parameters!$C$48:$F$48,0)))/12} -> 0.16666667 | M15: {=INDEX(Parameters!$C$49:$F$49,MATCH(YEAR(M$3),Parameters!$C$48:$F$48,0))*(1-INDEX(Parameters!$C$50:$F$50,MATCH(YEAR(M$3),Parameters!$C$48:$F$48,0)))/12} -> 0.16666667 | ... BA15: {=INDEX(Parameters!$C$49:$F$49,MATCH(YEAR(BA$3),Parameters!$C$48:$F$48,0))*(1-INDEX(Parameters!$C$50:$F$50,MATCH(YEAR(BA$3),Parameters!$C$48:$F$48,0)))/12} -> 3.0833333 | BC15: =SUMPRODUCT((YEAR($F$3:$BA$3)=BC$3)*$F15:$BA15) -> 2 | BD15: =SUMPRODUCT((YEAR($F$3:$BA$3)=BD$3)*$F15:$BA15) -> 9.2 | BE15: =SUMPRODUCT((YEAR($F$3:$BA$3)=BE$3)*$F15:$BA15) -> 21.46 | BF15: =SUMPRODUCT((YEAR($F$3:$BA$3)=BF$3)*$F15:$BA15) -> 37
B16: Live projects | E16: # | F16: =SUM(F15) -> 0.16666667 | G16: =SUM(F15:G15) -> 0.33333333 | H16: =SUM(F15:H15) -> 0.5 | I16: =SUM(F15:I15) -> 0.66666667 | J16: =SUM(F15:J15) -> 0.83333333 | K16: =SUM(F15:K15) -> 1 | L16: =SUM(F15:L15) -> 1.1666667 | M16: =SUM(G15:M15) -> 1.1666667 | N16: =SUM(H15:N15) -> 1.1666667 | O16: =SUM(I15:O15) -> 1.1666667 | P16: =SUM(J15:P15) -> 1.1666667 | Q16: =SUM(K15:Q15) -> 1.1666667 | R16: =SUM(L15:R15) -> 1.7666667 | S16: =SUM(M15:S15) -> 2.3666667 | ... BA16: =SUM(AU15:BA15) -> 21.583333 | BC16: =SUMPRODUCT((YEAR($F$3:$BA$3)=BC$3)*$F16:$BA16)/12 -> 0.875 | BD16: =SUMPRODUCT((YEAR($F$3:$BA$3)=BD$3)*$F16:$BA16)/12 -> 4.3166667 | BE16: =SUMPRODUCT((YEAR($F$3:$BA$3)=BE$3)*$F16:$BA16)/12 -> 10.730417 | BF16: =SUMPRODUCT((YEAR($F$3:$BA$3)=BF$3)*$F16:$BA16)/12 -> 19.317083
B17: Retainer revenue | E17: € | F17: =F16*Parameters!$B$6 -> 1333.3333 | G17: =G16*Parameters!$B$6 -> 2666.6667 | H17: =H16*Parameters!$B$6 -> 4000 | I17: =I16*Parameters!$B$6 -> 5333.3333 | J17: =J16*Parameters!$B$6 -> 6666.6667 | K17: =K16*Parameters!$B$6 -> 8000 | L17: =L16*Parameters!$B$6 -> 9333.3333 | M17: =M16*Parameters!$B$6 -> 9333.3333 | ... BA17: =BA16*Parameters!$B$6 -> 172666.67 | BC17: =SUMPRODUCT((YEAR($F$3:$BA$3)=BC$3)*$F17:$BA17) -> 84000 | BD17: =SUMPRODUCT((YEAR($F$3:$BA$3)=BD$3)*$F17:$BA17) -> 414400 | BE17: =SUMPRODUCT((YEAR($F$3:$BA$3)=BE$3)*$F17:$BA17) -> 1030120 | BF17: =SUMPRODUCT((YEAR($F$3:$BA$3)=BF$3)*$F17:$BA17) -> 1854440
B18: Deals closed | E18: # | F18: 0 | G18: 0 | H18: 0 | I18: 0 | J18: 0 | K18: 0 | L18: 0 | M18: {=F15*INDEX(Parameters!$C$53:$F$53,MATCH(YEAR(M$3),Parameters!$C$48:$F$48,0))} -> 0.083333333 | N18: {=G15*INDEX(Parameters!$C$53:$F$53,MATCH(YEAR(N$3),Parameters!$C$48:$F$48,0))} -> 0.083333333 | O18: {=H15*INDEX(Parameters!$C$53:$F$53,MATCH(YEAR(O$3),Parameters!$C$48:$F$48,0))} -> 0.083333333 | P18: {=I15*INDEX(Parameters!$C$53:$F$53,MATCH(YEAR(P$3),Parameters!$C$48:$F$48,0))} -> 0.083333333 | Q18: {=J15*INDEX(Parameters!$C$53:$F$53,MATCH(YEAR(Q$3),Parameters!$C$48:$F$48,0))} -> 0.083333333 | R18: {=K15*INDEX(Parameters!$C$53:$F$53,MATCH(YEAR(R$3),Parameters!$C$48:$F$48,0))} -> 0.093333333 | S18: {=L15*INDEX(Parameters!$C$53:$F$53,MATCH(YEAR(S$3),Parameters!$C$48:$F$48,0))} -> 0.093333333 | T18: {=M15*INDEX(Parameters!$C$53:$F$53,MATCH(YEAR(T$3),Parameters!$C$48:$F$48,0))} -> 0.093333333 | ... BA18: {=AT15*INDEX(Parameters!$C$53:$F$53,MATCH(YEAR(BA$3),Parameters!$C$48:$F$48,0))} -> 2.1583333 | BC18: =SUMPRODUCT((YEAR($F$3:$BA$3)=BC$3)*$F18:$BA18) -> 0.41666667 | BD18: =SUMPRODUCT((YEAR($F$3:$BA$3)=BD$3)*$F18:$BA18) -> 2.8 | BE18: =SUMPRODUCT((YEAR($F$3:$BA$3)=BE$3)*$F18:$BA18) -> 9.01425 | BF18: =SUMPRODUCT((YEAR($F$3:$BA$3)=BF$3)*$F18:$BA18) -> 19.5545
B19: Success fees | E19: € | F19: {=F18*(INDEX(Parameters!$C$51:$F$51,MATCH(YEAR(F$3),Parameters!$C$48:$F$48,0))*Parameters!$B$12)} -> 0 | G19: {=G18*(INDEX(Parameters!$C$51:$F$51,MATCH(YEAR(G$3),Parameters!$C$48:$F$48,0))*Parameters!$B$12)} -> 0 | H19: {=H18*(INDEX(Parameters!$C$51:$F$51,MATCH(YEAR(H$3),Parameters!$C$48:$F$48,0))*Parameters!$B$12)} -> 0 | I19: {=I18*(INDEX(Parameters!$C$51:$F$51,MATCH(YEAR(I$3),Parameters!$C$48:$F$48,0))*Parameters!$B$12)} -> 0 | J19: {=J18*(INDEX(Parameters!$C$51:$F$51,MATCH(YEAR(J$3),Parameters!$C$48:$F$48,0))*Parameters!$B$12)} -> 0 | K19: {=K18*(INDEX(Parameters!$C$51:$F$51,MATCH(YEAR(K$3),Parameters!$C$48:$F$48,0))*Parameters!$B$12)} -> 0 | L19: {=L18*(INDEX(Parameters!$C$51:$F$51,MATCH(YEAR(L$3),Parameters!$C$48:$F$48,0))*Parameters!$B$12)} -> 0 | M19: {=M18*(INDEX(Parameters!$C$51:$F$51,MATCH(YEAR(M$3),Parameters!$C$48:$F$48,0))*Parameters!$B$12)} -> 10000 | ... BA19: {=BA18*(INDEX(Parameters!$C$51:$F$51,MATCH(YEAR(BA$3),Parameters!$C$48:$F$48,0))*Parameters!$B$12)} -> 1295000 | BC19: =SUMPRODUCT((YEAR($F$3:$BA$3)=BC$3)*$F19:$BA19) -> 50000 | BD19: =SUMPRODUCT((YEAR($F$3:$BA$3)=BD$3)*$F19:$BA19) -> 700000 | BE19: =SUMPRODUCT((YEAR($F$3:$BA$3)=BE$3)*$F19:$BA19) -> 3785985 | BF19: =SUMPRODUCT((YEAR($F$3:$BA$3)=BF$3)*$F19:$BA19) -> 11732700
B20: Total M&A revenue | E20: € | F20: =F17+F19 -> 1333.3333 | G20: =G17+G19 -> 2666.6667 | H20: =H17+H19 -> 4000 | I20: =I17+I19 -> 5333.3333 | J20: =J17+J19 -> 6666.6667 | K20: =K17+K19 -> 8000 | L20: =L17+L19 -> 9333.3333 | M20: =M17+M19 -> 19333.333 | ... BA20: =BA17+BA19 -> 1467666.7 | BC20: =SUMPRODUCT((YEAR($F$3:$BA$3)=BC$3)*$F20:$BA20) -> 134000 | BD20: =SUMPRODUCT((YEAR($F$3:$BA$3)=BD$3)*$F20:$BA20) -> 1114400 | BE20: =SUMPRODUCT((YEAR($F$3:$BA$3)=BE$3)*$F20:$BA20) -> 4816105 | BF20: =SUMPRODUCT((YEAR($F$3:$BA$3)=BF$3)*$F20:$BA20) -> 13587140
B22: TOTAL REVENUE
B23: Total retainer | E23: € | F23: =F9+F17 -> 11833.333 | G23: =G9+G17 -> 23666.667 | H23: =H9+H17 -> 35500 | I23: =I9+I17 -> 47333.333 | J23: =J9+J17 -> 59166.667 | K23: =K9+K17 -> 60500 | L23: =L9+L17 -> 61833.333 | M23: =M9+M17 -> 61833.333 | ... BA23: =BA9+BA17 -> 280583.33 | BC23: =SUMPRODUCT((YEAR($F$3:$BA$3)=BC$3)*$F23:$BA23) -> 609000 | BD23: =SUMPRODUCT((YEAR($F$3:$BA$3)=BD$3)*$F23:$BA23) -> 1417733.3 | BE23: =SUMPRODUCT((YEAR($F$3:$BA$3)=BE$3)*$F23:$BA23) -> 2275536.7 | BF23: =SUMPRODUCT((YEAR($F$3:$BA$3)=BF$3)*$F23:$BA23) -> 3146756.7
B24: Total success fees | E24: € | F24: =F11+F19 -> 0 | G24: =G11+G19 -> 0 | H24: =H11+H19 -> 0 | I24: =I11+I19 -> 0 | J24: =J11+J19 -> 0 | K24: =K11+K19 -> 6750 | L24: =L11+L19 -> 6750 | M24: =M11+M19 -> 16750 | ... BA24: =BA11+BA19 -> 1318125 | BC24: =SUMPRODUCT((YEAR($F$3:$BA$3)=BC$3)*$F24:$BA24) -> 97250 | BD24: =SUMPRODUCT((YEAR($F$3:$BA$3)=BD$3)*$F24:$BA24) -> 837520 | BE24: =SUMPRODUCT((YEAR($F$3:$BA$3)=BE$3)*$F24:$BA24) -> 4011364 | BF24: =SUMPRODUCT((YEAR($F$3:$BA$3)=BF$3)*$F24:$BA24) -> 12008762
B25: Total revenue (gross) | E25: € | F25: =F23+F24 -> 11833.333 | G25: =G23+G24 -> 23666.667 | H25: =H23+H24 -> 35500 | I25: =I23+I24 -> 47333.333 | J25: =J23+J24 -> 59166.667 | K25: =K23+K24 -> 67250 | L25: =L23+L24 -> 68583.333 | M25: =M23+M24 -> 78583.333 | ... BA25: =BA23+BA24 -> 1598708.3 | BC25: =SUMPRODUCT((YEAR($F$3:$BA$3)=BC$3)*$F25:$BA25) -> 706250 | BD25: =SUMPRODUCT((YEAR($F$3:$BA$3)=BD$3)*$F25:$BA25) -> 2255253.3 | BE25: =SUMPRODUCT((YEAR($F$3:$BA$3)=BE$3)*$F25:$BA25) -> 6286900.7 | BF25: =SUMPRODUCT((YEAR($F$3:$BA$3)=BF$3)*$F25:$BA25) -> 15155519
B26: Less: industry-partner share | E26: € | F26: {=-INDEX(Parameters!$C$54:$F$54,MATCH(YEAR(F$3),Parameters!$C$48:$F$48,0))*INDEX(Parameters!$C$56:$F$56,MATCH(YEAR(F$3),Parameters!$C$48:$F$48,0))*F25} -> -739.58333 | G26: {=-INDEX(Parameters!$C$54:$F$54,MATCH(YEAR(G$3),Parameters!$C$48:$F$48,0))*INDEX(Parameters!$C$56:$F$56,MATCH(YEAR(G$3),Parameters!$C$48:$F$48,0))*G25} -> -1479.1667 | H26: {=-INDEX(Parameters!$C$54:$F$54,MATCH(YEAR(H$3),Parameters!$C$48:$F$48,0))*INDEX(Parameters!$C$56:$F$56,MATCH(YEAR(H$3),Parameters!$C$48:$F$48,0))*H25} -> -2218.75 | I26: {=-INDEX(Parameters!$C$54:$F$54,MATCH(YEAR(I$3),Parameters!$C$48:$F$48,0))*INDEX(Parameters!$C$56:$F$56,MATCH(YEAR(I$3),Parameters!$C$48:$F$48,0))*I25} -> -2958.3333 | J26: {=-INDEX(Parameters!$C$54:$F$54,MATCH(YEAR(J$3),Parameters!$C$48:$F$48,0))*INDEX(Parameters!$C$56:$F$56,MATCH(YEAR(J$3),Parameters!$C$48:$F$48,0))*J25} -> -3697.9167 | K26: {=-INDEX(Parameters!$C$54:$F$54,MATCH(YEAR(K$3),Parameters!$C$48:$F$48,0))*INDEX(Parameters!$C$56:$F$56,MATCH(YEAR(K$3),Parameters!$C$48:$F$48,0))*K25} -> -4203.125 | L26: {=-INDEX(Parameters!$C$54:$F$54,MATCH(YEAR(L$3),Parameters!$C$48:$F$48,0))*INDEX(Parameters!$C$56:$F$56,MATCH(YEAR(L$3),Parameters!$C$48:$F$48,0))*L25} -> -4286.4583 | M26: {=-INDEX(Parameters!$C$54:$F$54,MATCH(YEAR(M$3),Parameters!$C$48:$F$48,0))*INDEX(Parameters!$C$56:$F$56,MATCH(YEAR(M$3),Parameters!$C$48:$F$48,0))*M25} -> -4911.4583 | ... BA26: {=-INDEX(Parameters!$C$54:$F$54,MATCH(YEAR(BA$3),Parameters!$C$48:$F$48,0))*INDEX(Parameters!$C$56:$F$56,MATCH(YEAR(BA$3),Parameters!$C$48:$F$48,0))*BA25} -> -99919.271 | BC26: =SUMPRODUCT((YEAR($F$3:$BA$3)=BC$3)*$F26:$BA26) -> -44140.625 | BD26: =SUMPRODUCT((YEAR($F$3:$BA$3)=BD$3)*$F26:$BA26) -> -140953.33 | BE26: =SUMPRODUCT((YEAR($F$3:$BA$3)=BE$3)*$F26:$BA26) -> -392931.29 | BF26: =SUMPRODUCT((YEAR($F$3:$BA$3)=BF$3)*$F26:$BA26) -> -947219.95
B27: Net revenue | E27: € | F27: =F25+F26 -> 11093.75 | G27: =G25+G26 -> 22187.5 | H27: =H25+H26 -> 33281.25 | I27: =I25+I26 -> 44375 | J27: =J25+J26 -> 55468.75 | K27: =K25+K26 -> 63046.875 | L27: =L25+L26 -> 64296.875 | M27: =M25+M26 -> 73671.875 | ... BA27: =BA25+BA26 -> 1498789.1 | BC27: =SUMPRODUCT((YEAR($F$3:$BA$3)=BC$3)*$F27:$BA27) -> 662109.38 | BD27: =SUMPRODUCT((YEAR($F$3:$BA$3)=BD$3)*$F27:$BA27) -> 2114300 | BE27: =SUMPRODUCT((YEAR($F$3:$BA$3)=BE$3)*$F27:$BA27) -> 5893969.4 | BF27: =SUMPRODUCT((YEAR($F$3:$BA$3)=BF$3)*$F27:$BA27) -> 14208299

Sheet Graphs
A4: Scenario W/ BHE and no new customers in Jan | O4: Year end
A5: Revenues | B5: 17620 | C5: 33900 | D5: 37400 | E5: 32320 | F5: 38320 | G5: 45920 | H5: 45920 | I5: 47520 | J5: 45920 | K5: 42400 | L5: 40800 | M5: 42400 | O5: =sum(B5:M5) -> 470440
A6: EBITDA | B6: -14884.833 | C6: 1395.1667 | D6: 4395.1667 | E6: -684.83333 | F6: 5315.1667 | G6: 12915.167 | H6: 12915.167 | I6: 14515.167 | J6: 12915.167 | K6: 9395.1667 | L6: 7795.1667 | M6: 9395.1667 | O6: =sum(B6:M6) -> 75382
A28: Scenario W/O BHE and no new customers in Jan | O28: Year end
A29: Revenues | B29: 12500 | C29: 21100 | D29: =19600+5000 -> 24600 | E29: 27200 | F29: 33200 | G29: 40800 | H29: 40800 | I29: 42400 | J29: 40800 | K29: 42400 | L29: 40800 | M29: 42400 | O29: =sum(B29:M29) -> 409000
A30: EBITDA | B30: -20004.833 | C30: -11404.833 | D30: =-13404.8333333333+5000 -> -8404.8333 | E30: -5804.8333 | F30: 195.16667 | G30: 7795.1667 | H30: 7795.1667 | I30: 9395.1667 | J30: 7795.1667 | K30: 9395.1667 | L30: 7795.1667 | M30: 9395.1667 | O30: =sum(B30:M30) -> 13942
B33: EVOLUTE — ANNUAL SUMMARY 2027–2030
B34: € / # | C34: 2027 | D34: 2028 | E34: 2029 | F34: 2030
B35: Revenue (gross) | C35: ='Commercials Forecast'!BC25 -> 706250 | D35: ='Commercials Forecast'!BD25 -> 2255253.3 | E35: ='Commercials Forecast'!BE25 -> 6286900.7 | F35: ='Commercials Forecast'!BF25 -> 15155519
B36: Net revenue | C36: ='Income statement'!BC9 | D36: ='Income statement'!BD9 | E36: ='Income statement'!BE9 | F36: ='Income statement'!BF9
B37: EBITDA | C37: ='Income statement'!BC21 | D37: ='Income statement'!BD21 | E37: ='Income statement'!BE21 | F37: ='Income statement'!BF21
B38: EBITDA margin % | C38: ='Income statement'!BC22 -> 138000 | D38: ='Income statement'!BD22 | E38: ='Income statement'!BE22 | F38: ='Income statement'!BF22
B39: New deals | C39: =Parameters!C49 -> 20 | D39: =Parameters!D49 -> 40 | E39: =Parameters!E49 -> 58 | F39: =Parameters!F49 -> 74
B40: Avg live projects | C40: =Personnel!BC7 -> 8.6666667 | D40: =Personnel!BD7 -> 18.2 | E40: =Personnel!BE7 -> 27.743333 | F40: =Personnel!BF7 -> 37
B41: Analysts (peak) | C41: =Personnel!BC8 -> 3 | D41: =Personnel!BD8 -> 7 | E41: =Personnel!BE8 -> 10 | F41: =Personnel!BF8 -> 13
B42: Total FTE (peak) | C42: =Personnel!BC14 -> 8 | D42: =Personnel!BD14 -> 14 | E42: =Personnel!BE14 -> 17 | F42: =Personnel!BF14 -> 20

Sheet Personnel
B2: Personnel — Monthly 2027–2030 (€)
E3: Unit | F3: 46388 | G3: 46419 | H3: 46447 | I3: 46478 | J3: 46508 | K3: 46539 | L3: 46569 | M3: 46600 | N3: 46631 | O3: 46661 | P3: 46692 | Q3: 46722 | R3: 46753 | S3: 46784 | T3: 46813 | U3: 46844 | V3: 46874 | W3: 46905 | X3: 46935 | Y3: 46966 | Z3: 46997 | AA3: 47027 | AB3: 47058 | AC3: 47088 | AD3: 47119 | AE3: 47150 | AF3: 47178 | AG3: 47209 | AH3: 47239 | AI3: 47270 | AJ3: 47300 | AK3: 47331 | AL3: 47362 | AM3: 47392 | AN3: 47423 | AO3: 47453 | AP3: 47484 | AQ3: 47515 | AR3: 47543 | AS3: 47574 | AT3: 47604 | AU3: 47635 | AV3: 47665 | AW3: 47696 | AX3: 47727 | AY3: 47757 | AZ3: 47788 | BA3: 47818 | BC3: 2027 | BD3: 2028 | BE3: 2029 | BF3: 2030
B6: HEADCOUNT
B7: Live projects (total) | E7: # | F7: ='Commercials Forecast'!F8+'Commercials Forecast'!F16 -> 1.6666667 | G7: ='Commercials Forecast'!G8+'Commercials Forecast'!G16 -> 3.3333333 | H7: ='Commercials Forecast'!H8+'Commercials Forecast'!H16 -> 5 | I7: ='Commercials Forecast'!I8+'Commercials Forecast'!I16 -> 6.6666667 | J7: ='Commercials Forecast'!J8+'Commercials Forecast'!J16 -> 8.3333333 | K7: ='Commercials Forecast'!K8+'Commercials Forecast'!K16 -> 8.5 | L7: ='Commercials Forecast'!L8+'Commercials Forecast'!L16 -> 8.6666667 | M7: ='Commercials Forecast'!M8+'Commercials Forecast'!M16 -> 8.6666667 | ... BA7: ='Commercials Forecast'!BA8+'Commercials Forecast'!BA16 -> 37 | BC7: =Q7 -> 8.6666667 | BD7: =AC7 -> 18.2 | BE7: =AO7 -> 27.743333 | BF7: =BA7 -> 37
B8: Analysts (1 per 3 live) | E8: # | F8: =MAX(1,CEILING(F7/3,1)) -> 1 | G8: =MAX(1,CEILING(G7/3,1)) -> 2 | H8: =MAX(1,CEILING(H7/3,1)) -> 2 | I8: =MAX(1,CEILING(I7/3,1)) -> 3 | J8: =MAX(1,CEILING(J7/3,1)) -> 3 | K8: =MAX(1,CEILING(K7/3,1)) -> 3 | L8: =MAX(1,CEILING(L7/3,1)) -> 3 | M8: =MAX(1,CEILING(M7/3,1)) -> 3 | ... BA8: =MAX(1,CEILING(BA7/3,1)) -> 13 | BC8: =Q8 -> 3 | BD8: =AC8 -> 7 | BE8: =AO8 -> 10 | BF8: =BA8 -> 13
B9: Associates (10 / 15 triggers) | E9: # | F9: =IF(F7>=15,2,IF(F7>=10,1,0)) -> 0 | G9: =IF(G7>=15,2,IF(G7>=10,1,0)) -> 0 | H9: =IF(H7>=15,2,IF(H7>=10,1,0)) -> 0 | I9: =IF(I7>=15,2,IF(I7>=10,1,0)) -> 0 | J9: =IF(J7>=15,2,IF(J7>=10,1,0)) -> 0 | K9: =IF(K7>=15,2,IF(K7>=10,1,0)) -> 0 | L9: =IF(L7>=15,2,IF(L7>=10,1,0)) -> 0 | M9: =IF(M7>=15,2,IF(M7>=10,1,0)) -> 0 | ... BA9: =IF(BA7>=15,2,IF(BA7>=10,1,0)) -> 2 | BC9: =Q9 -> 0 | BD9: =AC9 -> 2 | BE9: =AO9 -> 2 | BF9: =BA9 -> 2
B10: Interns | E10: # | F10: 2 | G10: 2 | H10: 2 | I10: 2 | J10: 2 | K10: 2 | L10: 2 | M10: 2 | N10: 2 | O10: 2 | P10: 2 | Q10: 2 | R10: 2 | S10: 2 | T10: 2 | U10: 2 | V10: 2 | W10: 2 | X10: 2 | Y10: 2 | Z10: 2 | AA10: 2 | AB10: 2 | AC10: 2 | AD10: 2 | AE10: 2 | AF10: 2 | AG10: 2 | AH10: 2 | AI10: 2 | AJ10: 2 | AK10: 2 | AL10: 2 | AM10: 2 | AN10: 2 | AO10: 2 | AP10: 2 | AQ10: 2 | AR10: 2 | AS10: 2 | AT10: 2 | AU10: 2 | AV10: 2 | AW10: 2 | AX10: 2 | AY10: 2 | AZ10: 2 | BA10: 2 | BC10: =Q10 -> 2 | BD10: =AC10 -> 2 | BE10: =AO10 -> 2 | BF10: =BA10 -> 2
B11: Sales hire | E11: # | F11: 1 | G11: 1 | H11: 1 | I11: 1 | J11: 1 | K11: 1 | L11: 1 | M11: 1 | N11: 1 | O11: 1 | P11: 1 | Q11: 1 | R11: 1 | S11: 1 | T11: 1 | U11: 1 | V11: 1 | W11: 1 | X11: 1 | Y11: 1 | Z11: 1 | AA11: 1 | AB11: 1 | AC11: 1 | AD11: 1 | AE11: 1 | AF11: 1 | AG11: 1 | AH11: 1 | AI11: 1 | AJ11: 1 | AK11: 1 | AL11: 1 | AM11: 1 | AN11: 1 | AO11: 1 | AP11: 1 | AQ11: 1 | AR11: 1 | AS11: 1 | AT11: 1 | AU11: 1 | AV11: 1 | AW11: 1 | AX11: 1 | AY11: 1 | AZ11: 1 | BA11: 1 | BC11: =Q11 -> 1 | BD11: =AC11 -> 1 | BE11: =AO11 -> 1 | BF11: =BA11 -> 1
B12: Rob (Partner) | E12: # | F12: 1 | G12: 1 | H12: 1 | I12: 1 | J12: 1 | K12: 1 | L12: 1 | M12: 1 | N12: 1 | O12: 1 | P12: 1 | Q12: 1 | R12: 1 | S12: 1 | T12: 1 | U12: 1 | V12: 1 | W12: 1 | X12: 1 | Y12: 1 | Z12: 1 | AA12: 1 | AB12: 1 | AC12: 1 | AD12: 1 | AE12: 1 | AF12: 1 | AG12: 1 | AH12: 1 | AI12: 1 | AJ12: 1 | AK12: 1 | AL12: 1 | AM12: 1 | AN12: 1 | AO12: 1 | AP12: 1 | AQ12: 1 | AR12: 1 | AS12: 1 | AT12: 1 | AU12: 1 | AV12: 1 | AW12: 1 | AX12: 1 | AY12: 1 | AZ12: 1 | BA12: 1 | BC12: =Q12 -> 1 | BD12: =AC12 -> 1 | BE12: =AO12 -> 1 | BF12: =BA12 -> 1
B13: Simon (Client Lead) | E13: # | F13: 1 | G13: 1 | H13: 1 | I13: 1 | J13: 1 | K13: 1 | L13: 1 | M13: 1 | N13: 1 | O13: 1 | P13: 1 | Q13: 1 | R13: 1 | S13: 1 | T13: 1 | U13: 1 | V13: 1 | W13: 1 | X13: 1 | Y13: 1 | Z13: 1 | AA13: 1 | AB13: 1 | AC13: 1 | AD13: 1 | AE13: 1 | AF13: 1 | AG13: 1 | AH13: 1 | AI13: 1 | AJ13: 1 | AK13: 1 | AL13: 1 | AM13: 1 | AN13: 1 | AO13: 1 | AP13: 1 | AQ13: 1 | AR13: 1 | AS13: 1 | AT13: 1 | AU13: 1 | AV13: 1 | AW13: 1 | AX13: 1 | AY13: 1 | AZ13: 1 | BA13: 1 | BC13: =Q13 -> 1 | BD13: =AC13 -> 1 | BE13: =AO13 -> 1 | BF13: =BA13 -> 1
B14: Total FTE | E14: # | F14: =SUM(F8:F13) -> 6 | G14: =SUM(G8:G13) -> 7 | H14: =SUM(H8:H13) -> 7 | I14: =SUM(I8:I13) -> 8 | J14: =SUM(J8:J13) -> 8 | K14: =SUM(K8:K13) -> 8 | L14: =SUM(L8:L13) -> 8 | M14: =SUM(M8:M13) -> 8 | ... BA14: =SUM(BA8:BA13) -> 20 | BC14: =Q14 -> 8 | BD14: =AC14 -> 14 | BE14: =AO14 -> 17 | BF14: =BA14 -> 20
B16: PERSONNEL COSTS
B17: Gross salary | E17: € | F17: {=INDEX(Parameters!$C$58:$F$58,MATCH(YEAR(F$3),Parameters!$C$48:$F$48,0))+INDEX(Parameters!$C$59:$F$59,MATCH(YEAR(F$3),Parameters!$C$48:$F$48,0))+F8*Parameters!$C$19+F9*Parameters!$C$18+F10*Parameters!$B$20} -> 24500 | G17: {=INDEX(Parameters!$C$58:$F$58,MATCH(YEAR(G$3),Parameters!$C$48:$F$48,0))+INDEX(Parameters!$C$59:$F$59,MATCH(YEAR(G$3),Parameters!$C$48:$F$48,0))+G8*Parameters!$C$19+G9*Parameters!$C$18+G10*Parameters!$B$20} -> 27500 | H17: {=INDEX(Parameters!$C$58:$F$58,MATCH(YEAR(H$3),Parameters!$C$48:$F$48,0))+INDEX(Parameters!$C$59:$F$59,MATCH(YEAR(H$3),Parameters!$C$48:$F$48,0))+H8*Parameters!$C$19+H9*Parameters!$C$18+H10*Parameters!$B$20} -> 27500 | I17: {=INDEX(Parameters!$C$58:$F$58,MATCH(YEAR(I$3),Parameters!$C$48:$F$48,0))+INDEX(Parameters!$C$59:$F$59,MATCH(YEAR(I$3),Parameters!$C$48:$F$48,0))+I8*Parameters!$C$19+I9*Parameters!$C$18+I10*Parameters!$B$20} -> 30500 | J17: {=INDEX(Parameters!$C$58:$F$58,MATCH(YEAR(J$3),Parameters!$C$48:$F$48,0))+INDEX(Parameters!$C$59:$F$59,MATCH(YEAR(J$3),Parameters!$C$48:$F$48,0))+J8*Parameters!$C$19+J9*Parameters!$C$18+J10*Parameters!$B$20} -> 30500 | K17: {=INDEX(Parameters!$C$58:$F$58,MATCH(YEAR(K$3),Parameters!$C$48:$F$48,0))+INDEX(Parameters!$C$59:$F$59,MATCH(YEAR(K$3),Parameters!$C$48:$F$48,0))+K8*Parameters!$C$19+K9*Parameters!$C$18+K10*Parameters!$B$20} -> 30500 | L17: {=INDEX(Parameters!$C$58:$F$58,MATCH(YEAR(L$3),Parameters!$C$48:$F$48,0))+INDEX(Parameters!$C$59:$F$59,MATCH(YEAR(L$3),Parameters!$C$48:$F$48,0))+L8*Parameters!$C$19+L9*Parameters!$C$18+L10*Parameters!$B$20} -> 30500 | M17: {=INDEX(Parameters!$C$58:$F$58,MATCH(YEAR(M$3),Parameters!$C$48:$F$48,0))+INDEX(Parameters!$C$59:$F$59,MATCH(YEAR(M$3),Parameters!$C$48:$F$48,0))+M8*Parameters!$C$19+M9*Parameters!$C$18+M10*Parameters!$B$20} -> 30500 | ... BA17: {=INDEX(Parameters!$C$58:$F$58,MATCH(YEAR(BA$3),Parameters!$C$48:$F$48,0))+INDEX(Parameters!$C$59:$F$59,MATCH(YEAR(BA$3),Parameters!$C$48:$F$48,0))+BA8*Parameters!$C$19+BA9*Parameters!$C$18+BA10*Parameters!$B$20} -> 81500 | BC17: =SUMPRODUCT((YEAR($F$3:$BA$3)=BC$3)*$F17:$BA17) -> 354000 | BD17: =SUMPRODUCT((YEAR($F$3:$BA$3)=BD$3)*$F17:$BA17) -> 619500 | BE17: =SUMPRODUCT((YEAR($F$3:$BA$3)=BE$3)*$F17:$BA17) -> 792000 | BF17: =SUMPRODUCT((YEAR($F$3:$BA$3)=BF$3)*$F17:$BA17) -> 948000
B18: Holiday pay (8%) | E18: € | F18: =0.08*F17 -> 1960 | G18: =0.08*G17 -> 2200 | H18: =0.08*H17 -> 2200 | I18: =0.08*I17 -> 2440 | J18: =0.08*J17 -> 2440 | K18: =0.08*K17 -> 2440 | L18: =0.08*L17 -> 2440 | M18: =0.08*M17 -> 2440 | ... BA18: =0.08*BA17 -> 6520 | BC18: =SUMPRODUCT((YEAR($F$3:$BA$3)=BC$3)*$F18:$BA18) -> 28320 | BD18: =SUMPRODUCT((YEAR($F$3:$BA$3)=BD$3)*$F18:$BA18) -> 49560 | BE18: =SUMPRODUCT((YEAR($F$3:$BA$3)=BE$3)*$F18:$BA18) -> 63360 | BF18: =SUMPRODUCT((YEAR($F$3:$BA$3)=BF$3)*$F18:$BA18) -> 75840
B19: Employer taxes (19%) | E19: € | F19: =0.19*(F17+F18) -> 5027.4 | G19: =0.19*(G17+G18) -> 5643 | H19: =0.19*(H17+H18) -> 5643 | I19: =0.19*(I17+I18) -> 6258.6 | J19: =0.19*(J17+J18) -> 6258.6 | K19: =0.19*(K17+K18) -> 6258.6 | L19: =0.19*(L17+L18) -> 6258.6 | M19: =0.19*(M17+M18) -> 6258.6 | ... BA19: =0.19*(BA17+BA18) -> 16723.8 | BC19: =SUMPRODUCT((YEAR($F$3:$BA$3)=BC$3)*$F19:$BA19) -> 72640.8 | BD19: =SUMPRODUCT((YEAR($F$3:$BA$3)=BD$3)*$F19:$BA19) -> 127121.4 | BE19: =SUMPRODUCT((YEAR($F$3:$BA$3)=BE$3)*$F19:$BA19) -> 162518.4 | BF19: =SUMPRODUCT((YEAR($F$3:$BA$3)=BF$3)*$F19:$BA19) -> 194529.6
B20: Sales hire | E20: € | F20: =Parameters!$C$60/12 -> 7500 | G20: =Parameters!$C$60/12 -> 7500 | H20: =Parameters!$C$60/12 -> 7500 | I20: =Parameters!$C$60/12 -> 7500 | J20: =Parameters!$C$60/12 -> 7500 | K20: =Parameters!$C$60/12 -> 7500 | L20: =Parameters!$C$60/12 -> 7500 | M20: =Parameters!$C$60/12 -> 7500 | ... BA20: =Parameters!$C$60/12 -> 7500 | BC20: =SUMPRODUCT((YEAR($F$3:$BA$3)=BC$3)*$F20:$BA20) -> 90000 | BD20: =SUMPRODUCT((YEAR($F$3:$BA$3)=BD$3)*$F20:$BA20) -> 90000 | BE20: =SUMPRODUCT((YEAR($F$3:$BA$3)=BE$3)*$F20:$BA20) -> 90000 | BF20: =SUMPRODUCT((YEAR($F$3:$BA$3)=BF$3)*$F20:$BA20) -> 90000
B21: Success-fee bonus | E21: € | F21: {='Commercials Forecast'!F24*INDEX(Parameters!$C$57:$F$57,MATCH(YEAR(F$3),Parameters!$C$48:$F$48,0))*(0.9+0.1*(INDEX(Parameters!$C$54:$F$54,MATCH(YEAR(F$3),Parameters!$C$48:$F$48,0))+INDEX(Parameters!$C$55:$F$55,MATCH(YEAR(F$3),Parameters!$C$48:$F$48,0))))} -> 0 | G21: {='Commercials Forecast'!G24*INDEX(Parameters!$C$57:$F$57,MATCH(YEAR(G$3),Parameters!$C$48:$F$48,0))*(0.9+0.1*(INDEX(Parameters!$C$54:$F$54,MATCH(YEAR(G$3),Parameters!$C$48:$F$48,0))+INDEX(Parameters!$C$55:$F$55,MATCH(YEAR(G$3),Parameters!$C$48:$F$48,0))))} -> 0 | H21: {='Commercials Forecast'!H24*INDEX(Parameters!$C$57:$F$57,MATCH(YEAR(H$3),Parameters!$C$48:$F$48,0))*(0.9+0.1*(INDEX(Parameters!$C$54:$F$54,MATCH(YEAR(H$3),Parameters!$C$48:$F$48,0))+INDEX(Parameters!$C$55:$F$55,MATCH(YEAR(H$3),Parameters!$C$48:$F$48,0))))} -> 0 | I21: {='Commercials Forecast'!I24*INDEX(Parameters!$C$57:$F$57,MATCH(YEAR(I$3),Parameters!$C$48:$F$48,0))*(0.9+0.1*(INDEX(Parameters!$C$54:$F$54,MATCH(YEAR(I$3),Parameters!$C$48:$F$48,0))+INDEX(Parameters!$C$55:$F$55,MATCH(YEAR(I$3),Parameters!$C$48:$F$48,0))))} -> 0 | J21: {='Commercials Forecast'!J24*INDEX(Parameters!$C$57:$F$57,MATCH(YEAR(J$3),Parameters!$C$48:$F$48,0))*(0.9+0.1*(INDEX(Parameters!$C$54:$F$54,MATCH(YEAR(J$3),Parameters!$C$48:$F$48,0))+INDEX(Parameters!$C$55:$F$55,MATCH(YEAR(J$3),Parameters!$C$48:$F$48,0))))} -> 0 | K21: {='Commercials Forecast'!K24*INDEX(Parameters!$C$57:$F$57,MATCH(YEAR(K$3),Parameters!$C$48:$F$48,0))*(0.9+0.1*(INDEX(Parameters!$C$54:$F$54,MATCH(YEAR(K$3),Parameters!$C$48:$F$48,0))+INDEX(Parameters!$C$55:$F$55,MATCH(YEAR(K$3),Parameters!$C$48:$F$48,0))))} -> 2598.75 | L21: {='Commercials Forecast'!L24*INDEX(Parameters!$C$57:$F$57,MATCH(YEAR(L$3),Parameters!$C$48:$F$48,0))*(0.9+0.1*(INDEX(Parameters!$C$54:$F$54,MATCH(YEAR(L$3),Parameters!$C$48:$F$48,0))+INDEX(Parameters!$C$55:$F$55,MATCH(YEAR(L$3),Parameters!$C$48:$F$48,0))))} -> 2598.75 | M21: {='Commercials Forecast'!M24*INDEX(Parameters!$C$57:$F$57,MATCH(YEAR(M$3),Parameters!$C$48:$F$48,0))*(0.9+0.1*(INDEX(Parameters!$C$54:$F$54,MATCH(YEAR(M$3),Parameters!$C$48:$F$48,0))+INDEX(Parameters!$C$55:$F$55,MATCH(YEAR(M$3),Parameters!$C$48:$F$48,0))))} -> 6448.75 | ... BA21: {='Commercials Forecast'!BA24*INDEX(Parameters!$C$57:$F$57,MATCH(YEAR(BA$3),Parameters!$C$48:$F$48,0))*(0.9+0.1*(INDEX(Parameters!$C$54:$F$54,MATCH(YEAR(BA$3),Parameters!$C$48:$F$48,0))+INDEX(Parameters!$C$55:$F$55,MATCH(YEAR(BA$3),Parameters!$C$48:$F$48,0))))} -> 507478.12 | BC21: =SUMPRODUCT((YEAR($F$3:$BA$3)=BC$3)*$F21:$BA21) -> 37441.25 | BD21: =SUMPRODUCT((YEAR($F$3:$BA$3)=BD$3)*$F21:$BA21) -> 322445.2 | BE21: =SUMPRODUCT((YEAR($F$3:$BA$3)=BE$3)*$F21:$BA21) -> 1544375.1 | BF21: =SUMPRODUCT((YEAR($F$3:$BA$3)=BF$3)*$F21:$BA21) -> 4623373.6
B22: Contractors / accountant | E22: € | F22: 450 | G22: 450 | H22: 450 | I22: 450 | J22: 450 | K22: 450 | L22: 450 | M22: 450 | N22: 450 | O22: 450 | P22: 450 | Q22: 450 | R22: 450 | S22: 450 | T22: 450 | U22: 450 | V22: 450 | W22: 450 | X22: 450 | Y22: 450 | Z22: 450 | AA22: 450 | AB22: 450 | AC22: 450 | AD22: 450 | AE22: 450 | AF22: 450 | AG22: 450 | AH22: 450 | AI22: 450 | AJ22: 450 | AK22: 450 | AL22: 450 | AM22: 450 | AN22: 450 | AO22: 450 | AP22: 450 | AQ22: 450 | AR22: 450 | AS22: 450 | AT22: 450 | AU22: 450 | AV22: 450 | AW22: 450 | AX22: 450 | AY22: 450 | AZ22: 450 | BA22: 450 | BC22: =SUMPRODUCT((YEAR($F$3:$BA$3)=BC$3)*$F22:$BA22) -> 5400 | BD22: =SUMPRODUCT((YEAR($F$3:$BA$3)=BD$3)*$F22:$BA22) -> 5400 | BE22: =SUMPRODUCT((YEAR($F$3:$BA$3)=BE$3)*$F22:$BA22) -> 5400 | BF22: =SUMPRODUCT((YEAR($F$3:$BA$3)=BF$3)*$F22:$BA22) -> 5400
B23: Other people costs | E23: € | F23: 267 | G23: 267 | H23: 267 | I23: 267 | J23: 267 | K23: 267 | L23: 267 | M23: 267 | N23: 267 | O23: 267 | P23: 267 | Q23: 267 | R23: 267 | S23: 267 | T23: 267 | U23: 267 | V23: 267 | W23: 267 | X23: 267 | Y23: 267 | Z23: 267 | AA23: 267 | AB23: 267 | AC23: 267 | AD23: 267 | AE23: 267 | AF23: 267 | AG23: 267 | AH23: 267 | AI23: 267 | AJ23: 267 | AK23: 267 | AL23: 267 | AM23: 267 | AN23: 267 | AO23: 267 | AP23: 267 | AQ23: 267 | AR23: 267 | AS23: 267 | AT23: 267 | AU23: 267 | AV23: 267 | AW23: 267 | AX23: 267 | AY23: 267 | AZ23: 267 | BA23: 267 | BC23: =SUMPRODUCT((YEAR($F$3:$BA$3)=BC$3)*$F23:$BA23) -> 3204 | BD23: =SUMPRODUCT((YEAR($F$3:$BA$3)=BD$3)*$F23:$BA23) -> 3204 | BE23: =SUMPRODUCT((YEAR($F$3:$BA$3)=BE$3)*$F23:$BA23) -> 3204 | BF23: =SUMPRODUCT((YEAR($F$3:$BA$3)=BF$3)*$F23:$BA23) -> 3204
B24: Total personnel | E24: € | F24: =SUM(F17:F23) -> 39704.4 | G24: =SUM(G17:G23) -> 43560 | H24: =SUM(H17:H23) -> 43560 | I24: =SUM(I17:I23) -> 47415.6 | J24: =SUM(J17:J23) -> 47415.6 | K24: =SUM(K17:K23) -> 50014.35 | L24: =SUM(L17:L23) -> 50014.35 | M24: =SUM(M17:M23) -> 53864.35 | ... BA24: =SUM(BA17:BA23) -> 620438.93 | BC24: =SUMPRODUCT((YEAR($F$3:$BA$3)=BC$3)*$F24:$BA24) -> 591006.05 | BD24: =SUMPRODUCT((YEAR($F$3:$BA$3)=BD$3)*$F24:$BA24) -> 1217230.6 | BE24: =SUMPRODUCT((YEAR($F$3:$BA$3)=BE$3)*$F24:$BA24) -> 2660857.5 | BF24: =SUMPRODUCT((YEAR($F$3:$BA$3)=BF$3)*$F24:$BA24) -> 5940347.2

Sheet OPEX
B2: OPEX — Monthly 2027–2030 (€)
E3: Unit | F3: 46388 | G3: 46419 | H3: 46447 | I3: 46478 | J3: 46508 | K3: 46539 | L3: 46569 | M3: 46600 | N3: 46631 | O3: 46661 | P3: 46692 | Q3: 46722 | R3: 46753 | S3: 46784 | T3: 46813 | U3: 46844 | V3: 46874 | W3: 46905 | X3: 46935 | Y3: 46966 | Z3: 46997 | AA3: 47027 | AB3: 47058 | AC3: 47088 | AD3: 47119 | AE3: 47150 | AF3: 47178 | AG3: 47209 | AH3: 47239 | AI3: 47270 | AJ3: 47300 | AK3: 47331 | AL3: 47362 | AM3: 47392 | AN3: 47423 | AO3: 47453 | AP3: 47484 | AQ3: 47515 | AR3: 47543 | AS3: 47574 | AT3: 47604 | AU3: 47635 | AV3: 47665 | AW3: 47696 | AX3: 47727 | AY3: 47757 | AZ3: 47788 | BA3: 47818 | BC3: 2027 | BD3: 2028 | BE3: 2029 | BF3: 2030
B6: OTHER OPEX
B7: Rent | E7: € | F7: =Personnel!F14*Parameters!$C$63 -> 3600 | G7: =Personnel!G14*Parameters!$C$63 -> 4200 | H7: =Personnel!H14*Parameters!$C$63 -> 4200 | I7: =Personnel!I14*Parameters!$C$63 -> 4800 | J7: =Personnel!J14*Parameters!$C$63 -> 4800 | K7: =Personnel!K14*Parameters!$C$63 -> 4800 | L7: =Personnel!L14*Parameters!$C$63 -> 4800 | M7: =Personnel!M14*Parameters!$C$63 -> 4800 | ... BA7: =Personnel!BA14*Parameters!$C$63 -> 12000 | BC7: =SUMPRODUCT((YEAR($F$3:$BA$3)=BC$3)*$F7:$BA7) -> 55200 | BD7: =SUMPRODUCT((YEAR($F$3:$BA$3)=BD$3)*$F7:$BA7) -> 92400 | BE7: =SUMPRODUCT((YEAR($F$3:$BA$3)=BE$3)*$F7:$BA7) -> 116400 | BF7: =SUMPRODUCT((YEAR($F$3:$BA$3)=BF$3)*$F7:$BA7) -> 138000
B8: Software | E8: € | F8: =Parameters!$C$65+Personnel!F14*Parameters!$C$64 -> 2303.3333 | G8: =Parameters!$C$65+Personnel!G14*Parameters!$C$64 -> 2423.3333 | H8: =Parameters!$C$65+Personnel!H14*Parameters!$C$64 -> 2423.3333 | I8: =Parameters!$C$65+Personnel!I14*Parameters!$C$64 -> 2543.3333 | J8: =Parameters!$C$65+Personnel!J14*Parameters!$C$64 -> 2543.3333 | K8: =Parameters!$C$65+Personnel!K14*Parameters!$C$64 -> 2543.3333 | L8: =Parameters!$C$65+Personnel!L14*Parameters!$C$64 -> 2543.3333 | M8: =Parameters!$C$65+Personnel!M14*Parameters!$C$64 -> 2543.3333 | ... BA8: =Parameters!$C$65+Personnel!BA14*Parameters!$C$64 -> 3983.3333 | BC8: =SUMPRODUCT((YEAR($F$3:$BA$3)=BC$3)*$F8:$BA8) -> 30040 | BD8: =SUMPRODUCT((YEAR($F$3:$BA$3)=BD$3)*$F8:$BA8) -> 37480 | BE8: =SUMPRODUCT((YEAR($F$3:$BA$3)=BE$3)*$F8:$BA8) -> 42280 | BF8: =SUMPRODUCT((YEAR($F$3:$BA$3)=BF$3)*$F8:$BA8) -> 46600
B9: Office & hardware | E9: € | F9: =Personnel!F14*Parameters!$C$66 -> 240 | G9: =Personnel!G14*Parameters!$C$66 -> 280 | H9: =Personnel!H14*Parameters!$C$66 -> 280 | I9: =Personnel!I14*Parameters!$C$66 -> 320 | J9: =Personnel!J14*Parameters!$C$66 -> 320 | K9: =Personnel!K14*Parameters!$C$66 -> 320 | L9: =Personnel!L14*Parameters!$C$66 -> 320 | M9: =Personnel!M14*Parameters!$C$66 -> 320 | ... BA9: =Personnel!BA14*Parameters!$C$66 -> 800 | BC9: =SUMPRODUCT((YEAR($F$3:$BA$3)=BC$3)*$F9:$BA9) -> 3680 | BD9: =SUMPRODUCT((YEAR($F$3:$BA$3)=BD$3)*$F9:$BA9) -> 6160 | BE9: =SUMPRODUCT((YEAR($F$3:$BA$3)=BE$3)*$F9:$BA9) -> 7760 | BF9: =SUMPRODUCT((YEAR($F$3:$BA$3)=BF$3)*$F9:$BA9) -> 9200
B10: Marketing & Sales | E10: € | F10: =Parameters!$C$68 -> 2000 | G10: =Parameters!$C$68 -> 2000 | H10: =Parameters!$C$68 -> 2000 | I10: =Parameters!$C$68 -> 2000 | J10: =Parameters!$C$68 -> 2000 | K10: =Parameters!$C$68 -> 2000 | L10: =Parameters!$C$68 -> 2000 | M10: =Parameters!$C$68 -> 2000 | ... BA10: =Parameters!$C$68 -> 2000 | BC10: =SUMPRODUCT((YEAR($F$3:$BA$3)=BC$3)*$F10:$BA10) -> 24000 | BD10: =SUMPRODUCT((YEAR($F$3:$BA$3)=BD$3)*$F10:$BA10) -> 24000 | BE10: =SUMPRODUCT((YEAR($F$3:$BA$3)=BE$3)*$F10:$BA10) -> 24000 | BF10: =SUMPRODUCT((YEAR($F$3:$BA$3)=BF$3)*$F10:$BA10) -> 24000
B11: Travel | E11: € | F11: =Parameters!$C$69 -> 500 | G11: =Parameters!$C$69 -> 500 | H11: =Parameters!$C$69 -> 500 | I11: =Parameters!$C$69 -> 500 | J11: =Parameters!$C$69 -> 500 | K11: =Parameters!$C$69 -> 500 | L11: =Parameters!$C$69 -> 500 | M11: =Parameters!$C$69 -> 500 | ... BA11: =Parameters!$C$69 -> 500 | BC11: =SUMPRODUCT((YEAR($F$3:$BA$3)=BC$3)*$F11:$BA11) -> 6000 | BD11: =SUMPRODUCT((YEAR($F$3:$BA$3)=BD$3)*$F11:$BA11) -> 6000 | BE11: =SUMPRODUCT((YEAR($F$3:$BA$3)=BE$3)*$F11:$BA11) -> 6000 | BF11: =SUMPRODUCT((YEAR($F$3:$BA$3)=BF$3)*$F11:$BA11) -> 6000
B12: SG&A (F&B) | E12: € | F12: =Personnel!F14*Parameters!$C$67 -> 600 | G12: =Personnel!G14*Parameters!$C$67 -> 700 | H12: =Personnel!H14*Parameters!$C$67 -> 700 | I12: =Personnel!I14*Parameters!$C$67 -> 800 | J12: =Personnel!J14*Parameters!$C$67 -> 800 | K12: =Personnel!K14*Parameters!$C$67 -> 800 | L12: =Personnel!L14*Parameters!$C$67 -> 800 | M12: =Personnel!M14*Parameters!$C$67 -> 800 | ... BA12: =Personnel!BA14*Parameters!$C$67 -> 2000 | BC12: =SUMPRODUCT((YEAR($F$3:$BA$3)=BC$3)*$F12:$BA12) -> 9200 | BD12: =SUMPRODUCT((YEAR($F$3:$BA$3)=BD$3)*$F12:$BA12) -> 15400 | BE12: =SUMPRODUCT((YEAR($F$3:$BA$3)=BE$3)*$F12:$BA12) -> 19400 | BF12: =SUMPRODUCT((YEAR($F$3:$BA$3)=BF$3)*$F12:$BA12) -> 23000
B13: Other | E13: € | F13: =Parameters!$C$71 -> 140 | G13: =Parameters!$C$71 -> 140 | H13: =Parameters!$C$71 -> 140 | I13: =Parameters!$C$71 -> 140 | J13: =Parameters!$C$71 -> 140 | K13: =Parameters!$C$71 -> 140 | L13: =Parameters!$C$71 -> 140 | M13: =Parameters!$C$71 -> 140 | ... BA13: =Parameters!$C$71 -> 140 | BC13: =SUMPRODUCT((YEAR($F$3:$BA$3)=BC$3)*$F13:$BA13) -> 1680 | BD13: =SUMPRODUCT((YEAR($F$3:$BA$3)=BD$3)*$F13:$BA13) -> 1680 | BE13: =SUMPRODUCT((YEAR($F$3:$BA$3)=BE$3)*$F13:$BA13) -> 1680 | BF13: =SUMPRODUCT((YEAR($F$3:$BA$3)=BF$3)*$F13:$BA13) -> 1680
B14: RX allocation | E14: € | F14: =Parameters!$C$70 -> 1307 | G14: =Parameters!$C$70 -> 1307 | H14: =Parameters!$C$70 -> 1307 | I14: =Parameters!$C$70 -> 1307 | J14: =Parameters!$C$70 -> 1307 | K14: =Parameters!$C$70 -> 1307 | L14: =Parameters!$C$70 -> 1307 | M14: =Parameters!$C$70 -> 1307 | ... BA14: =Parameters!$C$70 -> 1307 | BC14: =SUMPRODUCT((YEAR($F$3:$BA$3)=BC$3)*$F14:$BA14) -> 15684 | BD14: =SUMPRODUCT((YEAR($F$3:$BA$3)=BD$3)*$F14:$BA14) -> 15684 | BE14: =SUMPRODUCT((YEAR($F$3:$BA$3)=BE$3)*$F14:$BA14) -> 15684 | BF14: =SUMPRODUCT((YEAR($F$3:$BA$3)=BF$3)*$F14:$BA14) -> 15684
B15: Total other OPEX | E15: € | F15: =SUM(F7:F14) -> 10690.333 | G15: =SUM(G7:G14) -> 11550.333 | H15: =SUM(H7:H14) -> 11550.333 | I15: =SUM(I7:I14) -> 12410.333 | J15: =SUM(J7:J14) -> 12410.333 | K15: =SUM(K7:K14) -> 12410.333 | L15: =SUM(L7:L14) -> 12410.333 | M15: =SUM(M7:M14) -> 12410.333 | ... BA15: =SUM(BA7:BA14) -> 22730.333 | BC15: =SUMPRODUCT((YEAR($F$3:$BA$3)=BC$3)*$F15:$BA15) -> 145484 | BD15: =SUMPRODUCT((YEAR($F$3:$BA$3)=BD$3)*$F15:$BA15) -> 198804 | BE15: =SUMPRODUCT((YEAR($F$3:$BA$3)=BE$3)*$F15:$BA15) -> 233204 | BF15: =SUMPRODUCT((YEAR($F$3:$BA$3)=BF$3)*$F15:$BA15) -> 264164
