Workbook

Sheet Cover
B2: EVOLUTE
B4: Financial Model — 2027–2030
B6: Currency: EUR (€)
B7: Basis: monthly, aggregated to annual
B8: STRICTLY CONFIDENTIAL
B10: Contents
B11: Assumptions — all inputs & business drivers (edit here only)
B12: Revenue forecast — Growth Capital & M&A deal engine
B13: Personnel — headcount & salaries
B14: OPEX — operating costs
B15: Financial Statements — income statement
B16: Dashboard — annual summary

Sheet How to read me
B2: How to read this model
B4: STRUCTURE
B5: Assumptions → Revenue forecast → Personnel → OPEX → Financial Statements → Dashboard.
B6: Every tab is monthly (Jan 2027 – Dec 2030) with annual roll-up columns at the far right.
B8: HOW TO USE
B9: Change numbers ONLY on the Assumptions tab. All other tabs recalculate automatically.
B11: REVENUE LOGIC
B12: Two business lines: Growth Capital (retainer + success fee on ticket) and M&A (retainer + success fee on EV).
B13: Deals get bigger (M&A EV) and convert better over time; mix drifts 90/10 → 50/50.
B14: Industry partners source 25% of deals and take 25% of their retainer + fee.
B16: STAFFING
B17: 1 analyst per 3 live projects; associate at 10 live, 2nd at 15. Simon = delivery lead, Rob = partner + sales hire.

Sheet Assumptions
B1: Assumptions | C1: 2027 | D1: 2028 | E1: 2029 | F1: 2030
B2: GROWTH CAPITAL
B3: Retainer / month | C3: 7000 | D3: 7500 | E3: 8000 | F3: 8500 | G3: €/mo
B4: Avg engagement length | C4: 6 | D4: 6 | E4: 6 | F4: 6 | G4: months
B5: Success fee % | C5: 0.02 | D5: 0.02 | E5: 0.02 | F5: 0.02 | G5: %
B6: Ticket size | C6: 5000000 | D6: 7000000 | E6: 10000000 | F6: 15000000 | G6: €
B7: Close rate % | C7: 0.2 | D7: 0.25 | E7: 0.28 | F7: 0.32 | G7: %
B9: M&A
B10: Retainer / month | C10: 8000 | D10: 8500 | E10: 8500 | F10: 9000 | G10: €/mo
B11: Avg engagement length | C11: 7 | D11: 7 | E11: 7 | F11: 7 | G11: months
B12: Success fee % | C12: 0.02 | D12: 0.02 | E12: 0.02 | F12: 0.02 | G12: %
B13: Enterprise value | C13: 12000000 | D13: 18000000 | E13: 24000000 | F13: 30000000 | G13: €
B14: Close rate % | C14: 0.5 | D14: 0.56 | E14: 0.63 | F14: 0.7 | G14: %
B16: SOFTWARE
B17: Software price / month | C17: 500 | D17: 500 | E17: 500 | F17: 500 | G17: €/mo
B18: Post-engagement churn / yr | C18: 0.2 | G18: %/yr
B19: Monthly churn (computed) | C19: =1-(1-$C$18)^(1/12) -> 0.01842347 | G19: %/mo
B20: Software wins / rep / month | C20: 0 | D20: 0 | E20: 3 | F20: 4 | G20: #
B21: Direct churn / yr | C21: 0.3 | G21: %/yr
B22: Direct monthly churn (computed) | C22: =1-(1-$C$21)^(1/12) -> 0.02928553 | G22: %/mo
B23: Hosting / subscriber / month | C23: 20 | G23: €/mo
B24: Hosting fixed / month | C24: 500 | G24: €/mo
B26: DEAL FLOW
B27: New deals started / yr | C27: 15 | D27: 20 | E27: 25 | F27: 30 | G27: #
B28: Growth Capital mix % | C28: 0.7 | D28: 0.6 | E28: 0.65 | F28: 0.5 | G28: % | H28: Explanation: The percentage of all new deals that are Growth Capital projects
B30: SOURCING & COMPENSATION
B31: Industry-partner: share of deals they source % | C31: 0.3 | D31: 0.35 | E31: 0.4 | F31: 0.45 | G31: % | H31: Explanation: The fraction of deals that are sourced by industry partners
B32: Sales-hire source share % | C32: 0.375 | D32: 0.4 | E32: 0.42 | F32: 0.44 | G32: % | H32: Explanation: The fraction of deals sourced by internal sales team
B33: Industry-partner: cut of those deals' revenue % | C33: 0.25 | D33: 0.25 | E33: 0.25 | F33: 0.25 | G33: % | H33: Explanation: When an industry partner refers a deal, they take 25% of the revenue on that deal (retainer + success fee)
B34: Success-fee bonus pool % | C34: 0.4 | D34: 0.4 | E34: 0.4 | F34: 0.4 | G34: % | H34: Explanation: 40% of success fees (after the partner cut when applicable) goes into the internal bonus pool for the team. The other 60% drops to the firm's bottom line
B36: PERSONNEL
B37: Rob salary / month | C37: =10000*(C$1-2026) -> 10000 | D37: =C37+2000 -> 12000 | E37: =D37+2000 -> 14000 | F37: =E37+2000 -> 16000 | G37: €/mo
B38: Simon salary / month | C38: 7500 | D38: =C38+2000 -> 9500 | E38: =D38+2000 -> 11500 | F38: =E38+2000 -> 13500 | G38: €/mo
B39: Associate salary / month | C39: 4500 | D39: =C39+250 -> 4750 | E39: =D39+250 -> 5000 | F39: =E39+250 -> 5250 | G39: €/mo
B40: Analyst salary / month | C40: 3000 | D40: =C40+250 -> 3250 | E40: =D40+250 -> 3500 | F40: =E40+250 -> 3750 | G40: €/mo
B41: Intern salary / month | C41: 500 | D41: 600 | E41: 700 | F41: 800 | G41: €/mo
B42: Marketing salary/ month | C42: 5000 | D42: =C42+500 -> 5500 | E42: =D42+500 -> 6000 | F42: =E42+500 -> 6500 | G42: €/mo
B43: Sales hire cost / month | C43: 6500 | D43: 7000 | E43: 7500 | F43: 8000 | G43: €/mo
B44: Software sales salary / month | C44: 5000 | D44: 5500 | E44: 6000 | F44: 6500 | G44: €/mo
B45: Developer salary / month | C45: 5500 | D45: 6000 | E45: 6500 | F45: 7000 | G45: €/mo
...

Sheet Revenue forecast
B2: Revenue forecast — Monthly 2027–2030 (€)
E3: Unit | F3: 46388 | G3: 46419 | H3: 46447 | I3: 46478 | J3: 46508 | K3: 46539 | L3: 46569 | M3: 46600 | N3: 46631 | O3: 46661 | P3: 46692 | Q3: 46722 | R3: 46753 | S3: 46784 | T3: 46813 | U3: 46844 | V3: 46874 | W3: 46905 | X3: 46935 | Y3: 46966 | Z3: 46997 | AA3: 47027 | AB3: 47058 | AC3: 47088 | AD3: 47119 | AE3: 47150 | AF3: 47178 | AG3: 47209 | AH3: 47239 | AI3: 47270 | AJ3: 47300 | AK3: 47331 | AL3: 47362 | AM3: 47392 | AN3: 47423 | AO3: 47453 | AP3: 47484 | AQ3: 47515 | AR3: 47543 | AS3: 47574 | AT3: 47604 | AU3: 47635 | AV3: 47665 | AW3: 47696 | AX3: 47727 | AY3: 47757 | AZ3: 47788 | BA3: 47818 | BC3: 2027 | BD3: 2028 | BE3: 2029 | BF3: 2030
B6: GROWTH CAPITAL
B7: New deals started | E7: # | F7: {=ROUND((INDEX(Assumptions!$C$27:$F$27,MATCH(YEAR(F$3),Assumptions!$C$1:$F$1,0))*INDEX(Assumptions!$C$28:$F$28,MATCH(YEAR(F$3),Assumptions!$C$1:$F$1,0)))*MONTH(F$3)/12,0)-ROUND((INDEX(Assumptions!$C$27:$F$27,MATCH(YEAR(F$3),Assumptions!$C$1:$F$1,0))*INDEX(Assumptions!$C$28:$F$28,MATCH(YEAR(F$3),Assumptions!$C$1:$F$1,0)))*(MONTH(F$3)-1)/12,0)} -> 1 | G7: {=ROUND((INDEX(Assumptions!$C$27:$F$27,MATCH(YEAR(G$3),Assumptions!$C$1:$F$1,0))*INDEX(Assumptions!$C$28:$F$28,MATCH(YEAR(G$3),Assumptions!$C$1:$F$1,0)))*MONTH(G$3)/12,0)-ROUND((INDEX(Assumptions!$C$27:$F$27,MATCH(YEAR(G$3),Assumptions!$C$1:$F$1,0))*INDEX(Assumptions!$C$28:$F$28,MATCH(YEAR(G$3),Assumptions!$C$1:$F$1,0)))*(MONTH(G$3)-1)/12,0)} -> 1 | H7: {=ROUND((INDEX(Assumptions!$C$27:$F$27,MATCH(YEAR(H$3),Assumptions!$C$1:$F$1,0))*INDEX(Assumptions!$C$28:$F$28,MATCH(YEAR(H$3),Assumptions!$C$1:$F$1,0)))*MONTH(H$3)/12,0)-ROUND((INDEX(Assumptions!$C$27:$F$27,MATCH(YEAR(H$3),Assumptions!$C$1:$F$1,0))*INDEX(Assumptions!$C$28:$F$28,MATCH(YEAR(H$3),Assumptions!$C$1:$F$1,0)))*(MONTH(H$3)-1)/12,0)} -> 1 | I7: {=ROUND((INDEX(Assumptions!$C$27:$F$27,MATCH(YEAR(I$3),Assumptions!$C$1:$F$1,0))*INDEX(Assumptions!$C$28:$F$28,MATCH(YEAR(I$3),Assumptions!$C$1:$F$1,0)))*MONTH(I$3)/12,0)-ROUND((INDEX(Assumptions!$C$27:$F$27,MATCH(YEAR(I$3),Assumptions!$C$1:$F$1,0))*INDEX(Assumptions!$C$28:$F$28,MATCH(YEAR(I$3),Assumptions!$C$1:$F$1,0)))*(MONTH(I$3)-1)/12,0)} -> 1 | J7: {=ROUND((INDEX(Assumptions!$C$27:$F$27,MATCH(YEAR(J$3),Assumptions!$C$1:$F$1,0))*INDEX(Assumptions!$C$28:$F$28,MATCH(YEAR(J$3),Assumptions!$C$1:$F$1,0)))*MONTH(J$3)/12,0)-ROUND((INDEX(Assumptions!$C$27:$F$27,MATCH(YEAR(J$3),Assumptions!$C$1:$F$1,0))*INDEX(Assumptions!$C$28:$F$28,MATCH(YEAR(J$3),Assumptions!$C$1:$F$1,0)))*(MONTH(J$3)-1)/12,0)} -> 0 | K7: {=ROUND((INDEX(Assumptions!$C$27:$F$27,MATCH(YEAR(K$3),Assumptions!$C$1:$F$1,0))*INDEX(Assumptions!$C$28:$F$28,MATCH(YEAR(K$3),Assumptions!$C$1:$F$1,0)))*MONTH(K$3)/12,0)-ROUND((INDEX(Assumptions!$C$27:$F$27,MATCH(YEAR(K$3),Assumptions!$C$1:$F$1,0))*INDEX(Assumptions!$C$28:$F$28,MATCH(YEAR(K$3),Assumptions!$C$1:$F$1,0)))*(MONTH(K$3)-1)/12,0)} -> 1 | L7: {=ROUND((INDEX(Assumptions!$C$27:$F$27,MATCH(YEAR(L$3),Assumptions!$C$1:$F$1,0))*INDEX(Assumptions!$C$28:$F$28,MATCH(YEAR(L$3),Assumptions!$C$1:$F$1,0)))*MONTH(L$3)/12,0)-ROUND((INDEX(Assumptions!$C$27:$F$27,MATCH(YEAR(L$3),Assumptions!$C$1:$F$1,0))*INDEX(Assumptions!$C$28:$F$28,MATCH(YEAR(L$3),Assumptions!$C$1:$F$1,0)))*(MONTH(L$3)-1)/12,0)} -> 1 | M7: {=ROUND((INDEX(Assumptions!$C$27:$F$27,MATCH(YEAR(M$3),Assumptions!$C$1:$F$1,0))*INDEX(Assumptions!$C$28:$F$28,MATCH(YEAR(M$3),Assumptions!$C$1:$F$1,0)))*MONTH(M$3)/12,0)-ROUND((INDEX(Assumptions!$C$27:$F$27,MATCH(YEAR(M$3),Assumptions!$C$1:$F$1,0))*INDEX(Assumptions!$C$28:$F$28,MATCH(YEAR(M$3),Assumptions!$C$1:$F$1,0)))*(MONTH(M$3)-1)/12,0)} -> 1 | ... BA7: {=ROUND((INDEX(Assumptions!$C$27:$F$27,MATCH(YEAR(BA$3),Assumptions!$C$1:$F$1,0))*INDEX(Assumptions!$C$28:$F$28,MATCH(YEAR(BA$3),Assumptions!$C$1:$F$1,0)))*MONTH(BA$3)/12,0)-ROUND((INDEX(Assumptions!$C$27:$F$27,MATCH(YEAR(BA$3),Assumptions!$C$1:$F$1,0))*INDEX(Assumptions!$C$28:$F$28,MATCH(YEAR(BA$3),Assumptions!$C$1:$F$1,0)))*(MONTH(BA$3)-1)/12,0)} -> 1 | BC7: =SUMPRODUCT((YEAR($F$3:$BA$3)=BC$3)*$F7:$BA7) -> 11 | BD7: =SUMPRODUCT((YEAR($F$3:$BA$3)=BD$3)*$F7:$BA7) -> 12 | BE7: =SUMPRODUCT((YEAR($F$3:$BA$3)=BE$3)*$F7:$BA7) -> 16 | BF7: =SUMPRODUCT((YEAR($F$3:$BA$3)=BF$3)*$F7:$BA7) -> 15
B8: Live projects | E8: # | F8: =SUM(F7)+F43 -> 4 | G8: =SUM(F7:G7)+G43 -> 5 | H8: =SUM(F7:H7)+H43 -> 4 | I8: =SUM(F7:I7)+I43 -> 5 | J8: =SUM(F7:J7) -> 4 | K8: =SUM(G7:K7) -> 4 | L8: =SUM(H7:L7) -> 4 | M8: =SUM(I7:M7) -> 4 | N8: =SUM(J7:N7) -> 4 | O8: =SUM(K7:O7) -> 5 | P8: =SUM(L7:P7) -> 5 | Q8: =SUM(M7:Q7) -> 5 | ... BA8: =SUM(AW7:BA7) -> 6
B9: Retainer revenue | E9: € | F9: {=F8*(INDEX(Assumptions!$C$3:$F$3,MATCH(YEAR(F$3),Assumptions!$C$1:$F$1,0))-INDEX(Assumptions!$C$17:$F$17,MATCH(YEAR(F$3),Assumptions!$C$1:$F$1,0)))} -> 26000 | G9: {=G8*(INDEX(Assumptions!$C$3:$F$3,MATCH(YEAR(G$3),Assumptions!$C$1:$F$1,0))-INDEX(Assumptions!$C$17:$F$17,MATCH(YEAR(G$3),Assumptions!$C$1:$F$1,0)))} -> 32500 | H9: {=H8*(INDEX(Assumptions!$C$3:$F$3,MATCH(YEAR(H$3),Assumptions!$C$1:$F$1,0))-INDEX(Assumptions!$C$17:$F$17,MATCH(YEAR(H$3),Assumptions!$C$1:$F$1,0)))} -> 26000 | I9: {=I8*(INDEX(Assumptions!$C$3:$F$3,MATCH(YEAR(I$3),Assumptions!$C$1:$F$1,0))-INDEX(Assumptions!$C$17:$F$17,MATCH(YEAR(I$3),Assumptions!$C$1:$F$1,0)))} -> 32500 | J9: {=J8*(INDEX(Assumptions!$C$3:$F$3,MATCH(YEAR(J$3),Assumptions!$C$1:$F$1,0))-INDEX(Assumptions!$C$17:$F$17,MATCH(YEAR(J$3),Assumptions!$C$1:$F$1,0)))} -> 26000 | K9: {=K8*(INDEX(Assumptions!$C$3:$F$3,MATCH(YEAR(K$3),Assumptions!$C$1:$F$1,0))-INDEX(Assumptions!$C$17:$F$17,MATCH(YEAR(K$3),Assumptions!$C$1:$F$1,0)))} -> 26000 | L9: {=L8*(INDEX(Assumptions!$C$3:$F$3,MATCH(YEAR(L$3),Assumptions!$C$1:$F$1,0))-INDEX(Assumptions!$C$17:$F$17,MATCH(YEAR(L$3),Assumptions!$C$1:$F$1,0)))} -> 26000 | M9: {=M8*(INDEX(Assumptions!$C$3:$F$3,MATCH(YEAR(M$3),Assumptions!$C$1:$F$1,0))-INDEX(Assumptions!$C$17:$F$17,MATCH(YEAR(M$3),Assumptions!$C$1:$F$1,0)))} -> 26000 | ... BA9: {=BA8*(INDEX(Assumptions!$C$3:$F$3,MATCH(YEAR(BA$3),Assumptions!$C$1:$F$1,0))-INDEX(Assumptions!$C$17:$F$17,MATCH(YEAR(BA$3),Assumptions!$C$1:$F$1,0)))} -> 48000 | BC9: =SUMPRODUCT((YEAR($F$3:$BA$3)=BC$3)*$F9:$BA9) -> 344500 | BD9: =SUMPRODUCT((YEAR($F$3:$BA$3)=BD$3)*$F9:$BA9) -> 420000 | BE9: =SUMPRODUCT((YEAR($F$3:$BA$3)=BE$3)*$F9:$BA9) -> 585000 | BF9: =SUMPRODUCT((YEAR($F$3:$BA$3)=BF$3)*$F9:$BA9) -> 600000
B10: Deals closed | E10: # | F10: 0 | G10: =G44 -> 1 | H10: 0 | I10: 0 | J10: 0 | K10: {=F7*INDEX(Assumptions!$C$7:$F$7,MATCH(YEAR(K$3),Assumptions!$C$1:$F$1,0))} -> 0.2 | L10: {=G7*INDEX(Assumptions!$C$7:$F$7,MATCH(YEAR(L$3),Assumptions!$C$1:$F$1,0))} -> 0.2 | M10: {=H7*INDEX(Assumptions!$C$7:$F$7,MATCH(YEAR(M$3),Assumptions!$C$1:$F$1,0))} -> 0.2 | N10: {=I7*INDEX(Assumptions!$C$7:$F$7,MATCH(YEAR(N$3),Assumptions!$C$1:$F$1,0))} -> 0.2 | O10: {=J7*INDEX(Assumptions!$C$7:$F$7,MATCH(YEAR(O$3),Assumptions!$C$1:$F$1,0))} -> 0 | P10: {=K7*INDEX(Assumptions!$C$7:$F$7,MATCH(YEAR(P$3),Assumptions!$C$1:$F$1,0))} -> 0.2 | Q10: {=L7*INDEX(Assumptions!$C$7:$F$7,MATCH(YEAR(Q$3),Assumptions!$C$1:$F$1,0))} -> 0.2 | R10: {=M7*INDEX(Assumptions!$C$7:$F$7,MATCH(YEAR(R$3),Assumptions!$C$1:$F$1,0))} -> 0.25 | ... BA10: {=AV7*INDEX(Assumptions!$C$7:$F$7,MATCH(YEAR(BA$3),Assumptions!$C$1:$F$1,0))} -> 0.32 | BC10: =SUMPRODUCT((YEAR($F$3:$BA$3)=BC$3)*$F10:$BA10) -> 2.2 | BD10: =SUMPRODUCT((YEAR($F$3:$BA$3)=BD$3)*$F10:$BA10) -> 3 | BE10: =SUMPRODUCT((YEAR($F$3:$BA$3)=BE$3)*$F10:$BA10) -> 3.92 | BF10: =SUMPRODUCT((YEAR($F$3:$BA$3)=BF$3)*$F10:$BA10) -> 5.12
B11: Success fees | E11: € | F11: {=F10*(INDEX(Assumptions!$C$6:$F$6,MATCH(YEAR(F$3),Assumptions!$C$1:$F$1,0))*Assumptions!$C$5)} -> 0 | G11: {=G10*(INDEX(Assumptions!$C$6:$F$6,MATCH(YEAR(G$3),Assumptions!$C$1:$F$1,0))*Assumptions!$C$5)} -> 100000 | H11: {=H10*(INDEX(Assumptions!$C$6:$F$6,MATCH(YEAR(H$3),Assumptions!$C$1:$F$1,0))*Assumptions!$C$5)} -> 0 | I11: {=I10*(INDEX(Assumptions!$C$6:$F$6,MATCH(YEAR(I$3),Assumptions!$C$1:$F$1,0))*Assumptions!$C$5)} -> 0 | J11: {=J10*(INDEX(Assumptions!$C$6:$F$6,MATCH(YEAR(J$3),Assumptions!$C$1:$F$1,0))*Assumptions!$C$5)} -> 0 | K11: {=K10*(INDEX(Assumptions!$C$6:$F$6,MATCH(YEAR(K$3),Assumptions!$C$1:$F$1,0))*Assumptions!$C$5)} -> 20000 | L11: {=L10*(INDEX(Assumptions!$C$6:$F$6,MATCH(YEAR(L$3),Assumptions!$C$1:$F$1,0))*Assumptions!$C$5)} -> 20000 | M11: {=M10*(INDEX(Assumptions!$C$6:$F$6,MATCH(YEAR(M$3),Assumptions!$C$1:$F$1,0))*Assumptions!$C$5)} -> 20000 | ... BA11: {=BA10*(INDEX(Assumptions!$C$6:$F$6,MATCH(YEAR(BA$3),Assumptions!$C$1:$F$1,0))*Assumptions!$C$5)} -> 96000 | BC11: =SUMPRODUCT((YEAR($F$3:$BA$3)=BC$3)*$F11:$BA11) -> 220000 | BD11: =SUMPRODUCT((YEAR($F$3:$BA$3)=BD$3)*$F11:$BA11) -> 420000 | BE11: =SUMPRODUCT((YEAR($F$3:$BA$3)=BE$3)*$F11:$BA11) -> 784000 | BF11: =SUMPRODUCT((YEAR($F$3:$BA$3)=BF$3)*$F11:$BA11) -> 1536000
B12: Total Growth revenue | E12: € | F12: =F9+F11 -> 26000 | G12: =G9+G11 -> 132500 | H12: =H9+H11 -> 26000 | I12: =I9+I11 -> 32500 | J12: =J9+J11 -> 26000 | K12: =K9+K11 -> 46000 | L12: =L9+L11 -> 46000 | M12: =M9+M11 -> 46000 | ... BA12: =BA9+BA11 -> 144000 | BC12: =SUMPRODUCT((YEAR($F$3:$BA$3)=BC$3)*$F12:$BA12) -> 564500 | BD12: =SUMPRODUCT((YEAR($F$3:$BA$3)=BD$3)*$F12:$BA12) -> 840000 | BE12: =SUMPRODUCT((YEAR($F$3:$BA$3)=BE$3)*$F12:$BA12) -> 1369000 | BF12: =SUMPRODUCT((YEAR($F$3:$BA$3)=BF$3)*$F12:$BA12) -> 2136000
B14: M&A
B15: New deals started | E15: # | F15: {=ROUND(INDEX(Assumptions!$C$27:$F$27,MATCH(YEAR(F$3),Assumptions!$C$1:$F$1,0))*MONTH(F$3)/12,0)-ROUND(INDEX(Assumptions!$C$27:$F$27,MATCH(YEAR(F$3),Assumptions!$C$1:$F$1,0))*(MONTH(F$3)-1)/12,0)-F7} -> 0 | G15: {=ROUND(INDEX(Assumptions!$C$27:$F$27,MATCH(YEAR(G$3),Assumptions!$C$1:$F$1,0))*MONTH(G$3)/12,0)-ROUND(INDEX(Assumptions!$C$27:$F$27,MATCH(YEAR(G$3),Assumptions!$C$1:$F$1,0))*(MONTH(G$3)-1)/12,0)-G7} -> 1 | H15: {=ROUND(INDEX(Assumptions!$C$27:$F$27,MATCH(YEAR(H$3),Assumptions!$C$1:$F$1,0))*MONTH(H$3)/12,0)-ROUND(INDEX(Assumptions!$C$27:$F$27,MATCH(YEAR(H$3),Assumptions!$C$1:$F$1,0))*(MONTH(H$3)-1)/12,0)-H7} -> 0 | I15: {=ROUND(INDEX(Assumptions!$C$27:$F$27,MATCH(YEAR(I$3),Assumptions!$C$1:$F$1,0))*MONTH(I$3)/12,0)-ROUND(INDEX(Assumptions!$C$27:$F$27,MATCH(YEAR(I$3),Assumptions!$C$1:$F$1,0))*(MONTH(I$3)-1)/12,0)-I7} -> 0 | J15: {=ROUND(INDEX(Assumptions!$C$27:$F$27,MATCH(YEAR(J$3),Assumptions!$C$1:$F$1,0))*MONTH(J$3)/12,0)-ROUND(INDEX(Assumptions!$C$27:$F$27,MATCH(YEAR(J$3),Assumptions!$C$1:$F$1,0))*(MONTH(J$3)-1)/12,0)-J7} -> 1 | K15: {=ROUND(INDEX(Assumptions!$C$27:$F$27,MATCH(YEAR(K$3),Assumptions!$C$1:$F$1,0))*MONTH(K$3)/12,0)-ROUND(INDEX(Assumptions!$C$27:$F$27,MATCH(YEAR(K$3),Assumptions!$C$1:$F$1,0))*(MONTH(K$3)-1)/12,0)-K7} -> 1 | L15: {=ROUND(INDEX(Assumptions!$C$27:$F$27,MATCH(YEAR(L$3),Assumptions!$C$1:$F$1,0))*MONTH(L$3)/12,0)-ROUND(INDEX(Assumptions!$C$27:$F$27,MATCH(YEAR(L$3),Assumptions!$C$1:$F$1,0))*(MONTH(L$3)-1)/12,0)-L7} -> 0 | M15: {=ROUND(INDEX(Assumptions!$C$27:$F$27,MATCH(YEAR(M$3),Assumptions!$C$1:$F$1,0))*MONTH(M$3)/12,0)-ROUND(INDEX(Assumptions!$C$27:$F$27,MATCH(YEAR(M$3),Assumptions!$C$1:$F$1,0))*(MONTH(M$3)-1)/12,0)-M7} -> 0 | ... BA15: {=ROUND(INDEX(Assumptions!$C$27:$F$27,MATCH(YEAR(BA$3),Assumptions!$C$1:$F$1,0))*MONTH(BA$3)/12,0)-ROUND(INDEX(Assumptions!$C$27:$F$27,MATCH(YEAR(BA$3),Assumptions!$C$1:$F$1,0))*(MONTH(BA$3)-1)/12,0)-BA7} -> 1 | BC15: =SUMPRODUCT((YEAR($F$3:$BA$3)=BC$3)*$F15:$BA15) -> 4 | BD15: =SUMPRODUCT((YEAR($F$3:$BA$3)=BD$3)*$F15:$BA15) -> 8 | BE15: =SUMPRODUCT((YEAR($F$3:$BA$3)=BE$3)*$F15:$BA15) -> 9 | BF15: =SUMPRODUCT((YEAR($F$3:$BA$3)=BF$3)*$F15:$BA15) -> 15
B16: Live projects | E16: # | F16: =SUM(F15) -> 0 | G16: =SUM(F15:G15) -> 1 | H16: =SUM(F15:H15) -> 1 | I16: =SUM(F15:I15) -> 1 | J16: =SUM(F15:J15) -> 2 | K16: =SUM(F15:K15) -> 3 | L16: =SUM(F15:L15) -> 3 | M16: =SUM(G15:M15) -> 3 | N16: =SUM(H15:N15) -> 2 | O16: =SUM(I15:O15) -> 3 | P16: =SUM(J15:P15) -> 3 | Q16: =SUM(K15:Q15) -> 2 | R16: =SUM(L15:R15) -> 2 | S16: =SUM(M15:S15) -> 2 | ... BA16: =SUM(AU15:BA15) -> 8
B17: Retainer revenue | E17: € | F17: {=F16*(INDEX(Assumptions!$C$10:$F$10,MATCH(YEAR(F$3),Assumptions!$C$1:$F$1,0))-INDEX(Assumptions!$C$17:$F$17,MATCH(YEAR(F$3),Assumptions!$C$1:$F$1,0)))} -> 0 | G17: {=G16*(INDEX(Assumptions!$C$10:$F$10,MATCH(YEAR(G$3),Assumptions!$C$1:$F$1,0))-INDEX(Assumptions!$C$17:$F$17,MATCH(YEAR(G$3),Assumptions!$C$1:$F$1,0)))} -> 7500 | H17: {=H16*(INDEX(Assumptions!$C$10:$F$10,MATCH(YEAR(H$3),Assumptions!$C$1:$F$1,0))-INDEX(Assumptions!$C$17:$F$17,MATCH(YEAR(H$3),Assumptions!$C$1:$F$1,0)))} -> 7500 | I17: {=I16*(INDEX(Assumptions!$C$10:$F$10,MATCH(YEAR(I$3),Assumptions!$C$1:$F$1,0))-INDEX(Assumptions!$C$17:$F$17,MATCH(YEAR(I$3),Assumptions!$C$1:$F$1,0)))} -> 7500 | J17: {=J16*(INDEX(Assumptions!$C$10:$F$10,MATCH(YEAR(J$3),Assumptions!$C$1:$F$1,0))-INDEX(Assumptions!$C$17:$F$17,MATCH(YEAR(J$3),Assumptions!$C$1:$F$1,0)))} -> 15000 | K17: {=K16*(INDEX(Assumptions!$C$10:$F$10,MATCH(YEAR(K$3),Assumptions!$C$1:$F$1,0))-INDEX(Assumptions!$C$17:$F$17,MATCH(YEAR(K$3),Assumptions!$C$1:$F$1,0)))} -> 22500 | L17: {=L16*(INDEX(Assumptions!$C$10:$F$10,MATCH(YEAR(L$3),Assumptions!$C$1:$F$1,0))-INDEX(Assumptions!$C$17:$F$17,MATCH(YEAR(L$3),Assumptions!$C$1:$F$1,0)))} -> 22500 | M17: {=M16*(INDEX(Assumptions!$C$10:$F$10,MATCH(YEAR(M$3),Assumptions!$C$1:$F$1,0))-INDEX(Assumptions!$C$17:$F$17,MATCH(YEAR(M$3),Assumptions!$C$1:$F$1,0)))} -> 22500 | ... BA17: {=BA16*(INDEX(Assumptions!$C$10:$F$10,MATCH(YEAR(BA$3),Assumptions!$C$1:$F$1,0))-INDEX(Assumptions!$C$17:$F$17,MATCH(YEAR(BA$3),Assumptions!$C$1:$F$1,0)))} -> 68000 | BC17: =SUMPRODUCT((YEAR($F$3:$BA$3)=BC$3)*$F17:$BA17) -> 180000 | BD17: =SUMPRODUCT((YEAR($F$3:$BA$3)=BD$3)*$F17:$BA17) -> 368000 | BE17: =SUMPRODUCT((YEAR($F$3:$BA$3)=BE$3)*$F17:$BA17) -> 496000 | BF17: =SUMPRODUCT((YEAR($F$3:$BA$3)=BF$3)*$F17:$BA17) -> 799000
B18: Deals closed | E18: # | F18: 0 | G18: 0 | H18: 0 | I18: 0 | J18: 0 | K18: 0 | L18: 0 | M18: {=F15*INDEX(Assumptions!$C$14:$F$14,MATCH(YEAR(M$3),Assumptions!$C$1:$F$1,0))} -> 0 | N18: {=G15*INDEX(Assumptions!$C$14:$F$14,MATCH(YEAR(N$3),Assumptions!$C$1:$F$1,0))} -> 0.5 | O18: {=H15*INDEX(Assumptions!$C$14:$F$14,MATCH(YEAR(O$3),Assumptions!$C$1:$F$1,0))} -> 0 | P18: {=I15*INDEX(Assumptions!$C$14:$F$14,MATCH(YEAR(P$3),Assumptions!$C$1:$F$1,0))} -> 0 | Q18: {=J15*INDEX(Assumptions!$C$14:$F$14,MATCH(YEAR(Q$3),Assumptions!$C$1:$F$1,0))} -> 0.5 | R18: {=K15*INDEX(Assumptions!$C$14:$F$14,MATCH(YEAR(R$3),Assumptions!$C$1:$F$1,0))} -> 0.56 | S18: {=L15*INDEX(Assumptions!$C$14:$F$14,MATCH(YEAR(S$3),Assumptions!$C$1:$F$1,0))} -> 0 | T18: {=M15*INDEX(Assumptions!$C$14:$F$14,MATCH(YEAR(T$3),Assumptions!$C$1:$F$1,0))} -> 0 | ... BA18: {=AT15*INDEX(Assumptions!$C$14:$F$14,MATCH(YEAR(BA$3),Assumptions!$C$1:$F$1,0))} -> 1.4 | BC18: =SUMPRODUCT((YEAR($F$3:$BA$3)=BC$3)*$F18:$BA18) -> 1 | BD18: =SUMPRODUCT((YEAR($F$3:$BA$3)=BD$3)*$F18:$BA18) -> 2.8 | BE18: =SUMPRODUCT((YEAR($F$3:$BA$3)=BE$3)*$F18:$BA18) -> 5.04 | BF18: =SUMPRODUCT((YEAR($F$3:$BA$3)=BF$3)*$F18:$BA18) -> 9.1
B19: Success fees | E19: € | F19: {=F18*(INDEX(Assumptions!$C$13:$F$13,MATCH(YEAR(F$3),Assumptions!$C$1:$F$1,0))*Assumptions!$C$12)} -> 0 | G19: {=G18*(INDEX(Assumptions!$C$13:$F$13,MATCH(YEAR(G$3),Assumptions!$C$1:$F$1,0))*Assumptions!$C$12)} -> 0 | H19: {=H18*(INDEX(Assumptions!$C$13:$F$13,MATCH(YEAR(H$3),Assumptions!$C$1:$F$1,0))*Assumptions!$C$12)} -> 0 | I19: {=I18*(INDEX(Assumptions!$C$13:$F$13,MATCH(YEAR(I$3),Assumptions!$C$1:$F$1,0))*Assumptions!$C$12)} -> 0 | J19: {=J18*(INDEX(Assumptions!$C$13:$F$13,MATCH(YEAR(J$3),Assumptions!$C$1:$F$1,0))*Assumptions!$C$12)} -> 0 | K19: {=K18*(INDEX(Assumptions!$C$13:$F$13,MATCH(YEAR(K$3),Assumptions!$C$1:$F$1,0))*Assumptions!$C$12)} -> 0 | L19: {=L18*(INDEX(Assumptions!$C$13:$F$13,MATCH(YEAR(L$3),Assumptions!$C$1:$F$1,0))*Assumptions!$C$12)} -> 0 | M19: {=M18*(INDEX(Assumptions!$C$13:$F$13,MATCH(YEAR(M$3),Assumptions!$C$1:$F$1,0))*Assumptions!$C$12)} -> 0 | ... BA19: {=BA18*(INDEX(Assumptions!$C$13:$F$13,MATCH(YEAR(BA$3),Assumptions!$C$1:$F$1,0))*Assumptions!$C$12)} -> 840000 | BC19: =SUMPRODUCT((YEAR($F$3:$BA$3)=BC$3)*$F19:$BA19) -> 240000 | BD19: =SUMPRODUCT((YEAR($F$3:$BA$3)=BD$3)*$F19:$BA19) -> 1008000 | BE19: =SUMPRODUCT((YEAR($F$3:$BA$3)=BE$3)*$F19:$BA19) -> 2419200 | BF19: =SUMPRODUCT((YEAR($F$3:$BA$3)=BF$3)*$F19:$BA19) -> 5460000
B20: Total M&A revenue | E20: € | F20: =F17+F19 -> 0 | G20: =G17+G19 -> 7500 | H20: =H17+H19 -> 7500 | I20: =I17+I19 -> 7500 | J20: =J17+J19 -> 15000 | K20: =K17+K19 -> 22500 | L20: =L17+L19 -> 22500 | M20: =M17+M19 -> 22500 | ... BA20: =BA17+BA19 -> 908000 | BC20: =SUMPRODUCT((YEAR($F$3:$BA$3)=BC$3)*$F20:$BA20) -> 420000 | BD20: =SUMPRODUCT((YEAR($F$3:$BA$3)=BD$3)*$F20:$BA20) -> 1376000 | BE20: =SUMPRODUCT((YEAR($F$3:$BA$3)=BE$3)*$F20:$BA20) -> 2915200 | BF20: =SUMPRODUCT((YEAR($F$3:$BA$3)=BF$3)*$F20:$BA20) -> 6259000
B22: SOFTWARE
B23: Payers — in engagement | E23: # | F23: =F8+F16 -> 4 | G23: =G8+G16 -> 6 | H23: =H8+H16 -> 5 | I23: =I8+I16 -> 6 | J23: =J8+J16 -> 6 | K23: =K8+K16 -> 7 | L23: =L8+L16 -> 7 | M23: =M8+M16 -> 7 | ... BA23: =BA8+BA16 -> 14
B24: Graduates (engagements ending) | E24: # | F24: =0 -> 0 | G24: =MAX(0,F43-G43) -> 0 | H24: =MAX(0,G43-H43) -> 2 | I24: =MAX(0,H43-I43) -> 0 | J24: =MAX(0,I43-J43) -> 1 | K24: =F7+MAX(0,J43-K43) -> 1 | L24: =G7+MAX(0,K43-L43) -> 1 | M24: =H7+F15+MAX(0,L43-M43) -> 1 | N24: =I7+G15+MAX(0,M43-N43) -> 2 | O24: =J7+H15+MAX(0,N43-O43) -> 0 | P24: =K7+I15+MAX(0,O43-P43) -> 1 | Q24: =L7+J15+MAX(0,P43-Q43) -> 2 | R24: =M7+K15+MAX(0,Q43-R43) -> 2 | S24: =N7+L15+MAX(0,R43-S43) -> 1 | T24: =O7+M15+MAX(0,S43-T43) -> 1 | ... BA24: =AV7+AT15+MAX(0,AZ43-BA43) -> 3 | BC24: =SUMPRODUCT((YEAR($F$3:$BA$3)=BC$3)*$F24:$BA24) -> 11 | BD24: =SUMPRODUCT((YEAR($F$3:$BA$3)=BD$3)*$F24:$BA24) -> 17 | BE24: =SUMPRODUCT((YEAR($F$3:$BA$3)=BE$3)*$F24:$BA24) -> 22 | BF24: =SUMPRODUCT((YEAR($F$3:$BA$3)=BF$3)*$F24:$BA24) -> 29
B25: Subscribers — post-engagement | E25: # | F25: =F24 -> 0 | G25: =F25*(1-Assumptions!$C$19)+G24 -> 0 | H25: =G25*(1-Assumptions!$C$19)+H24 -> 2 | I25: =H25*(1-Assumptions!$C$19)+I24 -> 1.9631531 | J25: =I25*(1-Assumptions!$C$19)+J24 -> 2.926985 | K25: =J25*(1-Assumptions!$C$19)+K24 -> 3.8730597 | L25: =K25*(1-Assumptions!$C$19)+L24 -> 4.8017045 | M25: =L25*(1-Assumptions!$C$19)+M24 -> 5.7132405 | N25: =M25*(1-Assumptions!$C$19)+N24 -> 7.6079828 | ... BA25: =AZ25*(1-Assumptions!$C$19)+BA24 -> 57.303068
B26: New direct customers | E26: # | F26: {=Personnel!F13*INDEX(Assumptions!$C$20:$F$20,MATCH(YEAR(F$3),Assumptions!$C$1:$F$1,0))} -> 0 | G26: {=Personnel!G13*INDEX(Assumptions!$C$20:$F$20,MATCH(YEAR(G$3),Assumptions!$C$1:$F$1,0))} -> 0 | H26: {=Personnel!H13*INDEX(Assumptions!$C$20:$F$20,MATCH(YEAR(H$3),Assumptions!$C$1:$F$1,0))} -> 0 | I26: {=Personnel!I13*INDEX(Assumptions!$C$20:$F$20,MATCH(YEAR(I$3),Assumptions!$C$1:$F$1,0))} -> 0 | J26: {=Personnel!J13*INDEX(Assumptions!$C$20:$F$20,MATCH(YEAR(J$3),Assumptions!$C$1:$F$1,0))} -> 0 | K26: {=Personnel!K13*INDEX(Assumptions!$C$20:$F$20,MATCH(YEAR(K$3),Assumptions!$C$1:$F$1,0))} -> 0 | L26: {=Personnel!L13*INDEX(Assumptions!$C$20:$F$20,MATCH(YEAR(L$3),Assumptions!$C$1:$F$1,0))} -> 0 | M26: {=Personnel!M13*INDEX(Assumptions!$C$20:$F$20,MATCH(YEAR(M$3),Assumptions!$C$1:$F$1,0))} -> 0 | ... BA26: {=Personnel!BA13*INDEX(Assumptions!$C$20:$F$20,MATCH(YEAR(BA$3),Assumptions!$C$1:$F$1,0))} -> 4 | BC26: =SUMPRODUCT((YEAR($F$3:$BA$3)=BC$3)*$F26:$BA26) -> 0 | BD26: =SUMPRODUCT((YEAR($F$3:$BA$3)=BD$3)*$F26:$BA26) -> 0 | BE26: =SUMPRODUCT((YEAR($F$3:$BA$3)=BE$3)*$F26:$BA26) -> 36 | BF26: =SUMPRODUCT((YEAR($F$3:$BA$3)=BF$3)*$F26:$BA26) -> 48
B27: Direct subscribers | E27: # | F27: =F26 -> 0 | G27: =F27*(1-Assumptions!$C$22)+G26 -> 0 | H27: =G27*(1-Assumptions!$C$22)+H26 -> 0 | I27: =H27*(1-Assumptions!$C$22)+I26 -> 0 | J27: =I27*(1-Assumptions!$C$22)+J26 -> 0 | K27: =J27*(1-Assumptions!$C$22)+K26 -> 0 | L27: =K27*(1-Assumptions!$C$22)+L26 -> 0 | M27: =L27*(1-Assumptions!$C$22)+M26 -> 0 | N27: =M27*(1-Assumptions!$C$22)+N26 -> 0 | ... BA27: =AZ27*(1-Assumptions!$C$22)+BA26 -> 62.488197
B28: Total software payers | E28: # | F28: =F23+F25+F27 -> 4 | G28: =G23+G25+G27 -> 6 | H28: =H23+H25+H27 -> 7 | I28: =I23+I25+I27 -> 7.9631531 | J28: =J23+J25+J27 -> 8.926985 | K28: =K23+K25+K27 -> 10.87306 | L28: =L23+L25+L27 -> 11.801705 | M28: =M23+M25+M27 -> 12.71324 | ... BA28: =BA23+BA25+BA27 -> 133.79126
B29: Software revenue | E29: € | F29: {=F28*INDEX(Assumptions!$C$17:$F$17,MATCH(YEAR(F$3),Assumptions!$C$1:$F$1,0))} -> 2000 | G29: {=G28*INDEX(Assumptions!$C$17:$F$17,MATCH(YEAR(G$3),Assumptions!$C$1:$F$1,0))} -> 3000 | H29: {=H28*INDEX(Assumptions!$C$17:$F$17,MATCH(YEAR(H$3),Assumptions!$C$1:$F$1,0))} -> 3500 | I29: {=I28*INDEX(Assumptions!$C$17:$F$17,MATCH(YEAR(I$3),Assumptions!$C$1:$F$1,0))} -> 3981.5765 | J29: {=J28*INDEX(Assumptions!$C$17:$F$17,MATCH(YEAR(J$3),Assumptions!$C$1:$F$1,0))} -> 4463.4925 | K29: {=K28*INDEX(Assumptions!$C$17:$F$17,MATCH(YEAR(K$3),Assumptions!$C$1:$F$1,0))} -> 5436.5299 | L29: {=L28*INDEX(Assumptions!$C$17:$F$17,MATCH(YEAR(L$3),Assumptions!$C$1:$F$1,0))} -> 5900.8523 | M29: {=M28*INDEX(Assumptions!$C$17:$F$17,MATCH(YEAR(M$3),Assumptions!$C$1:$F$1,0))} -> 6356.6202 | ... BA29: {=BA28*INDEX(Assumptions!$C$17:$F$17,MATCH(YEAR(BA$3),Assumptions!$C$1:$F$1,0))} -> 66895.632 | BC29: =SUMPRODUCT((YEAR($F$3:$BA$3)=BC$3)*$F29:$BA29) -> 65930.47 | BD29: =SUMPRODUCT((YEAR($F$3:$BA$3)=BD$3)*$F29:$BA29) -> 157755.32 | BE29: =SUMPRODUCT((YEAR($F$3:$BA$3)=BE$3)*$F29:$BA29) -> 367793.02 | BF29: =SUMPRODUCT((YEAR($F$3:$BA$3)=BF$3)*$F29:$BA29) -> 670533.27
B31: TOTAL REVENUE
B32: Total live projects (monthly only) | E32: # | F32: =F8+F16 -> 4 | G32: =G8+G16 -> 6 | H32: =H8+H16 -> 5 | I32: =I8+I16 -> 6 | J32: =J8+J16 -> 6 | K32: =K8+K16 -> 7 | L32: =L8+L16 -> 7 | M32: =M8+M16 -> 7 | ... BA32: =BA8+BA16 -> 14
B33: Total new deals started (annual only) | E33: # | BC33: =BC7+BC15 -> 15 | BD33: =BD7+BD15 -> 20 | BE33: =BE7+BE15 -> 25 | BF33: =BF7+BF15 -> 30
B34: Total retainer | E34: € | F34: =F9+F17 -> 26000 | G34: =G9+G17 -> 40000 | H34: =H9+H17 -> 33500 | I34: =I9+I17 -> 40000 | J34: =J9+J17 -> 41000 | K34: =K9+K17 -> 48500 | L34: =L9+L17 -> 48500 | M34: =M9+M17 -> 48500 | ... BA34: =BA9+BA17 -> 116000 | BC34: =SUMPRODUCT((YEAR($F$3:$BA$3)=BC$3)*$F34:$BA34) -> 524500 | BD34: =SUMPRODUCT((YEAR($F$3:$BA$3)=BD$3)*$F34:$BA34) -> 788000 | BE34: =SUMPRODUCT((YEAR($F$3:$BA$3)=BE$3)*$F34:$BA34) -> 1081000 | BF34: =SUMPRODUCT((YEAR($F$3:$BA$3)=BF$3)*$F34:$BA34) -> 1399000
B35: Total success fees | E35: € | F35: =F11+F19 -> 0 | G35: =G11+G19 -> 100000 | H35: =H11+H19 -> 0 | I35: =I11+I19 -> 0 | J35: =J11+J19 -> 0 | K35: =K11+K19 -> 20000 | L35: =L11+L19 -> 20000 | M35: =M11+M19 -> 20000 | ... BA35: =BA11+BA19 -> 936000 | BC35: =SUMPRODUCT((YEAR($F$3:$BA$3)=BC$3)*$F35:$BA35) -> 460000 | BD35: =SUMPRODUCT((YEAR($F$3:$BA$3)=BD$3)*$F35:$BA35) -> 1428000 | BE35: =SUMPRODUCT((YEAR($F$3:$BA$3)=BE$3)*$F35:$BA35) -> 3203200 | BF35: =SUMPRODUCT((YEAR($F$3:$BA$3)=BF$3)*$F35:$BA35) -> 6996000
B36: Total software revenue | E36: € | F36: =F29 -> 2000 | G36: =G29 -> 3000 | H36: =H29 -> 3500 | I36: =I29 -> 3981.5765 | J36: =J29 -> 4463.4925 | K36: =K29 -> 5436.5299 | L36: =L29 -> 5900.8523 | M36: =M29 -> 6356.6202 | ... BA36: =BA29 -> 66895.632 | BC36: =SUMPRODUCT((YEAR($F$3:$BA$3)=BC$3)*$F36:$BA36) -> 65930.47 | BD36: =SUMPRODUCT((YEAR($F$3:$BA$3)=BD$3)*$F36:$BA36) -> 157755.32 | BE36: =SUMPRODUCT((YEAR($F$3:$BA$3)=BE$3)*$F36:$BA36) -> 367793.02 | BF36: =SUMPRODUCT((YEAR($F$3:$BA$3)=BF$3)*$F36:$BA36) -> 670533.27
B37: Total revenue (gross) | E37: € | F37: =F34+F35+F36 -> 28000 | G37: =G34+G35+G36 -> 143000 | H37: =H34+H35+H36 -> 37000 | I37: =I34+I35+I36 -> 43981.577 | J37: =J34+J35+J36 -> 45463.492 | K37: =K34+K35+K36 -> 73936.53 | L37: =L34+L35+L36 -> 74400.852 | M37: =M34+M35+M36 -> 74856.62 | ... BA37: =BA34+BA35+BA36 -> 1118895.6 | BC37: =SUMPRODUCT((YEAR($F$3:$BA$3)=BC$3)*$F37:$BA37) -> 1050430.5 | BD37: =SUMPRODUCT((YEAR($F$3:$BA$3)=BD$3)*$F37:$BA37) -> 2373755.3 | BE37: =SUMPRODUCT((YEAR($F$3:$BA$3)=BE$3)*$F37:$BA37) -> 4651993 | BF37: =SUMPRODUCT((YEAR($F$3:$BA$3)=BF$3)*$F37:$BA37) -> 9065533.3
B38: Less: industry-partner share | E38: € | F38: =-Assumptions!$C$31*Assumptions!$C$33*(F34+F35) -> -1950 | G38: =-Assumptions!$C$31*Assumptions!$C$33*(G34+G35) -> -10500 | H38: =-Assumptions!$C$31*Assumptions!$C$33*(H34+H35) -> -2512.5 | I38: =-Assumptions!$C$31*Assumptions!$C$33*(I34+I35) -> -3000 | J38: =-Assumptions!$C$31*Assumptions!$C$33*(J34+J35) -> -3075 | K38: =-Assumptions!$C$31*Assumptions!$C$33*(K34+K35) -> -5137.5 | L38: =-Assumptions!$C$31*Assumptions!$C$33*(L34+L35) -> -5137.5 | M38: =-Assumptions!$C$31*Assumptions!$C$33*(M34+M35) -> -5137.5 | ... BA38: =-Assumptions!$C$31*Assumptions!$C$33*(BA34+BA35) -> -78900 | BC38: =SUMPRODUCT((YEAR($F$3:$BA$3)=BC$3)*$F38:$BA38) -> -73837.5 | BD38: =SUMPRODUCT((YEAR($F$3:$BA$3)=BD$3)*$F38:$BA38) -> -166200 | BE38: =SUMPRODUCT((YEAR($F$3:$BA$3)=BE$3)*$F38:$BA38) -> -321315 | BF38: =SUMPRODUCT((YEAR($F$3:$BA$3)=BF$3)*$F38:$BA38) -> -629625
B39: Net revenue | E39: € | F39: =F37+F38 -> 26050 | G39: =G37+G38 -> 132500 | H39: =H37+H38 -> 34487.5 | I39: =I37+I38 -> 40981.577 | J39: =J37+J38 -> 42388.492 | K39: =K37+K38 -> 68799.03 | L39: =L37+L38 -> 69263.352 | M39: =M37+M38 -> 69719.12 | ... BA39: =BA37+BA38 -> 1039995.6 | BC39: =SUMPRODUCT((YEAR($F$3:$BA$3)=BC$3)*$F39:$BA39) -> 976592.97 | BD39: =SUMPRODUCT((YEAR($F$3:$BA$3)=BD$3)*$F39:$BA39) -> 2207555.3 | BE39: =SUMPRODUCT((YEAR($F$3:$BA$3)=BE$3)*$F39:$BA39) -> 4330678 | BF39: =SUMPRODUCT((YEAR($F$3:$BA$3)=BF$3)*$F39:$BA39) -> 8435908.3
B42: 2027 STARTING PROJECTS — Growth Capital opening pipeline
B43: Live projects (count) | E43: # | F43: 3 | G43: 3 | H43: 1 | I43: 1
B44: Deals closed | E44: # | G44: 1
B45: Success fee on close (memo) | E45: € | G45: {=INDEX(Assumptions!$C$6:$F$6,MATCH(2027,Assumptions!$C$1:$F$1,0))*Assumptions!$C$5} -> 100000
B46: Note: 1 of 3 deals is industry-partner-sourced — IP cut flows through the "Less: industry-partner share" line.

Sheet Personnel
B2: Personnel — Monthly 2027–2030 (€)
E3: Unit | F3: 46388 | G3: 46419 | H3: 46447 | I3: 46478 | J3: 46508 | K3: 46539 | L3: 46569 | M3: 46600 | N3: 46631 | O3: 46661 | P3: 46692 | Q3: 46722 | R3: 46753 | S3: 46784 | T3: 46813 | U3: 46844 | V3: 46874 | W3: 46905 | X3: 46935 | Y3: 46966 | Z3: 46997 | AA3: 47027 | AB3: 47058 | AC3: 47088 | AD3: 47119 | AE3: 47150 | AF3: 47178 | AG3: 47209 | AH3: 47239 | AI3: 47270 | AJ3: 47300 | AK3: 47331 | AL3: 47362 | AM3: 47392 | AN3: 47423 | AO3: 47453 | AP3: 47484 | AQ3: 47515 | AR3: 47543 | AS3: 47574 | AT3: 47604 | AU3: 47635 | AV3: 47665 | AW3: 47696 | AX3: 47727 | AY3: 47757 | AZ3: 47788 | BA3: 47818 | BC3: 2027 | BD3: 2028 | BE3: 2029 | BF3: 2030
B6: HEADCOUNT
B7: Live projects (total) | E7: # | F7: ='Revenue forecast'!F8+'Revenue forecast'!F16 -> 4 | G7: ='Revenue forecast'!G8+'Revenue forecast'!G16 -> 6 | H7: ='Revenue forecast'!H8+'Revenue forecast'!H16 -> 5 | I7: ='Revenue forecast'!I8+'Revenue forecast'!I16 -> 6 | J7: ='Revenue forecast'!J8+'Revenue forecast'!J16 -> 6 | K7: ='Revenue forecast'!K8+'Revenue forecast'!K16 -> 7 | L7: ='Revenue forecast'!L8+'Revenue forecast'!L16 -> 7 | M7: ='Revenue forecast'!M8+'Revenue forecast'!M16 -> 7 | ... BA7: ='Revenue forecast'!BA8+'Revenue forecast'!BA16 -> 14 | BC7: =Q7 -> 7 | BD7: =AC7 -> 10 | BE7: =AO7 -> 13 | BF7: =BA7 -> 14
B8: Analysts | E8: # | F8: {=MAX(1,CEILING(F7/INDEX(Assumptions!$C$48:$F$48,MATCH(YEAR(F$3),Assumptions!$C$1:$F$1,0)),1))} -> 2 | G8: {=MAX(F8,CEILING(G7/INDEX(Assumptions!$C$48:$F$48,MATCH(YEAR(G$3),Assumptions!$C$1:$F$1,0)),1))} -> 2 | H8: {=MAX(G8,CEILING(H7/INDEX(Assumptions!$C$48:$F$48,MATCH(YEAR(H$3),Assumptions!$C$1:$F$1,0)),1))} -> 2 | I8: {=MAX(H8,CEILING(I7/INDEX(Assumptions!$C$48:$F$48,MATCH(YEAR(I$3),Assumptions!$C$1:$F$1,0)),1))} -> 2 | J8: {=MAX(I8,CEILING(J7/INDEX(Assumptions!$C$48:$F$48,MATCH(YEAR(J$3),Assumptions!$C$1:$F$1,0)),1))} -> 2 | K8: {=MAX(J8,CEILING(K7/INDEX(Assumptions!$C$48:$F$48,MATCH(YEAR(K$3),Assumptions!$C$1:$F$1,0)),1))} -> 3 | L8: {=MAX(K8,CEILING(L7/INDEX(Assumptions!$C$48:$F$48,MATCH(YEAR(L$3),Assumptions!$C$1:$F$1,0)),1))} -> 3 | M8: {=MAX(L8,CEILING(M7/INDEX(Assumptions!$C$48:$F$48,MATCH(YEAR(M$3),Assumptions!$C$1:$F$1,0)),1))} -> 3 | N8: {=MAX(M8,CEILING(N7/INDEX(Assumptions!$C$48:$F$48,MATCH(YEAR(N$3),Assumptions!$C$1:$F$1,0)),1))} -> 3 | ... BA8: {=MAX(AZ8,CEILING(BA7/INDEX(Assumptions!$C$48:$F$48,MATCH(YEAR(BA$3),Assumptions!$C$1:$F$1,0)),1))} -> 6 | BC8: =Q8 -> 3 | BD8: =AC8 -> 4 | BE8: =AO8 -> 5 | BF8: =BA8 -> 6
B9: Associates | E9: # | F9: =IF(F7>=Assumptions!$C$52,2,IF(F7>=Assumptions!$C$51,1,0)) -> 0 | G9: =MAX(F9,IF(G7>=Assumptions!$C$52,2,IF(G7>=Assumptions!$C$51,1,0))) -> 0 | H9: =MAX(G9,IF(H7>=Assumptions!$C$52,2,IF(H7>=Assumptions!$C$51,1,0))) -> 0 | I9: =MAX(H9,IF(I7>=Assumptions!$C$52,2,IF(I7>=Assumptions!$C$51,1,0))) -> 0 | J9: =MAX(I9,IF(J7>=Assumptions!$C$52,2,IF(J7>=Assumptions!$C$51,1,0))) -> 0 | K9: =MAX(J9,IF(K7>=Assumptions!$C$52,2,IF(K7>=Assumptions!$C$51,1,0))) -> 0 | L9: =MAX(K9,IF(L7>=Assumptions!$C$52,2,IF(L7>=Assumptions!$C$51,1,0))) -> 0 | M9: =MAX(L9,IF(M7>=Assumptions!$C$52,2,IF(M7>=Assumptions!$C$51,1,0))) -> 0 | N9: =MAX(M9,IF(N7>=Assumptions!$C$52,2,IF(N7>=Assumptions!$C$51,1,0))) -> 0 | ... BA9: =MAX(AZ9,IF(BA7>=Assumptions!$C$52,2,IF(BA7>=Assumptions!$C$51,1,0))) -> 2 | BC9: =Q9 -> 0 | BD9: =AC9 -> 1 | BE9: =AO9 -> 1 | BF9: =BA9 -> 2
B10: Interns | E10: # | F10: =MAX(Assumptions!$C$53,ROUNDDOWN((F8+F9)/3,0)) -> 2 | G10: =MAX(Assumptions!$C$53,ROUNDDOWN((G8+G9)/3,0)) -> 2 | H10: =MAX(Assumptions!$C$53,ROUNDDOWN((H8+H9)/3,0)) -> 2 | I10: =MAX(Assumptions!$C$53,ROUNDDOWN((I8+I9)/3,0)) -> 2 | J10: =MAX(Assumptions!$C$53,ROUNDDOWN((J8+J9)/3,0)) -> 2 | K10: =MAX(Assumptions!$C$53,ROUNDDOWN((K8+K9)/3,0)) -> 2 | L10: =MAX(Assumptions!$C$53,ROUNDDOWN((L8+L9)/3,0)) -> 2 | M10: =MAX(Assumptions!$C$53,ROUNDDOWN((M8+M9)/3,0)) -> 2 | ... BA10: =MAX(Assumptions!$C$53,ROUNDDOWN((BA8+BA9)/3,0)) -> 2 | BC10: =Q10 -> 2 | BD10: =AC10 -> 2 | BE10: =AO10 -> 2 | BF10: =BA10 -> 2
B11: Sales hire | E11: # | F11: 1 | G11: 1 | H11: 1 | I11: 1 | J11: 1 | K11: 1 | L11: 1 | M11: 1 | N11: 1 | O11: 1 | P11: 1 | Q11: 1 | R11: 1 | S11: 1 | T11: 1 | U11: 1 | V11: 1 | W11: 1 | X11: 1 | Y11: 1 | Z11: 1 | AA11: 1 | AB11: 1 | AC11: 1 | AD11: 1 | AE11: 1 | AF11: 1 | AG11: 1 | AH11: 1 | AI11: 1 | AJ11: 1 | AK11: 1 | AL11: 1 | AM11: 1 | AN11: 1 | AO11: 1 | AP11: 1 | AQ11: 1 | AR11: 1 | AS11: 1 | AT11: 1 | AU11: 1 | AV11: 1 | AW11: 1 | AX11: 1 | AY11: 1 | AZ11: 1 | BA11: 1 | BC11: =Q11 -> 1 | BD11: =AC11 -> 1 | BE11: =AO11 -> 1 | BF11: =BA11 -> 1
B12: Marketing | E12: # | F12: 1 | G12: 1 | H12: 1 | I12: 1 | J12: 1 | K12: 1 | L12: 1 | M12: 1 | N12: 1 | O12: 1 | P12: 1 | Q12: 1 | R12: 1 | S12: 1 | T12: 1 | U12: 1 | V12: 1 | W12: 1 | X12: 1 | Y12: 1 | Z12: 1 | AA12: 1 | AB12: 1 | AC12: 1 | AD12: 1 | AE12: 1 | AF12: 1 | AG12: 1 | AH12: 1 | AI12: 1 | AJ12: 1 | AK12: 1 | AL12: 1 | AM12: 1 | AN12: 1 | AO12: 1 | AP12: 1 | AQ12: 1 | AR12: 1 | AS12: 1 | AT12: 1 | AU12: 1 | AV12: 1 | AW12: 1 | AX12: 1 | AY12: 1 | AZ12: 1 | BA12: 1 | BC12: =Q12 -> 1 | BD12: =AC12 -> 1 | BE12: =AO12 -> 1 | BF12: =BA12 -> 1
B13: Software sales | E13: # | F13: =IF(YEAR(F$3)>=2029,1,0) -> 0 | G13: =IF(YEAR(G$3)>=2029,1,0) -> 0 | H13: =IF(YEAR(H$3)>=2029,1,0) -> 0 | I13: =IF(YEAR(I$3)>=2029,1,0) -> 0 | J13: =IF(YEAR(J$3)>=2029,1,0) -> 0 | K13: =IF(YEAR(K$3)>=2029,1,0) -> 0 | L13: =IF(YEAR(L$3)>=2029,1,0) -> 0 | M13: =IF(YEAR(M$3)>=2029,1,0) -> 0 | ... BA13: =IF(YEAR(BA$3)>=2029,1,0) -> 1 | BC13: =Q13 -> 0 | BD13: =AC13 -> 0 | BE13: =AO13 -> 1 | BF13: =BA13 -> 1
B14: Developers | E14: # | F14: =IF(YEAR(F$3)>=2029,2,1) -> 1 | G14: =IF(YEAR(G$3)>=2029,2,1) -> 1 | H14: =IF(YEAR(H$3)>=2029,2,1) -> 1 | I14: =IF(YEAR(I$3)>=2029,2,1) -> 1 | J14: =IF(YEAR(J$3)>=2029,2,1) -> 1 | K14: =IF(YEAR(K$3)>=2029,2,1) -> 1 | L14: =IF(YEAR(L$3)>=2029,2,1) -> 1 | M14: =IF(YEAR(M$3)>=2029,2,1) -> 1 | ... BA14: =IF(YEAR(BA$3)>=2029,2,1) -> 2 | BC14: =Q14 -> 1 | BD14: =AC14 -> 1 | BE14: =AO14 -> 2 | BF14: =BA14 -> 2
B15: Rob | E15: # | F15: 1 | G15: 1 | H15: 1 | I15: 1 | J15: 1 | K15: 1 | L15: 1 | M15: 1 | N15: 1 | O15: 1 | P15: 1 | Q15: 1 | R15: 1 | S15: 1 | T15: 1 | U15: 1 | V15: 1 | W15: 1 | X15: 1 | Y15: 1 | Z15: 1 | AA15: 1 | AB15: 1 | AC15: 1 | AD15: 1 | AE15: 1 | AF15: 1 | AG15: 1 | AH15: 1 | AI15: 1 | AJ15: 1 | AK15: 1 | AL15: 1 | AM15: 1 | AN15: 1 | AO15: 1 | AP15: 1 | AQ15: 1 | AR15: 1 | AS15: 1 | AT15: 1 | AU15: 1 | AV15: 1 | AW15: 1 | AX15: 1 | AY15: 1 | AZ15: 1 | BA15: 1 | BC15: =Q15 -> 1 | BD15: =AC15 -> 1 | BE15: =AO15 -> 1 | BF15: =BA15 -> 1
B16: Simon | E16: # | F16: 1 | G16: 1 | H16: 1 | I16: 1 | J16: 1 | K16: 1 | L16: 1 | M16: 1 | N16: 1 | O16: 1 | P16: 1 | Q16: 1 | R16: 1 | S16: 1 | T16: 1 | U16: 1 | V16: 1 | W16: 1 | X16: 1 | Y16: 1 | Z16: 1 | AA16: 1 | AB16: 1 | AC16: 1 | AD16: 1 | AE16: 1 | AF16: 1 | AG16: 1 | AH16: 1 | AI16: 1 | AJ16: 1 | AK16: 1 | AL16: 1 | AM16: 1 | AN16: 1 | AO16: 1 | AP16: 1 | AQ16: 1 | AR16: 1 | AS16: 1 | AT16: 1 | AU16: 1 | AV16: 1 | AW16: 1 | AX16: 1 | AY16: 1 | AZ16: 1 | BA16: 1 | BC16: =Q16 -> 1 | BD16: =AC16 -> 1 | BE16: =AO16 -> 1 | BF16: =BA16 -> 1
B17: Total FTE | E17: # | F17: =SUM(F8:F16) -> 9 | G17: =SUM(G8:G16) -> 9 | H17: =SUM(H8:H16) -> 9 | I17: =SUM(I8:I16) -> 9 | J17: =SUM(J8:J16) -> 9 | K17: =SUM(K8:K16) -> 10 | L17: =SUM(L8:L16) -> 10 | M17: =SUM(M8:M16) -> 10 | ... BA17: =SUM(BA8:BA16) -> 17 | BC17: =Q17 -> 10 | BD17: =AC17 -> 12 | BE17: =AO17 -> 15 | BF17: =BA17 -> 17
B18: Consultancy FTE (ex-software team) | E18: # | F18: =F17-F13-F14 -> 8 | G18: =G17-G13-G14 -> 8 | H18: =H17-H13-H14 -> 8 | I18: =I17-I13-I14 -> 8 | J18: =J17-J13-J14 -> 8 | K18: =K17-K13-K14 -> 9 | L18: =L17-L13-L14 -> 9 | M18: =M17-M13-M14 -> 9 | ... BA18: =BA17-BA13-BA14 -> 14 | BC18: =Q18 -> 9 | BD18: =AC18 -> 11 | BE18: =AO18 -> 12 | BF18: =BA18 -> 14
B20: PERSONNEL COSTS
B21: Gross salary | E21: € | F21: {=INDEX(Assumptions!$C$37:$F$37,MATCH(YEAR(F$3),Assumptions!$C$1:$F$1,0))*IF(ISNUMBER(SEARCH("yr",Assumptions!$G$37)),1/12,1)+INDEX(Assumptions!$C$38:$F$38,MATCH(YEAR(F$3),Assumptions!$C$1:$F$1,0))*IF(ISNUMBER(SEARCH("yr",Assumptions!$G$38)),1/12,1)+F8*INDEX(Assumptions!$C$40:$F$40,MATCH(YEAR(F$3),Assumptions!$C$1:$F$1,0))*IF(ISNUMBER(SEARCH("yr",Assumptions!$G$40)),1/12,1)+F9*INDEX(Assumptions!$C$39:$F$39,MATCH(YEAR(F$3),Assumptions!$C$1:$F$1,0))*IF(ISNUMBER(SEARCH("yr",Assumptions!$G$39)),1/12,1)+F10*INDEX(Assumptions!$C$41:$F$41,MATCH(YEAR(F$3),Assumptions!$C$1:$F$1,0))*IF(ISNUMBER(SEARCH("yr",Assumptions!$G$41)),1/12,1)+F12*INDEX(Assumptions!$C$42:$F$42,MATCH(YEAR(F$3),Assumptions!$C$1:$F$1,0))*IF(ISNUMBER(SEARCH("yr",Assumptions!$G$42)),1/12,1)+F13*INDEX(Assumptions!$C$44:$F$44,MATCH(YEAR(F$3),Assumptions!$C$1:$F$1,0))*IF(ISNUMBER(SEARCH("yr",Assumptions!$G$44)),1/12,1)+F14*INDEX(Assumptions!$C$45:$F$45,MATCH(YEAR(F$3),Assumptions!$C$1:$F$1,0))*IF(ISNUMBER(SEARCH("yr",Assumptions!$G$45)),1/12,1)} -> 35000 | G21: {=INDEX(Assumptions!$C$37:$F$37,MATCH(YEAR(G$3),Assumptions!$C$1:$F$1,0))*IF(ISNUMBER(SEARCH("yr",Assumptions!$G$37)),1/12,1)+INDEX(Assumptions!$C$38:$F$38,MATCH(YEAR(G$3),Assumptions!$C$1:$F$1,0))*IF(ISNUMBER(SEARCH("yr",Assumptions!$G$38)),1/12,1)+G8*INDEX(Assumptions!$C$40:$F$40,MATCH(YEAR(G$3),Assumptions!$C$1:$F$1,0))*IF(ISNUMBER(SEARCH("yr",Assumptions!$G$40)),1/12,1)+G9*INDEX(Assumptions!$C$39:$F$39,MATCH(YEAR(G$3),Assumptions!$C$1:$F$1,0))*IF(ISNUMBER(SEARCH("yr",Assumptions!$G$39)),1/12,1)+G10*INDEX(Assumptions!$C$41:$F$41,MATCH(YEAR(G$3),Assumptions!$C$1:$F$1,0))*IF(ISNUMBER(SEARCH("yr",Assumptions!$G$41)),1/12,1)+G12*INDEX(Assumptions!$C$42:$F$42,MATCH(YEAR(G$3),Assumptions!$C$1:$F$1,0))*IF(ISNUMBER(SEARCH("yr",Assumptions!$G$42)),1/12,1)+G13*INDEX(Assumptions!$C$44:$F$44,MATCH(YEAR(G$3),Assumptions!$C$1:$F$1,0))*IF(ISNUMBER(SEARCH("yr",Assumptions!$G$44)),1/12,1)+G14*INDEX(Assumptions!$C$45:$F$45,MATCH(YEAR(G$3),Assumptions!$C$1:$F$1,0))*IF(ISNUMBER(SEARCH("yr",Assumptions!$G$45)),1/12,1)} -> 35000 | H21: {=INDEX(Assumptions!$C$37:$F$37,MATCH(YEAR(H$3),Assumptions!$C$1:$F$1,0))*IF(ISNUMBER(SEARCH("yr",Assumptions!$G$37)),1/12,1)+INDEX(Assumptions!$C$38:$F$38,MATCH(YEAR(H$3),Assumptions!$C$1:$F$1,0))*IF(ISNUMBER(SEARCH("yr",Assumptions!$G$38)),1/12,1)+H8*INDEX(Assumptions!$C$40:$F$40,MATCH(YEAR(H$3),Assumptions!$C$1:$F$1,0))*IF(ISNUMBER(SEARCH("yr",Assumptions!$G$40)),1/12,1)+H9*INDEX(Assumptions!$C$39:$F$39,MATCH(YEAR(H$3),Assumptions!$C$1:$F$1,0))*IF(ISNUMBER(SEARCH("yr",Assumptions!$G$39)),1/12,1)+H10*INDEX(Assumptions!$C$41:$F$41,MATCH(YEAR(H$3),Assumptions!$C$1:$F$1,0))*IF(ISNUMBER(SEARCH("yr",Assumptions!$G$41)),1/12,1)+H12*INDEX(Assumptions!$C$42:$F$42,MATCH(YEAR(H$3),Assumptions!$C$1:$F$1,0))*IF(ISNUMBER(SEARCH("yr",Assumptions!$G$42)),1/12,1)+H13*INDEX(Assumptions!$C$44:$F$44,MATCH(YEAR(H$3),Assumptions!$C$1:$F$1,0))*IF(ISNUMBER(SEARCH("yr",Assumptions!$G$44)),1/12,1)+H14*INDEX(Assumptions!$C$45:$F$45,MATCH(YEAR(H$3),Assumptions!$C$1:$F$1,0))*IF(ISNUMBER(SEARCH("yr",Assumptions!$G$45)),1/12,1)} -> 35000 | I21: {=INDEX(Assumptions!$C$37:$F$37,MATCH(YEAR(I$3),Assumptions!$C$1:$F$1,0))*IF(ISNUMBER(SEARCH("yr",Assumptions!$G$37)),1/12,1)+INDEX(Assumptions!$C$38:$F$38,MATCH(YEAR(I$3),Assumptions!$C$1:$F$1,0))*IF(ISNUMBER(SEARCH("yr",Assumptions!$G$38)),1/12,1)+I8*INDEX(Assumptions!$C$40:$F$40,MATCH(YEAR(I$3),Assumptions!$C$1:$F$1,0))*IF(ISNUMBER(SEARCH("yr",Assumptions!$G$40)),1/12,1)+I9*INDEX(Assumptions!$C$39:$F$39,MATCH(YEAR(I$3),Assumptions!$C$1:$F$1,0))*IF(ISNUMBER(SEARCH("yr",Assumptions!$G$39)),1/12,1)+I10*INDEX(Assumptions!$C$41:$F$41,MATCH(YEAR(I$3),Assumptions!$C$1:$F$1,0))*IF(ISNUMBER(SEARCH("yr",Assumptions!$G$41)),1/12,1)+I12*INDEX(Assumptions!$C$42:$F$42,MATCH(YEAR(I$3),Assumptions!$C$1:$F$1,0))*IF(ISNUMBER(SEARCH("yr",Assumptions!$G$42)),1/12,1)+I13*INDEX(Assumptions!$C$44:$F$44,MATCH(YEAR(I$3),Assumptions!$C$1:$F$1,0))*IF(ISNUMBER(SEARCH("yr",Assumptions!$G$44)),1/12,1)+I14*INDEX(Assumptions!$C$45:$F$45,MATCH(YEAR(I$3),Assumptions!$C$1:$F$1,0))*IF(ISNUMBER(SEARCH("yr",Assumptions!$G$45)),1/12,1)} -> 35000 | J21: {=INDEX(Assumptions!$C$37:$F$37,MATCH(YEAR(J$3),Assumptions!$C$1:$F$1,0))*IF(ISNUMBER(SEARCH("yr",Assumptions!$G$37)),1/12,1)+INDEX(Assumptions!$C$38:$F$38,MATCH(YEAR(J$3),Assumptions!$C$1:$F$1,0))*IF(ISNUMBER(SEARCH("yr",Assumptions!$G$38)),1/12,1)+J8*INDEX(Assumptions!$C$40:$F$40,MATCH(YEAR(J$3),Assumptions!$C$1:$F$1,0))*IF(ISNUMBER(SEARCH("yr",Assumptions!$G$40)),1/12,1)+J9*INDEX(Assumptions!$C$39:$F$39,MATCH(YEAR(J$3),Assumptions!$C$1:$F$1,0))*IF(ISNUMBER(SEARCH("yr",Assumptions!$G$39)),1/12,1)+J10*INDEX(Assumptions!$C$41:$F$41,MATCH(YEAR(J$3),Assumptions!$C$1:$F$1,0))*IF(ISNUMBER(SEARCH("yr",Assumptions!$G$41)),1/12,1)+J12*INDEX(Assumptions!$C$42:$F$42,MATCH(YEAR(J$3),Assumptions!$C$1:$F$1,0))*IF(ISNUMBER(SEARCH("yr",Assumptions!$G$42)),1/12,1)+J13*INDEX(Assumptions!$C$44:$F$44,MATCH(YEAR(J$3),Assumptions!$C$1:$F$1,0))*IF(ISNUMBER(SEARCH("yr",Assumptions!$G$44)),1/12,1)+J14*INDEX(Assumptions!$C$45:$F$45,MATCH(YEAR(J$3),Assumptions!$C$1:$F$1,0))*IF(ISNUMBER(SEARCH("yr",Assumptions!$G$45)),1/12,1)} -> 35000 | K21: {=INDEX(Assumptions!$C$37:$F$37,MATCH(YEAR(K$3),Assumptions!$C$1:$F$1,0))*IF(ISNUMBER(SEARCH("yr",Assumptions!$G$37)),1/12,1)+INDEX(Assumptions!$C$38:$F$38,MATCH(YEAR(K$3),Assumptions!$C$1:$F$1,0))*IF(ISNUMBER(SEARCH("yr",Assumptions!$G$38)),1/12,1)+K8*INDEX(Assumptions!$C$40:$F$40,MATCH(YEAR(K$3),Assumptions!$C$1:$F$1,0))*IF(ISNUMBER(SEARCH("yr",Assumptions!$G$40)),1/12,1)+K9*INDEX(Assumptions!$C$39:$F$39,MATCH(YEAR(K$3),Assumptions!$C$1:$F$1,0))*IF(ISNUMBER(SEARCH("yr",Assumptions!$G$39)),1/12,1)+K10*INDEX(Assumptions!$C$41:$F$41,MATCH(YEAR(K$3),Assumptions!$C$1:$F$1,0))*IF(ISNUMBER(SEARCH("yr",Assumptions!$G$41)),1/12,1)+K12*INDEX(Assumptions!$C$42:$F$42,MATCH(YEAR(K$3),Assumptions!$C$1:$F$1,0))*IF(ISNUMBER(SEARCH("yr",Assumptions!$G$42)),1/12,1)+K13*INDEX(Assumptions!$C$44:$F$44,MATCH(YEAR(K$3),Assumptions!$C$1:$F$1,0))*IF(ISNUMBER(SEARCH("yr",Assumptions!$G$44)),1/12,1)+K14*INDEX(Assumptions!$C$45:$F$45,MATCH(YEAR(K$3),Assumptions!$C$1:$F$1,0))*IF(ISNUMBER(SEARCH("yr",Assumptions!$G$45)),1/12,1)} -> 38000 | L21: {=INDEX(Assumptions!$C$37:$F$37,MATCH(YEAR(L$3),Assumptions!$C$1:$F$1,0))*IF(ISNUMBER(SEARCH("yr",Assumptions!$G$37)),1/12,1)+INDEX(Assumptions!$C$38:$F$38,MATCH(YEAR(L$3),Assumptions!$C$1:$F$1,0))*IF(ISNUMBER(SEARCH("yr",Assumptions!$G$38)),1/12,1)+L8*INDEX(Assumptions!$C$40:$F$40,MATCH(YEAR(L$3),Assumptions!$C$1:$F$1,0))*IF(ISNUMBER(SEARCH("yr",Assumptions!$G$40)),1/12,1)+L9*INDEX(Assumptions!$C$39:$F$39,MATCH(YEAR(L$3),Assumptions!$C$1:$F$1,0))*IF(ISNUMBER(SEARCH("yr",Assumptions!$G$39)),1/12,1)+L10*INDEX(Assumptions!$C$41:$F$41,MATCH(YEAR(L$3),Assumptions!$C$1:$F$1,0))*IF(ISNUMBER(SEARCH("yr",Assumptions!$G$41)),1/12,1)+L12*INDEX(Assumptions!$C$42:$F$42,MATCH(YEAR(L$3),Assumptions!$C$1:$F$1,0))*IF(ISNUMBER(SEARCH("yr",Assumptions!$G$42)),1/12,1)+L13*INDEX(Assumptions!$C$44:$F$44,MATCH(YEAR(L$3),Assumptions!$C$1:$F$1,0))*IF(ISNUMBER(SEARCH("yr",Assumptions!$G$44)),1/12,1)+L14*INDEX(Assumptions!$C$45:$F$45,MATCH(YEAR(L$3),Assumptions!$C$1:$F$1,0))*IF(ISNUMBER(SEARCH("yr",Assumptions!$G$45)),1/12,1)} -> 38000 | M21: {=INDEX(Assumptions!$C$37:$F$37,MATCH(YEAR(M$3),Assumptions!$C$1:$F$1,0))*IF(ISNUMBER(SEARCH("yr",Assumptions!$G$37)),1/12,1)+INDEX(Assumptions!$C$38:$F$38,MATCH(YEAR(M$3),Assumptions!$C$1:$F$1,0))*IF(ISNUMBER(SEARCH("yr",Assumptions!$G$38)),1/12,1)+M8*INDEX(Assumptions!$C$40:$F$40,MATCH(YEAR(M$3),Assumptions!$C$1:$F$1,0))*IF(ISNUMBER(SEARCH("yr",Assumptions!$G$40)),1/12,1)+M9*INDEX(Assumptions!$C$39:$F$39,MATCH(YEAR(M$3),Assumptions!$C$1:$F$1,0))*IF(ISNUMBER(SEARCH("yr",Assumptions!$G$39)),1/12,1)+M10*INDEX(Assumptions!$C$41:$F$41,MATCH(YEAR(M$3),Assumptions!$C$1:$F$1,0))*IF(ISNUMBER(SEARCH("yr",Assumptions!$G$41)),1/12,1)+M12*INDEX(Assumptions!$C$42:$F$42,MATCH(YEAR(M$3),Assumptions!$C$1:$F$1,0))*IF(ISNUMBER(SEARCH("yr",Assumptions!$G$42)),1/12,1)+M13*INDEX(Assumptions!$C$44:$F$44,MATCH(YEAR(M$3),Assumptions!$C$1:$F$1,0))*IF(ISNUMBER(SEARCH("yr",Assumptions!$G$44)),1/12,1)+M14*INDEX(Assumptions!$C$45:$F$45,MATCH(YEAR(M$3),Assumptions!$C$1:$F$1,0))*IF(ISNUMBER(SEARCH("yr",Assumptions!$G$45)),1/12,1)} -> 38000 | ... BA21: {=INDEX(Assumptions!$C$37:$F$37,MATCH(YEAR(BA$3),Assumptions!$C$1:$F$1,0))*IF(ISNUMBER(SEARCH("yr",Assumptions!$G$37)),1/12,1)+INDEX(Assumptions!$C$38:$F$38,MATCH(YEAR(BA$3),Assumptions!$C$1:$F$1,0))*IF(ISNUMBER(SEARCH("yr",Assumptions!$G$38)),1/12,1)+BA8*INDEX(Assumptions!$C$40:$F$40,MATCH(YEAR(BA$3),Assumptions!$C$1:$F$1,0))*IF(ISNUMBER(SEARCH("yr",Assumptions!$G$40)),1/12,1)+BA9*INDEX(Assumptions!$C$39:$F$39,MATCH(YEAR(BA$3),Assumptions!$C$1:$F$1,0))*IF(ISNUMBER(SEARCH("yr",Assumptions!$G$39)),1/12,1)+BA10*INDEX(Assumptions!$C$41:$F$41,MATCH(YEAR(BA$3),Assumptions!$C$1:$F$1,0))*IF(ISNUMBER(SEARCH("yr",Assumptions!$G$41)),1/12,1)+BA12*INDEX(Assumptions!$C$42:$F$42,MATCH(YEAR(BA$3),Assumptions!$C$1:$F$1,0))*IF(ISNUMBER(SEARCH("yr",Assumptions!$G$42)),1/12,1)+BA13*INDEX(Assumptions!$C$44:$F$44,MATCH(YEAR(BA$3),Assumptions!$C$1:$F$1,0))*IF(ISNUMBER(SEARCH("yr",Assumptions!$G$44)),1/12,1)+BA14*INDEX(Assumptions!$C$45:$F$45,MATCH(YEAR(BA$3),Assumptions!$C$1:$F$1,0))*IF(ISNUMBER(SEARCH("yr",Assumptions!$G$45)),1/12,1)} -> 91100 | BC21: =SUMPRODUCT((YEAR($F$3:$BA$3)=BC$3)*$F21:$BA21) -> 441000 | BD21: =SUMPRODUCT((YEAR($F$3:$BA$3)=BD$3)*$F21:$BA21) -> 575400 | BE21: =SUMPRODUCT((YEAR($F$3:$BA$3)=BE$3)*$F21:$BA21) -> 875300 | BF21: =SUMPRODUCT((YEAR($F$3:$BA$3)=BF$3)*$F21:$BA21) -> 1042200
B22: Holiday pay | E22: € | F22: =Assumptions!$C$46*F21 -> 2800 | G22: =Assumptions!$C$46*G21 -> 2800 | H22: =Assumptions!$C$46*H21 -> 2800 | I22: =Assumptions!$C$46*I21 -> 2800 | J22: =Assumptions!$C$46*J21 -> 2800 | K22: =Assumptions!$C$46*K21 -> 3040 | L22: =Assumptions!$C$46*L21 -> 3040 | M22: =Assumptions!$C$46*M21 -> 3040 | ... BA22: =Assumptions!$C$46*BA21 -> 7288 | BC22: =SUMPRODUCT((YEAR($F$3:$BA$3)=BC$3)*$F22:$BA22) -> 35280 | BD22: =SUMPRODUCT((YEAR($F$3:$BA$3)=BD$3)*$F22:$BA22) -> 46032 | BE22: =SUMPRODUCT((YEAR($F$3:$BA$3)=BE$3)*$F22:$BA22) -> 70024 | BF22: =SUMPRODUCT((YEAR($F$3:$BA$3)=BF$3)*$F22:$BA22) -> 83376
B23: Employer taxes | E23: € | F23: =Assumptions!$C$47*(F21+F22) -> 7182 | G23: =Assumptions!$C$47*(G21+G22) -> 7182 | H23: =Assumptions!$C$47*(H21+H22) -> 7182 | I23: =Assumptions!$C$47*(I21+I22) -> 7182 | J23: =Assumptions!$C$47*(J21+J22) -> 7182 | K23: =Assumptions!$C$47*(K21+K22) -> 7797.6 | L23: =Assumptions!$C$47*(L21+L22) -> 7797.6 | M23: =Assumptions!$C$47*(M21+M22) -> 7797.6 | ... BA23: =Assumptions!$C$47*(BA21+BA22) -> 18693.72 | BC23: =SUMPRODUCT((YEAR($F$3:$BA$3)=BC$3)*$F23:$BA23) -> 90493.2 | BD23: =SUMPRODUCT((YEAR($F$3:$BA$3)=BD$3)*$F23:$BA23) -> 118072.08 | BE23: =SUMPRODUCT((YEAR($F$3:$BA$3)=BE$3)*$F23:$BA23) -> 179611.56 | BF23: =SUMPRODUCT((YEAR($F$3:$BA$3)=BF$3)*$F23:$BA23) -> 213859.44
B24: Sales hire | E24: € | F24: {=INDEX(Assumptions!$C$43:$F$43,MATCH(YEAR(F$3),Assumptions!$C$1:$F$1,0))*IF(ISNUMBER(SEARCH("yr",Assumptions!$G$43)),1/12,1)} -> 6500 | G24: {=INDEX(Assumptions!$C$43:$F$43,MATCH(YEAR(G$3),Assumptions!$C$1:$F$1,0))*IF(ISNUMBER(SEARCH("yr",Assumptions!$G$43)),1/12,1)} -> 6500 | H24: {=INDEX(Assumptions!$C$43:$F$43,MATCH(YEAR(H$3),Assumptions!$C$1:$F$1,0))*IF(ISNUMBER(SEARCH("yr",Assumptions!$G$43)),1/12,1)} -> 6500 | I24: {=INDEX(Assumptions!$C$43:$F$43,MATCH(YEAR(I$3),Assumptions!$C$1:$F$1,0))*IF(ISNUMBER(SEARCH("yr",Assumptions!$G$43)),1/12,1)} -> 6500 | J24: {=INDEX(Assumptions!$C$43:$F$43,MATCH(YEAR(J$3),Assumptions!$C$1:$F$1,0))*IF(ISNUMBER(SEARCH("yr",Assumptions!$G$43)),1/12,1)} -> 6500 | K24: {=INDEX(Assumptions!$C$43:$F$43,MATCH(YEAR(K$3),Assumptions!$C$1:$F$1,0))*IF(ISNUMBER(SEARCH("yr",Assumptions!$G$43)),1/12,1)} -> 6500 | L24: {=INDEX(Assumptions!$C$43:$F$43,MATCH(YEAR(L$3),Assumptions!$C$1:$F$1,0))*IF(ISNUMBER(SEARCH("yr",Assumptions!$G$43)),1/12,1)} -> 6500 | M24: {=INDEX(Assumptions!$C$43:$F$43,MATCH(YEAR(M$3),Assumptions!$C$1:$F$1,0))*IF(ISNUMBER(SEARCH("yr",Assumptions!$G$43)),1/12,1)} -> 6500 | ... BA24: {=INDEX(Assumptions!$C$43:$F$43,MATCH(YEAR(BA$3),Assumptions!$C$1:$F$1,0))*IF(ISNUMBER(SEARCH("yr",Assumptions!$G$43)),1/12,1)} -> 8000 | BC24: =SUMPRODUCT((YEAR($F$3:$BA$3)=BC$3)*$F24:$BA24) -> 78000 | BD24: =SUMPRODUCT((YEAR($F$3:$BA$3)=BD$3)*$F24:$BA24) -> 84000 | BE24: =SUMPRODUCT((YEAR($F$3:$BA$3)=BE$3)*$F24:$BA24) -> 90000 | BF24: =SUMPRODUCT((YEAR($F$3:$BA$3)=BF$3)*$F24:$BA24) -> 96000
B25: Success-fee bonus | E25: € | F25: {='Revenue forecast'!F35*(1-Assumptions!$C$31*Assumptions!$C$33)*Assumptions!$C$34*(0.9+0.1*(Assumptions!$C$31+INDEX(Assumptions!$C$32:$F$32,MATCH(YEAR(F$3),Assumptions!$C$1:$F$1,0))))} -> 0 | G25: {='Revenue forecast'!G35*(1-Assumptions!$C$31*Assumptions!$C$33)*Assumptions!$C$34*(0.9+0.1*(Assumptions!$C$31+INDEX(Assumptions!$C$32:$F$32,MATCH(YEAR(G$3),Assumptions!$C$1:$F$1,0))))} -> 35797.5 | H25: {='Revenue forecast'!H35*(1-Assumptions!$C$31*Assumptions!$C$33)*Assumptions!$C$34*(0.9+0.1*(Assumptions!$C$31+INDEX(Assumptions!$C$32:$F$32,MATCH(YEAR(H$3),Assumptions!$C$1:$F$1,0))))} -> 0 | I25: {='Revenue forecast'!I35*(1-Assumptions!$C$31*Assumptions!$C$33)*Assumptions!$C$34*(0.9+0.1*(Assumptions!$C$31+INDEX(Assumptions!$C$32:$F$32,MATCH(YEAR(I$3),Assumptions!$C$1:$F$1,0))))} -> 0 | J25: {='Revenue forecast'!J35*(1-Assumptions!$C$31*Assumptions!$C$33)*Assumptions!$C$34*(0.9+0.1*(Assumptions!$C$31+INDEX(Assumptions!$C$32:$F$32,MATCH(YEAR(J$3),Assumptions!$C$1:$F$1,0))))} -> 0 | K25: {='Revenue forecast'!K35*(1-Assumptions!$C$31*Assumptions!$C$33)*Assumptions!$C$34*(0.9+0.1*(Assumptions!$C$31+INDEX(Assumptions!$C$32:$F$32,MATCH(YEAR(K$3),Assumptions!$C$1:$F$1,0))))} -> 7159.5 | L25: {='Revenue forecast'!L35*(1-Assumptions!$C$31*Assumptions!$C$33)*Assumptions!$C$34*(0.9+0.1*(Assumptions!$C$31+INDEX(Assumptions!$C$32:$F$32,MATCH(YEAR(L$3),Assumptions!$C$1:$F$1,0))))} -> 7159.5 | M25: {='Revenue forecast'!M35*(1-Assumptions!$C$31*Assumptions!$C$33)*Assumptions!$C$34*(0.9+0.1*(Assumptions!$C$31+INDEX(Assumptions!$C$32:$F$32,MATCH(YEAR(M$3),Assumptions!$C$1:$F$1,0))))} -> 7159.5 | ... BA25: {='Revenue forecast'!BA35*(1-Assumptions!$C$31*Assumptions!$C$33)*Assumptions!$C$34*(0.9+0.1*(Assumptions!$C$31+INDEX(Assumptions!$C$32:$F$32,MATCH(YEAR(BA$3),Assumptions!$C$1:$F$1,0))))} -> 337315.68 | BC25: =SUMPRODUCT((YEAR($F$3:$BA$3)=BC$3)*$F25:$BA25) -> 164668.5 | BD25: =SUMPRODUCT((YEAR($F$3:$BA$3)=BD$3)*$F25:$BA25) -> 512509.2 | BE25: =SUMPRODUCT((YEAR($F$3:$BA$3)=BE$3)*$F25:$BA25) -> 1151998.8 | BF25: =SUMPRODUCT((YEAR($F$3:$BA$3)=BF$3)*$F25:$BA25) -> 2521218.5
B26: Contractors / accountant | E26: € | F26: 0 | G26: 0 | H26: 0 | I26: 0 | J26: 0 | K26: 0 | L26: 0 | M26: 0 | N26: 0 | O26: 0 | P26: 0 | Q26: 0 | R26: 0 | S26: 0 | T26: 0 | U26: 0 | V26: 0 | W26: 0 | X26: 0 | Y26: 0 | Z26: 0 | AA26: 0 | AB26: 0 | AC26: 0 | AD26: 0 | AE26: 0 | AF26: 0 | AG26: 0 | AH26: 0 | AI26: 0 | AJ26: 0 | AK26: 0 | AL26: 0 | AM26: 0 | AN26: 0 | AO26: 0 | AP26: 0 | AQ26: 0 | AR26: 0 | AS26: 0 | AT26: 0 | AU26: 0 | AV26: 0 | AW26: 0 | AX26: 0 | AY26: 0 | AZ26: 0 | BA26: 0 | BC26: =SUMPRODUCT((YEAR($F$3:$BA$3)=BC$3)*$F26:$BA26) -> 0 | BD26: =SUMPRODUCT((YEAR($F$3:$BA$3)=BD$3)*$F26:$BA26) -> 0 | BE26: =SUMPRODUCT((YEAR($F$3:$BA$3)=BE$3)*$F26:$BA26) -> 0 | BF26: =SUMPRODUCT((YEAR($F$3:$BA$3)=BF$3)*$F26:$BA26) -> 0
B27: Other people costs | E27: € | F27: 267 | G27: 267 | H27: 267 | I27: 267 | J27: 267 | K27: 267 | L27: 267 | M27: 267 | N27: 267 | O27: 267 | P27: 267 | Q27: 267 | R27: 267 | S27: 267 | T27: 267 | U27: 267 | V27: 267 | W27: 267 | X27: 267 | Y27: 267 | Z27: 267 | AA27: 267 | AB27: 267 | AC27: 267 | AD27: 267 | AE27: 267 | AF27: 267 | AG27: 267 | AH27: 267 | AI27: 267 | AJ27: 267 | AK27: 267 | AL27: 267 | AM27: 267 | AN27: 267 | AO27: 267 | AP27: 267 | AQ27: 267 | AR27: 267 | AS27: 267 | AT27: 267 | AU27: 267 | AV27: 267 | AW27: 267 | AX27: 267 | AY27: 267 | AZ27: 267 | BA27: 267 | BC27: =SUMPRODUCT((YEAR($F$3:$BA$3)=BC$3)*$F27:$BA27) -> 3204 | BD27: =SUMPRODUCT((YEAR($F$3:$BA$3)=BD$3)*$F27:$BA27) -> 3204 | BE27: =SUMPRODUCT((YEAR($F$3:$BA$3)=BE$3)*$F27:$BA27) -> 3204 | BF27: =SUMPRODUCT((YEAR($F$3:$BA$3)=BF$3)*$F27:$BA27) -> 3204
B28: Total personnel | E28: € | F28: =SUM(F21:F27) -> 51749 | G28: =SUM(G21:G27) -> 87546.5 | H28: =SUM(H21:H27) -> 51749 | I28: =SUM(I21:I27) -> 51749 | J28: =SUM(J21:J27) -> 51749 | K28: =SUM(K21:K27) -> 62764.1 | L28: =SUM(L21:L27) -> 62764.1 | M28: =SUM(M21:M27) -> 62764.1 | ... BA28: =SUM(BA21:BA27) -> 462664.4 | BC28: =SUMPRODUCT((YEAR($F$3:$BA$3)=BC$3)*$F28:$BA28) -> 812645.7 | BD28: =SUMPRODUCT((YEAR($F$3:$BA$3)=BD$3)*$F28:$BA28) -> 1339217.3 | BE28: =SUMPRODUCT((YEAR($F$3:$BA$3)=BE$3)*$F28:$BA28) -> 2370138.4 | BF28: =SUMPRODUCT((YEAR($F$3:$BA$3)=BF$3)*$F28:$BA28) -> 3959857.9

Sheet OPEX
B2: OPEX — Monthly 2027–2030 (€)
E3: Unit | F3: 46388 | G3: 46419 | H3: 46447 | I3: 46478 | J3: 46508 | K3: 46539 | L3: 46569 | M3: 46600 | N3: 46631 | O3: 46661 | P3: 46692 | Q3: 46722 | R3: 46753 | S3: 46784 | T3: 46813 | U3: 46844 | V3: 46874 | W3: 46905 | X3: 46935 | Y3: 46966 | Z3: 46997 | AA3: 47027 | AB3: 47058 | AC3: 47088 | AD3: 47119 | AE3: 47150 | AF3: 47178 | AG3: 47209 | AH3: 47239 | AI3: 47270 | AJ3: 47300 | AK3: 47331 | AL3: 47362 | AM3: 47392 | AN3: 47423 | AO3: 47453 | AP3: 47484 | AQ3: 47515 | AR3: 47543 | AS3: 47574 | AT3: 47604 | AU3: 47635 | AV3: 47665 | AW3: 47696 | AX3: 47727 | AY3: 47757 | AZ3: 47788 | BA3: 47818 | BC3: 2027 | BD3: 2028 | BE3: 2029 | BF3: 2030
B6: OTHER OPEX
B7: Rent | E7: € | F7: =Personnel!F17*Assumptions!$C$56*IF(ISNUMBER(SEARCH("yr",Assumptions!$G$56)),1/12,1) -> 5400 | G7: =Personnel!G17*Assumptions!$C$56*IF(ISNUMBER(SEARCH("yr",Assumptions!$G$56)),1/12,1) -> 5400 | H7: =Personnel!H17*Assumptions!$C$56*IF(ISNUMBER(SEARCH("yr",Assumptions!$G$56)),1/12,1) -> 5400 | I7: =Personnel!I17*Assumptions!$C$56*IF(ISNUMBER(SEARCH("yr",Assumptions!$G$56)),1/12,1) -> 5400 | J7: =Personnel!J17*Assumptions!$C$56*IF(ISNUMBER(SEARCH("yr",Assumptions!$G$56)),1/12,1) -> 5400 | K7: =Personnel!K17*Assumptions!$C$56*IF(ISNUMBER(SEARCH("yr",Assumptions!$G$56)),1/12,1) -> 6000 | L7: =Personnel!L17*Assumptions!$C$56*IF(ISNUMBER(SEARCH("yr",Assumptions!$G$56)),1/12,1) -> 6000 | M7: =Personnel!M17*Assumptions!$C$56*IF(ISNUMBER(SEARCH("yr",Assumptions!$G$56)),1/12,1) -> 6000 | ... BA7: =Personnel!BA17*Assumptions!$C$56*IF(ISNUMBER(SEARCH("yr",Assumptions!$G$56)),1/12,1) -> 10200 | BC7: =SUMPRODUCT((YEAR($F$3:$BA$3)=BC$3)*$F7:$BA7) -> 69000 | BD7: =SUMPRODUCT((YEAR($F$3:$BA$3)=BD$3)*$F7:$BA7) -> 79200 | BE7: =SUMPRODUCT((YEAR($F$3:$BA$3)=BE$3)*$F7:$BA7) -> 105000 | BF7: =SUMPRODUCT((YEAR($F$3:$BA$3)=BF$3)*$F7:$BA7) -> 115200
