Workbook

Sheet Cover
B2: EVOLUTE
B4: Financial Model — 2027–2030
B6: Currency: EUR (€)
B7: Basis: monthly, aggregated to annual
B8: STRICTLY CONFIDENTIAL
B10: Contents
B11: Assumptions — all inputs & business drivers (edit here only)
B12: Revenue forecast — Growth Capital & M&A deal engine
B13: Personnel — headcount & salaries
B14: OPEX — operating costs
B15: Financial Statements — income statement
B16: Dashboard — annual summary

Sheet How to read me
B2: How to read this model
B4: STRUCTURE
B5: Assumptions → Revenue forecast → Personnel → OPEX → Financial Statements → Dashboard.
B6: Every tab is monthly (Jan 2027 – Dec 2030) with annual roll-up columns at the far right.
B8: HOW TO USE
B9: Change numbers ONLY on the Assumptions tab. All other tabs recalculate automatically.
B11: REVENUE LOGIC
B12: Two business lines: Growth Capital (retainer + success fee on ticket) and M&A (retainer + success fee on EV).
B13: Deals get bigger (M&A EV) and convert better over time; mix drifts 90/10 → 50/50.
B14: Industry partners source 25% of deals and take 25% of their retainer + fee.
B16: STAFFING
B17: 1 analyst per 3 live projects; associate at 10 live, 2nd at 15. Simon = delivery lead, Rob = partner + sales hire.

Sheet Assumptions
B1: Assumptions — Evolute (€)
B3: GROWTH CAPITAL
C4: 2027 | D4: 2028 | E4: 2029 | F4: 2030
B5: Retainer / month | C5: 7000 | G5: €/mo
B6: Avg engagement length | C6: 5 | G6: months
B7: Success fee % | C7: 0.02 | G7: %
B8: Ticket size | C8: 5000000 | D8: 7000000 | E8: 10000000 | F8: 15000000 | G8: €
B9: Close rate % | C9: 0.15 | D9: 0.18 | E9: 0.22 | F9: 0.25 | G9: %
B11: M&A
C12: 2027 | D12: 2028 | E12: 2029 | F12: 2030
B13: Retainer / month | C13: 8000 | G13: €/mo
B14: Avg engagement length | C14: 7 | G14: months
B15: Success fee % | C15: 0.02 | G15: %
B16: Enterprise value | C16: 12000000 | D16: 25000000 | E16: 42000000 | F16: 60000000 | G16: €
B17: Close rate % | C17: 0.5 | D17: 0.56 | E17: 0.63 | F17: 0.7 | G17: %
B19: DEAL FLOW
C20: 2027 | D20: 2028 | E20: 2029 | F20: 2030
B21: New deals started / yr | C21: 20 | D21: 40 | E21: 58 | F21: 74 | G21: #
B22: Growth Capital mix % | C22: 0.9 | D22: 0.77 | E22: 0.63 | F22: 0.5 | G22: %
B24: SOURCING & COMPENSATION | J24: is
B25: Industry-partner — share of deals they source % | C25: 0.25 | G25: %
B26: Sales-hire source share % | C26: 0.375 | G26: %
B27: Industry-partner — cut of those deals' revenue % | C27: 0.25 | G27: %
B28: Success-fee bonus pool % | C28: 0.4 | G28: %
B30: PERSONNEL
C31: 2027 | D31: 2028 | E31: 2029 | F31: 2030
B32: Rob salary / month | C32: =10000+2000*(C$31-2026) -> 12000 | D32: =10000+2000*(D$31-2026) -> 14000 | E32: =10000+2000*(E$31-2026) -> 16000 | F32: =10000+2000*(F$31-2026) -> 18000 | G32: €/mo
B33: Simon salary / month | C33: =6500+2000*(C$31-2026) -> 8500 | D33: =6500+2000*(D$31-2026) -> 10500 | E33: =6500+2000*(E$31-2026) -> 12500 | F33: =6500+2000*(F$31-2026) -> 14500 | G33: €/mo
B34: Analyst salary / month | C34: 3000 | G34: €/mo
B35: Associate salary / month | C35: 4500 | G35: €/mo
B36: Intern salary / month | C36: 500 | G36: €/mo
B37: Sales hire cost / yr | C37: 90000 | G37: €/yr
B38: Holiday pay % | C38: 0.08 | G38: %
B39: Employer tax % | C39: 0.19 | G39: %
B40: Live projects per analyst | C40: 3 | G40: #
B41: Associate trigger 1 (live proj) | C41: 10 | G41: #
B42: Associate trigger 2 (live proj) | C42: 15 | G42: #
B43: Starting interns | C43: 2 | G43: #
B45: OPEX (monthly)
B46: Rent / FTE | C46: 600 | G46: €/FTE
...

Sheet Revenue forecast
B2: Revenue forecast — Monthly 2027–2030 (€)
E3: Unit | F3: 46388 | G3: 46419 | H3: 46447 | I3: 46478 | J3: 46508 | K3: 46539 | L3: 46569 | M3: 46600 | N3: 46631 | O3: 46661 | P3: 46692 | Q3: 46722 | R3: 46753 | S3: 46784 | T3: 46813 | U3: 46844 | V3: 46874 | W3: 46905 | X3: 46935 | Y3: 46966 | Z3: 46997 | AA3: 47027 | AB3: 47058 | AC3: 47088 | AD3: 47119 | AE3: 47150 | AF3: 47178 | AG3: 47209 | AH3: 47239 | AI3: 47270 | AJ3: 47300 | AK3: 47331 | AL3: 47362 | AM3: 47392 | AN3: 47423 | AO3: 47453 | AP3: 47484 | AQ3: 47515 | AR3: 47543 | AS3: 47574 | AT3: 47604 | AU3: 47635 | AV3: 47665 | AW3: 47696 | AX3: 47727 | AY3: 47757 | AZ3: 47788 | BA3: 47818 | BC3: 2027 | BD3: 2028 | BE3: 2029 | BF3: 2030
B6: GROWTH CAPITAL
B7: New deals started | E7: # | F7: {=ROUND((INDEX(Assumptions!$C$21:$F$21,MATCH(YEAR(F$3),Assumptions!$C$4:$F$4,0))*INDEX(Assumptions!$C$22:$F$22,MATCH(YEAR(F$3),Assumptions!$C$4:$F$4,0)))*MONTH(F$3)/12,0)-ROUND((INDEX(Assumptions!$C$21:$F$21,MATCH(YEAR(F$3),Assumptions!$C$4:$F$4,0))*INDEX(Assumptions!$C$22:$F$22,MATCH(YEAR(F$3),Assumptions!$C$4:$F$4,0)))*(MONTH(F$3)-1)/12,0)} -> 2 | G7: {=ROUND((INDEX(Assumptions!$C$21:$F$21,MATCH(YEAR(G$3),Assumptions!$C$4:$F$4,0))*INDEX(Assumptions!$C$22:$F$22,MATCH(YEAR(G$3),Assumptions!$C$4:$F$4,0)))*MONTH(G$3)/12,0)-ROUND((INDEX(Assumptions!$C$21:$F$21,MATCH(YEAR(G$3),Assumptions!$C$4:$F$4,0))*INDEX(Assumptions!$C$22:$F$22,MATCH(YEAR(G$3),Assumptions!$C$4:$F$4,0)))*(MONTH(G$3)-1)/12,0)} -> 1 | H7: {=ROUND((INDEX(Assumptions!$C$21:$F$21,MATCH(YEAR(H$3),Assumptions!$C$4:$F$4,0))*INDEX(Assumptions!$C$22:$F$22,MATCH(YEAR(H$3),Assumptions!$C$4:$F$4,0)))*MONTH(H$3)/12,0)-ROUND((INDEX(Assumptions!$C$21:$F$21,MATCH(YEAR(H$3),Assumptions!$C$4:$F$4,0))*INDEX(Assumptions!$C$22:$F$22,MATCH(YEAR(H$3),Assumptions!$C$4:$F$4,0)))*(MONTH(H$3)-1)/12,0)} -> 2 | I7: {=ROUND((INDEX(Assumptions!$C$21:$F$21,MATCH(YEAR(I$3),Assumptions!$C$4:$F$4,0))*INDEX(Assumptions!$C$22:$F$22,MATCH(YEAR(I$3),Assumptions!$C$4:$F$4,0)))*MONTH(I$3)/12,0)-ROUND((INDEX(Assumptions!$C$21:$F$21,MATCH(YEAR(I$3),Assumptions!$C$4:$F$4,0))*INDEX(Assumptions!$C$22:$F$22,MATCH(YEAR(I$3),Assumptions!$C$4:$F$4,0)))*(MONTH(I$3)-1)/12,0)} -> 1 | J7: {=ROUND((INDEX(Assumptions!$C$21:$F$21,MATCH(YEAR(J$3),Assumptions!$C$4:$F$4,0))*INDEX(Assumptions!$C$22:$F$22,MATCH(YEAR(J$3),Assumptions!$C$4:$F$4,0)))*MONTH(J$3)/12,0)-ROUND((INDEX(Assumptions!$C$21:$F$21,MATCH(YEAR(J$3),Assumptions!$C$4:$F$4,0))*INDEX(Assumptions!$C$22:$F$22,MATCH(YEAR(J$3),Assumptions!$C$4:$F$4,0)))*(MONTH(J$3)-1)/12,0)} -> 2 | K7: {=ROUND((INDEX(Assumptions!$C$21:$F$21,MATCH(YEAR(K$3),Assumptions!$C$4:$F$4,0))*INDEX(Assumptions!$C$22:$F$22,MATCH(YEAR(K$3),Assumptions!$C$4:$F$4,0)))*MONTH(K$3)/12,0)-ROUND((INDEX(Assumptions!$C$21:$F$21,MATCH(YEAR(K$3),Assumptions!$C$4:$F$4,0))*INDEX(Assumptions!$C$22:$F$22,MATCH(YEAR(K$3),Assumptions!$C$4:$F$4,0)))*(MONTH(K$3)-1)/12,0)} -> 1 | L7: {=ROUND((INDEX(Assumptions!$C$21:$F$21,MATCH(YEAR(L$3),Assumptions!$C$4:$F$4,0))*INDEX(Assumptions!$C$22:$F$22,MATCH(YEAR(L$3),Assumptions!$C$4:$F$4,0)))*MONTH(L$3)/12,0)-ROUND((INDEX(Assumptions!$C$21:$F$21,MATCH(YEAR(L$3),Assumptions!$C$4:$F$4,0))*INDEX(Assumptions!$C$22:$F$22,MATCH(YEAR(L$3),Assumptions!$C$4:$F$4,0)))*(MONTH(L$3)-1)/12,0)} -> 2 | M7: {=ROUND((INDEX(Assumptions!$C$21:$F$21,MATCH(YEAR(M$3),Assumptions!$C$4:$F$4,0))*INDEX(Assumptions!$C$22:$F$22,MATCH(YEAR(M$3),Assumptions!$C$4:$F$4,0)))*MONTH(M$3)/12,0)-ROUND((INDEX(Assumptions!$C$21:$F$21,MATCH(YEAR(M$3),Assumptions!$C$4:$F$4,0))*INDEX(Assumptions!$C$22:$F$22,MATCH(YEAR(M$3),Assumptions!$C$4:$F$4,0)))*(MONTH(M$3)-1)/12,0)} -> 1 | ... BA7: {=ROUND((INDEX(Assumptions!$C$21:$F$21,MATCH(YEAR(BA$3),Assumptions!$C$4:$F$4,0))*INDEX(Assumptions!$C$22:$F$22,MATCH(YEAR(BA$3),Assumptions!$C$4:$F$4,0)))*MONTH(BA$3)/12,0)-ROUND((INDEX(Assumptions!$C$21:$F$21,MATCH(YEAR(BA$3),Assumptions!$C$4:$F$4,0))*INDEX(Assumptions!$C$22:$F$22,MATCH(YEAR(BA$3),Assumptions!$C$4:$F$4,0)))*(MONTH(BA$3)-1)/12,0)} -> 3 | BC7: =SUMPRODUCT((YEAR($F$3:$BA$3)=BC$3)*$F7:$BA7) -> 18 | BD7: =SUMPRODUCT((YEAR($F$3:$BA$3)=BD$3)*$F7:$BA7) -> 31 | BE7: =SUMPRODUCT((YEAR($F$3:$BA$3)=BE$3)*$F7:$BA7) -> 37 | BF7: =SUMPRODUCT((YEAR($F$3:$BA$3)=BF$3)*$F7:$BA7) -> 37
B8: Live projects | E8: # | F8: =SUM(F7) -> 2 | G8: =SUM(F7:G7) -> 3 | H8: =SUM(F7:H7) -> 5 | I8: =SUM(F7:I7) -> 6 | J8: =SUM(F7:J7) -> 8 | K8: =SUM(G7:K7) -> 7 | L8: =SUM(H7:L7) -> 8 | M8: =SUM(I7:M7) -> 7 | N8: =SUM(J7:N7) -> 8 | O8: =SUM(K7:O7) -> 7 | P8: =SUM(L7:P7) -> 8 | Q8: =SUM(M7:Q7) -> 7 | ... BA8: =SUM(AW7:BA7) -> 15 | BC8: =SUMPRODUCT((YEAR($F$3:$BA$3)=BC$3)*$F8:$BA8)/12 -> 6.3333333 | BD8: =SUMPRODUCT((YEAR($F$3:$BA$3)=BD$3)*$F8:$BA8)/12 -> 11.916667 | BE8: =SUMPRODUCT((YEAR($F$3:$BA$3)=BE$3)*$F8:$BA8)/12 -> 14.75 | BF8: =SUMPRODUCT((YEAR($F$3:$BA$3)=BF$3)*$F8:$BA8)/12 -> 15.75
B9: Retainer revenue | E9: € | F9: =F8*Assumptions!$C$5 -> 14000 | G9: =G8*Assumptions!$C$5 -> 21000 | H9: =H8*Assumptions!$C$5 -> 35000 | I9: =I8*Assumptions!$C$5 -> 42000 | J9: =J8*Assumptions!$C$5 -> 56000 | K9: =K8*Assumptions!$C$5 -> 49000 | L9: =L8*Assumptions!$C$5 -> 56000 | M9: =M8*Assumptions!$C$5 -> 49000 | ... BA9: =BA8*Assumptions!$C$5 -> 105000 | BC9: =SUMPRODUCT((YEAR($F$3:$BA$3)=BC$3)*$F9:$BA9) -> 532000 | BD9: =SUMPRODUCT((YEAR($F$3:$BA$3)=BD$3)*$F9:$BA9) -> 1001000 | BE9: =SUMPRODUCT((YEAR($F$3:$BA$3)=BE$3)*$F9:$BA9) -> 1239000 | BF9: =SUMPRODUCT((YEAR($F$3:$BA$3)=BF$3)*$F9:$BA9) -> 1323000
B10: Deals closed | E10: # | F10: 0 | G10: 0 | H10: 0 | I10: 0 | J10: 0 | K10: {=F7*INDEX(Assumptions!$C$9:$F$9,MATCH(YEAR(K$3),Assumptions!$C$4:$F$4,0))} -> 0.3 | L10: {=G7*INDEX(Assumptions!$C$9:$F$9,MATCH(YEAR(L$3),Assumptions!$C$4:$F$4,0))} -> 0.15 | M10: {=H7*INDEX(Assumptions!$C$9:$F$9,MATCH(YEAR(M$3),Assumptions!$C$4:$F$4,0))} -> 0.3 | N10: {=I7*INDEX(Assumptions!$C$9:$F$9,MATCH(YEAR(N$3),Assumptions!$C$4:$F$4,0))} -> 0.15 | O10: {=J7*INDEX(Assumptions!$C$9:$F$9,MATCH(YEAR(O$3),Assumptions!$C$4:$F$4,0))} -> 0.3 | P10: {=K7*INDEX(Assumptions!$C$9:$F$9,MATCH(YEAR(P$3),Assumptions!$C$4:$F$4,0))} -> 0.15 | Q10: {=L7*INDEX(Assumptions!$C$9:$F$9,MATCH(YEAR(Q$3),Assumptions!$C$4:$F$4,0))} -> 0.3 | R10: {=M7*INDEX(Assumptions!$C$9:$F$9,MATCH(YEAR(R$3),Assumptions!$C$4:$F$4,0))} -> 0.18 | ... BA10: {=AV7*INDEX(Assumptions!$C$9:$F$9,MATCH(YEAR(BA$3),Assumptions!$C$4:$F$4,0))} -> 0.75 | BC10: =SUMPRODUCT((YEAR($F$3:$BA$3)=BC$3)*$F10:$BA10) -> 1.65 | BD10: =SUMPRODUCT((YEAR($F$3:$BA$3)=BD$3)*$F10:$BA10) -> 4.5 | BE10: =SUMPRODUCT((YEAR($F$3:$BA$3)=BE$3)*$F10:$BA10) -> 7.48 | BF10: =SUMPRODUCT((YEAR($F$3:$BA$3)=BF$3)*$F10:$BA10) -> 9.5
B11: Success fees | E11: € | F11: {=F10*(INDEX(Assumptions!$C$8:$F$8,MATCH(YEAR(F$3),Assumptions!$C$4:$F$4,0))*Assumptions!$C$7)} -> 0 | G11: {=G10*(INDEX(Assumptions!$C$8:$F$8,MATCH(YEAR(G$3),Assumptions!$C$4:$F$4,0))*Assumptions!$C$7)} -> 0 | H11: {=H10*(INDEX(Assumptions!$C$8:$F$8,MATCH(YEAR(H$3),Assumptions!$C$4:$F$4,0))*Assumptions!$C$7)} -> 0 | I11: {=I10*(INDEX(Assumptions!$C$8:$F$8,MATCH(YEAR(I$3),Assumptions!$C$4:$F$4,0))*Assumptions!$C$7)} -> 0 | J11: {=J10*(INDEX(Assumptions!$C$8:$F$8,MATCH(YEAR(J$3),Assumptions!$C$4:$F$4,0))*Assumptions!$C$7)} -> 0 | K11: {=K10*(INDEX(Assumptions!$C$8:$F$8,MATCH(YEAR(K$3),Assumptions!$C$4:$F$4,0))*Assumptions!$C$7)} -> 30000 | L11: {=L10*(INDEX(Assumptions!$C$8:$F$8,MATCH(YEAR(L$3),Assumptions!$C$4:$F$4,0))*Assumptions!$C$7)} -> 15000 | M11: {=M10*(INDEX(Assumptions!$C$8:$F$8,MATCH(YEAR(M$3),Assumptions!$C$4:$F$4,0))*Assumptions!$C$7)} -> 30000 | ... BA11: {=BA10*(INDEX(Assumptions!$C$8:$F$8,MATCH(YEAR(BA$3),Assumptions!$C$4:$F$4,0))*Assumptions!$C$7)} -> 225000 | BC11: =SUMPRODUCT((YEAR($F$3:$BA$3)=BC$3)*$F11:$BA11) -> 165000 | BD11: =SUMPRODUCT((YEAR($F$3:$BA$3)=BD$3)*$F11:$BA11) -> 630000 | BE11: =SUMPRODUCT((YEAR($F$3:$BA$3)=BE$3)*$F11:$BA11) -> 1496000 | BF11: =SUMPRODUCT((YEAR($F$3:$BA$3)=BF$3)*$F11:$BA11) -> 2850000
B12: Total Growth revenue | E12: € | F12: =F9+F11 -> 14000 | G12: =G9+G11 -> 21000 | H12: =H9+H11 -> 35000 | I12: =I9+I11 -> 42000 | J12: =J9+J11 -> 56000 | K12: =K9+K11 -> 79000 | L12: =L9+L11 -> 71000 | M12: =M9+M11 -> 79000 | ... BA12: =BA9+BA11 -> 330000 | BC12: =SUMPRODUCT((YEAR($F$3:$BA$3)=BC$3)*$F12:$BA12) -> 697000 | BD12: =SUMPRODUCT((YEAR($F$3:$BA$3)=BD$3)*$F12:$BA12) -> 1631000 | BE12: =SUMPRODUCT((YEAR($F$3:$BA$3)=BE$3)*$F12:$BA12) -> 2735000 | BF12: =SUMPRODUCT((YEAR($F$3:$BA$3)=BF$3)*$F12:$BA12) -> 4173000
B14: M&A
B15: New deals started | E15: # | F15: {=ROUND((INDEX(Assumptions!$C$21:$F$21,MATCH(YEAR(F$3),Assumptions!$C$4:$F$4,0))*(1-INDEX(Assumptions!$C$22:$F$22,MATCH(YEAR(F$3),Assumptions!$C$4:$F$4,0))))*MONTH(F$3)/12,0)-ROUND((INDEX(Assumptions!$C$21:$F$21,MATCH(YEAR(F$3),Assumptions!$C$4:$F$4,0))*(1-INDEX(Assumptions!$C$22:$F$22,MATCH(YEAR(F$3),Assumptions!$C$4:$F$4,0))))*(MONTH(F$3)-1)/12,0)} -> 0 | G15: {=ROUND((INDEX(Assumptions!$C$21:$F$21,MATCH(YEAR(G$3),Assumptions!$C$4:$F$4,0))*(1-INDEX(Assumptions!$C$22:$F$22,MATCH(YEAR(G$3),Assumptions!$C$4:$F$4,0))))*MONTH(G$3)/12,0)-ROUND((INDEX(Assumptions!$C$21:$F$21,MATCH(YEAR(G$3),Assumptions!$C$4:$F$4,0))*(1-INDEX(Assumptions!$C$22:$F$22,MATCH(YEAR(G$3),Assumptions!$C$4:$F$4,0))))*(MONTH(G$3)-1)/12,0)} -> 0 | H15: {=ROUND((INDEX(Assumptions!$C$21:$F$21,MATCH(YEAR(H$3),Assumptions!$C$4:$F$4,0))*(1-INDEX(Assumptions!$C$22:$F$22,MATCH(YEAR(H$3),Assumptions!$C$4:$F$4,0))))*MONTH(H$3)/12,0)-ROUND((INDEX(Assumptions!$C$21:$F$21,MATCH(YEAR(H$3),Assumptions!$C$4:$F$4,0))*(1-INDEX(Assumptions!$C$22:$F$22,MATCH(YEAR(H$3),Assumptions!$C$4:$F$4,0))))*(MONTH(H$3)-1)/12,0)} -> 1 | I15: {=ROUND((INDEX(Assumptions!$C$21:$F$21,MATCH(YEAR(I$3),Assumptions!$C$4:$F$4,0))*(1-INDEX(Assumptions!$C$22:$F$22,MATCH(YEAR(I$3),Assumptions!$C$4:$F$4,0))))*MONTH(I$3)/12,0)-ROUND((INDEX(Assumptions!$C$21:$F$21,MATCH(YEAR(I$3),Assumptions!$C$4:$F$4,0))*(1-INDEX(Assumptions!$C$22:$F$22,MATCH(YEAR(I$3),Assumptions!$C$4:$F$4,0))))*(MONTH(I$3)-1)/12,0)} -> 0 | J15: {=ROUND((INDEX(Assumptions!$C$21:$F$21,MATCH(YEAR(J$3),Assumptions!$C$4:$F$4,0))*(1-INDEX(Assumptions!$C$22:$F$22,MATCH(YEAR(J$3),Assumptions!$C$4:$F$4,0))))*MONTH(J$3)/12,0)-ROUND((INDEX(Assumptions!$C$21:$F$21,MATCH(YEAR(J$3),Assumptions!$C$4:$F$4,0))*(1-INDEX(Assumptions!$C$22:$F$22,MATCH(YEAR(J$3),Assumptions!$C$4:$F$4,0))))*(MONTH(J$3)-1)/12,0)} -> 0 | K15: {=ROUND((INDEX(Assumptions!$C$21:$F$21,MATCH(YEAR(K$3),Assumptions!$C$4:$F$4,0))*(1-INDEX(Assumptions!$C$22:$F$22,MATCH(YEAR(K$3),Assumptions!$C$4:$F$4,0))))*MONTH(K$3)/12,0)-ROUND((INDEX(Assumptions!$C$21:$F$21,MATCH(YEAR(K$3),Assumptions!$C$4:$F$4,0))*(1-INDEX(Assumptions!$C$22:$F$22,MATCH(YEAR(K$3),Assumptions!$C$4:$F$4,0))))*(MONTH(K$3)-1)/12,0)} -> 0 | L15: {=ROUND((INDEX(Assumptions!$C$21:$F$21,MATCH(YEAR(L$3),Assumptions!$C$4:$F$4,0))*(1-INDEX(Assumptions!$C$22:$F$22,MATCH(YEAR(L$3),Assumptions!$C$4:$F$4,0))))*MONTH(L$3)/12,0)-ROUND((INDEX(Assumptions!$C$21:$F$21,MATCH(YEAR(L$3),Assumptions!$C$4:$F$4,0))*(1-INDEX(Assumptions!$C$22:$F$22,MATCH(YEAR(L$3),Assumptions!$C$4:$F$4,0))))*(MONTH(L$3)-1)/12,0)} -> 0 | M15: {=ROUND((INDEX(Assumptions!$C$21:$F$21,MATCH(YEAR(M$3),Assumptions!$C$4:$F$4,0))*(1-INDEX(Assumptions!$C$22:$F$22,MATCH(YEAR(M$3),Assumptions!$C$4:$F$4,0))))*MONTH(M$3)/12,0)-ROUND((INDEX(Assumptions!$C$21:$F$21,MATCH(YEAR(M$3),Assumptions!$C$4:$F$4,0))*(1-INDEX(Assumptions!$C$22:$F$22,MATCH(YEAR(M$3),Assumptions!$C$4:$F$4,0))))*(MONTH(M$3)-1)/12,0)} -> 0 | ... BA15: {=ROUND((INDEX(Assumptions!$C$21:$F$21,MATCH(YEAR(BA$3),Assumptions!$C$4:$F$4,0))*(1-INDEX(Assumptions!$C$22:$F$22,MATCH(YEAR(BA$3),Assumptions!$C$4:$F$4,0))))*MONTH(BA$3)/12,0)-ROUND((INDEX(Assumptions!$C$21:$F$21,MATCH(YEAR(BA$3),Assumptions!$C$4:$F$4,0))*(1-INDEX(Assumptions!$C$22:$F$22,MATCH(YEAR(BA$3),Assumptions!$C$4:$F$4,0))))*(MONTH(BA$3)-1)/12,0)} -> 3 | BC15: =SUMPRODUCT((YEAR($F$3:$BA$3)=BC$3)*$F15:$BA15) -> 2 | BD15: =SUMPRODUCT((YEAR($F$3:$BA$3)=BD$3)*$F15:$BA15) -> 9 | BE15: =SUMPRODUCT((YEAR($F$3:$BA$3)=BE$3)*$F15:$BA15) -> 21 | BF15: =SUMPRODUCT((YEAR($F$3:$BA$3)=BF$3)*$F15:$BA15) -> 37
B16: Live projects | E16: # | F16: =SUM(F15) -> 0 | G16: =SUM(F15:G15) -> 0 | H16: =SUM(F15:H15) -> 1 | I16: =SUM(F15:I15) -> 1 | J16: =SUM(F15:J15) -> 1 | K16: =SUM(F15:K15) -> 1 | L16: =SUM(F15:L15) -> 1 | M16: =SUM(G15:M15) -> 1 | N16: =SUM(H15:N15) -> 2 | O16: =SUM(I15:O15) -> 1 | P16: =SUM(J15:P15) -> 1 | Q16: =SUM(K15:Q15) -> 1 | R16: =SUM(L15:R15) -> 2 | S16: =SUM(M15:S15) -> 3 | ... BA16: =SUM(AU15:BA15) -> 22 | BC16: =SUMPRODUCT((YEAR($F$3:$BA$3)=BC$3)*$F16:$BA16)/12 -> 0.91666667 | BD16: =SUMPRODUCT((YEAR($F$3:$BA$3)=BD$3)*$F16:$BA16)/12 -> 4.25 | BE16: =SUMPRODUCT((YEAR($F$3:$BA$3)=BE$3)*$F16:$BA16)/12 -> 10.666667 | BF16: =SUMPRODUCT((YEAR($F$3:$BA$3)=BF$3)*$F16:$BA16)/12 -> 19.166667
B17: Retainer revenue | E17: € | F17: =F16*Assumptions!$C$13 -> 0 | G17: =G16*Assumptions!$C$13 -> 0 | H17: =H16*Assumptions!$C$13 -> 8000 | I17: =I16*Assumptions!$C$13 -> 8000 | J17: =J16*Assumptions!$C$13 -> 8000 | K17: =K16*Assumptions!$C$13 -> 8000 | L17: =L16*Assumptions!$C$13 -> 8000 | M17: =M16*Assumptions!$C$13 -> 8000 | ... BA17: =BA16*Assumptions!$C$13 -> 176000 | BC17: =SUMPRODUCT((YEAR($F$3:$BA$3)=BC$3)*$F17:$BA17) -> 88000 | BD17: =SUMPRODUCT((YEAR($F$3:$BA$3)=BD$3)*$F17:$BA17) -> 408000 | BE17: =SUMPRODUCT((YEAR($F$3:$BA$3)=BE$3)*$F17:$BA17) -> 1024000 | BF17: =SUMPRODUCT((YEAR($F$3:$BA$3)=BF$3)*$F17:$BA17) -> 1840000
B18: Deals closed | E18: # | F18: 0 | G18: 0 | H18: 0 | I18: 0 | J18: 0 | K18: 0 | L18: 0 | M18: {=F15*INDEX(Assumptions!$C$17:$F$17,MATCH(YEAR(M$3),Assumptions!$C$4:$F$4,0))} -> 0 | N18: {=G15*INDEX(Assumptions!$C$17:$F$17,MATCH(YEAR(N$3),Assumptions!$C$4:$F$4,0))} -> 0 | O18: {=H15*INDEX(Assumptions!$C$17:$F$17,MATCH(YEAR(O$3),Assumptions!$C$4:$F$4,0))} -> 0.5 | P18: {=I15*INDEX(Assumptions!$C$17:$F$17,MATCH(YEAR(P$3),Assumptions!$C$4:$F$4,0))} -> 0 | Q18: {=J15*INDEX(Assumptions!$C$17:$F$17,MATCH(YEAR(Q$3),Assumptions!$C$4:$F$4,0))} -> 0 | R18: {=K15*INDEX(Assumptions!$C$17:$F$17,MATCH(YEAR(R$3),Assumptions!$C$4:$F$4,0))} -> 0 | S18: {=L15*INDEX(Assumptions!$C$17:$F$17,MATCH(YEAR(S$3),Assumptions!$C$4:$F$4,0))} -> 0 | T18: {=M15*INDEX(Assumptions!$C$17:$F$17,MATCH(YEAR(T$3),Assumptions!$C$4:$F$4,0))} -> 0 | ... BA18: {=AT15*INDEX(Assumptions!$C$17:$F$17,MATCH(YEAR(BA$3),Assumptions!$C$4:$F$4,0))} -> 2.1 | BC18: =SUMPRODUCT((YEAR($F$3:$BA$3)=BC$3)*$F18:$BA18) -> 0.5 | BD18: =SUMPRODUCT((YEAR($F$3:$BA$3)=BD$3)*$F18:$BA18) -> 2.8 | BE18: =SUMPRODUCT((YEAR($F$3:$BA$3)=BE$3)*$F18:$BA18) -> 8.82 | BF18: =SUMPRODUCT((YEAR($F$3:$BA$3)=BF$3)*$F18:$BA18) -> 18.9
B19: Success fees | E19: € | F19: {=F18*(INDEX(Assumptions!$C$16:$F$16,MATCH(YEAR(F$3),Assumptions!$C$4:$F$4,0))*Assumptions!$C$15)} -> 0 | G19: {=G18*(INDEX(Assumptions!$C$16:$F$16,MATCH(YEAR(G$3),Assumptions!$C$4:$F$4,0))*Assumptions!$C$15)} -> 0 | H19: {=H18*(INDEX(Assumptions!$C$16:$F$16,MATCH(YEAR(H$3),Assumptions!$C$4:$F$4,0))*Assumptions!$C$15)} -> 0 | I19: {=I18*(INDEX(Assumptions!$C$16:$F$16,MATCH(YEAR(I$3),Assumptions!$C$4:$F$4,0))*Assumptions!$C$15)} -> 0 | J19: {=J18*(INDEX(Assumptions!$C$16:$F$16,MATCH(YEAR(J$3),Assumptions!$C$4:$F$4,0))*Assumptions!$C$15)} -> 0 | K19: {=K18*(INDEX(Assumptions!$C$16:$F$16,MATCH(YEAR(K$3),Assumptions!$C$4:$F$4,0))*Assumptions!$C$15)} -> 0 | L19: {=L18*(INDEX(Assumptions!$C$16:$F$16,MATCH(YEAR(L$3),Assumptions!$C$4:$F$4,0))*Assumptions!$C$15)} -> 0 | M19: {=M18*(INDEX(Assumptions!$C$16:$F$16,MATCH(YEAR(M$3),Assumptions!$C$4:$F$4,0))*Assumptions!$C$15)} -> 0 | ... BA19: {=BA18*(INDEX(Assumptions!$C$16:$F$16,MATCH(YEAR(BA$3),Assumptions!$C$4:$F$4,0))*Assumptions!$C$15)} -> 2520000 | BC19: =SUMPRODUCT((YEAR($F$3:$BA$3)=BC$3)*$F19:$BA19) -> 120000 | BD19: =SUMPRODUCT((YEAR($F$3:$BA$3)=BD$3)*$F19:$BA19) -> 1400000 | BE19: =SUMPRODUCT((YEAR($F$3:$BA$3)=BE$3)*$F19:$BA19) -> 7408800 | BF19: =SUMPRODUCT((YEAR($F$3:$BA$3)=BF$3)*$F19:$BA19) -> 22680000
B20: Total M&A revenue | E20: € | F20: =F17+F19 -> 0 | G20: =G17+G19 -> 0 | H20: =H17+H19 -> 8000 | I20: =I17+I19 -> 8000 | J20: =J17+J19 -> 8000 | K20: =K17+K19 -> 8000 | L20: =L17+L19 -> 8000 | M20: =M17+M19 -> 8000 | ... BA20: =BA17+BA19 -> 2696000 | BC20: =SUMPRODUCT((YEAR($F$3:$BA$3)=BC$3)*$F20:$BA20) -> 208000 | BD20: =SUMPRODUCT((YEAR($F$3:$BA$3)=BD$3)*$F20:$BA20) -> 1808000 | BE20: =SUMPRODUCT((YEAR($F$3:$BA$3)=BE$3)*$F20:$BA20) -> 8432800 | BF20: =SUMPRODUCT((YEAR($F$3:$BA$3)=BF$3)*$F20:$BA20) -> 24520000
B22: TOTAL REVENUE
B23: Total retainer | E23: € | F23: =F9+F17 -> 14000 | G23: =G9+G17 -> 21000 | H23: =H9+H17 -> 43000 | I23: =I9+I17 -> 50000 | J23: =J9+J17 -> 64000 | K23: =K9+K17 -> 57000 | L23: =L9+L17 -> 64000 | M23: =M9+M17 -> 57000 | ... BA23: =BA9+BA17 -> 281000 | BC23: =SUMPRODUCT((YEAR($F$3:$BA$3)=BC$3)*$F23:$BA23) -> 620000 | BD23: =SUMPRODUCT((YEAR($F$3:$BA$3)=BD$3)*$F23:$BA23) -> 1409000 | BE23: =SUMPRODUCT((YEAR($F$3:$BA$3)=BE$3)*$F23:$BA23) -> 2263000 | BF23: =SUMPRODUCT((YEAR($F$3:$BA$3)=BF$3)*$F23:$BA23) -> 3163000
B24: Total success fees | E24: € | F24: =F11+F19 -> 0 | G24: =G11+G19 -> 0 | H24: =H11+H19 -> 0 | I24: =I11+I19 -> 0 | J24: =J11+J19 -> 0 | K24: =K11+K19 -> 30000 | L24: =L11+L19 -> 15000 | M24: =M11+M19 -> 30000 | ... BA24: =BA11+BA19 -> 2745000 | BC24: =SUMPRODUCT((YEAR($F$3:$BA$3)=BC$3)*$F24:$BA24) -> 285000 | BD24: =SUMPRODUCT((YEAR($F$3:$BA$3)=BD$3)*$F24:$BA24) -> 2030000 | BE24: =SUMPRODUCT((YEAR($F$3:$BA$3)=BE$3)*$F24:$BA24) -> 8904800 | BF24: =SUMPRODUCT((YEAR($F$3:$BA$3)=BF$3)*$F24:$BA24) -> 25530000
B25: Total revenue (gross) | E25: € | F25: =F23+F24 -> 14000 | G25: =G23+G24 -> 21000 | H25: =H23+H24 -> 43000 | I25: =I23+I24 -> 50000 | J25: =J23+J24 -> 64000 | K25: =K23+K24 -> 87000 | L25: =L23+L24 -> 79000 | M25: =M23+M24 -> 87000 | ... BA25: =BA23+BA24 -> 3026000 | BC25: =SUMPRODUCT((YEAR($F$3:$BA$3)=BC$3)*$F25:$BA25) -> 905000 | BD25: =SUMPRODUCT((YEAR($F$3:$BA$3)=BD$3)*$F25:$BA25) -> 3439000 | BE25: =SUMPRODUCT((YEAR($F$3:$BA$3)=BE$3)*$F25:$BA25) -> 11167800 | BF25: =SUMPRODUCT((YEAR($F$3:$BA$3)=BF$3)*$F25:$BA25) -> 28693000
B26: Less: industry-partner share | E26: € | F26: =-Assumptions!$C$25*Assumptions!$C$27*F25 -> -875 | G26: =-Assumptions!$C$25*Assumptions!$C$27*G25 -> -1312.5 | H26: =-Assumptions!$C$25*Assumptions!$C$27*H25 -> -2687.5 | I26: =-Assumptions!$C$25*Assumptions!$C$27*I25 -> -3125 | J26: =-Assumptions!$C$25*Assumptions!$C$27*J25 -> -4000 | K26: =-Assumptions!$C$25*Assumptions!$C$27*K25 -> -5437.5 | L26: =-Assumptions!$C$25*Assumptions!$C$27*L25 -> -4937.5 | M26: =-Assumptions!$C$25*Assumptions!$C$27*M25 -> -5437.5 | ... BA26: =-Assumptions!$C$25*Assumptions!$C$27*BA25 -> -189125 | BC26: =SUMPRODUCT((YEAR($F$3:$BA$3)=BC$3)*$F26:$BA26) -> -56562.5 | BD26: =SUMPRODUCT((YEAR($F$3:$BA$3)=BD$3)*$F26:$BA26) -> -214937.5 | BE26: =SUMPRODUCT((YEAR($F$3:$BA$3)=BE$3)*$F26:$BA26) -> -697987.5 | BF26: =SUMPRODUCT((YEAR($F$3:$BA$3)=BF$3)*$F26:$BA26) -> -1793312.5
B27: Net revenue | E27: € | F27: =F25+F26 -> 13125 | G27: =G25+G26 -> 19687.5 | H27: =H25+H26 -> 40312.5 | I27: =I25+I26 -> 46875 | J27: =J25+J26 -> 60000 | K27: =K25+K26 -> 81562.5 | L27: =L25+L26 -> 74062.5 | M27: =M25+M26 -> 81562.5 | ... BA27: =BA25+BA26 -> 2836875 | BC27: =SUMPRODUCT((YEAR($F$3:$BA$3)=BC$3)*$F27:$BA27) -> 848437.5 | BD27: =SUMPRODUCT((YEAR($F$3:$BA$3)=BD$3)*$F27:$BA27) -> 3224062.5 | BE27: =SUMPRODUCT((YEAR($F$3:$BA$3)=BE$3)*$F27:$BA27) -> 10469812 | BF27: =SUMPRODUCT((YEAR($F$3:$BA$3)=BF$3)*$F27:$BA27) -> 26899688

Sheet Personnel
B2: Personnel — Monthly 2027–2030 (€)
E3: Unit | F3: 46388 | G3: 46419 | H3: 46447 | I3: 46478 | J3: 46508 | K3: 46539 | L3: 46569 | M3: 46600 | N3: 46631 | O3: 46661 | P3: 46692 | Q3: 46722 | R3: 46753 | S3: 46784 | T3: 46813 | U3: 46844 | V3: 46874 | W3: 46905 | X3: 46935 | Y3: 46966 | Z3: 46997 | AA3: 47027 | AB3: 47058 | AC3: 47088 | AD3: 47119 | AE3: 47150 | AF3: 47178 | AG3: 47209 | AH3: 47239 | AI3: 47270 | AJ3: 47300 | AK3: 47331 | AL3: 47362 | AM3: 47392 | AN3: 47423 | AO3: 47453 | AP3: 47484 | AQ3: 47515 | AR3: 47543 | AS3: 47574 | AT3: 47604 | AU3: 47635 | AV3: 47665 | AW3: 47696 | AX3: 47727 | AY3: 47757 | AZ3: 47788 | BA3: 47818 | BC3: 2027 | BD3: 2028 | BE3: 2029 | BF3: 2030
B6: HEADCOUNT
B7: Live projects (total) | E7: # | F7: ='Revenue forecast'!F8+'Revenue forecast'!F16 -> 2 | G7: ='Revenue forecast'!G8+'Revenue forecast'!G16 -> 3 | H7: ='Revenue forecast'!H8+'Revenue forecast'!H16 -> 6 | I7: ='Revenue forecast'!I8+'Revenue forecast'!I16 -> 7 | J7: ='Revenue forecast'!J8+'Revenue forecast'!J16 -> 9 | K7: ='Revenue forecast'!K8+'Revenue forecast'!K16 -> 8 | L7: ='Revenue forecast'!L8+'Revenue forecast'!L16 -> 9 | M7: ='Revenue forecast'!M8+'Revenue forecast'!M16 -> 8 | ... BA7: ='Revenue forecast'!BA8+'Revenue forecast'!BA16 -> 37 | BC7: =Q7 -> 8 | BD7: =AC7 -> 18 | BE7: =AO7 -> 28 | BF7: =BA7 -> 37
B8: Analysts | E8: # | F8: =MAX(1,CEILING(F7/Assumptions!$C$40,1)) -> 1 | G8: =MAX(1,CEILING(G7/Assumptions!$C$40,1)) -> 1 | H8: =MAX(1,CEILING(H7/Assumptions!$C$40,1)) -> 2 | I8: =MAX(1,CEILING(I7/Assumptions!$C$40,1)) -> 3 | J8: =MAX(1,CEILING(J7/Assumptions!$C$40,1)) -> 3 | K8: =MAX(1,CEILING(K7/Assumptions!$C$40,1)) -> 3 | L8: =MAX(1,CEILING(L7/Assumptions!$C$40,1)) -> 3 | M8: =MAX(1,CEILING(M7/Assumptions!$C$40,1)) -> 3 | ... BA8: =MAX(1,CEILING(BA7/Assumptions!$C$40,1)) -> 13 | BC8: =Q8 -> 3 | BD8: =AC8 -> 6 | BE8: =AO8 -> 10 | BF8: =BA8 -> 13
B9: Associates | E9: # | F9: =IF(F7>=Assumptions!$C$42,2,IF(F7>=Assumptions!$C$41,1,0)) -> 0 | G9: =IF(G7>=Assumptions!$C$42,2,IF(G7>=Assumptions!$C$41,1,0)) -> 0 | H9: =IF(H7>=Assumptions!$C$42,2,IF(H7>=Assumptions!$C$41,1,0)) -> 0 | I9: =IF(I7>=Assumptions!$C$42,2,IF(I7>=Assumptions!$C$41,1,0)) -> 0 | J9: =IF(J7>=Assumptions!$C$42,2,IF(J7>=Assumptions!$C$41,1,0)) -> 0 | K9: =IF(K7>=Assumptions!$C$42,2,IF(K7>=Assumptions!$C$41,1,0)) -> 0 | L9: =IF(L7>=Assumptions!$C$42,2,IF(L7>=Assumptions!$C$41,1,0)) -> 0 | M9: =IF(M7>=Assumptions!$C$42,2,IF(M7>=Assumptions!$C$41,1,0)) -> 0 | ... BA9: =IF(BA7>=Assumptions!$C$42,2,IF(BA7>=Assumptions!$C$41,1,0)) -> 2 | BC9: =Q9 -> 0 | BD9: =AC9 -> 2 | BE9: =AO9 -> 2 | BF9: =BA9 -> 2
B10: Interns | E10: # | F10: =Assumptions!$C$43 -> 2 | G10: =Assumptions!$C$43 -> 2 | H10: =Assumptions!$C$43 -> 2 | I10: =Assumptions!$C$43 -> 2 | J10: =Assumptions!$C$43 -> 2 | K10: =Assumptions!$C$43 -> 2 | L10: =Assumptions!$C$43 -> 2 | M10: =Assumptions!$C$43 -> 2 | ... BA10: =Assumptions!$C$43 -> 2 | BC10: =Q10 -> 2 | BD10: =AC10 -> 2 | BE10: =AO10 -> 2 | BF10: =BA10 -> 2
B11: Sales hire | E11: # | F11: 1 | G11: 1 | H11: 1 | I11: 1 | J11: 1 | K11: 1 | L11: 1 | M11: 1 | N11: 1 | O11: 1 | P11: 1 | Q11: 1 | R11: 1 | S11: 1 | T11: 1 | U11: 1 | V11: 1 | W11: 1 | X11: 1 | Y11: 1 | Z11: 1 | AA11: 1 | AB11: 1 | AC11: 1 | AD11: 1 | AE11: 1 | AF11: 1 | AG11: 1 | AH11: 1 | AI11: 1 | AJ11: 1 | AK11: 1 | AL11: 1 | AM11: 1 | AN11: 1 | AO11: 1 | AP11: 1 | AQ11: 1 | AR11: 1 | AS11: 1 | AT11: 1 | AU11: 1 | AV11: 1 | AW11: 1 | AX11: 1 | AY11: 1 | AZ11: 1 | BA11: 1 | BC11: =Q11 -> 1 | BD11: =AC11 -> 1 | BE11: =AO11 -> 1 | BF11: =BA11 -> 1
B12: Rob (Partner) | E12: # | F12: 1 | G12: 1 | H12: 1 | I12: 1 | J12: 1 | K12: 1 | L12: 1 | M12: 1 | N12: 1 | O12: 1 | P12: 1 | Q12: 1 | R12: 1 | S12: 1 | T12: 1 | U12: 1 | V12: 1 | W12: 1 | X12: 1 | Y12: 1 | Z12: 1 | AA12: 1 | AB12: 1 | AC12: 1 | AD12: 1 | AE12: 1 | AF12: 1 | AG12: 1 | AH12: 1 | AI12: 1 | AJ12: 1 | AK12: 1 | AL12: 1 | AM12: 1 | AN12: 1 | AO12: 1 | AP12: 1 | AQ12: 1 | AR12: 1 | AS12: 1 | AT12: 1 | AU12: 1 | AV12: 1 | AW12: 1 | AX12: 1 | AY12: 1 | AZ12: 1 | BA12: 1 | BC12: =Q12 -> 1 | BD12: =AC12 -> 1 | BE12: =AO12 -> 1 | BF12: =BA12 -> 1
B13: Simon (Client Lead) | E13: # | F13: 1 | G13: 1 | H13: 1 | I13: 1 | J13: 1 | K13: 1 | L13: 1 | M13: 1 | N13: 1 | O13: 1 | P13: 1 | Q13: 1 | R13: 1 | S13: 1 | T13: 1 | U13: 1 | V13: 1 | W13: 1 | X13: 1 | Y13: 1 | Z13: 1 | AA13: 1 | AB13: 1 | AC13: 1 | AD13: 1 | AE13: 1 | AF13: 1 | AG13: 1 | AH13: 1 | AI13: 1 | AJ13: 1 | AK13: 1 | AL13: 1 | AM13: 1 | AN13: 1 | AO13: 1 | AP13: 1 | AQ13: 1 | AR13: 1 | AS13: 1 | AT13: 1 | AU13: 1 | AV13: 1 | AW13: 1 | AX13: 1 | AY13: 1 | AZ13: 1 | BA13: 1 | BC13: =Q13 -> 1 | BD13: =AC13 -> 1 | BE13: =AO13 -> 1 | BF13: =BA13 -> 1
B14: Total FTE | E14: # | F14: =SUM(F8:F13) -> 6 | G14: =SUM(G8:G13) -> 6 | H14: =SUM(H8:H13) -> 7 | I14: =SUM(I8:I13) -> 8 | J14: =SUM(J8:J13) -> 8 | K14: =SUM(K8:K13) -> 8 | L14: =SUM(L8:L13) -> 8 | M14: =SUM(M8:M13) -> 8 | ... BA14: =SUM(BA8:BA13) -> 20 | BC14: =Q14 -> 8 | BD14: =AC14 -> 13 | BE14: =AO14 -> 17 | BF14: =BA14 -> 20
B16: PERSONNEL COSTS
B17: Gross salary | E17: € | F17: {=INDEX(Assumptions!$C$32:$F$32,MATCH(YEAR(F$3),Assumptions!$C$4:$F$4,0))+INDEX(Assumptions!$C$33:$F$33,MATCH(YEAR(F$3),Assumptions!$C$4:$F$4,0))+F8*Assumptions!$C$34+F9*Assumptions!$C$35+F10*Assumptions!$C$36} -> 24500 | G17: {=INDEX(Assumptions!$C$32:$F$32,MATCH(YEAR(G$3),Assumptions!$C$4:$F$4,0))+INDEX(Assumptions!$C$33:$F$33,MATCH(YEAR(G$3),Assumptions!$C$4:$F$4,0))+G8*Assumptions!$C$34+G9*Assumptions!$C$35+G10*Assumptions!$C$36} -> 24500 | H17: {=INDEX(Assumptions!$C$32:$F$32,MATCH(YEAR(H$3),Assumptions!$C$4:$F$4,0))+INDEX(Assumptions!$C$33:$F$33,MATCH(YEAR(H$3),Assumptions!$C$4:$F$4,0))+H8*Assumptions!$C$34+H9*Assumptions!$C$35+H10*Assumptions!$C$36} -> 27500 | I17: {=INDEX(Assumptions!$C$32:$F$32,MATCH(YEAR(I$3),Assumptions!$C$4:$F$4,0))+INDEX(Assumptions!$C$33:$F$33,MATCH(YEAR(I$3),Assumptions!$C$4:$F$4,0))+I8*Assumptions!$C$34+I9*Assumptions!$C$35+I10*Assumptions!$C$36} -> 30500 | J17: {=INDEX(Assumptions!$C$32:$F$32,MATCH(YEAR(J$3),Assumptions!$C$4:$F$4,0))+INDEX(Assumptions!$C$33:$F$33,MATCH(YEAR(J$3),Assumptions!$C$4:$F$4,0))+J8*Assumptions!$C$34+J9*Assumptions!$C$35+J10*Assumptions!$C$36} -> 30500 | K17: {=INDEX(Assumptions!$C$32:$F$32,MATCH(YEAR(K$3),Assumptions!$C$4:$F$4,0))+INDEX(Assumptions!$C$33:$F$33,MATCH(YEAR(K$3),Assumptions!$C$4:$F$4,0))+K8*Assumptions!$C$34+K9*Assumptions!$C$35+K10*Assumptions!$C$36} -> 30500 | L17: {=INDEX(Assumptions!$C$32:$F$32,MATCH(YEAR(L$3),Assumptions!$C$4:$F$4,0))+INDEX(Assumptions!$C$33:$F$33,MATCH(YEAR(L$3),Assumptions!$C$4:$F$4,0))+L8*Assumptions!$C$34+L9*Assumptions!$C$35+L10*Assumptions!$C$36} -> 30500 | M17: {=INDEX(Assumptions!$C$32:$F$32,MATCH(YEAR(M$3),Assumptions!$C$4:$F$4,0))+INDEX(Assumptions!$C$33:$F$33,MATCH(YEAR(M$3),Assumptions!$C$4:$F$4,0))+M8*Assumptions!$C$34+M9*Assumptions!$C$35+M10*Assumptions!$C$36} -> 30500 | ... BA17: {=INDEX(Assumptions!$C$32:$F$32,MATCH(YEAR(BA$3),Assumptions!$C$4:$F$4,0))+INDEX(Assumptions!$C$33:$F$33,MATCH(YEAR(BA$3),Assumptions!$C$4:$F$4,0))+BA8*Assumptions!$C$34+BA9*Assumptions!$C$35+BA10*Assumptions!$C$36} -> 81500 | BC17: =SUMPRODUCT((YEAR($F$3:$BA$3)=BC$3)*$F17:$BA17) -> 358500 | BD17: =SUMPRODUCT((YEAR($F$3:$BA$3)=BD$3)*$F17:$BA17) -> 597000 | BE17: =SUMPRODUCT((YEAR($F$3:$BA$3)=BE$3)*$F17:$BA17) -> 783000 | BF17: =SUMPRODUCT((YEAR($F$3:$BA$3)=BF$3)*$F17:$BA17) -> 939000
B18: Holiday pay | E18: € | F18: =Assumptions!$C$38*F17 -> 1960 | G18: =Assumptions!$C$38*G17 -> 1960 | H18: =Assumptions!$C$38*H17 -> 2200 | I18: =Assumptions!$C$38*I17 -> 2440 | J18: =Assumptions!$C$38*J17 -> 2440 | K18: =Assumptions!$C$38*K17 -> 2440 | L18: =Assumptions!$C$38*L17 -> 2440 | M18: =Assumptions!$C$38*M17 -> 2440 | ... BA18: =Assumptions!$C$38*BA17 -> 6520 | BC18: =SUMPRODUCT((YEAR($F$3:$BA$3)=BC$3)*$F18:$BA18) -> 28680 | BD18: =SUMPRODUCT((YEAR($F$3:$BA$3)=BD$3)*$F18:$BA18) -> 47760 | BE18: =SUMPRODUCT((YEAR($F$3:$BA$3)=BE$3)*$F18:$BA18) -> 62640 | BF18: =SUMPRODUCT((YEAR($F$3:$BA$3)=BF$3)*$F18:$BA18) -> 75120
B19: Employer taxes | E19: € | F19: =Assumptions!$C$39*(F17+F18) -> 5027.4 | G19: =Assumptions!$C$39*(G17+G18) -> 5027.4 | H19: =Assumptions!$C$39*(H17+H18) -> 5643 | I19: =Assumptions!$C$39*(I17+I18) -> 6258.6 | J19: =Assumptions!$C$39*(J17+J18) -> 6258.6 | K19: =Assumptions!$C$39*(K17+K18) -> 6258.6 | L19: =Assumptions!$C$39*(L17+L18) -> 6258.6 | M19: =Assumptions!$C$39*(M17+M18) -> 6258.6 | ... BA19: =Assumptions!$C$39*(BA17+BA18) -> 16723.8 | BC19: =SUMPRODUCT((YEAR($F$3:$BA$3)=BC$3)*$F19:$BA19) -> 73564.2 | BD19: =SUMPRODUCT((YEAR($F$3:$BA$3)=BD$3)*$F19:$BA19) -> 122504.4 | BE19: =SUMPRODUCT((YEAR($F$3:$BA$3)=BE$3)*$F19:$BA19) -> 160671.6 | BF19: =SUMPRODUCT((YEAR($F$3:$BA$3)=BF$3)*$F19:$BA19) -> 192682.8
B20: Sales hire | E20: € | F20: =Assumptions!$C$37/12 -> 7500 | G20: =Assumptions!$C$37/12 -> 7500 | H20: =Assumptions!$C$37/12 -> 7500 | I20: =Assumptions!$C$37/12 -> 7500 | J20: =Assumptions!$C$37/12 -> 7500 | K20: =Assumptions!$C$37/12 -> 7500 | L20: =Assumptions!$C$37/12 -> 7500 | M20: =Assumptions!$C$37/12 -> 7500 | ... BA20: =Assumptions!$C$37/12 -> 7500 | BC20: =SUMPRODUCT((YEAR($F$3:$BA$3)=BC$3)*$F20:$BA20) -> 90000 | BD20: =SUMPRODUCT((YEAR($F$3:$BA$3)=BD$3)*$F20:$BA20) -> 90000 | BE20: =SUMPRODUCT((YEAR($F$3:$BA$3)=BE$3)*$F20:$BA20) -> 90000 | BF20: =SUMPRODUCT((YEAR($F$3:$BA$3)=BF$3)*$F20:$BA20) -> 90000
B21: Success-fee bonus | E21: € | F21: ='Revenue forecast'!F24*Assumptions!$C$28*(0.9+0.1*(Assumptions!$C$25+Assumptions!$C$26)) -> 0 | G21: ='Revenue forecast'!G24*Assumptions!$C$28*(0.9+0.1*(Assumptions!$C$25+Assumptions!$C$26)) -> 0 | H21: ='Revenue forecast'!H24*Assumptions!$C$28*(0.9+0.1*(Assumptions!$C$25+Assumptions!$C$26)) -> 0 | I21: ='Revenue forecast'!I24*Assumptions!$C$28*(0.9+0.1*(Assumptions!$C$25+Assumptions!$C$26)) -> 0 | J21: ='Revenue forecast'!J24*Assumptions!$C$28*(0.9+0.1*(Assumptions!$C$25+Assumptions!$C$26)) -> 0 | K21: ='Revenue forecast'!K24*Assumptions!$C$28*(0.9+0.1*(Assumptions!$C$25+Assumptions!$C$26)) -> 11550 | L21: ='Revenue forecast'!L24*Assumptions!$C$28*(0.9+0.1*(Assumptions!$C$25+Assumptions!$C$26)) -> 5775 | M21: ='Revenue forecast'!M24*Assumptions!$C$28*(0.9+0.1*(Assumptions!$C$25+Assumptions!$C$26)) -> 11550 | ... BA21: ='Revenue forecast'!BA24*Assumptions!$C$28*(0.9+0.1*(Assumptions!$C$25+Assumptions!$C$26)) -> 1056825 | BC21: =SUMPRODUCT((YEAR($F$3:$BA$3)=BC$3)*$F21:$BA21) -> 109725 | BD21: =SUMPRODUCT((YEAR($F$3:$BA$3)=BD$3)*$F21:$BA21) -> 781550 | BE21: =SUMPRODUCT((YEAR($F$3:$BA$3)=BE$3)*$F21:$BA21) -> 3428348 | BF21: =SUMPRODUCT((YEAR($F$3:$BA$3)=BF$3)*$F21:$BA21) -> 9829050
B22: Contractors / accountant | E22: € | F22: 450 | G22: 450 | H22: 450 | I22: 450 | J22: 450 | K22: 450 | L22: 450 | M22: 450 | N22: 450 | O22: 450 | P22: 450 | Q22: 450 | R22: 450 | S22: 450 | T22: 450 | U22: 450 | V22: 450 | W22: 450 | X22: 450 | Y22: 450 | Z22: 450 | AA22: 450 | AB22: 450 | AC22: 450 | AD22: 450 | AE22: 450 | AF22: 450 | AG22: 450 | AH22: 450 | AI22: 450 | AJ22: 450 | AK22: 450 | AL22: 450 | AM22: 450 | AN22: 450 | AO22: 450 | AP22: 450 | AQ22: 450 | AR22: 450 | AS22: 450 | AT22: 450 | AU22: 450 | AV22: 450 | AW22: 450 | AX22: 450 | AY22: 450 | AZ22: 450 | BA22: 450 | BC22: =SUMPRODUCT((YEAR($F$3:$BA$3)=BC$3)*$F22:$BA22) -> 5400 | BD22: =SUMPRODUCT((YEAR($F$3:$BA$3)=BD$3)*$F22:$BA22) -> 5400 | BE22: =SUMPRODUCT((YEAR($F$3:$BA$3)=BE$3)*$F22:$BA22) -> 5400 | BF22: =SUMPRODUCT((YEAR($F$3:$BA$3)=BF$3)*$F22:$BA22) -> 5400
B23: Other people costs | E23: € | F23: 267 | G23: 267 | H23: 267 | I23: 267 | J23: 267 | K23: 267 | L23: 267 | M23: 267 | N23: 267 | O23: 267 | P23: 267 | Q23: 267 | R23: 267 | S23: 267 | T23: 267 | U23: 267 | V23: 267 | W23: 267 | X23: 267 | Y23: 267 | Z23: 267 | AA23: 267 | AB23: 267 | AC23: 267 | AD23: 267 | AE23: 267 | AF23: 267 | AG23: 267 | AH23: 267 | AI23: 267 | AJ23: 267 | AK23: 267 | AL23: 267 | AM23: 267 | AN23: 267 | AO23: 267 | AP23: 267 | AQ23: 267 | AR23: 267 | AS23: 267 | AT23: 267 | AU23: 267 | AV23: 267 | AW23: 267 | AX23: 267 | AY23: 267 | AZ23: 267 | BA23: 267 | BC23: =SUMPRODUCT((YEAR($F$3:$BA$3)=BC$3)*$F23:$BA23) -> 3204 | BD23: =SUMPRODUCT((YEAR($F$3:$BA$3)=BD$3)*$F23:$BA23) -> 3204 | BE23: =SUMPRODUCT((YEAR($F$3:$BA$3)=BE$3)*$F23:$BA23) -> 3204 | BF23: =SUMPRODUCT((YEAR($F$3:$BA$3)=BF$3)*$F23:$BA23) -> 3204
B24: Total personnel | E24: € | F24: =SUM(F17:F23) -> 39704.4 | G24: =SUM(G17:G23) -> 39704.4 | H24: =SUM(H17:H23) -> 43560 | I24: =SUM(I17:I23) -> 47415.6 | J24: =SUM(J17:J23) -> 47415.6 | K24: =SUM(K17:K23) -> 58965.6 | L24: =SUM(L17:L23) -> 53190.6 | M24: =SUM(M17:M23) -> 58965.6 | ... BA24: =SUM(BA17:BA23) -> 1169785.8 | BC24: =SUMPRODUCT((YEAR($F$3:$BA$3)=BC$3)*$F24:$BA24) -> 669073.2 | BD24: =SUMPRODUCT((YEAR($F$3:$BA$3)=BD$3)*$F24:$BA24) -> 1647418.4 | BE24: =SUMPRODUCT((YEAR($F$3:$BA$3)=BE$3)*$F24:$BA24) -> 4533263.6 | BF24: =SUMPRODUCT((YEAR($F$3:$BA$3)=BF$3)*$F24:$BA24) -> 11134457

Sheet OPEX
B2: OPEX — Monthly 2027–2030 (€)
E3: Unit | F3: 46388 | G3: 46419 | H3: 46447 | I3: 46478 | J3: 46508 | K3: 46539 | L3: 46569 | M3: 46600 | N3: 46631 | O3: 46661 | P3: 46692 | Q3: 46722 | R3: 46753 | S3: 46784 | T3: 46813 | U3: 46844 | V3: 46874 | W3: 46905 | X3: 46935 | Y3: 46966 | Z3: 46997 | AA3: 47027 | AB3: 47058 | AC3: 47088 | AD3: 47119 | AE3: 47150 | AF3: 47178 | AG3: 47209 | AH3: 47239 | AI3: 47270 | AJ3: 47300 | AK3: 47331 | AL3: 47362 | AM3: 47392 | AN3: 47423 | AO3: 47453 | AP3: 47484 | AQ3: 47515 | AR3: 47543 | AS3: 47574 | AT3: 47604 | AU3: 47635 | AV3: 47665 | AW3: 47696 | AX3: 47727 | AY3: 47757 | AZ3: 47788 | BA3: 47818 | BC3: 2027 | BD3: 2028 | BE3: 2029 | BF3: 2030
B6: OTHER OPEX
B7: Rent | E7: € | F7: =Personnel!F14*Assumptions!$C$46 -> 3600 | G7: =Personnel!G14*Assumptions!$C$46 -> 3600 | H7: =Personnel!H14*Assumptions!$C$46 -> 4200 | I7: =Personnel!I14*Assumptions!$C$46 -> 4800 | J7: =Personnel!J14*Assumptions!$C$46 -> 4800 | K7: =Personnel!K14*Assumptions!$C$46 -> 4800 | L7: =Personnel!L14*Assumptions!$C$46 -> 4800 | M7: =Personnel!M14*Assumptions!$C$46 -> 4800 | ... BA7: =Personnel!BA14*Assumptions!$C$46 -> 12000 | BC7: =SUMPRODUCT((YEAR($F$3:$BA$3)=BC$3)*$F7:$BA7) -> 55800 | BD7: =SUMPRODUCT((YEAR($F$3:$BA$3)=BD$3)*$F7:$BA7) -> 88200 | BE7: =SUMPRODUCT((YEAR($F$3:$BA$3)=BE$3)*$F7:$BA7) -> 114600 | BF7: =SUMPRODUCT((YEAR($F$3:$BA$3)=BF$3)*$F7:$BA7) -> 136200
B8: Software | E8: € | F8: =Assumptions!$C$48+Personnel!F14*Assumptions!$C$47 -> 2303.3333 | G8: =Assumptions!$C$48+Personnel!G14*Assumptions!$C$47 -> 2303.3333 | H8: =Assumptions!$C$48+Personnel!H14*Assumptions!$C$47 -> 2423.3333 | I8: =Assumptions!$C$48+Personnel!I14*Assumptions!$C$47 -> 2543.3333 | J8: =Assumptions!$C$48+Personnel!J14*Assumptions!$C$47 -> 2543.3333 | K8: =Assumptions!$C$48+Personnel!K14*Assumptions!$C$47 -> 2543.3333 | L8: =Assumptions!$C$48+Personnel!L14*Assumptions!$C$47 -> 2543.3333 | M8: =Assumptions!$C$48+Personnel!M14*Assumptions!$C$47 -> 2543.3333 | ... BA8: =Assumptions!$C$48+Personnel!BA14*Assumptions!$C$47 -> 3983.3333 | BC8: =SUMPRODUCT((YEAR($F$3:$BA$3)=BC$3)*$F8:$BA8) -> 30160 | BD8: =SUMPRODUCT((YEAR($F$3:$BA$3)=BD$3)*$F8:$BA8) -> 36640 | BE8: =SUMPRODUCT((YEAR($F$3:$BA$3)=BE$3)*$F8:$BA8) -> 41920 | BF8: =SUMPRODUCT((YEAR($F$3:$BA$3)=BF$3)*$F8:$BA8) -> 46240
B9: Office & hardware | E9: € | F9: =Personnel!F14*Assumptions!$C$49 -> 240 | G9: =Personnel!G14*Assumptions!$C$49 -> 240 | H9: =Personnel!H14*Assumptions!$C$49 -> 280 | I9: =Personnel!I14*Assumptions!$C$49 -> 320 | J9: =Personnel!J14*Assumptions!$C$49 -> 320 | K9: =Personnel!K14*Assumptions!$C$49 -> 320 | L9: =Personnel!L14*Assumptions!$C$49 -> 320 | M9: =Personnel!M14*Assumptions!$C$49 -> 320 | ... BA9: =Personnel!BA14*Assumptions!$C$49 -> 800 | BC9: =SUMPRODUCT((YEAR($F$3:$BA$3)=BC$3)*$F9:$BA9) -> 3720 | BD9: =SUMPRODUCT((YEAR($F$3:$BA$3)=BD$3)*$F9:$BA9) -> 5880 | BE9: =SUMPRODUCT((YEAR($F$3:$BA$3)=BE$3)*$F9:$BA9) -> 7640 | BF9: =SUMPRODUCT((YEAR($F$3:$BA$3)=BF$3)*$F9:$BA9) -> 9080
B10: Marketing & Sales | E10: € | F10: =Assumptions!$C$51 -> 2000 | G10: =Assumptions!$C$51 -> 2000 | H10: =Assumptions!$C$51 -> 2000 | I10: =Assumptions!$C$51 -> 2000 | J10: =Assumptions!$C$51 -> 2000 | K10: =Assumptions!$C$51 -> 2000 | L10: =Assumptions!$C$51 -> 2000 | M10: =Assumptions!$C$51 -> 2000 | ... BA10: =Assumptions!$C$51 -> 2000 | BC10: =SUMPRODUCT((YEAR($F$3:$BA$3)=BC$3)*$F10:$BA10) -> 24000 | BD10: =SUMPRODUCT((YEAR($F$3:$BA$3)=BD$3)*$F10:$BA10) -> 24000 | BE10: =SUMPRODUCT((YEAR($F$3:$BA$3)=BE$3)*$F10:$BA10) -> 24000 | BF10: =SUMPRODUCT((YEAR($F$3:$BA$3)=BF$3)*$F10:$BA10) -> 24000
B11: Travel | E11: € | F11: =Assumptions!$C$52 -> 500 | G11: =Assumptions!$C$52 -> 500 | H11: =Assumptions!$C$52 -> 500 | I11: =Assumptions!$C$52 -> 500 | J11: =Assumptions!$C$52 -> 500 | K11: =Assumptions!$C$52 -> 500 | L11: =Assumptions!$C$52 -> 500 | M11: =Assumptions!$C$52 -> 500 | ... BA11: =Assumptions!$C$52 -> 500 | BC11: =SUMPRODUCT((YEAR($F$3:$BA$3)=BC$3)*$F11:$BA11) -> 6000 | BD11: =SUMPRODUCT((YEAR($F$3:$BA$3)=BD$3)*$F11:$BA11) -> 6000 | BE11: =SUMPRODUCT((YEAR($F$3:$BA$3)=BE$3)*$F11:$BA11) -> 6000 | BF11: =SUMPRODUCT((YEAR($F$3:$BA$3)=BF$3)*$F11:$BA11) -> 6000
B12: SG&A (F&B) | E12: € | F12: =Personnel!F14*Assumptions!$C$50 -> 600 | G12: =Personnel!G14*Assumptions!$C$50 -> 600 | H12: =Personnel!H14*Assumptions!$C$50 -> 700 | I12: =Personnel!I14*Assumptions!$C$50 -> 800 | J12: =Personnel!J14*Assumptions!$C$50 -> 800 | K12: =Personnel!K14*Assumptions!$C$50 -> 800 | L12: =Personnel!L14*Assumptions!$C$50 -> 800 | M12: =Personnel!M14*Assumptions!$C$50 -> 800 | ... BA12: =Personnel!BA14*Assumptions!$C$50 -> 2000 | BC12: =SUMPRODUCT((YEAR($F$3:$BA$3)=BC$3)*$F12:$BA12) -> 9300 | BD12: =SUMPRODUCT((YEAR($F$3:$BA$3)=BD$3)*$F12:$BA12) -> 14700 | BE12: =SUMPRODUCT((YEAR($F$3:$BA$3)=BE$3)*$F12:$BA12) -> 19100 | BF12: =SUMPRODUCT((YEAR($F$3:$BA$3)=BF$3)*$F12:$BA12) -> 22700
B13: Other | E13: € | F13: =Assumptions!$C$54 -> 140 | G13: =Assumptions!$C$54 -> 140 | H13: =Assumptions!$C$54 -> 140 | I13: =Assumptions!$C$54 -> 140 | J13: =Assumptions!$C$54 -> 140 | K13: =Assumptions!$C$54 -> 140 | L13: =Assumptions!$C$54 -> 140 | M13: =Assumptions!$C$54 -> 140 | ... BA13: =Assumptions!$C$54 -> 140 | BC13: =SUMPRODUCT((YEAR($F$3:$BA$3)=BC$3)*$F13:$BA13) -> 1680 | BD13: =SUMPRODUCT((YEAR($F$3:$BA$3)=BD$3)*$F13:$BA13) -> 1680 | BE13: =SUMPRODUCT((YEAR($F$3:$BA$3)=BE$3)*$F13:$BA13) -> 1680 | BF13: =SUMPRODUCT((YEAR($F$3:$BA$3)=BF$3)*$F13:$BA13) -> 1680
B14: RX allocation | E14: € | F14: =Assumptions!$C$53 -> 1307 | G14: =Assumptions!$C$53 -> 1307 | H14: =Assumptions!$C$53 -> 1307 | I14: =Assumptions!$C$53 -> 1307 | J14: =Assumptions!$C$53 -> 1307 | K14: =Assumptions!$C$53 -> 1307 | L14: =Assumptions!$C$53 -> 1307 | M14: =Assumptions!$C$53 -> 1307 | ... BA14: =Assumptions!$C$53 -> 1307 | BC14: =SUMPRODUCT((YEAR($F$3:$BA$3)=BC$3)*$F14:$BA14) -> 15684 | BD14: =SUMPRODUCT((YEAR($F$3:$BA$3)=BD$3)*$F14:$BA14) -> 15684 | BE14: =SUMPRODUCT((YEAR($F$3:$BA$3)=BE$3)*$F14:$BA14) -> 15684 | BF14: =SUMPRODUCT((YEAR($F$3:$BA$3)=BF$3)*$F14:$BA14) -> 15684
B15: Total other OPEX | E15: € | F15: =SUM(F7:F14) -> 10690.333 | G15: =SUM(G7:G14) -> 10690.333 | H15: =SUM(H7:H14) -> 11550.333 | I15: =SUM(I7:I14) -> 12410.333 | J15: =SUM(J7:J14) -> 12410.333 | K15: =SUM(K7:K14) -> 12410.333 | L15: =SUM(L7:L14) -> 12410.333 | M15: =SUM(M7:M14) -> 12410.333 | ... BA15: =SUM(BA7:BA14) -> 22730.333 | BC15: =SUMPRODUCT((YEAR($F$3:$BA$3)=BC$3)*$F15:$BA15) -> 146344 | BD15: =SUMPRODUCT((YEAR($F$3:$BA$3)=BD$3)*$F15:$BA15) -> 192784 | BE15: =SUMPRODUCT((YEAR($F$3:$BA$3)=BE$3)*$F15:$BA15) -> 230624 | BF15: =SUMPRODUCT((YEAR($F$3:$BA$3)=BF$3)*$F15:$BA15) -> 261584

Sheet Financial Statements
B1: Financial Statements — Income Statement, Monthly 2027–2030 (€)
C2: 46388 | D2: 46419 | E2: 46447 | F2: 46478 | G2: 46508 | H2: 46539 | I2: 46569 | J2: 46600 | K2: 46631 | L2: 46661 | M2: 46692 | N2: 46722 | O2: 46753 | P2: 46784 | Q2: 46813 | R2: 46844 | S2: 46874 | T2: 46905 | U2: 46935 | V2: 46966 | W2: 46997 | X2: 47027 | Y2: 47058 | Z2: 47088 | AA2: 47119 | AB2: 47150 | AC2: 47178 | AD2: 47209 | AE2: 47239 | AF2: 47270 | AG2: 47300 | AH2: 47331 | AI2: 47362 | AJ2: 47392 | AK2: 47423 | AL2: 47453 | AM2: 47484 | AN2: 47515 | AO2: 47543 | AP2: 47574 | AQ2: 47604 | AR2: 47635 | AS2: 47665 | AT2: 47696 | AU2: 47727 | AV2: 47757 | AW2: 47788 | AX2: 47818 | AZ2: 2027 | BA2: 2028 | BB2: 2029 | BC2: 2030
B4: Revenues
B5: Retainer | C5: ='Revenue forecast'!F23 -> 14000 | D5: ='Revenue forecast'!G23 -> 21000 | E5: ='Revenue forecast'!H23 -> 43000 | F5: ='Revenue forecast'!I23 -> 50000 | G5: ='Revenue forecast'!J23 -> 64000 | H5: ='Revenue forecast'!K23 -> 57000 | I5: ='Revenue forecast'!L23 -> 64000 | J5: ='Revenue forecast'!M23 -> 57000 | ... AX5: ='Revenue forecast'!BA23 -> 281000 | AZ5: =SUMPRODUCT((YEAR($C$2:$AX$2)=AZ$2)*$C5:$AX5) -> 620000 | BA5: =SUMPRODUCT((YEAR($C$2:$AX$2)=BA$2)*$C5:$AX5) -> 1409000 | BB5: =SUMPRODUCT((YEAR($C$2:$AX$2)=BB$2)*$C5:$AX5) -> 2263000 | BC5: =SUMPRODUCT((YEAR($C$2:$AX$2)=BC$2)*$C5:$AX5) -> 3163000
B6: Closing fees | C6: ='Revenue forecast'!F24 -> 0 | D6: ='Revenue forecast'!G24 -> 0 | E6: ='Revenue forecast'!H24 -> 0 | F6: ='Revenue forecast'!I24 -> 0 | G6: ='Revenue forecast'!J24 -> 0 | H6: ='Revenue forecast'!K24 -> 30000 | I6: ='Revenue forecast'!L24 -> 15000 | J6: ='Revenue forecast'!M24 -> 30000 | ... AX6: ='Revenue forecast'!BA24 -> 2745000 | AZ6: =SUMPRODUCT((YEAR($C$2:$AX$2)=AZ$2)*$C6:$AX6) -> 285000 | BA6: =SUMPRODUCT((YEAR($C$2:$AX$2)=BA$2)*$C6:$AX6) -> 2030000 | BB6: =SUMPRODUCT((YEAR($C$2:$AX$2)=BB$2)*$C6:$AX6) -> 8904800 | BC6: =SUMPRODUCT((YEAR($C$2:$AX$2)=BC$2)*$C6:$AX6) -> 25530000
B7: Less: industry-partner share | C7: ='Revenue forecast'!F26 -> -875 | D7: ='Revenue forecast'!G26 -> -1312.5 | E7: ='Revenue forecast'!H26 -> -2687.5 | F7: ='Revenue forecast'!I26 -> -3125 | G7: ='Revenue forecast'!J26 -> -4000 | H7: ='Revenue forecast'!K26 -> -5437.5 | I7: ='Revenue forecast'!L26 -> -4937.5 | J7: ='Revenue forecast'!M26 -> -5437.5 | ... AX7: ='Revenue forecast'!BA26 -> -189125 | AZ7: =SUMPRODUCT((YEAR($C$2:$AX$2)=AZ$2)*$C7:$AX7) -> -56562.5 | BA7: =SUMPRODUCT((YEAR($C$2:$AX$2)=BA$2)*$C7:$AX7) -> -214937.5 | BB7: =SUMPRODUCT((YEAR($C$2:$AX$2)=BB$2)*$C7:$AX7) -> -697987.5 | BC7: =SUMPRODUCT((YEAR($C$2:$AX$2)=BC$2)*$C7:$AX7) -> -1793312.5
B8: Total revenues | C8: =C5+C6+C7 -> 13125 | D8: =D5+D6+D7 -> 19687.5 | E8: =E5+E6+E7 -> 40312.5 | F8: =F5+F6+F7 -> 46875 | G8: =G5+G6+G7 -> 60000 | H8: =H5+H6+H7 -> 81562.5 | I8: =I5+I6+I7 -> 74062.5 | J8: =J5+J6+J7 -> 81562.5 | ... AX8: =AX5+AX6+AX7 -> 2836875 | AZ8: =SUMPRODUCT((YEAR($C$2:$AX$2)=AZ$2)*$C8:$AX8) -> 848437.5 | BA8: =SUMPRODUCT((YEAR($C$2:$AX$2)=BA$2)*$C8:$AX8) -> 3224062.5 | BB8: =SUMPRODUCT((YEAR($C$2:$AX$2)=BB$2)*$C8:$AX8) -> 10469812 | BC8: =SUMPRODUCT((YEAR($C$2:$AX$2)=BC$2)*$C8:$AX8) -> 26899688
B10: Personnel
B11: Gross salary | C11: =Personnel!F17+Personnel!F20 -> 32000 | D11: =Personnel!G17+Personnel!G20 -> 32000 | E11: =Personnel!H17+Personnel!H20 -> 35000 | F11: =Personnel!I17+Personnel!I20 -> 38000 | G11: =Personnel!J17+Personnel!J20 -> 38000 | H11: =Personnel!K17+Personnel!K20 -> 38000 | I11: =Personnel!L17+Personnel!L20 -> 38000 | J11: =Personnel!M17+Personnel!M20 -> 38000 | ... AX11: =Personnel!BA17+Personnel!BA20 -> 89000 | AZ11: =SUMPRODUCT((YEAR($C$2:$AX$2)=AZ$2)*$C11:$AX11) -> 448500 | BA11: =SUMPRODUCT((YEAR($C$2:$AX$2)=BA$2)*$C11:$AX11) -> 687000 | BB11: =SUMPRODUCT((YEAR($C$2:$AX$2)=BB$2)*$C11:$AX11) -> 873000 | BC11: =SUMPRODUCT((YEAR($C$2:$AX$2)=BC$2)*$C11:$AX11) -> 1029000
B12: Bonus | C12: =Personnel!F21 -> 0 | D12: =Personnel!G21 -> 0 | E12: =Personnel!H21 -> 0 | F12: =Personnel!I21 -> 0 | G12: =Personnel!J21 -> 0 | H12: =Personnel!K21 -> 11550 | I12: =Personnel!L21 -> 5775 | J12: =Personnel!M21 -> 11550 | ... AX12: =Personnel!BA21 -> 1056825 | AZ12: =SUMPRODUCT((YEAR($C$2:$AX$2)=AZ$2)*$C12:$AX12) -> 109725 | BA12: =SUMPRODUCT((YEAR($C$2:$AX$2)=BA$2)*$C12:$AX12) -> 781550 | BB12: =SUMPRODUCT((YEAR($C$2:$AX$2)=BB$2)*$C12:$AX12) -> 3428348 | BC12: =SUMPRODUCT((YEAR($C$2:$AX$2)=BC$2)*$C12:$AX12) -> 9829050
B13: Employer taxes | C13: =Personnel!F18+Personnel!F19 -> 6987.4 | D13: =Personnel!G18+Personnel!G19 -> 6987.4 | E13: =Personnel!H18+Personnel!H19 -> 7843 | F13: =Personnel!I18+Personnel!I19 -> 8698.6 | G13: =Personnel!J18+Personnel!J19 -> 8698.6 | H13: =Personnel!K18+Personnel!K19 -> 8698.6 | I13: =Personnel!L18+Personnel!L19 -> 8698.6 | J13: =Personnel!M18+Personnel!M19 -> 8698.6 | ... AX13: =Personnel!BA18+Personnel!BA19 -> 23243.8 | AZ13: =SUMPRODUCT((YEAR($C$2:$AX$2)=AZ$2)*$C13:$AX13) -> 102244.2 | BA13: =SUMPRODUCT((YEAR($C$2:$AX$2)=BA$2)*$C13:$AX13) -> 170264.4 | BB13: =SUMPRODUCT((YEAR($C$2:$AX$2)=BB$2)*$C13:$AX13) -> 223311.6 | BC13: =SUMPRODUCT((YEAR($C$2:$AX$2)=BC$2)*$C13:$AX13) -> 267802.8
B14: Contractors | C14: =Personnel!F22 -> 450 | D14: =Personnel!G22 -> 450 | E14: =Personnel!H22 -> 450 | F14: =Personnel!I22 -> 450 | G14: =Personnel!J22 -> 450 | H14: =Personnel!K22 -> 450 | I14: =Personnel!L22 -> 450 | J14: =Personnel!M22 -> 450 | ... AX14: =Personnel!BA22 -> 450 | AZ14: =SUMPRODUCT((YEAR($C$2:$AX$2)=AZ$2)*$C14:$AX14) -> 5400 | BA14: =SUMPRODUCT((YEAR($C$2:$AX$2)=BA$2)*$C14:$AX14) -> 5400 | BB14: =SUMPRODUCT((YEAR($C$2:$AX$2)=BB$2)*$C14:$AX14) -> 5400 | BC14: =SUMPRODUCT((YEAR($C$2:$AX$2)=BC$2)*$C14:$AX14) -> 5400
B15: Strategic Advisory costs | C15: 0 | D15: 0 | E15: 0 | F15: 0 | G15: 0 | H15: 0 | I15: 0 | J15: 0 | K15: 0 | L15: 0 | M15: 0 | N15: 0 | O15: 0 | P15: 0 | Q15: 0 | R15: 0 | S15: 0 | T15: 0 | U15: 0 | V15: 0 | W15: 0 | X15: 0 | Y15: 0 | Z15: 0 | AA15: 0 | AB15: 0 | AC15: 0 | AD15: 0 | AE15: 0 | AF15: 0 | AG15: 0 | AH15: 0 | AI15: 0 | AJ15: 0 | AK15: 0 | AL15: 0 | AM15: 0 | AN15: 0 | AO15: 0 | AP15: 0 | AQ15: 0 | AR15: 0 | AS15: 0 | AT15: 0 | AU15: 0 | AV15: 0 | AW15: 0 | AX15: 0 | AZ15: =SUMPRODUCT((YEAR($C$2:$AX$2)=AZ$2)*$C15:$AX15) -> 0 | BA15: =SUMPRODUCT((YEAR($C$2:$AX$2)=BA$2)*$C15:$AX15) -> 0 | BB15: =SUMPRODUCT((YEAR($C$2:$AX$2)=BB$2)*$C15:$AX15) -> 0 | BC15: =SUMPRODUCT((YEAR($C$2:$AX$2)=BC$2)*$C15:$AX15) -> 0
B16: Other people costs | C16: =Personnel!F23 -> 267 | D16: =Personnel!G23 -> 267 | E16: =Personnel!H23 -> 267 | F16: =Personnel!I23 -> 267 | G16: =Personnel!J23 -> 267 | H16: =Personnel!K23 -> 267 | I16: =Personnel!L23 -> 267 | J16: =Personnel!M23 -> 267 | ... AX16: =Personnel!BA23 -> 267 | AZ16: =SUMPRODUCT((YEAR($C$2:$AX$2)=AZ$2)*$C16:$AX16) -> 3204 | BA16: =SUMPRODUCT((YEAR($C$2:$AX$2)=BA$2)*$C16:$AX16) -> 3204 | BB16: =SUMPRODUCT((YEAR($C$2:$AX$2)=BB$2)*$C16:$AX16) -> 3204 | BC16: =SUMPRODUCT((YEAR($C$2:$AX$2)=BC$2)*$C16:$AX16) -> 3204
B17: Total personnel | C17: =SUM(C11:C16) -> 39704.4 | D17: =SUM(D11:D16) -> 39704.4 | E17: =SUM(E11:E16) -> 43560 | F17: =SUM(F11:F16) -> 47415.6 | G17: =SUM(G11:G16) -> 47415.6 | H17: =SUM(H11:H16) -> 58965.6 | I17: =SUM(I11:I16) -> 53190.6 | J17: =SUM(J11:J16) -> 58965.6 | ... AX17: =SUM(AX11:AX16) -> 1169785.8 | AZ17: =SUMPRODUCT((YEAR($C$2:$AX$2)=AZ$2)*$C17:$AX17) -> 669073.2 | BA17: =SUMPRODUCT((YEAR($C$2:$AX$2)=BA$2)*$C17:$AX17) -> 1647418.4 | BB17: =SUMPRODUCT((YEAR($C$2:$AX$2)=BB$2)*$C17:$AX17) -> 4533263.6 | BC17: =SUMPRODUCT((YEAR($C$2:$AX$2)=BC$2)*$C17:$AX17) -> 11134457
B19: Gross profit | C19: =C8-C17 -> -26579.4 | D19: =D8-D17 -> -20016.9 | E19: =E8-E17 -> -3247.5 | F19: =F8-F17 -> -540.6 | G19: =G8-G17 -> 12584.4 | H19: =H8-H17 -> 22596.9 | I19: =I8-I17 -> 20871.9 | J19: =J8-J17 -> 22596.9 | ... AX19: =AX8-AX17 -> 1667089.2 | AZ19: =SUMPRODUCT((YEAR($C$2:$AX$2)=AZ$2)*$C19:$AX19) -> 179364.3 | BA19: =SUMPRODUCT((YEAR($C$2:$AX$2)=BA$2)*$C19:$AX19) -> 1576644.1 | BB19: =SUMPRODUCT((YEAR($C$2:$AX$2)=BB$2)*$C19:$AX19) -> 5936548.9 | BC19: =SUMPRODUCT((YEAR($C$2:$AX$2)=BC$2)*$C19:$AX19) -> 15765231
B21: Other OPEX
B22: Rent | C22: =OPEX!F7 -> 3600 | D22: =OPEX!G7 -> 3600 | E22: =OPEX!H7 -> 4200 | F22: =OPEX!I7 -> 4800 | G22: =OPEX!J7 -> 4800 | H22: =OPEX!K7 -> 4800 | I22: =OPEX!L7 -> 4800 | J22: =OPEX!M7 -> 4800 | ... AX22: =OPEX!BA7 -> 12000 | AZ22: =SUMPRODUCT((YEAR($C$2:$AX$2)=AZ$2)*$C22:$AX22) -> 55800 | BA22: =SUMPRODUCT((YEAR($C$2:$AX$2)=BA$2)*$C22:$AX22) -> 88200 | BB22: =SUMPRODUCT((YEAR($C$2:$AX$2)=BB$2)*$C22:$AX22) -> 114600 | BC22: =SUMPRODUCT((YEAR($C$2:$AX$2)=BC$2)*$C22:$AX22) -> 136200
B23: Software | C23: =OPEX!F8 -> 2303.3333 | D23: =OPEX!G8 -> 2303.3333 | E23: =OPEX!H8 -> 2423.3333 | F23: =OPEX!I8 -> 2543.3333 | G23: =OPEX!J8 -> 2543.3333 | H23: =OPEX!K8 -> 2543.3333 | I23: =OPEX!L8 -> 2543.3333 | J23: =OPEX!M8 -> 2543.3333 | ... AX23: =OPEX!BA8 -> 3983.3333 | AZ23: =SUMPRODUCT((YEAR($C$2:$AX$2)=AZ$2)*$C23:$AX23) -> 30160 | BA23: =SUMPRODUCT((YEAR($C$2:$AX$2)=BA$2)*$C23:$AX23) -> 36640 | BB23: =SUMPRODUCT((YEAR($C$2:$AX$2)=BB$2)*$C23:$AX23) -> 41920 | BC23: =SUMPRODUCT((YEAR($C$2:$AX$2)=BC$2)*$C23:$AX23) -> 46240
B24: Office | C24: =OPEX!F9 -> 240 | D24: =OPEX!G9 -> 240 | E24: =OPEX!H9 -> 280 | F24: =OPEX!I9 -> 320 | G24: =OPEX!J9 -> 320 | H24: =OPEX!K9 -> 320 | I24: =OPEX!L9 -> 320 | J24: =OPEX!M9 -> 320 | ... AX24: =OPEX!BA9 -> 800 | AZ24: =SUMPRODUCT((YEAR($C$2:$AX$2)=AZ$2)*$C24:$AX24) -> 3720 | BA24: =SUMPRODUCT((YEAR($C$2:$AX$2)=BA$2)*$C24:$AX24) -> 5880 | BB24: =SUMPRODUCT((YEAR($C$2:$AX$2)=BB$2)*$C24:$AX24) -> 7640 | BC24: =SUMPRODUCT((YEAR($C$2:$AX$2)=BC$2)*$C24:$AX24) -> 9080
B25: Marketing & Sales | C25: =OPEX!F10 -> 2000 | D25: =OPEX!G10 -> 2000 | E25: =OPEX!H10 -> 2000 | F25: =OPEX!I10 -> 2000 | G25: =OPEX!J10 -> 2000 | H25: =OPEX!K10 -> 2000 | I25: =OPEX!L10 -> 2000 | J25: =OPEX!M10 -> 2000 | ... AX25: =OPEX!BA10 -> 2000 | AZ25: =SUMPRODUCT((YEAR($C$2:$AX$2)=AZ$2)*$C25:$AX25) -> 24000 | BA25: =SUMPRODUCT((YEAR($C$2:$AX$2)=BA$2)*$C25:$AX25) -> 24000 | BB25: =SUMPRODUCT((YEAR($C$2:$AX$2)=BB$2)*$C25:$AX25) -> 24000 | BC25: =SUMPRODUCT((YEAR($C$2:$AX$2)=BC$2)*$C25:$AX25) -> 24000
B26: Travel | C26: =OPEX!F11 -> 500 | D26: =OPEX!G11 -> 500 | E26: =OPEX!H11 -> 500 | F26: =OPEX!I11 -> 500 | G26: =OPEX!J11 -> 500 | H26: =OPEX!K11 -> 500 | I26: =OPEX!L11 -> 500 | J26: =OPEX!M11 -> 500 | ... AX26: =OPEX!BA11 -> 500 | AZ26: =SUMPRODUCT((YEAR($C$2:$AX$2)=AZ$2)*$C26:$AX26) -> 6000 | BA26: =SUMPRODUCT((YEAR($C$2:$AX$2)=BA$2)*$C26:$AX26) -> 6000 | BB26: =SUMPRODUCT((YEAR($C$2:$AX$2)=BB$2)*$C26:$AX26) -> 6000 | BC26: =SUMPRODUCT((YEAR($C$2:$AX$2)=BC$2)*$C26:$AX26) -> 6000
B27: SG&A | C27: =OPEX!F12 -> 600 | D27: =OPEX!G12 -> 600 | E27: =OPEX!H12 -> 700 | F27: =OPEX!I12 -> 800 | G27: =OPEX!J12 -> 800 | H27: =OPEX!K12 -> 800 | I27: =OPEX!L12 -> 800 | J27: =OPEX!M12 -> 800 | ... AX27: =OPEX!BA12 -> 2000 | AZ27: =SUMPRODUCT((YEAR($C$2:$AX$2)=AZ$2)*$C27:$AX27) -> 9300 | BA27: =SUMPRODUCT((YEAR($C$2:$AX$2)=BA$2)*$C27:$AX27) -> 14700 | BB27: =SUMPRODUCT((YEAR($C$2:$AX$2)=BB$2)*$C27:$AX27) -> 19100 | BC27: =SUMPRODUCT((YEAR($C$2:$AX$2)=BC$2)*$C27:$AX27) -> 22700
B28: Other | C28: =OPEX!F13 -> 140 | D28: =OPEX!G13 -> 140 | E28: =OPEX!H13 -> 140 | F28: =OPEX!I13 -> 140 | G28: =OPEX!J13 -> 140 | H28: =OPEX!K13 -> 140 | I28: =OPEX!L13 -> 140 | J28: =OPEX!M13 -> 140 | ... AX28: =OPEX!BA13 -> 140 | AZ28: =SUMPRODUCT((YEAR($C$2:$AX$2)=AZ$2)*$C28:$AX28) -> 1680 | BA28: =SUMPRODUCT((YEAR($C$2:$AX$2)=BA$2)*$C28:$AX28) -> 1680 | BB28: =SUMPRODUCT((YEAR($C$2:$AX$2)=BB$2)*$C28:$AX28) -> 1680 | BC28: =SUMPRODUCT((YEAR($C$2:$AX$2)=BC$2)*$C28:$AX28) -> 1680
B29: Total other OPEX | C29: =SUM(C22:C28) -> 9383.3333 | D29: =SUM(D22:D28) -> 9383.3333 | E29: =SUM(E22:E28) -> 10243.333 | F29: =SUM(F22:F28) -> 11103.333 | G29: =SUM(G22:G28) -> 11103.333 | H29: =SUM(H22:H28) -> 11103.333 | I29: =SUM(I22:I28) -> 11103.333 | J29: =SUM(J22:J28) -> 11103.333 | ... AX29: =SUM(AX22:AX28) -> 21423.333 | AZ29: =SUMPRODUCT((YEAR($C$2:$AX$2)=AZ$2)*$C29:$AX29) -> 130660 | BA29: =SUMPRODUCT((YEAR($C$2:$AX$2)=BA$2)*$C29:$AX29) -> 177100 | BB29: =SUMPRODUCT((YEAR($C$2:$AX$2)=BB$2)*$C29:$AX29) -> 214940 | BC29: =SUMPRODUCT((YEAR($C$2:$AX$2)=BC$2)*$C29:$AX29) -> 245900
B31: RX allocation | C31: =OPEX!F14 -> 1307 | D31: =OPEX!G14 -> 1307 | E31: =OPEX!H14 -> 1307 | F31: =OPEX!I14 -> 1307 | G31: =OPEX!J14 -> 1307 | H31: =OPEX!K14 -> 1307 | I31: =OPEX!L14 -> 1307 | J31: =OPEX!M14 -> 1307 | ... AX31: =OPEX!BA14 -> 1307 | AZ31: =SUMPRODUCT((YEAR($C$2:$AX$2)=AZ$2)*$C31:$AX31) -> 15684 | BA31: =SUMPRODUCT((YEAR($C$2:$AX$2)=BA$2)*$C31:$AX31) -> 15684 | BB31: =SUMPRODUCT((YEAR($C$2:$AX$2)=BB$2)*$C31:$AX31) -> 15684 | BC31: =SUMPRODUCT((YEAR($C$2:$AX$2)=BC$2)*$C31:$AX31) -> 15684
B33: Total costs | C33: =C17+C29+C31 -> 50394.733 | D33: =D17+D29+D31 -> 50394.733 | E33: =E17+E29+E31 -> 55110.333 | F33: =F17+F29+F31 -> 59825.933 | G33: =G17+G29+G31 -> 59825.933 | H33: =H17+H29+H31 -> 71375.933 | I33: =I17+I29+I31 -> 65600.933 | J33: =J17+J29+J31 -> 71375.933 | ... AX33: =AX17+AX29+AX31 -> 1192516.1 | AZ33: =SUMPRODUCT((YEAR($C$2:$AX$2)=AZ$2)*$C33:$AX33) -> 815417.2 | BA33: =SUMPRODUCT((YEAR($C$2:$AX$2)=BA$2)*$C33:$AX33) -> 1840202.4 | BB33: =SUMPRODUCT((YEAR($C$2:$AX$2)=BB$2)*$C33:$AX33) -> 4763887.6 | BC33: =SUMPRODUCT((YEAR($C$2:$AX$2)=BC$2)*$C33:$AX33) -> 11396041
B35: EBITDA (total) | C35: =C8-C33 -> -37269.733 | D35: =D8-D33 -> -30707.233 | E35: =E8-E33 -> -14797.833 | F35: =F8-F33 -> -12950.933 | G35: =G8-G33 -> 174.06667 | H35: =H8-H33 -> 10186.567 | I35: =I8-I33 -> 8461.5667 | J35: =J8-J33 -> 10186.567 | ... AX35: =AX8-AX33 -> 1644358.9 | AZ35: =SUMPRODUCT((YEAR($C$2:$AX$2)=AZ$2)*$C35:$AX35) -> 33020.3 | BA35: =SUMPRODUCT((YEAR($C$2:$AX$2)=BA$2)*$C35:$AX35) -> 1383860.1 | BB35: =SUMPRODUCT((YEAR($C$2:$AX$2)=BB$2)*$C35:$AX35) -> 5705924.9 | BC35: =SUMPRODUCT((YEAR($C$2:$AX$2)=BC$2)*$C35:$AX35) -> 15503647
B36: EBITDA margin (total) | C36: =IF(C8=0,0,C35/C8) -> -2.8395987 | D36: =IF(D8=0,0,D35/D8) -> -1.5597325 | E36: =IF(E8=0,0,E35/E8) -> -0.36707804 | F36: =IF(F8=0,0,F35/F8) -> -0.27628658 | G36: =IF(G8=0,0,G35/G8) -> 0.0029011111 | H36: =IF(H8=0,0,H35/H8) -> 0.12489277 | I36: =IF(I8=0,0,I35/I8) -> 0.114249 | J36: =IF(J8=0,0,J35/J8) -> 0.12489277 | ... AX36: =IF(AX8=0,0,AX35/AX8) -> 0.57963741 | AZ36: =IF(AZ8=0,0,AZ35/AZ8) -> 0.038918954 | BA36: =IF(BA8=0,0,BA35/BA8) -> 0.42922868 | BB36: =IF(BB8=0,0,BB35/BB8) -> 0.54498826 | BC36: =IF(BC8=0,0,BC35/BC8) -> 0.57635044
B38: EBITDA (without success fee) | C38: =C5-C33+C12 -> -36394.733 | D38: =D5-D33+D12 -> -29394.733 | E38: =E5-E33+E12 -> -12110.333 | F38: =F5-F33+F12 -> -9825.9333 | G38: =G5-G33+G12 -> 4174.0667 | H38: =H5-H33+H12 -> -2825.9333 | I38: =I5-I33+I12 -> 4174.0667 | J38: =J5-J33+J12 -> -2825.9333 | ... AX38: =AX5-AX33+AX12 -> 145308.87 | AZ38: =SUMPRODUCT((YEAR($C$2:$AX$2)=AZ$2)*$C38:$AX38) -> -85692.2 | BA38: =SUMPRODUCT((YEAR($C$2:$AX$2)=BA$2)*$C38:$AX38) -> 350347.6 | BB38: =SUMPRODUCT((YEAR($C$2:$AX$2)=BB$2)*$C38:$AX38) -> 927460.4 | BC38: =SUMPRODUCT((YEAR($C$2:$AX$2)=BC$2)*$C38:$AX38) -> 1596009.2
B39: EBITDA margin (without success fee) | C39: =IF(C5=0,0,C38/C5) -> -2.5996238 | D39: =IF(D5=0,0,D38/D5) -> -1.3997492 | E39: =IF(E5=0,0,E38/E5) -> -0.28163566 | F39: =IF(F5=0,0,F38/F5) -> -0.19651867 | G39: =IF(G5=0,0,G38/G5) -> 0.065219792 | H39: =IF(H5=0,0,H38/H5) -> -0.049577778 | I39: =IF(I5=0,0,I38/I5) -> 0.065219792 | J39: =IF(J5=0,0,J38/J5) -> -0.049577778 | ... AX39: =IF(AX5=0,0,AX38/AX5) -> 0.5171134 | AZ39: =IF(AZ5=0,0,AZ38/AZ5) -> -0.13821323 | BA39: =IF(BA5=0,0,BA38/BA5) -> 0.24864982 | BB39: =IF(BB5=0,0,BB38/BB5) -> 0.40983668 | BC39: =IF(BC5=0,0,BC38/BC5) -> 0.50458716

Sheet Dashboard
B2: Dashboard — Annual Summary 2027–2030
C4: 2027 | D4: 2028 | E4: 2029 | F4: 2030
B5: Revenue (gross) | C5: ='Revenue forecast'!BC25 -> 905000 | D5: ='Revenue forecast'!BD25 -> 3439000 | E5: ='Revenue forecast'!BE25 -> 11167800 | F5: ='Revenue forecast'!BF25 -> 28693000
B6: Net revenue | C6: ='Financial Statements'!AZ8 -> 848437.5 | D6: ='Financial Statements'!BA8 -> 3224062.5 | E6: ='Financial Statements'!BB8 -> 10469812 | F6: ='Financial Statements'!BC8 -> 26899688
B7: EBITDA | C7: ='Financial Statements'!AZ35 -> 33020.3 | D7: ='Financial Statements'!BA35 -> 1383860.1 | E7: ='Financial Statements'!BB35 -> 5705924.9 | F7: ='Financial Statements'!BC35 -> 15503647
B8: EBITDA margin % | C8: ='Financial Statements'!AZ36 -> 0.038918954 | D8: ='Financial Statements'!BA36 -> 0.42922868 | E8: ='Financial Statements'!BB36 -> 0.54498826 | F8: ='Financial Statements'!BC36 -> 0.57635044
B9: New deals | C9: =Assumptions!C21 -> 20 | D9: =Assumptions!D21 -> 40 | E9: =Assumptions!E21 -> 58 | F9: =Assumptions!F21 -> 74
B10: Live projects (avg) | C10: =Personnel!BC7 -> 8 | D10: =Personnel!BD7 -> 18 | E10: =Personnel!BE7 -> 28 | F10: =Personnel!BF7 -> 37
B11: Total FTE | C11: =Personnel!BC14 -> 8 | D11: =Personnel!BD14 -> 13 | E11: =Personnel!BE14 -> 17 | F11: =Personnel!BF14 -> 20
