Workbook

Sheet Cover
B15: Financial Model
B19: Currency: EUR (€)
B21: STRICTLY CONFIDENTIAL

Sheet How to read me
B1: Tarnoc — How to Read This Model
B3: COLOR CODING
B4: Sample | C4: Assumptions are hardcoded inputs (sourced from documents)
B5: Sample | C5: Hardcoded historicalsis actual data from source documents
B6: Sample | C6: Formula cells are calculated, not hardcoded
B7: Sample | C7: Subtotal / total rows
B8: Sample | C8: Section headers / grand totals
B9: Sample | C9: Subsection headers
B10: Sample | C10: Margin / ratio rows (grey)
B11: Sample | C11: Balance sheet check rows (must = 0)
B14: FORMULA ARCHITECTURE
B15: Assumptions → Revenue Forecast, COGS, OPEX, CAPEX, Personnel (all drivers sourced here)
B16: Revenue Forecast → Financial Statements (revenue lines via cross-sheet links)
B17: COGS → Financial Statements (cost lines via cross-sheet links)
B18: OPEX → Financial Statements (opex lines via cross-sheet links)
B20: To change a number: ONLY edit cells in the Assumptions tab (yellow/orange).
B21: All other tabs will recalculate automatically.
B24: FURTHER EXPLANATIONS
B25: Subsidies: Tarnoc is and has been eligible for a number of subsidies. We will consider application for large projects, however this model excludes the forecast of any subsidy financing foing forward.
B26: Installation revenues: This is modelled fully as pass through revenue for now, as we plan to charge a customer exactly what we pay the installation partner for these services. This is subject to change in the future.
B27: Tarnoc's main products are the TTK (turbineketel), the Combi and Combi+ (turbineketel + outdoor unit), and the Twincycle (in development for 2027). Every unit contains a turbineketel; the Combi and Combi+ differ only by their outdoor unit and installation. We also plan to sell various add-ons such as performance booster units, boilers for hybrid setups, and sound reduction units.
B28: Service Revenues: Service revenues are calculated relative to installed base. We assume a certain percentage (see assumptions) of customers will purchase our Service package, and are charged annually.
... B30: Sales and Marketing costs are largely driven by permfomance marketing, and are calcualted on a volume and CPL basis. ]

Sheet Assumptions
B2: Drivers & Assumptions
B3: ASSUMPTIONS
B5: General Assumptions
B6: Opening Cash Balance (Jan 2024) | C6: 29538.9
B7: Annual salary increase (%) | C7: 0.08
B8: Employer cost basis | C8: Werkgeverlasten (incl. taxes)
B9: Holiday pay (%) | C9: 0.08
B10: Income tax rate | C10: 0.258
B12: Working Capital | H12: 20
B14: Days Sales Outstanding (DSO) | C14: days | D14: 20
B15: Days Payable Outstanding (DPO) | C15: days | D15: 45
B16: Days Inventory Outstanding (DIO) | C16: days | D16: 0
B17: Pre-payment | C17: %
B19: Revenue Build
B20: Units sold
C21: 2026 | D21: 2027 | E21: 2028 | F21: 2029 | G21: 2030
B22: TTK | C22: 0 | D22: 600 | E22: 2000 | F22: 4000 | G22: 8000
B23: Combi | C23: 0 | D23: 450 | E23: 1500 | F23: 3000 | G23: 6000
B24: Combi+ | C24: 0 | D24: 450 | E24: 1500 | F24: 3000 | G24: 6000
B25: Discounter | C25: 1 | D25: 1 | E25: 0.6
B27: Pricing
B28: PRICING — build-up (turbineketel + outdoor unit), ex VAT
B29: Turbineketel base price (all products) | C29: =10800/1.21 -> 8925.6198 | D29: Mgmt input — gross €10,800 incl VAT
B30: Outdoor unit — Combi | C30: =2725/1.21 -> 2252.0661 | D30: gross €2,725 incl VAT
B31: Outdoor unit — Combi+ | C31: =6425/1.21 -> 5309.9174 | D31: gross €6,425 incl VAT
B32: Combi price (ketel + ODU) | C32: =C29+C30 -> 11177.686 | D32: computed, ex VAT
B33: Combi+ price (ketel + ODU) | C33: =C29+C31 -> 14235.537 | D33: computed, ex VAT
B34: INSTALLATION (PASS-THROUGH; REV=COST)
B35: Installation — TTK | C35: =2800/1.21 -> 2314.0496 | D35: gross €2,800 incl VAT
B36: Installation — Combi | C36: =3800/1.21 -> 3140.4959 | D36: gross €3,800 incl VAT
B37: Installation — Combi+ | C37: =3800/1.21 -> 3140.4959 | D37: gross €3,800 incl VAT
B38: COGS
B39: TTK
B40: Bill of Materials TTK supplier 1
B41: # | C41: Category | D41: Component | E41: 1,000 units | F41: 5,000 units | G41: 10,000 units | H41: Unit | I41: Source
B42: B1 | C42: Supplier 1 | D42: Compressor + VFD | E42: 6314 | F42: 4500 | G42: 2692.44 | H42: €/unit | I42: Source: BOM data provided
B43: B2 | C43: Supplier 1 | D43: Heat exchangers (set) | E43: 805.5 | F43: =E43*0.7 -> 563.85 | G43: =0.6*F43 -> 338.31 | H43: €/unit | I43: Source: BOM data provided
B44: B3 | C44: Supplier 1 | D44: Electronics & Power Electronics | E44: 632.92 | F44: =E44*0.7 -> 443.044 | G44: =0.6*F44 -> 265.8264 | H44: €/unit | I44: Source: BOM data provided
B45: B4 | C45: Supplier 1 | D45: Hydraulic Components (Pumps, Valves, etc.) | E45: 283.76 | F45: =E45*0.7 -> 198.632 | G45: =0.6*F45 -> 119.1792 | H45: €/unit | I45: Source: BOM data provided
B46: B5 | C46: Supplier 1 | D46: Silencer & Insulation | E46: 118.48 | F46: =E46*0.7 -> 82.936 | G46: =0.6*F46 -> 49.7616 | H46: €/unit | I46: Source: BOM data provided
...

Sheet Financial Statements
B1: Tarnoc B.V. — Financial Statements (€)
E2: 2025 | Q2: 2026 | AC2: 2027 | AO2: 2028
E3: 45658 | F3: 45689 | G3: 45717 | H3: 45748 | I3: 45778 | J3: 45809 | K3: 45839 | L3: 45870 | M3: 45901 | N3: 45931 | O3: 45962 | P3: 45992 | Q3: 46023 | R3: 46054 | S3: 46082 | T3: 46113 | U3: 46143 | V3: 46174 | W3: 46204 | X3: 46235 | Y3: 46266 | Z3: 46296 | AA3: 46327 | AB3: 46357 | AC3: 46388 | AD3: 46419 | AE3: 46447 | AF3: 46478 | AG3: 46508 | AH3: 46539 | AI3: 46569 | AJ3: 46600 | AK3: 46631 | AL3: 46661 | AM3: 46692 | AN3: 46722 | AO3: 46753 | AP3: 46784 | AQ3: 46813 | AR3: 46844 | AS3: 46874 | AT3: 46905 | AU3: 46935 | AV3: 46966 | AW3: 46997 | AX3: 47027 | AY3: 47058 | AZ3: 47088 | BB3: 2025 | BC3: 2026 | BD3: 2027 | BE3: 2028 | BF3: 2029
B5: PROFIT & LOSS STATEMENT
B6: Revenues
B7: TTK | D7: € | M7: ='Revenue Forecast'!M9 | N7: ='Revenue Forecast'!N9 | O7: ='Revenue Forecast'!O9 | P7: ='Revenue Forecast'!P9 | Q7: ='Revenue Forecast'!Q9 -> 0 | R7: ='Revenue Forecast'!R9 -> 0 | S7: ='Revenue Forecast'!S9 -> 0 | T7: ='Revenue Forecast'!T9 -> 0 | ... AZ7: ='Revenue Forecast'!AZ9 -> 2413699.2 | BB7: =sum(E7:P7) -> 0 | BC7: =sum(Q7:AB7) -> 0 | BD7: =sum(AC7:AN7) -> 6147390.1 | BE7: =sum(AO7:AZ7) -> 18366742 | BF7: ='Revenue Forecast'!BF9 -> 36733484
B8: Combi | D8: € | M8: ='Revenue Forecast'!M15 | N8: ='Revenue Forecast'!N15 | O8: ='Revenue Forecast'!O15 | P8: ='Revenue Forecast'!P15 | Q8: ='Revenue Forecast'!Q15 -> 0 | R8: ='Revenue Forecast'!R15 -> 0 | S8: ='Revenue Forecast'!S15 -> 0 | T8: ='Revenue Forecast'!T15 -> 0 | ... AZ8: ='Revenue Forecast'!AZ15 -> 2651491.3 | BB8: =sum(E8:P8) -> 0 | BC8: =sum(Q8:AB8) -> 0 | BD8: =sum(AC8:AN8) -> 4543745 | BE8: =sum(AO8:AZ8) -> 18210022 | BF8: ='Revenue Forecast'!BF15 -> 36420044
B9: Combi+ | Q9: ='Revenue Forecast'!Q21 -> 0 | R9: ='Revenue Forecast'!R21 -> 0 | S9: ='Revenue Forecast'!S21 -> 0 | T9: ='Revenue Forecast'!T21 -> 0 | U9: ='Revenue Forecast'!U21 -> 0 | V9: ='Revenue Forecast'!V21 -> 0 | W9: ='Revenue Forecast'!W21 -> 0 | X9: ='Revenue Forecast'!X21 -> 0 | ... AZ9: ='Revenue Forecast'!AZ21 -> 3345623.6 | BB9: ='Revenue Forecast'!BB21 -> 0 | BC9: ='Revenue Forecast'!BC21 -> 0 | BD9: ='Revenue Forecast'!BD21 -> 5733249.2 | BE9: ='Revenue Forecast'!BE21 -> 22977212 | BF9: ='Revenue Forecast'!BF21 -> 45954424
B10: Other | M10: ='Revenue Forecast'!M25+'Revenue Forecast'!M31 -> 0 | N10: ='Revenue Forecast'!N25+'Revenue Forecast'!N31 -> 0 | O10: ='Revenue Forecast'!O25+'Revenue Forecast'!O31 -> 0 | P10: ='Revenue Forecast'!P25+'Revenue Forecast'!P31 -> 0 | Q10: ='Revenue Forecast'!Q25+'Revenue Forecast'!Q31 -> 0 | R10: ='Revenue Forecast'!R25+'Revenue Forecast'!R31 -> 0 | S10: ='Revenue Forecast'!S25+'Revenue Forecast'!S31 -> 0 | T10: ='Revenue Forecast'!T25+'Revenue Forecast'!T31 -> 0 | ... AZ10: ='Revenue Forecast'!AZ25+'Revenue Forecast'!AZ31 -> 2080971.8 | BB10: =sum(E10:P10) -> 0 | BC10: =sum(Q10:AB10) -> 0 | BD10: =sum(AC10:AN10) -> 4050736.1 | BE10: =sum(AO10:AZ10) -> 14748059 | BF10: ='Revenue Forecast'!BF25+'Revenue Forecast'!BF31 -> 29944341
B11: Subsidies & grants | D11: € | M11: ='Revenue Forecast'!M35 -> 0 | N11: ='Revenue Forecast'!N35 -> 19480 | O11: ='Revenue Forecast'!O35 -> 78000 | P11: ='Revenue Forecast'!P35 -> 0 | Q11: ='Revenue Forecast'!Q35 -> 0 | R11: ='Revenue Forecast'!R35 -> 0 | S11: ='Revenue Forecast'!S35 -> 0 | T11: 0 | U11: ='Revenue Forecast'!U35 -> 0 | V11: 106782 | W11: ='Revenue Forecast'!W35 -> 0 | X11: ='Revenue Forecast'!X35 -> 0 | Y11: ='Revenue Forecast'!Y35 -> 0 | Z11: ='Revenue Forecast'!Z35 -> 0 | AA11: ='Revenue Forecast'!AA35 -> 0 | AB11: ='Revenue Forecast'!AB35 -> 0 | AC11: ='Revenue Forecast'!AC35 -> 0 | AD11: ='Revenue Forecast'!AD35 -> 0 | ... AZ11: ='Revenue Forecast'!AZ35 -> 0 | BB11: =sum(E11:P11) -> 97480 | BC11: =sum(Q11:AB11) -> 106782 | BD11: pm | BE11: pm | BF11: pm
B12: Total Revenue | D12: € | M12: ='Revenue Forecast'!M37 -> 0 | N12: ='Revenue Forecast'!N37 -> 19480 | O12: ='Revenue Forecast'!O37 -> 78000 | P12: ='Revenue Forecast'!P37 -> 0 | Q12: ='Revenue Forecast'!Q37 -> 0 | R12: ='Revenue Forecast'!R37 -> 0 | S12: ='Revenue Forecast'!S37 -> 0 | T12: ='Revenue Forecast'!T37 -> 0 | ... AZ12: ='Revenue Forecast'!AZ37 -> 10491786 | BB12: =sum(E12:P12) -> 97480 | BC12: =sum(Q12:AB12) -> 106782 | BD12: =sum(AC12:AN12) -> 20475120 | BE12: =sum(AO12:AZ12) -> 74302035 | BF12: =sum(BF7:BF11) -> 1.4905229e+08
B14: Cost of goods sold
B15: TTK | D15: € | E15: =COGS!E9 | F15: =COGS!F9 | G15: =COGS!G9 | H15: =COGS!H9 | I15: =COGS!I9 | J15: =COGS!J9 | K15: =COGS!K9 | L15: =COGS!L9 | ... AZ15: =COGS!AZ9 -> 1868094.5 | BB15: =sum(E15:P15) -> 0 | BC15: =sum(Q15:AB15) -> 0 | BD15: =sum(AC15:AN15) -> 4757803.1 | BE15: =sum(AO15:AZ15) -> 14215031 | BF15: =COGS!BF9 -> 20328549
B16: Combi | D16: € | E16: =COGS!E14 | F16: =COGS!F14 | G16: =COGS!G14 | H16: =COGS!H14 | I16: =COGS!I14 | J16: =COGS!J14 | K16: =COGS!K14 | L16: =COGS!L14 | ... AZ16: =COGS!AZ14 -> 1946662.1 | BB16: =sum(E16:P16) -> 0 | BC16: =sum(Q16:AB16) -> 0 | BD16: =sum(AC16:AN16) -> 3335910 | BE16: =sum(AO16:AZ16) -> 13369367 | BF16: =COGS!BF14 -> 19556938
B17: Combi+ | Q17: =COGS!Q19 -> 0 | R17: =COGS!R19 -> 0 | S17: =COGS!S19 -> 0 | T17: =COGS!T19 -> 0 | U17: =COGS!U19 -> 0 | V17: =COGS!V19 -> 0 | W17: =COGS!W19 -> 0 | X17: =COGS!X19 -> 0 | ... AZ17: =COGS!AZ19 -> 1997564.6 | BB17: =COGS!BB19 | BC17: =COGS!BC19 -> 0 | BD17: =COGS!BD19 -> 3423139.3 | BE17: =COGS!BE19 -> 13718957 | BF17: =COGS!BF19 -> 20123260
B18: Other | E18: =COGS!E22 | F18: =COGS!F22 | G18: =COGS!G22 | H18: =COGS!H22 | I18: =COGS!I22 | J18: =COGS!J22 | K18: =COGS!K22 | L18: =COGS!L22 | ... P18: =COGS!P22 | Q18: =COGS!Q22+COGS!Q27 -> 0 | R18: =COGS!R22+COGS!R27 -> 0 | S18: =COGS!S22+COGS!S27 -> 0 | T18: =COGS!T22+COGS!T27 -> 0 | U18: =COGS!U22+COGS!U27 -> 0 | V18: =COGS!V22+COGS!V27 -> 0 | W18: =COGS!W22+COGS!W27 -> 0 | X18: =COGS!X22+COGS!X27 -> 0 | ... AZ18: =COGS!AZ22+COGS!AZ27 -> 2047119.8 | BB18: =sum(E18:P18) -> 0 | BC18: =sum(Q18:AB18) -> 0 | BD18: =sum(AC18:AN18) -> 3997540.1 | BE18: =sum(AO18:AZ18) -> 14506408 | BF18: =COGS!BF22 -> 28599669
B19: Total COGS | D19: € | M19: =COGS!M29 -> 0 | N19: =COGS!N29 -> 0 | O19: =COGS!O29 -> 0 | P19: =COGS!P29 -> 0 | Q19: =COGS!Q29 -> 0 | R19: =COGS!R29 -> 0 | S19: =COGS!S29 -> 0 | T19: =COGS!T29 -> 0 | ... AZ19: =COGS!AZ29 -> 7859441 | BB19: =sum(E19:P19) -> 0 | BC19: =sum(Q19:AB19) -> 0 | BD19: =sum(AC19:AN19) -> 15514392 | BE19: =sum(AO19:AZ19) -> 55809762 | BF19: =sum(BF15:BF18) -> 88608416
B21: Gross Profit | M21: =M12-M19 -> 0 | N21: =N12-N19 -> 19480 | O21: =O12-O19 -> 78000 | P21: =P12-P19 -> 0 | Q21: =Q12-Q19 -> 0 | R21: =R12-R19 -> 0 | S21: =S12-S19 -> 0 | T21: =T12-T19 -> 0 | ... AZ21: =AZ12-AZ19 -> 2632344.9 | BB21: =sum(E21:P21) -> 97480 | BC21: =sum(Q21:AB21) -> 106782 | BD21: =sum(AC21:AN21) -> 4960727.9 | BE21: =sum(AO21:AZ21) -> 18492272 | BF21: =BF12-BF19 -> 60443877
B22: Gross margin % | D22: % | BE22: =BE21/BE12 -> 0.24887976 | BF22: =BF21/BF12 -> 0.40552128
B24: Operational expenses
B25: R&D | D25: € | M25: =OPEX!O38 -> 47500 | N25: =OPEX!P38 -> 47500 | O25: =OPEX!Q38 -> 47500 | P25: =OPEX!R38 -> 216433 | Q25: =OPEX!S38 -> 75700 | R25: =OPEX!T38 -> 75700 | S25: =OPEX!U38 -> 75700 | T25: =OPEX!V38 -> 75700 | ... AZ25: =OPEX!BB38 -> 152614.77 | BB25: =sum(E25:P25) -> 358933 | BC25: =sum(Q25:AB25) -> 1150160 | BD25: =sum(AC25:AN25) -> 1576575.2 | BE25: =sum(AO25:AZ25) -> 1821001.2 | BF25: =OPEX!BH38 -> 3056754.8
B26: S&M | D26: € | M26: =OPEX!O39 -> 0 | N26: =OPEX!P39 -> 0 | O26: =OPEX!Q39 -> 0 | P26: =OPEX!R39 -> 20000 | Q26: =OPEX!S39 -> 21000 | R26: =OPEX!T39 -> 31800 | S26: =OPEX!U39 -> 31800 | T26: =OPEX!V39 -> 31800 | ... AZ26: =OPEX!BB39 -> 195538.4 | BB26: =sum(E26:P26) -> 20000 | BC26: =sum(Q26:AB26) -> 464300 | BD26: =sum(AC26:AN26) -> 1115088 | BE26: =sum(AO26:AZ26) -> 2046330.7 | BF26: =OPEX!BH39 -> 3286395.4
B27: G&A | D27: € | M27: =OPEX!O40 -> 11500 | N27: =OPEX!P40 -> 11500 | O27: =OPEX!Q40 -> 11500 | P27: =OPEX!R40 -> 11500 | Q27: =OPEX!S40 -> 31820 | R27: =OPEX!T40 -> 31820 | S27: =OPEX!U40 -> 31820 | T27: =OPEX!V40 -> 31820 | ... AZ27: =OPEX!BB40 -> 89245.088 | BB27: =sum(E27:P27) -> 46000 | BC27: =sum(Q27:AB27) -> 462060 | BD27: =sum(AC27:AN27) -> 832843.2 | BE27: =sum(AO27:AZ27) -> 1050610.7 | BF27: =OPEX!BH40 -> 1307705.9
B28: Total OPEX | D28: € | M28: =(M27+M26+M25) -> 59000 | N28: =(N27+N26+N25) -> 59000 | O28: =(O27+O26+O25) -> 59000 | P28: =(P27+P26+P25) -> 247933 | Q28: =(Q27+Q26+Q25) -> 128520 | R28: =(R27+R26+R25) -> 139320 | S28: =(S27+S26+S25) -> 139320 | T28: =(T27+T26+T25) -> 139320 | ... AZ28: =(AZ27+AZ26+AZ25) -> 437398.26 | BB28: =sum(E28:P28) -> 424933 | BC28: =sum(Q28:AB28) -> 2076520 | BD28: =sum(AC28:AN28) -> 3524506.4 | BE28: =sum(AO28:AZ28) -> 4917942.6 | BF28: =sum(BF25:BF27) -> 7650856.1
B30: EBITDA | D30: € | M30: =M21-M28 -> -59000 | N30: =N21-N28 -> -39520 | O30: =O21-O28 -> 19000 | P30: =P21-P28 -> -247933 | Q30: =Q21-Q28 -> -128520 | R30: =R21-R28 -> -139320 | S30: =S21-S28 -> -139320 | T30: =T21-T28 -> -139320 | ... AZ30: =AZ21-AZ28 -> 2194946.6 | BB30: =sum(E30:P30) -> -327453 | BC30: =sum(Q30:AB30) -> -1969738 | BD30: =sum(AC30:AN30) -> 1436221.5 | BE30: =sum(AO30:AZ30) -> 13574330 | BF30: =BF21-BF28 -> 52793021
B31: EBITDA margin % | D31: % | BE31: =BE30/BE12 -> 0.18269123 | BF31: =BF30/BF12 -> 0.35419127
B33: Depreciation & Amortisation | D33: € | M33: 0 | N33: 0 | O33: 0 | P33: 0 | Q33: 0 | R33: 0 | S33: 0 | T33: 0 | U33: 0 | V33: 0 | W33: 0 | X33: 0 | Y33: 0 | Z33: 0 | AA33: 0 | AB33: 0 | AC33: 0 | AD33: 0 | AE33: 0 | AF33: 0 | AG33: 0 | AH33: 0 | AI33: 0 | AJ33: 0 | AK33: 0 | AL33: 0 | AM33: 0 | AN33: 0 | AO33: 0 | AP33: 0 | AQ33: 0 | AR33: 0 | AS33: 0 | AT33: 0 | AU33: 0 | AV33: 0 | AW33: 0 | AX33: 0 | AY33: 0 | AZ33: 0 | BB33: =sum(E33:P33) -> 0 | BC33: =sum(Q33:AB33) -> 0 | BD33: =sum(AC33:AN33) -> 0 | BE33: =sum(AO33:AZ33) -> 0 | BF33: 0
B34: Interst payments | D34: € | M34: 0 | N34: 0 | O34: 0 | P34: 0 | Q34: =P80*0.05/12 -> 0 | R34: =Q80*0.05/12 -> 0 | S34: =R80*0.05/12 -> 0 | T34: =S80*0.05/12 -> 0 | U34: =T80*0.05/12 -> 0 | V34: =U80*0.05/12 -> 0 | W34: =V80*0.05/12 -> 0 | X34: =W80*0.05/12 -> 0 | ... AZ34: =AY80*0.05/12 -> 2975 | BB34: =sum(E34:P34) -> 0 | BC34: =sum(Q34:AB34) -> 0 | BD34: =sum(AC34:AN34) -> 17382.925 | BE34: =sum(AO34:AZ34) -> 35700 | BF34: =BE80*0.05/12 -> 2975
B35: EBT | D35: € | M35: =M30-sum(M33:M34) -> -59000 | N35: =N30-sum(N33:N34) -> -39520 | O35: =O30-sum(O33:O34) -> 19000 | P35: =P30-sum(P33:P34) -> -247933 | Q35: =Q30-sum(Q33:Q34) -> -128520 | R35: =R30-sum(R33:R34) -> -139320 | S35: =S30-sum(S33:S34) -> -139320 | T35: =T30-sum(T33:T34) -> -139320 | ... AZ35: =AZ30-sum(AZ33:AZ34) -> 2191971.6 | BB35: =sum(E35:P35) -> -327453 | BC35: =sum(Q35:AB35) -> -1969738 | BD35: =sum(AC35:AN35) -> 1418838.6 | BE35: =sum(AO35:AZ35) -> 13538630 | BF35: =BF30-sum(BF33:BF34) -> 52790046
BE36: =BE35/BE12 -> 0.18221076 | BF36: =BF35/BF12 -> 0.35417131
B38: Income tax | D38: € | M38: 0 | N38: 0 | O38: 0 | P38: 0 | Q38: 0 | R38: 0 | S38: 0 | T38: 0 | U38: 0 | V38: 0 | W38: 0 | X38: 0 | Y38: 0 | Z38: 0 | AA38: 0 | AB38: 0 | AC38: 0 | AD38: 0 | AE38: 0 | AF38: 0 | AG38: 0 | AH38: 0 | AI38: 0 | AJ38: 0 | AK38: 0 | AL38: 0 | AM38: 0 | AN38: 0 | AO38: 0 | AP38: 0 | AQ38: 0 | AR38: 0 | AS38: 0 | AT38: 0 | AU38: 0 | AV38: 0 | AW38: 0 | AX38: 0 | AY38: 0 | AZ38: 0 | BB38: =sum(E38:P38) -> 0 | BC38: =sum(Q38:AB38) -> 0 | BD38: =sum(AC38:AN38) -> 0 | BE38: =sum(AO38:AZ38) -> 0 | BF38: =(BF35-AZ42)*Assumptions!$C$10 -> 14438552
B39: NET INCOME | D39: € | M39: =M35-M38 -> -59000 | N39: =N35-N38 -> -39520 | O39: =O35-O38 -> 19000 | P39: =P35-P38 -> -247933 | Q39: =Q35-Q38 -> -128520 | R39: =R35-R38 -> -139320 | S39: =S35-S38 -> -139320 | T39: =T35-T38 -> -139320 | ... AZ39: =AZ35-AZ38 -> 2191971.6 | BB39: =sum(E39:P39) -> -327453 | BC39: =sum(Q39:AB39) -> -1969738 | BD39: =sum(AC39:AN39) -> 1418838.6 | BE39: =sum(AO39:AZ39) -> 13538630 | BF39: =BF35-BF38 -> 38351494
B40: Profit margin % | BE40: =BE39/BE12 -> 0.18221076 | BF40: =BF39/BF12 -> 0.25730227
B42: Tax carry over to be applied | M42: 108239 | N42: =M42+(-N39*Assumptions!$C$10) -> 118435.16 | O42: =N42+(-O39*Assumptions!$C$10) -> 113533.16 | P42: =O42+(-P39*Assumptions!$C$10) -> 177499.87 | Q42: =P42+(-Q39*Assumptions!$C$10) -> 210658.03 | R42: =Q42+(-R39*Assumptions!$C$10) -> 246602.59 | S42: =R42+(-S39*Assumptions!$C$10) -> 282547.15 | T42: =S42+(-T39*Assumptions!$C$10) -> 318491.71 | U42: =T42+(-U39*Assumptions!$C$10) -> 357016.27 | ... AZ42: =AY42+(-AZ39*Assumptions!$C$10) -> -3173334.6
B44: CASH FLOW STATEMENT
B45: Net income | D45: € | M45: =M39 -> -59000 | N45: =N39 -> -39520 | O45: =O39 -> 19000 | P45: =P39 -> -247933 | Q45: =Q39 -> -128520 | R45: =R39 -> -139320 | S45: =S39 -> -139320 | T45: =T39 -> -139320 | ... AZ45: =AZ39 -> 2191971.6 | BB45: =sum(E45:P45) -> -327453 | BC45: =sum(Q45:AB45) -> -1969738 | BD45: =sum(AC45:AN45) -> 1418838.6 | BE45: =sum(AO45:AZ45) -> 13538630 | BF45: =BF39 -> 38351494
B46: Depreciation & amortisation | D46: € | M46: 0 | N46: 0 | O46: 0 | P46: 0 | Q46: 0 | R46: 0 | S46: 0 | T46: 0 | U46: 0 | V46: 0 | W46: 0 | X46: 0 | Y46: 0 | Z46: 0 | AA46: 0 | AB46: 0 | AC46: 0 | AD46: 0 | AE46: 0 | AF46: 0 | AG46: 0 | AH46: 0 | AI46: 0 | AJ46: 0 | AK46: 0 | AL46: 0 | AM46: 0 | AN46: 0 | AO46: 0 | AP46: 0 | AQ46: 0 | AR46: 0 | AS46: 0 | AT46: 0 | AU46: 0 | AV46: 0 | AW46: 0 | AX46: 0 | AY46: 0 | AZ46: 0 | BB46: =sum(E46:P46) -> 0 | BC46: =sum(Q46:AB46) -> 0 | BD46: =sum(AC46:AN46) -> 0 | BE46: =sum(AO46:AZ46) -> 0 | BF46: =BF33 -> 0
B47: Increase in accounts receivable (delta DSO) | D47: € | M47: 0 | N47: =-(N66-M66) -> -12986.667 | O47: =-(O66-N66) -> -39013.333 | P47: =-(P66-O66) -> 52000 | Q47: =-(Q66-P66) -> 0 | R47: =-(R66-Q66) -> 0 | S47: =-(S66-R66) -> 0 | T47: =-(T66-S66) -> 0 | U47: =-(U66-T66) -> 0 | ... AZ47: =-(AZ66-AY66) -> -729422.62 | BB47: =sum(E47:P47) -> 0 | BC47: =sum(Q47:AB47) -> 0 | BD47: =sum(AC47:AN47) -> -1925040.2 | BE47: =sum(AO47:AZ47) -> -5069483.7 | BF47: =-(BF66-BE66) -> -1172725
B48: Increase in accounts payable (delta DPO) | D48: € | M48: 0 | N48: =(N75-M75) -> 0 | O48: =(O75-N75) -> 0 | P48: =(P75-O75) -> 0 | Q48: =(Q75-P75) -> 0 | R48: =(R75-Q75) -> 0 | S48: =(S75-R75) -> 0 | T48: =(T75-S75) -> 0 | U48: =(U75-T75) -> 0 | ... AZ48: =(AZ75-AY75) -> 1223237.6 | BB48: =sum(E48:P48) -> 0 | BC48: =sum(Q48:AB48) -> 0 | BD48: =sum(AC48:AN48) -> 3272022.5 | BE48: =sum(AO48:AZ48) -> 8517139 | BF48: =BF75-BE75 -> -864836.17
B49: Change in inventory (delta DIO) | D49: € | M49: 0 | N49: =-(N67-M67) -> 0 | O49: =-(O67-N67) -> 0 | P49: =-(P67-O67) -> 0 | Q49: =-(Q67-P67) -> 0 | R49: =-(R67-Q67) -> 0 | S49: =-(S67-R67) -> 0 | T49: =-(T67-S67) -> 0 | U49: =-(U67-T67) -> 0 | ... AZ49: =-(AZ67-AY67) -> 0 | BB49: =sum(E49:P49) -> 0 | BC49: =sum(Q49:AB49) -> 0 | BD49: =sum(AC49:AN49) -> 0 | BE49: =sum(AO49:AZ49) -> 0 | BF49: 0
...

Sheet Revenue Forecast
B1: Tarnoc B.V. — Revenue Forecast (€, ex VAT unless noted)
E2: 2025 | Q2: 2026 | AC2: 2027 | AO2: 2028
E3: 45658 | F3: 45689 | G3: 45717 | H3: 45748 | I3: 45778 | J3: 45809 | K3: 45839 | L3: 45870 | M3: 45901 | N3: 45931 | O3: 45962 | P3: 45992 | Q3: 46023 | R3: 46054 | S3: 46082 | T3: 46113 | U3: 46143 | V3: 46174 | W3: 46204 | X3: 46235 | Y3: 46266 | Z3: 46296 | AA3: 46327 | AB3: 46357 | AC3: 46388 | AD3: 46419 | AE3: 46447 | AF3: 46478 | AG3: 46508 | AH3: 46539 | AI3: 46569 | AJ3: 46600 | AK3: 46631 | AL3: 46661 | AM3: 46692 | AN3: 46722 | AO3: 46753 | AP3: 46784 | AQ3: 46813 | AR3: 46844 | AS3: 46874 | AT3: 46905 | AU3: 46935 | AV3: 46966 | AW3: 46997 | AX3: 47027 | AY3: 47058 | AZ3: 47088 | BB3: 2025 | BC3: 2026 | BD3: 2027 | BE3: 2028 | BF3: 2029
AB4: 2 | AC4: 3 | AD4: 4 | AE4: 5 | AF4: 6 | AG4: 7 | AH4: 8 | AI4: 9 | AJ4: 10 | AK4: 11 | AL4: 12 | AM4: 13 | AN4: 14 | AO4: 15 | AP4: 16 | AQ4: 17 | AR4: 18 | AS4: 19 | AT4: 20 | AU4: 21 | AV4: 22 | AW4: 23 | AX4: 24 | AY4: 25 | AZ4: 26
B5: TURBINEKETEL (TTK)
B6: TTK units sold | D6: # | Q6: {=IF(YEAR(Q$3)=2026,0,ROUND(EXP(0.095*((YEAR(Q$3)-2027)*12+MONTH(Q$3)-1))/SUMPRODUCT(EXP(0.095*(ROW(INDIRECT("1:24"))-1)))*SUM(Assumptions!$D$22:$E$22),0))} -> 0 | R6: {=IF(YEAR(R$3)=2026,0,ROUND(EXP(0.095*((YEAR(R$3)-2027)*12+MONTH(R$3)-1))/SUMPRODUCT(EXP(0.095*(ROW(INDIRECT("1:24"))-1)))*SUM(Assumptions!$D$22:$E$22),0))} -> 0 | S6: {=IF(YEAR(S$3)=2026,0,ROUND(EXP(0.095*((YEAR(S$3)-2027)*12+MONTH(S$3)-1))/SUMPRODUCT(EXP(0.095*(ROW(INDIRECT("1:24"))-1)))*SUM(Assumptions!$D$22:$E$22),0))} -> 0 | T6: {=IF(YEAR(T$3)=2026,0,ROUND(EXP(0.095*((YEAR(T$3)-2027)*12+MONTH(T$3)-1))/SUMPRODUCT(EXP(0.095*(ROW(INDIRECT("1:24"))-1)))*SUM(Assumptions!$D$22:$E$22),0))} -> 0 | U6: {=IF(YEAR(U$3)=2026,0,ROUND(EXP(0.095*((YEAR(U$3)-2027)*12+MONTH(U$3)-1))/SUMPRODUCT(EXP(0.095*(ROW(INDIRECT("1:24"))-1)))*SUM(Assumptions!$D$22:$E$22),0))} -> 0 | V6: {=IF(YEAR(V$3)=2026,0,ROUND(EXP(0.095*((YEAR(V$3)-2027)*12+MONTH(V$3)-1))/SUMPRODUCT(EXP(0.095*(ROW(INDIRECT("1:24"))-1)))*SUM(Assumptions!$D$22:$E$22),0))} -> 0 | W6: {=IF(YEAR(W$3)=2026,0,ROUND(EXP(0.095*((YEAR(W$3)-2027)*12+MONTH(W$3)-1))/SUMPRODUCT(EXP(0.095*(ROW(INDIRECT("1:24"))-1)))*SUM(Assumptions!$D$22:$E$22),0))} -> 0 | X6: {=IF(YEAR(X$3)=2026,0,ROUND(EXP(0.095*((YEAR(X$3)-2027)*12+MONTH(X$3)-1))/SUMPRODUCT(EXP(0.095*(ROW(INDIRECT("1:24"))-1)))*SUM(Assumptions!$D$22:$E$22),0))} -> 0 | ... AB6: {=IF(YEAR(AB$3)=2026,0,ROUND(EXP(0.095*((YEAR(AB$3)-2027)*12+MONTH(AB$3)-1))/SUMPRODUCT(EXP(0.095*(ROW(INDIRECT("1:24"))-1)))*SUM(Assumptions!$D$22:$E$22),0))} -> 0 | AC6: {=IF(YEAR(AC$3)=2026,0,ROUND(EXP(0.091*((YEAR(AC$3)-2027)*12+MONTH(AC$3)-1))/SUMPRODUCT(EXP(0.091*(ROW(INDIRECT("1:24"))-1)))*SUM(Assumptions!$D$22:$E$22),0))} -> 31 | AD6: {=IF(YEAR(AD$3)=2026,0,ROUND(EXP(0.091*((YEAR(AD$3)-2027)*12+MONTH(AD$3)-1))/SUMPRODUCT(EXP(0.091*(ROW(INDIRECT("1:24"))-1)))*SUM(Assumptions!$D$22:$E$22),0))} -> 34 | AE6: {=IF(YEAR(AE$3)=2026,0,ROUND(EXP(0.091*((YEAR(AE$3)-2027)*12+MONTH(AE$3)-1))/SUMPRODUCT(EXP(0.091*(ROW(INDIRECT("1:24"))-1)))*SUM(Assumptions!$D$22:$E$22),0))} -> 38 | AF6: {=IF(YEAR(AF$3)=2026,0,ROUND(EXP(0.091*((YEAR(AF$3)-2027)*12+MONTH(AF$3)-1))/SUMPRODUCT(EXP(0.091*(ROW(INDIRECT("1:24"))-1)))*SUM(Assumptions!$D$22:$E$22),0))} -> 41 | AG6: {=IF(YEAR(AG$3)=2026,0,ROUND(EXP(0.091*((YEAR(AG$3)-2027)*12+MONTH(AG$3)-1))/SUMPRODUCT(EXP(0.091*(ROW(INDIRECT("1:24"))-1)))*SUM(Assumptions!$D$22:$E$22),0))} -> 45 | AH6: {=IF(YEAR(AH$3)=2026,0,ROUND(EXP(0.091*((YEAR(AH$3)-2027)*12+MONTH(AH$3)-1))/SUMPRODUCT(EXP(0.091*(ROW(INDIRECT("1:24"))-1)))*SUM(Assumptions!$D$22:$E$22),0))} -> 50 | AI6: {=IF(YEAR(AI$3)=2026,0,ROUND(EXP(0.091*((YEAR(AI$3)-2027)*12+MONTH(AI$3)-1))/SUMPRODUCT(EXP(0.091*(ROW(INDIRECT("1:24"))-1)))*SUM(Assumptions!$D$22:$E$22),0))} -> 54 | AJ6: {=IF(YEAR(AJ$3)=2026,0,ROUND(EXP(0.091*((YEAR(AJ$3)-2027)*12+MONTH(AJ$3)-1))/SUMPRODUCT(EXP(0.091*(ROW(INDIRECT("1:24"))-1)))*SUM(Assumptions!$D$22:$E$22),0))} -> 59 | ... AN6: {=IF(YEAR(AN$3)=2026,0,ROUND(EXP(0.091*((YEAR(AN$3)-2027)*12+MONTH(AN$3)-1))/SUMPRODUCT(EXP(0.091*(ROW(INDIRECT("1:24"))-1)))*SUM(Assumptions!$D$22:$E$22),0))} -> 86 | AO6: {=IF(YEAR(AO$3)=2026,0,ROUND(EXP(0.0915*((YEAR(AO$3)-2027)*12+MONTH(AO$3)-1))/SUMPRODUCT(EXP(0.0915*(ROW(INDIRECT("1:24"))-1)))*SUM(Assumptions!$D$22:$E$22),0))} -> 93 | AP6: {=IF(YEAR(AP$3)=2026,0,ROUND(EXP(0.0915*((YEAR(AP$3)-2027)*12+MONTH(AP$3)-1))/SUMPRODUCT(EXP(0.0915*(ROW(INDIRECT("1:24"))-1)))*SUM(Assumptions!$D$22:$E$22),0))} -> 102 | AQ6: {=IF(YEAR(AQ$3)=2026,0,ROUND(EXP(0.0915*((YEAR(AQ$3)-2027)*12+MONTH(AQ$3)-1))/SUMPRODUCT(EXP(0.0915*(ROW(INDIRECT("1:24"))-1)))*SUM(Assumptions!$D$22:$E$22),0))} -> 112 | AR6: {=IF(YEAR(AR$3)=2026,0,ROUND(EXP(0.0915*((YEAR(AR$3)-2027)*12+MONTH(AR$3)-1))/SUMPRODUCT(EXP(0.0915*(ROW(INDIRECT("1:24"))-1)))*SUM(Assumptions!$D$22:$E$22),0))} -> 123 | AS6: {=IF(YEAR(AS$3)=2026,0,ROUND(EXP(0.0915*((YEAR(AS$3)-2027)*12+MONTH(AS$3)-1))/SUMPRODUCT(EXP(0.0915*(ROW(INDIRECT("1:24"))-1)))*SUM(Assumptions!$D$22:$E$22),0))} -> 135 | AT6: {=IF(YEAR(AT$3)=2026,0,ROUND(EXP(0.0915*((YEAR(AT$3)-2027)*12+MONTH(AT$3)-1))/SUMPRODUCT(EXP(0.0915*(ROW(INDIRECT("1:24"))-1)))*SUM(Assumptions!$D$22:$E$22),0))} -> 148 | AU6: {=IF(YEAR(AU$3)=2026,0,ROUND(EXP(0.0915*((YEAR(AU$3)-2027)*12+MONTH(AU$3)-1))/SUMPRODUCT(EXP(0.0915*(ROW(INDIRECT("1:24"))-1)))*SUM(Assumptions!$D$22:$E$22),0))} -> 162 | AV6: {=IF(YEAR(AV$3)=2026,0,ROUND(EXP(0.0915*((YEAR(AV$3)-2027)*12+MONTH(AV$3)-1))/SUMPRODUCT(EXP(0.0915*(ROW(INDIRECT("1:24"))-1)))*SUM(Assumptions!$D$22:$E$22),0))} -> 177 | ... AZ6: {=IF(YEAR(AZ$3)=2026,0,ROUND(EXP(0.0915*((YEAR(AZ$3)-2027)*12+MONTH(AZ$3)-1))/SUMPRODUCT(EXP(0.0915*(ROW(INDIRECT("1:24"))-1)))*SUM(Assumptions!$D$22:$E$22),0))} -> 256 | BB6: =SUM(E6:P6) -> 0 | BC6: =SUM(Q6:AB6) -> 0 | BD6: =SUM(AC6:AN6) -> 652 | BE6: =SUM(AO6:AZ6) -> 1948 | BF6: =BE6*2 -> 3896
B7: TTK Revenue | D7: € | Q7: =Q6*Assumptions!$C$29 -> 0 | R7: =R6*Assumptions!$C$29 -> 0 | S7: =S6*Assumptions!$C$29 -> 0 | T7: =T6*Assumptions!$C$29 -> 0 | U7: =U6*Assumptions!$C$29 -> 0 | V7: =V6*Assumptions!$C$29 -> 0 | W7: =W6*Assumptions!$C$29 -> 0 | X7: =X6*Assumptions!$C$29 -> 0 | ... AZ7: =AZ6*Assumptions!$C$29 -> 2284958.7 | BB7: =SUM(E7:P7) -> 0 | BC7: =SUM(Q7:AB7) -> 0 | BD7: =SUM(AC7:AN7) -> 5819504.1 | BE7: =SUM(AO7:AZ7) -> 17387107 | BF7: =BF6*Assumptions!$C$29 -> 34774215
B8: TTK upsell | D8: € | Q8: =Q6*SUMPRODUCT(Assumptions!$E$116:$F$118) -> 0 | R8: =R6*SUMPRODUCT(Assumptions!$E$116:$F$118) -> 0 | S8: =S6*SUMPRODUCT(Assumptions!$E$116:$F$118) -> 0 | T8: =T6*SUMPRODUCT(Assumptions!$E$116:$F$118) -> 0 | U8: =U6*SUMPRODUCT(Assumptions!$E$116:$F$118) -> 0 | V8: =V6*SUMPRODUCT(Assumptions!$E$116:$F$118) -> 0 | W8: =W6*SUMPRODUCT(Assumptions!$E$116:$F$118) -> 0 | X8: =X6*SUMPRODUCT(Assumptions!$E$116:$F$118) -> 0 | ... AB8: =AB6*SUMPRODUCT(Assumptions!$E$116:$F$118) -> 0 | AC8: =AC6*SUMPRODUCT(Assumptions!$E$116:$E$118,Assumptions!$F$116:$F$118) -> 15589.669 | AD8: =AD6*SUMPRODUCT(Assumptions!$E$116:$E$118,Assumptions!$F$116:$F$118) -> 17098.347 | AE8: =AE6*SUMPRODUCT(Assumptions!$E$116:$E$118,Assumptions!$F$116:$F$118) -> 19109.917 | AF8: =AF6*SUMPRODUCT(Assumptions!$E$116:$E$118,Assumptions!$F$116:$F$118) -> 20618.595 | AG8: =AG6*SUMPRODUCT(Assumptions!$E$116:$E$118,Assumptions!$F$116:$F$118) -> 22630.165 | AH8: =AH6*SUMPRODUCT(Assumptions!$E$116:$E$118,Assumptions!$F$116:$F$118) -> 25144.628 | AI8: =AI6*SUMPRODUCT(Assumptions!$E$116:$E$118,Assumptions!$F$116:$F$118) -> 27156.198 | AJ8: =AJ6*SUMPRODUCT(Assumptions!$E$116:$E$118,Assumptions!$F$116:$F$118) -> 29670.661 | ... AZ8: =AZ6*SUMPRODUCT(Assumptions!$E$116:$E$118,Assumptions!$F$116:$F$118) -> 128740.5 | BB8: =SUM(E8:P8) -> 0 | BC8: =SUM(Q8:AB8) -> 0 | BD8: =SUM(AC8:AN8) -> 327885.95 | BE8: =SUM(AO8:AZ8) -> 979634.71 | BF8: =BF6*SUMPRODUCT(Assumptions!$E$116:$E$118,Assumptions!$F$116:$F$118) -> 1959269.4
B9: Total TTK Revenue | D9: € | Q9: =sum(Q7:Q8) -> 0 | R9: =sum(R7:R8) -> 0 | S9: =sum(S7:S8) -> 0 | T9: =sum(T7:T8) -> 0 | U9: =sum(U7:U8) -> 0 | V9: =sum(V7:V8) -> 0 | W9: =sum(W7:W8) -> 0 | X9: =sum(X7:X8) -> 0 | ... AZ9: =sum(AZ7:AZ8) -> 2413699.2 | BB9: =SUM(E9:P9) -> 0 | BC9: =SUM(Q9:AB9) -> 0 | BD9: =SUM(AC9:AN9) -> 6147390.1 | BE9: =SUM(AO9:AZ9) -> 18366742 | BF9: =BE9*2 -> 36733484
B11: COMBI
B12: Combi units sold | D12: # | Q12: {=IF(YEAR(Q$3)=2026,0,ROUND(EXP(0.11*((YEAR(Q$3)-2027)*12+MONTH(Q$3)-1))/SUMPRODUCT(EXP(0.11*(ROW(INDIRECT("1:24"))-1)))*SUM(Assumptions!$D$23:$E$23),0))} -> 0 | R12: {=IF(YEAR(R$3)=2026,0,ROUND(EXP(0.11*((YEAR(R$3)-2027)*12+MONTH(R$3)-1))/SUMPRODUCT(EXP(0.11*(ROW(INDIRECT("1:24"))-1)))*SUM(Assumptions!$D$23:$E$23),0))} -> 0 | S12: {=IF(YEAR(S$3)=2026,0,ROUND(EXP(0.11*((YEAR(S$3)-2027)*12+MONTH(S$3)-1))/SUMPRODUCT(EXP(0.11*(ROW(INDIRECT("1:24"))-1)))*SUM(Assumptions!$D$23:$E$23),0))} -> 0 | T12: {=IF(YEAR(T$3)=2026,0,ROUND(EXP(0.11*((YEAR(T$3)-2027)*12+MONTH(T$3)-1))/SUMPRODUCT(EXP(0.11*(ROW(INDIRECT("1:24"))-1)))*SUM(Assumptions!$D$23:$E$23),0))} -> 0 | U12: {=IF(YEAR(U$3)=2026,0,ROUND(EXP(0.11*((YEAR(U$3)-2027)*12+MONTH(U$3)-1))/SUMPRODUCT(EXP(0.11*(ROW(INDIRECT("1:24"))-1)))*SUM(Assumptions!$D$23:$E$23),0))} -> 0 | V12: {=IF(YEAR(V$3)=2026,0,ROUND(EXP(0.11*((YEAR(V$3)-2027)*12+MONTH(V$3)-1))/SUMPRODUCT(EXP(0.11*(ROW(INDIRECT("1:24"))-1)))*SUM(Assumptions!$D$23:$E$23),0))} -> 0 | W12: {=IF(YEAR(W$3)=2026,0,ROUND(EXP(0.11*((YEAR(W$3)-2027)*12+MONTH(W$3)-1))/SUMPRODUCT(EXP(0.11*(ROW(INDIRECT("1:24"))-1)))*SUM(Assumptions!$D$23:$E$23),0))} -> 0 | X12: {=IF(YEAR(X$3)=2026,0,ROUND(EXP(0.11*((YEAR(X$3)-2027)*12+MONTH(X$3)-1))/SUMPRODUCT(EXP(0.11*(ROW(INDIRECT("1:24"))-1)))*SUM(Assumptions!$D$23:$E$23),0))} -> 0 | ... AB12: {=IF(YEAR(AB$3)=2026,0,ROUND(EXP(0.11*((YEAR(AB$3)-2027)*12+MONTH(AB$3)-1))/SUMPRODUCT(EXP(0.11*(ROW(INDIRECT("1:24"))-1)))*SUM(Assumptions!$D$23:$E$23),0))} -> 0 | AC12: {=IF(YEAR(AC$3)=2026,0,ROUND(EXP(0.116*((YEAR(AC$3)-2027)*12+MONTH(AC$3)-1))/SUMPRODUCT(EXP(0.116*(ROW(INDIRECT("1:24"))-1)))*SUM(Assumptions!$D$23:$E$23),0))} -> 16 | AD12: {=IF(YEAR(AD$3)=2026,0,ROUND(EXP(0.116*((YEAR(AD$3)-2027)*12+MONTH(AD$3)-1))/SUMPRODUCT(EXP(0.116*(ROW(INDIRECT("1:24"))-1)))*SUM(Assumptions!$D$23:$E$23),0))} -> 18 | AE12: {=IF(YEAR(AE$3)=2026,0,ROUND(EXP(0.116*((YEAR(AE$3)-2027)*12+MONTH(AE$3)-1))/SUMPRODUCT(EXP(0.116*(ROW(INDIRECT("1:24"))-1)))*SUM(Assumptions!$D$23:$E$23),0))} -> 20 | AF12: {=IF(YEAR(AF$3)=2026,0,ROUND(EXP(0.116*((YEAR(AF$3)-2027)*12+MONTH(AF$3)-1))/SUMPRODUCT(EXP(0.116*(ROW(INDIRECT("1:24"))-1)))*SUM(Assumptions!$D$23:$E$23),0))} -> 22 | AG12: {=IF(YEAR(AG$3)=2026,0,ROUND(EXP(0.116*((YEAR(AG$3)-2027)*12+MONTH(AG$3)-1))/SUMPRODUCT(EXP(0.116*(ROW(INDIRECT("1:24"))-1)))*SUM(Assumptions!$D$23:$E$23),0))} -> 25 | AH12: {=IF(YEAR(AH$3)=2026,0,ROUND(EXP(0.116*((YEAR(AH$3)-2027)*12+MONTH(AH$3)-1))/SUMPRODUCT(EXP(0.116*(ROW(INDIRECT("1:24"))-1)))*SUM(Assumptions!$D$23:$E$23),0))} -> 28 | AI12: {=IF(YEAR(AI$3)=2026,0,ROUND(EXP(0.116*((YEAR(AI$3)-2027)*12+MONTH(AI$3)-1))/SUMPRODUCT(EXP(0.116*(ROW(INDIRECT("1:24"))-1)))*SUM(Assumptions!$D$23:$E$23),0))} -> 32 | AJ12: {=IF(YEAR(AJ$3)=2026,0,ROUND(EXP(0.116*((YEAR(AJ$3)-2027)*12+MONTH(AJ$3)-1))/SUMPRODUCT(EXP(0.116*(ROW(INDIRECT("1:24"))-1)))*SUM(Assumptions!$D$23:$E$23),0))} -> 36 | ... AN12: {=IF(YEAR(AN$3)=2026,0,ROUND(EXP(0.116*((YEAR(AN$3)-2027)*12+MONTH(AN$3)-1))/SUMPRODUCT(EXP(0.116*(ROW(INDIRECT("1:24"))-1)))*SUM(Assumptions!$D$23:$E$23),0))} -> 57 | AO12: {=IF(YEAR(AO$3)=2026,0,ROUND(EXP(0.1157*((YEAR(AO$3)-2027)*12+MONTH(AO$3)-1))/SUMPRODUCT(EXP(0.1157*(ROW(INDIRECT("1:24"))-1)))*SUM(Assumptions!$D$23:$E$23),0))} -> 64 | AP12: {=IF(YEAR(AP$3)=2026,0,ROUND(EXP(0.1157*((YEAR(AP$3)-2027)*12+MONTH(AP$3)-1))/SUMPRODUCT(EXP(0.1157*(ROW(INDIRECT("1:24"))-1)))*SUM(Assumptions!$D$23:$E$23),0))} -> 71 | AQ12: {=IF(YEAR(AQ$3)=2026,0,ROUND(EXP(0.1157*((YEAR(AQ$3)-2027)*12+MONTH(AQ$3)-1))/SUMPRODUCT(EXP(0.1157*(ROW(INDIRECT("1:24"))-1)))*SUM(Assumptions!$D$23:$E$23),0))} -> 80 | AR12: {=IF(YEAR(AR$3)=2026,0,ROUND(EXP(0.1157*((YEAR(AR$3)-2027)*12+MONTH(AR$3)-1))/SUMPRODUCT(EXP(0.1157*(ROW(INDIRECT("1:24"))-1)))*SUM(Assumptions!$D$23:$E$23),0))} -> 90 | AS12: {=IF(YEAR(AS$3)=2026,0,ROUND(EXP(0.1157*((YEAR(AS$3)-2027)*12+MONTH(AS$3)-1))/SUMPRODUCT(EXP(0.1157*(ROW(INDIRECT("1:24"))-1)))*SUM(Assumptions!$D$23:$E$23),0))} -> 101 | AT12: {=IF(YEAR(AT$3)=2026,0,ROUND(EXP(0.1157*((YEAR(AT$3)-2027)*12+MONTH(AT$3)-1))/SUMPRODUCT(EXP(0.1157*(ROW(INDIRECT("1:24"))-1)))*SUM(Assumptions!$D$23:$E$23),0))} -> 113 | AU12: {=IF(YEAR(AU$3)=2026,0,ROUND(EXP(0.1157*((YEAR(AU$3)-2027)*12+MONTH(AU$3)-1))/SUMPRODUCT(EXP(0.1157*(ROW(INDIRECT("1:24"))-1)))*SUM(Assumptions!$D$23:$E$23),0))} -> 127 | AV12: {=IF(YEAR(AV$3)=2026,0,ROUND(EXP(0.1157*((YEAR(AV$3)-2027)*12+MONTH(AV$3)-1))/SUMPRODUCT(EXP(0.1157*(ROW(INDIRECT("1:24"))-1)))*SUM(Assumptions!$D$23:$E$23),0))} -> 143 | ... AZ12: {=IF(YEAR(AZ$3)=2026,0,ROUND(EXP(0.1157*((YEAR(AZ$3)-2027)*12+MONTH(AZ$3)-1))/SUMPRODUCT(EXP(0.1157*(ROW(INDIRECT("1:24"))-1)))*SUM(Assumptions!$D$23:$E$23),0))} -> 227 | BB12: =SUM(E12:P12) -> 0 | BC12: =SUM(Q12:AB12) -> 0 | BD12: =SUM(AC12:AN12) -> 389 | BE12: =SUM(AO12:AZ12) -> 1559 | BF12: =BE12*2 -> 3118
B13: Combi Revenue | D13: € | Q13: =Q12*Assumptions!$C$32 -> 0 | R13: =R12*Assumptions!$C$32 -> 0 | S13: =S12*Assumptions!$C$32 -> 0 | T13: =T12*Assumptions!$C$32 -> 0 | U13: =U12*Assumptions!$C$32 -> 0 | V13: =V12*Assumptions!$C$32 -> 0 | W13: =W12*Assumptions!$C$32 -> 0 | X13: =X12*Assumptions!$C$32 -> 0 | ... AZ13: =AZ12*Assumptions!$C$32 -> 2537334.7 | BB13: =SUM(E13:P13) -> 0 | BC13: =SUM(Q13:AB13) -> 0 | BD13: =SUM(AC13:AN13) -> 4348119.8 | BE13: =SUM(AO13:AZ13) -> 17426012 | BF13: =BF12*Assumptions!$C$32 -> 34852025
B14: Combi upsell | D14: € | Q14: =Q12*SUMPRODUCT(Assumptions!$E$116:$E$118,Assumptions!$F$116:$F$118) -> 0 | R14: =R12*SUMPRODUCT(Assumptions!$E$116:$E$118,Assumptions!$F$116:$F$118) -> 0 | S14: =S12*SUMPRODUCT(Assumptions!$E$116:$E$118,Assumptions!$F$116:$F$118) -> 0 | T14: =T12*SUMPRODUCT(Assumptions!$E$116:$E$118,Assumptions!$F$116:$F$118) -> 0 | U14: =U12*SUMPRODUCT(Assumptions!$E$116:$E$118,Assumptions!$F$116:$F$118) -> 0 | V14: =V12*SUMPRODUCT(Assumptions!$E$116:$E$118,Assumptions!$F$116:$F$118) -> 0 | W14: =W12*SUMPRODUCT(Assumptions!$E$116:$E$118,Assumptions!$F$116:$F$118) -> 0 | X14: =X12*SUMPRODUCT(Assumptions!$E$116:$E$118,Assumptions!$F$116:$F$118) -> 0 | ... AZ14: =AZ12*SUMPRODUCT(Assumptions!$E$116:$E$118,Assumptions!$F$116:$F$118) -> 114156.61 | BB14: =SUM(E14:P14) -> 0 | BC14: =SUM(Q14:AB14) -> 0 | BD14: =SUM(AC14:AN14) -> 195625.21 | BE14: =SUM(AO14:AZ14) -> 784009.5 | BF14: =BF12*SUMPRODUCT(Assumptions!$E$116:$E$118,Assumptions!$F$116:$F$118) -> 1568019
B15: Total Combi Revenue | D15: € | Q15: =sum(Q13:Q14) -> 0 | R15: =sum(R13:R14) -> 0 | S15: =sum(S13:S14) -> 0 | T15: =sum(T13:T14) -> 0 | U15: =sum(U13:U14) -> 0 | V15: =sum(V13:V14) -> 0 | W15: =sum(W13:W14) -> 0 | X15: =sum(X13:X14) -> 0 | ... AZ15: =sum(AZ13:AZ14) -> 2651491.3 | BB15: =SUM(E15:P15) -> 0 | BC15: =SUM(Q15:AB15) -> 0 | BD15: =SUM(AC15:AN15) -> 4543745 | BE15: =SUM(AO15:AZ15) -> 18210022 | BF15: =BE15*2 -> 36420044
B17: COMBI+
B18: Combi+ units sold | D18: # | Q18: {=IF(YEAR(Q$3)=2026,0,ROUND(EXP(0.11*((YEAR(Q$3)-2027)*12+MONTH(Q$3)-1))/SUMPRODUCT(EXP(0.11*(ROW(INDIRECT("1:24"))-1)))*SUM(Assumptions!$D$24:$E$24),0))} -> 0 | R18: {=IF(YEAR(R$3)=2026,0,ROUND(EXP(0.11*((YEAR(R$3)-2027)*12+MONTH(R$3)-1))/SUMPRODUCT(EXP(0.11*(ROW(INDIRECT("1:24"))-1)))*SUM(Assumptions!$D$24:$E$24),0))} -> 0 | S18: {=IF(YEAR(S$3)=2026,0,ROUND(EXP(0.11*((YEAR(S$3)-2027)*12+MONTH(S$3)-1))/SUMPRODUCT(EXP(0.11*(ROW(INDIRECT("1:24"))-1)))*SUM(Assumptions!$D$24:$E$24),0))} -> 0 | T18: {=IF(YEAR(T$3)=2026,0,ROUND(EXP(0.11*((YEAR(T$3)-2027)*12+MONTH(T$3)-1))/SUMPRODUCT(EXP(0.11*(ROW(INDIRECT("1:24"))-1)))*SUM(Assumptions!$D$24:$E$24),0))} -> 0 | U18: {=IF(YEAR(U$3)=2026,0,ROUND(EXP(0.11*((YEAR(U$3)-2027)*12+MONTH(U$3)-1))/SUMPRODUCT(EXP(0.11*(ROW(INDIRECT("1:24"))-1)))*SUM(Assumptions!$D$24:$E$24),0))} -> 0 | V18: {=IF(YEAR(V$3)=2026,0,ROUND(EXP(0.11*((YEAR(V$3)-2027)*12+MONTH(V$3)-1))/SUMPRODUCT(EXP(0.11*(ROW(INDIRECT("1:24"))-1)))*SUM(Assumptions!$D$24:$E$24),0))} -> 0 | W18: {=IF(YEAR(W$3)=2026,0,ROUND(EXP(0.11*((YEAR(W$3)-2027)*12+MONTH(W$3)-1))/SUMPRODUCT(EXP(0.11*(ROW(INDIRECT("1:24"))-1)))*SUM(Assumptions!$D$24:$E$24),0))} -> 0 | X18: {=IF(YEAR(X$3)=2026,0,ROUND(EXP(0.11*((YEAR(X$3)-2027)*12+MONTH(X$3)-1))/SUMPRODUCT(EXP(0.11*(ROW(INDIRECT("1:24"))-1)))*SUM(Assumptions!$D$24:$E$24),0))} -> 0 | ... AB18: {=IF(YEAR(AB$3)=2026,0,ROUND(EXP(0.11*((YEAR(AB$3)-2027)*12+MONTH(AB$3)-1))/SUMPRODUCT(EXP(0.11*(ROW(INDIRECT("1:24"))-1)))*SUM(Assumptions!$D$24:$E$24),0))} -> 0 | AC18: {=IF(YEAR(AC$3)=2026,0,ROUND(EXP(0.116*((YEAR(AC$3)-2027)*12+MONTH(AC$3)-1))/SUMPRODUCT(EXP(0.116*(ROW(INDIRECT("1:24"))-1)))*SUM(Assumptions!$D$24:$E$24),0))} -> 16 | AD18: {=IF(YEAR(AD$3)=2026,0,ROUND(EXP(0.116*((YEAR(AD$3)-2027)*12+MONTH(AD$3)-1))/SUMPRODUCT(EXP(0.116*(ROW(INDIRECT("1:24"))-1)))*SUM(Assumptions!$D$24:$E$24),0))} -> 18 | AE18: {=IF(YEAR(AE$3)=2026,0,ROUND(EXP(0.116*((YEAR(AE$3)-2027)*12+MONTH(AE$3)-1))/SUMPRODUCT(EXP(0.116*(ROW(INDIRECT("1:24"))-1)))*SUM(Assumptions!$D$24:$E$24),0))} -> 20 | AF18: {=IF(YEAR(AF$3)=2026,0,ROUND(EXP(0.116*((YEAR(AF$3)-2027)*12+MONTH(AF$3)-1))/SUMPRODUCT(EXP(0.116*(ROW(INDIRECT("1:24"))-1)))*SUM(Assumptions!$D$24:$E$24),0))} -> 22 | AG18: {=IF(YEAR(AG$3)=2026,0,ROUND(EXP(0.116*((YEAR(AG$3)-2027)*12+MONTH(AG$3)-1))/SUMPRODUCT(EXP(0.116*(ROW(INDIRECT("1:24"))-1)))*SUM(Assumptions!$D$24:$E$24),0))} -> 25 | AH18: {=IF(YEAR(AH$3)=2026,0,ROUND(EXP(0.116*((YEAR(AH$3)-2027)*12+MONTH(AH$3)-1))/SUMPRODUCT(EXP(0.116*(ROW(INDIRECT("1:24"))-1)))*SUM(Assumptions!$D$24:$E$24),0))} -> 28 | AI18: {=IF(YEAR(AI$3)=2026,0,ROUND(EXP(0.116*((YEAR(AI$3)-2027)*12+MONTH(AI$3)-1))/SUMPRODUCT(EXP(0.116*(ROW(INDIRECT("1:24"))-1)))*SUM(Assumptions!$D$24:$E$24),0))} -> 32 | AJ18: {=IF(YEAR(AJ$3)=2026,0,ROUND(EXP(0.116*((YEAR(AJ$3)-2027)*12+MONTH(AJ$3)-1))/SUMPRODUCT(EXP(0.116*(ROW(INDIRECT("1:24"))-1)))*SUM(Assumptions!$D$24:$E$24),0))} -> 36 | ... AN18: {=IF(YEAR(AN$3)=2026,0,ROUND(EXP(0.116*((YEAR(AN$3)-2027)*12+MONTH(AN$3)-1))/SUMPRODUCT(EXP(0.116*(ROW(INDIRECT("1:24"))-1)))*SUM(Assumptions!$D$24:$E$24),0))} -> 57 | AO18: {=IF(YEAR(AO$3)=2026,0,ROUND(EXP(0.1157*((YEAR(AO$3)-2027)*12+MONTH(AO$3)-1))/SUMPRODUCT(EXP(0.1157*(ROW(INDIRECT("1:24"))-1)))*SUM(Assumptions!$D$24:$E$24),0))} -> 64 | AP18: {=IF(YEAR(AP$3)=2026,0,ROUND(EXP(0.1157*((YEAR(AP$3)-2027)*12+MONTH(AP$3)-1))/SUMPRODUCT(EXP(0.1157*(ROW(INDIRECT("1:24"))-1)))*SUM(Assumptions!$D$24:$E$24),0))} -> 71 | AQ18: {=IF(YEAR(AQ$3)=2026,0,ROUND(EXP(0.1157*((YEAR(AQ$3)-2027)*12+MONTH(AQ$3)-1))/SUMPRODUCT(EXP(0.1157*(ROW(INDIRECT("1:24"))-1)))*SUM(Assumptions!$D$24:$E$24),0))} -> 80 | AR18: {=IF(YEAR(AR$3)=2026,0,ROUND(EXP(0.1157*((YEAR(AR$3)-2027)*12+MONTH(AR$3)-1))/SUMPRODUCT(EXP(0.1157*(ROW(INDIRECT("1:24"))-1)))*SUM(Assumptions!$D$24:$E$24),0))} -> 90 | AS18: {=IF(YEAR(AS$3)=2026,0,ROUND(EXP(0.1157*((YEAR(AS$3)-2027)*12+MONTH(AS$3)-1))/SUMPRODUCT(EXP(0.1157*(ROW(INDIRECT("1:24"))-1)))*SUM(Assumptions!$D$24:$E$24),0))} -> 101 | AT18: {=IF(YEAR(AT$3)=2026,0,ROUND(EXP(0.1157*((YEAR(AT$3)-2027)*12+MONTH(AT$3)-1))/SUMPRODUCT(EXP(0.1157*(ROW(INDIRECT("1:24"))-1)))*SUM(Assumptions!$D$24:$E$24),0))} -> 113 | AU18: {=IF(YEAR(AU$3)=2026,0,ROUND(EXP(0.1157*((YEAR(AU$3)-2027)*12+MONTH(AU$3)-1))/SUMPRODUCT(EXP(0.1157*(ROW(INDIRECT("1:24"))-1)))*SUM(Assumptions!$D$24:$E$24),0))} -> 127 | AV18: {=IF(YEAR(AV$3)=2026,0,ROUND(EXP(0.1157*((YEAR(AV$3)-2027)*12+MONTH(AV$3)-1))/SUMPRODUCT(EXP(0.1157*(ROW(INDIRECT("1:24"))-1)))*SUM(Assumptions!$D$24:$E$24),0))} -> 143 | ... AZ18: {=IF(YEAR(AZ$3)=2026,0,ROUND(EXP(0.1157*((YEAR(AZ$3)-2027)*12+MONTH(AZ$3)-1))/SUMPRODUCT(EXP(0.1157*(ROW(INDIRECT("1:24"))-1)))*SUM(Assumptions!$D$24:$E$24),0))} -> 227 | BB18: =SUM(E18:P18) -> 0 | BC18: =SUM(Q18:AB18) -> 0 | BD18: =SUM(AC18:AN18) -> 389 | BE18: =SUM(AO18:AZ18) -> 1559 | BF18: =BE18*2 -> 3118
B19: Combi+ Revenue | D19: € | Q19: =Q18*Assumptions!$C$33 -> 0 | R19: =R18*Assumptions!$C$33 -> 0 | S19: =S18*Assumptions!$C$33 -> 0 | T19: =T18*Assumptions!$C$33 -> 0 | U19: =U18*Assumptions!$C$33 -> 0 | V19: =V18*Assumptions!$C$33 -> 0 | W19: =W18*Assumptions!$C$33 -> 0 | X19: =X18*Assumptions!$C$33 -> 0 | ... AZ19: =AZ18*Assumptions!$C$33 -> 3231466.9 | BB19: =SUM(E19:P19) -> 0 | BC19: =SUM(Q19:AB19) -> 0 | BD19: =SUM(AC19:AN19) -> 5537624 | BE19: =SUM(AO19:AZ19) -> 22193202 | BF19: =BF18*Assumptions!$C$33 -> 44386405
B20: Combi+ upsell | D20: € | Q20: =Q18*SUMPRODUCT(Assumptions!$E$116:$E$118,Assumptions!$F$116:$F$118) -> 0 | R20: =R18*SUMPRODUCT(Assumptions!$E$116:$E$118,Assumptions!$F$116:$F$118) -> 0 | S20: =S18*SUMPRODUCT(Assumptions!$E$116:$E$118,Assumptions!$F$116:$F$118) -> 0 | T20: =T18*SUMPRODUCT(Assumptions!$E$116:$E$118,Assumptions!$F$116:$F$118) -> 0 | U20: =U18*SUMPRODUCT(Assumptions!$E$116:$E$118,Assumptions!$F$116:$F$118) -> 0 | V20: =V18*SUMPRODUCT(Assumptions!$E$116:$E$118,Assumptions!$F$116:$F$118) -> 0 | W20: =W18*SUMPRODUCT(Assumptions!$E$116:$E$118,Assumptions!$F$116:$F$118) -> 0 | X20: =X18*SUMPRODUCT(Assumptions!$E$116:$E$118,Assumptions!$F$116:$F$118) -> 0 | ... AZ20: =AZ18*SUMPRODUCT(Assumptions!$E$116:$E$118,Assumptions!$F$116:$F$118) -> 114156.61 | BB20: =SUM(E20:P20) -> 0 | BC20: =SUM(Q20:AB20) -> 0 | BD20: =SUM(AC20:AN20) -> 195625.21 | BE20: =SUM(AO20:AZ20) -> 784009.5 | BF20: =BF18*SUMPRODUCT(Assumptions!$E$116:$E$118,Assumptions!$F$116:$F$118) -> 1568019
B21: Total Combi+ Revenue | D21: € | Q21: =sum(Q19:Q20) -> 0 | R21: =sum(R19:R20) -> 0 | S21: =sum(S19:S20) -> 0 | T21: =sum(T19:T20) -> 0 | U21: =sum(U19:U20) -> 0 | V21: =sum(V19:V20) -> 0 | W21: =sum(W19:W20) -> 0 | X21: =sum(X19:X20) -> 0 | ... AZ21: =sum(AZ19:AZ20) -> 3345623.6 | BB21: =SUM(E21:P21) -> 0 | BC21: =SUM(Q21:AB21) -> 0 | BD21: =SUM(AC21:AN21) -> 5733249.2 | BE21: =SUM(AO21:AZ21) -> 22977212 | BF21: =BE21*2 -> 45954424
B23: INSTALLATION REVENUES | D23: €
B24: Units installed | D24: # | E24: =E6+E12+E18 -> 0 | F24: =F6+F12+F18 -> 0 | G24: =G6+G12+G18 -> 0 | H24: =H6+H12+H18 -> 0 | I24: =I6+I12+I18 -> 0 | J24: =J6+J12+J18 -> 0 | K24: =K6+K12+K18 -> 0 | L24: =L6+L12+L18 -> 0 | ... AZ24: =AZ6+AZ12+AZ18 -> 710 | BB24: =SUM(E24:P24) -> 0 | BC24: =SUM(Q24:AB24) -> 0 | BD24: =SUM(AC24:AN24) -> 1430 | BE24: =SUM(AO24:AZ24) -> 5066 | BF24: =BF6+BF12+BF18 -> 10132
B25: Total Installation Revenue | D25: € | E25: =E6*Assumptions!$C$35+E12*Assumptions!$C$36+E18*Assumptions!$C$37 -> 0 | F25: =F6*Assumptions!$C$35+F12*Assumptions!$C$36+F18*Assumptions!$C$37 -> 0 | G25: =G6*Assumptions!$C$35+G12*Assumptions!$C$36+G18*Assumptions!$C$37 -> 0 | H25: =H6*Assumptions!$C$35+H12*Assumptions!$C$36+H18*Assumptions!$C$37 -> 0 | I25: =I6*Assumptions!$C$35+I12*Assumptions!$C$36+I18*Assumptions!$C$37 -> 0 | J25: =J6*Assumptions!$C$35+J12*Assumptions!$C$36+J18*Assumptions!$C$37 -> 0 | K25: =K6*Assumptions!$C$35+K12*Assumptions!$C$36+K18*Assumptions!$C$37 -> 0 | L25: =L6*Assumptions!$C$35+L12*Assumptions!$C$36+L18*Assumptions!$C$37 -> 0 | ... AZ25: =AZ6*Assumptions!$C$35+AZ12*Assumptions!$C$36+AZ18*Assumptions!$C$37 -> 2018181.8 | BB25: =SUM(E25:P25) -> 0 | BC25: =SUM(Q25:AB25) -> 0 | BD25: =SUM(AC25:AN25) -> 3952066.1 | BE25: =SUM(AO25:AZ25) -> 14299835 | BF25: =BE25*2 -> 28599669
B27: SERVICE REVENUES
B28: Installed base (TTK) | D28: # | Q28: =Q6 -> 0 | R28: =R6 -> 0 | S28: =S6 -> 0 | T28: =T6 -> 0 | U28: =U6 -> 0 | V28: =V6 -> 0 | W28: =W6 -> 0 | X28: =X6 -> 0 | ... AC28: =AC6 -> 31 | AD28: =AC28+AD6 -> 65 | AE28: =AD28+AE6 -> 103 | AF28: =AE28+AF6 -> 144 | AG28: =AF28+AG6 -> 189 | AH28: =AG28+AH6 -> 239 | AI28: =AH28+AI6 -> 293 | AJ28: =AI28+AJ6 -> 352 | AK28: =AJ28+AK6 -> 417 | ... AZ28: =AY28+AZ6 -> 2600 | BB28: =SUM(E28:P28) -> 0 | BC28: =SUM(Q28:AB28) -> 0 | BD28: =AN28 -> 652 | BE28: =AZ28 -> 2600 | BF28: =BF24*0.4 -> 4052.8
B29: Installed base (Combi) | D29: # | Q29: =Q12 -> 0 | R29: =R12 -> 0 | S29: =S12 -> 0 | T29: =T12 -> 0 | U29: =U12 -> 0 | V29: =V12 -> 0 | W29: =W12 -> 0 | X29: =X12 -> 0 | ... AC29: =AC12 -> 16 | AD29: =AC29+AD12 -> 34 | AE29: =AD29+AE12 -> 54 | AF29: =AE29+AF12 -> 76 | AG29: =AF29+AG12 -> 101 | AH29: =AG29+AH12 -> 129 | AI29: =AH29+AI12 -> 161 | AJ29: =AI29+AJ12 -> 197 | AK29: =AJ29+AK12 -> 237 | ... AZ29: =AY29+AZ12 -> 1948 | BB29: =SUM(E29:P29) -> 0 | BC29: =SUM(Q29:AB29) -> 0 | BD29: =AN29 -> 389 | BE29: =AZ29 -> 1948 | BF29: =BF24*0.3 -> 3039.6
B30: Installed base (Combi+) | Q30: =Q18 -> 0 | R30: =R18 -> 0 | S30: =S18 -> 0 | T30: =T18 -> 0 | U30: =U18 -> 0 | V30: =V18 -> 0 | W30: =W18 -> 0 | X30: =X18 -> 0 | ... AC30: =AC18 -> 16 | AD30: =AC30+AD18 -> 34 | AE30: =AD30+AE18 -> 54 | AF30: =AE30+AF18 -> 76 | AG30: =AF30+AG18 -> 101 | AH30: =AG30+AH18 -> 129 | AI30: =AH30+AI18 -> 161 | AJ30: =AI30+AJ18 -> 197 | AK30: =AJ30+AK18 -> 237 | ... AZ30: =AY30+AZ18 -> 1948 | BB30: =SUM(E30:P30) -> 0 | BC30: =SUM(Q30:AB30) -> 0 | BD30: =AN30 -> 389 | BE30: =AZ30 -> 1948 | BF30: =BF24*0.3 -> 3039.6
B31: Total Service Revenue | D31: € | Q31: =Q41*SUMPRODUCT(Assumptions!$E$128:$E$129,Assumptions!$F$128:$F$129) -> 0 | R31: =R41*SUMPRODUCT(Assumptions!$E$128:$E$129,Assumptions!$F$128:$F$129) -> 0 | S31: =S41*SUMPRODUCT(Assumptions!$E$128:$E$129,Assumptions!$F$128:$F$129) -> 0 | T31: =T41*SUMPRODUCT(Assumptions!$E$128:$E$129,Assumptions!$F$128:$F$129) -> 0 | U31: =U41*SUMPRODUCT(Assumptions!$E$128:$E$129,Assumptions!$F$128:$F$129) -> 0 | V31: =V41*SUMPRODUCT(Assumptions!$E$128:$E$129,Assumptions!$F$128:$F$129) -> 0 | W31: =W41*SUMPRODUCT(Assumptions!$E$128:$E$129,Assumptions!$F$128:$F$129) -> 0 | X31: =X41*SUMPRODUCT(Assumptions!$E$128:$E$129,Assumptions!$F$128:$F$129) -> 0 | ... AB31: =AB41*SUMPRODUCT(Assumptions!$E$128:$E$129,Assumptions!$F$128:$F$129) -> 0 | AC31: =AC41*SUMPRODUCT(Assumptions!$E$128:$E$129,Assumptions!$F$128:$F$129)+Q31 -> 4347 | AD31: =AD41*SUMPRODUCT(Assumptions!$E$128:$E$129,Assumptions!$F$128:$F$129)+R31 -> 4830 | AE31: =AE41*SUMPRODUCT(Assumptions!$E$128:$E$129,Assumptions!$F$128:$F$129)+S31 -> 5382 | AF31: =AF41*SUMPRODUCT(Assumptions!$E$128:$E$129,Assumptions!$F$128:$F$129)+T31 -> 5865 | AG31: =AG41*SUMPRODUCT(Assumptions!$E$128:$E$129,Assumptions!$F$128:$F$129)+U31 -> 6555 | AH31: =AH41*SUMPRODUCT(Assumptions!$E$128:$E$129,Assumptions!$F$128:$F$129)+V31 -> 7314 | AI31: =AI41*SUMPRODUCT(Assumptions!$E$128:$E$129,Assumptions!$F$128:$F$129)+W31 -> 8142 | AJ31: =AJ41*SUMPRODUCT(Assumptions!$E$128:$E$129,Assumptions!$F$128:$F$129)+X31 -> 9039 | ... AZ31: =AZ41*SUMPRODUCT(Assumptions!$E$128:$E$129,Assumptions!$F$128:$F$129)+AN31 -> 62790 | BB31: =SUM(E31:P31) -> 0 | BC31: =SUM(Q31:AB31) -> 0 | BD31: =SUM(AC31:AN31) -> 98670 | BE31: =SUM(AO31:AZ31) -> 448224 | BF31: =(BE31*2)+BE31 -> 1344672
B33: SUBSIDIES & GRANTS
B34: All other | D34: € | E34: 0 | F34: 0 | G34: 0 | H34: 0 | I34: 0 | J34: 0 | K34: 0 | L34: 0 | M34: 0 | N34: 19480 | O34: 78000 | P34: 0 | Q34: 0 | R34: 0 | S34: 0 | T34: 0 | U34: 0 | V34: 106782 | W34: 0 | X34: 0 | Y34: 0 | Z34: 0 | AA34: 0 | AB34: 0 | AC34: 0 | AD34: 0 | AE34: 0 | AF34: 0 | AG34: 0 | AH34: 0 | AI34: 0 | AJ34: 0 | AK34: 0 | AL34: 0 | AM34: 0 | AN34: 0 | AO34: 0 | AP34: 0 | AQ34: 0 | AR34: 0 | AS34: 0 | AT34: 0 | AU34: 0 | AV34: 0 | AW34: 0 | AX34: 0 | AY34: 0 | AZ34: 0 | BB34: =SUM(E34:P34) -> 97480 | BC34: =SUM(Q34:AB34) -> 106782 | BD34: =SUM(AC34:AN34) -> 0 | BE34: =SUM(AO34:AZ34) -> 0 | BF34: 0
B35: Total Subsidies & Grants | D35: € | E35: =sum(E34) -> 0 | F35: =sum(F34) -> 0 | G35: =sum(G34) -> 0 | H35: =sum(H34) -> 0 | I35: =sum(I34) -> 0 | J35: =sum(J34) -> 0 | K35: =sum(K34) -> 0 | L35: =sum(L34) -> 0 | ... AZ35: =sum(AZ34) -> 0 | BB35: =SUM(E35:P35) -> 97480 | BC35: =SUM(Q35:AB35) -> 106782 | BD35: =BD34 -> 0 | BE35: =BE34 -> 0 | BF35: =BF34 -> 0
B37: TOTAL REVENUE | E37: =E9+E15+E21+E25+E31+E35 -> 0 | F37: =F9+F15+F21+F25+F31+F35 -> 0 | G37: =G9+G15+G21+G25+G31+G35 -> 0 | H37: =H9+H15+H21+H25+H31+H35 -> 0 | I37: =I9+I15+I21+I25+I31+I35 -> 0 | J37: =J9+J15+J21+J25+J31+J35 -> 0 | K37: =K9+K15+K21+K25+K31+K35 -> 0 | L37: =L9+L15+L21+L25+L31+L35 -> 0 | ... AZ37: =AZ9+AZ15+AZ21+AZ25+AZ31+AZ35 -> 10491786 | BB37: =BB9+BB15+BB21+BB25+BB31+BB35 -> 97480 | BC37: =BC9+BC15+BC21+BC25+BC31+BC35 -> 106782 | BD37: =SUM(AC37:AN37) -> 20475120 | BE37: =SUM(AO37:AZ37) -> 74302035 | BF37: =BF9+BF15+BF21+BF25+BF31+BF35 -> 1.4905229e+08
B40: Installed Base | E40: =sum(E28:E30) -> 0 | F40: =sum(F28:F30) -> 0 | G40: =sum(G28:G30) -> 0 | H40: =sum(H28:H30) -> 0 | I40: =sum(I28:I30) -> 0 | J40: =sum(J28:J30) -> 0 | K40: =sum(K28:K30) -> 0 | L40: =sum(L28:L30) -> 0 | ... AZ40: =sum(AZ28:AZ30) -> 6496 | BB40: =sum(BB28:BB30) -> 0 | BC40: =sum(BC28:BC30) -> 0 | BD40: =sum(BD28:BD30) -> 1430 | BE40: =sum(BE28:BE30) -> 6496 | BF40: =sum(BF28:BF30) -> 10132
B41: Units sold | D41: # | E41: =E6+E12+E18 -> 0 | F41: =F6+F12+F18 -> 0 | G41: =G6+G12+G18 -> 0 | H41: =H6+H12+H18 -> 0 | I41: =I6+I12+I18 -> 0 | J41: =J6+J12+J18 -> 0 | K41: =K6+K12+K18 -> 0 | L41: =L6+L12+L18 -> 0 | ... AZ41: =AZ6+AZ12+AZ18 -> 710 | BB41: 0 | BC41: 0 | BD41: =SUM(AC41:AN41) -> 1430 | BE41: =SUM(AO41:AZ41) -> 5066 | BF41: =BF24 -> 10132

Sheet COGS
B1: Tarnoc B.V. — COGS Schedule (€)
E2: 2025 | Q2: 2026 | AC2: 2027 | AO2: 2028
E3: 45658 | F3: 45689 | G3: 45717 | H3: 45748 | I3: 45778 | J3: 45809 | K3: 45839 | L3: 45870 | M3: 45901 | N3: 45931 | O3: 45962 | P3: 45992 | Q3: 46023 | R3: 46054 | S3: 46082 | T3: 46113 | U3: 46143 | V3: 46174 | W3: 46204 | X3: 46235 | Y3: 46266 | Z3: 46296 | AA3: 46327 | AB3: 46357 | AC3: 46388 | AD3: 46419 | AE3: 46447 | AF3: 46478 | AG3: 46508 | AH3: 46539 | AI3: 46569 | AJ3: 46600 | AK3: 46631 | AL3: 46661 | AM3: 46692 | AN3: 46722 | AO3: 46753 | AP3: 46784 | AQ3: 46813 | AR3: 46844 | AS3: 46874 | AT3: 46905 | AU3: 46935 | AV3: 46966 | AW3: 46997 | AX3: 47027 | AY3: 47058 | AZ3: 47088 | BB3: 2025 | BC3: 2026 | BD3: 2027 | BE3: 2028 | BF3: 2029
B6: TTK
B7: TTK | D7: € | Q7: =IFNA('Revenue Forecast'!Q6*VLOOKUP('Revenue Forecast'!$BD$41+'Revenue Forecast'!$BE$41,Assumptions!$B$70:$C$72,2,TRUE),0) -> 0 | R7: =IFNA('Revenue Forecast'!R6*VLOOKUP('Revenue Forecast'!$BD$41+'Revenue Forecast'!$BE$41,Assumptions!$B$70:$C$72,2,TRUE),0) -> 0 | S7: =IFNA('Revenue Forecast'!S6*VLOOKUP('Revenue Forecast'!$BD$41+'Revenue Forecast'!$BE$41,Assumptions!$B$70:$C$72,2,TRUE),0) -> 0 | T7: =IFNA('Revenue Forecast'!T6*VLOOKUP('Revenue Forecast'!$BD$41+'Revenue Forecast'!$BE$41,Assumptions!$B$70:$C$72,2,TRUE),0) -> 0 | U7: =IFNA('Revenue Forecast'!U6*VLOOKUP('Revenue Forecast'!$BD$41+'Revenue Forecast'!$BE$41,Assumptions!$B$70:$C$72,2,TRUE),0) -> 0 | V7: =IFNA('Revenue Forecast'!V6*VLOOKUP('Revenue Forecast'!$BD$41+'Revenue Forecast'!$BE$41,Assumptions!$B$70:$C$72,2,TRUE),0) -> 0 | W7: =IFNA('Revenue Forecast'!W6*VLOOKUP('Revenue Forecast'!$BD$41+'Revenue Forecast'!$BE$41,Assumptions!$B$70:$C$72,2,TRUE),0) -> 0 | X7: =IFNA('Revenue Forecast'!X6*VLOOKUP('Revenue Forecast'!$BD$41+'Revenue Forecast'!$BE$41,Assumptions!$B$70:$C$72,2,TRUE),0) -> 0 | ... AZ7: =IFNA('Revenue Forecast'!AZ6*VLOOKUP('Revenue Forecast'!$BD$41+'Revenue Forecast'!$BE$41,Assumptions!$B$70:$C$72,2,TRUE),0) -> 1812337.7 | BC7: =SUM(Q7:AB7) -> 0 | BD7: =SUM(AC7:AN7) -> 4615797.5 | BE7: =SUM(AO7:AZ7) -> 13790757 | BF7: ='Revenue Forecast'!BF6*Assumptions!$G$53 -> 19480000
B8: Upsell | D8: € | Q8: ='Revenue Forecast'!Q6*SUMPRODUCT(Assumptions!$E$116:$E$118,Assumptions!$G$116:$G$118) -> 0 | R8: ='Revenue Forecast'!R6*SUMPRODUCT(Assumptions!$E$116:$E$118,Assumptions!$G$116:$G$118) -> 0 | S8: ='Revenue Forecast'!S6*SUMPRODUCT(Assumptions!$E$116:$E$118,Assumptions!$G$116:$G$118) -> 0 | T8: ='Revenue Forecast'!T6*SUMPRODUCT(Assumptions!$E$116:$E$118,Assumptions!$G$116:$G$118) -> 0 | U8: ='Revenue Forecast'!U6*SUMPRODUCT(Assumptions!$E$116:$E$118,Assumptions!$G$116:$G$118) -> 0 | V8: ='Revenue Forecast'!V6*SUMPRODUCT(Assumptions!$E$116:$E$118,Assumptions!$G$116:$G$118) -> 0 | W8: ='Revenue Forecast'!W6*SUMPRODUCT(Assumptions!$E$116:$E$118,Assumptions!$G$116:$G$118) -> 0 | X8: ='Revenue Forecast'!X6*SUMPRODUCT(Assumptions!$E$116:$E$118,Assumptions!$G$116:$G$118) -> 0 | ... AZ8: ='Revenue Forecast'!AZ6*SUMPRODUCT(Assumptions!$E$116:$E$118,Assumptions!$G$116:$G$118) -> 55756.8 | BC8: =SUM(Q8:AB8) -> 0 | BD8: =SUM(AC8:AN8) -> 142005.6 | BE8: =SUM(AO8:AZ8) -> 424274.4 | BF8: ='Revenue Forecast'!BF6*SUMPRODUCT(Assumptions!$E$116:$E$118,Assumptions!$G$116:$G$118) -> 848548.8
B9: Total TTK COGS | D9: € | Q9: =sum(Q7:Q8) -> 0 | R9: =sum(R7:R8) -> 0 | S9: =sum(S7:S8) -> 0 | T9: =sum(T7:T8) -> 0 | U9: =sum(U7:U8) -> 0 | V9: =sum(V7:V8) -> 0 | W9: =sum(W7:W8) -> 0 | X9: =sum(X7:X8) -> 0 | ... AZ9: =sum(AZ7:AZ8) -> 1868094.5 | BB9: =SUM(E9:P9) -> 0 | BC9: =SUM(Q9:AB9) -> 0 | BD9: =SUM(AC9:AN9) -> 4757803.1 | BE9: =SUM(AO9:AZ9) -> 14215031 | BF9: =sum(BF7:BF8) -> 20328549
B11: COMBI
B12: Total COGS Combi | D12: € | Q12: =IFNA('Revenue Forecast'!Q12*(VLOOKUP('Revenue Forecast'!$BD$41+'Revenue Forecast'!$BE$41,Assumptions!$B$70:$C$72,2,TRUE)+VLOOKUP('Revenue Forecast'!$BD$12+'Revenue Forecast'!$BE$12,Assumptions!$B$82:$C$84,2,TRUE)+Assumptions!$E$78),0) -> 0 | R12: =IFNA('Revenue Forecast'!R12*(VLOOKUP('Revenue Forecast'!$BD$41+'Revenue Forecast'!$BE$41,Assumptions!$B$70:$C$72,2,TRUE)+VLOOKUP('Revenue Forecast'!$BD$12+'Revenue Forecast'!$BE$12,Assumptions!$B$82:$C$84,2,TRUE)+Assumptions!$E$78),0) -> 0 | S12: =IFNA('Revenue Forecast'!S12*(VLOOKUP('Revenue Forecast'!$BD$41+'Revenue Forecast'!$BE$41,Assumptions!$B$70:$C$72,2,TRUE)+VLOOKUP('Revenue Forecast'!$BD$12+'Revenue Forecast'!$BE$12,Assumptions!$B$82:$C$84,2,TRUE)+Assumptions!$E$78),0) -> 0 | T12: =IFNA('Revenue Forecast'!T12*(VLOOKUP('Revenue Forecast'!$BD$41+'Revenue Forecast'!$BE$41,Assumptions!$B$70:$C$72,2,TRUE)+VLOOKUP('Revenue Forecast'!$BD$12+'Revenue Forecast'!$BE$12,Assumptions!$B$82:$C$84,2,TRUE)+Assumptions!$E$78),0) -> 0 | U12: =IFNA('Revenue Forecast'!U12*(VLOOKUP('Revenue Forecast'!$BD$41+'Revenue Forecast'!$BE$41,Assumptions!$B$70:$C$72,2,TRUE)+VLOOKUP('Revenue Forecast'!$BD$12+'Revenue Forecast'!$BE$12,Assumptions!$B$82:$C$84,2,TRUE)+Assumptions!$E$78),0) -> 0 | V12: =IFNA('Revenue Forecast'!V12*(VLOOKUP('Revenue Forecast'!$BD$41+'Revenue Forecast'!$BE$41,Assumptions!$B$70:$C$72,2,TRUE)+VLOOKUP('Revenue Forecast'!$BD$12+'Revenue Forecast'!$BE$12,Assumptions!$B$82:$C$84,2,TRUE)+Assumptions!$E$78),0) -> 0 | W12: =IFNA('Revenue Forecast'!W12*(VLOOKUP('Revenue Forecast'!$BD$41+'Revenue Forecast'!$BE$41,Assumptions!$B$70:$C$72,2,TRUE)+VLOOKUP('Revenue Forecast'!$BD$12+'Revenue Forecast'!$BE$12,Assumptions!$B$82:$C$84,2,TRUE)+Assumptions!$E$78),0) -> 0 | X12: =IFNA('Revenue Forecast'!X12*(VLOOKUP('Revenue Forecast'!$BD$41+'Revenue Forecast'!$BE$41,Assumptions!$B$70:$C$72,2,TRUE)+VLOOKUP('Revenue Forecast'!$BD$12+'Revenue Forecast'!$BE$12,Assumptions!$B$82:$C$84,2,TRUE)+Assumptions!$E$78),0) -> 0 | ... AZ12: =IFNA('Revenue Forecast'!AZ12*(VLOOKUP('Revenue Forecast'!$BD$41+'Revenue Forecast'!$BE$41,Assumptions!$B$70:$C$72,2,TRUE)+VLOOKUP('Revenue Forecast'!$BD$12+'Revenue Forecast'!$BE$12,Assumptions!$B$82:$C$84,2,TRUE)+Assumptions!$E$78),0) -> 1897221.5 | BC12: =SUM(Q12:AB12) -> 0 | BD12: =SUM(AC12:AN12) -> 3251185.8 | BE12: =SUM(AO12:AZ12) -> 13029816 | BF12: ='Revenue Forecast'!BF12*(Assumptions!$G$53+Assumptions!$C$84+Assumptions!$E$78) -> 18877837
B13: Upsell | D13: € | Q13: ='Revenue Forecast'!Q12*SUMPRODUCT(Assumptions!$E$116:$E$118,Assumptions!$G$116:$G$118) -> 0 | R13: ='Revenue Forecast'!R12*SUMPRODUCT(Assumptions!$E$116:$E$118,Assumptions!$G$116:$G$118) -> 0 | S13: ='Revenue Forecast'!S12*SUMPRODUCT(Assumptions!$E$116:$E$118,Assumptions!$G$116:$G$118) -> 0 | T13: ='Revenue Forecast'!T12*SUMPRODUCT(Assumptions!$E$116:$E$118,Assumptions!$G$116:$G$118) -> 0 | U13: ='Revenue Forecast'!U12*SUMPRODUCT(Assumptions!$E$116:$E$118,Assumptions!$G$116:$G$118) -> 0 | V13: ='Revenue Forecast'!V12*SUMPRODUCT(Assumptions!$E$116:$E$118,Assumptions!$G$116:$G$118) -> 0 | W13: ='Revenue Forecast'!W12*SUMPRODUCT(Assumptions!$E$116:$E$118,Assumptions!$G$116:$G$118) -> 0 | X13: ='Revenue Forecast'!X12*SUMPRODUCT(Assumptions!$E$116:$E$118,Assumptions!$G$116:$G$118) -> 0 | ... AZ13: ='Revenue Forecast'!AZ12*SUMPRODUCT(Assumptions!$E$116:$E$118,Assumptions!$G$116:$G$118) -> 49440.6 | BC13: =SUM(Q13:AB13) -> 0 | BD13: =SUM(AC13:AN13) -> 84724.2 | BE13: =SUM(AO13:AZ13) -> 339550.2 | BF13: ='Revenue Forecast'!BF12*SUMPRODUCT(Assumptions!$E$116:$E$118,Assumptions!$G$116:$G$118) -> 679100.4
B14: Total Combi COGS | D14: € | Q14: =sum(Q12:Q13) -> 0 | R14: =sum(R12:R13) -> 0 | S14: =sum(S12:S13) -> 0 | T14: =sum(T12:T13) -> 0 | U14: =sum(U12:U13) -> 0 | V14: =sum(V12:V13) -> 0 | W14: =sum(W12:W13) -> 0 | X14: =sum(X12:X13) -> 0 | ... AZ14: =sum(AZ12:AZ13) -> 1946662.1 | BB14: =SUM(E14:P14) -> 0 | BC14: =SUM(Q14:AB14) -> 0 | BD14: =SUM(AC14:AN14) -> 3335910 | BE14: =SUM(AO14:AZ14) -> 13369367 | BF14: =sum(BF12:BF13) -> 19556938
B16: COMBI+
B17: Total COGS Combi+ | Q17: =IFNA('Revenue Forecast'!Q18*(VLOOKUP('Revenue Forecast'!$BD$41+'Revenue Forecast'!$BE$41,Assumptions!$B$70:$C$72,2,TRUE)+VLOOKUP('Revenue Forecast'!$BD$18+'Revenue Forecast'!$BE$18,Assumptions!$E$82:$F$84,2,TRUE)+Assumptions!$E$78),0) -> 0 | R17: =IFNA('Revenue Forecast'!R18*(VLOOKUP('Revenue Forecast'!$BD$41+'Revenue Forecast'!$BE$41,Assumptions!$B$70:$C$72,2,TRUE)+VLOOKUP('Revenue Forecast'!$BD$18+'Revenue Forecast'!$BE$18,Assumptions!$E$82:$F$84,2,TRUE)+Assumptions!$E$78),0) -> 0 | S17: =IFNA('Revenue Forecast'!S18*(VLOOKUP('Revenue Forecast'!$BD$41+'Revenue Forecast'!$BE$41,Assumptions!$B$70:$C$72,2,TRUE)+VLOOKUP('Revenue Forecast'!$BD$18+'Revenue Forecast'!$BE$18,Assumptions!$E$82:$F$84,2,TRUE)+Assumptions!$E$78),0) -> 0 | T17: =IFNA('Revenue Forecast'!T18*(VLOOKUP('Revenue Forecast'!$BD$41+'Revenue Forecast'!$BE$41,Assumptions!$B$70:$C$72,2,TRUE)+VLOOKUP('Revenue Forecast'!$BD$18+'Revenue Forecast'!$BE$18,Assumptions!$E$82:$F$84,2,TRUE)+Assumptions!$E$78),0) -> 0 | U17: =IFNA('Revenue Forecast'!U18*(VLOOKUP('Revenue Forecast'!$BD$41+'Revenue Forecast'!$BE$41,Assumptions!$B$70:$C$72,2,TRUE)+VLOOKUP('Revenue Forecast'!$BD$18+'Revenue Forecast'!$BE$18,Assumptions!$E$82:$F$84,2,TRUE)+Assumptions!$E$78),0) -> 0 | V17: =IFNA('Revenue Forecast'!V18*(VLOOKUP('Revenue Forecast'!$BD$41+'Revenue Forecast'!$BE$41,Assumptions!$B$70:$C$72,2,TRUE)+VLOOKUP('Revenue Forecast'!$BD$18+'Revenue Forecast'!$BE$18,Assumptions!$E$82:$F$84,2,TRUE)+Assumptions!$E$78),0) -> 0 | W17: =IFNA('Revenue Forecast'!W18*(VLOOKUP('Revenue Forecast'!$BD$41+'Revenue Forecast'!$BE$41,Assumptions!$B$70:$C$72,2,TRUE)+VLOOKUP('Revenue Forecast'!$BD$18+'Revenue Forecast'!$BE$18,Assumptions!$E$82:$F$84,2,TRUE)+Assumptions!$E$78),0) -> 0 | X17: =IFNA('Revenue Forecast'!X18*(VLOOKUP('Revenue Forecast'!$BD$41+'Revenue Forecast'!$BE$41,Assumptions!$B$70:$C$72,2,TRUE)+VLOOKUP('Revenue Forecast'!$BD$18+'Revenue Forecast'!$BE$18,Assumptions!$E$82:$F$84,2,TRUE)+Assumptions!$E$78),0) -> 0 | ... AZ17: =IFNA('Revenue Forecast'!AZ18*(VLOOKUP('Revenue Forecast'!$BD$41+'Revenue Forecast'!$BE$41,Assumptions!$B$70:$C$72,2,TRUE)+VLOOKUP('Revenue Forecast'!$BD$18+'Revenue Forecast'!$BE$18,Assumptions!$E$82:$F$84,2,TRUE)+Assumptions!$E$78),0) -> 1948124 | BC17: =SUM(Q17:AB17) -> 0 | BD17: =SUM(AC17:AN17) -> 3338415.1 | BE17: =SUM(AO17:AZ17) -> 13379407 | BF17: ='Revenue Forecast'!BF18*(Assumptions!$G$53+Assumptions!$F$84+Assumptions!$E$78) -> 19444160
