Workbook

Sheet Cover
B15: Financial Model
B19: Currency: EUR (€)
B21: STRICTLY CONFIDENTIAL

Sheet How to read me
B1: Tarnoc — How to Read This Model
B3: COLOR CODING
B4: Sample | C4: Assumptions are hardcoded inputs (sourced from documents)
B5: Sample | C5: Hardcoded historicalsis actual data from source documents
B6: Sample | C6: Formula cells are calculated, not hardcoded
B7: Sample | C7: Subtotal / total rows
B8: Sample | C8: Section headers / grand totals
B9: Sample | C9: Subsection headers
B10: Sample | C10: Margin / ratio rows (grey)
B11: Sample | C11: Balance sheet check rows (must = 0)
B14: FORMULA ARCHITECTURE
B15: Assumptions → Revenue Forecast, COGS, OPEX, CAPEX, Personnel (all drivers sourced here)
B16: Revenue Forecast → Financial Statements (revenue lines via cross-sheet links)
B17: COGS → Financial Statements (cost lines via cross-sheet links)
B18: OPEX → Financial Statements (opex lines via cross-sheet links)
B20: To change a number: ONLY edit cells in the Assumptions tab (yellow/orange).
B21: All other tabs will recalculate automatically.
B24: FURTHER EXPLANATIONS
B25: Subsidies: Tarnoc is and has been eligible for a number of subsidies. We will consider application for large projects, however this model excludes the forecast of any subsidy financing foing forward.
B26: Installation revenues: This is modelled fully as pass through revenue for now, as we plan to charge a customer exactly what we pay the installation partner for these services. This is subject to change in the future.
B27: Tarnoc's main products are the TTK (turbineketel) and the Combi+ (turbineketel + outdoor unit), plus the Twincycle (in development for 2027). Every unit contains a turbineketel; the Combi+ adds an outdoor unit and a heavier installation. We also plan to sell various add-ons such as boilers for hybrid setups and sound reduction units.
B28: Service Revenues: Service revenues are calculated relative to installed base. We assume a certain percentage (see assumptions) of customers will purchase our Service package, and are charged annually.
... B46: Market share is on the face of the model. The turbineketel replaces a gas boiler one-for-one, so the market is the ~400,000 gas boilers replaced in the Netherlands each year - not the ~125,000 heat pumps sold in 2024. Share is measured against that, plus Belgium and Germany once the expansion market opens.

Sheet Assumptions
B2: Drivers & Assumptions
B3: ASSUMPTIONS | L3: what this row does
B5: General Assumptions
B6: Opening Cash Balance (Jan 2024) | C6: 29538.9
B7: Annual salary increase (%) | C7: 0.08 | L7: salary raise applied every year on the Personnel tab
B8: Employer cost basis | C8: Werkgeverlasten (incl. taxes)
B9: Holiday pay (%) | C9: 0.08
B10: Income tax rate | C10: 0.258
B11: Interst on WC loan | C11: 0.05 | L11: interest rate charged on the CLA / working-capital loan
B13: Working Capital | H13: 20
B15: Days Sales Outstanding (DSO) | C15: days | D15: 20 | L15: days customers take to pay — sets receivables on the balance sheet
B16: Days Payable Outstanding (DPO) | C16: days | D16: 45 | L16: days we take to pay suppliers — sets payables
B17: Days Inventory Outstanding (DIO) | C17: days | D17: =IF($D$82=2,30,0) | L17: days of stock held. 0 in Base (as before); 30 in the Aggressive case
B18: Pre-payment | C18: % | L18: share paid up front. left blank, so no customer deposits assumed
B20: Revenue Build
B21: ~Units sold | D21: ='Growth Engine'!BC43 | E21: ='Growth Engine'!BD43 | F21: ='Growth Engine'!BE43 | G21: ='Growth Engine'!BF43 | L21: OUTPUT, not an input — units come from the Growth Engine tab (demand vs sales capacity vs build capacity)
C22: 2026 | D22: 2027 | E22: 2028 | F22: 2029 | G22: 2030
B23: TTK | C23: 0 | D23: =D$21*$H23 | E23: =E$21*$H23 | F23: =F$21*$H23 | G23: =G$21*$H23 | H23: 0.2 | L23: TTK units = total units x the mix % in column H
B24: Combi+ | C24: 0 | D24: =D$21*$H24 | E24: =E$21*$H24 | F24: =F$21*$H24 | G24: =G$21*$H24 | H24: =1-H23 | L24: Combi+ units = total units x the mix % in column H
B27: Pricing
B28: PRICING — build-up (turbineketel + outdoor unit) | D28: (inc VAT)
B29: Turbineketel base price (all products) | C29: 8525.62 | D29: =C29*1.21 | L29: column D is just the same price with VAT added, for reference
B30: Outdoor unit — Combi+ | C30: 5309.92 | D30: =C30*1.21 | L30: column D is the incl-VAT version, for reference
B31: Combi+ price (ketel + ODU) | C31: =C29+C30 | D31: =C31*1.21 | L31: Combi+ price = ketel + outdoor unit
B32: INSTALLATION (PASS-THROUGH; REV=COST)
B33: Installation — TTK | C33: 2800 | L33: charged at cost, no margin (pass-through)
B34: Installation — Combi+ | C34: 3800 | L34: charged at cost, no margin (pass-through)
B35: COGS
B36: TTK
B37: Bill of Materials TTK supplier 1
B38: # | C38: Category | D38: Component | E38: 1,000 units | F38: 5,000 units | G38: 10,000 units | H38: Unit | I38: Source
B39: B1 | C39: Supplier 1 | D39: Compressor + VFD | E39: 6314 | F39: 4500 | G39: 2692.44 | H39: €/unit | I39: Source: BOM data provided | L39: compressor prices typed in per tier, not a % step-down
B40: B2 | C40: Supplier 1 | D40: Heat exchangers (set) | E40: 805.5 | F40: =E40*0.7 | G40: =0.6*F40 | H40: €/unit | I40: Source: BOM data provided | L40: volume discount: 5k column = 70% of 1k, 10k = 60% of 5k
B41: B3 | C41: Supplier 1 | D41: Electronics & Power Electronics | E41: 632.92 | F41: =E41*0.7 | G41: =0.6*F41 | H41: €/unit | I41: Source: BOM data provided | L41: volume discount: 5k column = 70% of 1k, 10k = 60% of 5k
B42: B4 | C42: Supplier 1 | D42: Hydraulic Components (Pumps, Valves, etc.) | E42: 283.76 | F42: =E42*0.7 | G42: =0.6*F42 | H42: €/unit | I42: Source: BOM data provided | L42: volume discount: 5k column = 70% of 1k, 10k = 60% of 5k
B43: B5 | C43: Supplier 1 | D43: Silencer & Insulation | E43: 118.48 | F43: =E43*0.7 | G43: =0.6*F43 | H43: €/unit | I43: Source: BOM data provided | L43: volume discount: 5k column = 70% of 1k, 10k = 60% of 5k
B44: B6 | C44: Supplier 1 | D44: Enclosure (Sheet Metal & Coating) | E44: 653.03 | F44: =E44*0.7 | G44: =0.6*F44 | H44: €/unit | I44: Source: BOM data provided | L44: volume discount: 5k column = 70% of 1k, 10k = 60% of 5k
B45: B7 | C45: Supplier 1 | D45: Other Components | E45: 290 | F45: =E45*0.7 | G45: 126 | H45: €/unit | I45: Source: BOM data provided | L45: 5k = 70% of 1k; the 10k number is typed in by hand
B46: B8 | C46: Supplier 1 | D46: Assembly & Final Testing | E46: 200 | F46: =E46*0.7 | G46: =0.6*F46 | H46: €/unit | I46: Source: BOM data provided | L46: volume discount: 5k column = 70% of 1k, 10k = 60% of 5k
B47: B9 | C47: Supplier 1 | D47: Packaging & Inbound Logistics | E47: 395 | F47: =E47*0.7 | G47: =0.6*F47 | H47: €/unit | I47: Source: BOM data provided | L47: volume discount: 5k column = 70% of 1k, 10k = 60% of 5k
...

Sheet Growth Engine
B2: Tarnoc B.V. — Growth Engine
B3: Units sold are an OUTPUT of demand, sales capacity and build capacity — not an input. Every driver lives on the Assumptions tab (rows 130+). Case switch: Assumptions D82.
B5: Month | F5: 46388 | G5: 46419 | H5: 46447 | I5: 46478 | J5: 46508 | K5: 46539 | L5: 46569 | M5: 46600 | N5: 46631 | O5: 46661 | P5: 46692 | Q5: 46722 | R5: 46753 | S5: 46784 | T5: 46813 | U5: 46844 | V5: 46874 | W5: 46905 | X5: 46935 | Y5: 46966 | Z5: 46997 | AA5: 47027 | AB5: 47058 | AC5: 47088 | AD5: 47119 | AE5: 47150 | AF5: 47178 | AG5: 47209 | AH5: 47239 | AI5: 47270 | AJ5: 47300 | AK5: 47331 | AL5: 47362 | AM5: 47392 | AN5: 47423 | AO5: 47453 | AP5: 47484 | AQ5: 47515 | AR5: 47543 | AS5: 47574 | AT5: 47604 | AU5: 47635 | AV5: 47665 | AW5: 47696 | AX5: 47727 | AY5: 47757 | AZ5: 47788 | BA5: 47818 | BC5: 2027 | BD5: 2028 | BE5: 2029 | BF5: 2030 | BH5: what this row does
B7: MARKET — serviceable demand for a 1-for-1 gas-boiler replacement
B8: NL serviceable market | C8: units/mo | F8: =Assumptions!$F$134*Assumptions!$F$135/12 | G8: =Assumptions!$F$134*Assumptions!$F$135/12 | H8: =Assumptions!$F$134*Assumptions!$F$135/12 | I8: =Assumptions!$F$134*Assumptions!$F$135/12 | J8: =Assumptions!$F$134*Assumptions!$F$135/12 | K8: =Assumptions!$F$134*Assumptions!$F$135/12 | L8: =Assumptions!$F$134*Assumptions!$F$135/12 | M8: =Assumptions!$F$134*Assumptions!$F$135/12 | ... BA8: =Assumptions!$F$134*Assumptions!$F$135/12 | BC8: =SUM(F8:Q8) | BD8: =SUM(R8:AC8) | BE8: =SUM(AD8:AO8) | BF8: =SUM(AP8:BA8) | BH8: ~400k gas boilers replaced a year in NL x the share suitable for a 1-for-1 swap
B9: Expansion market (BE+DE) | C9: units/mo | F9: =IF(YEAR(F$5)>=Assumptions!$F$137,Assumptions!$F$136*Assumptions!$F$135/12,0) | G9: =IF(YEAR(G$5)>=Assumptions!$F$137,Assumptions!$F$136*Assumptions!$F$135/12,0) | H9: =IF(YEAR(H$5)>=Assumptions!$F$137,Assumptions!$F$136*Assumptions!$F$135/12,0) | I9: =IF(YEAR(I$5)>=Assumptions!$F$137,Assumptions!$F$136*Assumptions!$F$135/12,0) | J9: =IF(YEAR(J$5)>=Assumptions!$F$137,Assumptions!$F$136*Assumptions!$F$135/12,0) | K9: =IF(YEAR(K$5)>=Assumptions!$F$137,Assumptions!$F$136*Assumptions!$F$135/12,0) | L9: =IF(YEAR(L$5)>=Assumptions!$F$137,Assumptions!$F$136*Assumptions!$F$135/12,0) | M9: =IF(YEAR(M$5)>=Assumptions!$F$137,Assumptions!$F$136*Assumptions!$F$135/12,0) | ... BA9: =IF(YEAR(BA$5)>=Assumptions!$F$137,Assumptions!$F$136*Assumptions!$F$135/12,0) | BC9: =SUM(F9:Q9) | BD9: =SUM(R9:AC9) | BE9: =SUM(AD9:AO9) | BF9: =SUM(AP9:BA9) | BH9: opens in the entry year set on Assumptions
B10: Total serviceable market | C10: units/mo | F10: =F8+F9 | G10: =G8+G9 | H10: =H8+H9 | I10: =I8+I9 | J10: =J8+J9 | K10: =K8+K9 | L10: =L8+L9 | M10: =M8+M9 | ... BA10: =BA8+BA9 | BC10: =SUM(F10:Q10) | BD10: =SUM(R10:AC10) | BE10: =SUM(AD10:AO10) | BF10: =SUM(AP10:BA10)
B11: Share ceiling — max units allowed | C11: units/mo | F11: =F10*Assumptions!$F$138 | G11: =G10*Assumptions!$F$138 | H11: =H10*Assumptions!$F$138 | I11: =I10*Assumptions!$F$138 | J11: =J10*Assumptions!$F$138 | K11: =K10*Assumptions!$F$138 | L11: =L10*Assumptions!$F$138 | M11: =M10*Assumptions!$F$138 | ... BA11: =BA10*Assumptions!$F$138 | BC11: =SUM(F11:Q11) | BD11: =SUM(R11:AC11) | BE11: =SUM(AD11:AO11) | BF11: =SUM(AP11:BA11) | BH11: a hard ceiling, so the plan can never quietly assume we own an unrealistic slice of the market
B13: DEMAND GENERATION — marketing spend drives orders
B14: Marketing spend | C14: EUR/mo | F14: =IF(YEAR(F$5)=2027,Assumptions!$F$140,IF(YEAR(F$5)=2028,Assumptions!$F$141,IF(YEAR(F$5)=2029,Assumptions!$F$142,Assumptions!$F$143))) | G14: =IF(YEAR(G$5)=2027,Assumptions!$F$140,IF(YEAR(G$5)=2028,Assumptions!$F$141,IF(YEAR(G$5)=2029,Assumptions!$F$142,Assumptions!$F$143))) | H14: =IF(YEAR(H$5)=2027,Assumptions!$F$140,IF(YEAR(H$5)=2028,Assumptions!$F$141,IF(YEAR(H$5)=2029,Assumptions!$F$142,Assumptions!$F$143))) | I14: =IF(YEAR(I$5)=2027,Assumptions!$F$140,IF(YEAR(I$5)=2028,Assumptions!$F$141,IF(YEAR(I$5)=2029,Assumptions!$F$142,Assumptions!$F$143))) | J14: =IF(YEAR(J$5)=2027,Assumptions!$F$140,IF(YEAR(J$5)=2028,Assumptions!$F$141,IF(YEAR(J$5)=2029,Assumptions!$F$142,Assumptions!$F$143))) | K14: =IF(YEAR(K$5)=2027,Assumptions!$F$140,IF(YEAR(K$5)=2028,Assumptions!$F$141,IF(YEAR(K$5)=2029,Assumptions!$F$142,Assumptions!$F$143))) | L14: =IF(YEAR(L$5)=2027,Assumptions!$F$140,IF(YEAR(L$5)=2028,Assumptions!$F$141,IF(YEAR(L$5)=2029,Assumptions!$F$142,Assumptions!$F$143))) | M14: =IF(YEAR(M$5)=2027,Assumptions!$F$140,IF(YEAR(M$5)=2028,Assumptions!$F$141,IF(YEAR(M$5)=2029,Assumptions!$F$142,Assumptions!$F$143))) | ... BA14: =IF(YEAR(BA$5)=2027,Assumptions!$F$140,IF(YEAR(BA$5)=2028,Assumptions!$F$141,IF(YEAR(BA$5)=2029,Assumptions!$F$142,Assumptions!$F$143))) | BC14: =SUM(F14:Q14) | BD14: =SUM(R14:AC14) | BE14: =SUM(AD14:AO14) | BF14: =SUM(AP14:BA14)
B15: Installed base, start of month | C15: units | F15: =0 | G15: =F46 | H15: =G46 | I15: =H46 | J15: =I46 | K15: =J46 | L15: =K46 | M15: =L46 | N15: =M46 | ... BA15: =AZ46 | BC15: =Q15 | BD15: =AC15 | BE15: =AO15 | BF15: =BA15
B16: Effective CPL | C16: EUR | F16: =Assumptions!$F$144*(1-Assumptions!$F$145)^IF(F15<400,0,LOG(F15/400,2)) | G16: =Assumptions!$F$144*(1-Assumptions!$F$145)^IF(G15<400,0,LOG(G15/400,2)) | H16: =Assumptions!$F$144*(1-Assumptions!$F$145)^IF(H15<400,0,LOG(H15/400,2)) | I16: =Assumptions!$F$144*(1-Assumptions!$F$145)^IF(I15<400,0,LOG(I15/400,2)) | J16: =Assumptions!$F$144*(1-Assumptions!$F$145)^IF(J15<400,0,LOG(J15/400,2)) | K16: =Assumptions!$F$144*(1-Assumptions!$F$145)^IF(K15<400,0,LOG(K15/400,2)) | L16: =Assumptions!$F$144*(1-Assumptions!$F$145)^IF(L15<400,0,LOG(L15/400,2)) | M16: =Assumptions!$F$144*(1-Assumptions!$F$145)^IF(M15<400,0,LOG(M15/400,2)) | ... BA16: =Assumptions!$F$144*(1-Assumptions!$F$145)^IF(BA15<400,0,LOG(BA15/400,2)) | BC16: =AVERAGE(F16:Q16) | BD16: =AVERAGE(R16:AC16) | BE16: =AVERAGE(AD16:AO16) | BF16: =AVERAGE(AP16:BA16) | BH16: cost per lead falls 10% per doubling of installed base — brand, referral and channel pull
B17: Leads | C17: leads | F17: =IFERROR(F14/F16,0) | G17: =IFERROR(G14/G16,0) | H17: =IFERROR(H14/H16,0) | I17: =IFERROR(I14/I16,0) | J17: =IFERROR(J14/J16,0) | K17: =IFERROR(K14/K16,0) | L17: =IFERROR(L14/L16,0) | M17: =IFERROR(M14/M16,0) | ... BA17: =IFERROR(BA14/BA16,0) | BC17: =SUM(F17:Q17) | BD17: =SUM(R17:AC17) | BE17: =SUM(AD17:AO17) | BF17: =SUM(AP17:BA17)
B18: Qualified leads | C18: leads | F18: =F17*Assumptions!$F$146 | G18: =G17*Assumptions!$F$146 | H18: =H17*Assumptions!$F$146 | I18: =I17*Assumptions!$F$146 | J18: =J17*Assumptions!$F$146 | K18: =K17*Assumptions!$F$146 | L18: =L17*Assumptions!$F$146 | M18: =M17*Assumptions!$F$146 | ... BA18: =BA17*Assumptions!$F$146 | BC18: =SUM(F18:Q18) | BD18: =SUM(R18:AC18) | BE18: =SUM(AD18:AO18) | BF18: =SUM(AP18:BA18)
B19: DEMAND — orders generated | C19: units/mo | F19: =F18*Assumptions!$F$147 | G19: =G18*Assumptions!$F$147 | H19: =H18*Assumptions!$F$147 | I19: =I18*Assumptions!$F$147 | J19: =J18*Assumptions!$F$147 | K19: =K18*Assumptions!$F$147 | L19: =L18*Assumptions!$F$147 | M19: =M18*Assumptions!$F$147 | ... BA19: =BA18*Assumptions!$F$147 | BC19: =SUM(F19:Q19) | BD19: =SUM(R19:AC19) | BE19: =SUM(AD19:AO19) | BF19: =SUM(AP19:BA19)
B20: Implied CAC | C20: EUR/unit | F20: =IFERROR(F14/F19,0) | G20: =IFERROR(G14/G19,0) | H20: =IFERROR(H14/H19,0) | I20: =IFERROR(I14/I19,0) | J20: =IFERROR(J14/J19,0) | K20: =IFERROR(K14/K19,0) | L20: =IFERROR(L14/L19,0) | M20: =IFERROR(M14/M19,0) | ... BA20: =IFERROR(BA14/BA19,0) | BC20: =AVERAGE(F20:Q20) | BD20: =AVERAGE(R20:AC20) | BE20: =AVERAGE(AD20:AO20) | BF20: =AVERAGE(AP20:BA20) | BH20: reconciles to the EUR600/customer already assumed on Assumptions row 102
B22: SALES CAPACITY — direct reps early, enabled installer channel at scale
B23: Direct motion share | C23: % | F23: =IF(YEAR(F$5)=2027,Assumptions!$F$149,IF(YEAR(F$5)=2028,Assumptions!$F$150,IF(YEAR(F$5)=2029,Assumptions!$F$151,Assumptions!$F$152))) | G23: =IF(YEAR(G$5)=2027,Assumptions!$F$149,IF(YEAR(G$5)=2028,Assumptions!$F$150,IF(YEAR(G$5)=2029,Assumptions!$F$151,Assumptions!$F$152))) | H23: =IF(YEAR(H$5)=2027,Assumptions!$F$149,IF(YEAR(H$5)=2028,Assumptions!$F$150,IF(YEAR(H$5)=2029,Assumptions!$F$151,Assumptions!$F$152))) | I23: =IF(YEAR(I$5)=2027,Assumptions!$F$149,IF(YEAR(I$5)=2028,Assumptions!$F$150,IF(YEAR(I$5)=2029,Assumptions!$F$151,Assumptions!$F$152))) | J23: =IF(YEAR(J$5)=2027,Assumptions!$F$149,IF(YEAR(J$5)=2028,Assumptions!$F$150,IF(YEAR(J$5)=2029,Assumptions!$F$151,Assumptions!$F$152))) | K23: =IF(YEAR(K$5)=2027,Assumptions!$F$149,IF(YEAR(K$5)=2028,Assumptions!$F$150,IF(YEAR(K$5)=2029,Assumptions!$F$151,Assumptions!$F$152))) | L23: =IF(YEAR(L$5)=2027,Assumptions!$F$149,IF(YEAR(L$5)=2028,Assumptions!$F$150,IF(YEAR(L$5)=2029,Assumptions!$F$151,Assumptions!$F$152))) | M23: =IF(YEAR(M$5)=2027,Assumptions!$F$149,IF(YEAR(M$5)=2028,Assumptions!$F$150,IF(YEAR(M$5)=2029,Assumptions!$F$151,Assumptions!$F$152))) | ... BA23: =IF(YEAR(BA$5)=2027,Assumptions!$F$149,IF(YEAR(BA$5)=2028,Assumptions!$F$150,IF(YEAR(BA$5)=2029,Assumptions!$F$151,Assumptions!$F$152))) | BC23: =AVERAGE(F23:Q23) | BD23: =AVERAGE(R23:AC23) | BE23: =AVERAGE(AD23:AO23) | BF23: =AVERAGE(AP23:BA23)
B24: Reps hired in month | C24: FTE | F24: =IF(YEAR(F$5)=2027,Assumptions!$F$154,IF(YEAR(F$5)=2028,Assumptions!$F$155,IF(YEAR(F$5)=2029,Assumptions!$F$156,Assumptions!$F$157))) | G24: =IF(YEAR(G$5)=2027,Assumptions!$F$154,IF(YEAR(G$5)=2028,Assumptions!$F$155,IF(YEAR(G$5)=2029,Assumptions!$F$156,Assumptions!$F$157))) | H24: =IF(YEAR(H$5)=2027,Assumptions!$F$154,IF(YEAR(H$5)=2028,Assumptions!$F$155,IF(YEAR(H$5)=2029,Assumptions!$F$156,Assumptions!$F$157))) | I24: =IF(YEAR(I$5)=2027,Assumptions!$F$154,IF(YEAR(I$5)=2028,Assumptions!$F$155,IF(YEAR(I$5)=2029,Assumptions!$F$156,Assumptions!$F$157))) | J24: =IF(YEAR(J$5)=2027,Assumptions!$F$154,IF(YEAR(J$5)=2028,Assumptions!$F$155,IF(YEAR(J$5)=2029,Assumptions!$F$156,Assumptions!$F$157))) | K24: =IF(YEAR(K$5)=2027,Assumptions!$F$154,IF(YEAR(K$5)=2028,Assumptions!$F$155,IF(YEAR(K$5)=2029,Assumptions!$F$156,Assumptions!$F$157))) | L24: =IF(YEAR(L$5)=2027,Assumptions!$F$154,IF(YEAR(L$5)=2028,Assumptions!$F$155,IF(YEAR(L$5)=2029,Assumptions!$F$156,Assumptions!$F$157))) | M24: =IF(YEAR(M$5)=2027,Assumptions!$F$154,IF(YEAR(M$5)=2028,Assumptions!$F$155,IF(YEAR(M$5)=2029,Assumptions!$F$156,Assumptions!$F$157))) | ... BA24: =IF(YEAR(BA$5)=2027,Assumptions!$F$154,IF(YEAR(BA$5)=2028,Assumptions!$F$155,IF(YEAR(BA$5)=2029,Assumptions!$F$156,Assumptions!$F$157))) | BC24: =SUM(F24:Q24) | BD24: =SUM(R24:AC24) | BE24: =SUM(AD24:AO24) | BF24: =SUM(AP24:BA24)
B25: Reps on payroll | C25: FTE | F25: =Assumptions!$F$153+F24 | G25: =F25+G24 | H25: =G25+H24 | I25: =H25+I24 | J25: =I25+J24 | K25: =J25+K24 | L25: =K25+L24 | M25: =L25+M24 | N25: =M25+N24 | ... BA25: =AZ25+BA24 | BC25: =Q25 | BD25: =AC25 | BE25: =AO25 | BF25: =BA25
B26: Reps fully ramped | C26: FTE | F26: =Assumptions!$F$153 | G26: =IF(1<Assumptions!$F$159,Assumptions!$F$153,INDEX($F25:BA25,2-Assumptions!$F$159)) | H26: =IF(2<Assumptions!$F$159,Assumptions!$F$153,INDEX($F25:BA25,3-Assumptions!$F$159)) | I26: =IF(3<Assumptions!$F$159,Assumptions!$F$153,INDEX($F25:BA25,4-Assumptions!$F$159)) | J26: =IF(4<Assumptions!$F$159,Assumptions!$F$153,INDEX($F25:BA25,5-Assumptions!$F$159)) | K26: =IF(5<Assumptions!$F$159,Assumptions!$F$153,INDEX($F25:BA25,6-Assumptions!$F$159)) | L26: =IF(6<Assumptions!$F$159,Assumptions!$F$153,INDEX($F25:BA25,7-Assumptions!$F$159)) | M26: =IF(7<Assumptions!$F$159,Assumptions!$F$153,INDEX($F25:BA25,8-Assumptions!$F$159)) | N26: =IF(8<Assumptions!$F$159,Assumptions!$F$153,INDEX($F25:BA25,9-Assumptions!$F$159)) | O26: =IF(9<Assumptions!$F$159,Assumptions!$F$153,INDEX($F25:BA25,10-Assumptions!$F$159)) | P26: =IF(10<Assumptions!$F$159,Assumptions!$F$153,INDEX($F25:BA25,11-Assumptions!$F$159)) | Q26: =IF(11<Assumptions!$F$159,Assumptions!$F$153,INDEX($F25:BA25,12-Assumptions!$F$159)) | R26: =IF(12<Assumptions!$F$159,Assumptions!$F$153,INDEX($F25:BA25,13-Assumptions!$F$159)) | S26: =IF(13<Assumptions!$F$159,Assumptions!$F$153,INDEX($F25:BA25,14-Assumptions!$F$159)) | T26: =IF(14<Assumptions!$F$159,Assumptions!$F$153,INDEX($F25:BA25,15-Assumptions!$F$159)) | U26: =IF(15<Assumptions!$F$159,Assumptions!$F$153,INDEX($F25:BA25,16-Assumptions!$F$159)) | V26: =IF(16<Assumptions!$F$159,Assumptions!$F$153,INDEX($F25:BA25,17-Assumptions!$F$159)) | W26: =IF(17<Assumptions!$F$159,Assumptions!$F$153,INDEX($F25:BA25,18-Assumptions!$F$159)) | X26: =IF(18<Assumptions!$F$159,Assumptions!$F$153,INDEX($F25:BA25,19-Assumptions!$F$159)) | Y26: =IF(19<Assumptions!$F$159,Assumptions!$F$153,INDEX($F25:BA25,20-Assumptions!$F$159)) | Z26: =IF(20<Assumptions!$F$159,Assumptions!$F$153,INDEX($F25:BA25,21-Assumptions!$F$159)) | AA26: =IF(21<Assumptions!$F$159,Assumptions!$F$153,INDEX($F25:BA25,22-Assumptions!$F$159)) | AB26: =IF(22<Assumptions!$F$159,Assumptions!$F$153,INDEX($F25:BA25,23-Assumptions!$F$159)) | AC26: =IF(23<Assumptions!$F$159,Assumptions!$F$153,INDEX($F25:BA25,24-Assumptions!$F$159)) | AD26: =IF(24<Assumptions!$F$159,Assumptions!$F$153,INDEX($F25:BA25,25-Assumptions!$F$159)) | AE26: =IF(25<Assumptions!$F$159,Assumptions!$F$153,INDEX($F25:BA25,26-Assumptions!$F$159)) | AF26: =IF(26<Assumptions!$F$159,Assumptions!$F$153,INDEX($F25:BA25,27-Assumptions!$F$159)) | AG26: =IF(27<Assumptions!$F$159,Assumptions!$F$153,INDEX($F25:BA25,28-Assumptions!$F$159)) | AH26: =IF(28<Assumptions!$F$159,Assumptions!$F$153,INDEX($F25:BA25,29-Assumptions!$F$159)) | AI26: =IF(29<Assumptions!$F$159,Assumptions!$F$153,INDEX($F25:BA25,30-Assumptions!$F$159)) | AJ26: =IF(30<Assumptions!$F$159,Assumptions!$F$153,INDEX($F25:BA25,31-Assumptions!$F$159)) | AK26: =IF(31<Assumptions!$F$159,Assumptions!$F$153,INDEX($F25:BA25,32-Assumptions!$F$159)) | AL26: =IF(32<Assumptions!$F$159,Assumptions!$F$153,INDEX($F25:BA25,33-Assumptions!$F$159)) | AM26: =IF(33<Assumptions!$F$159,Assumptions!$F$153,INDEX($F25:BA25,34-Assumptions!$F$159)) | AN26: =IF(34<Assumptions!$F$159,Assumptions!$F$153,INDEX($F25:BA25,35-Assumptions!$F$159)) | AO26: =IF(35<Assumptions!$F$159,Assumptions!$F$153,INDEX($F25:BA25,36-Assumptions!$F$159)) | AP26: =IF(36<Assumptions!$F$159,Assumptions!$F$153,INDEX($F25:BA25,37-Assumptions!$F$159)) | AQ26: =IF(37<Assumptions!$F$159,Assumptions!$F$153,INDEX($F25:BA25,38-Assumptions!$F$159)) | AR26: =IF(38<Assumptions!$F$159,Assumptions!$F$153,INDEX($F25:BA25,39-Assumptions!$F$159)) | AS26: =IF(39<Assumptions!$F$159,Assumptions!$F$153,INDEX($F25:BA25,40-Assumptions!$F$159)) | AT26: =IF(40<Assumptions!$F$159,Assumptions!$F$153,INDEX($F25:BA25,41-Assumptions!$F$159)) | AU26: =IF(41<Assumptions!$F$159,Assumptions!$F$153,INDEX($F25:BA25,42-Assumptions!$F$159)) | AV26: =IF(42<Assumptions!$F$159,Assumptions!$F$153,INDEX($F25:BA25,43-Assumptions!$F$159)) | AW26: =IF(43<Assumptions!$F$159,Assumptions!$F$153,INDEX($F25:BA25,44-Assumptions!$F$159)) | AX26: =IF(44<Assumptions!$F$159,Assumptions!$F$153,INDEX($F25:BA25,45-Assumptions!$F$159)) | AY26: =IF(45<Assumptions!$F$159,Assumptions!$F$153,INDEX($F25:BA25,46-Assumptions!$F$159)) | AZ26: =IF(46<Assumptions!$F$159,Assumptions!$F$153,INDEX($F25:BA25,47-Assumptions!$F$159)) | BA26: =IF(47<Assumptions!$F$159,Assumptions!$F$153,INDEX($F25:BA25,48-Assumptions!$F$159)) | BC26: =Q26 | BD26: =AC26 | BE26: =AO26 | BF26: =BA26 | BH26: a rep carries no quota until fully ramped (6 months) — deliberately conservative
B27: Direct capacity | C27: units/mo | F27: =F26*Assumptions!$F$158*Assumptions!$F$160 | G27: =G26*Assumptions!$F$158*Assumptions!$F$160 | H27: =H26*Assumptions!$F$158*Assumptions!$F$160 | I27: =I26*Assumptions!$F$158*Assumptions!$F$160 | J27: =J26*Assumptions!$F$158*Assumptions!$F$160 | K27: =K26*Assumptions!$F$158*Assumptions!$F$160 | L27: =L26*Assumptions!$F$158*Assumptions!$F$160 | M27: =M26*Assumptions!$F$158*Assumptions!$F$160 | ... BA27: =BA26*Assumptions!$F$158*Assumptions!$F$160 | BC27: =SUM(F27:Q27) | BD27: =SUM(R27:AC27) | BE27: =SUM(AD27:AO27) | BF27: =SUM(AP27:BA27)
B28: Installer partners recruited | C28: partners | F28: =IF(YEAR(F$5)=2027,Assumptions!$F$162,IF(YEAR(F$5)=2028,Assumptions!$F$163,IF(YEAR(F$5)=2029,Assumptions!$F$164,Assumptions!$F$165))) | G28: =IF(YEAR(G$5)=2027,Assumptions!$F$162,IF(YEAR(G$5)=2028,Assumptions!$F$163,IF(YEAR(G$5)=2029,Assumptions!$F$164,Assumptions!$F$165))) | H28: =IF(YEAR(H$5)=2027,Assumptions!$F$162,IF(YEAR(H$5)=2028,Assumptions!$F$163,IF(YEAR(H$5)=2029,Assumptions!$F$164,Assumptions!$F$165))) | I28: =IF(YEAR(I$5)=2027,Assumptions!$F$162,IF(YEAR(I$5)=2028,Assumptions!$F$163,IF(YEAR(I$5)=2029,Assumptions!$F$164,Assumptions!$F$165))) | J28: =IF(YEAR(J$5)=2027,Assumptions!$F$162,IF(YEAR(J$5)=2028,Assumptions!$F$163,IF(YEAR(J$5)=2029,Assumptions!$F$164,Assumptions!$F$165))) | K28: =IF(YEAR(K$5)=2027,Assumptions!$F$162,IF(YEAR(K$5)=2028,Assumptions!$F$163,IF(YEAR(K$5)=2029,Assumptions!$F$164,Assumptions!$F$165))) | L28: =IF(YEAR(L$5)=2027,Assumptions!$F$162,IF(YEAR(L$5)=2028,Assumptions!$F$163,IF(YEAR(L$5)=2029,Assumptions!$F$164,Assumptions!$F$165))) | M28: =IF(YEAR(M$5)=2027,Assumptions!$F$162,IF(YEAR(M$5)=2028,Assumptions!$F$163,IF(YEAR(M$5)=2029,Assumptions!$F$164,Assumptions!$F$165))) | ... BA28: =IF(YEAR(BA$5)=2027,Assumptions!$F$162,IF(YEAR(BA$5)=2028,Assumptions!$F$163,IF(YEAR(BA$5)=2029,Assumptions!$F$164,Assumptions!$F$165))) | BC28: =SUM(F28:Q28) | BD28: =SUM(R28:AC28) | BE28: =SUM(AD28:AO28) | BF28: =SUM(AP28:BA28)
B29: Installer partners on books | C29: partners | F29: =Assumptions!$F$161+F28 | G29: =F29+G28 | H29: =G29+H28 | I29: =H29+I28 | J29: =I29+J28 | K29: =J29+K28 | L29: =K29+L28 | M29: =L29+M28 | N29: =M29+N28 | ... BA29: =AZ29+BA28 | BC29: =Q29 | BD29: =AC29 | BE29: =AO29 | BF29: =BA29
B30: Installer partners productive | C30: partners | F30: =Assumptions!$F$161 | G30: =IF(1<Assumptions!$F$166,Assumptions!$F$161,INDEX($F29:BA29,2-Assumptions!$F$166)) | H30: =IF(2<Assumptions!$F$166,Assumptions!$F$161,INDEX($F29:BA29,3-Assumptions!$F$166)) | I30: =IF(3<Assumptions!$F$166,Assumptions!$F$161,INDEX($F29:BA29,4-Assumptions!$F$166)) | J30: =IF(4<Assumptions!$F$166,Assumptions!$F$161,INDEX($F29:BA29,5-Assumptions!$F$166)) | K30: =IF(5<Assumptions!$F$166,Assumptions!$F$161,INDEX($F29:BA29,6-Assumptions!$F$166)) | L30: =IF(6<Assumptions!$F$166,Assumptions!$F$161,INDEX($F29:BA29,7-Assumptions!$F$166)) | M30: =IF(7<Assumptions!$F$166,Assumptions!$F$161,INDEX($F29:BA29,8-Assumptions!$F$166)) | N30: =IF(8<Assumptions!$F$166,Assumptions!$F$161,INDEX($F29:BA29,9-Assumptions!$F$166)) | O30: =IF(9<Assumptions!$F$166,Assumptions!$F$161,INDEX($F29:BA29,10-Assumptions!$F$166)) | P30: =IF(10<Assumptions!$F$166,Assumptions!$F$161,INDEX($F29:BA29,11-Assumptions!$F$166)) | Q30: =IF(11<Assumptions!$F$166,Assumptions!$F$161,INDEX($F29:BA29,12-Assumptions!$F$166)) | R30: =IF(12<Assumptions!$F$166,Assumptions!$F$161,INDEX($F29:BA29,13-Assumptions!$F$166)) | S30: =IF(13<Assumptions!$F$166,Assumptions!$F$161,INDEX($F29:BA29,14-Assumptions!$F$166)) | T30: =IF(14<Assumptions!$F$166,Assumptions!$F$161,INDEX($F29:BA29,15-Assumptions!$F$166)) | U30: =IF(15<Assumptions!$F$166,Assumptions!$F$161,INDEX($F29:BA29,16-Assumptions!$F$166)) | V30: =IF(16<Assumptions!$F$166,Assumptions!$F$161,INDEX($F29:BA29,17-Assumptions!$F$166)) | W30: =IF(17<Assumptions!$F$166,Assumptions!$F$161,INDEX($F29:BA29,18-Assumptions!$F$166)) | X30: =IF(18<Assumptions!$F$166,Assumptions!$F$161,INDEX($F29:BA29,19-Assumptions!$F$166)) | Y30: =IF(19<Assumptions!$F$166,Assumptions!$F$161,INDEX($F29:BA29,20-Assumptions!$F$166)) | Z30: =IF(20<Assumptions!$F$166,Assumptions!$F$161,INDEX($F29:BA29,21-Assumptions!$F$166)) | AA30: =IF(21<Assumptions!$F$166,Assumptions!$F$161,INDEX($F29:BA29,22-Assumptions!$F$166)) | AB30: =IF(22<Assumptions!$F$166,Assumptions!$F$161,INDEX($F29:BA29,23-Assumptions!$F$166)) | AC30: =IF(23<Assumptions!$F$166,Assumptions!$F$161,INDEX($F29:BA29,24-Assumptions!$F$166)) | AD30: =IF(24<Assumptions!$F$166,Assumptions!$F$161,INDEX($F29:BA29,25-Assumptions!$F$166)) | AE30: =IF(25<Assumptions!$F$166,Assumptions!$F$161,INDEX($F29:BA29,26-Assumptions!$F$166)) | AF30: =IF(26<Assumptions!$F$166,Assumptions!$F$161,INDEX($F29:BA29,27-Assumptions!$F$166)) | AG30: =IF(27<Assumptions!$F$166,Assumptions!$F$161,INDEX($F29:BA29,28-Assumptions!$F$166)) | AH30: =IF(28<Assumptions!$F$166,Assumptions!$F$161,INDEX($F29:BA29,29-Assumptions!$F$166)) | AI30: =IF(29<Assumptions!$F$166,Assumptions!$F$161,INDEX($F29:BA29,30-Assumptions!$F$166)) | AJ30: =IF(30<Assumptions!$F$166,Assumptions!$F$161,INDEX($F29:BA29,31-Assumptions!$F$166)) | AK30: =IF(31<Assumptions!$F$166,Assumptions!$F$161,INDEX($F29:BA29,32-Assumptions!$F$166)) | AL30: =IF(32<Assumptions!$F$166,Assumptions!$F$161,INDEX($F29:BA29,33-Assumptions!$F$166)) | AM30: =IF(33<Assumptions!$F$166,Assumptions!$F$161,INDEX($F29:BA29,34-Assumptions!$F$166)) | AN30: =IF(34<Assumptions!$F$166,Assumptions!$F$161,INDEX($F29:BA29,35-Assumptions!$F$166)) | AO30: =IF(35<Assumptions!$F$166,Assumptions!$F$161,INDEX($F29:BA29,36-Assumptions!$F$166)) | AP30: =IF(36<Assumptions!$F$166,Assumptions!$F$161,INDEX($F29:BA29,37-Assumptions!$F$166)) | AQ30: =IF(37<Assumptions!$F$166,Assumptions!$F$161,INDEX($F29:BA29,38-Assumptions!$F$166)) | AR30: =IF(38<Assumptions!$F$166,Assumptions!$F$161,INDEX($F29:BA29,39-Assumptions!$F$166)) | AS30: =IF(39<Assumptions!$F$166,Assumptions!$F$161,INDEX($F29:BA29,40-Assumptions!$F$166)) | AT30: =IF(40<Assumptions!$F$166,Assumptions!$F$161,INDEX($F29:BA29,41-Assumptions!$F$166)) | AU30: =IF(41<Assumptions!$F$166,Assumptions!$F$161,INDEX($F29:BA29,42-Assumptions!$F$166)) | AV30: =IF(42<Assumptions!$F$166,Assumptions!$F$161,INDEX($F29:BA29,43-Assumptions!$F$166)) | AW30: =IF(43<Assumptions!$F$166,Assumptions!$F$161,INDEX($F29:BA29,44-Assumptions!$F$166)) | AX30: =IF(44<Assumptions!$F$166,Assumptions!$F$161,INDEX($F29:BA29,45-Assumptions!$F$166)) | AY30: =IF(45<Assumptions!$F$166,Assumptions!$F$161,INDEX($F29:BA29,46-Assumptions!$F$166)) | AZ30: =IF(46<Assumptions!$F$166,Assumptions!$F$161,INDEX($F29:BA29,47-Assumptions!$F$166)) | BA30: =IF(47<Assumptions!$F$166,Assumptions!$F$161,INDEX($F29:BA29,48-Assumptions!$F$166)) | BC30: =Q30 | BD30: =AC30 | BE30: =AO30 | BF30: =BA30
B31: Channel capacity | C31: units/mo | F31: =F30*Assumptions!$F$167 | G31: =G30*Assumptions!$F$167 | H31: =H30*Assumptions!$F$167 | I31: =I30*Assumptions!$F$167 | J31: =J30*Assumptions!$F$167 | K31: =K30*Assumptions!$F$167 | L31: =L30*Assumptions!$F$167 | M31: =M30*Assumptions!$F$167 | ... BA31: =BA30*Assumptions!$F$167 | BC31: =SUM(F31:Q31) | BD31: =SUM(R31:AC31) | BE31: =SUM(AD31:AO31) | BF31: =SUM(AP31:BA31)
B32: TOTAL sales capacity | C32: units/mo | F32: =MIN(IFERROR(F27/F23,1000000),IFERROR(F31/(1-F23),1000000)) | G32: =MIN(IFERROR(G27/G23,1000000),IFERROR(G31/(1-G23),1000000)) | H32: =MIN(IFERROR(H27/H23,1000000),IFERROR(H31/(1-H23),1000000)) | I32: =MIN(IFERROR(I27/I23,1000000),IFERROR(I31/(1-I23),1000000)) | J32: =MIN(IFERROR(J27/J23,1000000),IFERROR(J31/(1-J23),1000000)) | K32: =MIN(IFERROR(K27/K23,1000000),IFERROR(K31/(1-K23),1000000)) | L32: =MIN(IFERROR(L27/L23,1000000),IFERROR(L31/(1-L23),1000000)) | M32: =MIN(IFERROR(M27/M23,1000000),IFERROR(M31/(1-M23),1000000)) | ... BA32: =MIN(IFERROR(BA27/BA23,1000000),IFERROR(BA31/(1-BA23),1000000)) | BC32: =SUM(F32:Q32) | BD32: =SUM(R32:AC32) | BE32: =SUM(AD32:AO32) | BF32: =SUM(AP32:BA32) | BH32: how many we can actually sell: our own reps have to cover the direct share, installers the rest
B33: Partner managers required | C33: FTE | F33: =ROUNDUP(F29/Assumptions!$F$168,0) | G33: =ROUNDUP(G29/Assumptions!$F$168,0) | H33: =ROUNDUP(H29/Assumptions!$F$168,0) | I33: =ROUNDUP(I29/Assumptions!$F$168,0) | J33: =ROUNDUP(J29/Assumptions!$F$168,0) | K33: =ROUNDUP(K29/Assumptions!$F$168,0) | L33: =ROUNDUP(L29/Assumptions!$F$168,0) | M33: =ROUNDUP(M29/Assumptions!$F$168,0) | ... BA33: =ROUNDUP(BA29/Assumptions!$F$168,0) | BC33: =Q33 | BD33: =AC33 | BE33: =AO33 | BF33: =BA33
B36: BUILD CAPACITY — assembly partner first, in-house lines take over
B37: Assembly partner capacity | C37: units/mo | F37: =Assumptions!$F$172 | G37: =Assumptions!$F$172 | H37: =Assumptions!$F$172 | I37: =Assumptions!$F$172 | J37: =Assumptions!$F$172 | K37: =Assumptions!$F$172 | L37: =Assumptions!$F$172 | M37: =Assumptions!$F$172 | ... BA37: =Assumptions!$F$172 | BC37: =SUM(F37:Q37) | BD37: =SUM(R37:AC37) | BE37: =SUM(AD37:AO37) | BF37: =SUM(AP37:BA37)
B38: In-house lines live | C38: lines | F38: =IF(F$5>=Assumptions!$F$173,1,0)+IF(F$5>=Assumptions!$F$174,1,0) | G38: =IF(G$5>=Assumptions!$F$173,1,0)+IF(G$5>=Assumptions!$F$174,1,0) | H38: =IF(H$5>=Assumptions!$F$173,1,0)+IF(H$5>=Assumptions!$F$174,1,0) | I38: =IF(I$5>=Assumptions!$F$173,1,0)+IF(I$5>=Assumptions!$F$174,1,0) | J38: =IF(J$5>=Assumptions!$F$173,1,0)+IF(J$5>=Assumptions!$F$174,1,0) | K38: =IF(K$5>=Assumptions!$F$173,1,0)+IF(K$5>=Assumptions!$F$174,1,0) | L38: =IF(L$5>=Assumptions!$F$173,1,0)+IF(L$5>=Assumptions!$F$174,1,0) | M38: =IF(M$5>=Assumptions!$F$173,1,0)+IF(M$5>=Assumptions!$F$174,1,0) | ... BA38: =IF(BA$5>=Assumptions!$F$173,1,0)+IF(BA$5>=Assumptions!$F$174,1,0) | BC38: =Q38 | BD38: =AC38 | BE38: =AO38 | BF38: =BA38
B39: In-house capacity | C39: units/mo | F39: =F38*Assumptions!$F$175 | G39: =G38*Assumptions!$F$175 | H39: =H38*Assumptions!$F$175 | I39: =I38*Assumptions!$F$175 | J39: =J38*Assumptions!$F$175 | K39: =K38*Assumptions!$F$175 | L39: =L38*Assumptions!$F$175 | M39: =M38*Assumptions!$F$175 | ... BA39: =BA38*Assumptions!$F$175 | BC39: =SUM(F39:Q39) | BD39: =SUM(R39:AC39) | BE39: =SUM(AD39:AO39) | BF39: =SUM(AP39:BA39)
B40: TOTAL build capacity | C40: units/mo | F40: =F37+F39 | G40: =G37+G39 | H40: =H37+H39 | I40: =I37+I39 | J40: =J37+J39 | K40: =K37+K39 | L40: =L37+L39 | M40: =M37+M39 | ... BA40: =BA37+BA39 | BC40: =SUM(F40:Q40) | BD40: =SUM(R40:AC40) | BE40: =SUM(AD40:AO40) | BF40: =SUM(AP40:BA40)
B42: UNITS SOLD — and what stopped us selling more, month by month
B43: UNITS SOLD | C43: units | F43: =ROUND(MIN(F19,F11,F32,F40),0) | G43: =ROUND(MIN(G19,G11,G32,G40),0) | H43: =ROUND(MIN(H19,H11,H32,H40),0) | I43: =ROUND(MIN(I19,I11,I32,I40),0) | J43: =ROUND(MIN(J19,J11,J32,J40),0) | K43: =ROUND(MIN(K19,K11,K32,K40),0) | L43: =ROUND(MIN(L19,L11,L32,L40),0) | M43: =ROUND(MIN(M19,M11,M32,M40),0) | ... BA43: =ROUND(MIN(BA19,BA11,BA32,BA40),0) | BC43: =SUM(F43:Q43) | BD43: =SUM(R43:AC43) | BE43: =SUM(AD43:AO43) | BF43: =SUM(AP43:BA43) | BH43: we sell the smallest of: what people want, what the market allows, what we can sell, what we can build
B44: Why we did not sell more | F44: =IF(F43>=F40-0.5,"Build capacity",IF(F43>=F32-0.5,"Sales capacity",IF(F43>=F11-0.5,"Market ceiling","Demand"))) | G44: =IF(G43>=G40-0.5,"Build capacity",IF(G43>=G32-0.5,"Sales capacity",IF(G43>=G11-0.5,"Market ceiling","Demand"))) | H44: =IF(H43>=H40-0.5,"Build capacity",IF(H43>=H32-0.5,"Sales capacity",IF(H43>=H11-0.5,"Market ceiling","Demand"))) | I44: =IF(I43>=I40-0.5,"Build capacity",IF(I43>=I32-0.5,"Sales capacity",IF(I43>=I11-0.5,"Market ceiling","Demand"))) | J44: =IF(J43>=J40-0.5,"Build capacity",IF(J43>=J32-0.5,"Sales capacity",IF(J43>=J11-0.5,"Market ceiling","Demand"))) | K44: =IF(K43>=K40-0.5,"Build capacity",IF(K43>=K32-0.5,"Sales capacity",IF(K43>=K11-0.5,"Market ceiling","Demand"))) | L44: =IF(L43>=L40-0.5,"Build capacity",IF(L43>=L32-0.5,"Sales capacity",IF(L43>=L11-0.5,"Market ceiling","Demand"))) | M44: =IF(M43>=M40-0.5,"Build capacity",IF(M43>=M32-0.5,"Sales capacity",IF(M43>=M11-0.5,"Market ceiling","Demand"))) | ... BA44: =IF(BA43>=BA40-0.5,"Build capacity",IF(BA43>=BA32-0.5,"Sales capacity",IF(BA43>=BA11-0.5,"Market ceiling","Demand")))
B45: Build capacity utilisation | C45: % | F45: =IFERROR(F43/F40,0) | G45: =IFERROR(G43/G40,0) | H45: =IFERROR(H43/H40,0) | I45: =IFERROR(I43/I40,0) | J45: =IFERROR(J43/J40,0) | K45: =IFERROR(K43/K40,0) | L45: =IFERROR(L43/L40,0) | M45: =IFERROR(M43/M40,0) | ... BA45: =IFERROR(BA43/BA40,0) | BC45: =AVERAGE(F45:Q45) | BD45: =AVERAGE(R45:AC45) | BE45: =AVERAGE(AD45:AO45) | BF45: =AVERAGE(AP45:BA45)
B46: Installed base, end of month | C46: units | F46: =F15+F43 | G46: =G15+G43 | H46: =H15+H43 | I46: =I15+I43 | J46: =J15+J43 | K46: =K15+K43 | L46: =L15+L43 | M46: =M15+M43 | ... BA46: =BA15+BA43 | BC46: =Q46 | BD46: =AC46 | BE46: =AO46 | BF46: =BA46
B47: CONSEQUENCES — market share, installed base, and the org the plan needs
B48: Implied share of serviceable market | C48: % | F48: =IFERROR(F43/F10,0) | G48: =IFERROR(G43/G10,0) | H48: =IFERROR(H43/H10,0) | I48: =IFERROR(I43/I10,0) | J48: =IFERROR(J43/J10,0) | K48: =IFERROR(K43/K10,0) | L48: =IFERROR(L43/L10,0) | M48: =IFERROR(M43/M10,0) | ... BA48: =IFERROR(BA43/BA10,0) | BC48: =AVERAGE(F48:Q48) | BD48: =AVERAGE(R48:AC48) | BE48: =AVERAGE(AD48:AO48) | BF48: =AVERAGE(AP48:BA48) | BH48: the first number a VC computes — kept on the face of the model
...

Sheet Financial Statements
B1: Tarnoc B.V. — Financial Statements (€)
E2: 2025 | Q2: 2026 | AC2: 2027 | AO2: 2028
E3: 45658 | F3: 45689 | G3: 45717 | H3: 45748 | I3: 45778 | J3: 45809 | K3: 45839 | L3: 45870 | M3: 45901 | N3: 45931 | O3: 45962 | P3: 45992 | Q3: 46023 | R3: 46054 | S3: 46082 | T3: 46113 | U3: 46143 | V3: 46174 | W3: 46204 | X3: 46235 | Y3: 46266 | Z3: 46296 | AA3: 46327 | AB3: 46357 | AC3: 46388 | AD3: 46419 | AE3: 46447 | AF3: 46478 | AG3: 46508 | AH3: 46539 | AI3: 46569 | AJ3: 46600 | AK3: 46631 | AL3: 46661 | AM3: 46692 | AN3: 46722 | AO3: 46753 | AP3: 46784 | AQ3: 46813 | AR3: 46844 | AS3: 46874 | AT3: 46905 | AU3: 46935 | AV3: 46966 | AW3: 46997 | AX3: 47027 | AY3: 47058 | AZ3: 47088 | BB3: 2025 | BC3: 2026 | BD3: 2027 | BE3: 2028 | BF3: 2029 | BH3: what this row does
B5: PROFIT & LOSS STATEMENT
B6: Revenues
B7: TTK | D7: € | M7: ='Revenue Forecast'!M9 | N7: ='Revenue Forecast'!N9 | O7: ='Revenue Forecast'!O9 | P7: ='Revenue Forecast'!P9 | Q7: ='Revenue Forecast'!Q9 | R7: ='Revenue Forecast'!R9 | S7: ='Revenue Forecast'!S9 | T7: ='Revenue Forecast'!T9 | ... AZ7: ='Revenue Forecast'!AZ9 | BB7: =sum(E7:P7) | BC7: =sum(Q7:AB7) | BD7: =sum(AC7:AN7) | BE7: =sum(AO7:AZ7) | BF7: ='Revenue Forecast'!BF9 | BH7: TTK revenue, pulled from the Revenue Forecast
B8: Combi+ | D8: € | Q8: ='Revenue Forecast'!Q15 | R8: ='Revenue Forecast'!R15 | S8: ='Revenue Forecast'!S15 | T8: ='Revenue Forecast'!T15 | U8: ='Revenue Forecast'!U15 | V8: ='Revenue Forecast'!V15 | W8: ='Revenue Forecast'!W15 | X8: ='Revenue Forecast'!X15 | ... AZ8: ='Revenue Forecast'!AZ15 | BB8: ='Revenue Forecast'!BB15 | BC8: ='Revenue Forecast'!BC15 | BD8: ='Revenue Forecast'!BD15 | BE8: ='Revenue Forecast'!BE15 | BF8: ='Revenue Forecast'!BF15 | BH8: Combi+ revenue, pulled from the Revenue Forecast
B9: Other | D9: € | M9: ='Revenue Forecast'!M19+'Revenue Forecast'!M24 | N9: ='Revenue Forecast'!N19+'Revenue Forecast'!N24 | O9: ='Revenue Forecast'!O19+'Revenue Forecast'!O24 | P9: ='Revenue Forecast'!P19+'Revenue Forecast'!P24 | Q9: ='Revenue Forecast'!Q19+'Revenue Forecast'!Q24 | R9: ='Revenue Forecast'!R19+'Revenue Forecast'!R24 | S9: ='Revenue Forecast'!S19+'Revenue Forecast'!S24 | T9: ='Revenue Forecast'!T19+'Revenue Forecast'!T24 | ... AZ9: ='Revenue Forecast'!AZ19+'Revenue Forecast'!AZ24 | BB9: =sum(E9:P9) | BC9: =sum(Q9:AB9) | BD9: =sum(AC9:AN9) | BE9: =sum(AO9:AZ9) | BF9: ='Revenue Forecast'!BF19+'Revenue Forecast'!BF24 | BH9: installation + service revenue from the Revenue Forecast
B10: Subsidies & grants | D10: € | M10: ='Revenue Forecast'!M28 | N10: ='Revenue Forecast'!N28 | O10: ='Revenue Forecast'!O28 | P10: ='Revenue Forecast'!P28 | Q10: ='Revenue Forecast'!Q28 | R10: ='Revenue Forecast'!R28 | S10: ='Revenue Forecast'!S28 | T10: 0 | U10: ='Revenue Forecast'!U28 | V10: ='Revenue Forecast'!V28 | W10: ='Revenue Forecast'!W28 | X10: ='Revenue Forecast'!X28 | Y10: ='Revenue Forecast'!Y28 | Z10: ='Revenue Forecast'!Z28 | AA10: ='Revenue Forecast'!AA28 | AB10: ='Revenue Forecast'!AB28 | ... AZ10: ='Revenue Forecast'!AZ28 | BB10: =sum(E10:P10) | BC10: =sum(Q10:AB10) | BD10: pm | BE10: pm | BF10: pm | BH10: subsidies from the Revenue Forecast. nothing budgeted
B11: Total Revenue | D11: € | M11: ='Revenue Forecast'!M30 | N11: ='Revenue Forecast'!N30 | O11: ='Revenue Forecast'!O30 | P11: ='Revenue Forecast'!P30 | Q11: ='Revenue Forecast'!Q30 | R11: ='Revenue Forecast'!R30 | S11: ='Revenue Forecast'!S30 | T11: ='Revenue Forecast'!T30 | ... AZ11: ='Revenue Forecast'!AZ30 | BB11: =sum(E11:P11) | BC11: =sum(Q11:AB11) | BD11: =sum(AC11:AN11) | BE11: =sum(AO11:AZ11) | BF11: =sum(BF7:BF10) | BH11: all the revenue lines added
B13: Cost of goods sold
B14: TTK | D14: € | E14: =COGS!E9 | F14: =COGS!F9 | G14: =COGS!G9 | H14: =COGS!H9 | I14: =COGS!I9 | J14: =COGS!J9 | K14: =COGS!K9 | L14: =COGS!L9 | ... AZ14: =COGS!AZ9 | BB14: =sum(E14:P14) | BC14: =sum(Q14:AB14) | BD14: =sum(AC14:AN14) | BE14: =sum(AO14:AZ14) | BF14: =COGS!BF9 | BH14: TTK cost of sales, from the COGS tab
B15: Combi+ | D15: € | Q15: =COGS!Q14 | R15: =COGS!R14 | S15: =COGS!S14 | T15: =COGS!T14 | U15: =COGS!U14 | V15: =COGS!V14 | W15: =COGS!W14 | X15: =COGS!X14 | ... AZ15: =COGS!AZ14 | BB15: =COGS!BB14 | BC15: =COGS!BC14 | BD15: =COGS!BD14 | BE15: =COGS!BE14 | BF15: =COGS!BF14 | BH15: Combi+ cost of sales, from COGS
B16: Other | D16: € | E16: =COGS!E17 | F16: =COGS!F17 | G16: =COGS!G17 | H16: =COGS!H17 | I16: =COGS!I17 | J16: =COGS!J17 | K16: =COGS!K17 | L16: =COGS!L17 | ... P16: =COGS!P17 | Q16: =COGS!Q17+COGS!Q20 | R16: =COGS!R17+COGS!R20 | S16: =COGS!S17+COGS!S20 | T16: =COGS!T17+COGS!T20 | U16: =COGS!U17+COGS!U20 | V16: =COGS!V17+COGS!V20 | W16: =COGS!W17+COGS!W20 | X16: =COGS!X17+COGS!X20 | ... AZ16: =COGS!AZ17+COGS!AZ20 | BB16: =sum(E16:P16) | BC16: =sum(Q16:AB16) | BD16: =sum(AC16:AN16) | BE16: =sum(AO16:AZ16) | BF16: =COGS!BF17+COGS!BF20 | BH16: installation + service costs, from COGS
B17: Total COGS | D17: € | M17: =COGS!M22 | N17: =COGS!N22 | O17: =COGS!O22 | P17: =COGS!P22 | Q17: =COGS!Q22 | R17: =COGS!R22 | S17: =COGS!S22 | T17: =COGS!T22 | ... AZ17: =COGS!AZ22 | BB17: =sum(E17:P17) | BC17: =sum(Q17:AB17) | BD17: =sum(AC17:AN17) | BE17: =sum(AO17:AZ17) | BF17: =sum(BF14:BF16) | BH17: all the cost lines added
B19: Gross Profit
B20: TTK | D20: € | Q20: =Q7-Q14 | R20: =R7-R14 | S20: =S7-S14 | T20: =T7-T14 | U20: =U7-U14 | V20: =V7-V14 | W20: =W7-W14 | X20: =X7-X14 | ... AZ20: =AZ7-AZ14 | BC20: =BC7-BC14 | BD20: =BD7-BD14 | BE20: =BE7-BE14 | BF20: =BF7-BF14 | BH20: TTK revenue minus TTK cost
B21: Combi+ | D21: € | Q21: =Q8-Q15 | R21: =R8-R15 | S21: =S8-S15 | T21: =T8-T15 | U21: =U8-U15 | V21: =V8-V15 | W21: =W8-W15 | X21: =X8-X15 | ... AZ21: =AZ8-AZ15 | BC21: =BC8-BC15 | BD21: =BD8-BD15 | BE21: =BE8-BE15 | BF21: =BF8-BF15 | BH21: Combi+ revenue minus Combi+ cost
B22: Other | D22: € | Q22: =Q9-Q16 | R22: =R9-R16 | S22: =S9-S16 | T22: =T9-T16 | U22: =U9-U16 | V22: =V9-V16 | W22: =W9-W16 | X22: =X9-X16 | ... AZ22: =AZ9-AZ16 | BC22: =BC9-BC16 | BD22: =BD9-BD16 | BE22: =BE9-BE16 | BF22: =BF9-BF16 | BH22: installation + service revenue minus their cost
B23: Gross Profit | D23: € | M23: =M11-M17 | N23: =N11-N17 | O23: =O11-O17 | P23: =P11-P17 | Q23: =Q11-Q17 | R23: =R11-R17 | S23: =S11-S17 | T23: =T11-T17 | ... AZ23: =AZ11-AZ17 | BB23: =sum(E23:P23) | BC23: =sum(Q23:AB23) | BD23: =sum(AC23:AN23) | BE23: =sum(AO23:AZ23) | BF23: =BF11-BF17 | BH23: revenue minus cost of sales
B24: Gross margin % | D24: % | BD24: =BD23/BD11 | BE24: =BE23/BE11 | BF24: =BF23/BF11 | BH24: gross profit as a % of revenue (year columns only)
B26: Operational expenses
B27: R&D | D27: € | M27: =OPEX!O38 | N27: =OPEX!P38 | O27: =OPEX!Q38 | P27: =OPEX!R38 | Q27: =OPEX!S38 | R27: =OPEX!T38 | S27: =OPEX!U38 | T27: =OPEX!V38 | ... AZ27: =OPEX!BB38 | BB27: =sum(E27:P27) | BC27: =sum(Q27:AB27) | BD27: =sum(AC27:AN27) | BE27: =sum(AO27:AZ27) | BF27: =OPEX!BH38 | BH27: R&D spend, people and other, from OPEX
B28: S&M | D28: € | M28: =OPEX!O39 | N28: =OPEX!P39 | O28: =OPEX!Q39 | P28: =OPEX!R39 | Q28: =OPEX!S39 | R28: =OPEX!T39 | S28: =OPEX!U39 | T28: =OPEX!V39 | ... AZ28: =OPEX!BB39 | BB28: =sum(E28:P28) | BC28: =sum(Q28:AB28) | BD28: =sum(AC28:AN28) | BE28: =sum(AO28:AZ28) | BF28: =OPEX!BH39 | BH28: S&M spend from OPEX
B29: G&A | D29: € | M29: =OPEX!O40 | N29: =OPEX!P40 | O29: =OPEX!Q40 | P29: =OPEX!R40 | Q29: =OPEX!S40 | R29: =OPEX!T40 | S29: =OPEX!U40 | T29: =OPEX!V40 | ... AZ29: =OPEX!BB40 | BB29: =sum(E29:P29) | BC29: =sum(Q29:AB29) | BD29: =sum(AC29:AN29) | BE29: =sum(AO29:AZ29) | BF29: =OPEX!BH40 | BH29: G&A spend from OPEX
B30: Total OPEX | D30: € | M30: =(M29+M28+M27) | N30: =(N29+N28+N27) | O30: =(O29+O28+O27) | P30: =(P29+P28+P27) | Q30: =(Q29+Q28+Q27) | R30: =(R29+R28+R27) | S30: =(S29+S28+S27) | T30: =(T29+T28+T27) | ... AZ30: =(AZ29+AZ28+AZ27) | BB30: =sum(E30:P30) | BC30: =sum(Q30:AB30) | BD30: =sum(AC30:AN30) | BE30: =sum(AO30:AZ30) | BF30: =sum(BF27:BF29) | BH30: the three OPEX lines added
B32: EBITDA | D32: € | M32: =M23-M30 | N32: =N23-N30 | O32: =O23-O30 | P32: =P23-P30 | Q32: =Q23-Q30 | R32: =R23-R30 | S32: =S23-S30 | T32: =T23-T30 | ... AZ32: =AZ23-AZ30 | BB32: =sum(E32:P32) | BC32: =sum(Q32:AB32) | BD32: =sum(AC32:AN32) | BE32: =sum(AO32:AZ32) | BF32: =BF23-BF30 | BH32: gross profit minus operating costs
B33: EBITDA margin % | D33: % | BE33: =BE32/BE11 | BF33: =BF32/BF11 | BH33: EBITDA as a % of revenue
B35: Depreciation & Amortisation | D35: € | E35: =-SUM($E$53:E53)/(Assumptions!$D$128*12) | F35: =-SUM($E$53:F53)/(Assumptions!$D$128*12) | G35: =-SUM($E$53:G53)/(Assumptions!$D$128*12) | H35: =-SUM($E$53:H53)/(Assumptions!$D$128*12) | I35: =-SUM($E$53:I53)/(Assumptions!$D$128*12) | J35: =-SUM($E$53:J53)/(Assumptions!$D$128*12) | K35: =-SUM($E$53:K53)/(Assumptions!$D$128*12) | L35: =-SUM($E$53:L53)/(Assumptions!$D$128*12) | ... AZ35: =-SUM($E$53:AZ53)/(Assumptions!$D$128*12) | BB35: =sum(E35:P35) | BC35: =sum(Q35:AB35) | BD35: =sum(AC35:AN35) | BE35: =sum(AO35:AZ35) | BF35: =(-SUM($E$53:$AZ$53)+(-BF53)/2)/Assumptions!$D$128 | BH35: straight line on cumulative capex, blended life from Assumptions D128
B36: Interest payments | D36: € | M36: 0 | N36: 0 | O36: 0 | P36: 0 | Q36: =P82*Assumptions!$C$11/12 | R36: =Q82*Assumptions!$C$11/12 | S36: =R82*Assumptions!$C$11/12 | T36: =S82*Assumptions!$C$11/12 | U36: =T82*Assumptions!$C$11/12 | V36: =U82*Assumptions!$C$11/12 | W36: =V82*Assumptions!$C$11/12 | X36: =W82*Assumptions!$C$11/12 | ... AZ36: =AY82*Assumptions!$C$11/12 | BB36: =sum(E36:P36) | BC36: =sum(Q36:AB36) | BD36: =sum(AC36:AN36) | BE36: =sum(AO36:AZ36) | BF36: =BE82*Assumptions!$C$11/12 | BH36: interest on last month's loan balance, yearly rate divided by 12
B37: EBT | D37: € | M37: =M32-sum(M35:M36) | N37: =N32-sum(N35:N36) | O37: =O32-sum(O35:O36) | P37: =P32-sum(P35:P36) | Q37: =Q32-sum(Q35:Q36) | R37: =R32-sum(R35:R36) | S37: =S32-sum(S35:S36) | T37: =T32-sum(T35:T36) | ... AZ37: =AZ32-sum(AZ35:AZ36) | BB37: =sum(E37:P37) | BC37: =sum(Q37:AB37) | BD37: =sum(AC37:AN37) | BE37: =sum(AO37:AZ37) | BF37: =BF32-sum(BF35:BF36) | BH37: EBITDA minus depreciation and interest
BE38: =BE37/BE11 | BF38: =BF37/BF11 | BH38: profit before tax as a % of revenue
B40: Income tax | D40: € | M40: 0 | N40: 0 | O40: 0 | P40: 0 | Q40: 0 | R40: 0 | S40: 0 | T40: 0 | U40: 0 | V40: 0 | W40: 0 | X40: 0 | Y40: 0 | Z40: 0 | AA40: 0 | AB40: 0 | AC40: 0 | AD40: 0 | AE40: 0 | AF40: 0 | AG40: 0 | AH40: 0 | AI40: 0 | AJ40: 0 | AK40: 0 | AL40: 0 | AM40: 0 | AN40: 0 | AO40: 0 | AP40: 0 | AQ40: 0 | AR40: 0 | AS40: 0 | AT40: 0 | AU40: 0 | AV40: 0 | AW40: 0 | AX40: 0 | AY40: 0 | AZ40: 0 | BB40: =sum(E40:P40) | BC40: =sum(Q40:AB40) | BD40: =sum(AC40:AN40) | BE40: =sum(AO40:AZ40) | BF40: =(BF37-AZ44)*Assumptions!$C$10 | BH40: tax on profit, but only once the old losses below are used up
B41: NET INCOME | D41: € | M41: =M37-M40 | N41: =N37-N40 | O41: =O37-O40 | P41: =P37-P40 | Q41: =Q37-Q40 | R41: =R37-R40 | S41: =S37-S40 | T41: =T37-T40 | ... AZ41: =AZ37-AZ40 | BB41: =sum(E41:P41) | BC41: =sum(Q41:AB41) | BD41: =sum(AC41:AN41) | BE41: =sum(AO41:AZ41) | BF41: =BF37-BF40 | BH41: profit after tax
B42: Profit margin % | BE42: =BE41/BE11 | BF42: =BF41/BF11 | BH42: net profit as a % of revenue
B44: Tax carry over to be applied | M44: 108239 | N44: =M44+(-N41*Assumptions!$C$10) | O44: =N44+(-O41*Assumptions!$C$10) | P44: =O44+(-P41*Assumptions!$C$10) | Q44: =P44+(-Q41*Assumptions!$C$10) | R44: =Q44+(-R41*Assumptions!$C$10) | S44: =R44+(-S41*Assumptions!$C$10) | T44: =S44+(-T41*Assumptions!$C$10) | U44: =T44+(-U41*Assumptions!$C$10) | ... AZ44: =AY44+(-AZ41*Assumptions!$C$10) | BH44: running pot of unused tax losses: grows in loss months, gets eaten when profitable
B46: CASH FLOW STATEMENT
B47: Net income | D47: € | M47: =M41 | N47: =N41 | O47: =O41 | P47: =P41 | Q47: =Q41 | R47: =R41 | S47: =S41 | T47: =T41 | ... AZ47: =AZ41 | BB47: =sum(E47:P47) | BC47: =sum(Q47:AB47) | BD47: =sum(AC47:AN47) | BE47: =sum(AO47:AZ47) | BF47: =BF41 | BH47: cash flow starts from net income
B48: Depreciation & amortisation | D48: € | E48: =E35 | F48: =F35 | G48: =G35 | H48: =H35 | I48: =I35 | J48: =J35 | K48: =K35 | L48: =L35 | ... AZ48: =AZ35 | BB48: =sum(E48:P48) | BC48: =sum(Q48:AB48) | BD48: =sum(AC48:AN48) | BE48: =sum(AO48:AZ48) | BF48: =BF35 | BH48: adds depreciation back, it isn't cash
B49: Increase in accounts receivable (delta DSO) | D49: € | M49: 0 | N49: =-(N68-M68) | O49: =-(O68-N68) | P49: =-(P68-O68) | Q49: =-(Q68-P68) | R49: =-(R68-Q68) | S49: =-(S68-R68) | T49: =-(T68-S68) | U49: =-(U68-T68) | ... AZ49: =-(AZ68-AY68) | BB49: =sum(E49:P49) | BC49: =sum(Q49:AB49) | BD49: =sum(AC49:AN49) | BE49: =sum(AO49:AZ49) | BF49: =-(BF68-BE68) | BH49: cash tied up when receivables grow, freed when they shrink
...

Sheet Revenue Forecast
B1: Tarnoc B.V. — Revenue Forecast (€, ex VAT unless noted)
E2: 2025 | Q2: 2026 | AC2: 2027 | AO2: 2028
E3: 45658 | F3: 45689 | G3: 45717 | H3: 45748 | I3: 45778 | J3: 45809 | K3: 45839 | L3: 45870 | M3: 45901 | N3: 45931 | O3: 45962 | P3: 45992 | Q3: 46023 | R3: 46054 | S3: 46082 | T3: 46113 | U3: 46143 | V3: 46174 | W3: 46204 | X3: 46235 | Y3: 46266 | Z3: 46296 | AA3: 46327 | AB3: 46357 | AC3: 46388 | AD3: 46419 | AE3: 46447 | AF3: 46478 | AG3: 46508 | AH3: 46539 | AI3: 46569 | AJ3: 46600 | AK3: 46631 | AL3: 46661 | AM3: 46692 | AN3: 46722 | AO3: 46753 | AP3: 46784 | AQ3: 46813 | AR3: 46844 | AS3: 46874 | AT3: 46905 | AU3: 46935 | AV3: 46966 | AW3: 46997 | AX3: 47027 | AY3: 47058 | AZ3: 47088 | BB3: 2025 | BC3: 2026 | BD3: 2027 | BE3: 2028 | BF3: 2029 | BH3: what this row does
AB4: 2 | AC4: 3 | AD4: 4 | AE4: 5 | AF4: 6 | AG4: 7 | AH4: 8 | AI4: 9 | AJ4: 10 | AK4: 11 | AL4: 12 | AM4: 13 | AN4: 14 | AO4: 15 | AP4: 16 | AQ4: 17 | AR4: 18 | AS4: 19 | AT4: 20 | AU4: 21 | AV4: 22 | AW4: 23 | AX4: 24 | AY4: 25 | AZ4: 26
B5: TURBINEKETEL (TTK)
B6: TTK units sold | D6: # | E6: 0 | F6: 0 | G6: 0 | H6: 0 | I6: 0 | J6: 0 | K6: 0 | L6: 0 | M6: 0 | N6: 0 | O6: 0 | P6: 0 | Q6: 0 | R6: 0 | S6: 0 | T6: 0 | U6: 0 | V6: 0 | W6: 0 | X6: 0 | Y6: 0 | Z6: 0 | AA6: 0 | AB6: 0 | AC6: ='Growth Engine'!F43*Assumptions!$H$23 | AD6: ='Growth Engine'!G43*Assumptions!$H$23 | AE6: ='Growth Engine'!H43*Assumptions!$H$23 | AF6: ='Growth Engine'!I43*Assumptions!$H$23 | AG6: ='Growth Engine'!J43*Assumptions!$H$23 | AH6: ='Growth Engine'!K43*Assumptions!$H$23 | AI6: ='Growth Engine'!L43*Assumptions!$H$23 | AJ6: ='Growth Engine'!M43*Assumptions!$H$23 | ... AZ6: ='Growth Engine'!AC43*Assumptions!$H$23 | BB6: =SUM(E6:P6) | BC6: =SUM(Q6:AB6) | BD6: =SUM(AC6:AN6) | BE6: =SUM(AO6:AZ6) | BF6: =Assumptions!$F$23 | BH6: units from the Growth Engine tab x the TTK share of the mix (Assumptions H23)
B7: TTK Revenue | D7: € | Q7: =Q6*Assumptions!$C$29 | R7: =R6*Assumptions!$C$29 | S7: =S6*Assumptions!$C$29 | T7: =T6*Assumptions!$C$29 | U7: =U6*Assumptions!$C$29 | V7: =V6*Assumptions!$C$29 | W7: =W6*Assumptions!$C$29 | X7: =X6*Assumptions!$C$29 | ... AZ7: =AZ6*Assumptions!$C$29 | BB7: =SUM(E7:P7) | BC7: =SUM(Q7:AB7) | BD7: =SUM(AC7:AN7) | BE7: =SUM(AO7:AZ7) | BF7: =BF6*Assumptions!$C$29 | BH7: units x TTK price
B8: TTK upsell | D8: € | Q8: =Q6*SUMPRODUCT(Assumptions!$E$112:$F$114) | R8: =R6*SUMPRODUCT(Assumptions!$E$112:$F$114) | S8: =S6*SUMPRODUCT(Assumptions!$E$112:$F$114) | T8: =T6*SUMPRODUCT(Assumptions!$E$112:$F$114) | U8: =U6*SUMPRODUCT(Assumptions!$E$112:$F$114) | V8: =V6*SUMPRODUCT(Assumptions!$E$112:$F$114) | W8: =W6*SUMPRODUCT(Assumptions!$E$112:$F$114) | X8: =X6*SUMPRODUCT(Assumptions!$E$112:$F$114) | ... AB8: =AB6*SUMPRODUCT(Assumptions!$E$112:$F$114) | AC8: =AC6*SUMPRODUCT(Assumptions!$E$112:$E$114,Assumptions!$F$112:$F$114) | AD8: =AD6*SUMPRODUCT(Assumptions!$E$112:$E$114,Assumptions!$F$112:$F$114) | AE8: =AE6*SUMPRODUCT(Assumptions!$E$112:$E$114,Assumptions!$F$112:$F$114) | AF8: =AF6*SUMPRODUCT(Assumptions!$E$112:$E$114,Assumptions!$F$112:$F$114) | AG8: =AG6*SUMPRODUCT(Assumptions!$E$112:$E$114,Assumptions!$F$112:$F$114) | AH8: =AH6*SUMPRODUCT(Assumptions!$E$112:$E$114,Assumptions!$F$112:$F$114) | AI8: =AI6*SUMPRODUCT(Assumptions!$E$112:$E$114,Assumptions!$F$112:$F$114) | AJ8: =AJ6*SUMPRODUCT(Assumptions!$E$112:$E$114,Assumptions!$F$112:$F$114) | ... AZ8: =AZ6*SUMPRODUCT(Assumptions!$E$112:$E$114,Assumptions!$F$112:$F$114) | BB8: =SUM(E8:P8) | BC8: =SUM(Q8:AB8) | BD8: =SUM(AC8:AN8) | BE8: =SUM(AO8:AZ8) | BF8: =BF6*SUMPRODUCT(Assumptions!$E$112:$E$114,Assumptions!$F$112:$F$114) | BH8: units x average upsell basket (attach % x price)
B9: Total TTK Revenue | D9: € | Q9: =sum(Q7:Q8) | R9: =sum(R7:R8) | S9: =sum(S7:S8) | T9: =sum(T7:T8) | U9: =sum(U7:U8) | V9: =sum(V7:V8) | W9: =sum(W7:W8) | X9: =sum(X7:X8) | ... AZ9: =sum(AZ7:AZ8) | BB9: =SUM(E9:P9) | BC9: =SUM(Q9:AB9) | BD9: =SUM(AC9:AN9) | BE9: =SUM(AO9:AZ9) | BF9: =SUM(BF7:BF8) | BH9: machine revenue + upsells
B11: COMBI+
B12: Combi+ units sold | D12: # | E12: 0 | F12: 0 | G12: 0 | H12: 0 | I12: 0 | J12: 0 | K12: 0 | L12: 0 | M12: 0 | N12: 0 | O12: 0 | P12: 0 | Q12: 0 | R12: 0 | S12: 0 | T12: 0 | U12: 0 | V12: 0 | W12: 0 | X12: 0 | Y12: 0 | Z12: 0 | AA12: 0 | AB12: 0 | AC12: ='Growth Engine'!F43*Assumptions!$H$24 | AD12: ='Growth Engine'!G43*Assumptions!$H$24 | AE12: ='Growth Engine'!H43*Assumptions!$H$24 | AF12: ='Growth Engine'!I43*Assumptions!$H$24 | AG12: ='Growth Engine'!J43*Assumptions!$H$24 | AH12: ='Growth Engine'!K43*Assumptions!$H$24 | AI12: ='Growth Engine'!L43*Assumptions!$H$24 | AJ12: ='Growth Engine'!M43*Assumptions!$H$24 | ... AZ12: ='Growth Engine'!AC43*Assumptions!$H$24 | BB12: =SUM(E12:P12) | BC12: =SUM(Q12:AB12) | BD12: =SUM(AC12:AN12) | BE12: =SUM(AO12:AZ12) | BF12: =Assumptions!$F$24 | BH12: units from the Growth Engine tab x the Combi+ share of the mix (Assumptions H24)
B13: Combi+ Revenue | D13: € | Q13: =Q12*Assumptions!$C$31 | R13: =R12*Assumptions!$C$31 | S13: =S12*Assumptions!$C$31 | T13: =T12*Assumptions!$C$31 | U13: =U12*Assumptions!$C$31 | V13: =V12*Assumptions!$C$31 | W13: =W12*Assumptions!$C$31 | X13: =X12*Assumptions!$C$31 | ... AZ13: =AZ12*Assumptions!$C$31 | BB13: =SUM(E13:P13) | BC13: =SUM(Q13:AB13) | BD13: =SUM(AC13:AN13) | BE13: =SUM(AO13:AZ13) | BF13: =BF12*Assumptions!$C$31 | BH13: units x Combi+ price (ketel + outdoor unit)
B14: Combi+ upsell | D14: € | Q14: =Q12*SUMPRODUCT(Assumptions!$E$112:$E$114,Assumptions!$F$112:$F$114) | R14: =R12*SUMPRODUCT(Assumptions!$E$112:$E$114,Assumptions!$F$112:$F$114) | S14: =S12*SUMPRODUCT(Assumptions!$E$112:$E$114,Assumptions!$F$112:$F$114) | T14: =T12*SUMPRODUCT(Assumptions!$E$112:$E$114,Assumptions!$F$112:$F$114) | U14: =U12*SUMPRODUCT(Assumptions!$E$112:$E$114,Assumptions!$F$112:$F$114) | V14: =V12*SUMPRODUCT(Assumptions!$E$112:$E$114,Assumptions!$F$112:$F$114) | W14: =W12*SUMPRODUCT(Assumptions!$E$112:$E$114,Assumptions!$F$112:$F$114) | X14: =X12*SUMPRODUCT(Assumptions!$E$112:$E$114,Assumptions!$F$112:$F$114) | ... AZ14: =AZ12*SUMPRODUCT(Assumptions!$E$112:$E$114,Assumptions!$F$112:$F$114) | BB14: =SUM(E14:P14) | BC14: =SUM(Q14:AB14) | BD14: =SUM(AC14:AN14) | BE14: =SUM(AO14:AZ14) | BF14: =BF12*SUMPRODUCT(Assumptions!$E$112:$E$114,Assumptions!$F$112:$F$114) | BH14: units x average upsell basket
B15: Total Combi+ Revenue | D15: € | Q15: =sum(Q13:Q14) | R15: =sum(R13:R14) | S15: =sum(S13:S14) | T15: =sum(T13:T14) | U15: =sum(U13:U14) | V15: =sum(V13:V14) | W15: =sum(W13:W14) | X15: =sum(X13:X14) | ... AZ15: =sum(AZ13:AZ14) | BB15: =SUM(E15:P15) | BC15: =SUM(Q15:AB15) | BD15: =SUM(AC15:AN15) | BE15: =SUM(AO15:AZ15) | BF15: =sum(BF13:BF14) | BH15: machine revenue + upsells
B17: INSTALLATION REVENUES | D17: €
B18: Units installed | D18: # | E18: =E6+E12 | F18: =F6+F12 | G18: =G6+G12 | H18: =H6+H12 | I18: =I6+I12 | J18: =J6+J12 | K18: =K6+K12 | L18: =L6+L12 | ... AZ18: =AZ6+AZ12 | BB18: =SUM(E18:P18) | BC18: =SUM(Q18:AB18) | BD18: =SUM(AC18:AN18) | BE18: =SUM(AO18:AZ18) | BF18: =BF6+BF12 | BH18: TTK + Combi+ units. every unit sold gets installed
B19: Total Installation Revenue | D19: € | E19: =E6*Assumptions!$C$33+E12*Assumptions!$C$34 | F19: =F6*Assumptions!$C$33+F12*Assumptions!$C$34 | G19: =G6*Assumptions!$C$33+G12*Assumptions!$C$34 | H19: =H6*Assumptions!$C$33+H12*Assumptions!$C$34 | I19: =I6*Assumptions!$C$33+I12*Assumptions!$C$34 | J19: =J6*Assumptions!$C$33+J12*Assumptions!$C$34 | K19: =K6*Assumptions!$C$33+K12*Assumptions!$C$34 | L19: =L6*Assumptions!$C$33+L12*Assumptions!$C$34 | ... AZ19: =AZ6*Assumptions!$C$33+AZ12*Assumptions!$C$34 | BB19: =SUM(E19:P19) | BC19: =SUM(Q19:AB19) | BD19: =SUM(AC19:AN19) | BE19: =SUM(AO19:AZ19) | BF19: =BF6*Assumptions!$C$33+BF12*Assumptions!$C$34 | BH19: units x installation price per product. pass-through, cost is the same
B21: SERVICE REVENUES
B22: Installed base (TTK) | D22: # | Q22: =Q6 | R22: =R6 | S22: =S6 | T22: =T6 | U22: =U6 | V22: =V6 | W22: =W6 | X22: =X6 | ... AC22: =AC6 | AD22: =AC22+AD6 | AE22: =AD22+AE6 | AF22: =AE22+AF6 | AG22: =AF22+AG6 | AH22: =AG22+AH6 | AI22: =AH22+AI6 | AJ22: =AI22+AJ6 | AK22: =AJ22+AK6 | ... AZ22: =AY22+AZ6 | BB22: =SUM(E22:P22) | BC22: =SUM(Q22:AB22) | BD22: =AN22 | BE22: =AZ22 | BF22: =BE22+($BF$18*Assumptions!$H$23) | BH22: TTK machines out in the field: last month's base + this month's sales
B23: Installed base (Combi+) | Q23: =Q12 | R23: =R12 | S23: =S12 | T23: =T12 | U23: =U12 | V23: =V12 | W23: =W12 | X23: =X12 | ... AC23: =AC12 | AD23: =AC23+AD12 | AE23: =AD23+AE12 | AF23: =AE23+AF12 | AG23: =AF23+AG12 | AH23: =AG23+AH12 | AI23: =AH23+AI12 | AJ23: =AI23+AJ12 | AK23: =AJ23+AK12 | ... AZ23: =AY23+AZ12 | BB23: =SUM(E23:P23) | BC23: =SUM(Q23:AB23) | BD23: =AN23 | BE23: =AZ23 | BF23: =BE23+($BF$18*Assumptions!$H$24) | BH23: Combi+ machines out in the field, same running total
B24: Total Service Revenue | D24: € | Q24: =Q34*SUMPRODUCT(Assumptions!$E$120:$E$121,Assumptions!$F$120:$F$121) | R24: =R34*SUMPRODUCT(Assumptions!$E$120:$E$121,Assumptions!$F$120:$F$121) | S24: =S34*SUMPRODUCT(Assumptions!$E$120:$E$121,Assumptions!$F$120:$F$121) | T24: =T34*SUMPRODUCT(Assumptions!$E$120:$E$121,Assumptions!$F$120:$F$121) | U24: =U34*SUMPRODUCT(Assumptions!$E$120:$E$121,Assumptions!$F$120:$F$121) | V24: =V34*SUMPRODUCT(Assumptions!$E$120:$E$121,Assumptions!$F$120:$F$121) | W24: =W34*SUMPRODUCT(Assumptions!$E$120:$E$121,Assumptions!$F$120:$F$121) | X24: =X34*SUMPRODUCT(Assumptions!$E$120:$E$121,Assumptions!$F$120:$F$121) | ... AB24: =AB34*SUMPRODUCT(Assumptions!$E$120:$E$121,Assumptions!$F$120:$F$121) | AC24: =AC34*SUMPRODUCT(Assumptions!$E$120:$E$121,Assumptions!$F$120:$F$121)+Q24 | AD24: =AD34*SUMPRODUCT(Assumptions!$E$120:$E$121,Assumptions!$F$120:$F$121)+R24 | AE24: =AE34*SUMPRODUCT(Assumptions!$E$120:$E$121,Assumptions!$F$120:$F$121)+S24 | AF24: =AF34*SUMPRODUCT(Assumptions!$E$120:$E$121,Assumptions!$F$120:$F$121)+T24 | AG24: =AG34*SUMPRODUCT(Assumptions!$E$120:$E$121,Assumptions!$F$120:$F$121)+U24 | AH24: =AH34*SUMPRODUCT(Assumptions!$E$120:$E$121,Assumptions!$F$120:$F$121)+V24 | AI24: =AI34*SUMPRODUCT(Assumptions!$E$120:$E$121,Assumptions!$F$120:$F$121)+W24 | AJ24: =AJ34*SUMPRODUCT(Assumptions!$E$120:$E$121,Assumptions!$F$120:$F$121)+X24 | ... AZ24: =AZ34*SUMPRODUCT(Assumptions!$E$120:$E$121,Assumptions!$F$120:$F$121)+AN24 | BB24: =SUM(E24:P24) | BC24: =SUM(Q24:AB24) | BD24: =SUM(AC24:AN24) | BE24: =SUM(AO24:AZ24) | BF24: =BF34*SUMPRODUCT(Assumptions!$E$120:$E$121,Assumptions!$F$120:$F$121)+BE24 | BH24: this month's units x service rate + the same month last year, so contracts keep stacking as the base grows. 2029 adds all of 2028 on top
B26: SUBSIDIES & GRANTS
B27: All other | D27: € | E27: 0 | F27: 0 | G27: 0 | H27: 0 | I27: 0 | J27: 0 | K27: 0 | L27: 0 | M27: 0 | N27: 19480 | O27: 78000 | P27: 0 | Q27: 0 | R27: 0 | S27: 0 | T27: 0 | U27: 0 | V27: 0 | W27: 0 | X27: 106782 | Y27: 0 | Z27: 0 | AA27: 0 | AB27: 0 | AC27: 0 | AD27: 0 | AE27: 0 | AF27: 0 | AG27: 0 | AH27: 0 | AI27: 0 | AJ27: 0 | AK27: 0 | AL27: 0 | AM27: 0 | AN27: 0 | AO27: 0 | AP27: 0 | AQ27: 0 | AR27: 0 | AS27: 0 | AT27: 0 | AU27: 0 | AV27: 0 | AW27: 0 | AX27: 0 | AY27: 0 | AZ27: 0 | BB27: =SUM(E27:P27) | BC27: =SUM(Q27:AB27) | BD27: =SUM(AC27:AN27) | BE27: =SUM(AO27:AZ27) | BF27: 0 | BH27: nothing budgeted. the year columns just add the months up
B28: Total Subsidies & Grants | D28: € | E28: =sum(E27) | F28: =sum(F27) | G28: =sum(G27) | H28: =sum(H27) | I28: =sum(I27) | J28: =sum(J27) | K28: =sum(K27) | L28: =sum(L27) | ... AZ28: =sum(AZ27) | BB28: =SUM(E28:P28) | BC28: =SUM(Q28:AB28) | BD28: =BD27 | BE28: =BE27 | BF28: =BF27 | BH28: same as the line above
