Workbook

Sheet Summary
B1: Tarnoc B.V. Summary (Base case, EUR3m raise)
B2: Written 7 September 2026. The results table is live; the text is not. | D2: Case shown: | E2: Base case, EUR3m raise
D3: BOM priced on: | E3: two-year volume commitment
B5: WHAT THIS IS
B6: A monthly model of Tarnoc from January 2026 to December 2030. Every figure is calculated from the Assumptions tab.
B7: The only typed numbers are the assumptions, the committed 2026 plan (OPEX rows 38 to 43) and the back-office headcount (Personnel row 17).
B8: This workbook holds the base case only (EUR3m raise). The BOM is priced on two-year volume.
B9: Prices, BOM tiers, service and upsell tables, shipping, the 2026 plan, the subsidy, the raise amounts and working-capital days are the client's own figures.
B11: HOW UNITS SOLD ARE CALCULATED
B12: Units sold in a month is the lowest of three numbers:
B13: 1. Demand: marketing spend / EUR120 per lead x 50% qualified x 40% won, plus the orders installer partners bring in themselves (1 a month each in 2027, 4 by 2030).
B14: 2. Selling capacity: own reps x 20 a month for the direct share of sales, installer partners x 8 a month for the rest. Direct share 80% in 2027, 50% in 2028, 35%, then 30%.
B15: 3. Build capacity: the assembly partner's contracted volume. This case has no in-house production.
B17: WHAT FOLLOWS FROM UNITS
B18: Revenue: units x price, plus upsell, plus installation passed through to the installer at cost, plus service contracts on the installed base.
... B22: RESULTS
C23: 2026 | D23: 2027 | E23: 2028 | F23: 2029 | G23: 2030
B24: Units sold | C24: =Dashboard!D6 | D24: =Dashboard!E6 | E24: =Dashboard!F6 | F24: =Dashboard!G6 | G24: =Dashboard!H6
B25: Revenue | C25: =Dashboard!D14 | D25: =Dashboard!E14 | E25: =Dashboard!F14 | F25: =Dashboard!G14 | G25: =Dashboard!H14
B26: Gross margin | C26: =Dashboard!D16 | D26: =Dashboard!E16 | E26: =Dashboard!F16 | F26: =Dashboard!G16 | G26: =Dashboard!H16
B27: EBITDA | C27: =Dashboard!D18 | D27: =Dashboard!E18 | E27: =Dashboard!F18 | F27: =Dashboard!G18 | G27: =Dashboard!H18
B28: Total headcount at year end | C28: =Dashboard!D24 | D28: =Dashboard!E24 | E28: =Dashboard!F24 | F28: =Dashboard!G24 | G28: =Dashboard!H24
B29: Cash at year end | C29: =Dashboard!D31 | D29: =Dashboard!E31 | E29: =Dashboard!F31 | F29: =Dashboard!G31 | G29: =Dashboard!H31
B31: Lowest cash after the raise, and when | C31: =Dashboard!D37 | D31: =Dashboard!D38
B32: Months of operating cost that covers | C32: =Dashboard!D53
B33: Share of the raise the plan uses | C33: =Dashboard!D52
B34: Lowest cash before the raise | C34: =Dashboard!D39
B36: THIS CASE IN TWO LINES (typed on 7 September 2026; the table above is live)
B37: Base, EUR3m: 354 / 1,344 / 4,122 / 7,407 units in 2027 to 2030, EUR126m revenue in 2030. Gross margin 10%, 25%, 37%, 37%. EBITDA -2.5m, +0.9m, +17m, +34m. 95 people.
B38: Cash low EUR0.6m in December 2027, about two months of cost; 80% of the raise used.
B39: Gross margin steps from about 10% to 25% the year two-year volume passes 5,000 units (2028), and to 37% past 10,000 (2029).
B41: DOES IT MAKE SENSE
B42: Mechanically, yes. Both cases pass the full audit: no formula errors, balance sheet ties every month, funding received equals the inputs, 116 rows agree with an independent re-implementation.
B43: Commercially it holds on one condition: the supplier prices the BOM on two-year volume. Without that, 2027 and 2028 are priced at EUR9,984 a unit and base does not close on EUR3m.
B44: Soft spot 1. Base turns on about 500 units: 2028 plus 2029 volume is 5,500 against a 5,000 tier. Below 5,000, 2028 costs EUR2,900 more per unit and EBITDA goes back to about -3m.
B46: ASSUMPTIONS CHECKED AGAINST THE MARKET (research of 4 September 2026, sources in docs/tarnoc-assumptions-research-2026-09-04.md)
B47: Assumption | C47: In the model | D47: Verdict | E47: What the market evidence says
B48: Cost per marketing lead | C48: EUR120 | D48: supported | E48: Exclusive heat-pump leads EUR130-280 NL/BE, EUR50-350 DE; EUR90-180 is the range
B49: Lead to order (50% qualified x 40% won) | C49: 20%, EUR600 per order | D49: high | E49: Published 8-15% and EUR900-1,800 per order; the client's current number; stronger for a product priced below installed heat pumps
B50: Installer commission | C50: 10% of unit price | D50: supported as a fee | E50: Loyalty and referral schemes pay 4-10%; installers who buy and resell expect 20-30% trade margin
...

Sheet Cover
B6: TARNOC B.V.
B8: Financial Model
B9: Built from scratch, September 2026
B10: Base case, EUR3m raise
B12: Currency | C12: EUR, ex VAT unless stated
B13: Period | C13: January 2026 to December 2030, monthly
B14: Fiscal year | C14: Calendar
B15: Units | C15: Whole euros
B18: Start with the Summary tab, then How to read me.
B21: STRICTLY CONFIDENTIAL

Sheet How to read me
B1: Tarnoc B.V. How to read this model
B3: COLOUR CODING
B4: Sample | C4: Hardcoded input. These are the only cells to change. They live on Assumptions, plus the back-office headcount row on Personnel.
B5: Sample | C5: Calculated cell. Do not type over these.
B6: Sample | C6: Subtotal or total row.
B7: Sample | C7: Section header.
B8: Sample | C8: Margin or ratio row.
B9: Sample | C9: Check row. Must read nil.
B12: HOW THE MODEL FITS TOGETHER
C13: Assumptions -> every other tab. The only other typed numbers are the back-office headcount on Personnel and the committed 2026 plan on OPEX.
C14: Revenue Forecast -> COGS, OPEX, Personnel, Financial Statements.
C15: Personnel -> OPEX -> Financial Statements.
C16: Everything -> Dashboard.
B18: THE CASE
C19: This workbook holds the base case only (EUR3m raise). The Value column on Assumptions is the plan; there is no case switch.
C20: The bill of materials is priced on two-year volume (this year plus next), which assumes a volume commitment to the supplier. There is no switch for this; it is how the COGS tab works.
B22: HOW UNITS SOLD IS DECIDED
C23: Units sold is not typed in. Three numbers are worked out for every month and the smallest one wins:
C24: 1. Demand. Marketing spend divided by cost per lead, through the two conversion rates, plus the orders installer partners bring in on their own jobs.
C25: 2. What we can sell. Our own reps times quota, plus installer partners times units each, capped by the direct and channel mix. No ramp-up: reps and partners sell at full rate from the month they join.
C26: 3. What we can build. The assembly partner's contracted volume.
C27: There is no market size or market share anywhere in the model.
B30: THINGS WORTH KNOWING
C31: Installation is a pass-through. It is charged to the customer at exactly what the installation partner is paid, so it adds revenue and an identical cost and no margin.
C32: Field service engineers are salaried staff on the Personnel tab. The service contract cost per unit in COGS covers parts, consumables and travel, not their salaries.
C33: Unit cost falls in steps, not smoothly. The turbineketel bill of materials is EUR9,984 below 5,000 units a year, EUR7,069 from 5,000 and EUR4,998 from 10,000. Almost all of the profit in the later years comes from crossing the second step, so that assumption carries more weight than any other in the model.
C34: Every month is a real column. There are no annual-only columns, so nothing can be hardcoded in a year that the monthly build does not see.

Sheet Assumptions
B1: Tarnoc B.V. Assumptions
B2: Every driver lives here. Pale yellow cells are inputs, everything else is calculated. This workbook is the base case, eur3m raise.
B4: GENERAL
D5: Value
B6: Opening cash at Jan-2026 | C6: EUR | D6: 853120 | J6: the actual balance carried into January 2026
B7: Base year for salary and cost inflation | C7: year | D7: 2026 | J7: costs are quoted in this year's money and inflated from here
B8: Annual salary increase | C8: % | D8: 0.05
B9: Corporate income tax rate | C9: % | D9: 0.258 | J9: losses are carried forward until profits absorb them
B10: Interest on the convertible loan | C10: % | D10: 0.05
B11: First month we can sell | C11: date | D11: 46388 | J11: nil units before this. Product, certification and supply have to be ready first
B12: Committed 2026 plan holds until | C12: date | D12: 46296 | J12: operating costs to this month are taken from the existing plan, not from the drivers
B13: Subsidy received | C13: EUR | D13: 106782
B14: Subsidy received in | C14: date | D14: 46235
B15: WORKING CAPITAL
B16: Days sales outstanding | C16: days | D16: 20
B17: Days payable outstanding | C17: days | D17: 45
B18: Days inventory outstanding | C18: days | D18: 0 | J18: the assembly partner holds the stock; nothing sits on our balance sheet
B19: PRICING (ex VAT)
B20: Turbineketel list price | C20: EUR/unit | D20: 8525.62
B21: Outdoor unit, Combi+ only | C21: EUR/unit | D21: 5309.92
B22: Combi+ price (ketel plus outdoor unit) | C22: EUR/unit | D22: =Assumptions!$D$20+Assumptions!$D$21
B23: Installation, TTK | C23: EUR/unit | D23: 2800 | J23: pass-through: the customer is charged what the installer is paid
B24: Installation, Combi+ | C24: EUR/unit | D24: 3800 | J24: pass-through, so it adds revenue and an identical cost
B25: TTK share of units | C25: % | D25: 0.2
B26: Combi+ share of units | C26: % | D26: =1-Assumptions!$D$25
B27: UPSELL BASKET (attached to every unit sold)
D28: Attach % | E28: Price | F28: Cost
B29: Boiler variant 50 | D29: 0.49 | E29: 165.29 | F29: 80
B30: Boiler variant 100 | D30: 0.19 | E30: 330.58 | F30: 150
B31: Sound reduction | D31: 0.79 | E31: 454.55 | F31: 190
B32: Upsell revenue per unit sold | C32: EUR/unit | D32: =SUMPRODUCT($D$29:$D$31,$E$29:$E$31)
B33: Upsell cost per unit sold | C33: EUR/unit | D33: =SUMPRODUCT($D$29:$D$31,$F$29:$F$31)
B34: SERVICE CONTRACTS (annual, charged on the installed base)
D35: Attach % | E35: Price/yr | F35: Cost/yr
B36: TTK, basic | D36: 0.34 | E36: 60 | F36: 30
B37: TTK, premium | D37: 0.54 | E37: 90 | F37: 40
B38: Combi+, basic | D38: 0.34 | E38: 150 | F38: 75
B39: Combi+, premium | D39: 0.54 | E39: 200 | F39: 100
B40: Service revenue per installed unit per year | C40: EUR/unit | D40: =Assumptions!$D$25*SUMPRODUCT($D$36:$D$37,$E$36:$E$37)+Assumptions!$D$26*SUMPRODUCT($D$38:$D$39,$E$38:$E$39)
B41: Service cost per installed unit per year | C41: EUR/unit | D41: =Assumptions!$D$25*SUMPRODUCT($D$36:$D$37,$F$36:$F$37)+Assumptions!$D$26*SUMPRODUCT($D$38:$D$39,$F$38:$F$39) | J41: parts, consumables and travel per contract; the field engineers themselves are salaried on the Personnel tab
...

Sheet Financial Statements
B1: Tarnoc B.V. Financial Statements
B2: Three statements, monthly. The check on row 58 must read zero in every column.
E3: 46023 | F3: 46054 | G3: 46082 | H3: 46113 | I3: 46143 | J3: 46174 | K3: 46204 | L3: 46235 | M3: 46266 | N3: 46296 | O3: 46327 | P3: 46357 | Q3: 46388 | R3: 46419 | S3: 46447 | T3: 46478 | U3: 46508 | V3: 46539 | W3: 46569 | X3: 46600 | Y3: 46631 | Z3: 46661 | AA3: 46692 | AB3: 46722 | AC3: 46753 | AD3: 46784 | AE3: 46813 | AF3: 46844 | AG3: 46874 | AH3: 46905 | AI3: 46935 | AJ3: 46966 | AK3: 46997 | AL3: 47027 | AM3: 47058 | AN3: 47088 | AO3: 47119 | AP3: 47150 | AQ3: 47178 | AR3: 47209 | AS3: 47239 | AT3: 47270 | AU3: 47300 | AV3: 47331 | AW3: 47362 | AX3: 47392 | AY3: 47423 | AZ3: 47453 | BA3: 47484 | BB3: 47515 | BC3: 47543 | BD3: 47574 | BE3: 47604 | BF3: 47635 | BG3: 47665 | BH3: 47696 | BI3: 47727 | BJ3: 47757 | BK3: 47788 | BL3: 47818 | BN3: 2026 | BO3: 2027 | BP3: 2028 | BQ3: 2029 | BR3: 2030 | BT3: what this row does
B5: PROFIT AND LOSS
B6: Revenue | C6: EUR | E6: ='Revenue Forecast'!E50 | F6: ='Revenue Forecast'!F50 | G6: ='Revenue Forecast'!G50 | H6: ='Revenue Forecast'!H50 | I6: ='Revenue Forecast'!I50 | J6: ='Revenue Forecast'!J50 | K6: ='Revenue Forecast'!K50 | L6: ='Revenue Forecast'!L50 | ... BL6: ='Revenue Forecast'!BL50 | BN6: =SUM(E6:P6) | BO6: =SUM(Q6:AB6) | BP6: =SUM(AC6:AN6) | BQ6: =SUM(AO6:AZ6) | BR6: =SUM(BA6:BL6)
B7: Cost of goods sold | C7: EUR | E7: =-COGS!E19 | F7: =-COGS!F19 | G7: =-COGS!G19 | H7: =-COGS!H19 | I7: =-COGS!I19 | J7: =-COGS!J19 | K7: =-COGS!K19 | L7: =-COGS!L19 | ... BL7: =-COGS!BL19 | BN7: =SUM(E7:P7) | BO7: =SUM(Q7:AB7) | BP7: =SUM(AC7:AN7) | BQ7: =SUM(AO7:AZ7) | BR7: =SUM(BA7:BL7)
B8: Gross profit | C8: EUR | E8: =E6+E7 | F8: =F6+F7 | G8: =G6+G7 | H8: =H6+H7 | I8: =I6+I7 | J8: =J6+J7 | K8: =K6+K7 | L8: =L6+L7 | ... BL8: =BL6+BL7 | BN8: =SUM(E8:P8) | BO8: =SUM(Q8:AB8) | BP8: =SUM(AC8:AN8) | BQ8: =SUM(AO8:AZ8) | BR8: =SUM(BA8:BL8)
B9: Gross margin | C9: % | E9: =IFERROR(E8/E6,0) | F9: =IFERROR(F8/F6,0) | G9: =IFERROR(G8/G6,0) | H9: =IFERROR(H8/H6,0) | I9: =IFERROR(I8/I6,0) | J9: =IFERROR(J8/J6,0) | K9: =IFERROR(K8/K6,0) | L9: =IFERROR(L8/L6,0) | ... BL9: =IFERROR(BL8/BL6,0) | BN9: =IFERROR(BN8/BN6,0) | BO9: =IFERROR(BO8/BO6,0) | BP9: =IFERROR(BP8/BP6,0) | BQ9: =IFERROR(BQ8/BQ6,0) | BR9: =IFERROR(BR8/BR6,0)
B11: Research and development | C11: EUR | E11: =-OPEX!E30 | F11: =-OPEX!F30 | G11: =-OPEX!G30 | H11: =-OPEX!H30 | I11: =-OPEX!I30 | J11: =-OPEX!J30 | K11: =-OPEX!K30 | L11: =-OPEX!L30 | ... BL11: =-OPEX!BL30 | BN11: =SUM(E11:P11) | BO11: =SUM(Q11:AB11) | BP11: =SUM(AC11:AN11) | BQ11: =SUM(AO11:AZ11) | BR11: =SUM(BA11:BL11)
B12: Sales and marketing | C12: EUR | E12: =-OPEX!E31 | F12: =-OPEX!F31 | G12: =-OPEX!G31 | H12: =-OPEX!H31 | I12: =-OPEX!I31 | J12: =-OPEX!J31 | K12: =-OPEX!K31 | L12: =-OPEX!L31 | ... BL12: =-OPEX!BL31 | BN12: =SUM(E12:P12) | BO12: =SUM(Q12:AB12) | BP12: =SUM(AC12:AN12) | BQ12: =SUM(AO12:AZ12) | BR12: =SUM(BA12:BL12)
B13: General and administrative | C13: EUR | E13: =-OPEX!E32 | F13: =-OPEX!F32 | G13: =-OPEX!G32 | H13: =-OPEX!H32 | I13: =-OPEX!I32 | J13: =-OPEX!J32 | K13: =-OPEX!K32 | L13: =-OPEX!L32 | ... BL13: =-OPEX!BL32 | BN13: =SUM(E13:P13) | BO13: =SUM(Q13:AB13) | BP13: =SUM(AC13:AN13) | BQ13: =SUM(AO13:AZ13) | BR13: =SUM(BA13:BL13)
B14: Total operating expenses | C14: EUR | E14: =SUM(E11:E13) | F14: =SUM(F11:F13) | G14: =SUM(G11:G13) | H14: =SUM(H11:H13) | I14: =SUM(I11:I13) | J14: =SUM(J11:J13) | K14: =SUM(K11:K13) | L14: =SUM(L11:L13) | ... BL14: =SUM(BL11:BL13) | BN14: =SUM(E14:P14) | BO14: =SUM(Q14:AB14) | BP14: =SUM(AC14:AN14) | BQ14: =SUM(AO14:AZ14) | BR14: =SUM(BA14:BL14)
B16: EBITDA | C16: EUR | E16: =E8+E14 | F16: =F8+F14 | G16: =G8+G14 | H16: =H8+H14 | I16: =I8+I14 | J16: =J8+J14 | K16: =K8+K14 | L16: =L8+L14 | ... BL16: =BL8+BL14 | BN16: =SUM(E16:P16) | BO16: =SUM(Q16:AB16) | BP16: =SUM(AC16:AN16) | BQ16: =SUM(AO16:AZ16) | BR16: =SUM(BA16:BL16)
B17: EBITDA margin | C17: % | E17: =IFERROR(E16/E6,0) | F17: =IFERROR(F16/F6,0) | G17: =IFERROR(G16/G6,0) | H17: =IFERROR(H16/H6,0) | I17: =IFERROR(I16/I6,0) | J17: =IFERROR(J16/J6,0) | K17: =IFERROR(K16/K6,0) | L17: =IFERROR(L16/L6,0) | ... BL17: =IFERROR(BL16/BL6,0) | BN17: =IFERROR(BN16/BN6,0) | BO17: =IFERROR(BO16/BO6,0) | BP17: =IFERROR(BP16/BP6,0) | BQ17: =IFERROR(BQ16/BQ6,0) | BR17: =IFERROR(BR16/BR6,0)
B19: Depreciation | C19: EUR | E19: =0 | F19: =0 | G19: =0 | H19: =0 | I19: =0 | J19: =0 | K19: =0 | L19: =0 | ... BL19: =0 | BN19: =SUM(E19:P19) | BO19: =SUM(Q19:AB19) | BP19: =SUM(AC19:AN19) | BQ19: =SUM(AO19:AZ19) | BR19: =SUM(BA19:BL19) | BT19: no fixed assets in this case
B20: Interest on the loan | C20: EUR | E20: =0 | F20: =-E51*Assumptions!$D$10/12 | G20: =-F51*Assumptions!$D$10/12 | H20: =-G51*Assumptions!$D$10/12 | I20: =-H51*Assumptions!$D$10/12 | J20: =-I51*Assumptions!$D$10/12 | K20: =-J51*Assumptions!$D$10/12 | L20: =-K51*Assumptions!$D$10/12 | M20: =-L51*Assumptions!$D$10/12 | ... BL20: =-BK51*Assumptions!$D$10/12 | BN20: =SUM(E20:P20) | BO20: =SUM(Q20:AB20) | BP20: =SUM(AC20:AN20) | BQ20: =SUM(AO20:AZ20) | BR20: =SUM(BA20:BL20)
B21: Profit before tax | C21: EUR | E21: =E16+E19+E20 | F21: =F16+F19+F20 | G21: =G16+G19+G20 | H21: =H16+H19+H20 | I21: =I16+I19+I20 | J21: =J16+J19+J20 | K21: =K16+K19+K20 | L21: =L16+L19+L20 | ... BL21: =BL16+BL19+BL20 | BN21: =SUM(E21:P21) | BO21: =SUM(Q21:AB21) | BP21: =SUM(AC21:AN21) | BQ21: =SUM(AO21:AZ21) | BR21: =SUM(BA21:BL21)
B22: Tax | C22: EUR | E22: =-IF(E21>0,MAX(0,E21-0)*Assumptions!$D$9,0) | F22: =-IF(F21>0,MAX(0,F21-E64)*Assumptions!$D$9,0) | G22: =-IF(G21>0,MAX(0,G21-F64)*Assumptions!$D$9,0) | H22: =-IF(H21>0,MAX(0,H21-G64)*Assumptions!$D$9,0) | I22: =-IF(I21>0,MAX(0,I21-H64)*Assumptions!$D$9,0) | J22: =-IF(J21>0,MAX(0,J21-I64)*Assumptions!$D$9,0) | K22: =-IF(K21>0,MAX(0,K21-J64)*Assumptions!$D$9,0) | L22: =-IF(L21>0,MAX(0,L21-K64)*Assumptions!$D$9,0) | M22: =-IF(M21>0,MAX(0,M21-L64)*Assumptions!$D$9,0) | ... BL22: =-IF(BL21>0,MAX(0,BL21-BK64)*Assumptions!$D$9,0) | BN22: =SUM(E22:P22) | BO22: =SUM(Q22:AB22) | BP22: =SUM(AC22:AN22) | BQ22: =SUM(AO22:AZ22) | BR22: =SUM(BA22:BL22) | BT22: losses are carried forward and absorb profit before any tax is paid
B23: Net income | C23: EUR | E23: =E21+E22 | F23: =F21+F22 | G23: =G21+G22 | H23: =H21+H22 | I23: =I21+I22 | J23: =J21+J22 | K23: =K21+K22 | L23: =L21+L22 | ... BL23: =BL21+BL22 | BN23: =SUM(E23:P23) | BO23: =SUM(Q23:AB23) | BP23: =SUM(AC23:AN23) | BQ23: =SUM(AO23:AZ23) | BR23: =SUM(BA23:BL23)
B24: Net margin | C24: % | E24: =IFERROR(E23/E6,0) | F24: =IFERROR(F23/F6,0) | G24: =IFERROR(G23/G6,0) | H24: =IFERROR(H23/H6,0) | I24: =IFERROR(I23/I6,0) | J24: =IFERROR(J23/J6,0) | K24: =IFERROR(K23/K6,0) | L24: =IFERROR(L23/L6,0) | ... BL24: =IFERROR(BL23/BL6,0) | BN24: =IFERROR(BN23/BN6,0) | BO24: =IFERROR(BO23/BO6,0) | BP24: =IFERROR(BP23/BP6,0) | BQ24: =IFERROR(BQ23/BQ6,0) | BR24: =IFERROR(BR23/BR6,0)
B26: CASH FLOW
B27: Net income | C27: EUR | E27: =E23 | F27: =F23 | G27: =G23 | H27: =H23 | I27: =I23 | J27: =J23 | K27: =K23 | L27: =L23 | ... BL27: =BL23 | BN27: =SUM(E27:P27) | BO27: =SUM(Q27:AB27) | BP27: =SUM(AC27:AN27) | BQ27: =SUM(AO27:AZ27) | BR27: =SUM(BA27:BL27)
B28: Depreciation added back | C28: EUR | E28: =-E19 | F28: =-F19 | G28: =-G19 | H28: =-H19 | I28: =-I19 | J28: =-J19 | K28: =-K19 | L28: =-L19 | ... BL28: =-BL19 | BN28: =SUM(E28:P28) | BO28: =SUM(Q28:AB28) | BP28: =SUM(AC28:AN28) | BQ28: =SUM(AO28:AZ28) | BR28: =SUM(BA28:BL28)
B29: Movement in receivables | C29: EUR | E29: =-(E44-0) | F29: =-(F44-E44) | G29: =-(G44-F44) | H29: =-(H44-G44) | I29: =-(I44-H44) | J29: =-(J44-I44) | K29: =-(K44-J44) | L29: =-(L44-K44) | M29: =-(M44-L44) | ... BL29: =-(BL44-BK44) | BN29: =SUM(E29:P29) | BO29: =SUM(Q29:AB29) | BP29: =SUM(AC29:AN29) | BQ29: =SUM(AO29:AZ29) | BR29: =SUM(BA29:BL29)
B30: Movement in inventory | C30: EUR | E30: =-(E45-0) | F30: =-(F45-E45) | G30: =-(G45-F45) | H30: =-(H45-G45) | I30: =-(I45-H45) | J30: =-(J45-I45) | K30: =-(K45-J45) | L30: =-(L45-K45) | M30: =-(M45-L45) | ... BL30: =-(BL45-BK45) | BN30: =SUM(E30:P30) | BO30: =SUM(Q30:AB30) | BP30: =SUM(AC30:AN30) | BQ30: =SUM(AO30:AZ30) | BR30: =SUM(BA30:BL30)
B31: Movement in payables | C31: EUR | E31: =E50-0 | F31: =F50-E50 | G31: =G50-F50 | H31: =H50-G50 | I31: =I50-H50 | J31: =J50-I50 | K31: =K50-J50 | L31: =L50-K50 | M31: =M50-L50 | ... BL31: =BL50-BK50 | BN31: =SUM(E31:P31) | BO31: =SUM(Q31:AB31) | BP31: =SUM(AC31:AN31) | BQ31: =SUM(AO31:AZ31) | BR31: =SUM(BA31:BL31)
B32: Cash from operations | C32: EUR | E32: =SUM(E27:E31) | F32: =SUM(F27:F31) | G32: =SUM(G27:G31) | H32: =SUM(H27:H31) | I32: =SUM(I27:I31) | J32: =SUM(J27:J31) | K32: =SUM(K27:K31) | L32: =SUM(L27:L31) | ... BL32: =SUM(BL27:BL31) | BN32: =SUM(E32:P32) | BO32: =SUM(Q32:AB32) | BP32: =SUM(AC32:AN32) | BQ32: =SUM(AO32:AZ32) | BR32: =SUM(BA32:BL32)
B33: Capital expenditure | C33: EUR | E33: =-E61 | F33: =-F61 | G33: =-G61 | H33: =-H61 | I33: =-I61 | J33: =-J61 | K33: =-K61 | L33: =-L61 | ... BL33: =-BL61 | BN33: =SUM(E33:P33) | BO33: =SUM(Q33:AB33) | BP33: =SUM(AC33:AN33) | BQ33: =SUM(AO33:AZ33) | BR33: =SUM(BA33:BL33)
B34: Cash from investing | C34: EUR | E34: =E33 | F34: =F33 | G34: =G33 | H34: =H33 | I34: =I33 | J34: =J33 | K34: =K33 | L34: =L33 | ... BL34: =BL33 | BN34: =SUM(E34:P34) | BO34: =SUM(Q34:AB34) | BP34: =SUM(AC34:AN34) | BQ34: =SUM(AO34:AZ34) | BR34: =SUM(BA34:BL34)
B35: Equity raised | C35: EUR | E35: =IF(AND(YEAR(E$3)=YEAR(Assumptions!$D$114),MONTH(E$3)=MONTH(Assumptions!$D$114)),Assumptions!$D$115,0)+IF(AND(YEAR(E$3)=YEAR(Assumptions!$D$116),MONTH(E$3)=MONTH(Assumptions!$D$116)),Assumptions!$D$117,0) | F35: =IF(AND(YEAR(F$3)=YEAR(Assumptions!$D$114),MONTH(F$3)=MONTH(Assumptions!$D$114)),Assumptions!$D$115,0)+IF(AND(YEAR(F$3)=YEAR(Assumptions!$D$116),MONTH(F$3)=MONTH(Assumptions!$D$116)),Assumptions!$D$117,0) | G35: =IF(AND(YEAR(G$3)=YEAR(Assumptions!$D$114),MONTH(G$3)=MONTH(Assumptions!$D$114)),Assumptions!$D$115,0)+IF(AND(YEAR(G$3)=YEAR(Assumptions!$D$116),MONTH(G$3)=MONTH(Assumptions!$D$116)),Assumptions!$D$117,0) | H35: =IF(AND(YEAR(H$3)=YEAR(Assumptions!$D$114),MONTH(H$3)=MONTH(Assumptions!$D$114)),Assumptions!$D$115,0)+IF(AND(YEAR(H$3)=YEAR(Assumptions!$D$116),MONTH(H$3)=MONTH(Assumptions!$D$116)),Assumptions!$D$117,0) | I35: =IF(AND(YEAR(I$3)=YEAR(Assumptions!$D$114),MONTH(I$3)=MONTH(Assumptions!$D$114)),Assumptions!$D$115,0)+IF(AND(YEAR(I$3)=YEAR(Assumptions!$D$116),MONTH(I$3)=MONTH(Assumptions!$D$116)),Assumptions!$D$117,0) | J35: =IF(AND(YEAR(J$3)=YEAR(Assumptions!$D$114),MONTH(J$3)=MONTH(Assumptions!$D$114)),Assumptions!$D$115,0)+IF(AND(YEAR(J$3)=YEAR(Assumptions!$D$116),MONTH(J$3)=MONTH(Assumptions!$D$116)),Assumptions!$D$117,0) | K35: =IF(AND(YEAR(K$3)=YEAR(Assumptions!$D$114),MONTH(K$3)=MONTH(Assumptions!$D$114)),Assumptions!$D$115,0)+IF(AND(YEAR(K$3)=YEAR(Assumptions!$D$116),MONTH(K$3)=MONTH(Assumptions!$D$116)),Assumptions!$D$117,0) | L35: =IF(AND(YEAR(L$3)=YEAR(Assumptions!$D$114),MONTH(L$3)=MONTH(Assumptions!$D$114)),Assumptions!$D$115,0)+IF(AND(YEAR(L$3)=YEAR(Assumptions!$D$116),MONTH(L$3)=MONTH(Assumptions!$D$116)),Assumptions!$D$117,0) | ... BL35: =IF(AND(YEAR(BL$3)=YEAR(Assumptions!$D$114),MONTH(BL$3)=MONTH(Assumptions!$D$114)),Assumptions!$D$115,0)+IF(AND(YEAR(BL$3)=YEAR(Assumptions!$D$116),MONTH(BL$3)=MONTH(Assumptions!$D$116)),Assumptions!$D$117,0) | BN35: =SUM(E35:P35) | BO35: =SUM(Q35:AB35) | BP35: =SUM(AC35:AN35) | BQ35: =SUM(AO35:AZ35) | BR35: =SUM(BA35:BL35) | BT35: dates and amounts are on the Assumptions funding block; any day in the month counts
B36: Loan drawn | C36: EUR | E36: =IF(AND(YEAR(E$3)=YEAR(Assumptions!$D$119),MONTH(E$3)=MONTH(Assumptions!$D$119)),Assumptions!$D$118,0) | F36: =IF(AND(YEAR(F$3)=YEAR(Assumptions!$D$119),MONTH(F$3)=MONTH(Assumptions!$D$119)),Assumptions!$D$118,0) | G36: =IF(AND(YEAR(G$3)=YEAR(Assumptions!$D$119),MONTH(G$3)=MONTH(Assumptions!$D$119)),Assumptions!$D$118,0) | H36: =IF(AND(YEAR(H$3)=YEAR(Assumptions!$D$119),MONTH(H$3)=MONTH(Assumptions!$D$119)),Assumptions!$D$118,0) | I36: =IF(AND(YEAR(I$3)=YEAR(Assumptions!$D$119),MONTH(I$3)=MONTH(Assumptions!$D$119)),Assumptions!$D$118,0) | J36: =IF(AND(YEAR(J$3)=YEAR(Assumptions!$D$119),MONTH(J$3)=MONTH(Assumptions!$D$119)),Assumptions!$D$118,0) | K36: =IF(AND(YEAR(K$3)=YEAR(Assumptions!$D$119),MONTH(K$3)=MONTH(Assumptions!$D$119)),Assumptions!$D$118,0) | L36: =IF(AND(YEAR(L$3)=YEAR(Assumptions!$D$119),MONTH(L$3)=MONTH(Assumptions!$D$119)),Assumptions!$D$118,0) | ... BL36: =IF(AND(YEAR(BL$3)=YEAR(Assumptions!$D$119),MONTH(BL$3)=MONTH(Assumptions!$D$119)),Assumptions!$D$118,0) | BN36: =SUM(E36:P36) | BO36: =SUM(Q36:AB36) | BP36: =SUM(AC36:AN36) | BQ36: =SUM(AO36:AZ36) | BR36: =SUM(BA36:BL36)
B37: Cash from financing | C37: EUR | E37: =E35+E36 | F37: =F35+F36 | G37: =G35+G36 | H37: =H35+H36 | I37: =I35+I36 | J37: =J35+J36 | K37: =K35+K36 | L37: =L35+L36 | ... BL37: =BL35+BL36 | BN37: =SUM(E37:P37) | BO37: =SUM(Q37:AB37) | BP37: =SUM(AC37:AN37) | BQ37: =SUM(AO37:AZ37) | BR37: =SUM(BA37:BL37)
B38: Movement in cash | C38: EUR | E38: =E32+E34+E37 | F38: =F32+F34+F37 | G38: =G32+G34+G37 | H38: =H32+H34+H37 | I38: =I32+I34+I37 | J38: =J32+J34+J37 | K38: =K32+K34+K37 | L38: =L32+L34+L37 | ... BL38: =BL32+BL34+BL37 | BN38: =SUM(E38:P38) | BO38: =SUM(Q38:AB38) | BP38: =SUM(AC38:AN38) | BQ38: =SUM(AO38:AZ38) | BR38: =SUM(BA38:BL38)
B39: Cash at the start of the month | C39: EUR | E39: =Assumptions!$D$6 | F39: =E40 | G39: =F40 | H39: =G40 | I39: =H40 | J39: =I40 | K39: =J40 | L39: =K40 | M39: =L40 | ... BL39: =BK40 | BN39: =E39 | BO39: =Q39 | BP39: =AC39 | BQ39: =AO39 | BR39: =BA39
B40: Cash at the end of the month | C40: EUR | E40: =E39+E38 | F40: =F39+F38 | G40: =G39+G38 | H40: =H39+H38 | I40: =I39+I38 | J40: =J39+J38 | K40: =K39+K38 | L40: =L39+L38 | ... BL40: =BL39+BL38 | BN40: =P40 | BO40: =AB40 | BP40: =AN40 | BQ40: =AZ40 | BR40: =BL40
B42: BALANCE SHEET
B43: Cash | C43: EUR | E43: =E40 | F43: =F40 | G43: =G40 | H43: =H40 | I43: =I40 | J43: =J40 | K43: =K40 | L43: =L40 | ... BL43: =BL40 | BN43: =P43 | BO43: =AB43 | BP43: =AN43 | BQ43: =AZ43 | BR43: =BL43
B44: Receivables | C44: EUR | E44: =Assumptions!$D$16/30*(E6-'Revenue Forecast'!E49) | F44: =Assumptions!$D$16/30*(F6-'Revenue Forecast'!F49) | G44: =Assumptions!$D$16/30*(G6-'Revenue Forecast'!G49) | H44: =Assumptions!$D$16/30*(H6-'Revenue Forecast'!H49) | I44: =Assumptions!$D$16/30*(I6-'Revenue Forecast'!I49) | J44: =Assumptions!$D$16/30*(J6-'Revenue Forecast'!J49) | K44: =Assumptions!$D$16/30*(K6-'Revenue Forecast'!K49) | L44: =Assumptions!$D$16/30*(L6-'Revenue Forecast'!L49) | ... BL44: =Assumptions!$D$16/30*(BL6-'Revenue Forecast'!BL49) | BN44: =P44 | BO44: =AB44 | BP44: =AN44 | BQ44: =AZ44 | BR44: =BL44 | BT44: on trading revenue only; the subsidy is a cash receipt, not an invoice
B45: Inventory | C45: EUR | E45: =Assumptions!$D$18/30*-E7 | F45: =Assumptions!$D$18/30*-F7 | G45: =Assumptions!$D$18/30*-G7 | H45: =Assumptions!$D$18/30*-H7 | I45: =Assumptions!$D$18/30*-I7 | J45: =Assumptions!$D$18/30*-J7 | K45: =Assumptions!$D$18/30*-K7 | L45: =Assumptions!$D$18/30*-L7 | ... BL45: =Assumptions!$D$18/30*-BL7 | BN45: =P45 | BO45: =AB45 | BP45: =AN45 | BQ45: =AZ45 | BR45: =BL45
B46: Total current assets | C46: EUR | E46: =SUM(E43:E45) | F46: =SUM(F43:F45) | G46: =SUM(G43:G45) | H46: =SUM(H43:H45) | I46: =SUM(I43:I45) | J46: =SUM(J43:J45) | K46: =SUM(K43:K45) | L46: =SUM(L43:L45) | ... BL46: =SUM(BL43:BL45) | BN46: =P46 | BO46: =AB46 | BP46: =AN46 | BQ46: =AZ46 | BR46: =BL46
...

Sheet Revenue Forecast
B1: Tarnoc B.V. Revenue Forecast
B2: Units sold is an output: marketing spend generates orders, and selling and build capacity cap them.
E3: 46023 | F3: 46054 | G3: 46082 | H3: 46113 | I3: 46143 | J3: 46174 | K3: 46204 | L3: 46235 | M3: 46266 | N3: 46296 | O3: 46327 | P3: 46357 | Q3: 46388 | R3: 46419 | S3: 46447 | T3: 46478 | U3: 46508 | V3: 46539 | W3: 46569 | X3: 46600 | Y3: 46631 | Z3: 46661 | AA3: 46692 | AB3: 46722 | AC3: 46753 | AD3: 46784 | AE3: 46813 | AF3: 46844 | AG3: 46874 | AH3: 46905 | AI3: 46935 | AJ3: 46966 | AK3: 46997 | AL3: 47027 | AM3: 47058 | AN3: 47088 | AO3: 47119 | AP3: 47150 | AQ3: 47178 | AR3: 47209 | AS3: 47239 | AT3: 47270 | AU3: 47300 | AV3: 47331 | AW3: 47362 | AX3: 47392 | AY3: 47423 | AZ3: 47453 | BA3: 47484 | BB3: 47515 | BC3: 47543 | BD3: 47574 | BE3: 47604 | BF3: 47635 | BG3: 47665 | BH3: 47696 | BI3: 47727 | BJ3: 47757 | BK3: 47788 | BL3: 47818 | BN3: 2026 | BO3: 2027 | BP3: 2028 | BQ3: 2029 | BR3: 2030 | BT3: what this row does
B5: DEMAND
B6: Marketing spend | C6: EUR/mo | E6: =IF(E$3<Assumptions!$D$11,0,HLOOKUP(YEAR(E$3),Assumptions!$D$44:$H$45,2,FALSE)) | F6: =IF(F$3<Assumptions!$D$11,0,HLOOKUP(YEAR(F$3),Assumptions!$D$44:$H$45,2,FALSE)) | G6: =IF(G$3<Assumptions!$D$11,0,HLOOKUP(YEAR(G$3),Assumptions!$D$44:$H$45,2,FALSE)) | H6: =IF(H$3<Assumptions!$D$11,0,HLOOKUP(YEAR(H$3),Assumptions!$D$44:$H$45,2,FALSE)) | I6: =IF(I$3<Assumptions!$D$11,0,HLOOKUP(YEAR(I$3),Assumptions!$D$44:$H$45,2,FALSE)) | J6: =IF(J$3<Assumptions!$D$11,0,HLOOKUP(YEAR(J$3),Assumptions!$D$44:$H$45,2,FALSE)) | K6: =IF(K$3<Assumptions!$D$11,0,HLOOKUP(YEAR(K$3),Assumptions!$D$44:$H$45,2,FALSE)) | L6: =IF(L$3<Assumptions!$D$11,0,HLOOKUP(YEAR(L$3),Assumptions!$D$44:$H$45,2,FALSE)) | ... BL6: =IF(BL$3<Assumptions!$D$11,0,HLOOKUP(YEAR(BL$3),Assumptions!$D$44:$H$45,2,FALSE)) | BN6: =SUM(E6:P6) | BO6: =SUM(Q6:AB6) | BP6: =SUM(AC6:AN6) | BQ6: =SUM(AO6:AZ6) | BR6: =SUM(BA6:BL6) | BT6: from the Assumptions year table
B7: Installed base at start of month | C7: units | E7: =0 | F7: =E41 | G7: =F41 | H7: =G41 | I7: =H41 | J7: =I41 | K7: =J41 | L7: =K41 | M7: =L41 | ... BL7: =BK41 | BN7: =P7 | BO7: =AB7 | BP7: =AN7 | BQ7: =AZ7 | BR7: =BL7
B8: Cost per lead | C8: EUR | E8: =Assumptions!$D$47 | F8: =Assumptions!$D$47 | G8: =Assumptions!$D$47 | H8: =Assumptions!$D$47 | I8: =Assumptions!$D$47 | J8: =Assumptions!$D$47 | K8: =Assumptions!$D$47 | L8: =Assumptions!$D$47 | ... BL8: =Assumptions!$D$47 | BN8: =IFERROR(AVERAGE(E8:P8),0) | BO8: =IFERROR(AVERAGE(Q8:AB8),0) | BP8: =IFERROR(AVERAGE(AC8:AN8),0) | BQ8: =IFERROR(AVERAGE(AO8:AZ8),0) | BR8: =IFERROR(AVERAGE(BA8:BL8),0) | BT8: held flat: marketing per unit only falls as installers bring in more of the orders
B9: Qualified leads | C9: leads | E9: =IFERROR(E6/E8,0)*Assumptions!$D$48 | F9: =IFERROR(F6/F8,0)*Assumptions!$D$48 | G9: =IFERROR(G6/G8,0)*Assumptions!$D$48 | H9: =IFERROR(H6/H8,0)*Assumptions!$D$48 | I9: =IFERROR(I6/I8,0)*Assumptions!$D$48 | J9: =IFERROR(J6/J8,0)*Assumptions!$D$48 | K9: =IFERROR(K6/K8,0)*Assumptions!$D$48 | L9: =IFERROR(L6/L8,0)*Assumptions!$D$48 | ... BL9: =IFERROR(BL6/BL8,0)*Assumptions!$D$48 | BN9: =SUM(E9:P9) | BO9: =SUM(Q9:AB9) | BP9: =SUM(AC9:AN9) | BQ9: =SUM(AO9:AZ9) | BR9: =SUM(BA9:BL9) | BT9: marketing spend divided by cost per lead, then the lead to qualified rate
B10: Orders the funnel generates | C10: units | E10: =E9*Assumptions!$D$49 | F10: =F9*Assumptions!$D$49 | G10: =G9*Assumptions!$D$49 | H10: =H9*Assumptions!$D$49 | I10: =I9*Assumptions!$D$49 | J10: =J9*Assumptions!$D$49 | K10: =K9*Assumptions!$D$49 | L10: =L9*Assumptions!$D$49 | ... BL10: =BL9*Assumptions!$D$49 | BN10: =SUM(E10:P10) | BO10: =SUM(Q10:AB10) | BP10: =SUM(AC10:AN10) | BQ10: =SUM(AO10:AZ10) | BR10: =SUM(BA10:BL10)
B11: Orders installer partners bring in | C11: units | E11: =E20*HLOOKUP(YEAR(E$3),Assumptions!$D$57:$H$58,2,FALSE) | F11: =F20*HLOOKUP(YEAR(F$3),Assumptions!$D$57:$H$58,2,FALSE) | G11: =G20*HLOOKUP(YEAR(G$3),Assumptions!$D$57:$H$58,2,FALSE) | H11: =H20*HLOOKUP(YEAR(H$3),Assumptions!$D$57:$H$58,2,FALSE) | I11: =I20*HLOOKUP(YEAR(I$3),Assumptions!$D$57:$H$58,2,FALSE) | J11: =J20*HLOOKUP(YEAR(J$3),Assumptions!$D$57:$H$58,2,FALSE) | K11: =K20*HLOOKUP(YEAR(K$3),Assumptions!$D$57:$H$58,2,FALSE) | L11: =L20*HLOOKUP(YEAR(L$3),Assumptions!$D$57:$H$58,2,FALSE) | ... BL11: =BL20*HLOOKUP(YEAR(BL$3),Assumptions!$D$57:$H$58,2,FALSE) | BN11: =SUM(E11:P11) | BO11: =SUM(Q11:AB11) | BP11: =SUM(AC11:AN11) | BQ11: =SUM(AO11:AZ11) | BR11: =SUM(BA11:BL11) | BT11: partners on the books times the orders each finds on their own jobs
B12: Demand | C12: units | E12: =E10+E11 | F12: =F10+F11 | G12: =G10+G11 | H12: =H10+H11 | I12: =I10+I11 | J12: =J10+J11 | K12: =K10+K11 | L12: =L10+L11 | ... BL12: =BL10+BL11 | BN12: =SUM(E12:P12) | BO12: =SUM(Q12:AB12) | BP12: =SUM(AC12:AN12) | BQ12: =SUM(AO12:AZ12) | BR12: =SUM(BA12:BL12)
B14: SELLING CAPACITY
B15: Share sold direct | C15: % | E15: =HLOOKUP(YEAR(E$3),Assumptions!$D$51:$H$52,2,FALSE) | F15: =HLOOKUP(YEAR(F$3),Assumptions!$D$51:$H$52,2,FALSE) | G15: =HLOOKUP(YEAR(G$3),Assumptions!$D$51:$H$52,2,FALSE) | H15: =HLOOKUP(YEAR(H$3),Assumptions!$D$51:$H$52,2,FALSE) | I15: =HLOOKUP(YEAR(I$3),Assumptions!$D$51:$H$52,2,FALSE) | J15: =HLOOKUP(YEAR(J$3),Assumptions!$D$51:$H$52,2,FALSE) | K15: =HLOOKUP(YEAR(K$3),Assumptions!$D$51:$H$52,2,FALSE) | L15: =HLOOKUP(YEAR(L$3),Assumptions!$D$51:$H$52,2,FALSE) | ... BL15: =HLOOKUP(YEAR(BL$3),Assumptions!$D$51:$H$52,2,FALSE) | BN15: =IFERROR(AVERAGE(E15:P15),0) | BO15: =IFERROR(AVERAGE(Q15:AB15),0) | BP15: =IFERROR(AVERAGE(AC15:AN15),0) | BQ15: =IFERROR(AVERAGE(AO15:AZ15),0) | BR15: =IFERROR(AVERAGE(BA15:BL15),0) | BT15: the rest is sold by trained installer partners
B16: Rep hiring rate | C16: FTE/month | E16: =IF(E$3<Assumptions!$D$11,0,HLOOKUP(YEAR(E$3),Assumptions!$D$53:$H$54,2,FALSE)) | F16: =IF(F$3<Assumptions!$D$11,0,HLOOKUP(YEAR(F$3),Assumptions!$D$53:$H$54,2,FALSE)) | G16: =IF(G$3<Assumptions!$D$11,0,HLOOKUP(YEAR(G$3),Assumptions!$D$53:$H$54,2,FALSE)) | H16: =IF(H$3<Assumptions!$D$11,0,HLOOKUP(YEAR(H$3),Assumptions!$D$53:$H$54,2,FALSE)) | I16: =IF(I$3<Assumptions!$D$11,0,HLOOKUP(YEAR(I$3),Assumptions!$D$53:$H$54,2,FALSE)) | J16: =IF(J$3<Assumptions!$D$11,0,HLOOKUP(YEAR(J$3),Assumptions!$D$53:$H$54,2,FALSE)) | K16: =IF(K$3<Assumptions!$D$11,0,HLOOKUP(YEAR(K$3),Assumptions!$D$53:$H$54,2,FALSE)) | L16: =IF(L$3<Assumptions!$D$11,0,HLOOKUP(YEAR(L$3),Assumptions!$D$53:$H$54,2,FALSE)) | ... BL16: =IF(BL$3<Assumptions!$D$11,0,HLOOKUP(YEAR(BL$3),Assumptions!$D$53:$H$54,2,FALSE)) | BN16: =SUM(E16:P16) | BO16: =SUM(Q16:AB16) | BP16: =SUM(AC16:AN16) | BQ16: =SUM(AO16:AZ16) | BR16: =SUM(BA16:BL16) | BT16: the planned rate, which can be less than one a month
B17: Reps in post | C17: FTE | E17: =ROUNDDOWN(Assumptions!$D$60+SUM($E16:E16),0) | F17: =ROUNDDOWN(Assumptions!$D$60+SUM($E16:F16),0) | G17: =ROUNDDOWN(Assumptions!$D$60+SUM($E16:G16),0) | H17: =ROUNDDOWN(Assumptions!$D$60+SUM($E16:H16),0) | I17: =ROUNDDOWN(Assumptions!$D$60+SUM($E16:I16),0) | J17: =ROUNDDOWN(Assumptions!$D$60+SUM($E16:J16),0) | K17: =ROUNDDOWN(Assumptions!$D$60+SUM($E16:K16),0) | L17: =ROUNDDOWN(Assumptions!$D$60+SUM($E16:L16),0) | ... BL17: =ROUNDDOWN(Assumptions!$D$60+SUM($E16:BL16),0) | BN17: =P17 | BO17: =AB17 | BP17: =AN17 | BQ17: =AZ17 | BR17: =BL17 | BT17: whole people only, so half a rep a month means one every second month
B18: Capacity from our own reps | C18: units/mo | E18: =E17*Assumptions!$D$61 | F18: =F17*Assumptions!$D$61 | G18: =G17*Assumptions!$D$61 | H18: =H17*Assumptions!$D$61 | I18: =I17*Assumptions!$D$61 | J18: =J17*Assumptions!$D$61 | K18: =K17*Assumptions!$D$61 | L18: =L17*Assumptions!$D$61 | ... BL18: =BL17*Assumptions!$D$61 | BN18: =SUM(E18:P18) | BO18: =SUM(Q18:AB18) | BP18: =SUM(AC18:AN18) | BQ18: =SUM(AO18:AZ18) | BR18: =SUM(BA18:BL18) | BT18: every rep in post carries full quota from the month they are hired
B19: Partner signing rate | C19: partners/month | E19: =IF(E$3<Assumptions!$D$11,0,HLOOKUP(YEAR(E$3),Assumptions!$D$55:$H$56,2,FALSE)) | F19: =IF(F$3<Assumptions!$D$11,0,HLOOKUP(YEAR(F$3),Assumptions!$D$55:$H$56,2,FALSE)) | G19: =IF(G$3<Assumptions!$D$11,0,HLOOKUP(YEAR(G$3),Assumptions!$D$55:$H$56,2,FALSE)) | H19: =IF(H$3<Assumptions!$D$11,0,HLOOKUP(YEAR(H$3),Assumptions!$D$55:$H$56,2,FALSE)) | I19: =IF(I$3<Assumptions!$D$11,0,HLOOKUP(YEAR(I$3),Assumptions!$D$55:$H$56,2,FALSE)) | J19: =IF(J$3<Assumptions!$D$11,0,HLOOKUP(YEAR(J$3),Assumptions!$D$55:$H$56,2,FALSE)) | K19: =IF(K$3<Assumptions!$D$11,0,HLOOKUP(YEAR(K$3),Assumptions!$D$55:$H$56,2,FALSE)) | L19: =IF(L$3<Assumptions!$D$11,0,HLOOKUP(YEAR(L$3),Assumptions!$D$55:$H$56,2,FALSE)) | ... BL19: =IF(BL$3<Assumptions!$D$11,0,HLOOKUP(YEAR(BL$3),Assumptions!$D$55:$H$56,2,FALSE)) | BN19: =SUM(E19:P19) | BO19: =SUM(Q19:AB19) | BP19: =SUM(AC19:AN19) | BQ19: =SUM(AO19:AZ19) | BR19: =SUM(BA19:BL19) | BT19: the planned rate, which can be less than one a month
B20: Installer partners on the books | C20: partners | E20: =ROUNDDOWN(Assumptions!$D$62+SUM($E19:E19),0) | F20: =ROUNDDOWN(Assumptions!$D$62+SUM($E19:F19),0) | G20: =ROUNDDOWN(Assumptions!$D$62+SUM($E19:G19),0) | H20: =ROUNDDOWN(Assumptions!$D$62+SUM($E19:H19),0) | I20: =ROUNDDOWN(Assumptions!$D$62+SUM($E19:I19),0) | J20: =ROUNDDOWN(Assumptions!$D$62+SUM($E19:J19),0) | K20: =ROUNDDOWN(Assumptions!$D$62+SUM($E19:K19),0) | L20: =ROUNDDOWN(Assumptions!$D$62+SUM($E19:L19),0) | ... BL20: =ROUNDDOWN(Assumptions!$D$62+SUM($E19:BL19),0) | BN20: =P20 | BO20: =AB20 | BP20: =AN20 | BQ20: =AZ20 | BR20: =BL20 | BT20: whole partners only, signed as the running total passes each whole number
B21: Capacity from the installer channel | C21: units/mo | E21: =E20*Assumptions!$D$63 | F21: =F20*Assumptions!$D$63 | G21: =G20*Assumptions!$D$63 | H21: =H20*Assumptions!$D$63 | I21: =I20*Assumptions!$D$63 | J21: =J20*Assumptions!$D$63 | K21: =K20*Assumptions!$D$63 | L21: =L20*Assumptions!$D$63 | ... BL21: =BL20*Assumptions!$D$63 | BN21: =SUM(E21:P21) | BO21: =SUM(Q21:AB21) | BP21: =SUM(AC21:AN21) | BQ21: =SUM(AO21:AZ21) | BR21: =SUM(BA21:BL21) | BT21: every partner on the books sells full volume from the month they are signed
B22: Selling capacity | C22: units/mo | E22: =MIN(IFERROR(E18/E15,1000000),IFERROR(E21/(1-E15),1000000)) | F22: =MIN(IFERROR(F18/F15,1000000),IFERROR(F21/(1-F15),1000000)) | G22: =MIN(IFERROR(G18/G15,1000000),IFERROR(G21/(1-G15),1000000)) | H22: =MIN(IFERROR(H18/H15,1000000),IFERROR(H21/(1-H15),1000000)) | I22: =MIN(IFERROR(I18/I15,1000000),IFERROR(I21/(1-I15),1000000)) | J22: =MIN(IFERROR(J18/J15,1000000),IFERROR(J21/(1-J15),1000000)) | K22: =MIN(IFERROR(K18/K15,1000000),IFERROR(K21/(1-K15),1000000)) | L22: =MIN(IFERROR(L18/L15,1000000),IFERROR(L21/(1-L15),1000000)) | ... BL22: =MIN(IFERROR(BL18/BL15,1000000),IFERROR(BL21/(1-BL15),1000000)) | BN22: =SUM(E22:P22) | BO22: =SUM(Q22:AB22) | BP22: =SUM(AC22:AN22) | BQ22: =SUM(AO22:AZ22) | BR22: =SUM(BA22:BL22) | BT22: our reps must cover the direct share and the partners the rest, so the mix caps it
B23: Partner managers needed | C23: FTE | E23: =ROUND(E20/Assumptions!$D$65,0) | F23: =ROUND(F20/Assumptions!$D$65,0) | G23: =ROUND(G20/Assumptions!$D$65,0) | H23: =ROUND(H20/Assumptions!$D$65,0) | I23: =ROUND(I20/Assumptions!$D$65,0) | J23: =ROUND(J20/Assumptions!$D$65,0) | K23: =ROUND(K20/Assumptions!$D$65,0) | L23: =ROUND(L20/Assumptions!$D$65,0) | ... BL23: =ROUND(BL20/Assumptions!$D$65,0) | BN23: =P23 | BO23: =AB23 | BP23: =AN23 | BQ23: =AZ23 | BR23: =BL23
B24: Selling capacity used | C24: % | E24: =IFERROR(E34/E22,0) | F24: =IFERROR(F34/F22,0) | G24: =IFERROR(G34/G22,0) | H24: =IFERROR(H34/H22,0) | I24: =IFERROR(I34/I22,0) | J24: =IFERROR(J34/J22,0) | K24: =IFERROR(K34/K22,0) | L24: =IFERROR(L34/L22,0) | ... BL24: =IFERROR(BL34/BL22,0) | BN24: =IFERROR(BN34/BN22,0) | BO24: =IFERROR(BO34/BO22,0) | BP24: =IFERROR(BP34/BP22,0) | BQ24: =IFERROR(BQ34/BQ22,0) | BR24: =IFERROR(BR34/BR22,0)
B27: BUILD CAPACITY
B28: Assembly partner | C28: units/mo | E28: =Assumptions!$D$68 | F28: =Assumptions!$D$68 | G28: =Assumptions!$D$68 | H28: =Assumptions!$D$68 | I28: =Assumptions!$D$68 | J28: =Assumptions!$D$68 | K28: =Assumptions!$D$68 | L28: =Assumptions!$D$68 | ... BL28: =Assumptions!$D$68 | BN28: =SUM(E28:P28) | BO28: =SUM(Q28:AB28) | BP28: =SUM(AC28:AN28) | BQ28: =SUM(AO28:AZ28) | BR28: =SUM(BA28:BL28) | BT28: the partner builds every unit in this case
B31: Build capacity | C31: units/mo | E31: =E28 | F31: =F28 | G31: =G28 | H31: =H28 | I31: =I28 | J31: =J28 | K31: =K28 | L31: =L28 | ... BL31: =BL28 | BN31: =SUM(E31:P31) | BO31: =SUM(Q31:AB31) | BP31: =SUM(AC31:AN31) | BQ31: =SUM(AO31:AZ31) | BR31: =SUM(BA31:BL31)
B33: UNITS SOLD
B34: Units sold | C34: units | E34: =IF(E$3<Assumptions!$D$11,0,ROUND(MIN(E12,E22,E31),0)) | F34: =IF(F$3<Assumptions!$D$11,0,ROUND(MIN(F12,F22,F31),0)) | G34: =IF(G$3<Assumptions!$D$11,0,ROUND(MIN(G12,G22,G31),0)) | H34: =IF(H$3<Assumptions!$D$11,0,ROUND(MIN(H12,H22,H31),0)) | I34: =IF(I$3<Assumptions!$D$11,0,ROUND(MIN(I12,I22,I31),0)) | J34: =IF(J$3<Assumptions!$D$11,0,ROUND(MIN(J12,J22,J31),0)) | K34: =IF(K$3<Assumptions!$D$11,0,ROUND(MIN(K12,K22,K31),0)) | L34: =IF(L$3<Assumptions!$D$11,0,ROUND(MIN(L12,L22,L31),0)) | ... BL34: =IF(BL$3<Assumptions!$D$11,0,ROUND(MIN(BL12,BL22,BL31),0)) | BN34: =SUM(E34:P34) | BO34: =SUM(Q34:AB34) | BP34: =SUM(AC34:AN34) | BQ34: =SUM(AO34:AZ34) | BR34: =SUM(BA34:BL34) | BT34: nil until the first month we can sell, then the smallest of demand, selling and build capacity
B35: Build capacity used | C35: % | E35: =IFERROR(E34/E31,0) | F35: =IFERROR(F34/F31,0) | G35: =IFERROR(G34/G31,0) | H35: =IFERROR(H34/H31,0) | I35: =IFERROR(I34/I31,0) | J35: =IFERROR(J34/J31,0) | K35: =IFERROR(K34/K31,0) | L35: =IFERROR(L34/L31,0) | ... BL35: =IFERROR(BL34/BL31,0) | BN35: =IFERROR(BN34/BN31,0) | BO35: =IFERROR(BO34/BO31,0) | BP35: =IFERROR(BP34/BP31,0) | BQ35: =IFERROR(BQ34/BQ31,0) | BR35: =IFERROR(BR34/BR31,0)
B38: UNIT SPLIT AND INSTALLED BASE
B39: TTK units | C39: units | E39: =ROUND(E34*Assumptions!$D$25,0) | F39: =ROUND(F34*Assumptions!$D$25,0) | G39: =ROUND(G34*Assumptions!$D$25,0) | H39: =ROUND(H34*Assumptions!$D$25,0) | I39: =ROUND(I34*Assumptions!$D$25,0) | J39: =ROUND(J34*Assumptions!$D$25,0) | K39: =ROUND(K34*Assumptions!$D$25,0) | L39: =ROUND(L34*Assumptions!$D$25,0) | ... BL39: =ROUND(BL34*Assumptions!$D$25,0) | BN39: =SUM(E39:P39) | BO39: =SUM(Q39:AB39) | BP39: =SUM(AC39:AN39) | BQ39: =SUM(AO39:AZ39) | BR39: =SUM(BA39:BL39) | BT39: whole units, and the Combi+ row takes the remainder so the two add to units sold
B40: Combi+ units | C40: units | E40: =E34-E39 | F40: =F34-F39 | G40: =G34-G39 | H40: =H34-H39 | I40: =I34-I39 | J40: =J34-J39 | K40: =K34-K39 | L40: =L34-L39 | ... BL40: =BL34-BL39 | BN40: =SUM(E40:P40) | BO40: =SUM(Q40:AB40) | BP40: =SUM(AC40:AN40) | BQ40: =SUM(AO40:AZ40) | BR40: =SUM(BA40:BL40)
B41: Installed base at end of month | C41: units | E41: =E7+E34 | F41: =F7+F34 | G41: =G7+G34 | H41: =H7+H34 | I41: =I7+I34 | J41: =J7+J34 | K41: =K7+K34 | L41: =L7+L34 | ... BL41: =BL7+BL34 | BN41: =P41 | BO41: =AB41 | BP41: =AN41 | BQ41: =AZ41 | BR41: =BL41
B43: REVENUE
B44: Turbineketel | C44: EUR | E44: =E39*Assumptions!$D$20 | F44: =F39*Assumptions!$D$20 | G44: =G39*Assumptions!$D$20 | H44: =H39*Assumptions!$D$20 | I44: =I39*Assumptions!$D$20 | J44: =J39*Assumptions!$D$20 | K44: =K39*Assumptions!$D$20 | L44: =L39*Assumptions!$D$20 | ... BL44: =BL39*Assumptions!$D$20 | BN44: =SUM(E44:P44) | BO44: =SUM(Q44:AB44) | BP44: =SUM(AC44:AN44) | BQ44: =SUM(AO44:AZ44) | BR44: =SUM(BA44:BL44)
B45: Combi+ | C45: EUR | E45: =E40*Assumptions!$D$22 | F45: =F40*Assumptions!$D$22 | G45: =G40*Assumptions!$D$22 | H45: =H40*Assumptions!$D$22 | I45: =I40*Assumptions!$D$22 | J45: =J40*Assumptions!$D$22 | K45: =K40*Assumptions!$D$22 | L45: =L40*Assumptions!$D$22 | ... BL45: =BL40*Assumptions!$D$22 | BN45: =SUM(E45:P45) | BO45: =SUM(Q45:AB45) | BP45: =SUM(AC45:AN45) | BQ45: =SUM(AO45:AZ45) | BR45: =SUM(BA45:BL45)
B46: Upsell basket | C46: EUR | E46: =E34*Assumptions!$D$32 | F46: =F34*Assumptions!$D$32 | G46: =G34*Assumptions!$D$32 | H46: =H34*Assumptions!$D$32 | I46: =I34*Assumptions!$D$32 | J46: =J34*Assumptions!$D$32 | K46: =K34*Assumptions!$D$32 | L46: =L34*Assumptions!$D$32 | ... BL46: =BL34*Assumptions!$D$32 | BN46: =SUM(E46:P46) | BO46: =SUM(Q46:AB46) | BP46: =SUM(AC46:AN46) | BQ46: =SUM(AO46:AZ46) | BR46: =SUM(BA46:BL46)
B47: Installation (pass-through) | C47: EUR | E47: =E39*Assumptions!$D$23+E40*Assumptions!$D$24 | F47: =F39*Assumptions!$D$23+F40*Assumptions!$D$24 | G47: =G39*Assumptions!$D$23+G40*Assumptions!$D$24 | H47: =H39*Assumptions!$D$23+H40*Assumptions!$D$24 | I47: =I39*Assumptions!$D$23+I40*Assumptions!$D$24 | J47: =J39*Assumptions!$D$23+J40*Assumptions!$D$24 | K47: =K39*Assumptions!$D$23+K40*Assumptions!$D$24 | L47: =L39*Assumptions!$D$23+L40*Assumptions!$D$24 | ... BL47: =BL39*Assumptions!$D$23+BL40*Assumptions!$D$24 | BN47: =SUM(E47:P47) | BO47: =SUM(Q47:AB47) | BP47: =SUM(AC47:AN47) | BQ47: =SUM(AO47:AZ47) | BR47: =SUM(BA47:BL47) | BT47: revenue equals cost, so it adds no margin
B48: Service contracts | C48: EUR | E48: =E7*Assumptions!$D$40/12 | F48: =F7*Assumptions!$D$40/12 | G48: =G7*Assumptions!$D$40/12 | H48: =H7*Assumptions!$D$40/12 | I48: =I7*Assumptions!$D$40/12 | J48: =J7*Assumptions!$D$40/12 | K48: =K7*Assumptions!$D$40/12 | L48: =L7*Assumptions!$D$40/12 | ... BL48: =BL7*Assumptions!$D$40/12 | BN48: =SUM(E48:P48) | BO48: =SUM(Q48:AB48) | BP48: =SUM(AC48:AN48) | BQ48: =SUM(AO48:AZ48) | BR48: =SUM(BA48:BL48) | BT48: charged on the installed base at the start of the month
B49: Subsidies and grants | C49: EUR | E49: =IF(AND(YEAR(E$3)=YEAR(Assumptions!$D$14),MONTH(E$3)=MONTH(Assumptions!$D$14)),Assumptions!$D$13,0) | F49: =IF(AND(YEAR(F$3)=YEAR(Assumptions!$D$14),MONTH(F$3)=MONTH(Assumptions!$D$14)),Assumptions!$D$13,0) | G49: =IF(AND(YEAR(G$3)=YEAR(Assumptions!$D$14),MONTH(G$3)=MONTH(Assumptions!$D$14)),Assumptions!$D$13,0) | H49: =IF(AND(YEAR(H$3)=YEAR(Assumptions!$D$14),MONTH(H$3)=MONTH(Assumptions!$D$14)),Assumptions!$D$13,0) | I49: =IF(AND(YEAR(I$3)=YEAR(Assumptions!$D$14),MONTH(I$3)=MONTH(Assumptions!$D$14)),Assumptions!$D$13,0) | J49: =IF(AND(YEAR(J$3)=YEAR(Assumptions!$D$14),MONTH(J$3)=MONTH(Assumptions!$D$14)),Assumptions!$D$13,0) | K49: =IF(AND(YEAR(K$3)=YEAR(Assumptions!$D$14),MONTH(K$3)=MONTH(Assumptions!$D$14)),Assumptions!$D$13,0) | L49: =IF(AND(YEAR(L$3)=YEAR(Assumptions!$D$14),MONTH(L$3)=MONTH(Assumptions!$D$14)),Assumptions!$D$13,0) | ... BL49: =IF(AND(YEAR(BL$3)=YEAR(Assumptions!$D$14),MONTH(BL$3)=MONTH(Assumptions!$D$14)),Assumptions!$D$13,0) | BN49: =SUM(E49:P49) | BO49: =SUM(Q49:AB49) | BP49: =SUM(AC49:AN49) | BQ49: =SUM(AO49:AZ49) | BR49: =SUM(BA49:BL49) | BT49: the 2026 subsidy already in the committed plan
B50: Total revenue | C50: EUR | E50: =SUM(E44:E49) | F50: =SUM(F44:F49) | G50: =SUM(G44:G49) | H50: =SUM(H44:H49) | I50: =SUM(I44:I49) | J50: =SUM(J44:J49) | K50: =SUM(K44:K49) | L50: =SUM(L44:L49) | ... BL50: =SUM(BL44:BL49) | BN50: =SUM(E50:P50) | BO50: =SUM(Q50:AB50) | BP50: =SUM(AC50:AN50) | BQ50: =SUM(AO50:AZ50) | BR50: =SUM(BA50:BL50)
...

Sheet COGS
B1: Tarnoc B.V. Cost of Goods Sold
B2: Unit cost falls as volume crosses each tier. The tier is set on this year plus next year's units, a two-year volume commitment to the supplier.
E3: 46023 | F3: 46054 | G3: 46082 | H3: 46113 | I3: 46143 | J3: 46174 | K3: 46204 | L3: 46235 | M3: 46266 | N3: 46296 | O3: 46327 | P3: 46357 | Q3: 46388 | R3: 46419 | S3: 46447 | T3: 46478 | U3: 46508 | V3: 46539 | W3: 46569 | X3: 46600 | Y3: 46631 | Z3: 46661 | AA3: 46692 | AB3: 46722 | AC3: 46753 | AD3: 46784 | AE3: 46813 | AF3: 46844 | AG3: 46874 | AH3: 46905 | AI3: 46935 | AJ3: 46966 | AK3: 46997 | AL3: 47027 | AM3: 47058 | AN3: 47088 | AO3: 47119 | AP3: 47150 | AQ3: 47178 | AR3: 47209 | AS3: 47239 | AT3: 47270 | AU3: 47300 | AV3: 47331 | AW3: 47362 | AX3: 47392 | AY3: 47423 | AZ3: 47453 | BA3: 47484 | BB3: 47515 | BC3: 47543 | BD3: 47574 | BE3: 47604 | BF3: 47635 | BG3: 47665 | BH3: 47696 | BI3: 47727 | BJ3: 47757 | BK3: 47788 | BL3: 47818 | BN3: 2026 | BO3: 2027 | BP3: 2028 | BQ3: 2029 | BR3: 2030 | BT3: what this row does
B5: VOLUME TIER
B6: Units sold this calendar year | C6: units | E6: =IFERROR(HLOOKUP(YEAR(E$3),'Revenue Forecast'!$BN$3:$BR$34,32,FALSE),0) | F6: =IFERROR(HLOOKUP(YEAR(F$3),'Revenue Forecast'!$BN$3:$BR$34,32,FALSE),0) | G6: =IFERROR(HLOOKUP(YEAR(G$3),'Revenue Forecast'!$BN$3:$BR$34,32,FALSE),0) | H6: =IFERROR(HLOOKUP(YEAR(H$3),'Revenue Forecast'!$BN$3:$BR$34,32,FALSE),0) | I6: =IFERROR(HLOOKUP(YEAR(I$3),'Revenue Forecast'!$BN$3:$BR$34,32,FALSE),0) | J6: =IFERROR(HLOOKUP(YEAR(J$3),'Revenue Forecast'!$BN$3:$BR$34,32,FALSE),0) | K6: =IFERROR(HLOOKUP(YEAR(K$3),'Revenue Forecast'!$BN$3:$BR$34,32,FALSE),0) | L6: =IFERROR(HLOOKUP(YEAR(L$3),'Revenue Forecast'!$BN$3:$BR$34,32,FALSE),0) | ... BL6: =IFERROR(HLOOKUP(YEAR(BL$3),'Revenue Forecast'!$BN$3:$BR$34,32,FALSE),0) | BN6: =P6 | BO6: =AB6 | BP6: =AN6 | BQ6: =AZ6 | BR6: =BL6
B7: Units sold next calendar year | C7: units | E7: =IFERROR(HLOOKUP(YEAR(E$3)+1,'Revenue Forecast'!$BN$3:$BR$34,32,FALSE),E6) | F7: =IFERROR(HLOOKUP(YEAR(F$3)+1,'Revenue Forecast'!$BN$3:$BR$34,32,FALSE),F6) | G7: =IFERROR(HLOOKUP(YEAR(G$3)+1,'Revenue Forecast'!$BN$3:$BR$34,32,FALSE),G6) | H7: =IFERROR(HLOOKUP(YEAR(H$3)+1,'Revenue Forecast'!$BN$3:$BR$34,32,FALSE),H6) | I7: =IFERROR(HLOOKUP(YEAR(I$3)+1,'Revenue Forecast'!$BN$3:$BR$34,32,FALSE),I6) | J7: =IFERROR(HLOOKUP(YEAR(J$3)+1,'Revenue Forecast'!$BN$3:$BR$34,32,FALSE),J6) | K7: =IFERROR(HLOOKUP(YEAR(K$3)+1,'Revenue Forecast'!$BN$3:$BR$34,32,FALSE),K6) | L7: =IFERROR(HLOOKUP(YEAR(L$3)+1,'Revenue Forecast'!$BN$3:$BR$34,32,FALSE),L6) | ... BL7: =IFERROR(HLOOKUP(YEAR(BL$3)+1,'Revenue Forecast'!$BN$3:$BR$34,32,FALSE),BL6) | BN7: =P7 | BO7: =AB7 | BP7: =AN7 | BQ7: =AZ7 | BR7: =BL7 | BT7: beyond the horizon, next year is taken as at least this year
B8: Two-year volume, sets the tier | C8: units | E8: =E6+E7 | F8: =F6+F7 | G8: =G6+G7 | H8: =H6+H7 | I8: =I6+I7 | J8: =J6+J7 | K8: =K6+K7 | L8: =L6+L7 | ... BL8: =BL6+BL7 | BN8: =P8 | BO8: =AB8 | BP8: =AN8 | BQ8: =AZ8 | BR8: =BL8 | BT8: the supplier prices on a two-year volume commitment: this year plus next
B9: Turbineketel cost per unit | C9: EUR/unit | E9: =VLOOKUP(E8,Assumptions!$D$71:$E$73,2,TRUE) | F9: =VLOOKUP(F8,Assumptions!$D$71:$E$73,2,TRUE) | G9: =VLOOKUP(G8,Assumptions!$D$71:$E$73,2,TRUE) | H9: =VLOOKUP(H8,Assumptions!$D$71:$E$73,2,TRUE) | I9: =VLOOKUP(I8,Assumptions!$D$71:$E$73,2,TRUE) | J9: =VLOOKUP(J8,Assumptions!$D$71:$E$73,2,TRUE) | K9: =VLOOKUP(K8,Assumptions!$D$71:$E$73,2,TRUE) | L9: =VLOOKUP(L8,Assumptions!$D$71:$E$73,2,TRUE) | ... BL9: =VLOOKUP(BL8,Assumptions!$D$71:$E$73,2,TRUE) | BN9: =IFERROR(AVERAGE(E9:P9),0) | BO9: =IFERROR(AVERAGE(Q9:AB9),0) | BP9: =IFERROR(AVERAGE(AC9:AN9),0) | BQ9: =IFERROR(AVERAGE(AO9:AZ9),0) | BR9: =IFERROR(AVERAGE(BA9:BL9),0) | BT9: EUR9,984 below 5,000 units, EUR7,069 from 5,000, EUR4,998 from 10,000
B10: Outdoor unit cost per unit | C10: EUR/unit | E10: =VLOOKUP(E8,Assumptions!$D$71:$F$73,3,TRUE) | F10: =VLOOKUP(F8,Assumptions!$D$71:$F$73,3,TRUE) | G10: =VLOOKUP(G8,Assumptions!$D$71:$F$73,3,TRUE) | H10: =VLOOKUP(H8,Assumptions!$D$71:$F$73,3,TRUE) | I10: =VLOOKUP(I8,Assumptions!$D$71:$F$73,3,TRUE) | J10: =VLOOKUP(J8,Assumptions!$D$71:$F$73,3,TRUE) | K10: =VLOOKUP(K8,Assumptions!$D$71:$F$73,3,TRUE) | L10: =VLOOKUP(L8,Assumptions!$D$71:$F$73,3,TRUE) | ... BL10: =VLOOKUP(BL8,Assumptions!$D$71:$F$73,3,TRUE) | BN10: =IFERROR(AVERAGE(E10:P10),0) | BO10: =IFERROR(AVERAGE(Q10:AB10),0) | BP10: =IFERROR(AVERAGE(AC10:AN10),0) | BQ10: =IFERROR(AVERAGE(AO10:AZ10),0) | BR10: =IFERROR(AVERAGE(BA10:BL10),0)
B12: COST OF GOODS SOLD
B13: Turbineketel | C13: EUR | E13: ='Revenue Forecast'!E39*E9 | F13: ='Revenue Forecast'!F39*F9 | G13: ='Revenue Forecast'!G39*G9 | H13: ='Revenue Forecast'!H39*H9 | I13: ='Revenue Forecast'!I39*I9 | J13: ='Revenue Forecast'!J39*J9 | K13: ='Revenue Forecast'!K39*K9 | L13: ='Revenue Forecast'!L39*L9 | ... BL13: ='Revenue Forecast'!BL39*BL9 | BN13: =SUM(E13:P13) | BO13: =SUM(Q13:AB13) | BP13: =SUM(AC13:AN13) | BQ13: =SUM(AO13:AZ13) | BR13: =SUM(BA13:BL13)
B14: Combi+ | C14: EUR | E14: ='Revenue Forecast'!E40*(E9+E10+Assumptions!$D$75) | F14: ='Revenue Forecast'!F40*(F9+F10+Assumptions!$D$75) | G14: ='Revenue Forecast'!G40*(G9+G10+Assumptions!$D$75) | H14: ='Revenue Forecast'!H40*(H9+H10+Assumptions!$D$75) | I14: ='Revenue Forecast'!I40*(I9+I10+Assumptions!$D$75) | J14: ='Revenue Forecast'!J40*(J9+J10+Assumptions!$D$75) | K14: ='Revenue Forecast'!K40*(K9+K10+Assumptions!$D$75) | L14: ='Revenue Forecast'!L40*(L9+L10+Assumptions!$D$75) | ... BL14: ='Revenue Forecast'!BL40*(BL9+BL10+Assumptions!$D$75) | BN14: =SUM(E14:P14) | BO14: =SUM(Q14:AB14) | BP14: =SUM(AC14:AN14) | BQ14: =SUM(AO14:AZ14) | BR14: =SUM(BA14:BL14) | BT14: ketel plus outdoor unit plus inbound shipping
B15: Upsell basket | C15: EUR | E15: ='Revenue Forecast'!E34*Assumptions!$D$33 | F15: ='Revenue Forecast'!F34*Assumptions!$D$33 | G15: ='Revenue Forecast'!G34*Assumptions!$D$33 | H15: ='Revenue Forecast'!H34*Assumptions!$D$33 | I15: ='Revenue Forecast'!I34*Assumptions!$D$33 | J15: ='Revenue Forecast'!J34*Assumptions!$D$33 | K15: ='Revenue Forecast'!K34*Assumptions!$D$33 | L15: ='Revenue Forecast'!L34*Assumptions!$D$33 | ... BL15: ='Revenue Forecast'!BL34*Assumptions!$D$33 | BN15: =SUM(E15:P15) | BO15: =SUM(Q15:AB15) | BP15: =SUM(AC15:AN15) | BQ15: =SUM(AO15:AZ15) | BR15: =SUM(BA15:BL15)
B16: Installation (pass-through) | C16: EUR | E16: ='Revenue Forecast'!E47 | F16: ='Revenue Forecast'!F47 | G16: ='Revenue Forecast'!G47 | H16: ='Revenue Forecast'!H47 | I16: ='Revenue Forecast'!I47 | J16: ='Revenue Forecast'!J47 | K16: ='Revenue Forecast'!K47 | L16: ='Revenue Forecast'!L47 | ... BL16: ='Revenue Forecast'!BL47 | BN16: =SUM(E16:P16) | BO16: =SUM(Q16:AB16) | BP16: =SUM(AC16:AN16) | BQ16: =SUM(AO16:AZ16) | BR16: =SUM(BA16:BL16) | BT16: identical to the installation revenue, so it nets to nil
B17: Service delivery | C17: EUR | E17: ='Revenue Forecast'!E7*Assumptions!$D$41/12 | F17: ='Revenue Forecast'!F7*Assumptions!$D$41/12 | G17: ='Revenue Forecast'!G7*Assumptions!$D$41/12 | H17: ='Revenue Forecast'!H7*Assumptions!$D$41/12 | I17: ='Revenue Forecast'!I7*Assumptions!$D$41/12 | J17: ='Revenue Forecast'!J7*Assumptions!$D$41/12 | K17: ='Revenue Forecast'!K7*Assumptions!$D$41/12 | L17: ='Revenue Forecast'!L7*Assumptions!$D$41/12 | ... BL17: ='Revenue Forecast'!BL7*Assumptions!$D$41/12 | BN17: =SUM(E17:P17) | BO17: =SUM(Q17:AB17) | BP17: =SUM(AC17:AN17) | BQ17: =SUM(AO17:AZ17) | BR17: =SUM(BA17:BL17) | BT17: parts, consumables and travel per contract, from the service table; the engineers are on Personnel
B18: Installer partner commission | C18: EUR | E18: =('Revenue Forecast'!E44+'Revenue Forecast'!E45)*(1-'Revenue Forecast'!E15)*Assumptions!$D$64 | F18: =('Revenue Forecast'!F44+'Revenue Forecast'!F45)*(1-'Revenue Forecast'!F15)*Assumptions!$D$64 | G18: =('Revenue Forecast'!G44+'Revenue Forecast'!G45)*(1-'Revenue Forecast'!G15)*Assumptions!$D$64 | H18: =('Revenue Forecast'!H44+'Revenue Forecast'!H45)*(1-'Revenue Forecast'!H15)*Assumptions!$D$64 | I18: =('Revenue Forecast'!I44+'Revenue Forecast'!I45)*(1-'Revenue Forecast'!I15)*Assumptions!$D$64 | J18: =('Revenue Forecast'!J44+'Revenue Forecast'!J45)*(1-'Revenue Forecast'!J15)*Assumptions!$D$64 | K18: =('Revenue Forecast'!K44+'Revenue Forecast'!K45)*(1-'Revenue Forecast'!K15)*Assumptions!$D$64 | L18: =('Revenue Forecast'!L44+'Revenue Forecast'!L45)*(1-'Revenue Forecast'!L15)*Assumptions!$D$64 | ... BL18: =('Revenue Forecast'!BL44+'Revenue Forecast'!BL45)*(1-'Revenue Forecast'!BL15)*Assumptions!$D$64 | BN18: =SUM(E18:P18) | BO18: =SUM(Q18:AB18) | BP18: =SUM(AC18:AN18) | BQ18: =SUM(AO18:AZ18) | BR18: =SUM(BA18:BL18) | BT18: turbineketel and Combi+ revenue on the channel share of units, times the commission rate
B19: Total cost of goods sold | C19: EUR | E19: =SUM(E13:E18) | F19: =SUM(F13:F18) | G19: =SUM(G13:G18) | H19: =SUM(H13:H18) | I19: =SUM(I13:I18) | J19: =SUM(J13:J18) | K19: =SUM(K13:K18) | L19: =SUM(L13:L18) | ... BL19: =SUM(BL13:BL18) | BN19: =SUM(E19:P19) | BO19: =SUM(Q19:AB19) | BP19: =SUM(AC19:AN19) | BQ19: =SUM(AO19:AZ19) | BR19: =SUM(BA19:BL19)
B21: Gross profit per unit | C21: EUR/unit | E21: =IFERROR(('Revenue Forecast'!E50-'Revenue Forecast'!E49-E19)/'Revenue Forecast'!E34,0) | F21: =IFERROR(('Revenue Forecast'!F50-'Revenue Forecast'!F49-F19)/'Revenue Forecast'!F34,0) | G21: =IFERROR(('Revenue Forecast'!G50-'Revenue Forecast'!G49-G19)/'Revenue Forecast'!G34,0) | H21: =IFERROR(('Revenue Forecast'!H50-'Revenue Forecast'!H49-H19)/'Revenue Forecast'!H34,0) | I21: =IFERROR(('Revenue Forecast'!I50-'Revenue Forecast'!I49-I19)/'Revenue Forecast'!I34,0) | J21: =IFERROR(('Revenue Forecast'!J50-'Revenue Forecast'!J49-J19)/'Revenue Forecast'!J34,0) | K21: =IFERROR(('Revenue Forecast'!K50-'Revenue Forecast'!K49-K19)/'Revenue Forecast'!K34,0) | L21: =IFERROR(('Revenue Forecast'!L50-'Revenue Forecast'!L49-L19)/'Revenue Forecast'!L34,0) | ... BL21: =IFERROR(('Revenue Forecast'!BL50-'Revenue Forecast'!BL49-BL19)/'Revenue Forecast'!BL34,0) | BN21: =IFERROR(('Revenue Forecast'!BN50-'Revenue Forecast'!BN49-BN19)/'Revenue Forecast'!BN34,0) | BO21: =IFERROR(('Revenue Forecast'!BO50-'Revenue Forecast'!BO49-BO19)/'Revenue Forecast'!BO34,0) | BP21: =IFERROR(('Revenue Forecast'!BP50-'Revenue Forecast'!BP49-BP19)/'Revenue Forecast'!BP34,0) | BQ21: =IFERROR(('Revenue Forecast'!BQ50-'Revenue Forecast'!BQ49-BQ19)/'Revenue Forecast'!BQ34,0) | BR21: =IFERROR(('Revenue Forecast'!BR50-'Revenue Forecast'!BR49-BR19)/'Revenue Forecast'!BR34,0) | BT21: trading revenue less cost of sales, per unit; the subsidy is left out

Sheet OPEX
B1: Tarnoc B.V. Operating Expenses
B2: People come from the Personnel tab. Everything else scales with headcount or partners signed.
E3: 46023 | F3: 46054 | G3: 46082 | H3: 46113 | I3: 46143 | J3: 46174 | K3: 46204 | L3: 46235 | M3: 46266 | N3: 46296 | O3: 46327 | P3: 46357 | Q3: 46388 | R3: 46419 | S3: 46447 | T3: 46478 | U3: 46508 | V3: 46539 | W3: 46569 | X3: 46600 | Y3: 46631 | Z3: 46661 | AA3: 46692 | AB3: 46722 | AC3: 46753 | AD3: 46784 | AE3: 46813 | AF3: 46844 | AG3: 46874 | AH3: 46905 | AI3: 46935 | AJ3: 46966 | AK3: 46997 | AL3: 47027 | AM3: 47058 | AN3: 47088 | AO3: 47119 | AP3: 47150 | AQ3: 47178 | AR3: 47209 | AS3: 47239 | AT3: 47270 | AU3: 47300 | AV3: 47331 | AW3: 47362 | AX3: 47392 | AY3: 47423 | AZ3: 47453 | BA3: 47484 | BB3: 47515 | BC3: 47543 | BD3: 47574 | BE3: 47604 | BF3: 47635 | BG3: 47665 | BH3: 47696 | BI3: 47727 | BJ3: 47757 | BK3: 47788 | BL3: 47818 | BN3: 2026 | BO3: 2027 | BP3: 2028 | BQ3: 2029 | BR3: 2030 | BT3: what this row does
B5: PEOPLE
B6: Research and development | C6: EUR | E6: =IF(E$3<=Assumptions!$D$12,E38,Personnel!E26) | F6: =IF(F$3<=Assumptions!$D$12,F38,Personnel!F26) | G6: =IF(G$3<=Assumptions!$D$12,G38,Personnel!G26) | H6: =IF(H$3<=Assumptions!$D$12,H38,Personnel!H26) | I6: =IF(I$3<=Assumptions!$D$12,I38,Personnel!I26) | J6: =IF(J$3<=Assumptions!$D$12,J38,Personnel!J26) | K6: =IF(K$3<=Assumptions!$D$12,K38,Personnel!K26) | L6: =IF(L$3<=Assumptions!$D$12,L38,Personnel!L26) | ... BL6: =IF(BL$3<=Assumptions!$D$12,BL38,Personnel!BL26) | BN6: =SUM(E6:P6) | BO6: =SUM(Q6:AB6) | BP6: =SUM(AC6:AN6) | BQ6: =SUM(AO6:AZ6) | BR6: =SUM(BA6:BL6)
B7: Sales and marketing | C7: EUR | E7: =IF(E$3<=Assumptions!$D$12,E39,Personnel!E27) | F7: =IF(F$3<=Assumptions!$D$12,F39,Personnel!F27) | G7: =IF(G$3<=Assumptions!$D$12,G39,Personnel!G27) | H7: =IF(H$3<=Assumptions!$D$12,H39,Personnel!H27) | I7: =IF(I$3<=Assumptions!$D$12,I39,Personnel!I27) | J7: =IF(J$3<=Assumptions!$D$12,J39,Personnel!J27) | K7: =IF(K$3<=Assumptions!$D$12,K39,Personnel!K27) | L7: =IF(L$3<=Assumptions!$D$12,L39,Personnel!L27) | ... BL7: =IF(BL$3<=Assumptions!$D$12,BL39,Personnel!BL27) | BN7: =SUM(E7:P7) | BO7: =SUM(Q7:AB7) | BP7: =SUM(AC7:AN7) | BQ7: =SUM(AO7:AZ7) | BR7: =SUM(BA7:BL7)
B8: General and administrative | C8: EUR | E8: =IF(E$3<=Assumptions!$D$12,E40,Personnel!E28) | F8: =IF(F$3<=Assumptions!$D$12,F40,Personnel!F28) | G8: =IF(G$3<=Assumptions!$D$12,G40,Personnel!G28) | H8: =IF(H$3<=Assumptions!$D$12,H40,Personnel!H28) | I8: =IF(I$3<=Assumptions!$D$12,I40,Personnel!I28) | J8: =IF(J$3<=Assumptions!$D$12,J40,Personnel!J28) | K8: =IF(K$3<=Assumptions!$D$12,K40,Personnel!K28) | L8: =IF(L$3<=Assumptions!$D$12,L40,Personnel!L28) | ... BL8: =IF(BL$3<=Assumptions!$D$12,BL40,Personnel!BL28) | BN8: =SUM(E8:P8) | BO8: =SUM(Q8:AB8) | BP8: =SUM(AC8:AN8) | BQ8: =SUM(AO8:AZ8) | BR8: =SUM(BA8:BL8)
B9: Total people cost | C9: EUR | E9: =SUM(E6:E8) | F9: =SUM(F6:F8) | G9: =SUM(G6:G8) | H9: =SUM(H6:H8) | I9: =SUM(I6:I8) | J9: =SUM(J6:J8) | K9: =SUM(K6:K8) | L9: =SUM(L6:L8) | ... BL9: =SUM(BL6:BL8) | BN9: =SUM(E9:P9) | BO9: =SUM(Q9:AB9) | BP9: =SUM(AC9:AN9) | BQ9: =SUM(AO9:AZ9) | BR9: =SUM(BA9:BL9)
B11: SALES AND MARKETING, EVERYTHING ELSE
B12: Performance marketing | C12: EUR | E12: ='Revenue Forecast'!E6 | F12: ='Revenue Forecast'!F6 | G12: ='Revenue Forecast'!G6 | H12: ='Revenue Forecast'!H6 | I12: ='Revenue Forecast'!I6 | J12: ='Revenue Forecast'!J6 | K12: ='Revenue Forecast'!K6 | L12: ='Revenue Forecast'!L6 | ... BL12: ='Revenue Forecast'!BL6 | BN12: =SUM(E12:P12) | BO12: =SUM(Q12:AB12) | BP12: =SUM(AC12:AN12) | BQ12: =SUM(AO12:AZ12) | BR12: =SUM(BA12:BL12) | BT12: the same spend that drives the funnel, so it can never be double counted
