Workbook

Sheet Cover
B15: Financial Model
B19: Currency: EUR (€)
B21: STRICTLY CONFIDENTIAL

Sheet How to read me
B1: Tarnoc — How to Read This Model
B3: COLOR CODING
B4: Sample | C4: Assumptions are hardcoded inputs (sourced from documents)
B5: Sample | C5: Hardcoded historicalsis actual data from source documents
B6: Sample | C6: Formula cells are calculated, not hardcoded
B7: Sample | C7: Subtotal / total rows
B8: Sample | C8: Section headers / grand totals
B9: Sample | C9: Subsection headers
B10: Sample | C10: Margin / ratio rows (grey)
B11: Sample | C11: Balance sheet check rows (must = 0)
B14: FORMULA ARCHITECTURE
B15: Assumptions → Revenue Forecast, COGS, OPEX, CAPEX, Personnel (all drivers sourced here)
B16: Revenue Forecast → Financial Statements (revenue lines via cross-sheet links)
B17: COGS → Financial Statements (cost lines via cross-sheet links)
B18: OPEX → Financial Statements (opex lines via cross-sheet links)
B20: To change a number: ONLY edit cells in the Assumptions tab (yellow/orange).
B21: All other tabs will recalculate automatically.
B24: FURTHER EXPLANATIONS
B25: Subsidies: Tarnoc is and has been eligible for a number of subsidies. We will consider application for large projects, however this model excludes the forecast of any subsidy financing foing forward.
B26: Installation revenues: This is modelled fully as pass through revenue for now, as we plan to charge a customer exactly what we pay the installation partner for these services. This is subject to change in the future.
B27: Tarnoc's main products are the TTK, Tarnoc Mini, and the Twinciycle (to be in development in 2027). We also plan to sell verious add-ons such as performance booster units, boilers for hybrid setups, and sound reduction units.
B28: Service Revenues: Service revenues are calculated relative to installed base. We assume a certain percentage (see assumptions) of customers will purchase our Service package, and are charged annually.
... B30: Sales and Marketing costs are largely driven by permfomance marketing, and are calcualted on a volume and CPL basis. ]

Sheet Assumptions
B2: Drivers & Assumptions
B3: ASSUMPTIONS
B5: General Assumptions
B6: Opening Cash Balance (Jan 2024) | C6: 29538.9
B7: Annual salary increase (%) | C7: 0.08
B8: Employer cost basis | C8: Werkgeverlasten (incl. taxes)
B9: Holiday pay (%) | C9: 0.08
B10: Income tax rate | C10: 0.258
B12: Working Capital | H12: 20
B14: Days Sales Outstanding (DSO) | C14: days | D14: 20
B15: Days Payable Outstanding (DPO) | C15: days | D15: 45
B16: Days Inventory Outstanding (DIO) | C16: days | D16: 0
B17: Pre-payment | C17: %
B19: Revenue Build
B20: Units sold
C21: 2026 | D21: 2027 | E21: 2028 | F21: 2029 | G21: 2030
B22: TTK | C22: 0 | D22: =1000*D24 -> 1000 | E22: =3000*D24 -> 3000 | F22: =6000*D24 -> 6000 | G22: =12000*D24 -> 12000
B23: Tarnoc Mini | C23: 0 | D23: =500*D24 -> 500 | E23: =2000*D24 -> 2000 | F23: =4000*D24 -> 4000 | G23: =8000*D24 -> 8000
B24: Discounter | C24: 1 | D24: 1 | E24: 0.6
B26: Pricing
B27: TTK PRICING
B28: TTK Price | C28: =9800/1.21 -> 8099.1736 | D28: Management input (excl. VAT)
B30: MINI PRICING
B31: Mini Price | C31: =3350/1.21 -> 2768.595 | D31: Management input (excl. BTW)
B33: INSTALLATION (PASS THROUGH; REV=COST) | C33: 3200 | D33: Management input (excl. BTW)
B35: COGS
B36: TTK
B37: Bill of Materials TTK supplier 1
B38: # | C38: Category | D38: Component | E38: 1,000 units | F38: 5,000 units | G38: 10,000 units | H38: Unit | I38: Source
B39: B1 | C39: Supplier 1 | D39: Compressor + VFD | E39: 6314 | F39: 4500 | G39: 2692.44 | H39: €/unit | I39: Source: BOM data provided
B40: B2 | C40: Supplier 1 | D40: Heat exchangers (set) | E40: 805.5 | F40: =E40*0.7 -> 563.85 | G40: =0.6*F40 -> 338.31 | H40: €/unit | I40: Source: BOM data provided
B41: B3 | C41: Supplier 1 | D41: Electronics & Power Electronics | E41: 632.92 | F41: =E41*0.7 -> 443.044 | G41: =0.6*F41 -> 265.8264 | H41: €/unit | I41: Source: BOM data provided
B42: B4 | C42: Supplier 1 | D42: Hydraulic Components (Pumps, Valves, etc.) | E42: 283.76 | F42: =E42*0.7 -> 198.632 | G42: =0.6*F42 -> 119.1792 | H42: €/unit | I42: Source: BOM data provided
B43: B5 | C43: Supplier 1 | D43: Silencer & Insulation | E43: 118.48 | F43: =E43*0.7 -> 82.936 | G43: =0.6*F43 -> 49.7616 | H43: €/unit | I43: Source: BOM data provided
B44: B6 | C44: Supplier 1 | D44: Enclosure (Sheet Metal & Coating) | E44: 653.03 | F44: =E44*0.7 -> 457.121 | G44: =0.6*F44 -> 274.2726 | H44: €/unit | I44: Source: BOM data provided
B45: B7 | C45: Supplier 1 | D45: Other Components | E45: 300 | F45: =E45*0.7 -> 210 | G45: 126 | H45: €/unit | I45: Source: BOM data provided
B46: B8 | C46: Supplier 1 | D46: Assembly & Final Testing | E46: 200 | F46: =E46*0.7 -> 140 | G46: =0.6*F46 -> 84 | H46: €/unit | I46: Source: BOM data provided
B47: B9 | C47: Supplier 1 | D47: Packaging & Inbound Logistics | E47: 400 | F47: =E47*0.7 -> 280 | G47: =0.6*F47 -> 168 | H47: €/unit | I47: Source: BOM data provided
B48: B10 | C48: Supplier 1 | D48: Yield Loss & Warranty Provision (~3%) | E48: 291.23 | F48: =E48*0.7 -> 203.861 | G48: =0.6*F48 -> 122.3166 | H48: €/unit | I48: Source: BOM data provided
B49: B11 | C49: Contingency/risk | D49: Contingency & Risk Reserve | E49: 0 | F49: 0 | G49: 760 | H49: €/unit | I49: Source: No source, added for risk purposes
...

Sheet Financial Statements
B1: Tarnoc B.V. — Financial Statements (€)
E2: 2025 | Q2: 2026 | AC2: 2027 | AO2: 2028
E3: 45658 | F3: 45689 | G3: 45717 | H3: 45748 | I3: 45778 | J3: 45809 | K3: 45839 | L3: 45870 | M3: 45901 | N3: 45931 | O3: 45962 | P3: 45992 | Q3: 46023 | R3: 46054 | S3: 46082 | T3: 46113 | U3: 46143 | V3: 46174 | W3: 46204 | X3: 46235 | Y3: 46266 | Z3: 46296 | AA3: 46327 | AB3: 46357 | AC3: 46388 | AD3: 46419 | AE3: 46447 | AF3: 46478 | AG3: 46508 | AH3: 46539 | AI3: 46569 | AJ3: 46600 | AK3: 46631 | AL3: 46661 | AM3: 46692 | AN3: 46722 | AO3: 46753 | AP3: 46784 | AQ3: 46813 | AR3: 46844 | AS3: 46874 | AT3: 46905 | AU3: 46935 | AV3: 46966 | AW3: 46997 | AX3: 47027 | AY3: 47058 | AZ3: 47088 | BB3: 2025 | BC3: 2026 | BD3: 2027 | BE3: 2028 | BF3: 2029
B5: PROFIT & LOSS STATEMENT
B6: Revenues
B7: TTK | D7: € | M7: ='Revenue Forecast'!M9 | N7: ='Revenue Forecast'!N9 | O7: ='Revenue Forecast'!O9 | P7: ='Revenue Forecast'!P9 | Q7: ='Revenue Forecast'!Q9 -> 0 | R7: ='Revenue Forecast'!R9 -> 0 | S7: ='Revenue Forecast'!S9 -> 0 | T7: ='Revenue Forecast'!T9 -> 0 | ... AZ7: ='Revenue Forecast'!AZ9 -> 3975329.8 | BB7: =sum(E7:P7) -> 0 | BC7: =sum(Q7:AB7) -> 0 | BD7: =sum(AC7:AN7) -> 10140118 | BE7: =sum(AO7:AZ7) -> 30269008 | BF7: ='Revenue Forecast'!BF9 -> 60538017
B8: Tarnoc Mini | D8: € | M8: ='Revenue Forecast'!M15 | N8: ='Revenue Forecast'!N15 | O8: ='Revenue Forecast'!O15 | P8: ='Revenue Forecast'!P15 | Q8: ='Revenue Forecast'!Q15 -> 0 | R8: ='Revenue Forecast'!R15 -> 0 | S8: ='Revenue Forecast'!S15 -> 0 | T8: ='Revenue Forecast'!T15 -> 0 | ... AZ8: ='Revenue Forecast'!AZ15 -> 845528.16 | BB8: =sum(E8:P8) -> 0 | BC8: =sum(Q8:AB8) -> 0 | BD8: =sum(AC8:AN8) -> 1452797.5 | BE8: =sum(AO8:AZ8) -> 5811190.1 | BF8: ='Revenue Forecast'!BF15 -> 11622380
B9: Other | M9: ='Revenue Forecast'!M19+'Revenue Forecast'!M24 -> 0 | N9: ='Revenue Forecast'!N19+'Revenue Forecast'!N24 -> 0 | O9: ='Revenue Forecast'!O19+'Revenue Forecast'!O24 -> 0 | P9: ='Revenue Forecast'!P19+'Revenue Forecast'!P24 -> 0 | Q9: ='Revenue Forecast'!Q19+'Revenue Forecast'!Q24 -> 0 | R9: ='Revenue Forecast'!R19+'Revenue Forecast'!R24 -> 0 | S9: ='Revenue Forecast'!S19+'Revenue Forecast'!S24 -> 0 | T9: ='Revenue Forecast'!T19+'Revenue Forecast'!T24 -> 0 | ... AZ9: ='Revenue Forecast'!AZ19+'Revenue Forecast'!AZ24 -> 2253410 | BB9: =sum(E9:P9) -> 0 | BC9: =sum(Q9:AB9) -> 0 | BD9: =sum(AC9:AN9) -> 4919845 | BE9: =sum(AO9:AZ9) -> 16448845 | BF9: ='Revenue Forecast'!BF19+'Revenue Forecast'!BF24 -> 33346535
B10: Subsidies & grants | D10: € | M10: ='Revenue Forecast'!M28 -> 0 | N10: ='Revenue Forecast'!N28 -> 19480 | O10: ='Revenue Forecast'!O28 -> 78000 | P10: ='Revenue Forecast'!P28 -> 0 | Q10: ='Revenue Forecast'!Q28 -> 0 | R10: ='Revenue Forecast'!R28 -> 0 | S10: ='Revenue Forecast'!S28 -> 0 | T10: 0 | U10: ='Revenue Forecast'!U28 -> 0 | V10: 106782 | W10: ='Revenue Forecast'!W28 -> 0 | X10: ='Revenue Forecast'!X28 -> 0 | Y10: ='Revenue Forecast'!Y28 -> 0 | Z10: ='Revenue Forecast'!Z28 -> 0 | AA10: ='Revenue Forecast'!AA28 -> 0 | AB10: ='Revenue Forecast'!AB28 -> 0 | AC10: ='Revenue Forecast'!AC28 -> 0 | AD10: ='Revenue Forecast'!AD28 -> 0 | ... AZ10: ='Revenue Forecast'!AZ28 -> 0 | BB10: =sum(E10:P10) -> 97480 | BC10: =sum(Q10:AB10) -> 106782 | BD10: pm | BE10: pm | BF10: pm
B11: Total Revenue | D11: € | M11: ='Revenue Forecast'!M30 -> 0 | N11: ='Revenue Forecast'!N30 -> 19480 | O11: ='Revenue Forecast'!O30 -> 78000 | P11: ='Revenue Forecast'!P30 -> 0 | Q11: ='Revenue Forecast'!Q30 -> 0 | R11: ='Revenue Forecast'!R30 -> 0 | S11: ='Revenue Forecast'!S30 -> 0 | T11: ='Revenue Forecast'!T30 -> 0 | ... AZ11: ='Revenue Forecast'!AZ30 -> 7074267.9 | BB11: =sum(E11:P11) -> 97480 | BC11: =sum(Q11:AB11) -> 106782 | BD11: =sum(AC11:AN11) -> 16512760 | BE11: =sum(AO11:AZ11) -> 52529043 | BF11: =sum(BF7:BF10) -> 1.0550693e+08
B13: Cost of goods sold
B14: TTK | D14: € | E14: =COGS!E9 | F14: =COGS!F9 | G14: =COGS!G9 | H14: =COGS!H9 | I14: =COGS!I9 | J14: =COGS!J9 | K14: =COGS!K9 | L14: =COGS!L9 | ... AZ14: =COGS!AZ9 -> 3170614.1 | BB14: =sum(E14:P14) -> 0 | BC14: =sum(Q14:AB14) -> 0 | BD14: =sum(AC14:AN14) -> 11021554 | BE14: =sum(AO14:AZ14) -> 24141732 | BF14: =COGS!BF9 -> 35806800
B15: Tarnoc Mini | D15: € | E15: =COGS!E14 | F15: =COGS!F14 | G15: =COGS!G14 | H15: =COGS!H14 | I15: =COGS!I14 | J15: =COGS!J14 | K15: =COGS!K14 | L15: =COGS!L14 | ... AZ15: =COGS!AZ14 -> 395760 | BB15: =sum(E15:P15) -> 0 | BC15: =sum(Q15:AB15) -> 0 | BD15: =sum(AC15:AN15) -> 680000 | BE15: =sum(AO15:AZ15) -> 2720000 | BF15: =COGS!BF14 -> 4193400
B16: Other | E16: =COGS!E17 | F16: =COGS!F17 | G16: =COGS!G17 | H16: =COGS!H17 | I16: =COGS!I17 | J16: =COGS!J17 | K16: =COGS!K17 | L16: =COGS!L17 | ... P16: =COGS!P17 | Q16: =COGS!Q17+COGS!Q22 -> 0 | R16: =COGS!R17+COGS!R22 -> 0 | S16: =COGS!S17+COGS!S22 -> 0 | T16: =COGS!T17+COGS!T22 -> 0 | U16: =COGS!U17+COGS!U22 -> 0 | V16: =COGS!V17+COGS!V22 -> 0 | W16: =COGS!W17+COGS!W22 -> 0 | X16: =COGS!X17+COGS!X22 -> 0 | ... AZ16: =COGS!AZ17+COGS!AZ22 -> 2220302 | BB16: =sum(E16:P16) -> 0 | BC16: =sum(Q16:AB16) -> 0 | BD16: =sum(AC16:AN16) -> 4863859 | BE16: =sum(AO16:AZ16) -> 16206859 | BF16: =COGS!BF17 -> 32000000
B17: Total COGS | D17: € | M17: =COGS!M24 -> 0 | N17: =COGS!N24 -> 0 | O17: =COGS!O24 -> 0 | P17: =COGS!P24 -> 0 | Q17: =COGS!Q24 -> 0 | R17: =COGS!R24 -> 0 | S17: =COGS!S24 -> 0 | T17: =COGS!T24 -> 0 | ... AZ17: =COGS!AZ24 -> 5786676.1 | BB17: =sum(E17:P17) -> 0 | BC17: =sum(Q17:AB17) -> 0 | BD17: =sum(AC17:AN17) -> 16565413 | BE17: =sum(AO17:AZ17) -> 43068591 | BF17: =sum(BF14:BF16) -> 72000200
B19: Gross Profit | M19: =M11-M17 -> 0 | N19: =N11-N17 -> 19480 | O19: =O11-O17 -> 78000 | P19: =P11-P17 -> 0 | Q19: =Q11-Q17 -> 0 | R19: =R11-R17 -> 0 | S19: =S11-S17 -> 0 | T19: =T11-T17 -> 0 | ... AZ19: =AZ11-AZ17 -> 1287591.8 | BB19: =sum(E19:P19) -> 97480 | BC19: =sum(Q19:AB19) -> 106782 | BD19: =sum(AC19:AN19) -> -52652.311 | BE19: =sum(AO19:AZ19) -> 9460452.3 | BF19: =BF11-BF17 -> 33506732
B20: Gross margin % | D20: % | BE20: =BE19/BE11 -> 0.18009946 | BF20: =BF19/BF11 -> 0.31757849
B22: Operational expenses
B23: R&D | D23: € | M23: =OPEX!O38 -> 47500 | N23: =OPEX!P38 -> 47500 | O23: =OPEX!Q38 -> 47500 | P23: =OPEX!R38 -> 216433 | Q23: =OPEX!S38 -> 75700 | R23: =OPEX!T38 -> 75700 | S23: =OPEX!U38 -> 75700 | T23: =OPEX!V38 -> 75700 | ... AZ23: =OPEX!BB38 -> 152614.77 | BB23: =sum(E23:P23) -> 358933 | BC23: =sum(Q23:AB23) -> 1150160 | BD23: =sum(AC23:AN23) -> 1576575.2 | BE23: =sum(AO23:AZ23) -> 1821001.2 | BF23: =OPEX!BH38 -> 3055465.9
B24: S&M | D24: € | M24: =OPEX!O39 -> 0 | N24: =OPEX!P39 -> 0 | O24: =OPEX!Q39 -> 0 | P24: =OPEX!R39 -> 20000 | Q24: =OPEX!S39 -> 21000 | R24: =OPEX!T39 -> 31800 | S24: =OPEX!U39 -> 31800 | T24: =OPEX!V39 -> 31800 | ... AZ24: =OPEX!BB39 -> 245181.92 | BB24: =sum(E24:P24) -> 20000 | BC24: =sum(Q24:AB24) -> 464300 | BD24: =sum(AC24:AN24) -> 1367448 | BE24: =sum(AO24:AZ24) -> 2504934.2 | BF24: =OPEX!BH39 -> 4019540.2
B25: G&A | D25: € | M25: =OPEX!O40 -> 11500 | N25: =OPEX!P40 -> 11500 | O25: =OPEX!Q40 -> 11500 | P25: =OPEX!R40 -> 11500 | Q25: =OPEX!S40 -> 31820 | R25: =OPEX!T40 -> 31820 | S25: =OPEX!U40 -> 31820 | T25: =OPEX!V40 -> 31820 | ... AZ25: =OPEX!BB40 -> 89245.088 | BB25: =sum(E25:P25) -> 46000 | BC25: =sum(Q25:AB25) -> 462060 | BD25: =sum(AC25:AN25) -> 832843.2 | BE25: =sum(AO25:AZ25) -> 1050610.7 | BF25: =OPEX!BH40 -> 1307473.3
B26: Total OPEX | D26: € | M26: =(M25+M24+M23) -> 59000 | N26: =(N25+N24+N23) -> 59000 | O26: =(O25+O24+O23) -> 59000 | P26: =(P25+P24+P23) -> 247933 | Q26: =(Q25+Q24+Q23) -> 128520 | R26: =(R25+R24+R23) -> 139320 | S26: =(S25+S24+S23) -> 139320 | T26: =(T25+T24+T23) -> 139320 | ... AZ26: =(AZ25+AZ24+AZ23) -> 487041.78 | BB26: =sum(E26:P26) -> 424933 | BC26: =sum(Q26:AB26) -> 2076520 | BD26: =sum(AC26:AN26) -> 3776866.4 | BE26: =sum(AO26:AZ26) -> 5376546.1 | BF26: =sum(BF23:BF25) -> 8382479.5
B28: EBITDA | D28: € | M28: =M19-M26 -> -59000 | N28: =N19-N26 -> -39520 | O28: =O19-O26 -> 19000 | P28: =P19-P26 -> -247933 | Q28: =Q19-Q26 -> -128520 | R28: =R19-R26 -> -139320 | S28: =S19-S26 -> -139320 | T28: =T19-T26 -> -139320 | ... AZ28: =AZ19-AZ26 -> 800550 | BB28: =sum(E28:P28) -> -327453 | BC28: =sum(Q28:AB28) -> -1969738 | BD28: =sum(AC28:AN28) -> -3829518.7 | BE28: =sum(AO28:AZ28) -> 4083906.2 | BF28: =BF19-BF26 -> 25124252
B29: EBITDA margin % | D29: % | BE29: =BE28/BE11 -> 0.077745681 | BF29: =BF28/BF11 -> 0.23812893
B31: Depreciation & Amortisation | D31: € | M31: 0 | N31: 0 | O31: 0 | P31: 0 | Q31: 0 | R31: 0 | S31: 0 | T31: 0 | U31: 0 | V31: 0 | W31: 0 | X31: 0 | Y31: 0 | Z31: 0 | AA31: 0 | AB31: 0 | AC31: 0 | AD31: 0 | AE31: 0 | AF31: 0 | AG31: 0 | AH31: 0 | AI31: 0 | AJ31: 0 | AK31: 0 | AL31: 0 | AM31: 0 | AN31: 0 | AO31: 0 | AP31: 0 | AQ31: 0 | AR31: 0 | AS31: 0 | AT31: 0 | AU31: 0 | AV31: 0 | AW31: 0 | AX31: 0 | AY31: 0 | AZ31: 0 | BB31: =sum(E31:P31) -> 0 | BC31: =sum(Q31:AB31) -> 0 | BD31: =sum(AC31:AN31) -> 0 | BE31: =sum(AO31:AZ31) -> 0 | BF31: 0
B32: Interst payments | D32: € | M32: 0 | N32: 0 | O32: 0 | P32: 0 | Q32: 0 | R32: 0 | S32: 0 | T32: 0 | U32: 0 | V32: 0 | W32: 0 | X32: 0 | Y32: 0 | Z32: 0 | AA32: 0 | AB32: 0 | AC32: 0 | AD32: 0 | AE32: 0 | AF32: 0 | AG32: 0 | AH32: 0 | AI32: 0 | AJ32: 0 | AK32: 0 | AL32: 0 | AM32: 0 | AN32: 0 | AO32: 0 | AP32: 0 | AQ32: 0 | AR32: 0 | AS32: 0 | AT32: 0 | AU32: 0 | AV32: 0 | AW32: 0 | AX32: 0 | AY32: 0 | AZ32: 0 | BB32: =sum(E32:P32) -> 0 | BC32: =sum(Q32:AB32) -> 0 | BD32: =sum(AC32:AN32) -> 0 | BE32: =sum(AO32:AZ32) -> 0 | BF32: 0
B33: EBT | D33: € | M33: =M28-sum(M31:M32) -> -59000 | N33: =N28-sum(N31:N32) -> -39520 | O33: =O28-sum(O31:O32) -> 19000 | P33: =P28-sum(P31:P32) -> -247933 | Q33: =Q28-sum(Q31:Q32) -> -128520 | R33: =R28-sum(R31:R32) -> -139320 | S33: =S28-sum(S31:S32) -> -139320 | T33: =T28-sum(T31:T32) -> -139320 | ... AZ33: =AZ28-sum(AZ31:AZ32) -> 800550 | BB33: =sum(E33:P33) -> -327453 | BC33: =sum(Q33:AB33) -> -1969738 | BD33: =sum(AC33:AN33) -> -3829518.7 | BE33: =sum(AO33:AZ33) -> 4083906.2 | BF33: =BF28-sum(BF31:BF32) -> 25124252
BE34: =BE33/BE11 -> 0.077745681 | BF34: =BF33/BF11 -> 0.23812893
B36: Income tax | D36: € | M36: 0 | N36: 0 | O36: 0 | P36: 0 | Q36: 0 | R36: 0 | S36: 0 | T36: 0 | U36: 0 | V36: 0 | W36: 0 | X36: 0 | Y36: 0 | Z36: 0 | AA36: 0 | AB36: 0 | AC36: 0 | AD36: 0 | AE36: 0 | AF36: 0 | AG36: 0 | AH36: 0 | AI36: 0 | AJ36: 0 | AK36: 0 | AL36: 0 | AM36: 0 | AN36: 0 | AO36: 0 | AP36: 0 | AQ36: 0 | AR36: 0 | AS36: 0 | AT36: 0 | AU36: 0 | AV36: 0 | AW36: 0 | AX36: 0 | AY36: 0 | AZ36: 0 | BB36: =sum(E36:P36) -> 0 | BC36: =sum(Q36:AB36) -> 0 | BD36: =sum(AC36:AN36) -> 0 | BE36: =sum(AO36:AZ36) -> 0 | BF36: =(BF33-AZ40)*Assumptions!$C$10 -> 6322081.5
B37: NET INCOME | D37: € | M37: =M33-M36 -> -59000 | N37: =N33-N36 -> -39520 | O37: =O33-O36 -> 19000 | P37: =P33-P36 -> -247933 | Q37: =Q33-Q36 -> -128520 | R37: =R33-R36 -> -139320 | S37: =S33-S36 -> -139320 | T37: =T33-T36 -> -139320 | ... AZ37: =AZ33-AZ36 -> 800550 | BB37: =sum(E37:P37) -> -327453 | BC37: =sum(Q37:AB37) -> -1969738 | BD37: =sum(AC37:AN37) -> -3829518.7 | BE37: =sum(AO37:AZ37) -> 4083906.2 | BF37: =BF33-BF36 -> 18802171
B38: Profit margin % | BE38: =BE37/BE11 -> 0.077745681 | BF38: =BF37/BF11 -> 0.17820792
B40: Tax carry over to be applied | M40: 108239 | N40: =M40+(-N37*Assumptions!$C$10) -> 118435.16 | O40: =N40+(-O37*Assumptions!$C$10) -> 113533.16 | P40: =O40+(-P37*Assumptions!$C$10) -> 177499.87 | Q40: =P40+(-Q37*Assumptions!$C$10) -> 210658.03 | R40: =Q40+(-R37*Assumptions!$C$10) -> 246602.59 | S40: =R40+(-S37*Assumptions!$C$10) -> 282547.15 | T40: =S40+(-T37*Assumptions!$C$10) -> 318491.71 | U40: =T40+(-U37*Assumptions!$C$10) -> 357016.27 | ... AZ40: =AY40+(-AZ37*Assumptions!$C$10) -> 620060.3
B42: CASH FLOW STATEMENT
B43: Net income | D43: € | M43: =M37 -> -59000 | N43: =N37 -> -39520 | O43: =O37 -> 19000 | P43: =P37 -> -247933 | Q43: =Q37 -> -128520 | R43: =R37 -> -139320 | S43: =S37 -> -139320 | T43: =T37 -> -139320 | ... AZ43: =AZ37 -> 800550 | BB43: =sum(E43:P43) -> -327453 | BC43: =sum(Q43:AB43) -> -1969738 | BD43: =sum(AC43:AN43) -> -3829518.7 | BE43: =sum(AO43:AZ43) -> 4083906.2 | BF43: =BF37 -> 18802171
B44: Depreciation & amortisation | D44: € | M44: 0 | N44: 0 | O44: 0 | P44: 0 | Q44: 0 | R44: 0 | S44: 0 | T44: 0 | U44: 0 | V44: 0 | W44: 0 | X44: 0 | Y44: 0 | Z44: 0 | AA44: 0 | AB44: 0 | AC44: 0 | AD44: 0 | AE44: 0 | AF44: 0 | AG44: 0 | AH44: 0 | AI44: 0 | AJ44: 0 | AK44: 0 | AL44: 0 | AM44: 0 | AN44: 0 | AO44: 0 | AP44: 0 | AQ44: 0 | AR44: 0 | AS44: 0 | AT44: 0 | AU44: 0 | AV44: 0 | AW44: 0 | AX44: 0 | AY44: 0 | AZ44: 0 | BB44: =sum(E44:P44) -> 0 | BC44: =sum(Q44:AB44) -> 0 | BD44: =sum(AC44:AN44) -> 0 | BE44: =sum(AO44:AZ44) -> 0 | BF44: =BF31 -> 0
B45: Increase in accounts receivable (delta DSO) | D45: € | M45: 0 | N45: =-(N63-M63) -> -12986.667 | O45: =-(O63-N63) -> -39013.333 | P45: =-(P63-O63) -> 52000 | Q45: =-(Q63-P63) -> 0 | R45: =-(R63-Q63) -> 0 | S45: =-(S63-R63) -> 0 | T45: =-(T63-S63) -> 0 | U45: =-(U63-T63) -> 0 | ... AZ45: =-(AZ63-AY63) -> -444346.98 | BB45: =sum(E45:P45) -> 0 | BC45: =sum(Q45:AB45) -> 0 | BD45: =sum(AC45:AN45) -> -1476059.9 | BE45: =sum(AO45:AZ45) -> -3240118.7 | BF45: =-(BF63-BE63) -> -1065023.1
B46: Increase in accounts payable (delta DPO) | D46: € | M46: 0 | N46: =(N72-M72) -> 0 | O46: =(O72-N72) -> 0 | P46: =(P72-O72) -> 0 | Q46: =(Q72-P72) -> 0 | R46: =(R72-Q72) -> 0 | S46: =(S72-R72) -> 0 | T46: =(T72-S72) -> 0 | U46: =(U72-T72) -> 0 | ... AZ46: =(AZ72-AY72) -> 813510.21 | BB46: =sum(E46:P46) -> 0 | BC46: =sum(Q46:AB46) -> 0 | BD46: =sum(AC46:AN46) -> 3314109.1 | BE46: =sum(AO46:AZ46) -> 5365905.1 | BF46: =BF72-BE72 -> 196722.78
B47: Change in inventory (delta DIO) | D47: € | M47: 0 | N47: =-(N64-M64) -> 0 | O47: =-(O64-N64) -> 0 | P47: =-(P64-O64) -> 0 | Q47: =-(Q64-P64) -> 0 | R47: =-(R64-Q64) -> 0 | S47: =-(S64-R64) -> 0 | T47: =-(T64-S64) -> 0 | U47: =-(U64-T64) -> 0 | ... AZ47: =-(AZ64-AY64) -> 0 | BB47: =sum(E47:P47) -> 0 | BC47: =sum(Q47:AB47) -> 0 | BD47: =sum(AC47:AN47) -> 0 | BE47: =sum(AO47:AZ47) -> 0 | BF47: 0
B48: Cash from Operations | D48: € | M48: =sum(M43:M47) -> -59000 | N48: =sum(N43:N47) -> -52506.667 | O48: =sum(O43:O47) -> -20013.333 | P48: =sum(P43:P47) -> -195933 | Q48: =sum(Q43:Q47) -> -128520 | R48: =sum(R43:R47) -> -139320 | S48: =sum(S43:S47) -> -139320 | T48: =sum(T43:T47) -> -139320 | ... AZ48: =sum(AZ43:AZ47) -> 1169713.2 | BB48: =sum(E48:P48) -> -327453 | BC48: =sum(Q48:AB48) -> -1969738 | BD48: =sum(AC48:AN48) -> -1991469.5 | BE48: =sum(AO48:AZ48) -> 6209692.6 | BF48: =sum(BF43:BF47) -> 17933870
B49: CAPEX | D49: € | M49: 0 | N49: 0 | O49: 0 | P49: 0 | Q49: 0 | R49: 0 | S49: 0 | T49: 0 | U49: 0 | V49: 0 | W49: 0 | X49: 0 | Y49: 0 | Z49: 0 | AA49: 0 | AB49: 0 | AC49: 0 | AD49: 0 | AE49: 0 | AF49: 0 | AG49: 0 | AH49: 0 | AI49: 0 | AJ49: 0 | AK49: 0 | AL49: 0 | AM49: 0 | AN49: 0 | AO49: 0 | AP49: 0 | AQ49: 0 | AR49: 0 | AS49: 0 | AT49: 0 | AU49: 0 | AV49: 0 | AW49: 0 | AX49: 0 | AY49: 0 | AZ49: 0 | BB49: =sum(E49:P49) -> 0 | BC49: =sum(Q49:AB49) -> 0 | BD49: =sum(AC49:AN49) -> 0 | BE49: =sum(AO49:AZ49) -> 0 | BF49: 0
...

Sheet Revenue Forecast
B1: Tarnoc B.V. — Revenue Forecast (€, ex VAT unless noted)
E2: 2025 | Q2: 2026 | AC2: 2027 | AO2: 2028
E3: 45658 | F3: 45689 | G3: 45717 | H3: 45748 | I3: 45778 | J3: 45809 | K3: 45839 | L3: 45870 | M3: 45901 | N3: 45931 | O3: 45962 | P3: 45992 | Q3: 46023 | R3: 46054 | S3: 46082 | T3: 46113 | U3: 46143 | V3: 46174 | W3: 46204 | X3: 46235 | Y3: 46266 | Z3: 46296 | AA3: 46327 | AB3: 46357 | AC3: 46388 | AD3: 46419 | AE3: 46447 | AF3: 46478 | AG3: 46508 | AH3: 46539 | AI3: 46569 | AJ3: 46600 | AK3: 46631 | AL3: 46661 | AM3: 46692 | AN3: 46722 | AO3: 46753 | AP3: 46784 | AQ3: 46813 | AR3: 46844 | AS3: 46874 | AT3: 46905 | AU3: 46935 | AV3: 46966 | AW3: 46997 | AX3: 47027 | AY3: 47058 | AZ3: 47088 | BB3: 2025 | BC3: 2026 | BD3: 2027 | BE3: 2028 | BF3: 2029
AB4: 2 | AC4: 3 | AD4: 4 | AE4: 5 | AF4: 6 | AG4: 7 | AH4: 8 | AI4: 9 | AJ4: 10 | AK4: 11 | AL4: 12 | AM4: 13 | AN4: 14 | AO4: 15 | AP4: 16 | AQ4: 17 | AR4: 18 | AS4: 19 | AT4: 20 | AU4: 21 | AV4: 22 | AW4: 23 | AX4: 24 | AY4: 25 | AZ4: 26
B5: TURBINEKETEL (TTK)
B6: TTK units sold | D6: # | Q6: {=IF(YEAR(Q$3)=2026,0,ROUND(EXP(0.095*((YEAR(Q$3)-2027)*12+MONTH(Q$3)-1))/SUMPRODUCT(EXP(0.095*(ROW(INDIRECT("1:24"))-1)))*SUM(Assumptions!$D$22:$E$22),0))} -> 0 | R6: {=IF(YEAR(R$3)=2026,0,ROUND(EXP(0.095*((YEAR(R$3)-2027)*12+MONTH(R$3)-1))/SUMPRODUCT(EXP(0.095*(ROW(INDIRECT("1:24"))-1)))*SUM(Assumptions!$D$22:$E$22),0))} -> 0 | S6: {=IF(YEAR(S$3)=2026,0,ROUND(EXP(0.095*((YEAR(S$3)-2027)*12+MONTH(S$3)-1))/SUMPRODUCT(EXP(0.095*(ROW(INDIRECT("1:24"))-1)))*SUM(Assumptions!$D$22:$E$22),0))} -> 0 | T6: {=IF(YEAR(T$3)=2026,0,ROUND(EXP(0.095*((YEAR(T$3)-2027)*12+MONTH(T$3)-1))/SUMPRODUCT(EXP(0.095*(ROW(INDIRECT("1:24"))-1)))*SUM(Assumptions!$D$22:$E$22),0))} -> 0 | U6: {=IF(YEAR(U$3)=2026,0,ROUND(EXP(0.095*((YEAR(U$3)-2027)*12+MONTH(U$3)-1))/SUMPRODUCT(EXP(0.095*(ROW(INDIRECT("1:24"))-1)))*SUM(Assumptions!$D$22:$E$22),0))} -> 0 | V6: {=IF(YEAR(V$3)=2026,0,ROUND(EXP(0.095*((YEAR(V$3)-2027)*12+MONTH(V$3)-1))/SUMPRODUCT(EXP(0.095*(ROW(INDIRECT("1:24"))-1)))*SUM(Assumptions!$D$22:$E$22),0))} -> 0 | W6: {=IF(YEAR(W$3)=2026,0,ROUND(EXP(0.095*((YEAR(W$3)-2027)*12+MONTH(W$3)-1))/SUMPRODUCT(EXP(0.095*(ROW(INDIRECT("1:24"))-1)))*SUM(Assumptions!$D$22:$E$22),0))} -> 0 | X6: {=IF(YEAR(X$3)=2026,0,ROUND(EXP(0.095*((YEAR(X$3)-2027)*12+MONTH(X$3)-1))/SUMPRODUCT(EXP(0.095*(ROW(INDIRECT("1:24"))-1)))*SUM(Assumptions!$D$22:$E$22),0))} -> 0 | ... AB6: {=IF(YEAR(AB$3)=2026,0,ROUND(EXP(0.095*((YEAR(AB$3)-2027)*12+MONTH(AB$3)-1))/SUMPRODUCT(EXP(0.095*(ROW(INDIRECT("1:24"))-1)))*SUM(Assumptions!$D$22:$E$22),0))} -> 0 | AC6: {=IF(YEAR(AC$3)=2026,0,ROUND(EXP(0.091*((YEAR(AC$3)-2027)*12+MONTH(AC$3)-1))/SUMPRODUCT(EXP(0.091*(ROW(INDIRECT("1:24"))-1)))*SUM(Assumptions!$D$22:$E$22),0))} -> 48 | AD6: {=IF(YEAR(AD$3)=2026,0,ROUND(EXP(0.091*((YEAR(AD$3)-2027)*12+MONTH(AD$3)-1))/SUMPRODUCT(EXP(0.091*(ROW(INDIRECT("1:24"))-1)))*SUM(Assumptions!$D$22:$E$22),0))} -> 53 | AE6: {=IF(YEAR(AE$3)=2026,0,ROUND(EXP(0.091*((YEAR(AE$3)-2027)*12+MONTH(AE$3)-1))/SUMPRODUCT(EXP(0.091*(ROW(INDIRECT("1:24"))-1)))*SUM(Assumptions!$D$22:$E$22),0))} -> 58 | AF6: {=IF(YEAR(AF$3)=2026,0,ROUND(EXP(0.091*((YEAR(AF$3)-2027)*12+MONTH(AF$3)-1))/SUMPRODUCT(EXP(0.091*(ROW(INDIRECT("1:24"))-1)))*SUM(Assumptions!$D$22:$E$22),0))} -> 64 | AG6: {=IF(YEAR(AG$3)=2026,0,ROUND(EXP(0.091*((YEAR(AG$3)-2027)*12+MONTH(AG$3)-1))/SUMPRODUCT(EXP(0.091*(ROW(INDIRECT("1:24"))-1)))*SUM(Assumptions!$D$22:$E$22),0))} -> 70 | AH6: {=IF(YEAR(AH$3)=2026,0,ROUND(EXP(0.091*((YEAR(AH$3)-2027)*12+MONTH(AH$3)-1))/SUMPRODUCT(EXP(0.091*(ROW(INDIRECT("1:24"))-1)))*SUM(Assumptions!$D$22:$E$22),0))} -> 76 | AI6: {=IF(YEAR(AI$3)=2026,0,ROUND(EXP(0.091*((YEAR(AI$3)-2027)*12+MONTH(AI$3)-1))/SUMPRODUCT(EXP(0.091*(ROW(INDIRECT("1:24"))-1)))*SUM(Assumptions!$D$22:$E$22),0))} -> 83 | AJ6: {=IF(YEAR(AJ$3)=2026,0,ROUND(EXP(0.091*((YEAR(AJ$3)-2027)*12+MONTH(AJ$3)-1))/SUMPRODUCT(EXP(0.091*(ROW(INDIRECT("1:24"))-1)))*SUM(Assumptions!$D$22:$E$22),0))} -> 91 | ... AN6: {=IF(YEAR(AN$3)=2026,0,ROUND(EXP(0.091*((YEAR(AN$3)-2027)*12+MONTH(AN$3)-1))/SUMPRODUCT(EXP(0.091*(ROW(INDIRECT("1:24"))-1)))*SUM(Assumptions!$D$22:$E$22),0))} -> 132 | AO6: {=IF(YEAR(AO$3)=2026,0,ROUND(EXP(0.0915*((YEAR(AO$3)-2027)*12+MONTH(AO$3)-1))/SUMPRODUCT(EXP(0.0915*(ROW(INDIRECT("1:24"))-1)))*SUM(Assumptions!$D$22:$E$22),0))} -> 144 | AP6: {=IF(YEAR(AP$3)=2026,0,ROUND(EXP(0.0915*((YEAR(AP$3)-2027)*12+MONTH(AP$3)-1))/SUMPRODUCT(EXP(0.0915*(ROW(INDIRECT("1:24"))-1)))*SUM(Assumptions!$D$22:$E$22),0))} -> 158 | AQ6: {=IF(YEAR(AQ$3)=2026,0,ROUND(EXP(0.0915*((YEAR(AQ$3)-2027)*12+MONTH(AQ$3)-1))/SUMPRODUCT(EXP(0.0915*(ROW(INDIRECT("1:24"))-1)))*SUM(Assumptions!$D$22:$E$22),0))} -> 173 | AR6: {=IF(YEAR(AR$3)=2026,0,ROUND(EXP(0.0915*((YEAR(AR$3)-2027)*12+MONTH(AR$3)-1))/SUMPRODUCT(EXP(0.0915*(ROW(INDIRECT("1:24"))-1)))*SUM(Assumptions!$D$22:$E$22),0))} -> 189 | AS6: {=IF(YEAR(AS$3)=2026,0,ROUND(EXP(0.0915*((YEAR(AS$3)-2027)*12+MONTH(AS$3)-1))/SUMPRODUCT(EXP(0.0915*(ROW(INDIRECT("1:24"))-1)))*SUM(Assumptions!$D$22:$E$22),0))} -> 207 | AT6: {=IF(YEAR(AT$3)=2026,0,ROUND(EXP(0.0915*((YEAR(AT$3)-2027)*12+MONTH(AT$3)-1))/SUMPRODUCT(EXP(0.0915*(ROW(INDIRECT("1:24"))-1)))*SUM(Assumptions!$D$22:$E$22),0))} -> 227 | AU6: {=IF(YEAR(AU$3)=2026,0,ROUND(EXP(0.0915*((YEAR(AU$3)-2027)*12+MONTH(AU$3)-1))/SUMPRODUCT(EXP(0.0915*(ROW(INDIRECT("1:24"))-1)))*SUM(Assumptions!$D$22:$E$22),0))} -> 249 | AV6: {=IF(YEAR(AV$3)=2026,0,ROUND(EXP(0.0915*((YEAR(AV$3)-2027)*12+MONTH(AV$3)-1))/SUMPRODUCT(EXP(0.0915*(ROW(INDIRECT("1:24"))-1)))*SUM(Assumptions!$D$22:$E$22),0))} -> 273 | ... AZ6: {=IF(YEAR(AZ$3)=2026,0,ROUND(EXP(0.0915*((YEAR(AZ$3)-2027)*12+MONTH(AZ$3)-1))/SUMPRODUCT(EXP(0.0915*(ROW(INDIRECT("1:24"))-1)))*SUM(Assumptions!$D$22:$E$22),0))} -> 394 | BB6: =SUM(E6:P6) -> 0 | BC6: =SUM(Q6:AB6) -> 0 | BD6: =SUM(AC6:AN6) -> 1005 | BE6: =SUM(AO6:AZ6) -> 3000 | BF6: =BE6*2 -> 6000
B7: TTK Revenue | D7: € | Q7: =Q6*Assumptions!$C$28 -> 0 | R7: =R6*Assumptions!$C$28 -> 0 | S7: =S6*Assumptions!$C$28 -> 0 | T7: =T6*Assumptions!$C$28 -> 0 | U7: =U6*Assumptions!$C$28 -> 0 | V7: =V6*Assumptions!$C$28 -> 0 | W7: =W6*Assumptions!$C$28 -> 0 | X7: =X6*Assumptions!$C$28 -> 0 | ... AZ7: =AZ6*Assumptions!$C$28 -> 3191074.4 | BB7: =SUM(E7:P7) -> 0 | BC7: =SUM(Q7:AB7) -> 0 | BD7: =SUM(AC7:AN7) -> 8139669.4 | BE7: =SUM(AO7:AZ7) -> 24297521 | BF7: =BF6*Assumptions!$C$28 -> 48595041
B8: TTK upsell | D8: € | Q8: =Q6*SUMPRODUCT(Assumptions!$E$113:$F$116) -> 0 | R8: =R6*SUMPRODUCT(Assumptions!$E$113:$F$116) -> 0 | S8: =S6*SUMPRODUCT(Assumptions!$E$113:$F$116) -> 0 | T8: =T6*SUMPRODUCT(Assumptions!$E$113:$F$116) -> 0 | U8: =U6*SUMPRODUCT(Assumptions!$E$113:$F$116) -> 0 | V8: =V6*SUMPRODUCT(Assumptions!$E$113:$F$116) -> 0 | W8: =W6*SUMPRODUCT(Assumptions!$E$113:$F$116) -> 0 | X8: =X6*SUMPRODUCT(Assumptions!$E$113:$F$116) -> 0 | ... AB8: =AB6*SUMPRODUCT(Assumptions!$E$113:$F$116) -> 0 | AC8: =AC6*SUMPRODUCT(Assumptions!$E$113:$E$116,Assumptions!$F$113:$F$116) -> 95543.802 | AD8: =AD6*SUMPRODUCT(Assumptions!$E$113:$E$116,Assumptions!$F$113:$F$116) -> 105496.28 | AE8: =AE6*SUMPRODUCT(Assumptions!$E$113:$E$116,Assumptions!$F$113:$F$116) -> 115448.76 | AF8: =AF6*SUMPRODUCT(Assumptions!$E$113:$E$116,Assumptions!$F$113:$F$116) -> 127391.74 | AG8: =AG6*SUMPRODUCT(Assumptions!$E$113:$E$116,Assumptions!$F$113:$F$116) -> 139334.71 | AH8: =AH6*SUMPRODUCT(Assumptions!$E$113:$E$116,Assumptions!$F$113:$F$116) -> 151277.69 | AI8: =AI6*SUMPRODUCT(Assumptions!$E$113:$E$116,Assumptions!$F$113:$F$116) -> 165211.16 | AJ8: =AJ6*SUMPRODUCT(Assumptions!$E$113:$E$116,Assumptions!$F$113:$F$116) -> 181135.12 | ... AZ8: =AZ6*SUMPRODUCT(Assumptions!$E$113:$E$116,Assumptions!$F$113:$F$116) -> 784255.37 | BB8: =SUM(E8:P8) -> 0 | BC8: =SUM(Q8:AB8) -> 0 | BD8: =SUM(AC8:AN8) -> 2000448.3 | BE8: =SUM(AO8:AZ8) -> 5971487.6 | BF8: =BF6*SUMPRODUCT(Assumptions!$E$113:$E$116,Assumptions!$F$113:$F$116) -> 11942975
B9: Total TTK Revenue | D9: € | Q9: =sum(Q7:Q8) -> 0 | R9: =sum(R7:R8) -> 0 | S9: =sum(S7:S8) -> 0 | T9: =sum(T7:T8) -> 0 | U9: =sum(U7:U8) -> 0 | V9: =sum(V7:V8) -> 0 | W9: =sum(W7:W8) -> 0 | X9: =sum(X7:X8) -> 0 | ... AZ9: =sum(AZ7:AZ8) -> 3975329.8 | BB9: =SUM(E9:P9) -> 0 | BC9: =SUM(Q9:AB9) -> 0 | BD9: =SUM(AC9:AN9) -> 10140118 | BE9: =SUM(AO9:AZ9) -> 30269008 | BF9: =BE9*2 -> 60538017
B11: TARNOC MINI
B12: Mini units sold | D12: # | Q12: {=IF(YEAR(Q$3)=2026,0,ROUND(EXP(0.11*((YEAR(Q$3)-2027)*12+MONTH(Q$3)-1))/SUMPRODUCT(EXP(0.11*(ROW(INDIRECT("1:24"))-1)))*SUM(Assumptions!$D$23:$E$23),0))} -> 0 | R12: {=IF(YEAR(R$3)=2026,0,ROUND(EXP(0.11*((YEAR(R$3)-2027)*12+MONTH(R$3)-1))/SUMPRODUCT(EXP(0.11*(ROW(INDIRECT("1:24"))-1)))*SUM(Assumptions!$D$23:$E$23),0))} -> 0 | S12: {=IF(YEAR(S$3)=2026,0,ROUND(EXP(0.11*((YEAR(S$3)-2027)*12+MONTH(S$3)-1))/SUMPRODUCT(EXP(0.11*(ROW(INDIRECT("1:24"))-1)))*SUM(Assumptions!$D$23:$E$23),0))} -> 0 | T12: {=IF(YEAR(T$3)=2026,0,ROUND(EXP(0.11*((YEAR(T$3)-2027)*12+MONTH(T$3)-1))/SUMPRODUCT(EXP(0.11*(ROW(INDIRECT("1:24"))-1)))*SUM(Assumptions!$D$23:$E$23),0))} -> 0 | U12: {=IF(YEAR(U$3)=2026,0,ROUND(EXP(0.11*((YEAR(U$3)-2027)*12+MONTH(U$3)-1))/SUMPRODUCT(EXP(0.11*(ROW(INDIRECT("1:24"))-1)))*SUM(Assumptions!$D$23:$E$23),0))} -> 0 | V12: {=IF(YEAR(V$3)=2026,0,ROUND(EXP(0.11*((YEAR(V$3)-2027)*12+MONTH(V$3)-1))/SUMPRODUCT(EXP(0.11*(ROW(INDIRECT("1:24"))-1)))*SUM(Assumptions!$D$23:$E$23),0))} -> 0 | W12: {=IF(YEAR(W$3)=2026,0,ROUND(EXP(0.11*((YEAR(W$3)-2027)*12+MONTH(W$3)-1))/SUMPRODUCT(EXP(0.11*(ROW(INDIRECT("1:24"))-1)))*SUM(Assumptions!$D$23:$E$23),0))} -> 0 | X12: {=IF(YEAR(X$3)=2026,0,ROUND(EXP(0.11*((YEAR(X$3)-2027)*12+MONTH(X$3)-1))/SUMPRODUCT(EXP(0.11*(ROW(INDIRECT("1:24"))-1)))*SUM(Assumptions!$D$23:$E$23),0))} -> 0 | ... AB12: {=IF(YEAR(AB$3)=2026,0,ROUND(EXP(0.11*((YEAR(AB$3)-2027)*12+MONTH(AB$3)-1))/SUMPRODUCT(EXP(0.11*(ROW(INDIRECT("1:24"))-1)))*SUM(Assumptions!$D$23:$E$23),0))} -> 0 | AC12: {=IF(YEAR(AC$3)=2026,0,ROUND(EXP(0.116*((YEAR(AC$3)-2027)*12+MONTH(AC$3)-1))/SUMPRODUCT(EXP(0.116*(ROW(INDIRECT("1:24"))-1)))*SUM(Assumptions!$D$23:$E$23),0))} -> 20 | AD12: {=IF(YEAR(AD$3)=2026,0,ROUND(EXP(0.116*((YEAR(AD$3)-2027)*12+MONTH(AD$3)-1))/SUMPRODUCT(EXP(0.116*(ROW(INDIRECT("1:24"))-1)))*SUM(Assumptions!$D$23:$E$23),0))} -> 23 | AE12: {=IF(YEAR(AE$3)=2026,0,ROUND(EXP(0.116*((YEAR(AE$3)-2027)*12+MONTH(AE$3)-1))/SUMPRODUCT(EXP(0.116*(ROW(INDIRECT("1:24"))-1)))*SUM(Assumptions!$D$23:$E$23),0))} -> 26 | AF12: {=IF(YEAR(AF$3)=2026,0,ROUND(EXP(0.116*((YEAR(AF$3)-2027)*12+MONTH(AF$3)-1))/SUMPRODUCT(EXP(0.116*(ROW(INDIRECT("1:24"))-1)))*SUM(Assumptions!$D$23:$E$23),0))} -> 29 | AG12: {=IF(YEAR(AG$3)=2026,0,ROUND(EXP(0.116*((YEAR(AG$3)-2027)*12+MONTH(AG$3)-1))/SUMPRODUCT(EXP(0.116*(ROW(INDIRECT("1:24"))-1)))*SUM(Assumptions!$D$23:$E$23),0))} -> 32 | AH12: {=IF(YEAR(AH$3)=2026,0,ROUND(EXP(0.116*((YEAR(AH$3)-2027)*12+MONTH(AH$3)-1))/SUMPRODUCT(EXP(0.116*(ROW(INDIRECT("1:24"))-1)))*SUM(Assumptions!$D$23:$E$23),0))} -> 36 | AI12: {=IF(YEAR(AI$3)=2026,0,ROUND(EXP(0.116*((YEAR(AI$3)-2027)*12+MONTH(AI$3)-1))/SUMPRODUCT(EXP(0.116*(ROW(INDIRECT("1:24"))-1)))*SUM(Assumptions!$D$23:$E$23),0))} -> 41 | AJ12: {=IF(YEAR(AJ$3)=2026,0,ROUND(EXP(0.116*((YEAR(AJ$3)-2027)*12+MONTH(AJ$3)-1))/SUMPRODUCT(EXP(0.116*(ROW(INDIRECT("1:24"))-1)))*SUM(Assumptions!$D$23:$E$23),0))} -> 46 | ... AN12: {=IF(YEAR(AN$3)=2026,0,ROUND(EXP(0.116*((YEAR(AN$3)-2027)*12+MONTH(AN$3)-1))/SUMPRODUCT(EXP(0.116*(ROW(INDIRECT("1:24"))-1)))*SUM(Assumptions!$D$23:$E$23),0))} -> 73 | AO12: {=IF(YEAR(AO$3)=2026,0,ROUND(EXP(0.1157*((YEAR(AO$3)-2027)*12+MONTH(AO$3)-1))/SUMPRODUCT(EXP(0.1157*(ROW(INDIRECT("1:24"))-1)))*SUM(Assumptions!$D$23:$E$23),0))} -> 82 | AP12: {=IF(YEAR(AP$3)=2026,0,ROUND(EXP(0.1157*((YEAR(AP$3)-2027)*12+MONTH(AP$3)-1))/SUMPRODUCT(EXP(0.1157*(ROW(INDIRECT("1:24"))-1)))*SUM(Assumptions!$D$23:$E$23),0))} -> 92 | AQ12: {=IF(YEAR(AQ$3)=2026,0,ROUND(EXP(0.1157*((YEAR(AQ$3)-2027)*12+MONTH(AQ$3)-1))/SUMPRODUCT(EXP(0.1157*(ROW(INDIRECT("1:24"))-1)))*SUM(Assumptions!$D$23:$E$23),0))} -> 103 | AR12: {=IF(YEAR(AR$3)=2026,0,ROUND(EXP(0.1157*((YEAR(AR$3)-2027)*12+MONTH(AR$3)-1))/SUMPRODUCT(EXP(0.1157*(ROW(INDIRECT("1:24"))-1)))*SUM(Assumptions!$D$23:$E$23),0))} -> 115 | AS12: {=IF(YEAR(AS$3)=2026,0,ROUND(EXP(0.1157*((YEAR(AS$3)-2027)*12+MONTH(AS$3)-1))/SUMPRODUCT(EXP(0.1157*(ROW(INDIRECT("1:24"))-1)))*SUM(Assumptions!$D$23:$E$23),0))} -> 130 | AT12: {=IF(YEAR(AT$3)=2026,0,ROUND(EXP(0.1157*((YEAR(AT$3)-2027)*12+MONTH(AT$3)-1))/SUMPRODUCT(EXP(0.1157*(ROW(INDIRECT("1:24"))-1)))*SUM(Assumptions!$D$23:$E$23),0))} -> 145 | AU12: {=IF(YEAR(AU$3)=2026,0,ROUND(EXP(0.1157*((YEAR(AU$3)-2027)*12+MONTH(AU$3)-1))/SUMPRODUCT(EXP(0.1157*(ROW(INDIRECT("1:24"))-1)))*SUM(Assumptions!$D$23:$E$23),0))} -> 163 | AV12: {=IF(YEAR(AV$3)=2026,0,ROUND(EXP(0.1157*((YEAR(AV$3)-2027)*12+MONTH(AV$3)-1))/SUMPRODUCT(EXP(0.1157*(ROW(INDIRECT("1:24"))-1)))*SUM(Assumptions!$D$23:$E$23),0))} -> 183 | ... AZ12: {=IF(YEAR(AZ$3)=2026,0,ROUND(EXP(0.1157*((YEAR(AZ$3)-2027)*12+MONTH(AZ$3)-1))/SUMPRODUCT(EXP(0.1157*(ROW(INDIRECT("1:24"))-1)))*SUM(Assumptions!$D$23:$E$23),0))} -> 291 | BB12: =SUM(E12:P12) -> 0 | BC12: =SUM(Q12:AB12) -> 0 | BD12: =SUM(AC12:AN12) -> 500 | BE12: =SUM(AO12:AZ12) -> 2000 | BF12: =BE12*2 -> 4000
B13: Mini Revenue | D13: € | Q13: =Q12*Assumptions!$C$31 -> 0 | R13: =R12*Assumptions!$C$31 -> 0 | S13: =S12*Assumptions!$C$31 -> 0 | T13: =T12*Assumptions!$C$31 -> 0 | U13: =U12*Assumptions!$C$31 -> 0 | V13: =V12*Assumptions!$C$31 -> 0 | W13: =W12*Assumptions!$C$31 -> 0 | X13: =X12*Assumptions!$C$31 -> 0 | ... AZ13: =AZ12*Assumptions!$C$31 -> 805661.16 | BB13: =SUM(E13:P13) -> 0 | BC13: =SUM(Q13:AB13) -> 0 | BD13: =SUM(AC13:AN13) -> 1384297.5 | BE13: =SUM(AO13:AZ13) -> 5537190.1 | BF13: =BF12*Assumptions!$C$31 -> 11074380
B14: Mini upsell | D14: € | Q14: =Q12*PRODUCT(Assumptions!$E$122:$F$122) -> 0 | R14: =R12*PRODUCT(Assumptions!$E$122:$F$122) -> 0 | S14: =S12*PRODUCT(Assumptions!$E$122:$F$122) -> 0 | T14: =T12*PRODUCT(Assumptions!$E$122:$F$122) -> 0 | U14: =U12*PRODUCT(Assumptions!$E$122:$F$122) -> 0 | V14: =V12*PRODUCT(Assumptions!$E$122:$F$122) -> 0 | W14: =W12*PRODUCT(Assumptions!$E$122:$F$122) -> 0 | X14: =X12*PRODUCT(Assumptions!$E$122:$F$122) -> 0 | ... AZ14: =AZ12*PRODUCT(Assumptions!$E$122:$F$122) -> 39867 | BB14: =SUM(E14:P14) -> 0 | BC14: =SUM(Q14:AB14) -> 0 | BD14: =SUM(AC14:AN14) -> 68500 | BE14: =SUM(AO14:AZ14) -> 274000 | BF14: =BF12*PRODUCT(Assumptions!$E$122:$F$122) -> 548000
B15: Total Mini Revenue | D15: € | Q15: =sum(Q13:Q14) -> 0 | R15: =sum(R13:R14) -> 0 | S15: =sum(S13:S14) -> 0 | T15: =sum(T13:T14) -> 0 | U15: =sum(U13:U14) -> 0 | V15: =sum(V13:V14) -> 0 | W15: =sum(W13:W14) -> 0 | X15: =sum(X13:X14) -> 0 | ... AZ15: =sum(AZ13:AZ14) -> 845528.16 | BB15: =SUM(E15:P15) -> 0 | BC15: =SUM(Q15:AB15) -> 0 | BD15: =SUM(AC15:AN15) -> 1452797.5 | BE15: =SUM(AO15:AZ15) -> 5811190.1 | BF15: =BE15*2 -> 11622380
B17: INSTALLATION REVENUES | D17: €
B18: Units installed | D18: # | Q18: =Q12+Q6 -> 0 | R18: =R12+R6 -> 0 | S18: =S12+S6 -> 0 | T18: =T12+T6 -> 0 | U18: =U12+U6 -> 0 | V18: =V12+V6 -> 0 | W18: =W12+W6 -> 0 | X18: =X12+X6 -> 0 | ... AZ18: =AZ12+AZ6 -> 685 | BB18: =SUM(E18:P18) -> 0 | BC18: =SUM(Q18:AB18) -> 0 | BD18: =SUM(AC18:AN18) -> 1505 | BE18: =SUM(AO18:AZ18) -> 5000 | BF18: =BF6+BF12 -> 10000
B19: Total Installation Revenue | D19: € | Q19: =Q18*Assumptions!$C$33 -> 0 | R19: =R18*Assumptions!$C$33 -> 0 | S19: =S18*Assumptions!$C$33 -> 0 | T19: =T18*Assumptions!$C$33 -> 0 | U19: =U18*Assumptions!$C$33 -> 0 | V19: =V18*Assumptions!$C$33 -> 0 | W19: =W18*Assumptions!$C$33 -> 0 | X19: =X18*Assumptions!$C$33 -> 0 | ... AZ19: =AZ18*Assumptions!$C$33 -> 2192000 | BB19: =SUM(E19:P19) -> 0 | BC19: =SUM(Q19:AB19) -> 0 | BD19: =SUM(AC19:AN19) -> 4816000 | BE19: =SUM(AO19:AZ19) -> 16000000 | BF19: =BE19*2 -> 32000000
B21: SERVICE REVENUES
B22: Installed base (TTK) | D22: # | Q22: =Q6 -> 0 | R22: =R6 -> 0 | S22: =S6 -> 0 | T22: =T6 -> 0 | U22: =U6 -> 0 | V22: =V6 -> 0 | W22: =W6 -> 0 | X22: =X6 -> 0 | ... AC22: =AC6 -> 48 | AD22: =AC22+AD6 -> 101 | AE22: =AD22+AE6 -> 159 | AF22: =AE22+AF6 -> 223 | AG22: =AF22+AG6 -> 293 | AH22: =AG22+AH6 -> 369 | AI22: =AH22+AI6 -> 452 | AJ22: =AI22+AJ6 -> 543 | AK22: =AJ22+AK6 -> 643 | ... AZ22: =AY22+AZ6 -> 4005 | BB22: =SUM(E22:P22) -> 0 | BC22: =SUM(Q22:AB22) -> 0 | BD22: =AN22 -> 1005 | BE22: =AZ22 -> 4005 | BF22: =BF18*55% -> 5500
B23: Installed base (Mini) | D23: # | Q23: =Q12 -> 0 | R23: =R12 -> 0 | S23: =S12 -> 0 | T23: =T12 -> 0 | U23: =U12 -> 0 | V23: =V12 -> 0 | W23: =W12 -> 0 | X23: =X12 -> 0 | ... AC23: =AC12 -> 20 | AD23: =AC23+AD12 -> 43 | AE23: =AD23+AE12 -> 69 | AF23: =AE23+AF12 -> 98 | AG23: =AF23+AG12 -> 130 | AH23: =AG23+AH12 -> 166 | AI23: =AH23+AI12 -> 207 | AJ23: =AI23+AJ12 -> 253 | AK23: =AJ23+AK12 -> 304 | ... AZ23: =AY23+AZ12 -> 2500 | BB23: =SUM(E23:P23) -> 0 | BC23: =SUM(Q23:AB23) -> 0 | BD23: =AN23 -> 500 | BE23: =AZ23 -> 2500 | BF23: =BF18*0.45 -> 4500
B24: Total Service Revenue | D24: € | Q24: =Q34*SUMPRODUCT(Assumptions!$E$126:$E$127,Assumptions!$F$126:$F$127) -> 0 | R24: =R34*SUMPRODUCT(Assumptions!$E$126:$E$127,Assumptions!$F$126:$F$127) -> 0 | S24: =S34*SUMPRODUCT(Assumptions!$E$126:$E$127,Assumptions!$F$126:$F$127) -> 0 | T24: =T34*SUMPRODUCT(Assumptions!$E$126:$E$127,Assumptions!$F$126:$F$127) -> 0 | U24: =U34*SUMPRODUCT(Assumptions!$E$126:$E$127,Assumptions!$F$126:$F$127) -> 0 | V24: =V34*SUMPRODUCT(Assumptions!$E$126:$E$127,Assumptions!$F$126:$F$127) -> 0 | W24: =W34*SUMPRODUCT(Assumptions!$E$126:$E$127,Assumptions!$F$126:$F$127) -> 0 | X24: =X34*SUMPRODUCT(Assumptions!$E$126:$E$127,Assumptions!$F$126:$F$127) -> 0 | ... AB24: =AB34*SUMPRODUCT(Assumptions!$E$126:$E$127,Assumptions!$F$126:$F$127) -> 0 | AC24: =AC34*SUMPRODUCT(Assumptions!$E$126:$E$127,Assumptions!$F$126:$F$127)+Q24 -> 4692 | AD24: =AD34*SUMPRODUCT(Assumptions!$E$126:$E$127,Assumptions!$F$126:$F$127)+R24 -> 5244 | AE24: =AE34*SUMPRODUCT(Assumptions!$E$126:$E$127,Assumptions!$F$126:$F$127)+S24 -> 5796 | AF24: =AF34*SUMPRODUCT(Assumptions!$E$126:$E$127,Assumptions!$F$126:$F$127)+T24 -> 6417 | AG24: =AG34*SUMPRODUCT(Assumptions!$E$126:$E$127,Assumptions!$F$126:$F$127)+U24 -> 7038 | AH24: =AH34*SUMPRODUCT(Assumptions!$E$126:$E$127,Assumptions!$F$126:$F$127)+V24 -> 7728 | AI24: =AI34*SUMPRODUCT(Assumptions!$E$126:$E$127,Assumptions!$F$126:$F$127)+W24 -> 8556 | AJ24: =AJ34*SUMPRODUCT(Assumptions!$E$126:$E$127,Assumptions!$F$126:$F$127)+X24 -> 9453 | ... AZ24: =AZ34*SUMPRODUCT(Assumptions!$E$126:$E$127,Assumptions!$F$126:$F$127)+AN24 -> 61410 | BB24: =SUM(E24:P24) -> 0 | BC24: =SUM(Q24:AB24) -> 0 | BD24: =SUM(AC24:AN24) -> 103845 | BE24: =SUM(AO24:AZ24) -> 448845 | BF24: =(BE24*2)+BE24 -> 1346535
B26: SUBSIDIES & GRANTS
B27: All other | D27: € | E27: 0 | F27: 0 | G27: 0 | H27: 0 | I27: 0 | J27: 0 | K27: 0 | L27: 0 | M27: 0 | N27: 19480 | O27: 78000 | P27: 0 | Q27: 0 | R27: 0 | S27: 0 | T27: 0 | U27: 0 | V27: 106782 | W27: 0 | X27: 0 | Y27: 0 | Z27: 0 | AA27: 0 | AB27: 0 | AC27: 0 | AD27: 0 | AE27: 0 | AF27: 0 | AG27: 0 | AH27: 0 | AI27: 0 | AJ27: 0 | AK27: 0 | AL27: 0 | AM27: 0 | AN27: 0 | AO27: 0 | AP27: 0 | AQ27: 0 | AR27: 0 | AS27: 0 | AT27: 0 | AU27: 0 | AV27: 0 | AW27: 0 | AX27: 0 | AY27: 0 | AZ27: 0 | BB27: =SUM(E27:P27) -> 97480 | BC27: =SUM(Q27:AB27) -> 106782 | BD27: =SUM(AC27:AN27) -> 0 | BE27: =SUM(AO27:AZ27) -> 0 | BF27: 0
B28: Total Subsidies & Grants | D28: € | E28: =sum(E27) -> 0 | F28: =sum(F27) -> 0 | G28: =sum(G27) -> 0 | H28: =sum(H27) -> 0 | I28: =sum(I27) -> 0 | J28: =sum(J27) -> 0 | K28: =sum(K27) -> 0 | L28: =sum(L27) -> 0 | ... AZ28: =sum(AZ27) -> 0 | BB28: =SUM(E28:P28) -> 97480 | BC28: =SUM(Q28:AB28) -> 106782 | BD28: =BD27 -> 0 | BE28: =BE27 -> 0 | BF28: =BF27 -> 0
B30: TOTAL REVENUE | E30: =E15+E9+E19+E24+E28 -> 0 | F30: =F15+F9+F19+F24+F28 -> 0 | G30: =G15+G9+G19+G24+G28 -> 0 | H30: =H15+H9+H19+H24+H28 -> 0 | I30: =I15+I9+I19+I24+I28 -> 0 | J30: =J15+J9+J19+J24+J28 -> 0 | K30: =K15+K9+K19+K24+K28 -> 0 | L30: =L15+L9+L19+L24+L28 -> 0 | ... AZ30: =AZ15+AZ9+AZ19+AZ24+AZ28 -> 7074267.9 | BB30: =BB9+BB15+BB28+BB19+BB24 -> 97480 | BC30: =BC9+BC15+BC28+BC19+BC24 -> 106782 | BD30: =SUM(AC30:AN30) -> 16512760 | BE30: =SUM(AO30:AZ30) -> 52529043 | BF30: =BF9+BF15+BF28+BF19+BF24 -> 1.0550693e+08
B33: Installed Base | AC33: =sum(AC22:AC23) -> 68 | AD33: =sum(AD22:AD23) -> 144 | AE33: =sum(AE22:AE23) -> 228 | AF33: =sum(AF22:AF23) -> 321 | AG33: =sum(AG22:AG23) -> 423 | AH33: =sum(AH22:AH23) -> 535 | AI33: =sum(AI22:AI23) -> 659 | AJ33: =sum(AJ22:AJ23) -> 796 | ... AZ33: =sum(AZ22:AZ23) -> 6505 | BB33: =sum(BB22:BB23) -> 0 | BC33: =sum(BC22:BC23) -> 0 | BD33: =sum(BD22:BD23) -> 1505 | BE33: =sum(BE22:BE23) -> 6505 | BF33: =sum(BF22:BF23) -> 10000
B34: Units sold | D34: # | Q34: =Q12+Q6 -> 0 | R34: =R12+R6 -> 0 | S34: =S12+S6 -> 0 | T34: =T12+T6 -> 0 | U34: =U12+U6 -> 0 | V34: =V12+V6 -> 0 | W34: =W12+W6 -> 0 | X34: =X12+X6 -> 0 | ... AZ34: =AZ12+AZ6 -> 685 | BB34: 0 | BC34: 0 | BD34: =SUM(AC34:AN34) -> 1505 | BE34: =SUM(AO34:AZ34) -> 5000 | BF34: =BF18 -> 10000

Sheet COGS
B1: Tarnoc B.V. — COGS Schedule (€)
E2: 2025 | Q2: 2026 | AC2: 2027 | AO2: 2028
E3: 45658 | F3: 45689 | G3: 45717 | H3: 45748 | I3: 45778 | J3: 45809 | K3: 45839 | L3: 45870 | M3: 45901 | N3: 45931 | O3: 45962 | P3: 45992 | Q3: 46023 | R3: 46054 | S3: 46082 | T3: 46113 | U3: 46143 | V3: 46174 | W3: 46204 | X3: 46235 | Y3: 46266 | Z3: 46296 | AA3: 46327 | AB3: 46357 | AC3: 46388 | AD3: 46419 | AE3: 46447 | AF3: 46478 | AG3: 46508 | AH3: 46539 | AI3: 46569 | AJ3: 46600 | AK3: 46631 | AL3: 46661 | AM3: 46692 | AN3: 46722 | AO3: 46753 | AP3: 46784 | AQ3: 46813 | AR3: 46844 | AS3: 46874 | AT3: 46905 | AU3: 46935 | AV3: 46966 | AW3: 46997 | AX3: 47027 | AY3: 47058 | AZ3: 47088 | BB3: 2025 | BC3: 2026 | BD3: 2027 | BE3: 2028 | BF3: 2029
B6: TTK
B7: TTK | D7: € | Q7: =IFNA('Revenue Forecast'!Q6 * VLOOKUP('Revenue Forecast'!$BC$6, Assumptions!$B$67:$C$69, 2, TRUE), 0) -> 0 | R7: =IFNA('Revenue Forecast'!R6 * VLOOKUP('Revenue Forecast'!$BC$6, Assumptions!$B$67:$C$69, 2, TRUE), 0) -> 0 | S7: =IFNA('Revenue Forecast'!S6 * VLOOKUP('Revenue Forecast'!$BC$6, Assumptions!$B$67:$C$69, 2, TRUE), 0) -> 0 | T7: =IFNA('Revenue Forecast'!T6 * VLOOKUP('Revenue Forecast'!$BC$6, Assumptions!$B$67:$C$69, 2, TRUE), 0) -> 0 | U7: =IFNA('Revenue Forecast'!U6 * VLOOKUP('Revenue Forecast'!$BC$6, Assumptions!$B$67:$C$69, 2, TRUE), 0) -> 0 | V7: =IFNA('Revenue Forecast'!V6 * VLOOKUP('Revenue Forecast'!$BC$6, Assumptions!$B$67:$C$69, 2, TRUE), 0) -> 0 | W7: =IFNA('Revenue Forecast'!W6 * VLOOKUP('Revenue Forecast'!$BC$6, Assumptions!$B$67:$C$69, 2, TRUE), 0) -> 0 | X7: =IFNA('Revenue Forecast'!X6 * VLOOKUP('Revenue Forecast'!$BC$6, Assumptions!$B$67:$C$69, 2, TRUE), 0) -> 0 | ... AB7: =IFNA('Revenue Forecast'!AB6 * VLOOKUP('Revenue Forecast'!$BC$6, Assumptions!$B$67:$C$69, 2, TRUE), 0) -> 0 | AC7: ='Revenue Forecast'!AC6*VLOOKUP('Revenue Forecast'!$BD$6+'Revenue Forecast'!$BE$6,Assumptions!$B$67:$C$69,2,TRUE) -> 479948.16 | AD7: ='Revenue Forecast'!AD6*VLOOKUP('Revenue Forecast'!$BD$6+'Revenue Forecast'!$BE$6,Assumptions!$B$67:$C$69,2,TRUE) -> 529942.76 | AE7: ='Revenue Forecast'!AE6*VLOOKUP('Revenue Forecast'!$BD$6+'Revenue Forecast'!$BE$6,Assumptions!$B$67:$C$69,2,TRUE) -> 579937.36 | AF7: ='Revenue Forecast'!AF6*VLOOKUP('Revenue Forecast'!$BD$6+'Revenue Forecast'!$BE$6,Assumptions!$B$67:$C$69,2,TRUE) -> 639930.88 | AG7: ='Revenue Forecast'!AG6*VLOOKUP('Revenue Forecast'!$BD$6+'Revenue Forecast'!$BE$6,Assumptions!$B$67:$C$69,2,TRUE) -> 699924.4 | AH7: ='Revenue Forecast'!AH6*VLOOKUP('Revenue Forecast'!$BD$6+'Revenue Forecast'!$BE$6,Assumptions!$B$67:$C$69,2,TRUE) -> 759917.92 | AI7: ='Revenue Forecast'!AI6*VLOOKUP('Revenue Forecast'!$BD$6+'Revenue Forecast'!$BE$6,Assumptions!$B$67:$C$69,2,TRUE) -> 829910.36 | AJ7: ='Revenue Forecast'!AJ6*VLOOKUP('Revenue Forecast'!$BD$6+'Revenue Forecast'!$BE$6,Assumptions!$B$67:$C$69,2,TRUE) -> 909901.72 | ... AN7: ='Revenue Forecast'!AN6*VLOOKUP('Revenue Forecast'!$BD$6+'Revenue Forecast'!$BE$6,Assumptions!$B$67:$C$69,2,TRUE) -> 1319857.4 | AO7: ='Revenue Forecast'!AO6*VLOOKUP('Revenue Forecast'!$BE$6+'Revenue Forecast'!$BF$6,Assumptions!$B$67:$C$69,2,TRUE) -> 1019439.9 | AP7: ='Revenue Forecast'!AP6*VLOOKUP('Revenue Forecast'!$BE$6+'Revenue Forecast'!$BF$6,Assumptions!$B$67:$C$69,2,TRUE) -> 1118552.2 | AQ7: ='Revenue Forecast'!AQ6*VLOOKUP('Revenue Forecast'!$BE$6+'Revenue Forecast'!$BF$6,Assumptions!$B$67:$C$69,2,TRUE) -> 1224743.8 | AR7: ='Revenue Forecast'!AR6*VLOOKUP('Revenue Forecast'!$BE$6+'Revenue Forecast'!$BF$6,Assumptions!$B$67:$C$69,2,TRUE) -> 1338014.9 | AS7: ='Revenue Forecast'!AS6*VLOOKUP('Revenue Forecast'!$BE$6+'Revenue Forecast'!$BF$6,Assumptions!$B$67:$C$69,2,TRUE) -> 1465444.9 | AT7: ='Revenue Forecast'!AT6*VLOOKUP('Revenue Forecast'!$BE$6+'Revenue Forecast'!$BF$6,Assumptions!$B$67:$C$69,2,TRUE) -> 1607033.8 | AU7: ='Revenue Forecast'!AU6*VLOOKUP('Revenue Forecast'!$BE$6+'Revenue Forecast'!$BF$6,Assumptions!$B$67:$C$69,2,TRUE) -> 1762781.6 | AV7: ='Revenue Forecast'!AV6*VLOOKUP('Revenue Forecast'!$BE$6+'Revenue Forecast'!$BF$6,Assumptions!$B$67:$C$69,2,TRUE) -> 1932688.2 | ... AZ7: ='Revenue Forecast'!AZ6*VLOOKUP('Revenue Forecast'!$BE$6+'Revenue Forecast'!$BF$6,Assumptions!$B$67:$C$69,2,TRUE) -> 2789300.9 | BC7: =SUM(Q7:AB7) -> 0 | BD7: =SUM(AC7:AN7) -> 10048915 | BE7: =SUM(AO7:AZ7) -> 21238332 | BF7: ='Revenue Forecast'!BF6*Assumptions!G50 -> 30000000
B8: Upsell | D8: € | Q8: ='Revenue Forecast'!Q6*SUMPRODUCT(Assumptions!$E$113:$E$116,Assumptions!$G$113:$G$116) -> 0 | R8: ='Revenue Forecast'!R6*SUMPRODUCT(Assumptions!$E$113:$E$116,Assumptions!$G$113:$G$116) -> 0 | S8: ='Revenue Forecast'!S6*SUMPRODUCT(Assumptions!$E$113:$E$116,Assumptions!$G$113:$G$116) -> 0 | T8: ='Revenue Forecast'!T6*SUMPRODUCT(Assumptions!$E$113:$E$116,Assumptions!$G$113:$G$116) -> 0 | U8: ='Revenue Forecast'!U6*SUMPRODUCT(Assumptions!$E$113:$E$116,Assumptions!$G$113:$G$116) -> 0 | V8: ='Revenue Forecast'!V6*SUMPRODUCT(Assumptions!$E$113:$E$116,Assumptions!$G$113:$G$116) -> 0 | W8: ='Revenue Forecast'!W6*SUMPRODUCT(Assumptions!$E$113:$E$116,Assumptions!$G$113:$G$116) -> 0 | X8: ='Revenue Forecast'!X6*SUMPRODUCT(Assumptions!$E$113:$E$116,Assumptions!$G$113:$G$116) -> 0 | ... AZ8: ='Revenue Forecast'!AZ6*SUMPRODUCT(Assumptions!$E$113:$E$116,Assumptions!$G$113:$G$116) -> 381313.2 | BC8: =SUM(Q8:AB8) -> 0 | BD8: =SUM(AC8:AN8) -> 972639 | BE8: =SUM(AO8:AZ8) -> 2903400 | BF8: ='Revenue Forecast'!BF6*SUMPRODUCT(Assumptions!$E$113:$E$116,Assumptions!$G$113:$G$116) -> 5806800
B9: Total TTK COGS | D9: € | Q9: =sum(Q7:Q8) -> 0 | R9: =sum(R7:R8) -> 0 | S9: =sum(S7:S8) -> 0 | T9: =sum(T7:T8) -> 0 | U9: =sum(U7:U8) -> 0 | V9: =sum(V7:V8) -> 0 | W9: =sum(W7:W8) -> 0 | X9: =sum(X7:X8) -> 0 | ... AZ9: =sum(AZ7:AZ8) -> 3170614.1 | BB9: =SUM(E9:P9) -> 0 | BC9: =SUM(Q9:AB9) -> 0 | BD9: =SUM(AC9:AN9) -> 11021554 | BE9: =SUM(AO9:AZ9) -> 24141732 | BF9: =sum(BF7:BF8) -> 35806800
B11: TARNOC MINI
B12: Total COGS Mini | D12: € | Q12: =IFNA('Revenue Forecast'!Q12*VLOOKUP('Revenue Forecast'!$BD$12,Assumptions!$B$81:$C$84,2,TRUE),0) -> 0 | R12: =IFNA('Revenue Forecast'!R12*VLOOKUP('Revenue Forecast'!$BD$12,Assumptions!$B$81:$C$84,2,TRUE),0) -> 0 | S12: =IFNA('Revenue Forecast'!S12*VLOOKUP('Revenue Forecast'!$BD$12,Assumptions!$B$81:$C$84,2,TRUE),0) -> 0 | T12: =IFNA('Revenue Forecast'!T12*VLOOKUP('Revenue Forecast'!$BD$12,Assumptions!$B$81:$C$84,2,TRUE),0) -> 0 | U12: =IFNA('Revenue Forecast'!U12*VLOOKUP('Revenue Forecast'!$BD$12,Assumptions!$B$81:$C$84,2,TRUE),0) -> 0 | V12: =IFNA('Revenue Forecast'!V12*VLOOKUP('Revenue Forecast'!$BD$12,Assumptions!$B$81:$C$84,2,TRUE),0) -> 0 | W12: =IFNA('Revenue Forecast'!W12*VLOOKUP('Revenue Forecast'!$BD$12,Assumptions!$B$81:$C$84,2,TRUE),0) -> 0 | X12: =IFNA('Revenue Forecast'!X12*VLOOKUP('Revenue Forecast'!$BD$12,Assumptions!$B$81:$C$84,2,TRUE),0) -> 0 | ... AB12: =IFNA('Revenue Forecast'!AB12*VLOOKUP('Revenue Forecast'!$BD$12,Assumptions!$B$81:$C$84,2,TRUE),0) -> 0 | AC12: ='Revenue Forecast'!AC12*VLOOKUP('Revenue Forecast'!$BD$12,Assumptions!$B$80:$C$84,2,TRUE) -> 26000 | AD12: ='Revenue Forecast'!AD12*VLOOKUP('Revenue Forecast'!$BD$12,Assumptions!$B$80:$C$84,2,TRUE) -> 29900 | AE12: ='Revenue Forecast'!AE12*VLOOKUP('Revenue Forecast'!$BD$12,Assumptions!$B$80:$C$84,2,TRUE) -> 33800 | AF12: ='Revenue Forecast'!AF12*VLOOKUP('Revenue Forecast'!$BD$12,Assumptions!$B$80:$C$84,2,TRUE) -> 37700 | AG12: ='Revenue Forecast'!AG12*VLOOKUP('Revenue Forecast'!$BD$12,Assumptions!$B$80:$C$84,2,TRUE) -> 41600 | AH12: ='Revenue Forecast'!AH12*VLOOKUP('Revenue Forecast'!$BD$12,Assumptions!$B$80:$C$84,2,TRUE) -> 46800 | AI12: ='Revenue Forecast'!AI12*VLOOKUP('Revenue Forecast'!$BD$12,Assumptions!$B$80:$C$84,2,TRUE) -> 53300 | AJ12: ='Revenue Forecast'!AJ12*VLOOKUP('Revenue Forecast'!$BD$12,Assumptions!$B$80:$C$84,2,TRUE) -> 59800 | ... AZ12: ='Revenue Forecast'!AZ12*VLOOKUP('Revenue Forecast'!$BD$12,Assumptions!$B$80:$C$84,2,TRUE) -> 378300 | BC12: =SUM(Q12:AB12) -> 0 | BD12: =SUM(AC12:AN12) -> 650000 | BE12: =SUM(AO12:AZ12) -> 2600000 | BF12: ='Revenue Forecast'!BF12*Assumptions!H77 -> 3953400
B13: Upsell | D13: € | Q13: ='Revenue Forecast'!Q12*PRODUCT(Assumptions!$E$122,Assumptions!$G$122) -> 0 | R13: ='Revenue Forecast'!R12*PRODUCT(Assumptions!$E$122,Assumptions!$G$122) -> 0 | S13: ='Revenue Forecast'!S12*PRODUCT(Assumptions!$E$122,Assumptions!$G$122) -> 0 | T13: ='Revenue Forecast'!T12*PRODUCT(Assumptions!$E$122,Assumptions!$G$122) -> 0 | U13: ='Revenue Forecast'!U12*PRODUCT(Assumptions!$E$122,Assumptions!$G$122) -> 0 | V13: ='Revenue Forecast'!V12*PRODUCT(Assumptions!$E$122,Assumptions!$G$122) -> 0 | W13: ='Revenue Forecast'!W12*PRODUCT(Assumptions!$E$122,Assumptions!$G$122) -> 0 | X13: ='Revenue Forecast'!X12*PRODUCT(Assumptions!$E$122,Assumptions!$G$122) -> 0 | ... AZ13: ='Revenue Forecast'!AZ12*PRODUCT(Assumptions!$E$122,Assumptions!$G$122) -> 17460 | BC13: =SUM(Q13:AB13) -> 0 | BD13: =SUM(AC13:AN13) -> 30000 | BE13: =SUM(AO13:AZ13) -> 120000 | BF13: ='Revenue Forecast'!BF12*PRODUCT(Assumptions!$E$122,Assumptions!$G$122) -> 240000
B14: Total Mini COGS | D14: € | Q14: =sum(Q12:Q13) -> 0 | R14: =sum(R12:R13) -> 0 | S14: =sum(S12:S13) -> 0 | T14: =sum(T12:T13) -> 0 | U14: =sum(U12:U13) -> 0 | V14: =sum(V12:V13) -> 0 | W14: =sum(W12:W13) -> 0 | X14: =sum(X12:X13) -> 0 | ... AZ14: =sum(AZ12:AZ13) -> 395760 | BB14: =SUM(E14:P14) -> 0 | BC14: =SUM(Q14:AB14) -> 0 | BD14: =SUM(AC14:AN14) -> 680000 | BE14: =SUM(AO14:AZ14) -> 2720000 | BF14: =sum(BF12:BF13) -> 4193400
B16: INSTALLATION
B17: Total COGS Mini & TTK | D17: € | Q17: ='Revenue Forecast'!Q34*Assumptions!$C$33 -> 0 | R17: ='Revenue Forecast'!R34*Assumptions!$C$33 -> 0 | S17: ='Revenue Forecast'!S34*Assumptions!$C$33 -> 0 | T17: ='Revenue Forecast'!T34*Assumptions!$C$33 -> 0 | U17: ='Revenue Forecast'!U34*Assumptions!$C$33 -> 0 | V17: ='Revenue Forecast'!V34*Assumptions!$C$33 -> 0 | W17: ='Revenue Forecast'!W34*Assumptions!$C$33 -> 0 | X17: ='Revenue Forecast'!X34*Assumptions!$C$33 -> 0 | ... AZ17: ='Revenue Forecast'!AZ34*Assumptions!$C$33 -> 2192000 | BC17: =SUM(Q17:AB17) -> 0 | BD17: =SUM(AC17:AN17) -> 4816000 | BE17: =SUM(AO17:AZ17) -> 16000000 | BF17: ='Revenue Forecast'!BF18*Assumptions!$C$33 -> 32000000
B19: SERVICE REVENUES
B20: Installed base (TTK) | D20: # | Q20: =Q4 | R20: =R4 | S20: =S4 | T20: =T4 | U20: =U4 | V20: =V4 | W20: =W4 | X20: =X4 | ... AB20: =AB4 | AC20: ='Revenue Forecast'!AC6 -> 48 | AD20: ='Revenue Forecast'!AD6+'Revenue Forecast'!AC22 -> 101 | AE20: ='Revenue Forecast'!AE6+'Revenue Forecast'!AD22 -> 159 | AF20: ='Revenue Forecast'!AF6+'Revenue Forecast'!AE22 -> 223 | AG20: ='Revenue Forecast'!AG6+'Revenue Forecast'!AF22 -> 293 | AH20: ='Revenue Forecast'!AH6+'Revenue Forecast'!AG22 -> 369 | AI20: ='Revenue Forecast'!AI6+'Revenue Forecast'!AH22 -> 452 | AJ20: ='Revenue Forecast'!AJ6+'Revenue Forecast'!AI22 -> 543 | AK20: ='Revenue Forecast'!AK6+'Revenue Forecast'!AJ22 -> 643 | ... AZ20: ='Revenue Forecast'!AZ6+'Revenue Forecast'!AY22 -> 4005 | BB20: =SUM(E20:P20) -> 0 | BC20: =SUM(Q20:AB20) -> 0 | BD20: =AN20 -> 1005 | BE20: =AZ20 -> 4005 | BF20: ='Revenue Forecast'!BF22 -> 5500
B21: Installed base (Mini) | D21: # | Q21: =Q10 | R21: =R10 | S21: =S10 | T21: =T10 | U21: =U10 | V21: =V10 | W21: =W10 | X21: =X10 | ... AB21: =AB10 | AC21: ='Revenue Forecast'!AC12 -> 20 | AD21: ='Revenue Forecast'!AD12+'Revenue Forecast'!AC23 -> 43 | AE21: ='Revenue Forecast'!AE12+'Revenue Forecast'!AD23 -> 69 | AF21: ='Revenue Forecast'!AF12+'Revenue Forecast'!AE23 -> 98 | AG21: ='Revenue Forecast'!AG12+'Revenue Forecast'!AF23 -> 130 | AH21: ='Revenue Forecast'!AH12+'Revenue Forecast'!AG23 -> 166 | AI21: ='Revenue Forecast'!AI12+'Revenue Forecast'!AH23 -> 207 | AJ21: ='Revenue Forecast'!AJ12+'Revenue Forecast'!AI23 -> 253 | AK21: ='Revenue Forecast'!AK12+'Revenue Forecast'!AJ23 -> 304 | ... AZ21: ='Revenue Forecast'!AZ12+'Revenue Forecast'!AY23 -> 2500 | BB21: =SUM(E21:P21) -> 0 | BC21: =SUM(Q21:AB21) -> 0 | BD21: =AN21 -> 500 | BE21: =AZ21 -> 2500 | BF21: ='Revenue Forecast'!BF23 -> 4500
B22: Total Service Revenue | D22: € | Q22: ='Revenue Forecast'!Q34*SUMPRODUCT(Assumptions!$E$126:$E$127,Assumptions!$G$126:$G$127)+E22 -> 0 | R22: ='Revenue Forecast'!R34*SUMPRODUCT(Assumptions!$E$126:$E$127,Assumptions!$G$126:$G$127)+F22 -> 0 | S22: ='Revenue Forecast'!S34*SUMPRODUCT(Assumptions!$E$126:$E$127,Assumptions!$G$126:$G$127)+G22 -> 0 | T22: ='Revenue Forecast'!T34*SUMPRODUCT(Assumptions!$E$126:$E$127,Assumptions!$G$126:$G$127)+H22 -> 0 | U22: ='Revenue Forecast'!U34*SUMPRODUCT(Assumptions!$E$126:$E$127,Assumptions!$G$126:$G$127)+I22 -> 0 | V22: ='Revenue Forecast'!V34*SUMPRODUCT(Assumptions!$E$126:$E$127,Assumptions!$G$126:$G$127)+J22 -> 0 | W22: ='Revenue Forecast'!W34*SUMPRODUCT(Assumptions!$E$126:$E$127,Assumptions!$G$126:$G$127)+K22 -> 0 | X22: ='Revenue Forecast'!X34*SUMPRODUCT(Assumptions!$E$126:$E$127,Assumptions!$G$126:$G$127)+L22 -> 0 | ... AZ22: ='Revenue Forecast'!AZ34*SUMPRODUCT(Assumptions!$E$126:$E$127,Assumptions!$G$126:$G$127)+AN22 -> 28302 | BB22: =SUM(E22:P22) -> 0 | BC22: =SUM(Q22:AB22) -> 0 | BD22: =sum(AC22:AN22) -> 47859 | BE22: =sum(AO22:AZ22)+BD22 -> 254718 | BF22: =(BE22*2)+BE22 -> 764154
B24: TOTAL COGS | M24: =M7+M12 -> 0 | N24: =N9+N14+N17+N22 -> 0 | O24: =O9+O14+O17+O22 -> 0 | P24: =P9+P14+P17+P22 -> 0 | Q24: =Q9+Q14+Q17+Q22 -> 0 | R24: =R9+R14+R17+R22 -> 0 | S24: =S9+S14+S17+S22 -> 0 | T24: =T9+T14+T17+T22 -> 0 | U24: =U9+U14+U17+U22 -> 0 | ... AZ24: =AZ9+AZ14+AZ17+AZ22 -> 5786676.1 | BB24: =SUM(BB7+BB12) -> 0 | BC24: =SUM(BC7+BC12) -> 0 | BD24: =sum(AC24:AN24) -> 16565413 | BE24: =sum(AO24:AZ24) -> 43068591 | BF24: =BF17+BF14+BF9+BF22 -> 72764354

Sheet OPEX
B1: Tarnoc B.V. — OPEX Forecast (€, negative = cost) | U1: Actual | V1: Projected
G2: 2025 | S2: 2026 | AE2: 2027 | AQ2: 2028
G3: 45658 | H3: 45689 | I3: 45717 | J3: 45748 | K3: 45778 | L3: 45809 | M3: 45839 | N3: 45870 | O3: 45901 | P3: 45931 | Q3: 45962 | R3: 45992 | S3: 46023 | T3: 46054 | U3: 46082 | V3: 46113 | W3: 46143 | X3: 46174 | Y3: 46204 | Z3: 46235 | AA3: 46266 | AB3: 46296 | AC3: 46327 | AD3: 46357 | AE3: 46388 | AF3: 46419 | AG3: 46447 | AH3: 46478 | AI3: 46508 | AJ3: 46539 | AK3: 46569 | AL3: 46600 | AM3: 46631 | AN3: 46661 | AO3: 46692 | AP3: 46722 | AQ3: 46753 | AR3: 46784 | AS3: 46813 | AT3: 46844 | AU3: 46874 | AV3: 46905 | AW3: 46935 | AX3: 46966 | AY3: 46997 | AZ3: 47027 | BA3: 47058 | BB3: 47088 | BD3: 2025 | BE3: 2026 | BF3: 2027 | BG3: 2028 | BH3: 2029
B5: PERSONNEL
B6: R&D | D6: € | O6: =Personnel!Q49 -> 47500 | P6: =Personnel!R49 -> 47500 | Q6: =Personnel!S49 -> 47500 | R6: =Personnel!T49 -> 47500 | S6: =Personnel!U49 -> 50700 | T6: =Personnel!V49 -> 50700 | U6: =Personnel!W49 -> 50700 | V6: =Personnel!X49 -> 50700 | ... BB6: =Personnel!BD49 -> 110364.77 | BD6: =SUM(G6:R6) -> 190000 | BE6: =SUM(S6:AD6) -> 705160 | BF6: =SUM(AE6:AP6) -> 1186575.2 | BG6: =SUM(AQ6:BB6) -> 1314001.2 | BH6: =BG6*('Financial Statements'!$BE$7/'Financial Statements'!$BD$7)^0.5 -> 2270248.3
B7: S&M | D7: € | O7: =Personnel!Q50 -> 0 | P7: =Personnel!R50 -> 0 | Q7: =Personnel!S50 -> 0 | R7: =Personnel!T50 -> 0 | S7: =Personnel!U50 -> 0 | T7: =Personnel!V50 -> 10800 | U7: =Personnel!W50 -> 10800 | V7: =Personnel!X50 -> 10800 | ... BB7: =Personnel!BD50 -> 53176.32 | BD7: =SUM(G7:R7) -> 0 | BE7: =SUM(S7:AD7) -> 183300 | BF7: =SUM(AE7:AP7) -> 331128 | BG7: =SUM(AQ7:BB7) -> 620118.24 | BH7: =BG7*('Financial Statements'!$BE$7/'Financial Statements'!$BD$7)^0.5 -> 1071401.1
B8: G&A | D8: € | O8: =Personnel!Q51 -> 11500 | P8: =Personnel!R51 -> 11500 | Q8: =Personnel!S51 -> 11500 | R8: =Personnel!T51 -> 11500 | S8: =Personnel!U51 -> 11820 | T8: =Personnel!V51 -> 11820 | U8: =Personnel!W51 -> 11820 | V8: =Personnel!X51 -> 11820 | ... BB8: =Personnel!BD51 -> 55445.088 | BD8: =SUM(G8:R8) -> 46000 | BE8: =SUM(S8:AD8) -> 222060 | BF8: =SUM(AE8:AP8) -> 520843.2 | BG8: =SUM(AQ8:BB8) -> 645010.66 | BH8: =BG8*('Financial Statements'!$BE$7/'Financial Statements'!$BD$7)^0.2 -> 802708.62
B9: Total Personnel | D9: € | G9: =SUM(G6:G8) -> 0 | H9: =SUM(H6:H8) -> 0 | I9: =SUM(I6:I8) -> 0 | J9: =SUM(J6:J8) -> 0 | K9: =SUM(K6:K8) -> 0 | L9: =SUM(L6:L8) -> 0 | M9: =SUM(M6:M8) -> 0 | N9: =SUM(N6:N8) -> 0 | O9: =sum(O6:O8) -> 59000 | P9: =sum(P6:P8) -> 59000 | Q9: =sum(Q6:Q8) -> 59000 | R9: =sum(R6:R8) -> 59000 | S9: =sum(S6:S8) -> 62520 | T9: =sum(T6:T8) -> 73320 | U9: =sum(U6:U8) -> 73320 | V9: =sum(V6:V8) -> 73320 | ... BB9: =sum(BB6:BB8) -> 218986.18 | BD9: =SUM(G9:R9) -> 236000 | BE9: =SUM(S9:AD9) -> 1110520 | BF9: =SUM(AE9:AP9) -> 2038546.4 | BG9: =SUM(AQ9:BB9) -> 2579130.1 | BH9: =sum(BH6:BH8) -> 4144358.1
B11: NON-PERSONNEL
B13: R&D COSTS
B14: Kicker Development Cost | D14: € | R14: =Assumptions!E95 -> 168933 | BD14: =SUM(G14:R14) -> 168933 | BE14: =SUM(S14:AD14) -> 0 | BF14: =SUM(AE14:AP14) -> 0 | BG14: =SUM(AQ14:BB14) -> 0 | BH14: 0
B15: Ongoing Development costs | D15: € | S15: {=INDEX(Assumptions!$E$93:$I$93,MATCH(YEAR(S$3),Assumptions!$E$88:$I$88,0))} -> 10000 | T15: {=INDEX(Assumptions!$E$93:$I$93,MATCH(YEAR(T$3),Assumptions!$E$88:$I$88,0))} -> 10000 | U15: {=INDEX(Assumptions!$E$93:$I$93,MATCH(YEAR(U$3),Assumptions!$E$88:$I$88,0))} -> 10000 | V15: {=INDEX(Assumptions!$E$93:$I$93,MATCH(YEAR(V$3),Assumptions!$E$88:$I$88,0))} -> 10000 | W15: {=INDEX(Assumptions!$E$93:$I$93,MATCH(YEAR(W$3),Assumptions!$E$88:$I$88,0))} -> 10000 | X15: {=INDEX(Assumptions!$E$93:$I$93,MATCH(YEAR(X$3),Assumptions!$E$88:$I$88,0))} -> 10000 | Y15: {=INDEX(Assumptions!$E$93:$I$93,MATCH(YEAR(Y$3),Assumptions!$E$88:$I$88,0))} -> 10000 | Z15: {=INDEX(Assumptions!$E$93:$I$93,MATCH(YEAR(Z$3),Assumptions!$E$88:$I$88,0))} -> 10000 | ... BB15: {=INDEX(Assumptions!$E$93:$I$93,MATCH(YEAR(BB$3),Assumptions!$E$88:$I$88,0))} -> 16900 | BD15: =SUM(G15:R15) -> 0 | BE15: =SUM(S15:AD15) -> 120000 | BF15: =SUM(AE15:AP15) -> 156000 | BG15: =SUM(AQ15:BB15) -> 202800 | BH15: =BG15*('Financial Statements'!$BE$7/'Financial Statements'!$BD$7)^0.4 -> 314087.05
B16: Assembly partner | D16: € | AB16: =Assumptions!E98 -> 100000 | BD16: =SUM(G16:R16) -> 0 | BE16: =SUM(S16:AC16) -> 100000 | BF16: =SUM(AE16:AP16) -> 0 | BG16: =SUM(AQ16:BB16) -> 0
