Workbook

Sheet Cover
B15: Financial Model
B19: Currency: EUR (€)
B21: STRICTLY CONFIDENTIAL

Sheet How to read me
B1: Tarnoc — How to Read This Model
B3: COLOR CODING
B4: Sample | C4: Assumptions are hardcoded inputs (sourced from documents)
B5: Sample | C5: Hardcoded historicalsis actual data from source documents
B6: Sample | C6: Formula cells are calculated, not hardcoded
B7: Sample | C7: Subtotal / total rows
B8: Sample | C8: Section headers / grand totals
B9: Sample | C9: Subsection headers
B10: Sample | C10: Margin / ratio rows (grey)
B11: Sample | C11: Balance sheet check rows (must = 0)
B14: FORMULA ARCHITECTURE
B15: Assumptions → Revenue Forecast, COGS, OPEX, CAPEX, Personnel (all drivers sourced here)
B16: Revenue Forecast → Financial Statements (revenue lines via cross-sheet links)
B17: COGS → Financial Statements (cost lines via cross-sheet links)
B18: OPEX → Financial Statements (opex lines via cross-sheet links)
B20: To change a number: ONLY edit cells in the Assumptions tab (yellow/orange).
B21: All other tabs will recalculate automatically.
B24: FURTHER EXPLANATIONS
B25: Subsidies: Tarnoc is and has been eligible for a number of subsidies. We will consider application for large projects, however this model excludes the forecast of any subsidy financing foing forward.
B26: Installation revenues: This is modelled fully as pass through revenue for now, as we plan to charge a customer exactly what we pay the installation partner for these services. This is subject to change in the future.
B27: Tarnoc's main products are the TTK (turbineketel) and the Combi+ (turbineketel + outdoor unit), plus the Twincycle (in development for 2027). Every unit contains a turbineketel; the Combi+ adds an outdoor unit and a heavier installation. We also plan to sell various add-ons such as boilers for hybrid setups and sound reduction units.
B28: Service Revenues: Service revenues are calculated relative to installed base. We assume a certain percentage (see assumptions) of customers will purchase our Service package, and are charged annually.
... B45: 2) bill of materials, is all of that inclusive of VAT? because if not

Sheet Assumptions
B2: Drivers & Assumptions
B3: ASSUMPTIONS | L3: what this row does
B5: General Assumptions
B6: Opening Cash Balance (Jan 2024) | C6: 29538.9
B7: Annual salary increase (%) | C7: 0.08 | L7: salary raise applied every year on the Personnel tab
B8: Employer cost basis | C8: Werkgeverlasten (incl. taxes)
B9: Holiday pay (%) | C9: 0.08
B10: Income tax rate | C10: 0.258
B11: Interst on WC loan | C11: 0.05 | L11: interest rate charged on the CLA / working-capital loan
B13: Working Capital | H13: 20
B15: Days Sales Outstanding (DSO) | C15: days | D15: 20 | L15: days customers take to pay — sets receivables on the balance sheet
B16: Days Payable Outstanding (DPO) | C16: days | D16: 45 | L16: days we take to pay suppliers — sets payables
B17: Days Inventory Outstanding (DIO) | C17: days | D17: =IF($D$82=2,30,0) | L17: days of stock held. 0 in Base (as before); 30 in the Aggressive case
B18: Pre-payment | C18: % | L18: share paid up front. left blank, so no customer deposits assumed
B20: Revenue Build
B21: ~Units sold | D21: =IF($D$82=2,D84,D85) | E21: =IF($D$82=2,E84,E85) | F21: =IF($D$82=2,F84,F85) | G21: =IF($D$82=2,G84,G85) | L21: the main dial: total units a year, picked from the Case switch in row 82
C22: 2026 | D22: 2027 | E22: 2028 | F22: 2029 | G22: 2030
B23: TTK | C23: 0 | D23: =D$21*$H23 | E23: =E$21*$H23 | F23: =F$21*$H23 | G23: =G$21*$H23 | H23: 0.2 | L23: TTK units = total units x the mix % in column H
B24: Combi+ | C24: 0 | D24: =D$21*$H24 | E24: =E$21*$H24 | F24: =F$21*$H24 | G24: =G$21*$H24 | H24: =1-H23 | L24: Combi+ units = total units x the mix % in column H
B27: Pricing
B28: PRICING — build-up (turbineketel + outdoor unit) | D28: (inc VAT)
B29: Turbineketel base price (all products) | C29: 8525.62 | D29: =C29*1.21 | L29: column D is just the same price with VAT added, for reference
B30: Outdoor unit — Combi+ | C30: 5309.92 | D30: =C30*1.21 | L30: column D is the incl-VAT version, for reference
B31: Combi+ price (ketel + ODU) | C31: =C29+C30 | D31: =C31*1.21 | L31: Combi+ price = ketel + outdoor unit
B32: INSTALLATION (PASS-THROUGH; REV=COST)
B33: Installation — TTK | C33: 2800 | L33: charged at cost, no margin (pass-through)
B34: Installation — Combi+ | C34: 3800 | L34: charged at cost, no margin (pass-through)
B35: COGS
B36: TTK
B37: Bill of Materials TTK supplier 1
B38: # | C38: Category | D38: Component | E38: 1,000 units | F38: 5,000 units | G38: 10,000 units | H38: Unit | I38: Source
B39: B1 | C39: Supplier 1 | D39: Compressor + VFD | E39: 6314 | F39: 4500 | G39: 2692.44 | H39: €/unit | I39: Source: BOM data provided | L39: compressor prices typed in per tier, not a % step-down
B40: B2 | C40: Supplier 1 | D40: Heat exchangers (set) | E40: 805.5 | F40: =E40*0.7 | G40: =0.6*F40 | H40: €/unit | I40: Source: BOM data provided | L40: volume discount: 5k column = 70% of 1k, 10k = 60% of 5k
B41: B3 | C41: Supplier 1 | D41: Electronics & Power Electronics | E41: 632.92 | F41: =E41*0.7 | G41: =0.6*F41 | H41: €/unit | I41: Source: BOM data provided | L41: volume discount: 5k column = 70% of 1k, 10k = 60% of 5k
B42: B4 | C42: Supplier 1 | D42: Hydraulic Components (Pumps, Valves, etc.) | E42: 283.76 | F42: =E42*0.7 | G42: =0.6*F42 | H42: €/unit | I42: Source: BOM data provided | L42: volume discount: 5k column = 70% of 1k, 10k = 60% of 5k
B43: B5 | C43: Supplier 1 | D43: Silencer & Insulation | E43: 118.48 | F43: =E43*0.7 | G43: =0.6*F43 | H43: €/unit | I43: Source: BOM data provided | L43: volume discount: 5k column = 70% of 1k, 10k = 60% of 5k
B44: B6 | C44: Supplier 1 | D44: Enclosure (Sheet Metal & Coating) | E44: 653.03 | F44: =E44*0.7 | G44: =0.6*F44 | H44: €/unit | I44: Source: BOM data provided | L44: volume discount: 5k column = 70% of 1k, 10k = 60% of 5k
B45: B7 | C45: Supplier 1 | D45: Other Components | E45: 290 | F45: =E45*0.7 | G45: 126 | H45: €/unit | I45: Source: BOM data provided | L45: 5k = 70% of 1k; the 10k number is typed in by hand
B46: B8 | C46: Supplier 1 | D46: Assembly & Final Testing | E46: 200 | F46: =E46*0.7 | G46: =0.6*F46 | H46: €/unit | I46: Source: BOM data provided | L46: volume discount: 5k column = 70% of 1k, 10k = 60% of 5k
B47: B9 | C47: Supplier 1 | D47: Packaging & Inbound Logistics | E47: 395 | F47: =E47*0.7 | G47: =0.6*F47 | H47: €/unit | I47: Source: BOM data provided | L47: volume discount: 5k column = 70% of 1k, 10k = 60% of 5k
...

Sheet Financial Statements
B1: Tarnoc B.V. — Financial Statements (€)
E2: 2025 | Q2: 2026 | AC2: 2027 | AO2: 2028
E3: 45658 | F3: 45689 | G3: 45717 | H3: 45748 | I3: 45778 | J3: 45809 | K3: 45839 | L3: 45870 | M3: 45901 | N3: 45931 | O3: 45962 | P3: 45992 | Q3: 46023 | R3: 46054 | S3: 46082 | T3: 46113 | U3: 46143 | V3: 46174 | W3: 46204 | X3: 46235 | Y3: 46266 | Z3: 46296 | AA3: 46327 | AB3: 46357 | AC3: 46388 | AD3: 46419 | AE3: 46447 | AF3: 46478 | AG3: 46508 | AH3: 46539 | AI3: 46569 | AJ3: 46600 | AK3: 46631 | AL3: 46661 | AM3: 46692 | AN3: 46722 | AO3: 46753 | AP3: 46784 | AQ3: 46813 | AR3: 46844 | AS3: 46874 | AT3: 46905 | AU3: 46935 | AV3: 46966 | AW3: 46997 | AX3: 47027 | AY3: 47058 | AZ3: 47088 | BB3: 2025 | BC3: 2026 | BD3: 2027 | BE3: 2028 | BF3: 2029 | BH3: what this row does
B5: PROFIT & LOSS STATEMENT
B6: Revenues
B7: TTK | D7: € | M7: ='Revenue Forecast'!M9 | N7: ='Revenue Forecast'!N9 | O7: ='Revenue Forecast'!O9 | P7: ='Revenue Forecast'!P9 | Q7: ='Revenue Forecast'!Q9 | R7: ='Revenue Forecast'!R9 | S7: ='Revenue Forecast'!S9 | T7: ='Revenue Forecast'!T9 | ... AZ7: ='Revenue Forecast'!AZ9 | BB7: =sum(E7:P7) | BC7: =sum(Q7:AB7) | BD7: =sum(AC7:AN7) | BE7: =sum(AO7:AZ7) | BF7: ='Revenue Forecast'!BF9 | BH7: TTK revenue, pulled from the Revenue Forecast
B8: Combi+ | D8: € | Q8: ='Revenue Forecast'!Q15 | R8: ='Revenue Forecast'!R15 | S8: ='Revenue Forecast'!S15 | T8: ='Revenue Forecast'!T15 | U8: ='Revenue Forecast'!U15 | V8: ='Revenue Forecast'!V15 | W8: ='Revenue Forecast'!W15 | X8: ='Revenue Forecast'!X15 | ... AZ8: ='Revenue Forecast'!AZ15 | BB8: ='Revenue Forecast'!BB15 | BC8: ='Revenue Forecast'!BC15 | BD8: ='Revenue Forecast'!BD15 | BE8: ='Revenue Forecast'!BE15 | BF8: ='Revenue Forecast'!BF15 | BH8: Combi+ revenue, pulled from the Revenue Forecast
B9: Other | D9: € | M9: ='Revenue Forecast'!M19+'Revenue Forecast'!M24 | N9: ='Revenue Forecast'!N19+'Revenue Forecast'!N24 | O9: ='Revenue Forecast'!O19+'Revenue Forecast'!O24 | P9: ='Revenue Forecast'!P19+'Revenue Forecast'!P24 | Q9: ='Revenue Forecast'!Q19+'Revenue Forecast'!Q24 | R9: ='Revenue Forecast'!R19+'Revenue Forecast'!R24 | S9: ='Revenue Forecast'!S19+'Revenue Forecast'!S24 | T9: ='Revenue Forecast'!T19+'Revenue Forecast'!T24 | ... AZ9: ='Revenue Forecast'!AZ19+'Revenue Forecast'!AZ24 | BB9: =sum(E9:P9) | BC9: =sum(Q9:AB9) | BD9: =sum(AC9:AN9) | BE9: =sum(AO9:AZ9) | BF9: ='Revenue Forecast'!BF19+'Revenue Forecast'!BF24 | BH9: installation + service revenue from the Revenue Forecast
B10: Subsidies & grants | D10: € | M10: ='Revenue Forecast'!M28 | N10: ='Revenue Forecast'!N28 | O10: ='Revenue Forecast'!O28 | P10: ='Revenue Forecast'!P28 | Q10: ='Revenue Forecast'!Q28 | R10: ='Revenue Forecast'!R28 | S10: ='Revenue Forecast'!S28 | T10: 0 | U10: ='Revenue Forecast'!U28 | V10: ='Revenue Forecast'!V28 | W10: ='Revenue Forecast'!W28 | X10: ='Revenue Forecast'!X28 | Y10: ='Revenue Forecast'!Y28 | Z10: ='Revenue Forecast'!Z28 | AA10: ='Revenue Forecast'!AA28 | AB10: ='Revenue Forecast'!AB28 | ... AZ10: ='Revenue Forecast'!AZ28 | BB10: =sum(E10:P10) | BC10: =sum(Q10:AB10) | BD10: pm | BE10: pm | BF10: pm | BH10: subsidies from the Revenue Forecast. nothing budgeted
B11: Total Revenue | D11: € | M11: ='Revenue Forecast'!M30 | N11: ='Revenue Forecast'!N30 | O11: ='Revenue Forecast'!O30 | P11: ='Revenue Forecast'!P30 | Q11: ='Revenue Forecast'!Q30 | R11: ='Revenue Forecast'!R30 | S11: ='Revenue Forecast'!S30 | T11: ='Revenue Forecast'!T30 | ... AZ11: ='Revenue Forecast'!AZ30 | BB11: =sum(E11:P11) | BC11: =sum(Q11:AB11) | BD11: =sum(AC11:AN11) | BE11: =sum(AO11:AZ11) | BF11: =sum(BF7:BF10) | BH11: all the revenue lines added
B13: Cost of goods sold
B14: TTK | D14: € | E14: =COGS!E9 | F14: =COGS!F9 | G14: =COGS!G9 | H14: =COGS!H9 | I14: =COGS!I9 | J14: =COGS!J9 | K14: =COGS!K9 | L14: =COGS!L9 | ... AZ14: =COGS!AZ9 | BB14: =sum(E14:P14) | BC14: =sum(Q14:AB14) | BD14: =sum(AC14:AN14) | BE14: =sum(AO14:AZ14) | BF14: =COGS!BF9 | BH14: TTK cost of sales, from the COGS tab
B15: Combi+ | D15: € | Q15: =COGS!Q14 | R15: =COGS!R14 | S15: =COGS!S14 | T15: =COGS!T14 | U15: =COGS!U14 | V15: =COGS!V14 | W15: =COGS!W14 | X15: =COGS!X14 | ... AZ15: =COGS!AZ14 | BB15: =COGS!BB14 | BC15: =COGS!BC14 | BD15: =COGS!BD14 | BE15: =COGS!BE14 | BF15: =COGS!BF14 | BH15: Combi+ cost of sales, from COGS
B16: Other | D16: € | E16: =COGS!E17 | F16: =COGS!F17 | G16: =COGS!G17 | H16: =COGS!H17 | I16: =COGS!I17 | J16: =COGS!J17 | K16: =COGS!K17 | L16: =COGS!L17 | ... P16: =COGS!P17 | Q16: =COGS!Q17+COGS!Q20 | R16: =COGS!R17+COGS!R20 | S16: =COGS!S17+COGS!S20 | T16: =COGS!T17+COGS!T20 | U16: =COGS!U17+COGS!U20 | V16: =COGS!V17+COGS!V20 | W16: =COGS!W17+COGS!W20 | X16: =COGS!X17+COGS!X20 | ... AZ16: =COGS!AZ17+COGS!AZ20 | BB16: =sum(E16:P16) | BC16: =sum(Q16:AB16) | BD16: =sum(AC16:AN16) | BE16: =sum(AO16:AZ16) | BF16: =COGS!BF17+COGS!BF20 | BH16: installation + service costs, from COGS
B17: Total COGS | D17: € | M17: =COGS!M22 | N17: =COGS!N22 | O17: =COGS!O22 | P17: =COGS!P22 | Q17: =COGS!Q22 | R17: =COGS!R22 | S17: =COGS!S22 | T17: =COGS!T22 | ... AZ17: =COGS!AZ22 | BB17: =sum(E17:P17) | BC17: =sum(Q17:AB17) | BD17: =sum(AC17:AN17) | BE17: =sum(AO17:AZ17) | BF17: =sum(BF14:BF16) | BH17: all the cost lines added
B19: Gross Profit
B20: TTK | D20: € | Q20: =Q7-Q14 | R20: =R7-R14 | S20: =S7-S14 | T20: =T7-T14 | U20: =U7-U14 | V20: =V7-V14 | W20: =W7-W14 | X20: =X7-X14 | ... AZ20: =AZ7-AZ14 | BC20: =BC7-BC14 | BD20: =BD7-BD14 | BE20: =BE7-BE14 | BF20: =BF7-BF14 | BH20: TTK revenue minus TTK cost
B21: Combi+ | D21: € | Q21: =Q8-Q15 | R21: =R8-R15 | S21: =S8-S15 | T21: =T8-T15 | U21: =U8-U15 | V21: =V8-V15 | W21: =W8-W15 | X21: =X8-X15 | ... AZ21: =AZ8-AZ15 | BC21: =BC8-BC15 | BD21: =BD8-BD15 | BE21: =BE8-BE15 | BF21: =BF8-BF15 | BH21: Combi+ revenue minus Combi+ cost
B22: Other | D22: € | Q22: =Q9-Q16 | R22: =R9-R16 | S22: =S9-S16 | T22: =T9-T16 | U22: =U9-U16 | V22: =V9-V16 | W22: =W9-W16 | X22: =X9-X16 | ... AZ22: =AZ9-AZ16 | BC22: =BC9-BC16 | BD22: =BD9-BD16 | BE22: =BE9-BE16 | BF22: =BF9-BF16 | BH22: installation + service revenue minus their cost
B23: Gross Profit | D23: € | M23: =M11-M17 | N23: =N11-N17 | O23: =O11-O17 | P23: =P11-P17 | Q23: =Q11-Q17 | R23: =R11-R17 | S23: =S11-S17 | T23: =T11-T17 | ... AZ23: =AZ11-AZ17 | BB23: =sum(E23:P23) | BC23: =sum(Q23:AB23) | BD23: =sum(AC23:AN23) | BE23: =sum(AO23:AZ23) | BF23: =BF11-BF17 | BH23: revenue minus cost of sales
B24: Gross margin % | D24: % | BD24: =BD23/BD11 | BE24: =BE23/BE11 | BF24: =BF23/BF11 | BH24: gross profit as a % of revenue (year columns only)
B26: Operational expenses
B27: R&D | D27: € | M27: =OPEX!O38 | N27: =OPEX!P38 | O27: =OPEX!Q38 | P27: =OPEX!R38 | Q27: =OPEX!S38 | R27: =OPEX!T38 | S27: =OPEX!U38 | T27: =OPEX!V38 | ... AZ27: =OPEX!BB38 | BB27: =sum(E27:P27) | BC27: =sum(Q27:AB27) | BD27: =sum(AC27:AN27) | BE27: =sum(AO27:AZ27) | BF27: =OPEX!BH38 | BH27: R&D spend, people and other, from OPEX
B28: S&M | D28: € | M28: =OPEX!O39 | N28: =OPEX!P39 | O28: =OPEX!Q39 | P28: =OPEX!R39 | Q28: =OPEX!S39 | R28: =OPEX!T39 | S28: =OPEX!U39 | T28: =OPEX!V39 | ... AZ28: =OPEX!BB39 | BB28: =sum(E28:P28) | BC28: =sum(Q28:AB28) | BD28: =sum(AC28:AN28) | BE28: =sum(AO28:AZ28) | BF28: =OPEX!BH39 | BH28: S&M spend from OPEX
B29: G&A | D29: € | M29: =OPEX!O40 | N29: =OPEX!P40 | O29: =OPEX!Q40 | P29: =OPEX!R40 | Q29: =OPEX!S40 | R29: =OPEX!T40 | S29: =OPEX!U40 | T29: =OPEX!V40 | ... AZ29: =OPEX!BB40 | BB29: =sum(E29:P29) | BC29: =sum(Q29:AB29) | BD29: =sum(AC29:AN29) | BE29: =sum(AO29:AZ29) | BF29: =OPEX!BH40 | BH29: G&A spend from OPEX
B30: Total OPEX | D30: € | M30: =(M29+M28+M27) | N30: =(N29+N28+N27) | O30: =(O29+O28+O27) | P30: =(P29+P28+P27) | Q30: =(Q29+Q28+Q27) | R30: =(R29+R28+R27) | S30: =(S29+S28+S27) | T30: =(T29+T28+T27) | ... AZ30: =(AZ29+AZ28+AZ27) | BB30: =sum(E30:P30) | BC30: =sum(Q30:AB30) | BD30: =sum(AC30:AN30) | BE30: =sum(AO30:AZ30) | BF30: =sum(BF27:BF29) | BH30: the three OPEX lines added
B32: EBITDA | D32: € | M32: =M23-M30 | N32: =N23-N30 | O32: =O23-O30 | P32: =P23-P30 | Q32: =Q23-Q30 | R32: =R23-R30 | S32: =S23-S30 | T32: =T23-T30 | ... AZ32: =AZ23-AZ30 | BB32: =sum(E32:P32) | BC32: =sum(Q32:AB32) | BD32: =sum(AC32:AN32) | BE32: =sum(AO32:AZ32) | BF32: =BF23-BF30 | BH32: gross profit minus operating costs
B33: EBITDA margin % | D33: % | BE33: =BE32/BE11 | BF33: =BF32/BF11 | BH33: EBITDA as a % of revenue
B35: Depreciation & Amortisation | D35: € | E35: =-SUM($E$53:E53)/(Assumptions!$D$128*12) | F35: =-SUM($E$53:F53)/(Assumptions!$D$128*12) | G35: =-SUM($E$53:G53)/(Assumptions!$D$128*12) | H35: =-SUM($E$53:H53)/(Assumptions!$D$128*12) | I35: =-SUM($E$53:I53)/(Assumptions!$D$128*12) | J35: =-SUM($E$53:J53)/(Assumptions!$D$128*12) | K35: =-SUM($E$53:K53)/(Assumptions!$D$128*12) | L35: =-SUM($E$53:L53)/(Assumptions!$D$128*12) | ... AZ35: =-SUM($E$53:AZ53)/(Assumptions!$D$128*12) | BB35: =sum(E35:P35) | BC35: =sum(Q35:AB35) | BD35: =sum(AC35:AN35) | BE35: =sum(AO35:AZ35) | BF35: =(-SUM($E$53:$AZ$53)+(-BF53)/2)/Assumptions!$D$128 | BH35: straight line on cumulative capex, blended life from Assumptions D128
B36: Interest payments | D36: € | M36: 0 | N36: 0 | O36: 0 | P36: 0 | Q36: =P82*Assumptions!$C$11/12 | R36: =Q82*Assumptions!$C$11/12 | S36: =R82*Assumptions!$C$11/12 | T36: =S82*Assumptions!$C$11/12 | U36: =T82*Assumptions!$C$11/12 | V36: =U82*Assumptions!$C$11/12 | W36: =V82*Assumptions!$C$11/12 | X36: =W82*Assumptions!$C$11/12 | ... AZ36: =AY82*Assumptions!$C$11/12 | BB36: =sum(E36:P36) | BC36: =sum(Q36:AB36) | BD36: =sum(AC36:AN36) | BE36: =sum(AO36:AZ36) | BF36: =BE82*Assumptions!$C$11/12 | BH36: interest on last month's loan balance, yearly rate divided by 12
B37: EBT | D37: € | M37: =M32-sum(M35:M36) | N37: =N32-sum(N35:N36) | O37: =O32-sum(O35:O36) | P37: =P32-sum(P35:P36) | Q37: =Q32-sum(Q35:Q36) | R37: =R32-sum(R35:R36) | S37: =S32-sum(S35:S36) | T37: =T32-sum(T35:T36) | ... AZ37: =AZ32-sum(AZ35:AZ36) | BB37: =sum(E37:P37) | BC37: =sum(Q37:AB37) | BD37: =sum(AC37:AN37) | BE37: =sum(AO37:AZ37) | BF37: =BF32-sum(BF35:BF36) | BH37: EBITDA minus depreciation and interest
BE38: =BE37/BE11 | BF38: =BF37/BF11 | BH38: profit before tax as a % of revenue
B40: Income tax | D40: € | M40: 0 | N40: 0 | O40: 0 | P40: 0 | Q40: 0 | R40: 0 | S40: 0 | T40: 0 | U40: 0 | V40: 0 | W40: 0 | X40: 0 | Y40: 0 | Z40: 0 | AA40: 0 | AB40: 0 | AC40: 0 | AD40: 0 | AE40: 0 | AF40: 0 | AG40: 0 | AH40: 0 | AI40: 0 | AJ40: 0 | AK40: 0 | AL40: 0 | AM40: 0 | AN40: 0 | AO40: 0 | AP40: 0 | AQ40: 0 | AR40: 0 | AS40: 0 | AT40: 0 | AU40: 0 | AV40: 0 | AW40: 0 | AX40: 0 | AY40: 0 | AZ40: 0 | BB40: =sum(E40:P40) | BC40: =sum(Q40:AB40) | BD40: =sum(AC40:AN40) | BE40: =sum(AO40:AZ40) | BF40: =(BF37-AZ44)*Assumptions!$C$10 | BH40: tax on profit, but only once the old losses below are used up
B41: NET INCOME | D41: € | M41: =M37-M40 | N41: =N37-N40 | O41: =O37-O40 | P41: =P37-P40 | Q41: =Q37-Q40 | R41: =R37-R40 | S41: =S37-S40 | T41: =T37-T40 | ... AZ41: =AZ37-AZ40 | BB41: =sum(E41:P41) | BC41: =sum(Q41:AB41) | BD41: =sum(AC41:AN41) | BE41: =sum(AO41:AZ41) | BF41: =BF37-BF40 | BH41: profit after tax
B42: Profit margin % | BE42: =BE41/BE11 | BF42: =BF41/BF11 | BH42: net profit as a % of revenue
B44: Tax carry over to be applied | M44: 108239 | N44: =M44+(-N41*Assumptions!$C$10) | O44: =N44+(-O41*Assumptions!$C$10) | P44: =O44+(-P41*Assumptions!$C$10) | Q44: =P44+(-Q41*Assumptions!$C$10) | R44: =Q44+(-R41*Assumptions!$C$10) | S44: =R44+(-S41*Assumptions!$C$10) | T44: =S44+(-T41*Assumptions!$C$10) | U44: =T44+(-U41*Assumptions!$C$10) | ... AZ44: =AY44+(-AZ41*Assumptions!$C$10) | BH44: running pot of unused tax losses: grows in loss months, gets eaten when profitable
B46: CASH FLOW STATEMENT
B47: Net income | D47: € | M47: =M41 | N47: =N41 | O47: =O41 | P47: =P41 | Q47: =Q41 | R47: =R41 | S47: =S41 | T47: =T41 | ... AZ47: =AZ41 | BB47: =sum(E47:P47) | BC47: =sum(Q47:AB47) | BD47: =sum(AC47:AN47) | BE47: =sum(AO47:AZ47) | BF47: =BF41 | BH47: cash flow starts from net income
B48: Depreciation & amortisation | D48: € | E48: =E35 | F48: =F35 | G48: =G35 | H48: =H35 | I48: =I35 | J48: =J35 | K48: =K35 | L48: =L35 | ... AZ48: =AZ35 | BB48: =sum(E48:P48) | BC48: =sum(Q48:AB48) | BD48: =sum(AC48:AN48) | BE48: =sum(AO48:AZ48) | BF48: =BF35 | BH48: adds depreciation back, it isn't cash
B49: Increase in accounts receivable (delta DSO) | D49: € | M49: 0 | N49: =-(N68-M68) | O49: =-(O68-N68) | P49: =-(P68-O68) | Q49: =-(Q68-P68) | R49: =-(R68-Q68) | S49: =-(S68-R68) | T49: =-(T68-S68) | U49: =-(U68-T68) | ... AZ49: =-(AZ68-AY68) | BB49: =sum(E49:P49) | BC49: =sum(Q49:AB49) | BD49: =sum(AC49:AN49) | BE49: =sum(AO49:AZ49) | BF49: =-(BF68-BE68) | BH49: cash tied up when receivables grow, freed when they shrink
...

Sheet Revenue Forecast
B1: Tarnoc B.V. — Revenue Forecast (€, ex VAT unless noted)
E2: 2025 | Q2: 2026 | AC2: 2027 | AO2: 2028
E3: 45658 | F3: 45689 | G3: 45717 | H3: 45748 | I3: 45778 | J3: 45809 | K3: 45839 | L3: 45870 | M3: 45901 | N3: 45931 | O3: 45962 | P3: 45992 | Q3: 46023 | R3: 46054 | S3: 46082 | T3: 46113 | U3: 46143 | V3: 46174 | W3: 46204 | X3: 46235 | Y3: 46266 | Z3: 46296 | AA3: 46327 | AB3: 46357 | AC3: 46388 | AD3: 46419 | AE3: 46447 | AF3: 46478 | AG3: 46508 | AH3: 46539 | AI3: 46569 | AJ3: 46600 | AK3: 46631 | AL3: 46661 | AM3: 46692 | AN3: 46722 | AO3: 46753 | AP3: 46784 | AQ3: 46813 | AR3: 46844 | AS3: 46874 | AT3: 46905 | AU3: 46935 | AV3: 46966 | AW3: 46997 | AX3: 47027 | AY3: 47058 | AZ3: 47088 | BB3: 2025 | BC3: 2026 | BD3: 2027 | BE3: 2028 | BF3: 2029 | BH3: what this row does
AB4: 2 | AC4: 3 | AD4: 4 | AE4: 5 | AF4: 6 | AG4: 7 | AH4: 8 | AI4: 9 | AJ4: 10 | AK4: 11 | AL4: 12 | AM4: 13 | AN4: 14 | AO4: 15 | AP4: 16 | AQ4: 17 | AR4: 18 | AS4: 19 | AT4: 20 | AU4: 21 | AV4: 22 | AW4: 23 | AX4: 24 | AY4: 25 | AZ4: 26
B5: TURBINEKETEL (TTK)
B6: TTK units sold | D6: # | Q6: {=IF(YEAR(Q$3)=2026,0,ROUND(EXP((LN(Assumptions!$E$23/Assumptions!$D$23)/12)*((YEAR(Q$3)-2027)*12+MONTH(Q$3)-1))/SUMPRODUCT(EXP((LN(Assumptions!$E$23/Assumptions!$D$23)/12)*(ROW(INDIRECT("1:24"))-1)))*SUM(Assumptions!$D$23:$E$23),0))} | R6: {=IF(YEAR(R$3)=2026,0,ROUND(EXP((LN(Assumptions!$E$23/Assumptions!$D$23)/12)*((YEAR(R$3)-2027)*12+MONTH(R$3)-1))/SUMPRODUCT(EXP((LN(Assumptions!$E$23/Assumptions!$D$23)/12)*(ROW(INDIRECT("1:24"))-1)))*SUM(Assumptions!$D$23:$E$23),0))} | S6: {=IF(YEAR(S$3)=2026,0,ROUND(EXP((LN(Assumptions!$E$23/Assumptions!$D$23)/12)*((YEAR(S$3)-2027)*12+MONTH(S$3)-1))/SUMPRODUCT(EXP((LN(Assumptions!$E$23/Assumptions!$D$23)/12)*(ROW(INDIRECT("1:24"))-1)))*SUM(Assumptions!$D$23:$E$23),0))} | T6: {=IF(YEAR(T$3)=2026,0,ROUND(EXP((LN(Assumptions!$E$23/Assumptions!$D$23)/12)*((YEAR(T$3)-2027)*12+MONTH(T$3)-1))/SUMPRODUCT(EXP((LN(Assumptions!$E$23/Assumptions!$D$23)/12)*(ROW(INDIRECT("1:24"))-1)))*SUM(Assumptions!$D$23:$E$23),0))} | U6: {=IF(YEAR(U$3)=2026,0,ROUND(EXP((LN(Assumptions!$E$23/Assumptions!$D$23)/12)*((YEAR(U$3)-2027)*12+MONTH(U$3)-1))/SUMPRODUCT(EXP((LN(Assumptions!$E$23/Assumptions!$D$23)/12)*(ROW(INDIRECT("1:24"))-1)))*SUM(Assumptions!$D$23:$E$23),0))} | V6: {=IF(YEAR(V$3)=2026,0,ROUND(EXP((LN(Assumptions!$E$23/Assumptions!$D$23)/12)*((YEAR(V$3)-2027)*12+MONTH(V$3)-1))/SUMPRODUCT(EXP((LN(Assumptions!$E$23/Assumptions!$D$23)/12)*(ROW(INDIRECT("1:24"))-1)))*SUM(Assumptions!$D$23:$E$23),0))} | W6: {=IF(YEAR(W$3)=2026,0,ROUND(EXP((LN(Assumptions!$E$23/Assumptions!$D$23)/12)*((YEAR(W$3)-2027)*12+MONTH(W$3)-1))/SUMPRODUCT(EXP((LN(Assumptions!$E$23/Assumptions!$D$23)/12)*(ROW(INDIRECT("1:24"))-1)))*SUM(Assumptions!$D$23:$E$23),0))} | X6: {=IF(YEAR(X$3)=2026,0,ROUND(EXP((LN(Assumptions!$E$23/Assumptions!$D$23)/12)*((YEAR(X$3)-2027)*12+MONTH(X$3)-1))/SUMPRODUCT(EXP((LN(Assumptions!$E$23/Assumptions!$D$23)/12)*(ROW(INDIRECT("1:24"))-1)))*SUM(Assumptions!$D$23:$E$23),0))} | ... AM6: {=IF(YEAR(AM$3)=2026,0,ROUND(EXP((LN(Assumptions!$E$23/Assumptions!$D$23)/12)*((YEAR(AM$3)-2027)*12+MONTH(AM$3)-1))/SUMPRODUCT(EXP((LN(Assumptions!$E$23/Assumptions!$D$23)/12)*(ROW(INDIRECT("1:24"))-1)))*SUM(Assumptions!$D$23:$E$23),0))} | AN6: =Assumptions!$D$23-SUM(AC6:AM6) | AO6: {=IF(YEAR(AO$3)=2026,0,ROUND(EXP((LN(Assumptions!$E$23/Assumptions!$D$23)/12)*((YEAR(AO$3)-2027)*12+MONTH(AO$3)-1))/SUMPRODUCT(EXP((LN(Assumptions!$E$23/Assumptions!$D$23)/12)*(ROW(INDIRECT("1:24"))-1)))*SUM(Assumptions!$D$23:$E$23),0))} | AP6: {=IF(YEAR(AP$3)=2026,0,ROUND(EXP((LN(Assumptions!$E$23/Assumptions!$D$23)/12)*((YEAR(AP$3)-2027)*12+MONTH(AP$3)-1))/SUMPRODUCT(EXP((LN(Assumptions!$E$23/Assumptions!$D$23)/12)*(ROW(INDIRECT("1:24"))-1)))*SUM(Assumptions!$D$23:$E$23),0))} | AQ6: {=IF(YEAR(AQ$3)=2026,0,ROUND(EXP((LN(Assumptions!$E$23/Assumptions!$D$23)/12)*((YEAR(AQ$3)-2027)*12+MONTH(AQ$3)-1))/SUMPRODUCT(EXP((LN(Assumptions!$E$23/Assumptions!$D$23)/12)*(ROW(INDIRECT("1:24"))-1)))*SUM(Assumptions!$D$23:$E$23),0))} | AR6: {=IF(YEAR(AR$3)=2026,0,ROUND(EXP((LN(Assumptions!$E$23/Assumptions!$D$23)/12)*((YEAR(AR$3)-2027)*12+MONTH(AR$3)-1))/SUMPRODUCT(EXP((LN(Assumptions!$E$23/Assumptions!$D$23)/12)*(ROW(INDIRECT("1:24"))-1)))*SUM(Assumptions!$D$23:$E$23),0))} | AS6: {=IF(YEAR(AS$3)=2026,0,ROUND(EXP((LN(Assumptions!$E$23/Assumptions!$D$23)/12)*((YEAR(AS$3)-2027)*12+MONTH(AS$3)-1))/SUMPRODUCT(EXP((LN(Assumptions!$E$23/Assumptions!$D$23)/12)*(ROW(INDIRECT("1:24"))-1)))*SUM(Assumptions!$D$23:$E$23),0))} | AT6: {=IF(YEAR(AT$3)=2026,0,ROUND(EXP((LN(Assumptions!$E$23/Assumptions!$D$23)/12)*((YEAR(AT$3)-2027)*12+MONTH(AT$3)-1))/SUMPRODUCT(EXP((LN(Assumptions!$E$23/Assumptions!$D$23)/12)*(ROW(INDIRECT("1:24"))-1)))*SUM(Assumptions!$D$23:$E$23),0))} | AU6: {=IF(YEAR(AU$3)=2026,0,ROUND(EXP((LN(Assumptions!$E$23/Assumptions!$D$23)/12)*((YEAR(AU$3)-2027)*12+MONTH(AU$3)-1))/SUMPRODUCT(EXP((LN(Assumptions!$E$23/Assumptions!$D$23)/12)*(ROW(INDIRECT("1:24"))-1)))*SUM(Assumptions!$D$23:$E$23),0))} | AV6: {=IF(YEAR(AV$3)=2026,0,ROUND(EXP((LN(Assumptions!$E$23/Assumptions!$D$23)/12)*((YEAR(AV$3)-2027)*12+MONTH(AV$3)-1))/SUMPRODUCT(EXP((LN(Assumptions!$E$23/Assumptions!$D$23)/12)*(ROW(INDIRECT("1:24"))-1)))*SUM(Assumptions!$D$23:$E$23),0))} | ... AY6: {=IF(YEAR(AY$3)=2026,0,ROUND(EXP((LN(Assumptions!$E$23/Assumptions!$D$23)/12)*((YEAR(AY$3)-2027)*12+MONTH(AY$3)-1))/SUMPRODUCT(EXP((LN(Assumptions!$E$23/Assumptions!$D$23)/12)*(ROW(INDIRECT("1:24"))-1)))*SUM(Assumptions!$D$23:$E$23),0))} | AZ6: =Assumptions!$E$23-SUM(AO6:AY6) | BB6: =SUM(E6:P6) | BC6: =SUM(Q6:AB6) | BD6: =SUM(AC6:AN6) | BE6: =SUM(AO6:AZ6) | BF6: =Assumptions!$F$23 | BH6: monthly units on an S-curve ramp; December tops up so the year hits the target exactly. 2029 has no monthly detail, it reads the annual number
B7: TTK Revenue | D7: € | Q7: =Q6*Assumptions!$C$29 | R7: =R6*Assumptions!$C$29 | S7: =S6*Assumptions!$C$29 | T7: =T6*Assumptions!$C$29 | U7: =U6*Assumptions!$C$29 | V7: =V6*Assumptions!$C$29 | W7: =W6*Assumptions!$C$29 | X7: =X6*Assumptions!$C$29 | ... AZ7: =AZ6*Assumptions!$C$29 | BB7: =SUM(E7:P7) | BC7: =SUM(Q7:AB7) | BD7: =SUM(AC7:AN7) | BE7: =SUM(AO7:AZ7) | BF7: =BF6*Assumptions!$C$29 | BH7: units x TTK price
B8: TTK upsell | D8: € | Q8: =Q6*SUMPRODUCT(Assumptions!$E$112:$F$114) | R8: =R6*SUMPRODUCT(Assumptions!$E$112:$F$114) | S8: =S6*SUMPRODUCT(Assumptions!$E$112:$F$114) | T8: =T6*SUMPRODUCT(Assumptions!$E$112:$F$114) | U8: =U6*SUMPRODUCT(Assumptions!$E$112:$F$114) | V8: =V6*SUMPRODUCT(Assumptions!$E$112:$F$114) | W8: =W6*SUMPRODUCT(Assumptions!$E$112:$F$114) | X8: =X6*SUMPRODUCT(Assumptions!$E$112:$F$114) | ... AB8: =AB6*SUMPRODUCT(Assumptions!$E$112:$F$114) | AC8: =AC6*SUMPRODUCT(Assumptions!$E$112:$E$114,Assumptions!$F$112:$F$114) | AD8: =AD6*SUMPRODUCT(Assumptions!$E$112:$E$114,Assumptions!$F$112:$F$114) | AE8: =AE6*SUMPRODUCT(Assumptions!$E$112:$E$114,Assumptions!$F$112:$F$114) | AF8: =AF6*SUMPRODUCT(Assumptions!$E$112:$E$114,Assumptions!$F$112:$F$114) | AG8: =AG6*SUMPRODUCT(Assumptions!$E$112:$E$114,Assumptions!$F$112:$F$114) | AH8: =AH6*SUMPRODUCT(Assumptions!$E$112:$E$114,Assumptions!$F$112:$F$114) | AI8: =AI6*SUMPRODUCT(Assumptions!$E$112:$E$114,Assumptions!$F$112:$F$114) | AJ8: =AJ6*SUMPRODUCT(Assumptions!$E$112:$E$114,Assumptions!$F$112:$F$114) | ... AZ8: =AZ6*SUMPRODUCT(Assumptions!$E$112:$E$114,Assumptions!$F$112:$F$114) | BB8: =SUM(E8:P8) | BC8: =SUM(Q8:AB8) | BD8: =SUM(AC8:AN8) | BE8: =SUM(AO8:AZ8) | BF8: =BF6*SUMPRODUCT(Assumptions!$E$112:$E$114,Assumptions!$F$112:$F$114) | BH8: units x average upsell basket (attach % x price)
B9: Total TTK Revenue | D9: € | Q9: =sum(Q7:Q8) | R9: =sum(R7:R8) | S9: =sum(S7:S8) | T9: =sum(T7:T8) | U9: =sum(U7:U8) | V9: =sum(V7:V8) | W9: =sum(W7:W8) | X9: =sum(X7:X8) | ... AZ9: =sum(AZ7:AZ8) | BB9: =SUM(E9:P9) | BC9: =SUM(Q9:AB9) | BD9: =SUM(AC9:AN9) | BE9: =SUM(AO9:AZ9) | BF9: =SUM(BF7:BF8) | BH9: machine revenue + upsells
B11: COMBI+
B12: Combi+ units sold | D12: # | Q12: {=IF(YEAR(Q$3)=2026,0,ROUND(EXP((LN(Assumptions!$E$24/Assumptions!$D$24)/12)*((YEAR(Q$3)-2027)*12+MONTH(Q$3)-1))/SUMPRODUCT(EXP((LN(Assumptions!$E$24/Assumptions!$D$24)/12)*(ROW(INDIRECT("1:24"))-1)))*SUM(Assumptions!$D$24:$E$24),0))} | R12: {=IF(YEAR(R$3)=2026,0,ROUND(EXP((LN(Assumptions!$E$24/Assumptions!$D$24)/12)*((YEAR(R$3)-2027)*12+MONTH(R$3)-1))/SUMPRODUCT(EXP((LN(Assumptions!$E$24/Assumptions!$D$24)/12)*(ROW(INDIRECT("1:24"))-1)))*SUM(Assumptions!$D$24:$E$24),0))} | S12: {=IF(YEAR(S$3)=2026,0,ROUND(EXP((LN(Assumptions!$E$24/Assumptions!$D$24)/12)*((YEAR(S$3)-2027)*12+MONTH(S$3)-1))/SUMPRODUCT(EXP((LN(Assumptions!$E$24/Assumptions!$D$24)/12)*(ROW(INDIRECT("1:24"))-1)))*SUM(Assumptions!$D$24:$E$24),0))} | T12: {=IF(YEAR(T$3)=2026,0,ROUND(EXP((LN(Assumptions!$E$24/Assumptions!$D$24)/12)*((YEAR(T$3)-2027)*12+MONTH(T$3)-1))/SUMPRODUCT(EXP((LN(Assumptions!$E$24/Assumptions!$D$24)/12)*(ROW(INDIRECT("1:24"))-1)))*SUM(Assumptions!$D$24:$E$24),0))} | U12: {=IF(YEAR(U$3)=2026,0,ROUND(EXP((LN(Assumptions!$E$24/Assumptions!$D$24)/12)*((YEAR(U$3)-2027)*12+MONTH(U$3)-1))/SUMPRODUCT(EXP((LN(Assumptions!$E$24/Assumptions!$D$24)/12)*(ROW(INDIRECT("1:24"))-1)))*SUM(Assumptions!$D$24:$E$24),0))} | V12: {=IF(YEAR(V$3)=2026,0,ROUND(EXP((LN(Assumptions!$E$24/Assumptions!$D$24)/12)*((YEAR(V$3)-2027)*12+MONTH(V$3)-1))/SUMPRODUCT(EXP((LN(Assumptions!$E$24/Assumptions!$D$24)/12)*(ROW(INDIRECT("1:24"))-1)))*SUM(Assumptions!$D$24:$E$24),0))} | W12: {=IF(YEAR(W$3)=2026,0,ROUND(EXP((LN(Assumptions!$E$24/Assumptions!$D$24)/12)*((YEAR(W$3)-2027)*12+MONTH(W$3)-1))/SUMPRODUCT(EXP((LN(Assumptions!$E$24/Assumptions!$D$24)/12)*(ROW(INDIRECT("1:24"))-1)))*SUM(Assumptions!$D$24:$E$24),0))} | X12: {=IF(YEAR(X$3)=2026,0,ROUND(EXP((LN(Assumptions!$E$24/Assumptions!$D$24)/12)*((YEAR(X$3)-2027)*12+MONTH(X$3)-1))/SUMPRODUCT(EXP((LN(Assumptions!$E$24/Assumptions!$D$24)/12)*(ROW(INDIRECT("1:24"))-1)))*SUM(Assumptions!$D$24:$E$24),0))} | ... AM12: {=IF(YEAR(AM$3)=2026,0,ROUND(EXP((LN(Assumptions!$E$24/Assumptions!$D$24)/12)*((YEAR(AM$3)-2027)*12+MONTH(AM$3)-1))/SUMPRODUCT(EXP((LN(Assumptions!$E$24/Assumptions!$D$24)/12)*(ROW(INDIRECT("1:24"))-1)))*SUM(Assumptions!$D$24:$E$24),0))} | AN12: =Assumptions!$D$24-SUM(AC12:AM12) | AO12: {=IF(YEAR(AO$3)=2026,0,ROUND(EXP((LN(Assumptions!$E$24/Assumptions!$D$24)/12)*((YEAR(AO$3)-2027)*12+MONTH(AO$3)-1))/SUMPRODUCT(EXP((LN(Assumptions!$E$24/Assumptions!$D$24)/12)*(ROW(INDIRECT("1:24"))-1)))*SUM(Assumptions!$D$24:$E$24),0))} | AP12: {=IF(YEAR(AP$3)=2026,0,ROUND(EXP((LN(Assumptions!$E$24/Assumptions!$D$24)/12)*((YEAR(AP$3)-2027)*12+MONTH(AP$3)-1))/SUMPRODUCT(EXP((LN(Assumptions!$E$24/Assumptions!$D$24)/12)*(ROW(INDIRECT("1:24"))-1)))*SUM(Assumptions!$D$24:$E$24),0))} | AQ12: {=IF(YEAR(AQ$3)=2026,0,ROUND(EXP((LN(Assumptions!$E$24/Assumptions!$D$24)/12)*((YEAR(AQ$3)-2027)*12+MONTH(AQ$3)-1))/SUMPRODUCT(EXP((LN(Assumptions!$E$24/Assumptions!$D$24)/12)*(ROW(INDIRECT("1:24"))-1)))*SUM(Assumptions!$D$24:$E$24),0))} | AR12: {=IF(YEAR(AR$3)=2026,0,ROUND(EXP((LN(Assumptions!$E$24/Assumptions!$D$24)/12)*((YEAR(AR$3)-2027)*12+MONTH(AR$3)-1))/SUMPRODUCT(EXP((LN(Assumptions!$E$24/Assumptions!$D$24)/12)*(ROW(INDIRECT("1:24"))-1)))*SUM(Assumptions!$D$24:$E$24),0))} | AS12: {=IF(YEAR(AS$3)=2026,0,ROUND(EXP((LN(Assumptions!$E$24/Assumptions!$D$24)/12)*((YEAR(AS$3)-2027)*12+MONTH(AS$3)-1))/SUMPRODUCT(EXP((LN(Assumptions!$E$24/Assumptions!$D$24)/12)*(ROW(INDIRECT("1:24"))-1)))*SUM(Assumptions!$D$24:$E$24),0))} | AT12: {=IF(YEAR(AT$3)=2026,0,ROUND(EXP((LN(Assumptions!$E$24/Assumptions!$D$24)/12)*((YEAR(AT$3)-2027)*12+MONTH(AT$3)-1))/SUMPRODUCT(EXP((LN(Assumptions!$E$24/Assumptions!$D$24)/12)*(ROW(INDIRECT("1:24"))-1)))*SUM(Assumptions!$D$24:$E$24),0))} | AU12: {=IF(YEAR(AU$3)=2026,0,ROUND(EXP((LN(Assumptions!$E$24/Assumptions!$D$24)/12)*((YEAR(AU$3)-2027)*12+MONTH(AU$3)-1))/SUMPRODUCT(EXP((LN(Assumptions!$E$24/Assumptions!$D$24)/12)*(ROW(INDIRECT("1:24"))-1)))*SUM(Assumptions!$D$24:$E$24),0))} | AV12: {=IF(YEAR(AV$3)=2026,0,ROUND(EXP((LN(Assumptions!$E$24/Assumptions!$D$24)/12)*((YEAR(AV$3)-2027)*12+MONTH(AV$3)-1))/SUMPRODUCT(EXP((LN(Assumptions!$E$24/Assumptions!$D$24)/12)*(ROW(INDIRECT("1:24"))-1)))*SUM(Assumptions!$D$24:$E$24),0))} | ... AY12: {=IF(YEAR(AY$3)=2026,0,ROUND(EXP((LN(Assumptions!$E$24/Assumptions!$D$24)/12)*((YEAR(AY$3)-2027)*12+MONTH(AY$3)-1))/SUMPRODUCT(EXP((LN(Assumptions!$E$24/Assumptions!$D$24)/12)*(ROW(INDIRECT("1:24"))-1)))*SUM(Assumptions!$D$24:$E$24),0))} | AZ12: =Assumptions!$E$24-SUM(AO12:AY12) | BB12: =SUM(E12:P12) | BC12: =SUM(Q12:AB12) | BD12: =SUM(AC12:AN12) | BE12: =SUM(AO12:AZ12) | BF12: =Assumptions!$F$24 | BH12: same S-curve as TTK, on the Combi+ volume; December is the top-up. 2029 comes straight off the annual assumption
B13: Combi+ Revenue | D13: € | Q13: =Q12*Assumptions!$C$31 | R13: =R12*Assumptions!$C$31 | S13: =S12*Assumptions!$C$31 | T13: =T12*Assumptions!$C$31 | U13: =U12*Assumptions!$C$31 | V13: =V12*Assumptions!$C$31 | W13: =W12*Assumptions!$C$31 | X13: =X12*Assumptions!$C$31 | ... AZ13: =AZ12*Assumptions!$C$31 | BB13: =SUM(E13:P13) | BC13: =SUM(Q13:AB13) | BD13: =SUM(AC13:AN13) | BE13: =SUM(AO13:AZ13) | BF13: =BF12*Assumptions!$C$31 | BH13: units x Combi+ price (ketel + outdoor unit)
B14: Combi+ upsell | D14: € | Q14: =Q12*SUMPRODUCT(Assumptions!$E$112:$E$114,Assumptions!$F$112:$F$114) | R14: =R12*SUMPRODUCT(Assumptions!$E$112:$E$114,Assumptions!$F$112:$F$114) | S14: =S12*SUMPRODUCT(Assumptions!$E$112:$E$114,Assumptions!$F$112:$F$114) | T14: =T12*SUMPRODUCT(Assumptions!$E$112:$E$114,Assumptions!$F$112:$F$114) | U14: =U12*SUMPRODUCT(Assumptions!$E$112:$E$114,Assumptions!$F$112:$F$114) | V14: =V12*SUMPRODUCT(Assumptions!$E$112:$E$114,Assumptions!$F$112:$F$114) | W14: =W12*SUMPRODUCT(Assumptions!$E$112:$E$114,Assumptions!$F$112:$F$114) | X14: =X12*SUMPRODUCT(Assumptions!$E$112:$E$114,Assumptions!$F$112:$F$114) | ... AZ14: =AZ12*SUMPRODUCT(Assumptions!$E$112:$E$114,Assumptions!$F$112:$F$114) | BB14: =SUM(E14:P14) | BC14: =SUM(Q14:AB14) | BD14: =SUM(AC14:AN14) | BE14: =SUM(AO14:AZ14) | BF14: =BF12*SUMPRODUCT(Assumptions!$E$112:$E$114,Assumptions!$F$112:$F$114) | BH14: units x average upsell basket
B15: Total Combi+ Revenue | D15: € | Q15: =sum(Q13:Q14) | R15: =sum(R13:R14) | S15: =sum(S13:S14) | T15: =sum(T13:T14) | U15: =sum(U13:U14) | V15: =sum(V13:V14) | W15: =sum(W13:W14) | X15: =sum(X13:X14) | ... AZ15: =sum(AZ13:AZ14) | BB15: =SUM(E15:P15) | BC15: =SUM(Q15:AB15) | BD15: =SUM(AC15:AN15) | BE15: =SUM(AO15:AZ15) | BF15: =sum(BF13:BF14) | BH15: machine revenue + upsells
B17: INSTALLATION REVENUES | D17: €
B18: Units installed | D18: # | E18: =E6+E12 | F18: =F6+F12 | G18: =G6+G12 | H18: =H6+H12 | I18: =I6+I12 | J18: =J6+J12 | K18: =K6+K12 | L18: =L6+L12 | ... AZ18: =AZ6+AZ12 | BB18: =SUM(E18:P18) | BC18: =SUM(Q18:AB18) | BD18: =SUM(AC18:AN18) | BE18: =SUM(AO18:AZ18) | BF18: =BF6+BF12 | BH18: TTK + Combi+ units. every unit sold gets installed
B19: Total Installation Revenue | D19: € | E19: =E6*Assumptions!$C$33+E12*Assumptions!$C$34 | F19: =F6*Assumptions!$C$33+F12*Assumptions!$C$34 | G19: =G6*Assumptions!$C$33+G12*Assumptions!$C$34 | H19: =H6*Assumptions!$C$33+H12*Assumptions!$C$34 | I19: =I6*Assumptions!$C$33+I12*Assumptions!$C$34 | J19: =J6*Assumptions!$C$33+J12*Assumptions!$C$34 | K19: =K6*Assumptions!$C$33+K12*Assumptions!$C$34 | L19: =L6*Assumptions!$C$33+L12*Assumptions!$C$34 | ... AZ19: =AZ6*Assumptions!$C$33+AZ12*Assumptions!$C$34 | BB19: =SUM(E19:P19) | BC19: =SUM(Q19:AB19) | BD19: =SUM(AC19:AN19) | BE19: =SUM(AO19:AZ19) | BF19: =BF6*Assumptions!$C$33+BF12*Assumptions!$C$34 | BH19: units x installation price per product. pass-through, cost is the same
B21: SERVICE REVENUES
B22: Installed base (TTK) | D22: # | Q22: =Q6 | R22: =R6 | S22: =S6 | T22: =T6 | U22: =U6 | V22: =V6 | W22: =W6 | X22: =X6 | ... AC22: =AC6 | AD22: =AC22+AD6 | AE22: =AD22+AE6 | AF22: =AE22+AF6 | AG22: =AF22+AG6 | AH22: =AG22+AH6 | AI22: =AH22+AI6 | AJ22: =AI22+AJ6 | AK22: =AJ22+AK6 | ... AZ22: =AY22+AZ6 | BB22: =SUM(E22:P22) | BC22: =SUM(Q22:AB22) | BD22: =AN22 | BE22: =AZ22 | BF22: =BE22+($BF$18*Assumptions!$H$23) | BH22: TTK machines out in the field: last month's base + this month's sales
B23: Installed base (Combi+) | Q23: =Q12 | R23: =R12 | S23: =S12 | T23: =T12 | U23: =U12 | V23: =V12 | W23: =W12 | X23: =X12 | ... AC23: =AC12 | AD23: =AC23+AD12 | AE23: =AD23+AE12 | AF23: =AE23+AF12 | AG23: =AF23+AG12 | AH23: =AG23+AH12 | AI23: =AH23+AI12 | AJ23: =AI23+AJ12 | AK23: =AJ23+AK12 | ... AZ23: =AY23+AZ12 | BB23: =SUM(E23:P23) | BC23: =SUM(Q23:AB23) | BD23: =AN23 | BE23: =AZ23 | BF23: =BE23+($BF$18*Assumptions!$H$24) | BH23: Combi+ machines out in the field, same running total
B24: Total Service Revenue | D24: € | Q24: =Q34*SUMPRODUCT(Assumptions!$E$120:$E$121,Assumptions!$F$120:$F$121) | R24: =R34*SUMPRODUCT(Assumptions!$E$120:$E$121,Assumptions!$F$120:$F$121) | S24: =S34*SUMPRODUCT(Assumptions!$E$120:$E$121,Assumptions!$F$120:$F$121) | T24: =T34*SUMPRODUCT(Assumptions!$E$120:$E$121,Assumptions!$F$120:$F$121) | U24: =U34*SUMPRODUCT(Assumptions!$E$120:$E$121,Assumptions!$F$120:$F$121) | V24: =V34*SUMPRODUCT(Assumptions!$E$120:$E$121,Assumptions!$F$120:$F$121) | W24: =W34*SUMPRODUCT(Assumptions!$E$120:$E$121,Assumptions!$F$120:$F$121) | X24: =X34*SUMPRODUCT(Assumptions!$E$120:$E$121,Assumptions!$F$120:$F$121) | ... AB24: =AB34*SUMPRODUCT(Assumptions!$E$120:$E$121,Assumptions!$F$120:$F$121) | AC24: =AC34*SUMPRODUCT(Assumptions!$E$120:$E$121,Assumptions!$F$120:$F$121)+Q24 | AD24: =AD34*SUMPRODUCT(Assumptions!$E$120:$E$121,Assumptions!$F$120:$F$121)+R24 | AE24: =AE34*SUMPRODUCT(Assumptions!$E$120:$E$121,Assumptions!$F$120:$F$121)+S24 | AF24: =AF34*SUMPRODUCT(Assumptions!$E$120:$E$121,Assumptions!$F$120:$F$121)+T24 | AG24: =AG34*SUMPRODUCT(Assumptions!$E$120:$E$121,Assumptions!$F$120:$F$121)+U24 | AH24: =AH34*SUMPRODUCT(Assumptions!$E$120:$E$121,Assumptions!$F$120:$F$121)+V24 | AI24: =AI34*SUMPRODUCT(Assumptions!$E$120:$E$121,Assumptions!$F$120:$F$121)+W24 | AJ24: =AJ34*SUMPRODUCT(Assumptions!$E$120:$E$121,Assumptions!$F$120:$F$121)+X24 | ... AZ24: =AZ34*SUMPRODUCT(Assumptions!$E$120:$E$121,Assumptions!$F$120:$F$121)+AN24 | BB24: =SUM(E24:P24) | BC24: =SUM(Q24:AB24) | BD24: =SUM(AC24:AN24) | BE24: =SUM(AO24:AZ24) | BF24: =BF34*SUMPRODUCT(Assumptions!$E$120:$E$121,Assumptions!$F$120:$F$121)+BE24 | BH24: this month's units x service rate + the same month last year, so contracts keep stacking as the base grows. 2029 adds all of 2028 on top
B26: SUBSIDIES & GRANTS
B27: All other | D27: € | E27: 0 | F27: 0 | G27: 0 | H27: 0 | I27: 0 | J27: 0 | K27: 0 | L27: 0 | M27: 0 | N27: 19480 | O27: 78000 | P27: 0 | Q27: 0 | R27: 0 | S27: 0 | T27: 0 | U27: 0 | V27: 0 | W27: 0 | X27: 106782 | Y27: 0 | Z27: 0 | AA27: 0 | AB27: 0 | AC27: 0 | AD27: 0 | AE27: 0 | AF27: 0 | AG27: 0 | AH27: 0 | AI27: 0 | AJ27: 0 | AK27: 0 | AL27: 0 | AM27: 0 | AN27: 0 | AO27: 0 | AP27: 0 | AQ27: 0 | AR27: 0 | AS27: 0 | AT27: 0 | AU27: 0 | AV27: 0 | AW27: 0 | AX27: 0 | AY27: 0 | AZ27: 0 | BB27: =SUM(E27:P27) | BC27: =SUM(Q27:AB27) | BD27: =SUM(AC27:AN27) | BE27: =SUM(AO27:AZ27) | BF27: 0 | BH27: nothing budgeted. the year columns just add the months up
B28: Total Subsidies & Grants | D28: € | E28: =sum(E27) | F28: =sum(F27) | G28: =sum(G27) | H28: =sum(H27) | I28: =sum(I27) | J28: =sum(J27) | K28: =sum(K27) | L28: =sum(L27) | ... AZ28: =sum(AZ27) | BB28: =SUM(E28:P28) | BC28: =SUM(Q28:AB28) | BD28: =BD27 | BE28: =BE27 | BF28: =BF27 | BH28: same as the line above
B30: TOTAL REVENUE | E30: =E9+E15+E19+E24+E28 | F30: =F9+F15+F19+F24+F28 | G30: =G9+G15+G19+G24+G28 | H30: =H9+H15+H19+H24+H28 | I30: =I9+I15+I19+I24+I28 | J30: =J9+J15+J19+J24+J28 | K30: =K9+K15+K19+K24+K28 | L30: =L9+L15+L19+L24+L28 | ... AZ30: =AZ9+AZ15+AZ19+AZ24+AZ28 | BB30: =BB9+BB15+BB19+BB24+BB28 | BC30: =BC9+BC15+BC19+BC24+BC28 | BD30: =SUM(AC30:AN30) | BE30: =SUM(AO30:AZ30) | BF30: =BF9+BF15+BF19+BF24+BF28 | BH30: everything added: TTK + Combi+ + installation + service + subsidies
B33: Installed Base | E33: =sum(E22:E23) | F33: =sum(F22:F23) | G33: =sum(G22:G23) | H33: =sum(H22:H23) | I33: =sum(I22:I23) | J33: =sum(J22:J23) | K33: =sum(K22:K23) | L33: =sum(L22:L23) | ... AZ33: =sum(AZ22:AZ23) | BB33: =sum(BB22:BB23) | BC33: =sum(BC22:BC23) | BD33: =sum(BD22:BD23) | BE33: =sum(BE22:BE23) | BF33: =sum(BF22:BF23) | BH33: total machines in the field (TTK + Combi+)
B34: Units sold | D34: # | E34: =E6+E12 | F34: =F6+F12 | G34: =G6+G12 | H34: =H6+H12 | I34: =I6+I12 | J34: =J6+J12 | K34: =K6+K12 | L34: =L6+L12 | ... AZ34: =AZ6+AZ12 | BB34: 0 | BC34: 0 | BD34: =SUM(AC34:AN34) | BE34: =SUM(AO34:AZ34) | BF34: =BF18 | BH34: units sold this period. the COGS volume tiers look at this row

Sheet COGS
B1: Tarnoc B.V. — COGS Schedule (€)
E2: 2025 | Q2: 2026 | AC2: 2027 | AO2: 2028
E3: 45658 | F3: 45689 | G3: 45717 | H3: 45748 | I3: 45778 | J3: 45809 | K3: 45839 | L3: 45870 | M3: 45901 | N3: 45931 | O3: 45962 | P3: 45992 | Q3: 46023 | R3: 46054 | S3: 46082 | T3: 46113 | U3: 46143 | V3: 46174 | W3: 46204 | X3: 46235 | Y3: 46266 | Z3: 46296 | AA3: 46327 | AB3: 46357 | AC3: 46388 | AD3: 46419 | AE3: 46447 | AF3: 46478 | AG3: 46508 | AH3: 46539 | AI3: 46569 | AJ3: 46600 | AK3: 46631 | AL3: 46661 | AM3: 46692 | AN3: 46722 | AO3: 46753 | AP3: 46784 | AQ3: 46813 | AR3: 46844 | AS3: 46874 | AT3: 46905 | AU3: 46935 | AV3: 46966 | AW3: 46997 | AX3: 47027 | AY3: 47058 | AZ3: 47088 | BB3: 2025 | BC3: 2026 | BD3: 2027 | BE3: 2028 | BF3: 2029
B6: TTK
B7: TTK | D7: € | Q7: =IFNA('Revenue Forecast'!Q6*VLOOKUP('Revenue Forecast'!$BC$34,Assumptions!$B$67:$C$69,2,TRUE),0) | R7: =IFNA('Revenue Forecast'!R6*VLOOKUP('Revenue Forecast'!$BC$34,Assumptions!$B$67:$C$69,2,TRUE),0) | S7: =IFNA('Revenue Forecast'!S6*VLOOKUP('Revenue Forecast'!$BC$34,Assumptions!$B$67:$C$69,2,TRUE),0) | T7: =IFNA('Revenue Forecast'!T6*VLOOKUP('Revenue Forecast'!$BC$34,Assumptions!$B$67:$C$69,2,TRUE),0) | U7: =IFNA('Revenue Forecast'!U6*VLOOKUP('Revenue Forecast'!$BC$34,Assumptions!$B$67:$C$69,2,TRUE),0) | V7: =IFNA('Revenue Forecast'!V6*VLOOKUP('Revenue Forecast'!$BC$34,Assumptions!$B$67:$C$69,2,TRUE),0) | W7: =IFNA('Revenue Forecast'!W6*VLOOKUP('Revenue Forecast'!$BC$34,Assumptions!$B$67:$C$69,2,TRUE),0) | X7: =IFNA('Revenue Forecast'!X6*VLOOKUP('Revenue Forecast'!$BC$34,Assumptions!$B$67:$C$69,2,TRUE),0) | ... AB7: =IFNA('Revenue Forecast'!AB6*VLOOKUP('Revenue Forecast'!$BC$34,Assumptions!$B$67:$C$69,2,TRUE),0) | AC7: =IFNA('Revenue Forecast'!AC6*VLOOKUP(IF(Assumptions!$D$83=2,'Revenue Forecast'!$BD$34+'Revenue Forecast'!$BE$34,'Revenue Forecast'!$BD$34),Assumptions!$B$67:$C$69,2,TRUE),0) | AD7: =IFNA('Revenue Forecast'!AD6*VLOOKUP(IF(Assumptions!$D$83=2,'Revenue Forecast'!$BD$34+'Revenue Forecast'!$BE$34,'Revenue Forecast'!$BD$34),Assumptions!$B$67:$C$69,2,TRUE),0) | AE7: =IFNA('Revenue Forecast'!AE6*VLOOKUP(IF(Assumptions!$D$83=2,'Revenue Forecast'!$BD$34+'Revenue Forecast'!$BE$34,'Revenue Forecast'!$BD$34),Assumptions!$B$67:$C$69,2,TRUE),0) | AF7: =IFNA('Revenue Forecast'!AF6*VLOOKUP(IF(Assumptions!$D$83=2,'Revenue Forecast'!$BD$34+'Revenue Forecast'!$BE$34,'Revenue Forecast'!$BD$34),Assumptions!$B$67:$C$69,2,TRUE),0) | AG7: =IFNA('Revenue Forecast'!AG6*VLOOKUP(IF(Assumptions!$D$83=2,'Revenue Forecast'!$BD$34+'Revenue Forecast'!$BE$34,'Revenue Forecast'!$BD$34),Assumptions!$B$67:$C$69,2,TRUE),0) | AH7: =IFNA('Revenue Forecast'!AH6*VLOOKUP(IF(Assumptions!$D$83=2,'Revenue Forecast'!$BD$34+'Revenue Forecast'!$BE$34,'Revenue Forecast'!$BD$34),Assumptions!$B$67:$C$69,2,TRUE),0) | AI7: =IFNA('Revenue Forecast'!AI6*VLOOKUP(IF(Assumptions!$D$83=2,'Revenue Forecast'!$BD$34+'Revenue Forecast'!$BE$34,'Revenue Forecast'!$BD$34),Assumptions!$B$67:$C$69,2,TRUE),0) | AJ7: =IFNA('Revenue Forecast'!AJ6*VLOOKUP(IF(Assumptions!$D$83=2,'Revenue Forecast'!$BD$34+'Revenue Forecast'!$BE$34,'Revenue Forecast'!$BD$34),Assumptions!$B$67:$C$69,2,TRUE),0) | ... AN7: =IFNA('Revenue Forecast'!AN6*VLOOKUP(IF(Assumptions!$D$83=2,'Revenue Forecast'!$BD$34+'Revenue Forecast'!$BE$34,'Revenue Forecast'!$BD$34),Assumptions!$B$67:$C$69,2,TRUE),0) | AO7: =IFNA('Revenue Forecast'!AO6*VLOOKUP(IF(Assumptions!$D$83=2,'Revenue Forecast'!$BE$34+'Revenue Forecast'!$BF$34,'Revenue Forecast'!$BE$34),Assumptions!$B$67:$C$69,2,TRUE),0) | AP7: =IFNA('Revenue Forecast'!AP6*VLOOKUP(IF(Assumptions!$D$83=2,'Revenue Forecast'!$BE$34+'Revenue Forecast'!$BF$34,'Revenue Forecast'!$BE$34),Assumptions!$B$67:$C$69,2,TRUE),0) | AQ7: =IFNA('Revenue Forecast'!AQ6*VLOOKUP(IF(Assumptions!$D$83=2,'Revenue Forecast'!$BE$34+'Revenue Forecast'!$BF$34,'Revenue Forecast'!$BE$34),Assumptions!$B$67:$C$69,2,TRUE),0) | AR7: =IFNA('Revenue Forecast'!AR6*VLOOKUP(IF(Assumptions!$D$83=2,'Revenue Forecast'!$BE$34+'Revenue Forecast'!$BF$34,'Revenue Forecast'!$BE$34),Assumptions!$B$67:$C$69,2,TRUE),0) | AS7: =IFNA('Revenue Forecast'!AS6*VLOOKUP(IF(Assumptions!$D$83=2,'Revenue Forecast'!$BE$34+'Revenue Forecast'!$BF$34,'Revenue Forecast'!$BE$34),Assumptions!$B$67:$C$69,2,TRUE),0) | AT7: =IFNA('Revenue Forecast'!AT6*VLOOKUP(IF(Assumptions!$D$83=2,'Revenue Forecast'!$BE$34+'Revenue Forecast'!$BF$34,'Revenue Forecast'!$BE$34),Assumptions!$B$67:$C$69,2,TRUE),0) | AU7: =IFNA('Revenue Forecast'!AU6*VLOOKUP(IF(Assumptions!$D$83=2,'Revenue Forecast'!$BE$34+'Revenue Forecast'!$BF$34,'Revenue Forecast'!$BE$34),Assumptions!$B$67:$C$69,2,TRUE),0) | AV7: =IFNA('Revenue Forecast'!AV6*VLOOKUP(IF(Assumptions!$D$83=2,'Revenue Forecast'!$BE$34+'Revenue Forecast'!$BF$34,'Revenue Forecast'!$BE$34),Assumptions!$B$67:$C$69,2,TRUE),0) | ... AZ7: =IFNA('Revenue Forecast'!AZ6*VLOOKUP(IF(Assumptions!$D$83=2,'Revenue Forecast'!$BE$34+'Revenue Forecast'!$BF$34,'Revenue Forecast'!$BE$34),Assumptions!$B$67:$C$69,2,TRUE),0) | BC7: =SUM(Q7:AB7) | BD7: =SUM(AC7:AN7) | BE7: =SUM(AO7:AZ7) | BF7: ='Revenue Forecast'!BF6*VLOOKUP(IF(Assumptions!$D$83=2,'Revenue Forecast'!$BF$34+Assumptions!$G$21,'Revenue Forecast'!$BF$34),Assumptions!$B$67:$C$69,2,TRUE) | BH7: units x ketel build cost. the tier basis is set by the switch on Assumptions row 83
B8: Upsell | D8: € | Q8: ='Revenue Forecast'!Q6*SUMPRODUCT(Assumptions!$E$112:$E$114,Assumptions!$G$112:$G$114) | R8: ='Revenue Forecast'!R6*SUMPRODUCT(Assumptions!$E$112:$E$114,Assumptions!$G$112:$G$114) | S8: ='Revenue Forecast'!S6*SUMPRODUCT(Assumptions!$E$112:$E$114,Assumptions!$G$112:$G$114) | T8: ='Revenue Forecast'!T6*SUMPRODUCT(Assumptions!$E$112:$E$114,Assumptions!$G$112:$G$114) | U8: ='Revenue Forecast'!U6*SUMPRODUCT(Assumptions!$E$112:$E$114,Assumptions!$G$112:$G$114) | V8: ='Revenue Forecast'!V6*SUMPRODUCT(Assumptions!$E$112:$E$114,Assumptions!$G$112:$G$114) | W8: ='Revenue Forecast'!W6*SUMPRODUCT(Assumptions!$E$112:$E$114,Assumptions!$G$112:$G$114) | X8: ='Revenue Forecast'!X6*SUMPRODUCT(Assumptions!$E$112:$E$114,Assumptions!$G$112:$G$114) | ... AZ8: ='Revenue Forecast'!AZ6*SUMPRODUCT(Assumptions!$E$112:$E$114,Assumptions!$G$112:$G$114) | BC8: =SUM(Q8:AB8) | BD8: =SUM(AC8:AN8) | BE8: =SUM(AO8:AZ8) | BF8: ='Revenue Forecast'!BF6*SUMPRODUCT(Assumptions!$E$112:$E$114,Assumptions!$G$112:$G$114) | BH8: units x upsell cost (attach % x cost of each item)
B9: Total TTK COGS | D9: € | Q9: =sum(Q7:Q8) | R9: =sum(R7:R8) | S9: =sum(S7:S8) | T9: =sum(T7:T8) | U9: =sum(U7:U8) | V9: =sum(V7:V8) | W9: =sum(W7:W8) | X9: =sum(X7:X8) | ... AZ9: =sum(AZ7:AZ8) | BB9: =SUM(E9:P9) | BC9: =SUM(Q9:AB9) | BD9: =SUM(AC9:AN9) | BE9: =SUM(AO9:AZ9) | BF9: =sum(BF7:BF8) | BH9: machine cost + upsell cost
B11: COMBI+
B12: Combi+ | Q12: =IFNA('Revenue Forecast'!Q12*(VLOOKUP('Revenue Forecast'!$BC$34,Assumptions!$B$67:$C$69,2,TRUE)+VLOOKUP('Revenue Forecast'!$BC$12,Assumptions!$B$78:$C$80,2,TRUE)+Assumptions!$E$74),0) | R12: =IFNA('Revenue Forecast'!R12*(VLOOKUP('Revenue Forecast'!$BC$34,Assumptions!$B$67:$C$69,2,TRUE)+VLOOKUP('Revenue Forecast'!$BC$12,Assumptions!$B$78:$C$80,2,TRUE)+Assumptions!$E$74),0) | S12: =IFNA('Revenue Forecast'!S12*(VLOOKUP('Revenue Forecast'!$BC$34,Assumptions!$B$67:$C$69,2,TRUE)+VLOOKUP('Revenue Forecast'!$BC$12,Assumptions!$B$78:$C$80,2,TRUE)+Assumptions!$E$74),0) | T12: =IFNA('Revenue Forecast'!T12*(VLOOKUP('Revenue Forecast'!$BC$34,Assumptions!$B$67:$C$69,2,TRUE)+VLOOKUP('Revenue Forecast'!$BC$12,Assumptions!$B$78:$C$80,2,TRUE)+Assumptions!$E$74),0) | U12: =IFNA('Revenue Forecast'!U12*(VLOOKUP('Revenue Forecast'!$BC$34,Assumptions!$B$67:$C$69,2,TRUE)+VLOOKUP('Revenue Forecast'!$BC$12,Assumptions!$B$78:$C$80,2,TRUE)+Assumptions!$E$74),0) | V12: =IFNA('Revenue Forecast'!V12*(VLOOKUP('Revenue Forecast'!$BC$34,Assumptions!$B$67:$C$69,2,TRUE)+VLOOKUP('Revenue Forecast'!$BC$12,Assumptions!$B$78:$C$80,2,TRUE)+Assumptions!$E$74),0) | W12: =IFNA('Revenue Forecast'!W12*(VLOOKUP('Revenue Forecast'!$BC$34,Assumptions!$B$67:$C$69,2,TRUE)+VLOOKUP('Revenue Forecast'!$BC$12,Assumptions!$B$78:$C$80,2,TRUE)+Assumptions!$E$74),0) | X12: =IFNA('Revenue Forecast'!X12*(VLOOKUP('Revenue Forecast'!$BC$34,Assumptions!$B$67:$C$69,2,TRUE)+VLOOKUP('Revenue Forecast'!$BC$12,Assumptions!$B$78:$C$80,2,TRUE)+Assumptions!$E$74),0) | ... AB12: =IFNA('Revenue Forecast'!AB12*(VLOOKUP('Revenue Forecast'!$BC$34,Assumptions!$B$67:$C$69,2,TRUE)+VLOOKUP('Revenue Forecast'!$BC$12,Assumptions!$B$78:$C$80,2,TRUE)+Assumptions!$E$74),0) | AC12: =IFNA('Revenue Forecast'!AC12*(VLOOKUP(IF(Assumptions!$D$83=2,'Revenue Forecast'!$BD$34+'Revenue Forecast'!$BE$34,'Revenue Forecast'!$BD$34),Assumptions!$B$67:$C$69,2,TRUE)+VLOOKUP(IF(Assumptions!$D$83=2,'Revenue Forecast'!$BD$12+'Revenue Forecast'!$BE$12,'Revenue Forecast'!$BD$12),Assumptions!$B$78:$C$80,2,TRUE)+Assumptions!$E$74),0) | AD12: =IFNA('Revenue Forecast'!AD12*(VLOOKUP(IF(Assumptions!$D$83=2,'Revenue Forecast'!$BD$34+'Revenue Forecast'!$BE$34,'Revenue Forecast'!$BD$34),Assumptions!$B$67:$C$69,2,TRUE)+VLOOKUP(IF(Assumptions!$D$83=2,'Revenue Forecast'!$BD$12+'Revenue Forecast'!$BE$12,'Revenue Forecast'!$BD$12),Assumptions!$B$78:$C$80,2,TRUE)+Assumptions!$E$74),0) | AE12: =IFNA('Revenue Forecast'!AE12*(VLOOKUP(IF(Assumptions!$D$83=2,'Revenue Forecast'!$BD$34+'Revenue Forecast'!$BE$34,'Revenue Forecast'!$BD$34),Assumptions!$B$67:$C$69,2,TRUE)+VLOOKUP(IF(Assumptions!$D$83=2,'Revenue Forecast'!$BD$12+'Revenue Forecast'!$BE$12,'Revenue Forecast'!$BD$12),Assumptions!$B$78:$C$80,2,TRUE)+Assumptions!$E$74),0) | AF12: =IFNA('Revenue Forecast'!AF12*(VLOOKUP(IF(Assumptions!$D$83=2,'Revenue Forecast'!$BD$34+'Revenue Forecast'!$BE$34,'Revenue Forecast'!$BD$34),Assumptions!$B$67:$C$69,2,TRUE)+VLOOKUP(IF(Assumptions!$D$83=2,'Revenue Forecast'!$BD$12+'Revenue Forecast'!$BE$12,'Revenue Forecast'!$BD$12),Assumptions!$B$78:$C$80,2,TRUE)+Assumptions!$E$74),0) | AG12: =IFNA('Revenue Forecast'!AG12*(VLOOKUP(IF(Assumptions!$D$83=2,'Revenue Forecast'!$BD$34+'Revenue Forecast'!$BE$34,'Revenue Forecast'!$BD$34),Assumptions!$B$67:$C$69,2,TRUE)+VLOOKUP(IF(Assumptions!$D$83=2,'Revenue Forecast'!$BD$12+'Revenue Forecast'!$BE$12,'Revenue Forecast'!$BD$12),Assumptions!$B$78:$C$80,2,TRUE)+Assumptions!$E$74),0) | AH12: =IFNA('Revenue Forecast'!AH12*(VLOOKUP(IF(Assumptions!$D$83=2,'Revenue Forecast'!$BD$34+'Revenue Forecast'!$BE$34,'Revenue Forecast'!$BD$34),Assumptions!$B$67:$C$69,2,TRUE)+VLOOKUP(IF(Assumptions!$D$83=2,'Revenue Forecast'!$BD$12+'Revenue Forecast'!$BE$12,'Revenue Forecast'!$BD$12),Assumptions!$B$78:$C$80,2,TRUE)+Assumptions!$E$74),0) | AI12: =IFNA('Revenue Forecast'!AI12*(VLOOKUP(IF(Assumptions!$D$83=2,'Revenue Forecast'!$BD$34+'Revenue Forecast'!$BE$34,'Revenue Forecast'!$BD$34),Assumptions!$B$67:$C$69,2,TRUE)+VLOOKUP(IF(Assumptions!$D$83=2,'Revenue Forecast'!$BD$12+'Revenue Forecast'!$BE$12,'Revenue Forecast'!$BD$12),Assumptions!$B$78:$C$80,2,TRUE)+Assumptions!$E$74),0) | AJ12: =IFNA('Revenue Forecast'!AJ12*(VLOOKUP(IF(Assumptions!$D$83=2,'Revenue Forecast'!$BD$34+'Revenue Forecast'!$BE$34,'Revenue Forecast'!$BD$34),Assumptions!$B$67:$C$69,2,TRUE)+VLOOKUP(IF(Assumptions!$D$83=2,'Revenue Forecast'!$BD$12+'Revenue Forecast'!$BE$12,'Revenue Forecast'!$BD$12),Assumptions!$B$78:$C$80,2,TRUE)+Assumptions!$E$74),0) | ... AN12: =IFNA('Revenue Forecast'!AN12*(VLOOKUP(IF(Assumptions!$D$83=2,'Revenue Forecast'!$BD$34+'Revenue Forecast'!$BE$34,'Revenue Forecast'!$BD$34),Assumptions!$B$67:$C$69,2,TRUE)+VLOOKUP(IF(Assumptions!$D$83=2,'Revenue Forecast'!$BD$12+'Revenue Forecast'!$BE$12,'Revenue Forecast'!$BD$12),Assumptions!$B$78:$C$80,2,TRUE)+Assumptions!$E$74),0) | AO12: =IFNA('Revenue Forecast'!AO12*(VLOOKUP(IF(Assumptions!$D$83=2,'Revenue Forecast'!$BE$34+'Revenue Forecast'!$BF$34,'Revenue Forecast'!$BE$34),Assumptions!$B$67:$C$69,2,TRUE)+VLOOKUP(IF(Assumptions!$D$83=2,'Revenue Forecast'!$BE$12+'Revenue Forecast'!$BF$12,'Revenue Forecast'!$BE$12),Assumptions!$B$78:$C$80,2,TRUE)+Assumptions!$E$74),0) | AP12: =IFNA('Revenue Forecast'!AP12*(VLOOKUP(IF(Assumptions!$D$83=2,'Revenue Forecast'!$BE$34+'Revenue Forecast'!$BF$34,'Revenue Forecast'!$BE$34),Assumptions!$B$67:$C$69,2,TRUE)+VLOOKUP(IF(Assumptions!$D$83=2,'Revenue Forecast'!$BE$12+'Revenue Forecast'!$BF$12,'Revenue Forecast'!$BE$12),Assumptions!$B$78:$C$80,2,TRUE)+Assumptions!$E$74),0) | AQ12: =IFNA('Revenue Forecast'!AQ12*(VLOOKUP(IF(Assumptions!$D$83=2,'Revenue Forecast'!$BE$34+'Revenue Forecast'!$BF$34,'Revenue Forecast'!$BE$34),Assumptions!$B$67:$C$69,2,TRUE)+VLOOKUP(IF(Assumptions!$D$83=2,'Revenue Forecast'!$BE$12+'Revenue Forecast'!$BF$12,'Revenue Forecast'!$BE$12),Assumptions!$B$78:$C$80,2,TRUE)+Assumptions!$E$74),0) | AR12: =IFNA('Revenue Forecast'!AR12*(VLOOKUP(IF(Assumptions!$D$83=2,'Revenue Forecast'!$BE$34+'Revenue Forecast'!$BF$34,'Revenue Forecast'!$BE$34),Assumptions!$B$67:$C$69,2,TRUE)+VLOOKUP(IF(Assumptions!$D$83=2,'Revenue Forecast'!$BE$12+'Revenue Forecast'!$BF$12,'Revenue Forecast'!$BE$12),Assumptions!$B$78:$C$80,2,TRUE)+Assumptions!$E$74),0) | AS12: =IFNA('Revenue Forecast'!AS12*(VLOOKUP(IF(Assumptions!$D$83=2,'Revenue Forecast'!$BE$34+'Revenue Forecast'!$BF$34,'Revenue Forecast'!$BE$34),Assumptions!$B$67:$C$69,2,TRUE)+VLOOKUP(IF(Assumptions!$D$83=2,'Revenue Forecast'!$BE$12+'Revenue Forecast'!$BF$12,'Revenue Forecast'!$BE$12),Assumptions!$B$78:$C$80,2,TRUE)+Assumptions!$E$74),0) | AT12: =IFNA('Revenue Forecast'!AT12*(VLOOKUP(IF(Assumptions!$D$83=2,'Revenue Forecast'!$BE$34+'Revenue Forecast'!$BF$34,'Revenue Forecast'!$BE$34),Assumptions!$B$67:$C$69,2,TRUE)+VLOOKUP(IF(Assumptions!$D$83=2,'Revenue Forecast'!$BE$12+'Revenue Forecast'!$BF$12,'Revenue Forecast'!$BE$12),Assumptions!$B$78:$C$80,2,TRUE)+Assumptions!$E$74),0) | AU12: =IFNA('Revenue Forecast'!AU12*(VLOOKUP(IF(Assumptions!$D$83=2,'Revenue Forecast'!$BE$34+'Revenue Forecast'!$BF$34,'Revenue Forecast'!$BE$34),Assumptions!$B$67:$C$69,2,TRUE)+VLOOKUP(IF(Assumptions!$D$83=2,'Revenue Forecast'!$BE$12+'Revenue Forecast'!$BF$12,'Revenue Forecast'!$BE$12),Assumptions!$B$78:$C$80,2,TRUE)+Assumptions!$E$74),0) | AV12: =IFNA('Revenue Forecast'!AV12*(VLOOKUP(IF(Assumptions!$D$83=2,'Revenue Forecast'!$BE$34+'Revenue Forecast'!$BF$34,'Revenue Forecast'!$BE$34),Assumptions!$B$67:$C$69,2,TRUE)+VLOOKUP(IF(Assumptions!$D$83=2,'Revenue Forecast'!$BE$12+'Revenue Forecast'!$BF$12,'Revenue Forecast'!$BE$12),Assumptions!$B$78:$C$80,2,TRUE)+Assumptions!$E$74),0) | ... AZ12: =IFNA('Revenue Forecast'!AZ12*(VLOOKUP(IF(Assumptions!$D$83=2,'Revenue Forecast'!$BE$34+'Revenue Forecast'!$BF$34,'Revenue Forecast'!$BE$34),Assumptions!$B$67:$C$69,2,TRUE)+VLOOKUP(IF(Assumptions!$D$83=2,'Revenue Forecast'!$BE$12+'Revenue Forecast'!$BF$12,'Revenue Forecast'!$BE$12),Assumptions!$B$78:$C$80,2,TRUE)+Assumptions!$E$74),0) | BC12: =SUM(Q12:AB12) | BD12: =SUM(AC12:AN12) | BE12: =SUM(AO12:AZ12) | BF12: ='Revenue Forecast'!BF12*(VLOOKUP(IF(Assumptions!$D$83=2,'Revenue Forecast'!$BF$34+Assumptions!$G$21,'Revenue Forecast'!$BF$34),Assumptions!$B$67:$C$69,2,TRUE)+VLOOKUP(IF(Assumptions!$D$83=2,'Revenue Forecast'!$BF$12+Assumptions!$G$24,'Revenue Forecast'!$BF$12),Assumptions!$B$78:$C$80,2,TRUE)+Assumptions!$E$74) | BH12: units x (ketel tier + outdoor unit tier + shipping), ketel tier per the row-83 switch
B13: Upsell | Q13: ='Revenue Forecast'!Q12*SUMPRODUCT(Assumptions!$E$112:$E$114,Assumptions!$G$112:$G$114) | R13: ='Revenue Forecast'!R12*SUMPRODUCT(Assumptions!$E$112:$E$114,Assumptions!$G$112:$G$114) | S13: ='Revenue Forecast'!S12*SUMPRODUCT(Assumptions!$E$112:$E$114,Assumptions!$G$112:$G$114) | T13: ='Revenue Forecast'!T12*SUMPRODUCT(Assumptions!$E$112:$E$114,Assumptions!$G$112:$G$114) | U13: ='Revenue Forecast'!U12*SUMPRODUCT(Assumptions!$E$112:$E$114,Assumptions!$G$112:$G$114) | V13: ='Revenue Forecast'!V12*SUMPRODUCT(Assumptions!$E$112:$E$114,Assumptions!$G$112:$G$114) | W13: ='Revenue Forecast'!W12*SUMPRODUCT(Assumptions!$E$112:$E$114,Assumptions!$G$112:$G$114) | X13: ='Revenue Forecast'!X12*SUMPRODUCT(Assumptions!$E$112:$E$114,Assumptions!$G$112:$G$114) | ... AZ13: ='Revenue Forecast'!AZ12*SUMPRODUCT(Assumptions!$E$112:$E$114,Assumptions!$G$112:$G$114) | BC13: =SUM(Q13:AB13) | BD13: =SUM(AC13:AN13) | BE13: =SUM(AO13:AZ13) | BF13: ='Revenue Forecast'!BF12*SUMPRODUCT(Assumptions!$E$112:$E$114,Assumptions!$G$112:$G$114) | BH13: units x upsell cost
B14: Total Combi+ COGS | Q14: =sum(Q12:Q13) | R14: =sum(R12:R13) | S14: =sum(S12:S13) | T14: =sum(T12:T13) | U14: =sum(U12:U13) | V14: =sum(V12:V13) | W14: =sum(W12:W13) | X14: =sum(X12:X13) | ... AZ14: =sum(AZ12:AZ13) | BC14: =sum(BC12:BC13) | BD14: =sum(BD12:BD13) | BE14: =sum(BE12:BE13) | BF14: =sum(BF12:BF13) | BH14: machine cost + upsell cost
B16: INSTALLATION
B17: Installation COGS (pass-through, = installation revenue) | D17: € | Q17: ='Revenue Forecast'!Q19 | R17: ='Revenue Forecast'!R19 | S17: ='Revenue Forecast'!S19 | T17: ='Revenue Forecast'!T19 | U17: ='Revenue Forecast'!U19 | V17: ='Revenue Forecast'!V19 | W17: ='Revenue Forecast'!W19 | X17: ='Revenue Forecast'!X19 | ... AZ17: ='Revenue Forecast'!AZ19 | BB17: ='Revenue Forecast'!BB19 | BC17: ='Revenue Forecast'!BC19 | BD17: ='Revenue Forecast'!BD19 | BE17: ='Revenue Forecast'!BE19 | BF17: ='Revenue Forecast'!BF19 | BH17: same number as installation revenue. pass-through, zero margin
B19: SERVICE REVENUES
B20: Total Service Revenue | D20: € | Q20: ='Revenue Forecast'!Q34*SUMPRODUCT(Assumptions!$E$120:$E$121,Assumptions!$G$120:$G$121)+E20 | R20: ='Revenue Forecast'!R34*SUMPRODUCT(Assumptions!$E$120:$E$121,Assumptions!$G$120:$G$121)+F20 | S20: ='Revenue Forecast'!S34*SUMPRODUCT(Assumptions!$E$120:$E$121,Assumptions!$G$120:$G$121)+G20 | T20: ='Revenue Forecast'!T34*SUMPRODUCT(Assumptions!$E$120:$E$121,Assumptions!$G$120:$G$121)+H20 | U20: ='Revenue Forecast'!U34*SUMPRODUCT(Assumptions!$E$120:$E$121,Assumptions!$G$120:$G$121)+I20 | V20: ='Revenue Forecast'!V34*SUMPRODUCT(Assumptions!$E$120:$E$121,Assumptions!$G$120:$G$121)+J20 | W20: ='Revenue Forecast'!W34*SUMPRODUCT(Assumptions!$E$120:$E$121,Assumptions!$G$120:$G$121)+K20 | X20: ='Revenue Forecast'!X34*SUMPRODUCT(Assumptions!$E$120:$E$121,Assumptions!$G$120:$G$121)+L20 | ... AZ20: ='Revenue Forecast'!AZ34*SUMPRODUCT(Assumptions!$E$120:$E$121,Assumptions!$G$120:$G$121)+AN20 | BB20: =SUM(E20:P20) | BC20: =SUM(Q20:AB20) | BD20: =sum(AC20:AN20) | BE20: =sum(AO20:AZ20)+BD20 | BF20: ='Revenue Forecast'!BF34*SUMPRODUCT(Assumptions!$E$120:$E$121,Assumptions!$G$120:$G$121)+BE20 | BH20: units x cost per service contract + last year's, stacks like the revenue
B22: TOTAL COGS | M22: =M7 | N22: =N9+N17+N20 | O22: =O9+O17+O20 | P22: =P9+P17+P20 | Q22: =Q9+Q14+Q17+Q20 | R22: =R9+R14+R17+R20 | S22: =S9+S14+S17+S20 | T22: =T9+T14+T17+T20 | U22: =U9+U14+U17+U20 | V22: =V9+V14+V17+V20 | W22: =W9+W14+W17+W20 | X22: =X9+X14+X17+X20 | ... AZ22: =AZ9+AZ14+AZ17+AZ20 | BB22: =BB9+BB14+BB17+BB20 | BC22: =BC9+BC14+BC17+BC20 | BD22: =BD9+BD14+BD17+BD20 | BE22: =BE9+BE14+BE17+BE20 | BF22: =BF9+BF14+BF17+BF20 | BH22: TTK + Combi+ + installation + service costs

Sheet OPEX
B1: Tarnoc B.V. — OPEX Forecast (€, negative = cost) | U1: Actual | V1: Projected
G2: 2025 | S2: 2026 | AE2: 2027 | AQ2: 2028
G3: 45658 | H3: 45689 | I3: 45717 | J3: 45748 | K3: 45778 | L3: 45809 | M3: 45839 | N3: 45870 | O3: 45901 | P3: 45931 | Q3: 45962 | R3: 45992 | S3: 46023 | T3: 46054 | U3: 46082 | V3: 46113 | W3: 46143 | X3: 46174 | Y3: 46204 | Z3: 46235 | AA3: 46266 | AB3: 46296 | AC3: 46327 | AD3: 46357 | AE3: 46388 | AF3: 46419 | AG3: 46447 | AH3: 46478 | AI3: 46508 | AJ3: 46539 | AK3: 46569 | AL3: 46600 | AM3: 46631 | AN3: 46661 | AO3: 46692 | AP3: 46722 | AQ3: 46753 | AR3: 46784 | AS3: 46813 | AT3: 46844 | AU3: 46874 | AV3: 46905 | AW3: 46935 | AX3: 46966 | AY3: 46997 | AZ3: 47027 | BA3: 47058 | BB3: 47088 | BD3: 2025 | BE3: 2026 | BF3: 2027 | BG3: 2028 | BH3: 2029 | BK3: what this row does
B5: PERSONNEL
