Workbook

Sheet Cover
B15: Financial Model
B19: Currency: EUR (€)
B21: STRICTLY CONFIDENTIAL

Sheet How to read me
B1: Tarnoc — How to Read This Model
B3: COLOR CODING
B4: Sample | C4: Assumptions are hardcoded inputs (sourced from documents)
B5: Sample | C5: Hardcoded historicalsis actual data from source documents
B6: Sample | C6: Formula cells are calculated, not hardcoded
B7: Sample | C7: Subtotal / total rows
B8: Sample | C8: Section headers / grand totals
B9: Sample | C9: Subsection headers
B10: Sample | C10: Margin / ratio rows (grey)
B11: Sample | C11: Balance sheet check rows (must = 0)
B14: FORMULA ARCHITECTURE
B15: Assumptions → Revenue Forecast, COGS, OPEX, CAPEX, Personnel (all drivers sourced here)
B16: Revenue Forecast → Financial Statements (revenue lines via cross-sheet links)
B17: COGS → Financial Statements (cost lines via cross-sheet links)
B18: OPEX → Financial Statements (opex lines via cross-sheet links)
B20: To change a number: ONLY edit cells in the Assumptions tab (yellow/orange).
B21: All other tabs will recalculate automatically.
B24: FURTHER EXPLANATIONS
B25: Subsidies: Tarnoc is and has been eligible for a number of subsidies. We will consider application for large projects, however this model excludes the forecast of any subsidy financing foing forward.
B26: Installation revenues: This is modelled fully as pass through revenue for now, as we plan to charge a customer exactly what we pay the installation partner for these services. This is subject to change in the future.
B27: Tarnoc's main products are the TTK (turbineketel), the Combi and Combi+ (turbineketel + outdoor unit), and the Twincycle (in development for 2027). Every unit contains a turbineketel; the Combi and Combi+ differ only by their outdoor unit and installation. We also plan to sell various add-ons such as performance booster units, boilers for hybrid setups, and sound reduction units.
B28: Service Revenues: Service revenues are calculated relative to installed base. We assume a certain percentage (see assumptions) of customers will purchase our Service package, and are charged annually.
... B31: Revenues: Customer deposits have so far been collected at a TTK sales price of €8,099. We recently increased the list price to €8,925. For the purposes of this financial model, we assume an average selling price of €8,526, which we view as a conservative lower-bound assumption. Based on current market feedback, we believe the long-term market-clearing price is more likely to be approximately €9,000, although this will be validated over time as commercial sales progress.

Sheet Assumptions
B2: Drivers & Assumptions
B3: ASSUMPTIONS
B5: General Assumptions
B6: Opening Cash Balance (Jan 2024) | C6: 29538.9
B7: Annual salary increase (%) | C7: 0.08
B8: Employer cost basis | C8: Werkgeverlasten (incl. taxes)
B9: Holiday pay (%) | C9: 0.08
B10: Income tax rate | C10: 0.258
B11: Interst on WC loan | C11: 0.05
B13: Working Capital | H13: 20
B15: Days Sales Outstanding (DSO) | C15: days | D15: 20
B16: Days Payable Outstanding (DPO) | C16: days | D16: 45
B17: Days Inventory Outstanding (DIO) | C17: days | D17: 0
B18: Pre-payment | C18: %
B20: Revenue Build
B21: ~Units sold | D21: 1000 | E21: 3000 | F21: 6000 | G21: 12000
C22: 2026 | D22: 2027 | E22: 2028 | F22: 2029 | G22: 2030
B23: TTK | C23: 0 | D23: =D$21*$H23 -> 400 | E23: =E$21*$H23 -> 1200 | F23: =F$21*$H23 -> 2400 | G23: =G$21*$H23 -> 4800 | H23: 0.4
B24: Combi | C24: 0 | D24: =D$21*$H24 -> 300 | E24: =E$21*$H24 -> 900 | F24: =F$21*$H24 -> 1800 | G24: =G$21*$H24 -> 3600 | H24: 0.3
B25: Combi+ | C25: 0 | D25: =D$21*$H25 -> 300 | E25: =E$21*$H25 -> 900 | F25: =F$21*$H25 -> 1800 | G25: =G$21*$H25 -> 3600 | H25: 0.3
B28: Pricing
B29: PRICING — build-up (turbineketel + outdoor unit) | D29: (inc VAT)
B30: Turbineketel base price (all products) | C30: 8525.62 | D30: =C30*1.21 -> 10316
B31: Outdoor unit — Combi | C31: 2252.07 | D31: =C31*1.21 -> 2725.0047
B32: Outdoor unit — Combi+ | C32: 5309.92 | D32: =C32*1.21 -> 6425.0032
B33: Combi price (ketel + ODU) | C33: =C30+C31 -> 10777.69 | D33: =C33*1.21 -> 13041.005
B34: Combi+ price (ketel + ODU) | C34: =C30+C32 -> 13835.54 | D34: =C34*1.21 -> 16741.003
B35: INSTALLATION (PASS-THROUGH; REV=COST)
B36: Installation — TTK | C36: 2800
B37: Installation — Combi | C37: 3800
B38: Installation — Combi+ | C38: 3800
B39: COGS
B40: TTK
B41: Bill of Materials TTK supplier 1
B42: # | C42: Category | D42: Component | E42: 1,000 units | F42: 5,000 units | G42: 10,000 units | H42: Unit | I42: Source
B43: B1 | C43: Supplier 1 | D43: Compressor + VFD | E43: 6314 | F43: 4500 | G43: 2692.44 | H43: €/unit | I43: Source: BOM data provided
B44: B2 | C44: Supplier 1 | D44: Heat exchangers (set) | E44: 805.5 | F44: =E44*0.7 -> 563.85 | G44: =0.6*F44 -> 338.31 | H44: €/unit | I44: Source: BOM data provided
B45: B3 | C45: Supplier 1 | D45: Electronics & Power Electronics | E45: 632.92 | F45: =E45*0.7 -> 443.044 | G45: =0.6*F45 -> 265.8264 | H45: €/unit | I45: Source: BOM data provided
B46: B4 | C46: Supplier 1 | D46: Hydraulic Components (Pumps, Valves, etc.) | E46: 283.76 | F46: =E46*0.7 -> 198.632 | G46: =0.6*F46 -> 119.1792 | H46: €/unit | I46: Source: BOM data provided
B47: B5 | C47: Supplier 1 | D47: Silencer & Insulation | E47: 118.48 | F47: =E47*0.7 -> 82.936 | G47: =0.6*F47 -> 49.7616 | H47: €/unit | I47: Source: BOM data provided
...

Sheet Financial Statements
B1: Tarnoc B.V. — Financial Statements (€)
E2: 2025 | Q2: 2026 | AC2: 2027 | AO2: 2028
E3: 45658 | F3: 45689 | G3: 45717 | H3: 45748 | I3: 45778 | J3: 45809 | K3: 45839 | L3: 45870 | M3: 45901 | N3: 45931 | O3: 45962 | P3: 45992 | Q3: 46023 | R3: 46054 | S3: 46082 | T3: 46113 | U3: 46143 | V3: 46174 | W3: 46204 | X3: 46235 | Y3: 46266 | Z3: 46296 | AA3: 46327 | AB3: 46357 | AC3: 46388 | AD3: 46419 | AE3: 46447 | AF3: 46478 | AG3: 46508 | AH3: 46539 | AI3: 46569 | AJ3: 46600 | AK3: 46631 | AL3: 46661 | AM3: 46692 | AN3: 46722 | AO3: 46753 | AP3: 46784 | AQ3: 46813 | AR3: 46844 | AS3: 46874 | AT3: 46905 | AU3: 46935 | AV3: 46966 | AW3: 46997 | AX3: 47027 | AY3: 47058 | AZ3: 47088 | BB3: 2025 | BC3: 2026 | BD3: 2027 | BE3: 2028 | BF3: 2029
B5: PROFIT & LOSS STATEMENT
B6: Revenues
B7: TTK | D7: € | M7: ='Revenue Forecast'!M9 | N7: ='Revenue Forecast'!N9 | O7: ='Revenue Forecast'!O9 | P7: ='Revenue Forecast'!P9 | Q7: ='Revenue Forecast'!Q9 -> 0 | R7: ='Revenue Forecast'!R9 -> 0 | S7: ='Revenue Forecast'!S9 -> 0 | T7: ='Revenue Forecast'!T9 -> 0 | ... AZ7: ='Revenue Forecast'!AZ9 -> 1408448.6 | BB7: =sum(E7:P7) -> 0 | BC7: =sum(Q7:AB7) -> 0 | BD7: =sum(AC7:AN7) -> 3611406.7 | BE7: =sum(AO7:AZ7) -> 10834220 | BF7: ='Revenue Forecast'!BF9 -> 21670840
B8: Combi | D8: € | M8: ='Revenue Forecast'!M15 | N8: ='Revenue Forecast'!N15 | O8: ='Revenue Forecast'!O15 | P8: ='Revenue Forecast'!P15 | Q8: ='Revenue Forecast'!Q15 -> 0 | R8: ='Revenue Forecast'!R15 -> 0 | S8: ='Revenue Forecast'!S15 -> 0 | T8: ='Revenue Forecast'!T15 -> 0 | ... AZ8: ='Revenue Forecast'!AZ15 -> 1331109.2 | BB8: =sum(E8:P8) -> 0 | BC8: =sum(Q8:AB8) -> 0 | BD8: =sum(AC8:AN8) -> 3384176 | BE8: =sum(AO8:AZ8) -> 10152528 | BF8: ='Revenue Forecast'!BF15 -> 20305056
B9: Combi+ | D9: € | Q9: ='Revenue Forecast'!Q21 -> 0 | R9: ='Revenue Forecast'!R21 -> 0 | S9: ='Revenue Forecast'!S21 -> 0 | T9: ='Revenue Forecast'!T21 -> 0 | U9: ='Revenue Forecast'!U21 -> 0 | V9: ='Revenue Forecast'!V21 -> 0 | W9: ='Revenue Forecast'!W21 -> 0 | X9: ='Revenue Forecast'!X21 -> 0 | ... AZ9: ='Revenue Forecast'!AZ21 -> 1691935.5 | BB9: ='Revenue Forecast'!BB21 -> 0 | BC9: ='Revenue Forecast'!BC21 -> 0 | BD9: ='Revenue Forecast'!BD21 -> 4301531 | BE9: ='Revenue Forecast'!BE21 -> 12904593 | BF9: ='Revenue Forecast'!BF21 -> 25809186
B10: Other | D10: € | M10: ='Revenue Forecast'!M25+'Revenue Forecast'!M31 -> 0 | N10: ='Revenue Forecast'!N25+'Revenue Forecast'!N31 -> 0 | O10: ='Revenue Forecast'!O25+'Revenue Forecast'!O31 -> 0 | P10: ='Revenue Forecast'!P25+'Revenue Forecast'!P31 -> 0 | Q10: ='Revenue Forecast'!Q25+'Revenue Forecast'!Q31 -> 0 | R10: ='Revenue Forecast'!R25+'Revenue Forecast'!R31 -> 0 | S10: ='Revenue Forecast'!S25+'Revenue Forecast'!S31 -> 0 | T10: ='Revenue Forecast'!T25+'Revenue Forecast'!T31 -> 0 | ... AZ10: ='Revenue Forecast'!AZ25+'Revenue Forecast'!AZ31 -> 1416757 | BB10: =sum(E10:P10) -> 0 | BC10: =sum(Q10:AB10) -> 0 | BD10: =sum(AC10:AN10) -> 3559000 | BE10: =sum(AO10:AZ10) -> 10836000 | BF10: ='Revenue Forecast'!BF25+'Revenue Forecast'!BF31 -> 21402177
B11: Subsidies & grants | D11: € | M11: ='Revenue Forecast'!M35 -> 0 | N11: ='Revenue Forecast'!N35 -> 19480 | O11: ='Revenue Forecast'!O35 -> 78000 | P11: ='Revenue Forecast'!P35 -> 0 | Q11: ='Revenue Forecast'!Q35 -> 0 | R11: ='Revenue Forecast'!R35 -> 0 | S11: ='Revenue Forecast'!S35 -> 0 | T11: 0 | U11: ='Revenue Forecast'!U35 -> 0 | V11: ='Revenue Forecast'!V35 -> 0 | W11: ='Revenue Forecast'!W35 -> 0 | X11: ='Revenue Forecast'!X35 -> 106782 | Y11: ='Revenue Forecast'!Y35 -> 0 | Z11: ='Revenue Forecast'!Z35 -> 0 | AA11: ='Revenue Forecast'!AA35 -> 0 | AB11: ='Revenue Forecast'!AB35 -> 0 | ... AZ11: ='Revenue Forecast'!AZ35 -> 0 | BB11: =sum(E11:P11) -> 97480 | BC11: =sum(Q11:AB11) -> 106782 | BD11: pm | BE11: pm | BF11: pm
B12: Total Revenue | D12: € | M12: ='Revenue Forecast'!M37 -> 0 | N12: ='Revenue Forecast'!N37 -> 19480 | O12: ='Revenue Forecast'!O37 -> 78000 | P12: ='Revenue Forecast'!P37 -> 0 | Q12: ='Revenue Forecast'!Q37 -> 0 | R12: ='Revenue Forecast'!R37 -> 0 | S12: ='Revenue Forecast'!S37 -> 0 | T12: ='Revenue Forecast'!T37 -> 0 | ... AZ12: ='Revenue Forecast'!AZ37 -> 5848250.4 | BB12: =sum(E12:P12) -> 97480 | BC12: =sum(Q12:AB12) -> 106782 | BD12: =sum(AC12:AN12) -> 14856114 | BE12: =sum(AO12:AZ12) -> 44727341 | BF12: =sum(BF7:BF11) -> 89187260
B14: Cost of goods sold
B15: TTK | D15: € | E15: =COGS!E9 | F15: =COGS!F9 | G15: =COGS!G9 | H15: =COGS!H9 | I15: =COGS!I9 | J15: =COGS!J9 | K15: =COGS!K9 | L15: =COGS!L9 | ... AZ15: =COGS!AZ9 -> 1136732.1 | BB15: =sum(E15:P15) -> 0 | BC15: =sum(Q15:AB15) -> 0 | BD15: =sum(AC15:AN15) -> 4080688 | BE15: =sum(AO15:AZ15) -> 8744092.8 | BF15: =COGS!BF9 -> 12517920
B16: Combi | D16: € | E16: =COGS!E14 | F16: =COGS!F14 | G16: =COGS!G14 | H16: =COGS!H14 | I16: =COGS!I14 | J16: =COGS!J14 | K16: =COGS!K14 | L16: =COGS!L14 | ... AZ16: =COGS!AZ14 -> 1010682.3 | BB16: =sum(E16:P16) -> 0 | BC16: =sum(Q16:AB16) -> 0 | BD16: =sum(AC16:AN16) -> 3444024 | BE16: =sum(AO16:AZ16) -> 7708593.6 | BF16: =COGS!BF14 -> 11477376
B17: Combi+ | D17: € | Q17: =COGS!Q19 -> 0 | R17: =COGS!R19 -> 0 | S17: =COGS!S19 -> 0 | T17: =COGS!T19 -> 0 | U17: =COGS!U19 -> 0 | V17: =COGS!V19 -> 0 | W17: =COGS!W19 -> 0 | X17: =COGS!X19 -> 0 | ... AZ17: =COGS!AZ19 -> 1037142.6 | BB17: =COGS!BB19 | BC17: =COGS!BC19 -> 0 | BD17: =COGS!BD19 -> 3511296 | BE17: =COGS!BE19 -> 7910409.6 | BF17: =COGS!BF19 -> 11840652
B18: Other | D18: € | E18: =COGS!E22 | F18: =COGS!F22 | G18: =COGS!G22 | H18: =COGS!H22 | I18: =COGS!I22 | J18: =COGS!J22 | K18: =COGS!K22 | L18: =COGS!L22 | ... P18: =COGS!P22 | Q18: =COGS!Q22+COGS!Q27 -> 0 | R18: =COGS!R22+COGS!R27 -> 0 | S18: =COGS!S22+COGS!S27 -> 0 | T18: =COGS!T22+COGS!T27 -> 0 | U18: =COGS!U22+COGS!U27 -> 0 | V18: =COGS!V22+COGS!V27 -> 0 | W18: =COGS!W22+COGS!W27 -> 0 | X18: =COGS!X22+COGS!X27 -> 0 | ... AZ18: =COGS!AZ22+COGS!AZ27 -> 1375178.5 | BB18: =sum(E18:P18) -> 0 | BC18: =sum(Q18:AB18) -> 0 | BD18: =sum(AC18:AN18) -> 3479500 | BE18: =sum(AO18:AZ18) -> 10518000 | BF18: =COGS!BF22 -> 20400000
B19: Total COGS | D19: € | M19: =COGS!M29 -> 0 | N19: =COGS!N29 -> 0 | O19: =COGS!O29 -> 0 | P19: =COGS!P29 -> 0 | Q19: =COGS!Q29 -> 0 | R19: =COGS!R29 -> 0 | S19: =COGS!S29 -> 0 | T19: =COGS!T29 -> 0 | ... AZ19: =COGS!AZ29 -> 4559735.4 | BB19: =sum(E19:P19) -> 0 | BC19: =sum(Q19:AB19) -> 0 | BD19: =sum(AC19:AN19) -> 14515508 | BE19: =sum(AO19:AZ19) -> 34881096 | BF19: =sum(BF15:BF18) -> 56235948
B21: Gross Profit
B22: TTK | D22: € | Q22: =Q7-Q15 -> 0 | R22: =R7-R15 -> 0 | S22: =S7-S15 -> 0 | T22: =T7-T15 -> 0 | U22: =U7-U15 -> 0 | V22: =V7-V15 -> 0 | W22: =W7-W15 -> 0 | X22: =X7-X15 -> 0 | ... AZ22: =AZ7-AZ15 -> 271716.56 | BC22: =BC7-BC15 -> 0 | BD22: =BD7-BD15 -> -469281.28 | BE22: =BE7-BE15 -> 2090127.4 | BF22: =BF7-BF15 -> 9152920.3
B23: Combi | D23: € | Q23: =Q8-Q16 -> 0 | R23: =R8-R16 -> 0 | S23: =S8-S16 -> 0 | T23: =T8-T16 -> 0 | U23: =U8-U16 -> 0 | V23: =V8-V16 -> 0 | W23: =W8-W16 -> 0 | X23: =X8-X16 -> 0 | ... AZ23: =AZ8-AZ16 -> 320426.97 | BC23: =BC8-BC16 -> 0 | BD23: =BD8-BD16 -> -59847.96 | BE23: =BE8-BE16 -> 2443934.5 | BF23: =BF8-BF16 -> 8827680.2
B24: Combi+ | D24: € | Q24: =Q9-Q17 -> 0 | R24: =R9-R17 -> 0 | S24: =S9-S17 -> 0 | T24: =T9-T17 -> 0 | U24: =U9-U17 -> 0 | V24: =V9-V17 -> 0 | W24: =W9-W17 -> 0 | X24: =X9-X17 -> 0 | ... AZ24: =AZ9-AZ17 -> 654792.95 | BC24: =BC9-BC17 -> 0 | BD24: =BD9-BD17 -> 790235.04 | BE24: =BE9-BE17 -> 4994183.5 | BF24: =BF9-BF17 -> 13968534
B25: Other | D25: € | Q25: =Q10-Q18 -> 0 | R25: =R10-R18 -> 0 | S25: =S10-S18 -> 0 | T25: =T10-T18 -> 0 | U25: =U10-U18 -> 0 | V25: =V10-V18 -> 0 | W25: =W10-W18 -> 0 | X25: =X10-X18 -> 0 | ... AZ25: =AZ10-AZ18 -> 41578.5 | BC25: =BC10-BC18 -> 0 | BD25: =BD10-BD18 -> 79500 | BE25: =BE10-BE18 -> 318000 | BF25: =BF10-BF18 -> 1002177
B26: Gross Profit | D26: € | M26: =M12-M19 -> 0 | N26: =N12-N19 -> 19480 | O26: =O12-O19 -> 78000 | P26: =P12-P19 -> 0 | Q26: =Q12-Q19 -> 0 | R26: =R12-R19 -> 0 | S26: =S12-S19 -> 0 | T26: =T12-T19 -> 0 | ... AZ26: =AZ12-AZ19 -> 1288515 | BB26: =sum(E26:P26) -> 97480 | BC26: =sum(Q26:AB26) -> 106782 | BD26: =sum(AC26:AN26) -> 340605.8 | BE26: =sum(AO26:AZ26) -> 9846245.4 | BF26: =BF12-BF19 -> 32951312
B27: Gross margin % | D27: % | BD27: =BD26/BD12 -> 0.022926978 | BE27: =BE26/BE12 -> 0.22013929 | BF27: =BF26/BF12 -> 0.36946209
B29: Operational expenses
B30: R&D | D30: € | M30: =OPEX!O38 -> 47500 | N30: =OPEX!P38 -> 47500 | O30: =OPEX!Q38 -> 47500 | P30: =OPEX!R38 -> 216433 | Q30: =OPEX!S38 -> 75700 | R30: =OPEX!T38 -> 75700 | S30: =OPEX!U38 -> 75700 | T30: =OPEX!V38 -> 75700 | ... AZ30: =OPEX!BB38 -> 155927.27 | BB30: =sum(E30:P30) -> 358933 | BC30: =sum(Q30:AB30) -> 1126160 | BD30: =sum(AC30:AN30) -> 1589655.2 | BE30: =sum(AO30:AZ30) -> 1858677.6 | BF30: =OPEX!BH38 -> 2628853.4
B31: S&M | D31: € | M31: =OPEX!O39 -> 0 | N31: =OPEX!P39 -> 0 | O31: =OPEX!Q39 -> 0 | P31: =OPEX!R39 -> 20000 | Q31: =OPEX!S39 -> 21000 | R31: =OPEX!T39 -> 31800 | S31: =OPEX!U39 -> 31800 | T31: =OPEX!V39 -> 31800 | ... AZ31: =OPEX!BB39 -> 299788.12 | BB31: =sum(E31:P31) -> 20000 | BC31: =sum(Q31:AB31) -> 464300 | BD31: =sum(AC31:AN31) -> 1261348 | BE31: =sum(AO31:AZ31) -> 2659678.2 | BF31: =OPEX!BH39 -> 4818295
B32: G&A | D32: € | M32: =OPEX!O40 -> 11500 | N32: =OPEX!P40 -> 11500 | O32: =OPEX!Q40 -> 11500 | P32: =OPEX!R40 -> 11500 | Q32: =OPEX!S40 -> 31820 | R32: =OPEX!T40 -> 31820 | S32: =OPEX!U40 -> 31820 | T32: =OPEX!V40 -> 31820 | ... AZ32: =OPEX!BB40 -> 98395.088 | BB32: =sum(E32:P32) -> 46000 | BC32: =sum(Q32:AB32) -> 462060 | BD32: =sum(AC32:AN32) -> 844843.2 | BE32: =sum(AO32:AZ32) -> 1109410.7 | BF32: =OPEX!BH40 -> 1357154.2
B33: Total OPEX | D33: € | M33: =(M32+M31+M30) -> 59000 | N33: =(N32+N31+N30) -> 59000 | O33: =(O32+O31+O30) -> 59000 | P33: =(P32+P31+P30) -> 247933 | Q33: =(Q32+Q31+Q30) -> 128520 | R33: =(R32+R31+R30) -> 139320 | S33: =(S32+S31+S30) -> 139320 | T33: =(T32+T31+T30) -> 139320 | ... AZ33: =(AZ32+AZ31+AZ30) -> 554110.48 | BB33: =sum(E33:P33) -> 424933 | BC33: =sum(Q33:AB33) -> 2052520 | BD33: =sum(AC33:AN33) -> 3695846.4 | BE33: =sum(AO33:AZ33) -> 5627766.5 | BF33: =sum(BF30:BF32) -> 8804302.6
B35: EBITDA | D35: € | M35: =M26-M33 -> -59000 | N35: =N26-N33 -> -39520 | O35: =O26-O33 -> 19000 | P35: =P26-P33 -> -247933 | Q35: =Q26-Q33 -> -128520 | R35: =R26-R33 -> -139320 | S35: =S26-S33 -> -139320 | T35: =T26-T33 -> -139320 | ... AZ35: =AZ26-AZ33 -> 734404.5 | BB35: =sum(E35:P35) -> -327453 | BC35: =sum(Q35:AB35) -> -1945738 | BD35: =sum(AC35:AN35) -> -3355240.6 | BE35: =sum(AO35:AZ35) -> 4218478.9 | BF35: =BF26-BF33 -> 24147009
B36: EBITDA margin % | D36: % | BE36: =BE35/BE12 -> 0.09431544 | BF36: =BF35/BF12 -> 0.27074505
B38: Depreciation & Amortisation | D38: € | M38: 0 | N38: 0 | O38: 0 | P38: 0 | Q38: 0 | R38: 0 | S38: 0 | T38: 0 | U38: 0 | V38: 0 | W38: 0 | X38: 0 | Y38: 0 | Z38: 0 | AA38: 0 | AB38: 0 | AC38: 0 | AD38: 0 | AE38: 0 | AF38: 0 | AG38: 0 | AH38: 0 | AI38: 0 | AJ38: 0 | AK38: 0 | AL38: 0 | AM38: 0 | AN38: 0 | AO38: 0 | AP38: 0 | AQ38: 0 | AR38: 0 | AS38: 0 | AT38: 0 | AU38: 0 | AV38: 0 | AW38: 0 | AX38: 0 | AY38: 0 | AZ38: 0 | BB38: =sum(E38:P38) -> 0 | BC38: =sum(Q38:AB38) -> 0 | BD38: =sum(AC38:AN38) -> 0 | BE38: =sum(AO38:AZ38) -> 0 | BF38: 0
B39: Interest payments | D39: € | M39: 0 | N39: 0 | O39: 0 | P39: 0 | Q39: =P85*Assumptions!$C$11/12 -> 0 | R39: =Q85*Assumptions!$C$11/12 -> 0 | S39: =R85*Assumptions!$C$11/12 -> 0 | T39: =S85*Assumptions!$C$11/12 -> 0 | U39: =T85*Assumptions!$C$11/12 -> 0 | V39: =U85*Assumptions!$C$11/12 -> 0 | W39: =V85*Assumptions!$C$11/12 -> 0 | X39: =W85*Assumptions!$C$11/12 -> 0 | ... AZ39: =AY85*Assumptions!$C$11/12 -> 2975 | BB39: =sum(E39:P39) -> 0 | BC39: =sum(Q39:AB39) -> 0 | BD39: =sum(AC39:AN39) -> 13164.375 | BE39: =sum(AO39:AZ39) -> 35700 | BF39: =BE85*0.05/12 -> 2975
B40: EBT | D40: € | M40: =M35-sum(M38:M39) -> -59000 | N40: =N35-sum(N38:N39) -> -39520 | O40: =O35-sum(O38:O39) -> 19000 | P40: =P35-sum(P38:P39) -> -247933 | Q40: =Q35-sum(Q38:Q39) -> -128520 | R40: =R35-sum(R38:R39) -> -139320 | S40: =S35-sum(S38:S39) -> -139320 | T40: =T35-sum(T38:T39) -> -139320 | ... AZ40: =AZ35-sum(AZ38:AZ39) -> 731429.5 | BB40: =sum(E40:P40) -> -327453 | BC40: =sum(Q40:AB40) -> -1945738 | BD40: =sum(AC40:AN40) -> -3368405 | BE40: =sum(AO40:AZ40) -> 4182778.9 | BF40: =BF35-sum(BF38:BF39) -> 24144034
BE41: =BE40/BE12 -> 0.093517271 | BF41: =BF40/BF12 -> 0.27071169
B43: Income tax | D43: € | M43: 0 | N43: 0 | O43: 0 | P43: 0 | Q43: 0 | R43: 0 | S43: 0 | T43: 0 | U43: 0 | V43: 0 | W43: 0 | X43: 0 | Y43: 0 | Z43: 0 | AA43: 0 | AB43: 0 | AC43: 0 | AD43: 0 | AE43: 0 | AF43: 0 | AG43: 0 | AH43: 0 | AI43: 0 | AJ43: 0 | AK43: 0 | AL43: 0 | AM43: 0 | AN43: 0 | AO43: 0 | AP43: 0 | AQ43: 0 | AR43: 0 | AS43: 0 | AT43: 0 | AU43: 0 | AV43: 0 | AW43: 0 | AX43: 0 | AY43: 0 | AZ43: 0 | BB43: =sum(E43:P43) -> 0 | BC43: =sum(Q43:AB43) -> 0 | BD43: =sum(AC43:AN43) -> 0 | BE43: =sum(AO43:AZ43) -> 0 | BF43: =(BF40-AZ47)*Assumptions!$C$10 -> 6108057.7
B44: NET INCOME | D44: € | M44: =M40-M43 -> -59000 | N44: =N40-N43 -> -39520 | O44: =O40-O43 -> 19000 | P44: =P40-P43 -> -247933 | Q44: =Q40-Q43 -> -128520 | R44: =R40-R43 -> -139320 | S44: =S40-S43 -> -139320 | T44: =T40-T43 -> -139320 | ... AZ44: =AZ40-AZ43 -> 731429.5 | BB44: =sum(E44:P44) -> -327453 | BC44: =sum(Q44:AB44) -> -1945738 | BD44: =sum(AC44:AN44) -> -3368405 | BE44: =sum(AO44:AZ44) -> 4182778.9 | BF44: =BF40-BF43 -> 18035976
B45: Profit margin % | BE45: =BE44/BE12 -> 0.093517271 | BF45: =BF44/BF12 -> 0.20222593
B47: Tax carry over to be applied | M47: 108239 | N47: =M47+(-N44*Assumptions!$C$10) -> 118435.16 | O47: =N47+(-O44*Assumptions!$C$10) -> 113533.16 | P47: =O47+(-P44*Assumptions!$C$10) -> 177499.87 | Q47: =P47+(-Q44*Assumptions!$C$10) -> 210658.03 | R47: =Q47+(-R44*Assumptions!$C$10) -> 246602.59 | S47: =R47+(-S44*Assumptions!$C$10) -> 282547.15 | T47: =S47+(-T44*Assumptions!$C$10) -> 318491.71 | U47: =T47+(-U44*Assumptions!$C$10) -> 357016.27 | ... AZ47: =AY47+(-AZ44*Assumptions!$C$10) -> 469391.81
B49: CASH FLOW STATEMENT
...

Sheet Revenue Forecast
B1: Tarnoc B.V. — Revenue Forecast (€, ex VAT unless noted)
E2: 2025 | Q2: 2026 | AC2: 2027 | AO2: 2028
E3: 45658 | F3: 45689 | G3: 45717 | H3: 45748 | I3: 45778 | J3: 45809 | K3: 45839 | L3: 45870 | M3: 45901 | N3: 45931 | O3: 45962 | P3: 45992 | Q3: 46023 | R3: 46054 | S3: 46082 | T3: 46113 | U3: 46143 | V3: 46174 | W3: 46204 | X3: 46235 | Y3: 46266 | Z3: 46296 | AA3: 46327 | AB3: 46357 | AC3: 46388 | AD3: 46419 | AE3: 46447 | AF3: 46478 | AG3: 46508 | AH3: 46539 | AI3: 46569 | AJ3: 46600 | AK3: 46631 | AL3: 46661 | AM3: 46692 | AN3: 46722 | AO3: 46753 | AP3: 46784 | AQ3: 46813 | AR3: 46844 | AS3: 46874 | AT3: 46905 | AU3: 46935 | AV3: 46966 | AW3: 46997 | AX3: 47027 | AY3: 47058 | AZ3: 47088 | BB3: 2025 | BC3: 2026 | BD3: 2027 | BE3: 2028 | BF3: 2029
AB4: 2 | AC4: 3 | AD4: 4 | AE4: 5 | AF4: 6 | AG4: 7 | AH4: 8 | AI4: 9 | AJ4: 10 | AK4: 11 | AL4: 12 | AM4: 13 | AN4: 14 | AO4: 15 | AP4: 16 | AQ4: 17 | AR4: 18 | AS4: 19 | AT4: 20 | AU4: 21 | AV4: 22 | AW4: 23 | AX4: 24 | AY4: 25 | AZ4: 26
B5: TURBINEKETEL (TTK)
B6: TTK units sold | D6: # | Q6: {=IF(YEAR(Q$3)=2026,0,ROUND(EXP((LN(Assumptions!$E$23/Assumptions!$D$23)/12)*((YEAR(Q$3)-2027)*12+MONTH(Q$3)-1))/SUMPRODUCT(EXP((LN(Assumptions!$E$23/Assumptions!$D$23)/12)*(ROW(INDIRECT("1:24"))-1)))*SUM(Assumptions!$D$23:$E$23),0))} -> 0 | R6: {=IF(YEAR(R$3)=2026,0,ROUND(EXP((LN(Assumptions!$E$23/Assumptions!$D$23)/12)*((YEAR(R$3)-2027)*12+MONTH(R$3)-1))/SUMPRODUCT(EXP((LN(Assumptions!$E$23/Assumptions!$D$23)/12)*(ROW(INDIRECT("1:24"))-1)))*SUM(Assumptions!$D$23:$E$23),0))} -> 0 | S6: {=IF(YEAR(S$3)=2026,0,ROUND(EXP((LN(Assumptions!$E$23/Assumptions!$D$23)/12)*((YEAR(S$3)-2027)*12+MONTH(S$3)-1))/SUMPRODUCT(EXP((LN(Assumptions!$E$23/Assumptions!$D$23)/12)*(ROW(INDIRECT("1:24"))-1)))*SUM(Assumptions!$D$23:$E$23),0))} -> 0 | T6: {=IF(YEAR(T$3)=2026,0,ROUND(EXP((LN(Assumptions!$E$23/Assumptions!$D$23)/12)*((YEAR(T$3)-2027)*12+MONTH(T$3)-1))/SUMPRODUCT(EXP((LN(Assumptions!$E$23/Assumptions!$D$23)/12)*(ROW(INDIRECT("1:24"))-1)))*SUM(Assumptions!$D$23:$E$23),0))} -> 0 | U6: {=IF(YEAR(U$3)=2026,0,ROUND(EXP((LN(Assumptions!$E$23/Assumptions!$D$23)/12)*((YEAR(U$3)-2027)*12+MONTH(U$3)-1))/SUMPRODUCT(EXP((LN(Assumptions!$E$23/Assumptions!$D$23)/12)*(ROW(INDIRECT("1:24"))-1)))*SUM(Assumptions!$D$23:$E$23),0))} -> 0 | V6: {=IF(YEAR(V$3)=2026,0,ROUND(EXP((LN(Assumptions!$E$23/Assumptions!$D$23)/12)*((YEAR(V$3)-2027)*12+MONTH(V$3)-1))/SUMPRODUCT(EXP((LN(Assumptions!$E$23/Assumptions!$D$23)/12)*(ROW(INDIRECT("1:24"))-1)))*SUM(Assumptions!$D$23:$E$23),0))} -> 0 | W6: {=IF(YEAR(W$3)=2026,0,ROUND(EXP((LN(Assumptions!$E$23/Assumptions!$D$23)/12)*((YEAR(W$3)-2027)*12+MONTH(W$3)-1))/SUMPRODUCT(EXP((LN(Assumptions!$E$23/Assumptions!$D$23)/12)*(ROW(INDIRECT("1:24"))-1)))*SUM(Assumptions!$D$23:$E$23),0))} -> 0 | X6: {=IF(YEAR(X$3)=2026,0,ROUND(EXP((LN(Assumptions!$E$23/Assumptions!$D$23)/12)*((YEAR(X$3)-2027)*12+MONTH(X$3)-1))/SUMPRODUCT(EXP((LN(Assumptions!$E$23/Assumptions!$D$23)/12)*(ROW(INDIRECT("1:24"))-1)))*SUM(Assumptions!$D$23:$E$23),0))} -> 0 | ... AM6: {=IF(YEAR(AM$3)=2026,0,ROUND(EXP((LN(Assumptions!$E$23/Assumptions!$D$23)/12)*((YEAR(AM$3)-2027)*12+MONTH(AM$3)-1))/SUMPRODUCT(EXP((LN(Assumptions!$E$23/Assumptions!$D$23)/12)*(ROW(INDIRECT("1:24"))-1)))*SUM(Assumptions!$D$23:$E$23),0))} -> 48 | AN6: =Assumptions!$D$23-SUM(AC6:AM6) -> 53 | AO6: {=IF(YEAR(AO$3)=2026,0,ROUND(EXP((LN(Assumptions!$E$23/Assumptions!$D$23)/12)*((YEAR(AO$3)-2027)*12+MONTH(AO$3)-1))/SUMPRODUCT(EXP((LN(Assumptions!$E$23/Assumptions!$D$23)/12)*(ROW(INDIRECT("1:24"))-1)))*SUM(Assumptions!$D$23:$E$23),0))} -> 58 | AP6: {=IF(YEAR(AP$3)=2026,0,ROUND(EXP((LN(Assumptions!$E$23/Assumptions!$D$23)/12)*((YEAR(AP$3)-2027)*12+MONTH(AP$3)-1))/SUMPRODUCT(EXP((LN(Assumptions!$E$23/Assumptions!$D$23)/12)*(ROW(INDIRECT("1:24"))-1)))*SUM(Assumptions!$D$23:$E$23),0))} -> 63 | AQ6: {=IF(YEAR(AQ$3)=2026,0,ROUND(EXP((LN(Assumptions!$E$23/Assumptions!$D$23)/12)*((YEAR(AQ$3)-2027)*12+MONTH(AQ$3)-1))/SUMPRODUCT(EXP((LN(Assumptions!$E$23/Assumptions!$D$23)/12)*(ROW(INDIRECT("1:24"))-1)))*SUM(Assumptions!$D$23:$E$23),0))} -> 69 | AR6: {=IF(YEAR(AR$3)=2026,0,ROUND(EXP((LN(Assumptions!$E$23/Assumptions!$D$23)/12)*((YEAR(AR$3)-2027)*12+MONTH(AR$3)-1))/SUMPRODUCT(EXP((LN(Assumptions!$E$23/Assumptions!$D$23)/12)*(ROW(INDIRECT("1:24"))-1)))*SUM(Assumptions!$D$23:$E$23),0))} -> 76 | AS6: {=IF(YEAR(AS$3)=2026,0,ROUND(EXP((LN(Assumptions!$E$23/Assumptions!$D$23)/12)*((YEAR(AS$3)-2027)*12+MONTH(AS$3)-1))/SUMPRODUCT(EXP((LN(Assumptions!$E$23/Assumptions!$D$23)/12)*(ROW(INDIRECT("1:24"))-1)))*SUM(Assumptions!$D$23:$E$23),0))} -> 83 | AT6: {=IF(YEAR(AT$3)=2026,0,ROUND(EXP((LN(Assumptions!$E$23/Assumptions!$D$23)/12)*((YEAR(AT$3)-2027)*12+MONTH(AT$3)-1))/SUMPRODUCT(EXP((LN(Assumptions!$E$23/Assumptions!$D$23)/12)*(ROW(INDIRECT("1:24"))-1)))*SUM(Assumptions!$D$23:$E$23),0))} -> 91 | AU6: {=IF(YEAR(AU$3)=2026,0,ROUND(EXP((LN(Assumptions!$E$23/Assumptions!$D$23)/12)*((YEAR(AU$3)-2027)*12+MONTH(AU$3)-1))/SUMPRODUCT(EXP((LN(Assumptions!$E$23/Assumptions!$D$23)/12)*(ROW(INDIRECT("1:24"))-1)))*SUM(Assumptions!$D$23:$E$23),0))} -> 100 | AV6: {=IF(YEAR(AV$3)=2026,0,ROUND(EXP((LN(Assumptions!$E$23/Assumptions!$D$23)/12)*((YEAR(AV$3)-2027)*12+MONTH(AV$3)-1))/SUMPRODUCT(EXP((LN(Assumptions!$E$23/Assumptions!$D$23)/12)*(ROW(INDIRECT("1:24"))-1)))*SUM(Assumptions!$D$23:$E$23),0))} -> 109 | ... AY6: {=IF(YEAR(AY$3)=2026,0,ROUND(EXP((LN(Assumptions!$E$23/Assumptions!$D$23)/12)*((YEAR(AY$3)-2027)*12+MONTH(AY$3)-1))/SUMPRODUCT(EXP((LN(Assumptions!$E$23/Assumptions!$D$23)/12)*(ROW(INDIRECT("1:24"))-1)))*SUM(Assumptions!$D$23:$E$23),0))} -> 144 | AZ6: =Assumptions!$E$23-SUM(AO6:AY6) -> 156 | BB6: =SUM(E6:P6) -> 0 | BC6: =SUM(Q6:AB6) -> 0 | BD6: =SUM(AC6:AN6) -> 400 | BE6: =SUM(AO6:AZ6) -> 1200 | BF6: =Assumptions!$F$23 -> 2400
B7: TTK Revenue | D7: € | Q7: =Q6*Assumptions!$C$30 -> 0 | R7: =R6*Assumptions!$C$30 -> 0 | S7: =S6*Assumptions!$C$30 -> 0 | T7: =T6*Assumptions!$C$30 -> 0 | U7: =U6*Assumptions!$C$30 -> 0 | V7: =V6*Assumptions!$C$30 -> 0 | W7: =W6*Assumptions!$C$30 -> 0 | X7: =X6*Assumptions!$C$30 -> 0 | ... AZ7: =AZ6*Assumptions!$C$30 -> 1329996.7 | BB7: =SUM(E7:P7) -> 0 | BC7: =SUM(Q7:AB7) -> 0 | BD7: =SUM(AC7:AN7) -> 3410248 | BE7: =SUM(AO7:AZ7) -> 10230744 | BF7: =BF6*Assumptions!$C$30 -> 20461488
B8: TTK upsell | D8: € | Q8: =Q6*SUMPRODUCT(Assumptions!$E$117:$F$119) -> 0 | R8: =R6*SUMPRODUCT(Assumptions!$E$117:$F$119) -> 0 | S8: =S6*SUMPRODUCT(Assumptions!$E$117:$F$119) -> 0 | T8: =T6*SUMPRODUCT(Assumptions!$E$117:$F$119) -> 0 | U8: =U6*SUMPRODUCT(Assumptions!$E$117:$F$119) -> 0 | V8: =V6*SUMPRODUCT(Assumptions!$E$117:$F$119) -> 0 | W8: =W6*SUMPRODUCT(Assumptions!$E$117:$F$119) -> 0 | X8: =X6*SUMPRODUCT(Assumptions!$E$117:$F$119) -> 0 | ... AB8: =AB6*SUMPRODUCT(Assumptions!$E$117:$F$119) -> 0 | AC8: =AC6*SUMPRODUCT(Assumptions!$E$117:$E$119,Assumptions!$F$117:$F$119) -> 9555.0392 | AD8: =AD6*SUMPRODUCT(Assumptions!$E$117:$E$119,Assumptions!$F$117:$F$119) -> 10560.833 | AE8: =AE6*SUMPRODUCT(Assumptions!$E$117:$E$119,Assumptions!$F$117:$F$119) -> 11566.626 | AF8: =AF6*SUMPRODUCT(Assumptions!$E$117:$E$119,Assumptions!$F$117:$F$119) -> 12572.42 | AG8: =AG6*SUMPRODUCT(Assumptions!$E$117:$E$119,Assumptions!$F$117:$F$119) -> 14081.11 | AH8: =AH6*SUMPRODUCT(Assumptions!$E$117:$E$119,Assumptions!$F$117:$F$119) -> 15086.904 | AI8: =AI6*SUMPRODUCT(Assumptions!$E$117:$E$119,Assumptions!$F$117:$F$119) -> 16595.594 | AJ8: =AJ6*SUMPRODUCT(Assumptions!$E$117:$E$119,Assumptions!$F$117:$F$119) -> 18104.285 | ... AZ8: =AZ6*SUMPRODUCT(Assumptions!$E$117:$E$119,Assumptions!$F$117:$F$119) -> 78451.901 | BB8: =SUM(E8:P8) -> 0 | BC8: =SUM(Q8:AB8) -> 0 | BD8: =SUM(AC8:AN8) -> 201158.72 | BE8: =SUM(AO8:AZ8) -> 603476.16 | BF8: =BF6*SUMPRODUCT(Assumptions!$E$117:$E$119,Assumptions!$F$117:$F$119) -> 1206952.3
B9: Total TTK Revenue | D9: € | Q9: =sum(Q7:Q8) -> 0 | R9: =sum(R7:R8) -> 0 | S9: =sum(S7:S8) -> 0 | T9: =sum(T7:T8) -> 0 | U9: =sum(U7:U8) -> 0 | V9: =sum(V7:V8) -> 0 | W9: =sum(W7:W8) -> 0 | X9: =sum(X7:X8) -> 0 | ... AZ9: =sum(AZ7:AZ8) -> 1408448.6 | BB9: =SUM(E9:P9) -> 0 | BC9: =SUM(Q9:AB9) -> 0 | BD9: =SUM(AC9:AN9) -> 3611406.7 | BE9: =SUM(AO9:AZ9) -> 10834220 | BF9: =SUM(BF6:BF8) -> 21670840
B11: COMBI
B12: Combi units sold | D12: # | Q12: {=IF(YEAR(Q$3)=2026,0,ROUND(EXP((LN(Assumptions!$E$24/Assumptions!$D$24)/12)*((YEAR(Q$3)-2027)*12+MONTH(Q$3)-1))/SUMPRODUCT(EXP((LN(Assumptions!$E$24/Assumptions!$D$24)/12)*(ROW(INDIRECT("1:24"))-1)))*SUM(Assumptions!$D$24:$E$24),0))} -> 0 | R12: {=IF(YEAR(R$3)=2026,0,ROUND(EXP((LN(Assumptions!$E$24/Assumptions!$D$24)/12)*((YEAR(R$3)-2027)*12+MONTH(R$3)-1))/SUMPRODUCT(EXP((LN(Assumptions!$E$24/Assumptions!$D$24)/12)*(ROW(INDIRECT("1:24"))-1)))*SUM(Assumptions!$D$24:$E$24),0))} -> 0 | S12: {=IF(YEAR(S$3)=2026,0,ROUND(EXP((LN(Assumptions!$E$24/Assumptions!$D$24)/12)*((YEAR(S$3)-2027)*12+MONTH(S$3)-1))/SUMPRODUCT(EXP((LN(Assumptions!$E$24/Assumptions!$D$24)/12)*(ROW(INDIRECT("1:24"))-1)))*SUM(Assumptions!$D$24:$E$24),0))} -> 0 | T12: {=IF(YEAR(T$3)=2026,0,ROUND(EXP((LN(Assumptions!$E$24/Assumptions!$D$24)/12)*((YEAR(T$3)-2027)*12+MONTH(T$3)-1))/SUMPRODUCT(EXP((LN(Assumptions!$E$24/Assumptions!$D$24)/12)*(ROW(INDIRECT("1:24"))-1)))*SUM(Assumptions!$D$24:$E$24),0))} -> 0 | U12: {=IF(YEAR(U$3)=2026,0,ROUND(EXP((LN(Assumptions!$E$24/Assumptions!$D$24)/12)*((YEAR(U$3)-2027)*12+MONTH(U$3)-1))/SUMPRODUCT(EXP((LN(Assumptions!$E$24/Assumptions!$D$24)/12)*(ROW(INDIRECT("1:24"))-1)))*SUM(Assumptions!$D$24:$E$24),0))} -> 0 | V12: {=IF(YEAR(V$3)=2026,0,ROUND(EXP((LN(Assumptions!$E$24/Assumptions!$D$24)/12)*((YEAR(V$3)-2027)*12+MONTH(V$3)-1))/SUMPRODUCT(EXP((LN(Assumptions!$E$24/Assumptions!$D$24)/12)*(ROW(INDIRECT("1:24"))-1)))*SUM(Assumptions!$D$24:$E$24),0))} -> 0 | W12: {=IF(YEAR(W$3)=2026,0,ROUND(EXP((LN(Assumptions!$E$24/Assumptions!$D$24)/12)*((YEAR(W$3)-2027)*12+MONTH(W$3)-1))/SUMPRODUCT(EXP((LN(Assumptions!$E$24/Assumptions!$D$24)/12)*(ROW(INDIRECT("1:24"))-1)))*SUM(Assumptions!$D$24:$E$24),0))} -> 0 | X12: {=IF(YEAR(X$3)=2026,0,ROUND(EXP((LN(Assumptions!$E$24/Assumptions!$D$24)/12)*((YEAR(X$3)-2027)*12+MONTH(X$3)-1))/SUMPRODUCT(EXP((LN(Assumptions!$E$24/Assumptions!$D$24)/12)*(ROW(INDIRECT("1:24"))-1)))*SUM(Assumptions!$D$24:$E$24),0))} -> 0 | ... AM12: {=IF(YEAR(AM$3)=2026,0,ROUND(EXP((LN(Assumptions!$E$24/Assumptions!$D$24)/12)*((YEAR(AM$3)-2027)*12+MONTH(AM$3)-1))/SUMPRODUCT(EXP((LN(Assumptions!$E$24/Assumptions!$D$24)/12)*(ROW(INDIRECT("1:24"))-1)))*SUM(Assumptions!$D$24:$E$24),0))} -> 36 | AN12: =Assumptions!$D$24-SUM(AC12:AM12) -> 39 | AO12: {=IF(YEAR(AO$3)=2026,0,ROUND(EXP((LN(Assumptions!$E$24/Assumptions!$D$24)/12)*((YEAR(AO$3)-2027)*12+MONTH(AO$3)-1))/SUMPRODUCT(EXP((LN(Assumptions!$E$24/Assumptions!$D$24)/12)*(ROW(INDIRECT("1:24"))-1)))*SUM(Assumptions!$D$24:$E$24),0))} -> 43 | AP12: {=IF(YEAR(AP$3)=2026,0,ROUND(EXP((LN(Assumptions!$E$24/Assumptions!$D$24)/12)*((YEAR(AP$3)-2027)*12+MONTH(AP$3)-1))/SUMPRODUCT(EXP((LN(Assumptions!$E$24/Assumptions!$D$24)/12)*(ROW(INDIRECT("1:24"))-1)))*SUM(Assumptions!$D$24:$E$24),0))} -> 47 | AQ12: {=IF(YEAR(AQ$3)=2026,0,ROUND(EXP((LN(Assumptions!$E$24/Assumptions!$D$24)/12)*((YEAR(AQ$3)-2027)*12+MONTH(AQ$3)-1))/SUMPRODUCT(EXP((LN(Assumptions!$E$24/Assumptions!$D$24)/12)*(ROW(INDIRECT("1:24"))-1)))*SUM(Assumptions!$D$24:$E$24),0))} -> 52 | AR12: {=IF(YEAR(AR$3)=2026,0,ROUND(EXP((LN(Assumptions!$E$24/Assumptions!$D$24)/12)*((YEAR(AR$3)-2027)*12+MONTH(AR$3)-1))/SUMPRODUCT(EXP((LN(Assumptions!$E$24/Assumptions!$D$24)/12)*(ROW(INDIRECT("1:24"))-1)))*SUM(Assumptions!$D$24:$E$24),0))} -> 57 | AS12: {=IF(YEAR(AS$3)=2026,0,ROUND(EXP((LN(Assumptions!$E$24/Assumptions!$D$24)/12)*((YEAR(AS$3)-2027)*12+MONTH(AS$3)-1))/SUMPRODUCT(EXP((LN(Assumptions!$E$24/Assumptions!$D$24)/12)*(ROW(INDIRECT("1:24"))-1)))*SUM(Assumptions!$D$24:$E$24),0))} -> 62 | AT12: {=IF(YEAR(AT$3)=2026,0,ROUND(EXP((LN(Assumptions!$E$24/Assumptions!$D$24)/12)*((YEAR(AT$3)-2027)*12+MONTH(AT$3)-1))/SUMPRODUCT(EXP((LN(Assumptions!$E$24/Assumptions!$D$24)/12)*(ROW(INDIRECT("1:24"))-1)))*SUM(Assumptions!$D$24:$E$24),0))} -> 68 | AU12: {=IF(YEAR(AU$3)=2026,0,ROUND(EXP((LN(Assumptions!$E$24/Assumptions!$D$24)/12)*((YEAR(AU$3)-2027)*12+MONTH(AU$3)-1))/SUMPRODUCT(EXP((LN(Assumptions!$E$24/Assumptions!$D$24)/12)*(ROW(INDIRECT("1:24"))-1)))*SUM(Assumptions!$D$24:$E$24),0))} -> 75 | AV12: {=IF(YEAR(AV$3)=2026,0,ROUND(EXP((LN(Assumptions!$E$24/Assumptions!$D$24)/12)*((YEAR(AV$3)-2027)*12+MONTH(AV$3)-1))/SUMPRODUCT(EXP((LN(Assumptions!$E$24/Assumptions!$D$24)/12)*(ROW(INDIRECT("1:24"))-1)))*SUM(Assumptions!$D$24:$E$24),0))} -> 82 | ... AY12: {=IF(YEAR(AY$3)=2026,0,ROUND(EXP((LN(Assumptions!$E$24/Assumptions!$D$24)/12)*((YEAR(AY$3)-2027)*12+MONTH(AY$3)-1))/SUMPRODUCT(EXP((LN(Assumptions!$E$24/Assumptions!$D$24)/12)*(ROW(INDIRECT("1:24"))-1)))*SUM(Assumptions!$D$24:$E$24),0))} -> 108 | AZ12: =Assumptions!$E$24-SUM(AO12:AY12) -> 118 | BB12: =SUM(E12:P12) -> 0 | BC12: =SUM(Q12:AB12) -> 0 | BD12: =SUM(AC12:AN12) -> 300 | BE12: =SUM(AO12:AZ12) -> 900 | BF12: =Assumptions!$F$24 -> 1800
B13: Combi Revenue | D13: € | Q13: =Q12*Assumptions!$C$33 -> 0 | R13: =R12*Assumptions!$C$33 -> 0 | S13: =S12*Assumptions!$C$33 -> 0 | T13: =T12*Assumptions!$C$33 -> 0 | U13: =U12*Assumptions!$C$33 -> 0 | V13: =V12*Assumptions!$C$33 -> 0 | W13: =W12*Assumptions!$C$33 -> 0 | X13: =X12*Assumptions!$C$33 -> 0 | ... AZ13: =AZ12*Assumptions!$C$33 -> 1271767.4 | BB13: =SUM(E13:P13) -> 0 | BC13: =SUM(Q13:AB13) -> 0 | BD13: =SUM(AC13:AN13) -> 3233307 | BE13: =SUM(AO13:AZ13) -> 9699921 | BF13: =BF12*Assumptions!$C$33 -> 19399842
B14: Combi upsell | D14: € | Q14: =Q12*SUMPRODUCT(Assumptions!$E$117:$E$119,Assumptions!$F$117:$F$119) -> 0 | R14: =R12*SUMPRODUCT(Assumptions!$E$117:$E$119,Assumptions!$F$117:$F$119) -> 0 | S14: =S12*SUMPRODUCT(Assumptions!$E$117:$E$119,Assumptions!$F$117:$F$119) -> 0 | T14: =T12*SUMPRODUCT(Assumptions!$E$117:$E$119,Assumptions!$F$117:$F$119) -> 0 | U14: =U12*SUMPRODUCT(Assumptions!$E$117:$E$119,Assumptions!$F$117:$F$119) -> 0 | V14: =V12*SUMPRODUCT(Assumptions!$E$117:$E$119,Assumptions!$F$117:$F$119) -> 0 | W14: =W12*SUMPRODUCT(Assumptions!$E$117:$E$119,Assumptions!$F$117:$F$119) -> 0 | X14: =X12*SUMPRODUCT(Assumptions!$E$117:$E$119,Assumptions!$F$117:$F$119) -> 0 | ... AZ14: =AZ12*SUMPRODUCT(Assumptions!$E$117:$E$119,Assumptions!$F$117:$F$119) -> 59341.822 | BB14: =SUM(E14:P14) -> 0 | BC14: =SUM(Q14:AB14) -> 0 | BD14: =SUM(AC14:AN14) -> 150869.04 | BE14: =SUM(AO14:AZ14) -> 452607.12 | BF14: =BF12*SUMPRODUCT(Assumptions!$E$117:$E$119,Assumptions!$F$117:$F$119) -> 905214.24
B15: Total Combi Revenue | D15: € | Q15: =sum(Q13:Q14) -> 0 | R15: =sum(R13:R14) -> 0 | S15: =sum(S13:S14) -> 0 | T15: =sum(T13:T14) -> 0 | U15: =sum(U13:U14) -> 0 | V15: =sum(V13:V14) -> 0 | W15: =sum(W13:W14) -> 0 | X15: =sum(X13:X14) -> 0 | ... AZ15: =sum(AZ13:AZ14) -> 1331109.2 | BB15: =SUM(E15:P15) -> 0 | BC15: =SUM(Q15:AB15) -> 0 | BD15: =SUM(AC15:AN15) -> 3384176 | BE15: =SUM(AO15:AZ15) -> 10152528 | BF15: =sum(BF13:BF14) -> 20305056
B17: COMBI+
B18: Combi+ units sold | D18: # | Q18: {=IF(YEAR(Q$3)=2026,0,ROUND(EXP((LN(Assumptions!$E$25/Assumptions!$D$25)/12)*((YEAR(Q$3)-2027)*12+MONTH(Q$3)-1))/SUMPRODUCT(EXP((LN(Assumptions!$E$25/Assumptions!$D$25)/12)*(ROW(INDIRECT("1:24"))-1)))*SUM(Assumptions!$D$25:$E$25),0))} -> 0 | R18: {=IF(YEAR(R$3)=2026,0,ROUND(EXP((LN(Assumptions!$E$25/Assumptions!$D$25)/12)*((YEAR(R$3)-2027)*12+MONTH(R$3)-1))/SUMPRODUCT(EXP((LN(Assumptions!$E$25/Assumptions!$D$25)/12)*(ROW(INDIRECT("1:24"))-1)))*SUM(Assumptions!$D$25:$E$25),0))} -> 0 | S18: {=IF(YEAR(S$3)=2026,0,ROUND(EXP((LN(Assumptions!$E$25/Assumptions!$D$25)/12)*((YEAR(S$3)-2027)*12+MONTH(S$3)-1))/SUMPRODUCT(EXP((LN(Assumptions!$E$25/Assumptions!$D$25)/12)*(ROW(INDIRECT("1:24"))-1)))*SUM(Assumptions!$D$25:$E$25),0))} -> 0 | T18: {=IF(YEAR(T$3)=2026,0,ROUND(EXP((LN(Assumptions!$E$25/Assumptions!$D$25)/12)*((YEAR(T$3)-2027)*12+MONTH(T$3)-1))/SUMPRODUCT(EXP((LN(Assumptions!$E$25/Assumptions!$D$25)/12)*(ROW(INDIRECT("1:24"))-1)))*SUM(Assumptions!$D$25:$E$25),0))} -> 0 | U18: {=IF(YEAR(U$3)=2026,0,ROUND(EXP((LN(Assumptions!$E$25/Assumptions!$D$25)/12)*((YEAR(U$3)-2027)*12+MONTH(U$3)-1))/SUMPRODUCT(EXP((LN(Assumptions!$E$25/Assumptions!$D$25)/12)*(ROW(INDIRECT("1:24"))-1)))*SUM(Assumptions!$D$25:$E$25),0))} -> 0 | V18: {=IF(YEAR(V$3)=2026,0,ROUND(EXP((LN(Assumptions!$E$25/Assumptions!$D$25)/12)*((YEAR(V$3)-2027)*12+MONTH(V$3)-1))/SUMPRODUCT(EXP((LN(Assumptions!$E$25/Assumptions!$D$25)/12)*(ROW(INDIRECT("1:24"))-1)))*SUM(Assumptions!$D$25:$E$25),0))} -> 0 | W18: {=IF(YEAR(W$3)=2026,0,ROUND(EXP((LN(Assumptions!$E$25/Assumptions!$D$25)/12)*((YEAR(W$3)-2027)*12+MONTH(W$3)-1))/SUMPRODUCT(EXP((LN(Assumptions!$E$25/Assumptions!$D$25)/12)*(ROW(INDIRECT("1:24"))-1)))*SUM(Assumptions!$D$25:$E$25),0))} -> 0 | X18: {=IF(YEAR(X$3)=2026,0,ROUND(EXP((LN(Assumptions!$E$25/Assumptions!$D$25)/12)*((YEAR(X$3)-2027)*12+MONTH(X$3)-1))/SUMPRODUCT(EXP((LN(Assumptions!$E$25/Assumptions!$D$25)/12)*(ROW(INDIRECT("1:24"))-1)))*SUM(Assumptions!$D$25:$E$25),0))} -> 0 | ... AM18: {=IF(YEAR(AM$3)=2026,0,ROUND(EXP((LN(Assumptions!$E$25/Assumptions!$D$25)/12)*((YEAR(AM$3)-2027)*12+MONTH(AM$3)-1))/SUMPRODUCT(EXP((LN(Assumptions!$E$25/Assumptions!$D$25)/12)*(ROW(INDIRECT("1:24"))-1)))*SUM(Assumptions!$D$25:$E$25),0))} -> 36 | AN18: =Assumptions!$D$25-SUM(AC18:AM18) -> 39 | AO18: {=IF(YEAR(AO$3)=2026,0,ROUND(EXP((LN(Assumptions!$E$25/Assumptions!$D$25)/12)*((YEAR(AO$3)-2027)*12+MONTH(AO$3)-1))/SUMPRODUCT(EXP((LN(Assumptions!$E$25/Assumptions!$D$25)/12)*(ROW(INDIRECT("1:24"))-1)))*SUM(Assumptions!$D$25:$E$25),0))} -> 43 | AP18: {=IF(YEAR(AP$3)=2026,0,ROUND(EXP((LN(Assumptions!$E$25/Assumptions!$D$25)/12)*((YEAR(AP$3)-2027)*12+MONTH(AP$3)-1))/SUMPRODUCT(EXP((LN(Assumptions!$E$25/Assumptions!$D$25)/12)*(ROW(INDIRECT("1:24"))-1)))*SUM(Assumptions!$D$25:$E$25),0))} -> 47 | AQ18: {=IF(YEAR(AQ$3)=2026,0,ROUND(EXP((LN(Assumptions!$E$25/Assumptions!$D$25)/12)*((YEAR(AQ$3)-2027)*12+MONTH(AQ$3)-1))/SUMPRODUCT(EXP((LN(Assumptions!$E$25/Assumptions!$D$25)/12)*(ROW(INDIRECT("1:24"))-1)))*SUM(Assumptions!$D$25:$E$25),0))} -> 52 | AR18: {=IF(YEAR(AR$3)=2026,0,ROUND(EXP((LN(Assumptions!$E$25/Assumptions!$D$25)/12)*((YEAR(AR$3)-2027)*12+MONTH(AR$3)-1))/SUMPRODUCT(EXP((LN(Assumptions!$E$25/Assumptions!$D$25)/12)*(ROW(INDIRECT("1:24"))-1)))*SUM(Assumptions!$D$25:$E$25),0))} -> 57 | AS18: {=IF(YEAR(AS$3)=2026,0,ROUND(EXP((LN(Assumptions!$E$25/Assumptions!$D$25)/12)*((YEAR(AS$3)-2027)*12+MONTH(AS$3)-1))/SUMPRODUCT(EXP((LN(Assumptions!$E$25/Assumptions!$D$25)/12)*(ROW(INDIRECT("1:24"))-1)))*SUM(Assumptions!$D$25:$E$25),0))} -> 62 | AT18: {=IF(YEAR(AT$3)=2026,0,ROUND(EXP((LN(Assumptions!$E$25/Assumptions!$D$25)/12)*((YEAR(AT$3)-2027)*12+MONTH(AT$3)-1))/SUMPRODUCT(EXP((LN(Assumptions!$E$25/Assumptions!$D$25)/12)*(ROW(INDIRECT("1:24"))-1)))*SUM(Assumptions!$D$25:$E$25),0))} -> 68 | AU18: {=IF(YEAR(AU$3)=2026,0,ROUND(EXP((LN(Assumptions!$E$25/Assumptions!$D$25)/12)*((YEAR(AU$3)-2027)*12+MONTH(AU$3)-1))/SUMPRODUCT(EXP((LN(Assumptions!$E$25/Assumptions!$D$25)/12)*(ROW(INDIRECT("1:24"))-1)))*SUM(Assumptions!$D$25:$E$25),0))} -> 75 | AV18: {=IF(YEAR(AV$3)=2026,0,ROUND(EXP((LN(Assumptions!$E$25/Assumptions!$D$25)/12)*((YEAR(AV$3)-2027)*12+MONTH(AV$3)-1))/SUMPRODUCT(EXP((LN(Assumptions!$E$25/Assumptions!$D$25)/12)*(ROW(INDIRECT("1:24"))-1)))*SUM(Assumptions!$D$25:$E$25),0))} -> 82 | ... AY18: {=IF(YEAR(AY$3)=2026,0,ROUND(EXP((LN(Assumptions!$E$25/Assumptions!$D$25)/12)*((YEAR(AY$3)-2027)*12+MONTH(AY$3)-1))/SUMPRODUCT(EXP((LN(Assumptions!$E$25/Assumptions!$D$25)/12)*(ROW(INDIRECT("1:24"))-1)))*SUM(Assumptions!$D$25:$E$25),0))} -> 108 | AZ18: =Assumptions!$E$25-SUM(AO18:AY18) -> 118 | BB18: =SUM(E18:P18) -> 0 | BC18: =SUM(Q18:AB18) -> 0 | BD18: =SUM(AC18:AN18) -> 300 | BE18: =SUM(AO18:AZ18) -> 900 | BF18: =Assumptions!$F$25 -> 1800
B19: Combi+ Revenue | D19: € | Q19: =Q18*Assumptions!$C$34 -> 0 | R19: =R18*Assumptions!$C$34 -> 0 | S19: =S18*Assumptions!$C$34 -> 0 | T19: =T18*Assumptions!$C$34 -> 0 | U19: =U18*Assumptions!$C$34 -> 0 | V19: =V18*Assumptions!$C$34 -> 0 | W19: =W18*Assumptions!$C$34 -> 0 | X19: =X18*Assumptions!$C$34 -> 0 | ... AZ19: =AZ18*Assumptions!$C$34 -> 1632593.7 | BB19: =SUM(E19:P19) -> 0 | BC19: =SUM(Q19:AB19) -> 0 | BD19: =SUM(AC19:AN19) -> 4150662 | BE19: =SUM(AO19:AZ19) -> 12451986 | BF19: =BF18*Assumptions!$C$34 -> 24903972
B20: Combi+ upsell | D20: € | Q20: =Q18*SUMPRODUCT(Assumptions!$E$117:$E$119,Assumptions!$F$117:$F$119) -> 0 | R20: =R18*SUMPRODUCT(Assumptions!$E$117:$E$119,Assumptions!$F$117:$F$119) -> 0 | S20: =S18*SUMPRODUCT(Assumptions!$E$117:$E$119,Assumptions!$F$117:$F$119) -> 0 | T20: =T18*SUMPRODUCT(Assumptions!$E$117:$E$119,Assumptions!$F$117:$F$119) -> 0 | U20: =U18*SUMPRODUCT(Assumptions!$E$117:$E$119,Assumptions!$F$117:$F$119) -> 0 | V20: =V18*SUMPRODUCT(Assumptions!$E$117:$E$119,Assumptions!$F$117:$F$119) -> 0 | W20: =W18*SUMPRODUCT(Assumptions!$E$117:$E$119,Assumptions!$F$117:$F$119) -> 0 | X20: =X18*SUMPRODUCT(Assumptions!$E$117:$E$119,Assumptions!$F$117:$F$119) -> 0 | ... AZ20: =AZ18*SUMPRODUCT(Assumptions!$E$117:$E$119,Assumptions!$F$117:$F$119) -> 59341.822 | BB20: =SUM(E20:P20) -> 0 | BC20: =SUM(Q20:AB20) -> 0 | BD20: =SUM(AC20:AN20) -> 150869.04 | BE20: =SUM(AO20:AZ20) -> 452607.12 | BF20: =BF18*SUMPRODUCT(Assumptions!$E$117:$E$119,Assumptions!$F$117:$F$119) -> 905214.24
B21: Total Combi+ Revenue | D21: € | Q21: =sum(Q19:Q20) -> 0 | R21: =sum(R19:R20) -> 0 | S21: =sum(S19:S20) -> 0 | T21: =sum(T19:T20) -> 0 | U21: =sum(U19:U20) -> 0 | V21: =sum(V19:V20) -> 0 | W21: =sum(W19:W20) -> 0 | X21: =sum(X19:X20) -> 0 | ... AZ21: =sum(AZ19:AZ20) -> 1691935.5 | BB21: =SUM(E21:P21) -> 0 | BC21: =SUM(Q21:AB21) -> 0 | BD21: =SUM(AC21:AN21) -> 4301531 | BE21: =SUM(AO21:AZ21) -> 12904593 | BF21: =sum(BF19:BF20) -> 25809186
B23: INSTALLATION REVENUES | D23: €
B24: Units installed | D24: # | E24: =E6+E12+E18 -> 0 | F24: =F6+F12+F18 -> 0 | G24: =G6+G12+G18 -> 0 | H24: =H6+H12+H18 -> 0 | I24: =I6+I12+I18 -> 0 | J24: =J6+J12+J18 -> 0 | K24: =K6+K12+K18 -> 0 | L24: =L6+L12+L18 -> 0 | ... AZ24: =AZ6+AZ12+AZ18 -> 392 | BB24: =SUM(E24:P24) -> 0 | BC24: =SUM(Q24:AB24) -> 0 | BD24: =SUM(AC24:AN24) -> 1000 | BE24: =SUM(AO24:AZ24) -> 3000 | BF24: =BF6+BF12+BF18 -> 6000
B25: Total Installation Revenue | D25: € | E25: =E6*Assumptions!$C$36+E12*Assumptions!$C$37+E18*Assumptions!$C$38 -> 0 | F25: =F6*Assumptions!$C$36+F12*Assumptions!$C$37+F18*Assumptions!$C$38 -> 0 | G25: =G6*Assumptions!$C$36+G12*Assumptions!$C$37+G18*Assumptions!$C$38 -> 0 | H25: =H6*Assumptions!$C$36+H12*Assumptions!$C$37+H18*Assumptions!$C$38 -> 0 | I25: =I6*Assumptions!$C$36+I12*Assumptions!$C$37+I18*Assumptions!$C$38 -> 0 | J25: =J6*Assumptions!$C$36+J12*Assumptions!$C$37+J18*Assumptions!$C$38 -> 0 | K25: =K6*Assumptions!$C$36+K12*Assumptions!$C$37+K18*Assumptions!$C$38 -> 0 | L25: =L6*Assumptions!$C$36+L12*Assumptions!$C$37+L18*Assumptions!$C$38 -> 0 | ... AZ25: =AZ6*Assumptions!$C$36+AZ12*Assumptions!$C$37+AZ18*Assumptions!$C$38 -> 1333600 | BB25: =SUM(E25:P25) -> 0 | BC25: =SUM(Q25:AB25) -> 0 | BD25: =SUM(AC25:AN25) -> 3400000 | BE25: =SUM(AO25:AZ25) -> 10200000 | BF25: =BF6*Assumptions!$C$36+BF12*Assumptions!$C$37+BF18*Assumptions!$C$38 -> 20400000
B27: SERVICE REVENUES
B28: Installed base (TTK) | D28: # | Q28: =Q6 -> 0 | R28: =R6 -> 0 | S28: =S6 -> 0 | T28: =T6 -> 0 | U28: =U6 -> 0 | V28: =V6 -> 0 | W28: =W6 -> 0 | X28: =X6 -> 0 | ... AC28: =AC6 -> 19 | AD28: =AC28+AD6 -> 40 | AE28: =AD28+AE6 -> 63 | AF28: =AE28+AF6 -> 88 | AG28: =AF28+AG6 -> 116 | AH28: =AG28+AH6 -> 146 | AI28: =AH28+AI6 -> 179 | AJ28: =AI28+AJ6 -> 215 | AK28: =AJ28+AK6 -> 255 | ... AZ28: =AY28+AZ6 -> 1600 | BB28: =SUM(E28:P28) -> 0 | BC28: =SUM(Q28:AB28) -> 0 | BD28: =AN28 -> 400 | BE28: =AZ28 -> 1600 | BF28: =BF24*0.5 -> 3000
B29: Installed base (Combi) | D29: # | Q29: =Q12 -> 0 | R29: =R12 -> 0 | S29: =S12 -> 0 | T29: =T12 -> 0 | U29: =U12 -> 0 | V29: =V12 -> 0 | W29: =W12 -> 0 | X29: =X12 -> 0 | ... AC29: =AC12 -> 14 | AD29: =AC29+AD12 -> 30 | AE29: =AD29+AE12 -> 47 | AF29: =AE29+AF12 -> 66 | AG29: =AF29+AG12 -> 87 | AH29: =AG29+AH12 -> 110 | AI29: =AH29+AI12 -> 135 | AJ29: =AI29+AJ12 -> 162 | AK29: =AJ29+AK12 -> 192 | ... AZ29: =AY29+AZ12 -> 1200 | BB29: =SUM(E29:P29) -> 0 | BC29: =SUM(Q29:AB29) -> 0 | BD29: =AN29 -> 300 | BE29: =AZ29 -> 1200 | BF29: =BF24*0.25 -> 1500
B30: Installed base (Combi+) | Q30: =Q18 -> 0 | R30: =R18 -> 0 | S30: =S18 -> 0 | T30: =T18 -> 0 | U30: =U18 -> 0 | V30: =V18 -> 0 | W30: =W18 -> 0 | X30: =X18 -> 0 | ... AC30: =AC18 -> 14 | AD30: =AC30+AD18 -> 30 | AE30: =AD30+AE18 -> 47 | AF30: =AE30+AF18 -> 66 | AG30: =AF30+AG18 -> 87 | AH30: =AG30+AH18 -> 110 | AI30: =AH30+AI18 -> 135 | AJ30: =AI30+AJ18 -> 162 | AK30: =AJ30+AK18 -> 192 | ... AZ30: =AY30+AZ18 -> 1200 | BB30: =SUM(E30:P30) -> 0 | BC30: =SUM(Q30:AB30) -> 0 | BD30: =AN30 -> 300 | BE30: =AZ30 -> 1200 | BF30: =BF24*0.25 -> 1500
B31: Total Service Revenue | D31: € | Q31: =Q41*SUMPRODUCT(Assumptions!$E$129:$E$130,Assumptions!$F$129:$F$130) -> 0 | R31: =R41*SUMPRODUCT(Assumptions!$E$129:$E$130,Assumptions!$F$129:$F$130) -> 0 | S31: =S41*SUMPRODUCT(Assumptions!$E$129:$E$130,Assumptions!$F$129:$F$130) -> 0 | T31: =T41*SUMPRODUCT(Assumptions!$E$129:$E$130,Assumptions!$F$129:$F$130) -> 0 | U31: =U41*SUMPRODUCT(Assumptions!$E$129:$E$130,Assumptions!$F$129:$F$130) -> 0 | V31: =V41*SUMPRODUCT(Assumptions!$E$129:$E$130,Assumptions!$F$129:$F$130) -> 0 | W31: =W41*SUMPRODUCT(Assumptions!$E$129:$E$130,Assumptions!$F$129:$F$130) -> 0 | X31: =X41*SUMPRODUCT(Assumptions!$E$129:$E$130,Assumptions!$F$129:$F$130) -> 0 | ... AB31: =AB41*SUMPRODUCT(Assumptions!$E$129:$E$130,Assumptions!$F$129:$F$130) -> 0 | AC31: =AC41*SUMPRODUCT(Assumptions!$E$129:$E$130,Assumptions!$F$129:$F$130)+Q31 -> 7473 | AD31: =AD41*SUMPRODUCT(Assumptions!$E$129:$E$130,Assumptions!$F$129:$F$130)+R31 -> 8427 | AE31: =AE41*SUMPRODUCT(Assumptions!$E$129:$E$130,Assumptions!$F$129:$F$130)+S31 -> 9063 | AF31: =AF41*SUMPRODUCT(Assumptions!$E$129:$E$130,Assumptions!$F$129:$F$130)+T31 -> 10017 | AG31: =AG41*SUMPRODUCT(Assumptions!$E$129:$E$130,Assumptions!$F$129:$F$130)+U31 -> 11130 | AH31: =AH41*SUMPRODUCT(Assumptions!$E$129:$E$130,Assumptions!$F$129:$F$130)+V31 -> 12084 | AI31: =AI41*SUMPRODUCT(Assumptions!$E$129:$E$130,Assumptions!$F$129:$F$130)+W31 -> 13197 | AJ31: =AJ41*SUMPRODUCT(Assumptions!$E$129:$E$130,Assumptions!$F$129:$F$130)+X31 -> 14310 | ... AZ31: =AZ41*SUMPRODUCT(Assumptions!$E$129:$E$130,Assumptions!$F$129:$F$130)+AN31 -> 83157 | BB31: =SUM(E31:P31) -> 0 | BC31: =SUM(Q31:AB31) -> 0 | BD31: =SUM(AC31:AN31) -> 159000 | BE31: =SUM(AO31:AZ31) -> 636000 | BF31: =BF41*SUMPRODUCT(Assumptions!$E$129:$E$130,Assumptions!$F$129:$F$130)+AT31 -> 1002177
B33: SUBSIDIES & GRANTS
B34: All other | D34: € | E34: 0 | F34: 0 | G34: 0 | H34: 0 | I34: 0 | J34: 0 | K34: 0 | L34: 0 | M34: 0 | N34: 19480 | O34: 78000 | P34: 0 | Q34: 0 | R34: 0 | S34: 0 | T34: 0 | U34: 0 | V34: 0 | W34: 0 | X34: 106782 | Y34: 0 | Z34: 0 | AA34: 0 | AB34: 0 | AC34: 0 | AD34: 0 | AE34: 0 | AF34: 0 | AG34: 0 | AH34: 0 | AI34: 0 | AJ34: 0 | AK34: 0 | AL34: 0 | AM34: 0 | AN34: 0 | AO34: 0 | AP34: 0 | AQ34: 0 | AR34: 0 | AS34: 0 | AT34: 0 | AU34: 0 | AV34: 0 | AW34: 0 | AX34: 0 | AY34: 0 | AZ34: 0 | BB34: =SUM(E34:P34) -> 97480 | BC34: =SUM(Q34:AB34) -> 106782 | BD34: =SUM(AC34:AN34) -> 0 | BE34: =SUM(AO34:AZ34) -> 0 | BF34: 0
B35: Total Subsidies & Grants | D35: € | E35: =sum(E34) -> 0 | F35: =sum(F34) -> 0 | G35: =sum(G34) -> 0 | H35: =sum(H34) -> 0 | I35: =sum(I34) -> 0 | J35: =sum(J34) -> 0 | K35: =sum(K34) -> 0 | L35: =sum(L34) -> 0 | ... AZ35: =sum(AZ34) -> 0 | BB35: =SUM(E35:P35) -> 97480 | BC35: =SUM(Q35:AB35) -> 106782 | BD35: =BD34 -> 0 | BE35: =BE34 -> 0 | BF35: =BF34 -> 0
B37: TOTAL REVENUE | E37: =E9+E15+E21+E25+E31+E35 -> 0 | F37: =F9+F15+F21+F25+F31+F35 -> 0 | G37: =G9+G15+G21+G25+G31+G35 -> 0 | H37: =H9+H15+H21+H25+H31+H35 -> 0 | I37: =I9+I15+I21+I25+I31+I35 -> 0 | J37: =J9+J15+J21+J25+J31+J35 -> 0 | K37: =K9+K15+K21+K25+K31+K35 -> 0 | L37: =L9+L15+L21+L25+L31+L35 -> 0 | ... AZ37: =AZ9+AZ15+AZ21+AZ25+AZ31+AZ35 -> 5848250.4 | BB37: =BB9+BB15+BB21+BB25+BB31+BB35 -> 97480 | BC37: =BC9+BC15+BC21+BC25+BC31+BC35 -> 106782 | BD37: =SUM(AC37:AN37) -> 14856114 | BE37: =SUM(AO37:AZ37) -> 44727341 | BF37: =BF9+BF15+BF21+BF25+BF31+BF35 -> 89187260
B40: Installed Base | E40: =sum(E28:E30) -> 0 | F40: =sum(F28:F30) -> 0 | G40: =sum(G28:G30) -> 0 | H40: =sum(H28:H30) -> 0 | I40: =sum(I28:I30) -> 0 | J40: =sum(J28:J30) -> 0 | K40: =sum(K28:K30) -> 0 | L40: =sum(L28:L30) -> 0 | ... AZ40: =sum(AZ28:AZ30) -> 4000 | BB40: =sum(BB28:BB30) -> 0 | BC40: =sum(BC28:BC30) -> 0 | BD40: =sum(BD28:BD30) -> 1000 | BE40: =sum(BE28:BE30) -> 4000 | BF40: =sum(BF28:BF30) -> 6000
B41: Units sold | D41: # | E41: =E6+E12+E18 -> 0 | F41: =F6+F12+F18 -> 0 | G41: =G6+G12+G18 -> 0 | H41: =H6+H12+H18 -> 0 | I41: =I6+I12+I18 -> 0 | J41: =J6+J12+J18 -> 0 | K41: =K6+K12+K18 -> 0 | L41: =L6+L12+L18 -> 0 | ... AZ41: =AZ6+AZ12+AZ18 -> 392 | BB41: 0 | BC41: 0 | BD41: =SUM(AC41:AN41) -> 1000 | BE41: =SUM(AO41:AZ41) -> 3000 | BF41: =BF24 -> 6000

Sheet COGS
B1: Tarnoc B.V. — COGS Schedule (€)
E2: 2025 | Q2: 2026 | AC2: 2027 | AO2: 2028
E3: 45658 | F3: 45689 | G3: 45717 | H3: 45748 | I3: 45778 | J3: 45809 | K3: 45839 | L3: 45870 | M3: 45901 | N3: 45931 | O3: 45962 | P3: 45992 | Q3: 46023 | R3: 46054 | S3: 46082 | T3: 46113 | U3: 46143 | V3: 46174 | W3: 46204 | X3: 46235 | Y3: 46266 | Z3: 46296 | AA3: 46327 | AB3: 46357 | AC3: 46388 | AD3: 46419 | AE3: 46447 | AF3: 46478 | AG3: 46508 | AH3: 46539 | AI3: 46569 | AJ3: 46600 | AK3: 46631 | AL3: 46661 | AM3: 46692 | AN3: 46722 | AO3: 46753 | AP3: 46784 | AQ3: 46813 | AR3: 46844 | AS3: 46874 | AT3: 46905 | AU3: 46935 | AV3: 46966 | AW3: 46997 | AX3: 47027 | AY3: 47058 | AZ3: 47088 | BB3: 2025 | BC3: 2026 | BD3: 2027 | BE3: 2028 | BF3: 2029
B6: TTK
B7: TTK | D7: € | Q7: =IFNA('Revenue Forecast'!Q6*VLOOKUP('Revenue Forecast'!$BC$41,Assumptions!$B$71:$C$73,2,TRUE),0) -> 0 | R7: =IFNA('Revenue Forecast'!R6*VLOOKUP('Revenue Forecast'!$BC$41,Assumptions!$B$71:$C$73,2,TRUE),0) -> 0 | S7: =IFNA('Revenue Forecast'!S6*VLOOKUP('Revenue Forecast'!$BC$41,Assumptions!$B$71:$C$73,2,TRUE),0) -> 0 | T7: =IFNA('Revenue Forecast'!T6*VLOOKUP('Revenue Forecast'!$BC$41,Assumptions!$B$71:$C$73,2,TRUE),0) -> 0 | U7: =IFNA('Revenue Forecast'!U6*VLOOKUP('Revenue Forecast'!$BC$41,Assumptions!$B$71:$C$73,2,TRUE),0) -> 0 | V7: =IFNA('Revenue Forecast'!V6*VLOOKUP('Revenue Forecast'!$BC$41,Assumptions!$B$71:$C$73,2,TRUE),0) -> 0 | W7: =IFNA('Revenue Forecast'!W6*VLOOKUP('Revenue Forecast'!$BC$41,Assumptions!$B$71:$C$73,2,TRUE),0) -> 0 | X7: =IFNA('Revenue Forecast'!X6*VLOOKUP('Revenue Forecast'!$BC$41,Assumptions!$B$71:$C$73,2,TRUE),0) -> 0 | ... AB7: =IFNA('Revenue Forecast'!AB6*VLOOKUP('Revenue Forecast'!$BC$41,Assumptions!$B$71:$C$73,2,TRUE),0) -> 0 | AC7: =IFNA('Revenue Forecast'!AC6*VLOOKUP('Revenue Forecast'!$BD$41,Assumptions!$B$71:$C$73,2,TRUE),0) -> 189694.48 | AD7: =IFNA('Revenue Forecast'!AD6*VLOOKUP('Revenue Forecast'!$BD$41,Assumptions!$B$71:$C$73,2,TRUE),0) -> 209662.32 | AE7: =IFNA('Revenue Forecast'!AE6*VLOOKUP('Revenue Forecast'!$BD$41,Assumptions!$B$71:$C$73,2,TRUE),0) -> 229630.16 | AF7: =IFNA('Revenue Forecast'!AF6*VLOOKUP('Revenue Forecast'!$BD$41,Assumptions!$B$71:$C$73,2,TRUE),0) -> 249598 | AG7: =IFNA('Revenue Forecast'!AG6*VLOOKUP('Revenue Forecast'!$BD$41,Assumptions!$B$71:$C$73,2,TRUE),0) -> 279549.76 | AH7: =IFNA('Revenue Forecast'!AH6*VLOOKUP('Revenue Forecast'!$BD$41,Assumptions!$B$71:$C$73,2,TRUE),0) -> 299517.6 | AI7: =IFNA('Revenue Forecast'!AI6*VLOOKUP('Revenue Forecast'!$BD$41,Assumptions!$B$71:$C$73,2,TRUE),0) -> 329469.36 | AJ7: =IFNA('Revenue Forecast'!AJ6*VLOOKUP('Revenue Forecast'!$BD$41,Assumptions!$B$71:$C$73,2,TRUE),0) -> 359421.12 | ... AN7: =IFNA('Revenue Forecast'!AN6*VLOOKUP('Revenue Forecast'!$BD$41,Assumptions!$B$71:$C$73,2,TRUE),0) -> 529147.76 | AO7: =IFNA('Revenue Forecast'!AO6*VLOOKUP('Revenue Forecast'!$BE$41+'Revenue Forecast'!$BF$41,Assumptions!$B$71:$C$73,2,TRUE),0) -> 409998.75 | AP7: =IFNA('Revenue Forecast'!AP6*VLOOKUP('Revenue Forecast'!$BE$41+'Revenue Forecast'!$BF$41,Assumptions!$B$71:$C$73,2,TRUE),0) -> 445343.47 | AQ7: =IFNA('Revenue Forecast'!AQ6*VLOOKUP('Revenue Forecast'!$BE$41+'Revenue Forecast'!$BF$41,Assumptions!$B$71:$C$73,2,TRUE),0) -> 487757.14 | AR7: =IFNA('Revenue Forecast'!AR6*VLOOKUP('Revenue Forecast'!$BE$41+'Revenue Forecast'!$BF$41,Assumptions!$B$71:$C$73,2,TRUE),0) -> 537239.74 | AS7: =IFNA('Revenue Forecast'!AS6*VLOOKUP('Revenue Forecast'!$BE$41+'Revenue Forecast'!$BF$41,Assumptions!$B$71:$C$73,2,TRUE),0) -> 586722.35 | AT7: =IFNA('Revenue Forecast'!AT6*VLOOKUP('Revenue Forecast'!$BE$41+'Revenue Forecast'!$BF$41,Assumptions!$B$71:$C$73,2,TRUE),0) -> 643273.9 | AU7: =IFNA('Revenue Forecast'!AU6*VLOOKUP('Revenue Forecast'!$BE$41+'Revenue Forecast'!$BF$41,Assumptions!$B$71:$C$73,2,TRUE),0) -> 706894.4 | AV7: =IFNA('Revenue Forecast'!AV6*VLOOKUP('Revenue Forecast'!$BE$41+'Revenue Forecast'!$BF$41,Assumptions!$B$71:$C$73,2,TRUE),0) -> 770514.9 | ... AZ7: =IFNA('Revenue Forecast'!AZ6*VLOOKUP('Revenue Forecast'!$BE$41+'Revenue Forecast'!$BF$41,Assumptions!$B$71:$C$73,2,TRUE),0) -> 1102755.3 | BC7: =SUM(Q7:AB7) -> 0 | BD7: =SUM(AC7:AN7) -> 3993568 | BE7: =SUM(AO7:AZ7) -> 8482732.8 | BF7: ='Revenue Forecast'!BF6*VLOOKUP('Revenue Forecast'!$BF$41+Assumptions!$G$21,Assumptions!$B$71:$C$73,2,TRUE) -> 11995200
B8: Upsell | D8: € | Q8: ='Revenue Forecast'!Q6*SUMPRODUCT(Assumptions!$E$117:$E$119,Assumptions!$G$117:$G$119) -> 0 | R8: ='Revenue Forecast'!R6*SUMPRODUCT(Assumptions!$E$117:$E$119,Assumptions!$G$117:$G$119) -> 0 | S8: ='Revenue Forecast'!S6*SUMPRODUCT(Assumptions!$E$117:$E$119,Assumptions!$G$117:$G$119) -> 0 | T8: ='Revenue Forecast'!T6*SUMPRODUCT(Assumptions!$E$117:$E$119,Assumptions!$G$117:$G$119) -> 0 | U8: ='Revenue Forecast'!U6*SUMPRODUCT(Assumptions!$E$117:$E$119,Assumptions!$G$117:$G$119) -> 0 | V8: ='Revenue Forecast'!V6*SUMPRODUCT(Assumptions!$E$117:$E$119,Assumptions!$G$117:$G$119) -> 0 | W8: ='Revenue Forecast'!W6*SUMPRODUCT(Assumptions!$E$117:$E$119,Assumptions!$G$117:$G$119) -> 0 | X8: ='Revenue Forecast'!X6*SUMPRODUCT(Assumptions!$E$117:$E$119,Assumptions!$G$117:$G$119) -> 0 | ... AZ8: ='Revenue Forecast'!AZ6*SUMPRODUCT(Assumptions!$E$117:$E$119,Assumptions!$G$117:$G$119) -> 33976.8 | BC8: =SUM(Q8:AB8) -> 0 | BD8: =SUM(AC8:AN8) -> 87120 | BE8: =SUM(AO8:AZ8) -> 261360 | BF8: ='Revenue Forecast'!BF6*SUMPRODUCT(Assumptions!$E$117:$E$119,Assumptions!$G$117:$G$119) -> 522720
B9: Total TTK COGS | D9: € | Q9: =sum(Q7:Q8) -> 0 | R9: =sum(R7:R8) -> 0 | S9: =sum(S7:S8) -> 0 | T9: =sum(T7:T8) -> 0 | U9: =sum(U7:U8) -> 0 | V9: =sum(V7:V8) -> 0 | W9: =sum(W7:W8) -> 0 | X9: =sum(X7:X8) -> 0 | ... AZ9: =sum(AZ7:AZ8) -> 1136732.1 | BB9: =SUM(E9:P9) -> 0 | BC9: =SUM(Q9:AB9) -> 0 | BD9: =SUM(AC9:AN9) -> 4080688 | BE9: =SUM(AO9:AZ9) -> 8744092.8 | BF9: =sum(BF7:BF8) -> 12517920
B11: COMBI
